Workbook

Sheet Company Profile
A1: Company | B1: #VALUE! | C1: #VALUE! | D1: #VALUE! | E1: #VALUE! | F1: #VALUE!
A2: Official name | B2: {=_FV(B1,"Official name",TRUE)} -> RTX CORPORATION | C2: {=_FV(C1,"Official name",TRUE)} -> LOCKHEED MARTIN CORPORATION | D2: {=_FV(D1,"Official name",TRUE)} -> GENERAL DYNAMICS CORPORATION | E2: {=_FV(E1,"Official name",TRUE)} -> L3HARRIS TECHNOLOGIES, INC. | F2: {=_FV(F1,"Official name",TRUE)} -> NORTHROP GRUMMAN CORPORATION
A3: Share price | B3: {=_FV(B1,"Price")} -> 173 | C3: {=_FV(C1,"Price")} -> 470.64 | D3: {=_FV(D1,"Price")} -> 341.985 | E3: {=_FV(E1,"Price")} -> 285.2101 | F3: {=_FV(F1,"Price")} -> 566.12
A4: Change (%) | B4: {=_FV(B1,"Change (%)",TRUE)} -> -0.017045 | C4: {=_FV(C1,"Change (%)",TRUE)} -> -0.008595 | D4: {=_FV(D1,"Change (%)",TRUE)} -> 0.002036 | E4: {=_FV(E1,"Change (%)",TRUE)} -> -0.0008054 | F4: {=_FV(F1,"Change (%)",TRUE)} -> -0.001129
A5: Beta | B5: {=_FV(B1,"Beta")} -> 0.4389 | C5: {=_FV(C1,"Beta")} -> 0.2448 | D5: {=_FV(D1,"Beta")} -> 0.4068 | E5: {=_FV(E1,"Beta")} -> 0.6518 | F5: {=_FV(F1,"Beta")} -> 0.0565
A6: Market cap | B6: {=_FV(B1,"Market cap",TRUE)} -> 234259700000 | C6: {=_FV(C1,"Market cap",TRUE)} -> 108905060592 | D6: {=_FV(D1,"Market cap",TRUE)} -> 92377159192 | E6: {=_FV(E1,"Market cap",TRUE)} -> 53392360000 | F6: {=_FV(F1,"Market cap",TRUE)} -> 80796703012
A7: in mn | B7: =B6/1000000 -> 234259.7 | C7: =C6/1000000 -> 108905.06 | D7: =D6/1000000 -> 92377.159 | E7: =E6/1000000 -> 53392.36 | F7: =F6/1000000 -> 80796.703
A8: Shares Outstanding | B8: {=_FV(B1,"Shares outstanding",TRUE)} -> 1340772000 | C8: {=_FV(C1,"Shares outstanding",TRUE)} -> 231397800 | D8: {=_FV(D1,"Shares outstanding",TRUE)} -> 270120500 | E8: {=_FV(E1,"Shares outstanding",TRUE)} -> 187052900 | F8: {=_FV(F1,"Shares outstanding",TRUE)} -> 142720100
A9: in mn | B9: =B8/1000000 -> 1340.772 | C9: =C8/1000000 -> 231.3978 | D9: =D8/1000000 -> 270.1205 | E9: =E8/1000000 -> 187.0529 | F9: =F8/1000000 -> 142.7201
A10: P/E | B10: {=_FV(B1,"P/E",TRUE)} -> 35.7699 | C10: {=_FV(C1,"P/E",TRUE)} -> 26.217 | D10: {=_FV(D1,"P/E",TRUE)} -> 22.1718 | E10: {=_FV(E1,"P/E",TRUE)} -> 30.6295 | F10: {=_FV(F1,"P/E",TRUE)} -> 20.3757
A11: Year | B11: {=_FV(B1,"Year incorporated",TRUE)} -> 1934 | C11: {=_FV(C1,"Year incorporated",TRUE)} -> 1994 | D11: {=_FV(D1,"Year incorporated",TRUE)} -> 1952 | E11: {=_FV(E1,"Year incorporated",TRUE)} -> 1926 | F11: {=_FV(F1,"Year incorporated",TRUE)} -> 2010

Sheet Financials
A1: Income Statement | F1: RTX | H1: Income Statement | M1: LMC | O1: Income Statement | S1: General Dynamics | W1: Income Statement | AB1: L3H | AE1: Income Statement | AJ1: NG
A2: Particulars | B2: 2020 | C2: 2021 | D2: 2022 | E2: 2023 | F2: 2024 | H2: Particulars | I2: 2020 | J2: 2021 | K2: 2022 | L2: 2023 | M2: 2024 | O2: Particulars | P2: 2020 | Q2: 2021 | R2: 2022 | S2: 2023 | T2: 2024 | W2: Particulars | X2: 2020 | Y2: 2021 | Z2: 2022 | AA2: 2023 | AB2: 2024 | AE2: Particulars | AF2: 2020 | AG2: 2021 | AH2: 2022 | AI2: 2023 | AJ2: 2024
A3: Total revenue | B3: 56587 | C3: 64388 | D3: 67074 | E3: 68920 | F3: 80738 | H3: Total revenue | I3: 65398 | J3: 67044 | K3: 65984 | L3: 67571 | M3: 71043 | O3: Total revenue | P3: 37925 | Q3: 38469 | R3: 39407 | S3: 42272 | T3: 47716 | W3: Total revenue | X3: 18194 | Y3: 17814 | Z3: 17062 | AA3: 19419 | AB3: 21325 | AE3: Total revenue | AF3: 36799 | AG3: 35667 | AH3: 36602 | AI3: 39290 | AJ3: 41033
A4: COGS | B4: =38137+9919 -> 48056 | C4: =41095+10802 -> 51897 | D4: =41927+11479 -> 53406 | E4: =43425+13406 -> 56831 | F4: =50768+14560 -> 65328 | H4: COGS | I4: 56744 | J4: 57983 | K4: 57697 | L4: 59092 | M4: 64113 | O4: COGS | P4: =18192+13408 -> 31600 | Q4: =18524+13537 -> 32061 | R4: =18981+13804 -> 32785 | S4: =20591+15009 -> 35600 | T4: =24332+16020 -> 40352 | W4: COGS | X4: 12886 | Y4: 12438 | Z4: 12135 | AA4: 14306 | AB4: 15801 | AE4: COGS | AF4: =21559+7762 -> 29321 | AG4: =22309+6090 -> 28399 | AH4: =22761+6367 -> 29128 | AI4: =26226+6513 -> 32739 | AJ4: =26188+6483 -> 32671
A5: Gross Profit | B5: =B3-B4 -> 8531 | C5: =C3-C4 -> 12491 | D5: =D3-D4 -> 13668 | E5: =E3-E4 -> 12089 | F5: =F3-F4 -> 15410 | H5: Gross Profit | I5: =I3-I4 -> 8654 | J5: =J3-J4 -> 9061 | K5: =K3-K4 -> 8287 | L5: =L3-L4 -> 8479 | M5: =M3-M4 -> 6930 | O5: Gross Profit | P5: =P3-P4 -> 6325 | Q5: =Q3-Q4 -> 6408 | R5: =R3-R4 -> 6622 | S5: =S3-S4 -> 6672 | T5: =T3-T4 -> 7364 | W5: Gross Profit | X5: =X3-X4 -> 5308 | Y5: =Y3-Y4 -> 5376 | Z5: =Z3-Z4 -> 4927 | AA5: =AA3-AA4 -> 5113 | AB5: =AB3-AB4 -> 5524 | AE5: Gross Profit | AF5: =AF3-AF4 -> 7478 | AG5: =AG3-AG4 -> 7268 | AH5: =AH3-AH4 -> 7474 | AI5: =AI3-AI4 -> 6551 | AJ5: =AJ3-AJ4 -> 8362
A6: Operating expenses | B6: =2582+5540 -> 8122 | C6: =2732+5224 -> 7956 | D6: =2711+5663 -> 8374 | E6: =2805+5809 -> 8614 | F6: =2934+5806 -> 8740 | H6: Operating expenses | I6: -10 | J6: 62 | K6: 61 | L6: 28 | M6: 83 | O6: Operating expenses | P6: 2192 | Q6: 2245 | R6: 2411 | S6: 2427 | T6: 2568 | W6: Operating expenses | X6: =3315+51+767-401-16 -> 3716 | Y6: =3280-220+207-439 -> 2828 | Z6: =2998+802-425 -> 3375 | AA6: =3313+374-338 -> 3349 | AB6: =3568+38-354 -> 3252 | AE6: Operating expenses | AF6: =3413+1198-1034 -> 3577 | AG6: =3597-1980-1469-2355-19 -> -2226 | AH6: =3873-1505-1232-4 -> 1132 | AI6: =4014-530-246+422 -> 3660 | AJ6: =3992-656-443-168 -> 2725
A7: Operating income | B7: =B5-B6 -> 409 | C7: =C5-C6 -> 4535 | D7: =D5-D6 -> 5294 | E7: =E5-E6 -> 3475 | F7: =F5-F6 -> 6670 | H7: Operating income | I7: =I5+I6 -> 8644 | J7: =J5+J6 -> 9123 | K7: =K5+K6 -> 8348 | L7: =L5+L6 -> 8507 | M7: =M5+M6 -> 7013 | O7: Operating income | P7: =P5-P6 -> 4133 | Q7: =Q5-Q6 -> 4163 | R7: =R5-R6 -> 4211 | S7: =S5-S6 -> 4245 | T7: =T5-T6 -> 4796 | W7: Operating income | X7: =X5-X6 -> 1592 | Y7: =Y5-Y6 -> 2548 | Z7: =Z5-Z6 -> 1552 | AA7: =AA5-AA6 -> 1764 | AB7: =AB5-AB6 -> 2272 | AE7: Operating income | AF7: =AF5-AF6 -> 3901 | AG7: =AG5-AG6 -> 9494 | AH7: =AH5-AH6 -> 6342 | AI7: =AI5-AI6 -> 2891 | AJ7: =AJ5-AJ6 -> 5637
A8: Interest expense | B8: 1366 | C8: 1322 | D8: 1276 | E8: 1505 | F8: 1862 | H8: Interest expense | I8: 591 | J8: 569 | K8: 623 | L8: 916 | M8: 1036 | O8: Interest expense | P8: 477 | Q8: 424 | R8: 364 | S8: 343 | T8: 324 | W8: Interest expense | X8: 270 | Y8: 265 | Z8: 279 | AA8: 543 | AB8: 675 | AE8: Interest expense | AF8: 593 | AG8: 556 | AH8: 506 | AI8: 545 | AJ8: 621
A9: Income tax | B9: 575 | C9: 786 | D9: 790 | E9: 456 | F9: 1181 | H9: Income tax | I9: 1347 | J9: 1235 | K9: 948 | L9: 1178 | M9: 884 | O9: Income tax | P9: 571 | Q9: 616 | R9: 646 | S9: 669 | T9: 758 | W9: Income tax | X9: 234 | Y9: 440 | Z9: 212 | AA9: 23 | AB9: 85 | AE9: Income tax | AF9: 539 | AG9: 1933 | AH9: 940 | AI9: 290 | AJ9: 842
A10: Net Income | B10: =B7-B8-B9 -> -1532 | C10: =C7-C8-C9 -> 2427 | D10: =D7-D8-D9 -> 3228 | E10: =E7-E8-E9 -> 1514 | F10: =F7-F8-F9 -> 3627 | H10: Net Income | I10: =I7-I8-I9 -> 6706 | J10: =J7-J8-J9 -> 7319 | K10: =K7-K8-K9 -> 6777 | L10: =L7-L8-L9 -> 6413 | M10: =M7-M8-M9 -> 5093 | O10: Net Income | P10: =P7-P8-P9 -> 3085 | Q10: =Q7-Q8-Q9 -> 3123 | R10: =R7-R8-R9 -> 3201 | S10: =S7-S8-S9 -> 3233 | T10: =T7-T8-T9 -> 3714 | W10: Net Income | X10: =X7-X8-X9 -> 1088 | Y10: =Y7-Y8-Y9 -> 1843 | Z10: =Z7-Z8-Z9 -> 1061 | AA10: =AA7-AA8-AA9 -> 1198 | AB10: =AB7-AB8-AB9 -> 1512 | AE10: Net Income | AF10: =AF7-AF8-AF9 -> 2769 | AG10: =AG7-AG8-AG9 -> 7005 | AH10: =AH7-AH8-AH9 -> 4896 | AI10: =AI7-AI8-AI9 -> 2056 | AJ10: =AJ7-AJ8-AJ9 -> 4174
A12: Balance Sheet | H12: Balance Sheet | O12: Balance Sheet | W12: Balance Sheet | AE12: Balance Sheet
A13: Particulars | B13: 2020 | C13: 2021 | D13: 2022 | E13: 2023 | F13: 2024 | H13: Particulars | I13: 2020 | J13: 2021 | K13: 2022 | L13: 2023 | M13: 2024 | O13: Particulars | P13: 2020 | Q13: 2021 | R13: 2022 | S13: 2023 | T13: 2024 | W13: Particulars | X13: 2020 | Y13: 2021 | Z13: 2022 | AA13: 2023 | AB13: 2024 | AE13: Particulars | AF13: 2020 | AG13: 2021 | AH13: 2022 | AI13: 2023 | AJ13: 2024
A14: Total current assets | B14: 43376 | C14: 42050 | D14: 42443 | E14: 48417 | F14: 51133 | H14: Total current assets | I14: 19378 | J14: 19815 | K14: 20991 | L14: 20521 | M14: 21849 | O14: Total current assets | P14: 21543 | Q14: 19987 | R14: 21063 | S14: 23615 | T14: 24386 | W14: Total current assets | X14: 6667 | Y14: 6359 | Z14: 6754 | AA14: 8055 | AB14: 8218 | AE14: Total current assets | AF14: 15344 | AG14: 12426 | AH14: 12488 | AI14: 13706 | AJ14: 14274
A15: Cash & cash equivalents | B15: 8802 | C15: 7832 | D15: 6220 | E15: 6587 | F15: 5578 | H15: Cash & cash equivalents | I15: 3160 | J15: 3604 | K15: 2547 | L15: 1442 | M15: 2483 | O15: Cash & cash equivalents | P15: 2824 | Q15: 1603 | R15: 1242 | S15: 1913 | T15: 1697 | W15: Cash & cash equivalents | X15: 1276 | Y15: 941 | Z15: 880 | AA15: 560 | AB15: 615 | AE15: Cash & cash equivalents | AF15: 4907 | AG15: 3530 | AH15: 2577 | AI15: 3109 | AJ15: 4353
A16: Total current liabilities | B16: 35848 | C16: 35449 | D16: 39114 | E16: 46761 | F16: 51499 | H16: Total current liabilities | I16: 13933 | J16: 13997 | K16: 15887 | L16: 16937 | M16: 19420 | O16: Total current liabilities | P16: 15964 | Q16: 13978 | R16: 15341 | S16: 16432 | T16: 17824 | W16: Total current liabilities | X16: 4240 | Y16: 4551 | Z16: 5776 | AA16: 8004 | AB16: 7633 | AE16: Total current liabilities | AF16: 9580 | AG16: 9530 | AH16: 11587 | AI16: 11942 | AJ16: 14128
A17: Inventories | B17: 9411 | C17: 9178 | D17: 10617 | E17: 11777 | F17: 12768 | H17: Inventories | I17: 3545 | J17: 2981 | K17: 3088 | L17: 3132 | M17: 3474 | O17: Inventories | P17: 5745 | Q17: 5340 | R17: 6322 | S17: 8578 | T17: 9724 | W17: Inventories | X17: 973 | Y17: 982 | Z17: 1291 | AA17: 1472 | AB17: 1330 | AE17: Inventories | AF17: 759 | AG17: 811 | AH17: 978 | AI17: 1109 | AJ17: 1455
A18: Receivables | B18: 9254 | C18: 9661 | D18: 9108 | E18: 10838 | F18: 10976 | H18: Receivables | I18: 1978 | J18: 1963 | K18: 2505 | L18: 2132 | M18: 2351 | O18: Receivables | P18: 3161 | Q18: 3041 | R18: 3008 | S18: 3004 | T18: 2977 | W18: Receivables | X18: 1344 | Y18: 1045 | Z18: 1251 | AA18: 1230 | AB18: 1072 | AE18: Receivables | AF18: 1501 | AG18: 1467 | AH18: 1511 | AI18: 1454 | AJ18: 1272
A19: Payables | B19: 8639 | C19: 8751 | D19: 9896 | E19: 10698 | F19: 12897 | H19: Payables | I19: 880 | J19: 780 | K19: 2117 | L19: 2312 | M19: 2222 | O19: Payables | P19: 2952 | Q19: 3167 | R19: 3398 | S19: 3095 | T19: 3344 | W19: Payables | X19: 1406 | Y19: 1767 | Z19: 1945 | AA19: 2106 | AB19: 2005 | AE19: Payables | AF19: 1806 | AG19: 2197 | AH19: 2587 | AI19: 2110 | AJ19: 2599
A20: PPE | B20: 14962 | C20: 14972 | D20: 15170 | E20: 15748 | F20: 16089 | H20: PPE | I20: 7213 | J20: 7597 | K20: 7975 | L20: 8370 | M20: 8726 | O20: PPE | P20: 5100 | Q20: 5417 | R20: 5900 | S20: 6198 | T20: 6467 | W20: PPE | X20: 2102 | Y20: 2101 | Z20: 2104 | AA20: 2862 | AB20: 2806 | AE20: PPE | AF20: 7071 | AG20: 7894 | AH20: 8800 | AI20: 9653 | AJ20: 10536
A21: Total debt | B21: =247+550+31026 -> 31823 | C21: =134+24+31327 -> 31485 | D21: =625+595+30694 -> 31914 | E21: =189+1283+42355 -> 43827 | F21: =183+2352+38726 -> 41261 | H21: Total debt | I21: =500+11669 -> 12169 | J21: =6+11670 -> 11676 | K21: =118+15429 -> 15547 | L21: =168+17291 -> 17459 | M21: =643+19627 -> 20270 | O21: Total debt | P21: =3003+9995 -> 12998 | Q21: =1005+10490 -> 11495 | R21: =1253+9243 -> 10496 | S21: =507+8754 -> 9261 | T21: =1502+7260 -> 8762 | W21: Total debt | X21: =2+8+6908 -> 6918 | Y21: =2+11+7048 -> 7061 | Z21: =2+818+6225 -> 7045 | AA21: =1602+363+11160 -> 13125 | AB21: =515+640+11081 -> 12236 | AE21: Total debt | AF21: =14261 -> 14261 | AG21: =12777 -> 12777 | AH21: 11805 | AI21: 13786 | AJ21: 14692
A22: Shareholders equity | B22: =73852 -> 73852 | C22: 74664 | D22: 74178 | E22: =61410 -> 61410 | F22: 61923 | H22: Shareholders equity | I22: 6038 | J22: 10959 | K22: 9266 | L22: 6835 | M22: 6333 | O22: Shareholders equity | P22: 15661 | Q22: 17641 | R22: 18568 | S22: 21299 | T22: 22063 | W22: Shareholders equity | X22: 20841 | Y22: 19319 | Z22: 18624 | AA22: 18829 | AB22: 19579 | AE22: Shareholders equity | AF22: 10579 | AG22: 12926 | AH22: 15312 | AI22: 14795 | AJ22: 15290
H23: Total assets | O23: Total Assets | P23: 51308 | Q23: 50073 | R23: 51585 | S23: 54810 | T23: 55880 | W23: Total assets | X23: 36960 | Y23: 34709 | Z23: 33524 | AA23: 41687 | AB23: 42001 | AE23: Total assets | AF23: 44469 | AG23: 42579 | AH23: 43755 | AI23: 46544 | AJ23: 49359
A24: Cash Flow statement
A25: Particulars | B25: 2020 | C25: 2021 | D25: 2022 | E25: 2023 | F25: 2024 | H25: Cash Flow statement | O25: Cash Flow statement | W25: Cash Flow statement | AE25: Cash Flow statement
A26: Net cash flow from operating activities | B26: 4334 | C26: 7142 | D26: 7168 | E26: 7883 | F26: 7159 | H26: Particulars | I26: 2020 | J26: 2021 | K26: 2022 | L26: 2023 | M26: 2024 | O26: Particulars | P26: 2020 | Q26: 2021 | R26: 2022 | S26: 2023 | T26: 2024 | W26: Particulars | X26: 2020 | Y26: 2021 | Z26: 2022 | AA26: 2023 | AB26: 2024 | AE26: Particulars | AF26: 2020 | AG26: 2021 | AH26: 2022 | AI26: 2023 | AJ26: 2024
A27: Capex | B27: 1795 | C27: 2134 | D27: 2288 | E27: 2415 | F27: 2625 | H27: Net cash flow from operating activities | I27: 8183 | J27: 9221 | K27: 7802 | L27: 7920 | M27: 6972 | O27: Net cash flow from operating activities | P27: 3858 | Q27: 4271 | R27: 4579 | S27: 4710 | T27: 4112 | W27: Net cash flow from operating activities | X27: 2790 | Y27: 2687 | Z27: 2158 | AA27: 2096 | AB27: 2559 | AE27: Net cash flow from operating activities | AF27: 4305 | AG27: 3567 | AH27: 2901 | AI27: 3875 | AJ27: 4388
A28: Depreciation & amoritzation | B28: 4156 | C28: 4557 | D28: 4108 | E28: 4211 | F28: 4364 | H28: Capex | I28: 1766 | J28: 1522 | K28: 1670 | L28: 1691 | M28: 1685 | O28: Capex | P28: 967 | Q28: 887 | R28: 1114 | S28: 904 | T28: 916 | W28: Capex | X28: 368 | Y28: 342 | Z28: 252 | AA28: 449 | AB28: 408 | AE28: Capex | AF28: 1420 | AG28: 1415 | AH28: 1435 | AI28: 1775 | AJ28: 1767
A29: Debt paid | B29: 16082 | C29: 4254 | D29: 3 | E29: 578 | F29: 2500 | H29: Depreciation & amoritzation | I29: 1290 | J29: 1364 | K29: 1404 | L29: 1430 | M29: 1559 | O29: Depreciation & amoritzation | P29: =523+355 -> 878 | Q29: =568+322 -> 890 | R29: =586+298 -> 884 | S29: =608+255 -> 863 | T29: =644+242 -> 886 | W29: Depreciation & amoritzation | X29: 1032 | Y29: 967 | Z29: 938 | AA29: 1166 | AB29: 1289 | AE29: Depreciation & amoritzation | AF29: 1267 | AG29: 1239 | AH29: 1342 | AI29: 1338 | AJ29: 1370
A30: Dividends paid | B30: 2732 | C30: 2957 | D30: 3128 | E30: 3239 | F30: 3217 | H30: Debt paid | I30: 1650 | J30: 500 | K30: 2250 | L30: 115 | M30: 168 | O30: Debt paid | P30: =2000+500+420 -> 2920 | Q30: =2500+1997+500 -> 4997 | R30: =1000 -> 1000 | S30: 1250 | T30: 500 | W30: Debt paid | X30: 931 | Y30: =13 -> 13 | Z30: 14 | AA30: =3170+205 -> 3375 | AB30: =2620+1205 -> 3825 | AE30: Debt paid | AF30: =1027+78 -> 1105 | AG30: 2236 | AH30: 0 | AI30: 1050 | AJ30: 0
H31: Dividends paid | I31: 2764 | J31: 2940 | K31: 3016 | L31: 3056 | M31: 3059 | O31: Dividends paid | P31: 1240 | Q31: 1315 | R31: 1369 | S31: 1428 | T31: 1529 | W31: Dividends paid | X31: 725 | Y31: 817 | Z31: 864 | AA31: 868 | AB31: 886 | AE31: Dividends paid | AF31: 953 | AG31: 983 | AH31: 1052 | AI31: 1116 | AJ31: 1186
O34: Particulars | P34: 2020 | Q34: 2021 | R34: 2022 | S34: 2023 | T34: 2024 | W34: Particulars | X34: 2020 | Y34: 2021 | Z34: 2022 | AA34: 2023 | AB34: 2024 | AE34: Particulars | AF34: 2020 | AG34: 2021 | AH34: 2022 | AI34: 2023 | AJ34: 2024
O35: Revenue | P35: =P3 -> 37925 | Q35: =Q3 -> 38469 | R35: =R3 -> 39407 | S35: =S3 -> 42272 | T35: =T3 -> 47716 | W35: Revenue | X35: =X3 -> 18194 | Y35: =Y3 -> 17814 | Z35: =Z3 -> 17062 | AA35: =AA3 -> 19419 | AB35: =AB3 -> 21325 | AE35: Revenue | AF35: =AF3 -> 36799 | AG35: =AG3 -> 35667 | AH35: =AH3 -> 36602 | AI35: =AI3 -> 39290 | AJ35: =AJ3 -> 41033
O36: Operating income | P36: =P7 -> 4133 | Q36: =Q7 -> 4163 | R36: =R7 -> 4211 | S36: =S7 -> 4245 | T36: =T7 -> 4796 | W36: Operating income | X36: =X7 -> 1592 | Y36: =Y7 -> 2548 | Z36: =Z7 -> 1552 | AA36: =AA7 -> 1764 | AB36: =AB7 -> 2272 | AE36: Operating income | AF36: =AF7 -> 3901 | AG36: =AG7 -> 9494 | AH36: =AH7 -> 6342 | AI36: =AI7 -> 2891 | AJ36: =AJ7 -> 5637
O37: Net income | P37: =P10 -> 3085 | Q37: =Q10 -> 3123 | R37: =R10 -> 3201 | S37: =S10 -> 3233 | T37: =T10 -> 3714 | W37: Net income | X37: =X10 -> 1088 | Y37: =Y10 -> 1843 | Z37: =Z10 -> 1061 | AA37: =AA10 -> 1198 | AB37: =AB10 -> 1512 | AE37: Net income | AF37: =AF10 -> 2769 | AG37: =AG10 -> 7005 | AH37: =AH10 -> 4896 | AI37: =AI10 -> 2056 | AJ37: =AJ10 -> 4174
O39: Particulars | P39: 2025 | Q39: 2026 | R39: 2027 | S39: 2028 | T39: 2029 | U39: 2030 | W39: Particulars | X39: 2025 | Y39: 2026 | Z39: 2027 | AA39: 2028 | AB39: 2029 | AC39: 2030 | AE39: Particulars | AF39: 2025 | AG39: 2026 | AH39: 2027 | AI39: 2028 | AJ39: 2029 | AK39: 2030
O40: =O35 -> Revenue | P40: =DCF!R3 -> 49958.768 | Q40: =DCF!S3 -> 52306.951 | R40: =DCF!T3 -> 54765.505 | S40: =DCF!U3 -> 57339.616 | T40: =DCF!V3 -> 60034.717 | U40: =DCF!W3 -> 62856.495 | W40: =W35 -> Revenue | X40: =DCF!Z3 -> 22013.1 | Y40: =DCF!AA3 -> 22723.403 | Z40: =DCF!AB3 -> 23456.626 | AA40: =DCF!AC3 -> 24213.508 | AB40: =DCF!AD3 -> 24994.813 | AC40: =DCF!AE3 -> 25801.328 | AE40: =AE35 -> Revenue | AF40: =DCF!AH3 -> 41936.552 | AG40: =DCF!AI3 -> 42860 | AH40: =DCF!AJ3 -> 43803.783 | AI40: =DCF!AK3 -> 44768.348 | AJ40: =DCF!AL3 -> 45754.153 | AK40: =DCF!AM3 -> 46761.666
O41: =O36 -> Operating income | P41: =DCF!R4 -> 5231.1422 | Q41: =DCF!S4 -> 5477.0186 | R41: =DCF!T4 -> 5734.4518 | S41: =DCF!U4 -> 6003.9849 | T41: =DCF!V4 -> 6286.1868 | U41: =DCF!W4 -> 6581.6528 | W41: =W36 -> Operating income | X41: =DCF!Z4 -> 2282.6384 | Y41: =DCF!AA4 -> 2356.293 | Z41: =DCF!AB4 -> 2432.3242 | AA41: =DCF!AC4 -> 2510.8087 | AB41: =DCF!AD4 -> 2591.8257 | AC41: =DCF!AE4 -> 2675.457 | AE41: =AE36 -> Operating income | AF41: =DCF!AH4 -> 6258.6746 | AG41: =DCF!AI4 -> 6396.4915 | AH41: =DCF!AJ4 -> 6537.343 | AI41: =DCF!AK4 -> 6681.2962 | AJ41: =DCF!AL4 -> 6828.4192 | AK41: =DCF!AM4 -> 6978.7819
O42: =O37 -> Net income | P42: =DCF!R5 -> 4027.9795 | Q42: =DCF!S5 -> 4217.3043 | R42: =DCF!T5 -> 4415.5279 | S42: =DCF!U5 -> 4623.0684 | T42: =DCF!V5 -> 4840.3638 | U42: =DCF!W5 -> 5067.8727 | W42: =W37 -> Net income | X42: =DCF!Z5 -> 1757.6316 | Y42: =DCF!AA5 -> 1814.3456 | Z42: =DCF!AB5 -> 1872.8896 | AA42: =DCF!AC5 -> 1933.3227 | AB42: =DCF!AD5 -> 1995.7058 | AC42: =DCF!AE5 -> 2060.1019 | AE42: =AE37 -> Net income | AF42: =DCF!AH5 -> 4819.1795 | AG42: =DCF!AI5 -> 4925.2984 | AH42: =DCF!AJ5 -> 5033.7541 | AI42: =DCF!AK5 -> 5144.5981 | AJ42: =DCF!AL5 -> 5257.8828 | AK42: =DCF!AM5 -> 5373.6621

Sheet Assumptions & WACC
A1: Assumptions
A2: Metric | B2: RTX | C2: LMC | D2: GD | E2: L3H | F2: NG
A3: Revenue CAGR | B3: =(Table1[[#This Row],[2024]]/Table1[[#This Row],[2020]])^(1/5)-1 -> 0.073673572 | C3: =(Table18[[#This Row],[2024]]/Table18[[#This Row],[2020]])^(1/5)-1 -> 0.016696586 | D3: =(Table119[[#This Row],[2024]]/Table119[[#This Row],[2020]])^(1/5)-1 -> 0.047002426 | E3: =(Table1822[[#This Row],[2024]]/Table1822[[#This Row],[2020]])^(1/5)-1 -> 0.0322673 | F3: =(Table182225[[#This Row],[2024]]/Table182225[[#This Row],[2020]])^(1/5)-1 -> 0.022020132
A4: Operating margin | B4: =AVERAGE(Financials!B7:F7)/AVERAGE(Financials!B3:F3) -> 0.060357055 | C4: =AVERAGE(Financials!I7:M7)/AVERAGE(Financials!I3:M3) -> 0.12353133 | D4: =AVERAGE(Financials!P7:T7)/AVERAGE(Financials!P3:T3) -> 0.10470919 | E4: =AVERAGE(Financials!X7:AB7)/AVERAGE(Financials!X3:AB3) -> 0.10369454 | F4: =AVERAGE(Financials!AF7:AJ7)/AVERAGE(Financials!AF3:AJ3) -> 0.14924152
A5: Depreciation rate | B5: =AVERAGE(Financials!B28:F28)/AVERAGE(Financials!B3:F3) -> 0.063356697 | C5: =AVERAGE(Financials!I29:M29)/AVERAGE(Financials!I3:M3) -> 0.020908498 | D5: =AVERAGE(Financials!P29:T29)/AVERAGE(Financials!P3:T3) -> 0.021385983 | E5: =AVERAGE(Financials!X29:AB29)/AVERAGE(Financials!X3:AB3) -> 0.05747543 | F5: =AVERAGE(Financials!AF29:AJ29)/AVERAGE(Financials!AF3:AJ3) -> 0.034616217
A6: Capex | B6: =AVERAGE(Financials!B27:F27)/AVERAGE(Financials!B3:F3) -> 0.033333629 | C6: =AVERAGE(Financials!I28:M28)/AVERAGE(Financials!I3:M3) -> 0.024727035 | D6: =AVERAGE(Financials!P28:T28)/AVERAGE(Financials!P3:T3) -> 0.02326655 | E6: =AVERAGE(Financials!X28:AB28)/AVERAGE(Financials!X3:AB3) -> 0.01938943 | F6: =AVERAGE(Financials!AF28:AJ28)/AVERAGE(Financials!AF3:AJ3) -> 0.041248
A7: Working capital | B7: =AVERAGE(L9:M9)/AVERAGE(Financials!E3:F3) -> 0.0086196528 | C7: =AVERAGE(L16:M16)/AVERAGE(Financials!L3:M3) -> 0.043379457 | D7: =AVERAGE(Q9:U9)/AVERAGE(Financials!P3:T3) -> 0.150907 | E7: =AVERAGE(Q16:U16)/AVERAGE(Financials!X3:AB3) -> 0.062346771 | F7: =AVERAGE(I24:M24)/AVERAGE(Financials!AF3:AJ3) -> 0.06056782 | M7: RTX | U7: =D2 -> GD
A8: Beta | B8: ='Company Profile'!B5 -> 0.4389 | C8: ='Company Profile'!C5 -> 0.2448 | D8: ='Company Profile'!D5 -> 0.4068 | E8: ='Company Profile'!E5 -> 0.6518 | F8: ='Company Profile'!F5 -> 0.0565 | H8: Particulars | I8: 2020 | J8: 2021 | K8: 2022 | L8: 2023 | M8: 2024 | P8: Particulars | Q8: 2020 | R8: 2021 | S8: 2022 | T8: 2023 | U8: 2024
A9: Equity risk premium | B9: 0.041 | C9: 0.041 | D9: 0.041 | E9: 0.041 | F9: 0.041 | H9: Working Capital | I9: =Financials!B14-Financials!B16 -> 7528 | J9: =Financials!C14-Financials!C16 -> 6601 | K9: =Financials!D14-Financials!D16 -> 3329 | L9: =Financials!E14-Financials!E16 -> 1656 | M9: =Financials!F14-Financials!F16 -> -366 | P9: Working Capital | Q9: =Financials!P14-Financials!P16 -> 5579 | R9: =Financials!Q14-Financials!Q16 -> 6009 | S9: =Financials!R14-Financials!R16 -> 5722 | T9: =Financials!S14-Financials!S16 -> 7183 | U9: =Financials!T14-Financials!T16 -> 6562
A10: Risk free rate | B10: 0.0411 | C10: 0.0411 | D10: 0.0411 | E10: 0.0411 | F10: 0.0411
A11: Cost of equity | B11: =B10+(B8*B9) -> 0.0590949 | C11: =C10+(C8*C9) -> 0.0511368 | D11: =D10+(D8*D9) -> 0.0577788 | E11: =E10+(E8*E9) -> 0.0678238 | F11: =F10+(F8*F9) -> 0.0434165 | H11: Particulars | I11: 2025 | J11: 2026 | K11: 2027 | L11: 2028 | M11: 2029 | N11: 2030 | P11: Particulars | Q11: 2025 | R11: 2026 | S11: 2027 | T11: 2028 | U11: 2029 | V11: 2030
A12: Cost of debt (pre-tax) | B12: =AVERAGE(Financials!B8:F8)/AVERAGE(Financials!B21:F21) -> 0.040657756 | C12: =AVERAGE(Financials!I8:M8)/AVERAGE(Financials!I21:M21) -> 0.048430389 | D12: =AVERAGE(Financials!P8:T8)/AVERAGE(Financials!P21:T21) -> 0.036444579 | E12: =AVERAGE(Financials!X8:AB8)/AVERAGE(Financials!X21:AB21) -> 0.043807265 | F12: =AVERAGE(Financials!AF8:AJ8)/AVERAGE(Financials!AF21:AJ21) -> 0.041903715 | H12: Working capital | I12: =DCF!B3*'Assumptions & WACC'!$B$7 -> 747.20544 | J12: =DCF!C3*'Assumptions & WACC'!$B$7 -> 802.25473 | K12: =DCF!D3*'Assumptions & WACC'!$B$7 -> 861.3597 | L12: =DCF!E3*'Assumptions & WACC'!$B$7 -> 924.81915 | M12: =DCF!F3*'Assumptions & WACC'!$B$7 -> 992.95388 | N12: =DCF!G3*'Assumptions & WACC'!$B$7 -> 1066.1083 | P12: Working capital | Q12: =DCF!R3*'Assumptions & WACC'!$D$7 -> 7539.1276 | R12: =DCF!S3*'Assumptions & WACC'!$D$7 -> 7893.4849 | S12: =DCF!T3*'Assumptions & WACC'!$D$7 -> 8264.4978 | T12: =DCF!U3*'Assumptions & WACC'!$D$7 -> 8652.9493 | U12: =DCF!V3*'Assumptions & WACC'!$D$7 -> 9059.6589 | V12: =DCF!W3*'Assumptions & WACC'!$D$7 -> 9485.4849
A13: Tax rate | B13: 0.23 | C13: 0.23 | D13: 0.23 | E13: 0.23 | F13: 0.23
A14: Cost of debt (after-tax) | B14: =B12*(1-B13) -> 0.031306472 | C14: =C12*(1-C13) -> 0.037291399 | D14: =D12*(1-D13) -> 0.028062326 | E14: =E12*(1-E13) -> 0.033731594 | F14: =F12*(1-F13) -> 0.032265861 | M14: LMC | U14: =E2 -> L3H
A15: Total Debt | B15: =Financials!F21 -> 41261 | C15: =Financials!M21 -> 20270 | D15: =Financials!T21 -> 8762 | E15: =Financials!AB21 -> 12236 | F15: =Financials!AJ21 -> 14692 | H15: Particulars | I15: 2020 | J15: 2021 | K15: 2022 | L15: 2023 | M15: 2024 | P15: Particulars | Q15: 2020 | R15: 2021 | S15: 2022 | T15: 2023 | U15: 2024
A16: Market cap | B16: ='Company Profile'!B7 -> 234259.7 | C16: ='Company Profile'!C7 -> 108905.06 | D16: ='Company Profile'!D7 -> 92377.159 | E16: ='Company Profile'!E7 -> 53392.36 | F16: ='Company Profile'!F7 -> 80796.703 | H16: Working Capital | I16: =Financials!I14-Table29[[#This Row],[2020]] -> 5445 | J16: =Financials!J14-Table29[[#This Row],[2021]] -> 5818 | K16: =Financials!K14-Table29[[#This Row],[2022]] -> 5104 | L16: =Financials!L14-Table29[[#This Row],[2023]] -> 3584 | M16: =Financials!M14-Table29[[#This Row],[2024]] -> 2429 | P16: Working Capital | Q16: =Financials!X14-Table2923[[#This Row],[2020]] -> 2427 | R16: =Financials!Y14-Table2923[[#This Row],[2021]] -> 1808 | S16: =Financials!Z14-Table2923[[#This Row],[2022]] -> 978 | T16: =Financials!AA14-Table2923[[#This Row],[2023]] -> 51 | U16: =Financials!AB14-Table2923[[#This Row],[2024]] -> 585
A17: Total Capital | B17: =B15+B16 -> 275520.7 | C17: =C15+C16 -> 129175.06 | D17: =D15+D16 -> 101139.16 | E17: =E15+E16 -> 65628.36 | F17: =F15+F16 -> 95488.703
A18: Weight of debt | B18: =B15/B17 -> 0.14975644 | C18: =C15/C17 -> 0.15691883 | D18: =D15/D17 -> 0.086633111 | E18: =E15/E17 -> 0.18644379 | F18: =F15/F17 -> 0.15386113 | H18: Particulars | I18: 2025 | J18: 2026 | K18: 2027 | L18: 2028 | M18: 2029 | N18: 2030 | P18: Particulars | Q18: 2025 | R18: 2026 | S18: 2027 | T18: 2028 | U18: 2029 | V18: 2030
A19: Weight of equity | B19: =B16/B17 -> 0.85024356 | C19: =C16/C17 -> 0.84308117 | D19: =D16/D17 -> 0.91336689 | E19: =E16/E17 -> 0.81355621 | F19: =F16/F17 -> 0.84613887 | H19: Working capital | I19: =DCF!J3*'Assumptions & WACC'!$C$7 -> 3133.2624 | J19: =DCF!K3*'Assumptions & WACC'!$C$7 -> 3185.5772 | K19: =DCF!L3*'Assumptions & WACC'!$C$7 -> 3238.7654 | L19: =DCF!M3*'Assumptions & WACC'!$C$7 -> 3292.8418 | M19: =DCF!N3*'Assumptions & WACC'!$C$7 -> 3347.821 | N19: =DCF!O3*'Assumptions & WACC'!$C$7 -> 3403.7182 | P19: Working capital | Q19: =DCF!Z3*'Assumptions & WACC'!$E$7 -> 1372.4457 | R19: =DCF!AA3*'Assumptions & WACC'!$E$7 -> 1416.7308 | S19: =DCF!AB3*'Assumptions & WACC'!$E$7 -> 1462.4449 | T19: =DCF!AC3*'Assumptions & WACC'!$E$7 -> 1509.6341 | U19: =DCF!AD3*'Assumptions & WACC'!$E$7 -> 1558.3459 | V19: =DCF!AE3*'Assumptions & WACC'!$E$7 -> 1608.6295
A20: WACC | B20: =(B11*B19)+(B14*B18) -> 0.054933404 | C20: =(C11*C19)+(C14*C18) -> 0.048964196 | D20: =(D11*D19)+(D14*D18) -> 0.055204369 | E20: =(E11*E19)+(E14*E18) -> 0.06146752 | F20: =(F11*F19)+(F14*F18) -> 0.04170085
A21: Terminal Growth | B21: 0.03 | C21: 0.03 | D21: 0.03 | E21: 0.03 | F21: 0.03
A22: Outstanding shares | B22: ='Company Profile'!B9 -> 1340.772 | C22: ='Company Profile'!C9 -> 231.3978 | D22: ='Company Profile'!D9 -> 270.1205 | E22: ='Company Profile'!E9 -> 187.0529 | F22: ='Company Profile'!F9 -> 142.7201 | M22: =F2 -> NG
A23: PV discount rate | B23: =1/(1+B20)^6 -> 0.72552058 | C23: =1/(1+C20)^6 -> 0.75064745 | D23: =1/(1+D20)^6 -> 0.72440346 | E23: =1/(1+E20)^6 -> 0.6991329 | F23: =1/(1+F20)^6 -> 0.78260369 | H23: Particulars | I23: 2020 | J23: 2021 | K23: 2022 | L23: 2023 | M23: 2024
A24: Cash & cash equivalents | B24: =Financials!F15 -> 5578 | C24: =Financials!M15 -> 2483 | D24: =Financials!T15 -> 1697 | E24: =Financials!AB15 -> 615 | F24: =Financials!AJ15 -> 4353 | H24: Working Capital | I24: =Financials!AF14-Financials!AF16 -> 5764 | J24: =Financials!AG14-Financials!AG16 -> 2896 | K24: =Financials!AH14-Financials!AH16 -> 901 | L24: =Financials!AI14-Financials!AI16 -> 1764 | M24: =Financials!AJ14-Financials!AJ16 -> 146
H26: Particulars | I26: 2025 | J26: 2026 | K26: 2027 | L26: 2028 | M26: 2029 | N26: 2030
H27: Working capital | I27: =DCF!AH3*'Assumptions & WACC'!$F$7 -> 2540.0055 | J27: =DCF!AI3*'Assumptions & WACC'!$F$7 -> 2595.9368 | K27: =DCF!AJ3*'Assumptions & WACC'!$F$7 -> 2653.0997 | L27: =DCF!AK3*'Assumptions & WACC'!$F$7 -> 2711.5213 | M27: =DCF!AL3*'Assumptions & WACC'!$F$7 -> 2771.2293 | N27: =DCF!AM3*'Assumptions & WACC'!$F$7 -> 2832.2522

Sheet DCF
A1: DCF | G1: =Financials!F1 -> RTX | O1: =Financials!M1 -> LMC | Q1: DCF | V1: =Financials!S1 -> General Dynamics | AE1: =Financials!AB1 -> L3H | AG1: DCF | AM1: =Financials!AJ1 -> NG
A2: Particulars | B2: 2025 | C2: 2026 | D2: 2027 | E2: 2028 | F2: 2029 | G2: 2030 | I2: Particulars | J2: 2025 | K2: 2026 | L2: 2027 | M2: 2028 | N2: 2029 | O2: 2030 | Q2: Particulars | R2: 2025 | S2: 2026 | T2: 2027 | U2: 2028 | V2: 2029 | W2: 2030 | Y2: Particulars | Z2: 2025 | AA2: 2026 | AB2: 2027 | AC2: 2028 | AD2: 2029 | AE2: 2030 | AG2: Particulars | AH2: 2025 | AI2: 2026 | AJ2: 2027 | AK2: 2028 | AL2: 2029 | AM2: 2030
A3: Revenue | B3: =Table1[[#This Row],[2024]]*(1+'Assumptions & WACC'!$B3) -> 86686.257 | C3: =Table9[[#This Row],[2025]]*(1+'Assumptions & WACC'!$B$3) -> 93072.743 | D3: =Table9[[#This Row],[2026]]*(1+'Assumptions & WACC'!$B$3) -> 99929.745 | E3: =Table9[[#This Row],[2027]]*(1+'Assumptions & WACC'!$B$3) -> 107291.93 | F3: =Table9[[#This Row],[2028]]*(1+'Assumptions & WACC'!$B$3) -> 115196.51 | G3: =Table9[[#This Row],[2029]]*(1+'Assumptions & WACC'!$B$3) -> 123683.44 | I3: Revenue | J3: =Table18[[#This Row],[2024]]*(1+'Assumptions & WACC'!$C$3) -> 72229.176 | K3: =Table915[[#This Row],[2025]]*(1+'Assumptions & WACC'!$C$3) -> 73435.156 | L3: =Table915[[#This Row],[2026]]*(1+'Assumptions & WACC'!$C$3) -> 74661.273 | M3: =Table915[[#This Row],[2027]]*(1+'Assumptions & WACC'!$C$3) -> 75907.861 | N3: =Table915[[#This Row],[2028]]*(1+'Assumptions & WACC'!$C$3) -> 77175.263 | O3: =Table915[[#This Row],[2029]]*(1+'Assumptions & WACC'!$C$3) -> 78463.826 | Q3: Revenue | R3: =Table119[[#This Row],[2024]]*(1+'Assumptions & WACC'!D3) -> 49958.768 | S3: =Table934[[#This Row],[2025]]*(1+'Assumptions & WACC'!$D$3) -> 52306.951 | T3: =Table934[[#This Row],[2026]]*(1+'Assumptions & WACC'!$D$3) -> 54765.505 | U3: =Table934[[#This Row],[2027]]*(1+'Assumptions & WACC'!$D$3) -> 57339.616 | V3: =Table934[[#This Row],[2028]]*(1+'Assumptions & WACC'!$D$3) -> 60034.717 | W3: =Table934[[#This Row],[2029]]*(1+'Assumptions & WACC'!$D$3) -> 62856.495 | Y3: Revenue | Z3: =Table1822[[#This Row],[2024]]*(1+'Assumptions & WACC'!E3) -> 22013.1 | AA3: =Table91536[[#This Row],[2025]]*(1+'Assumptions & WACC'!$E$3) -> 22723.403 | AB3: =Table91536[[#This Row],[2026]]*(1+'Assumptions & WACC'!$E$3) -> 23456.626 | AC3: =Table91536[[#This Row],[2027]]*(1+'Assumptions & WACC'!$E$3) -> 24213.508 | AD3: =Table91536[[#This Row],[2028]]*(1+'Assumptions & WACC'!$E$3) -> 24994.813 | AE3: =Table91536[[#This Row],[2029]]*(1+'Assumptions & WACC'!$E$3) -> 25801.328 | AG3: Revenue | AH3: =Table182225[[#This Row],[2024]]*(1+'Assumptions & WACC'!F3) -> 41936.552 | AI3: =Table93444[[#This Row],[2025]]*(1+'Assumptions & WACC'!$F$3) -> 42860 | AJ3: =Table93444[[#This Row],[2026]]*(1+'Assumptions & WACC'!$F$3) -> 43803.783 | AK3: =Table93444[[#This Row],[2027]]*(1+'Assumptions & WACC'!$F$3) -> 44768.348 | AL3: =Table93444[[#This Row],[2028]]*(1+'Assumptions & WACC'!$F$3) -> 45754.153 | AM3: =Table93444[[#This Row],[2029]]*(1+'Assumptions & WACC'!$F$3) -> 46761.666
A4: EBIT | B4: =B3*'Assumptions & WACC'!$B$4 -> 5232.1272 | C4: =C3*'Assumptions & WACC'!$B$4 -> 5617.5967 | D4: =D3*'Assumptions & WACC'!$B$4 -> 6031.4651 | E4: =E3*'Assumptions & WACC'!$B$4 -> 6475.8247 | F4: =F3*'Assumptions & WACC'!$B$4 -> 6952.9218 | G4: =G3*'Assumptions & WACC'!$B$4 -> 7465.1684 | I4: EBIT | J4: =J3*'Assumptions & WACC'!$C$4 -> 8922.5662 | K4: =K3*'Assumptions & WACC'!$C$4 -> 9071.5426 | L4: =L3*'Assumptions & WACC'!$C$4 -> 9223.0064 | M4: =M3*'Assumptions & WACC'!$C$4 -> 9376.9991 | N4: =N3*'Assumptions & WACC'!$C$4 -> 9533.563 | O4: =O3*'Assumptions & WACC'!$C$4 -> 9692.741 | Q4: EBIT | R4: =R3*'Assumptions & WACC'!$D$4 -> 5231.1422 | S4: =S3*'Assumptions & WACC'!$D$4 -> 5477.0186 | T4: =T3*'Assumptions & WACC'!$D$4 -> 5734.4518 | U4: =U3*'Assumptions & WACC'!$D$4 -> 6003.9849 | V4: =V3*'Assumptions & WACC'!$D$4 -> 6286.1868 | W4: =W3*'Assumptions & WACC'!$D$4 -> 6581.6528 | Y4: EBIT | Z4: =Z3*'Assumptions & WACC'!$E$4 -> 2282.6384 | AA4: =AA3*'Assumptions & WACC'!$E$4 -> 2356.293 | AB4: =AB3*'Assumptions & WACC'!$E$4 -> 2432.3242 | AC4: =AC3*'Assumptions & WACC'!$E$4 -> 2510.8087 | AD4: =AD3*'Assumptions & WACC'!$E$4 -> 2591.8257 | AE4: =AE3*'Assumptions & WACC'!$E$4 -> 2675.457 | AG4: EBIT | AH4: =AH3*'Assumptions & WACC'!$F$4 -> 6258.6746 | AI4: =AI3*'Assumptions & WACC'!$F$4 -> 6396.4915 | AJ4: =AJ3*'Assumptions & WACC'!$F$4 -> 6537.343 | AK4: =AK3*'Assumptions & WACC'!$F$4 -> 6681.2962 | AL4: =AL3*'Assumptions & WACC'!$F$4 -> 6828.4192 | AM4: =AM3*'Assumptions & WACC'!$F$4 -> 6978.7819
A5: NOPAT | B5: =B4*(1-'Assumptions & WACC'!$B$13) -> 4028.7379 | C5: =C4*(1-'Assumptions & WACC'!$B$13) -> 4325.5494 | D5: =D4*(1-'Assumptions & WACC'!$B$13) -> 4644.2281 | E5: =E4*(1-'Assumptions & WACC'!$B$13) -> 4986.385 | F5: =F4*(1-'Assumptions & WACC'!$B$13) -> 5353.7498 | G5: =G4*(1-'Assumptions & WACC'!$B$13) -> 5748.1797 | I5: NOPAT | J5: =J4*(1-'Assumptions & WACC'!$C$13) -> 6870.376 | K5: =K4*(1-'Assumptions & WACC'!$C$13) -> 6985.0878 | L5: =L4*(1-'Assumptions & WACC'!$C$13) -> 7101.7149 | M5: =M4*(1-'Assumptions & WACC'!$C$13) -> 7220.2893 | N5: =N4*(1-'Assumptions & WACC'!$C$13) -> 7340.8435 | O5: =O4*(1-'Assumptions & WACC'!$C$13) -> 7463.4105 | Q5: NOPAT | R5: =R4*(1-'Assumptions & WACC'!$B$13) -> 4027.9795 | S5: =S4*(1-'Assumptions & WACC'!$B$13) -> 4217.3043 | T5: =T4*(1-'Assumptions & WACC'!$B$13) -> 4415.5279 | U5: =U4*(1-'Assumptions & WACC'!$B$13) -> 4623.0684 | V5: =V4*(1-'Assumptions & WACC'!$B$13) -> 4840.3638 | W5: =W4*(1-'Assumptions & WACC'!$B$13) -> 5067.8727 | Y5: NOPAT | Z5: =Z4*(1-'Assumptions & WACC'!$C$13) -> 1757.6316 | AA5: =AA4*(1-'Assumptions & WACC'!$C$13) -> 1814.3456 | AB5: =AB4*(1-'Assumptions & WACC'!$C$13) -> 1872.8896 | AC5: =AC4*(1-'Assumptions & WACC'!$C$13) -> 1933.3227 | AD5: =AD4*(1-'Assumptions & WACC'!$C$13) -> 1995.7058 | AE5: =AE4*(1-'Assumptions & WACC'!$C$13) -> 2060.1019 | AG5: NOPAT | AH5: =AH4*(1-'Assumptions & WACC'!$B$13) -> 4819.1795 | AI5: =AI4*(1-'Assumptions & WACC'!$B$13) -> 4925.2984 | AJ5: =AJ4*(1-'Assumptions & WACC'!$B$13) -> 5033.7541 | AK5: =AK4*(1-'Assumptions & WACC'!$B$13) -> 5144.5981 | AL5: =AL4*(1-'Assumptions & WACC'!$B$13) -> 5257.8828 | AM5: =AM4*(1-'Assumptions & WACC'!$B$13) -> 5373.6621
A6: Depreciation | B6: =B3*'Assumptions & WACC'!$B$5 -> 5492.1549 | C6: =C3*'Assumptions & WACC'!$B$5 -> 5896.7816 | D6: =D3*'Assumptions & WACC'!$B$5 -> 6331.2185 | E6: =E3*'Assumptions & WACC'!$B$5 -> 6797.662 | F6: =F3*'Assumptions & WACC'!$B$5 -> 7298.4701 | G6: =G3*'Assumptions & WACC'!$B$5 -> 7836.1744 | I6: Depreciation | J6: =J3*'Assumptions & WACC'!$C$5 -> 1510.2035 | K6: =K3*'Assumptions & WACC'!$C$5 -> 1535.4188 | L6: =L3*'Assumptions & WACC'!$C$5 -> 1561.055 | M6: =M3*'Assumptions & WACC'!$C$5 -> 1587.1193 | N6: =N3*'Assumptions & WACC'!$C$5 -> 1613.6188 | O6: =O3*'Assumptions & WACC'!$C$5 -> 1640.5607 | Q6: Depreciation | R6: =R3*'Assumptions & WACC'!$D$5 -> 1068.4173 | S6: =S3*'Assumptions & WACC'!$D$5 -> 1118.6356 | T6: =T3*'Assumptions & WACC'!$D$5 -> 1171.2141 | U6: =U3*'Assumptions & WACC'!$D$5 -> 1226.264 | V6: =V3*'Assumptions & WACC'!$D$5 -> 1283.9014 | W6: =W3*'Assumptions & WACC'!$D$5 -> 1344.2479 | Y6: Depreciation | Z6: =Z3*'Assumptions & WACC'!$E$5 -> 1265.2124 | AA6: =AA3*'Assumptions & WACC'!$E$5 -> 1306.0374 | AB6: =AB3*'Assumptions & WACC'!$E$5 -> 1348.1797 | AC6: =AC3*'Assumptions & WACC'!$E$5 -> 1391.6818 | AD6: =AD3*'Assumptions & WACC'!$E$5 -> 1436.5876 | AE6: =AE3*'Assumptions & WACC'!$E$5 -> 1482.9424 | AG6: Depreciation | AH6: =AH3*'Assumptions & WACC'!$F$5 -> 1451.6848 | AI6: =AI3*'Assumptions & WACC'!$F$5 -> 1483.6511 | AJ6: =AJ3*'Assumptions & WACC'!$F$5 -> 1516.3213 | AK6: =AK3*'Assumptions & WACC'!$F$5 -> 1549.7109 | AL6: =AL3*'Assumptions & WACC'!$F$5 -> 1583.8357 | AM6: =AM3*'Assumptions & WACC'!$F$5 -> 1618.712
A7: Capex | B7: =B3*'Assumptions & WACC'!$B$6 -> 2889.5676 | C7: =C3*'Assumptions & WACC'!$B$6 -> 3102.4523 | D7: =D3*'Assumptions & WACC'!$B$6 -> 3331.0211 | E7: =E3*'Assumptions & WACC'!$B$6 -> 3576.4293 | F7: =F3*'Assumptions & WACC'!$B$6 -> 3839.9176 | G7: =G3*'Assumptions & WACC'!$B$6 -> 4122.8181 | I7: Capex | J7: =J3*'Assumptions & WACC'!$C$6 -> 1786.0134 | K7: =K3*'Assumptions & WACC'!$C$6 -> 1815.8337 | L7: =L3*'Assumptions & WACC'!$C$6 -> 1846.1519 | M7: =M3*'Assumptions & WACC'!$C$6 -> 1876.9764 | N7: =N3*'Assumptions & WACC'!$C$6 -> 1908.3155 | O7: =O3*'Assumptions & WACC'!$C$6 -> 1940.1778 | Q7: Capex | R7: =R3*'Assumptions & WACC'!$D$6 -> 1162.3682 | S7: =S3*'Assumptions & WACC'!$D$6 -> 1217.0023 | T7: =T3*'Assumptions & WACC'!$D$6 -> 1274.2043 | U7: =U3*'Assumptions & WACC'!$D$6 -> 1334.095 | V7: =V3*'Assumptions & WACC'!$D$6 -> 1396.8007 | W7: =W3*'Assumptions & WACC'!$D$6 -> 1462.4538 | Y7: Capex | Z7: =Z3*'Assumptions & WACC'!$E$6 -> 426.82147 | AA7: =AA3*'Assumptions & WACC'!$E$6 -> 440.59384 | AB7: =AB3*'Assumptions & WACC'!$E$6 -> 454.81062 | AC7: =AC3*'Assumptions & WACC'!$E$6 -> 469.48613 | AD7: =AD3*'Assumptions & WACC'!$E$6 -> 484.63518 | AE7: =AE3*'Assumptions & WACC'!$E$6 -> 500.27305 | AG7: Capex | AH7: =AH3*'Assumptions & WACC'!$F$6 -> 1729.7989 | AI7: =AI3*'Assumptions & WACC'!$F$6 -> 1767.8893 | AJ7: =AJ3*'Assumptions & WACC'!$F$6 -> 1806.8185 | AK7: =AK3*'Assumptions & WACC'!$F$6 -> 1846.6048 | AL7: =AL3*'Assumptions & WACC'!$F$6 -> 1887.2673 | AM7: =AM3*'Assumptions & WACC'!$F$6 -> 1928.8252
A8: Change in Working capital | B8: ='Assumptions & WACC'!I12-'Assumptions & WACC'!M9 -> 1113.2054 | C8: ='Assumptions & WACC'!J12-'Assumptions & WACC'!I12 -> 55.049294 | D8: ='Assumptions & WACC'!K12-'Assumptions & WACC'!J12 -> 59.104972 | E8: ='Assumptions & WACC'!L12-'Assumptions & WACC'!K12 -> 63.459446 | F8: ='Assumptions & WACC'!M12-'Assumptions & WACC'!L12 -> 68.13473 | G8: ='Assumptions & WACC'!N12-'Assumptions & WACC'!M12 -> 73.154459 | I8: Change in Working capital | J8: ='Assumptions & WACC'!I19-'Assumptions & WACC'!M16 -> 704.26239 | K8: ='Assumptions & WACC'!J19-'Assumptions & WACC'!I19 -> 52.314784 | L8: ='Assumptions & WACC'!K19-'Assumptions & WACC'!J19 -> 53.188262 | M8: ='Assumptions & WACC'!L19-'Assumptions & WACC'!K19 -> 54.076325 | N8: ='Assumptions & WACC'!M19-'Assumptions & WACC'!L19 -> 54.979215 | O8: ='Assumptions & WACC'!N19-'Assumptions & WACC'!M19 -> 55.89718 | Q8: Change in Working capital | R8: ='Assumptions & WACC'!Q12-'Assumptions & WACC'!U9 -> 977.12762 | S8: ='Assumptions & WACC'!R12-'Assumptions & WACC'!Q12 -> 354.35729 | T8: ='Assumptions & WACC'!S12-'Assumptions & WACC'!R12 -> 371.01294 | U8: ='Assumptions & WACC'!T12-'Assumptions & WACC'!S12 -> 388.45145 | V8: ='Assumptions & WACC'!U12-'Assumptions & WACC'!T12 -> 406.70961 | W8: ='Assumptions & WACC'!V12-'Assumptions & WACC'!U12 -> 425.82595 | Y8: Change in Working capital | Z8: ='Assumptions & WACC'!Q19-'Assumptions & WACC'!U16 -> 787.44572 | AA8: ='Assumptions & WACC'!R19-'Assumptions & WACC'!Q19 -> 44.285117 | AB8: ='Assumptions & WACC'!S19-'Assumptions & WACC'!R19 -> 45.714078 | AC8: ='Assumptions & WACC'!T19-'Assumptions & WACC'!S19 -> 47.189148 | AD8: ='Assumptions & WACC'!U19-'Assumptions & WACC'!T19 -> 48.711815 | AE8: ='Assumptions & WACC'!V19-'Assumptions & WACC'!U19 -> 50.283613 | AG8: Change in Working capital | AH8: ='Assumptions & WACC'!I27-'Assumptions & WACC'!M24 -> 2394.0055 | AI8: ='Assumptions & WACC'!J27-'Assumptions & WACC'!I27 -> 55.931257 | AJ8: ='Assumptions & WACC'!K27-'Assumptions & WACC'!J27 -> 57.16287 | AK8: ='Assumptions & WACC'!L27-'Assumptions & WACC'!K27 -> 58.421604 | AL8: ='Assumptions & WACC'!M27-'Assumptions & WACC'!L27 -> 59.708056 | AM8: ='Assumptions & WACC'!N27-'Assumptions & WACC'!M27 -> 61.022835
A9: FCFF | B9: =B5+B6-B7-B8 -> 5518.1198 | C9: =C5+C6-C7-C8 -> 7064.8294 | D9: =D5+D6-D7-D8 -> 7585.3206 | E9: =E5+E6-E7-E8 -> 8144.1583 | F9: =F5+F6-F7-F8 -> 8744.1675 | G9: =G5+G6-G7-G8 -> 9388.3816 | I9: FCFF | J9: =J5+J6-J7-J8 -> 5890.3038 | K9: =K5+K6-K7-K8 -> 6652.3581 | L9: =L5+L6-L7-L8 -> 6763.4298 | M9: =M5+M6-M7-M8 -> 6876.356 | N9: =N5+N6-N7-N8 -> 6991.1676 | O9: =O5+O6-O7-O8 -> 7107.8963 | Q9: FCFF | R9: =R5+R6-R7-R8 -> 2956.9011 | S9: =S5+S6-S7-S8 -> 3764.5803 | T9: =T5+T6-T7-T8 -> 3941.5247 | U9: =U5+U6-U7-U8 -> 4126.7859 | V9: =V5+V6-V7-V8 -> 4320.7549 | W9: =W5+W6-W7-W8 -> 4523.8409 | Y9: FCFF | Z9: =Z5+Z6-Z7-Z8 -> 1808.5768 | AA9: =AA5+AA6-AA7-AA8 -> 2635.504 | AB9: =AB5+AB6-AB7-AB8 -> 2720.5446 | AC9: =AC5+AC6-AC7-AC8 -> 2808.3292 | AD9: =AD5+AD6-AD7-AD8 -> 2898.9464 | AE9: =AE5+AE6-AE7-AE8 -> 2992.4876 | AG9: FCFF | AH9: =AH5+AH6-AH7-AH8 -> 2147.0598 | AI9: =AI5+AI6-AI7-AI8 -> 4585.1289 | AJ9: =AJ5+AJ6-AJ7-AJ8 -> 4686.0941 | AK9: =AK5+AK6-AK7-AK8 -> 4789.2825 | AL9: =AL5+AL6-AL7-AL8 -> 4894.7431 | AM9: =AM5+AM6-AM7-AM8 -> 5002.526
A12: Metrics | B12: Value | I12: Metrics | J12: Value | Q12: Metrics | R12: Value | Y12: Metrics | Z12: Value | AG12: Metrics | AH12: Value
A13: Terminal Value | B13: =G9*(1+'Assumptions & WACC'!B21)/('Assumptions & WACC'!B20-'Assumptions & WACC'!B21) -> 387834.45 | I13: Terminal Value | J13: =O9*(1+'Assumptions & WACC'!C21)/('Assumptions & WACC'!C20-'Assumptions & WACC'!C21) -> 386050.28 | Q13: Terminal Value | R13: =W9*(1+'Assumptions & WACC'!D21)/('Assumptions & WACC'!D20-'Assumptions & WACC'!D21) -> 184870.96 | Y13: Terminal Value | Z13: =AE9*(1+'Assumptions & WACC'!E21)/('Assumptions & WACC'!E20-'Assumptions & WACC'!E21) -> 97950.593 | AG13: Terminal Value | AH13: =AM9*(1+'Assumptions & WACC'!F21)/('Assumptions & WACC'!F20-'Assumptions & WACC'!F21) -> 440361.32
A14: PV of Terminal value | B14: =B13/(1+'Assumptions & WACC'!B20)^6 -> 281381.87 | I14: PV of Terminal value | J14: =J13/(1+'Assumptions & WACC'!C20)^6 -> 289787.66 | Q14: PV of Terminal value | R14: =R13*'Assumptions & WACC'!D23 -> 133921.17 | Y14: PV of Terminal value | Z14: =Z13*'Assumptions & WACC'!E23 -> 68480.482 | AG14: PV of Terminal value | AH14: =AH13*'Assumptions & WACC'!F23 -> 344628.4
A15: PV of FCFF | B15: =NPV('Assumptions & WACC'!B20,DCF!B9:G9) -> 38119.776 | I15: PV of FCFF | J15: =NPV('Assumptions & WACC'!C20,DCF!J9:O9) -> 34040.948 | Q15: PV of FCFF | R15: =NPV('Assumptions & WACC'!D20,DCF!R9:W9) -> 19446.374 | Y15: PV of FCFF | Z15: =NPV('Assumptions & WACC'!E20,DCF!Z9:AE9) -> 12773.373 | AG15: PV of FCFF | AH15: =NPV('Assumptions & WACC'!F20,DCF!AH9:AM9) -> 22404.642
A16: Total enterprise value | B16: =B14+B15 -> 319501.65 | I16: Total enterprise value | J16: =J14+J15 -> 323828.61 | Q16: Total enterprise value | R16: =R14+R15 -> 153367.54 | Y16: Total enterprise value | Z16: =Z14+Z15 -> 81253.855 | AG16: Total enterprise value | AH16: =AH14+AH15 -> 367033.04
A17: Net debt | B17: ='Assumptions & WACC'!B15-Financials!F15 -> 35683 | I17: Net debt | J17: ='Assumptions & WACC'!C15-Financials!M15 -> 17787 | Q17: Net debt | R17: ='Assumptions & WACC'!D15-'Assumptions & WACC'!D24 -> 7065 | Y17: Net debt | Z17: ='Assumptions & WACC'!E15-'Assumptions & WACC'!E24 -> 11621 | AG17: Net debt | AH17: ='Assumptions & WACC'!F15-'Assumptions & WACC'!F24 -> 10339
A18: Total equity value | B18: =B16-B17 -> 283818.65 | I18: Total equity value | J18: =J16-J17 -> 306041.61 | Q18: Total equity value | R18: =R16-R17 -> 146302.54 | Y18: Total equity value | Z18: =Z16-Z17 -> 69632.855 | AG18: Total equity value | AH18: =AH16-AH17 -> 356694.04
A19: Outstanding shares | B19: ='Assumptions & WACC'!B22 -> 1340.772 | I19: Outstanding shares | J19: ='Assumptions & WACC'!C22 -> 231.3978 | Q19: Outstanding shares | R19: ='Assumptions & WACC'!D22 -> 270.1205 | Y19: Outstanding shares | Z19: ='Assumptions & WACC'!E22 -> 187.0529 | AG19: Outstanding shares | AH19: ='Assumptions & WACC'!F22 -> 142.7201
A20: Intrinsic value | B20: =B18/B19 -> 211.68301 | I20: Intrinsic value | J20: =J18/J19 -> 1322.5779 | Q20: Intrinsic value | R20: =R18/R19 -> 541.61954 | Y20: Intrinsic value | Z20: =Z18/Z19 -> 372.2629 | AG20: Intrinsic value | AH20: =AH18/AH19 -> 2499.2558
A21: Current market price | B21: ='Company Profile'!B3 -> 173 | I21: Current market price | J21: ='Company Profile'!C3 -> 470.64 | Q21: Current market price | R21: ='Company Profile'!D3 -> 341.985 | Y21: Current market price | Z21: ='Company Profile'!E3 -> 285.2101 | AG21: Current market price | AH21: ='Company Profile'!F3 -> 566.12
A22: Upside/Downside | B22: =(B20-B21)/B21 -> 0.22360121 | I22: Upside/Downside | J22: =(J20-J21)/J21 -> 1.8101688 | Q22: Upside/Downside | R22: =(R20-R21)/R21 -> 0.58375232 | Y22: Upside/Downside | Z22: =(Z20-Z21)/Z21 -> 0.30522341 | AG22: Upside/Downside | AH22: =(AH20-AH21)/AH21 -> 3.4147103

Sheet Relative
A1: Relative Valuation
A2: Company | B2: EV/EBITDA | C2: P/E | D2: P/S | E2: P/B | H2: Company | I2: EV/EBITDA | J2: P/E | K2: P/S | L2: Book Value | M2: Shares
A3: #VALUE! | B3: 12.5 | C3: {=_FV(A3,"P/E",TRUE)} -> 26.217 | D3: 1.64 | E3: 15.79 | H3: =A23 -> RTX | I3: =(B23*$B$20)/$M$3 -> 200.57561 | J3: =(C23*$B$20)/$M$3 -> 65.931462 | K3: =(D23*$B$20)/$M$3 -> 1467.6521 | L3: =(E23*$B$20)/$M$3 -> 1125.6338 | M3: ='Assumptions & WACC'!B22 -> 1340.772
A4: #VALUE! | B4: 20.19 | C4: {=_FV(A4,"P/E",TRUE)} -> 37.97 | D4: 9.66 | E4: 8.96 | H4: =A24 -> LMC | I4: =(B24*$B$20)/$M$4 -> 902.86541 | J4: =(C24*$B$20)/$M$4 -> 536.43182 | K4: =(D24*$B$20)/$M$4 -> 7482.7657 | L4: =(E24*$B$20)/$M$4 -> 667.03764 | M4: ='Assumptions & WACC'!C22 -> 231.3978
A5: #VALUE! | B5: 31.84 | C5: {=_FV(A5,"P/E",TRUE)} -> 54.03 | D5: 10.11 | E5: 12.13 | H5: =A25 -> GD | I5: =(B25*$B$20)/$M$5 -> 512.67692 | J5: =(C25*$B$20)/$M$5 -> 335.10772 | K5: =(D25*$B$20)/$M$5 -> 4305.3312 | L5: =(E25*$B$20)/$M$5 -> 1990.7059 | M5: ='Assumptions & WACC'!D22 -> 270.1205
A6: #VALUE! | B6: 15.66 | C6: {=_FV(A6,"P/E",TRUE)} -> 35.7699 | D6: 1.97 | E6: 2.52 | H6: =A26 -> L3H | I6: =(B26*$B$20)/$M$6 -> 463.98892 | J6: =(C26*$B$20)/$M$6 -> 197.00962 | K6: =(D26*$B$20)/$M$6 -> 2778.5913 | L6: =(E26*$B$20)/$M$6 -> 2551.0921 | M6: ='Assumptions & WACC'!E22 -> 187.0529
A7: #VALUE! | B7: 111.56 | C7: 69.93 | D7: 1.48 | E7: =176.55/(Financials!M22/'Assumptions & WACC'!C22) -> 6.4508577 | H7: =A27 -> NG | I7: =(B27*$B$20)/$M$7 -> 1196.5946 | J7: =(C27*$B$20)/$M$7 -> 712.79949 | K7: =(D27*$B$20)/$M$7 -> 7007.2596 | L7: =(E27*$B$20)/$M$7 -> 2611.0935 | M7: ='Assumptions & WACC'!F22 -> 142.7201
A8: #VALUE! | B8: 14.17 | C8: 16.5 | D8: 1.58 | E8: 3.1
A9: #VALUE! | B9: 17.73 | C9: 20.45 | D9: 3.92 | E9: 8.17 | H9: Company | I9: Target Price | J9: CMP | K9: U/D
A10: #VALUE! | B10: 16 | C10: 29.15 | D10: 4.26 | E10: 9.58 | H10: =H3 -> RTX | I10: =AVERAGE(I3:L3) -> 714.94826 | J10: ='Company Profile'!B3 -> 173 | K10: =(I10-J10)/J10 -> 3.1326489
A11: #VALUE! | B11: 17.45 | C11: 16.84 | D11: 1.7 | E11: 4.61 | H11: =H4 -> LMC | I11: =AVERAGE(I4:L4) -> 2397.2751 | J11: ='Company Profile'!C3 -> 470.64 | K11: =(I11-J11)/J11 -> 4.0936494
A12: #VALUE! | B12: 16.46 | C12: 23.75 | D12: 2.28 | E12: 5.54 | H12: =H5 -> GD | I12: =AVERAGE(I5:L5) -> 1785.9554 | J12: ='Company Profile'!D3 -> 341.985 | K12: =(I12-J12)/J12 -> 4.2223209
A13: #VALUE! | B13: 18.01 | C13: 19.76 | D13: 3.22 | E13: 7.96 | H13: =H6 -> L3H | I13: =AVERAGE(I6:L6) -> 1497.6705 | J13: ='Company Profile'!E3 -> 285.2101 | K13: =(I13-J13)/J13 -> 4.2511131
A14: #VALUE! | B14: 21.37 | C14: 22.68 | D14: 2.65 | E14: 7.91 | H14: =H7 -> NG | I14: =AVERAGE(I7:L7) -> 2881.9368 | J14: ='Company Profile'!F3 -> 566.12 | K14: =(I14-J14)/J14 -> 4.0906819
A15: #VALUE! | B15: 16.41 | C15: 14.66 | D15: 1.9 | E15: 2.1
A16: #VALUE! | B16: 21.97 | C16: 22.62 | D16: 2.15 | E16: 3.55
A17: #VALUE! | B17: 28.09 | C17: 40.16 | D17: 4.58 | E17: 12.47
A18: #VALUE! | B18: 10.55 | C18: 17.18 | D18: 3.44 | E18: 3.63
A20: Average | B20: =AVERAGE(B3:B18) -> 24.3725 | C20: =AVERAGE(C3:C18) -> 29.229181 | D20: =AVERAGE(D3:D18) -> 3.53375 | E20: =AVERAGE(E3:E18) -> 7.1544286
A22: Company | B22: EBITDA | C22: Net Income | D22: Revenue | E22: Book Value
A23: RTX | B23: =Financials!F7+Financials!F28 -> 11034 | C23: =Financials!F10 -> 3627 | D23: =Financials!F3 -> 80738 | E23: =Financials!F22 -> 61923
A24: LMC | B24: =Financials!M7+Financials!M29 -> 8572 | C24: =Financials!M10 -> 5093 | D24: =Financials!M3 -> 71043 | E24: =Financials!M22 -> 6333
A25: GD | B25: =Financials!T7+Financials!T29 -> 5682 | C25: =Financials!T10 -> 3714 | D25: =Financials!T3 -> 47716 | E25: =Financials!T22 -> 22063
A26: L3H | B26: =Financials!AB7+Financials!AB29 -> 3561 | C26: =Financials!AB10 -> 1512 | D26: =Financials!AB3 -> 21325 | E26: =Financials!AB22 -> 19579
A27: NG | B27: =Financials!AJ7+Financials!AJ29 -> 7007 | C27: =Financials!AJ10 -> 4174 | D27: =Financials!AJ3 -> 41033 | E27: =Financials!AJ22 -> 15290

Sheet Calc
A1: Year | B1: Particulars | C1: Company | D1: Value | F1: Company | G1: Change in EBIT (historical) | H1: Change in CE | I1: Incremental ROCE (Historical) | J1: Change in EBIT (Forecast) | K1: Capex | L1: Depreciation | M1: Effective capital | N1: Raw ROCE | O1: Adjusted ROCE (Forecast) | Q1: Particulars | R1: 2020 | S1: 2021 | T1: 2022 | U1: 2023 | V1: 2024
A2: 2020-24 | B2: Avg Capex | C2: =Relative!A23 -> RTX | D2: =AVERAGE(Financials!B27:F27) -> 2251.4 | F2: =C2 -> RTX | G2: =Financials!F7-Financials!B7 -> 6261 | H2: =(162860-51499)-(162150-35848) -> -14941 | I2: =G2/H2 -> -0.41904826 | J2: =DCF!G4-DCF!B4 -> 2233.0412 | K2: =D2 -> 2251.4 | L2: =AVERAGE(DCF!B6:G6) -> 6608.7436 | M2: =IF(K2-L2<=0,K2,MAX(K2-L2,0.1*K2)) -> 2251.4 | N2: =J2/M2 -> 0.99184562 | O2: =MIN(MAX(N2,0.05),0.15) -> 0.15 | Q2: Revenue | R2: {=Financials!B3:F3} -> 56587 | S2: 64388 | T2: 67074 | U2: 68920 | V2: 80738
A3: 2020-24 | B3: Avg Capex | C3: =Relative!A24 -> LMC | D3: =AVERAGE(Financials!I28:M28) -> 1666.8 | F3: =C3 -> LMC | G3: =Financials!M7-Financials!I7 -> -1631 | H3: =(55617-19420)-(50710-13933) -> -580 | I3: =G3/H3 -> 2.812069 | J3: =DCF!O4-DCF!J4 -> 770.17472 | K3: =D3 -> 1666.8 | L3: =AVERAGE(DCF!J6:O6) -> 1574.6627 | M3: =IF(K3-L3<=0,K3,MAX(K3-L3,0.1*K3)) -> 166.68 | N3: =J3/M3 -> 4.6206787 | O3: =MIN(MAX(N3,0.05),0.15) -> 0.15 | Q3: Operating income | R3: {=Financials!B7:F7} -> 409 | S3: 4535 | T3: 5294 | U3: 3475 | V3: 6670
A4: 2020-24 | B4: Avg Capex | C4: =Relative!A25 -> GD | D4: =AVERAGE(Financials!P28:T28) -> 957.6 | F4: =C4 -> GD | G4: =Financials!T7-Financials!P7 -> 663 | H4: =((Financials!T23-Financials!T16)-(Financials!P23-Financials!P16)) -> 2712 | I4: =G4/H4 -> 0.24446903 | J4: =Table934[[#This Row],[2030]]-Table934[[#This Row],[2025]] -> 1350.5106 | K4: =D4 -> 957.6 | L4: =AVERAGE(DCF!R6:W6) -> 1202.1134 | M4: =IF(K4-L4<=0,K4,MAX(K4-L4,0.1*K4)) -> 957.6 | N4: =J4/M4 -> 1.4103076 | O4: =MIN(MAX(N4,0.05),0.15) -> 0.15 | Q4: Net Income | R4: {=Financials!B10:F10} -> -1532 | S4: 2427 | T4: 3228 | U4: 1514 | V4: 3627
A5: 2020-24 | B5: Avg Capex | C5: =Relative!A26 -> L3H | D5: =AVERAGE(Financials!X28:AB28) -> 363.8 | F5: =C5 -> L3H | G5: =Financials!AB7-Financials!X7 -> 680 | H5: =((Financials!AB23-Financials!AB16)-(Financials!X23-Financials!X16)) -> 1648 | I5: =G5/H5 -> 0.41262136 | J5: =DCF!AE4-DCF!Z4 -> 392.81856 | K5: =D5 -> 363.8 | L5: =AVERAGE(DCF!Z6:AE6) -> 1371.7736 | M5: =IF(K5-L5<=0,K5,MAX(K5-L5,0.1*K5)) -> 363.8 | N5: =J5/M5 -> 1.0797651 | O5: =MIN(MAX(N5,0.05),0.15) -> 0.15 | Q5: Capex | R5: {=Financials!B27:F27} -> 1795 | S5: 2134 | T5: 2288 | U5: 2415 | V5: 2625 | Y5: Particulars | Z5: 2020 | AA5: 2021 | AB5: 2022 | AC5: 2023 | AD5: 2024 | AG5: Particulars | AH5: 2025 | AI5: 2026 | AJ5: 2027 | AK5: 2028 | AL5: 2029 | AM5: 2030
A6: 2020-24 | B6: Avg Capex | C6: =Relative!A27 -> NG | D6: =AVERAGE(Financials!AF28:AJ28) -> 1562.4 | F6: =C6 -> NG | G6: =Financials!AJ7-Financials!AF7 -> 1736 | H6: =((Financials!AJ23-Financials!AJ16)-(Financials!AF23-Financials!AF16)) -> 342 | I6: =G6/H6 -> 5.0760234 | J6: =DCF!AM4-DCF!AH4 -> 720.10729 | K6: =D6 -> 1562.4 | L6: =AVERAGE(Table93444[[#This Row],[2025]:[2030]]) -> 1533.986 | M6: =IF(K6-L6<=0,K6,MAX(K6-L6,0.1*K6)) -> 156.24 | N6: =J6/M6 -> 4.6089817 | O6: =MIN(MAX(N6,0.05),0.15) -> 0.15 | Y6: Revenue | Z6: {=Financials!P3:T3} -> 37925 | AA6: 38469 | AB6: 39407 | AC6: 42272 | AD6: 47716 | AG6: Revenue | AH6: {=DCF!R3:W3} -> 49958.768 | AI6: 52306.951 | AJ6: 54765.505 | AK6: 57339.616 | AL6: 60034.717 | AM6: 62856.495
B7: Avg Capex | C7: Avg | D7: =AVERAGE(D2:D6) -> 1360.4 | F7: Average | I7: =AVERAGE(I2:I6) -> 1.6252269 | N7: =AVERAGE(N2:N6) -> 2.5423157 | O7: =AVERAGE(O2:O6) -> 0.15 | Q7: Particulars | R7: 2020 | S7: 2021 | T7: 2022 | U7: 2023 | V7: 2024 | Y7: Operating income | Z7: {=Table119[[#This Row],[2020]:[2024]]} -> 4133 | AA7: 4163 | AB7: 4211 | AC7: 4245 | AD7: 4796 | AG7: Operating income | AH7: {=DCF!R4:W4} -> 5231.1422 | AI7: 5477.0186 | AJ7: 5734.4518 | AK7: 6003.9849 | AL7: 6286.1868 | AM7: 6581.6528
A8: 2025-30 | B8: Avg Capex | C8: =C2 -> RTX | D8: =AVERAGE(DCF!B7:G7) -> 3477.0343 | Q8: Revenue | R8: {=Financials!I3:M3} -> 65398 | S8: 67044 | T8: 65984 | U8: 67571 | V8: 71043 | Y8: Net Income | Z8: {=Financials!P10:T10} -> 3085 | AA8: 3123 | AB8: 3201 | AC8: 3233 | AD8: 3714 | AG8: Net income | AH8: {=DCF!R5:W5} -> 4027.9795 | AI8: 4217.3043 | AJ8: 4415.5279 | AK8: 4623.0684 | AL8: 4840.3638 | AM8: 5067.8727
A9: 2025-30 | B9: Avg Capex | C9: =C3 -> LMC | D9: =AVERAGE(DCF!J7:O7) -> 1862.2448 | Q9: Operating income | R9: {=Financials!I7:M7} -> 8644 | S9: 9123 | T9: 8348 | U9: 8507 | V9: 7013 | Y9: Capex | Z9: {=Financials!P28:T28} -> 967 | AA9: 887 | AB9: 1114 | AC9: 904 | AD9: 916 | AG9: Capex | AH9: {=DCF!R7:W7} -> 1162.3682 | AI9: 1217.0023 | AJ9: 1274.2043 | AK9: 1334.095 | AL9: 1396.8007 | AM9: 1462.4538
A10: 2025-30 | B10: Avg Capex | C10: =C4 -> GD | D10: =AVERAGE(DCF!R7:W7) -> 1307.8207 | Q10: Net Income | R10: {=Financials!I10:M10} -> 6706 | S10: 7319 | T10: 6777 | U10: 6413 | V10: 5093 | AG10: FCFF | AH10: {=DCF!R9:W9} -> 2956.9011 | AI10: 3764.5803 | AJ10: 3941.5247 | AK10: 4126.7859 | AL10: 4320.7549 | AM10: 4523.8409
A11: 2025-30 | B11: Avg Capex | C11: =C5 -> L3H | D11: =AVERAGE(DCF!Z7:AE7) -> 462.77005 | Q11: Capex | R11: {=Financials!I28:M28} -> 1766 | S11: 1522 | T11: 1670 | U11: 1691 | V11: 1685 | Y11: Particulars | Z11: 2020 | AA11: 2021 | AB11: 2022 | AC11: 2023 | AD11: 2024
A12: 2025-30 | B12: Avg Capex | C12: =C6 -> NG | D12: =AVERAGE(DCF!AH7:AM7) -> 1827.8673 | G12: Metric | H12: 2020-24 | I12: 2025-30 | Y12: Revenue | Z12: {=Financials!X3:AB3} -> 18194 | AA12: 17814 | AB12: 17062 | AC12: 19419 | AD12: 21325 | AG12: Particulars | AH12: 2025 | AI12: 2026 | AJ12: 2027 | AK12: 2028 | AL12: 2029 | AM12: 2030
B13: Avg Capex | C13: =C7 -> Avg | D13: =AVERAGE(D8:D12) -> 1787.5474 | G13: GDP | H13: =AVERAGE(-0.035,0.058) -> 0.0115 | I13: 0.02 | Q13: Particulars | R13: 2025 | S13: 2026 | T13: 2027 | U13: 2028 | V13: 2029 | W13: 2030 | Y13: Operating income | Z13: {=Financials!X7:AB7} -> 1592 | AA13: 2548 | AB13: 1552 | AC13: 1764 | AD13: 2272 | AG13: Revenue | AH13: {=DCF!Z3:AE3} -> 22013.1 | AI13: 22723.403 | AJ13: 23456.626 | AK13: 24213.508 | AL13: 24994.813 | AM13: 25801.328
A14: 2025-30 | B14: Capex CAGR | C14: =C8 -> RTX | D14: =(DCF!G7/DCF!B7)^(1/6)-1 -> 0.061028101 | G14: GDP | H14: 0.028 | I14: 0.028 | Q14: Revenue | R14: {=DCF!B3:G3} -> 86686.257 | S14: 93072.743 | T14: 99929.745 | U14: 107291.93 | V14: 115196.51 | W14: 123683.44 | Y14: Net Income | Z14: {=Financials!X10:AB10} -> 1088 | AA14: 1843 | AB14: 1061 | AC14: 1198 | AD14: 1512 | AG14: Operating income | AH14: {=DCF!Z4:AE4} -> 2282.6384 | AI14: 2356.293 | AJ14: 2432.3242 | AK14: 2510.8087 | AL14: 2591.8257 | AM14: 2675.457
A15: 2025-30 | B15: Capex CAGR | C15: =C9 -> LMC | D15: =(DCF!O7/DCF!J7)^(1/6)-1 -> 0.013894587 | G15: Change | H15: =H14-H13 -> 0.0165 | I15: =I14-I13 -> 0.008 | Q15: Operating income | R15: {=DCF!B4:G4} -> 5232.1272 | S15: 5617.5967 | T15: 6031.4651 | U15: 6475.8247 | V15: 6952.9218 | W15: 7465.1684 | Y15: Capex | Z15: {=Financials!X28:AB28} -> 368 | AA15: 342 | AB15: 252 | AC15: 449 | AD15: 408 | AG15: Net income | AH15: {=DCF!Z5:AE5} -> 1757.6316 | AI15: 1814.3456 | AJ15: 1872.8896 | AK15: 1933.3227 | AL15: 1995.7058 | AM15: 2060.1019
A16: 2025-30 | B16: Capex CAGR | C16: =C10 -> GD | D16: =(DCF!W7/DCF!R7)^(1/6)-1 -> 0.039018005 | G16: Sensitivity | H16: =D61/H15 -> 51.24802 | I16: =D67/I15 -> 26.460659 | Q16: Net income | R16: {=DCF!B5:G5} -> 4028.7379 | S16: 4325.5494 | T16: 4644.2281 | U16: 4986.385 | V16: 5353.7498 | W16: 5748.1797 | AG16: Capex | AH16: {=DCF!Z7:AE7} -> 426.82147 | AI16: 440.59384 | AJ16: 454.81062 | AK16: 469.48613 | AL16: 484.63518 | AM16: 500.27305
A17: 2025-30 | B17: Capex CAGR | C17: =C11 -> L3H | D17: =(DCF!AE7/DCF!Z7)^(1/6)-1 -> 0.026818004 | Q17: Capex | R17: {=DCF!B7:G7} -> 2889.5676 | S17: 3102.4523 | T17: 3331.0211 | U17: 3576.4293 | V17: 3839.9176 | W17: 4122.8181 | Y17: Particulars | Z17: 2020 | AA17: 2021 | AB17: 2022 | AC17: 2023 | AD17: 2024 | AG17: FCFF | AH17: {=DCF!Z9:AE9} -> 1808.5768 | AI17: 2635.504 | AJ17: 2720.5446 | AK17: 2808.3292 | AL17: 2898.9464 | AM17: 2992.4876
A18: 2025-30 | B18: Capex CAGR | C18: =C12 -> NG | D18: =(DCF!AM7/DCF!AH7)^(1/6)-1 -> 0.018316722 | Q18: FCFF | R18: {=DCF!B9:G9} -> 5518.1198 | S18: 7064.8294 | T18: 7585.3206 | U18: 8144.1583 | V18: 8744.1675 | W18: 9388.3816 | Y18: Revenue | Z18: {=Financials!AF3:AJ3} -> 36799 | AA18: 35667 | AB18: 36602 | AC18: 39290 | AD18: 41033
A19: 2025-30 | B19: Capex CAGR | C19: =C13 -> Avg | D19: =AVERAGE(D14:D18) -> 0.031815084 | Y19: Operating income | Z19: {=Financials!AF7:AJ7} -> 3901 | AA19: 9494 | AB19: 6342 | AC19: 2891 | AD19: 5637 | AG19: Particulars | AH19: 2025 | AI19: 2026 | AJ19: 2027 | AK19: 2028 | AL19: 2029 | AM19: 2030
A20: =A14 -> 2025-30 | B20: Earnings CAGR | C20: =C14 -> RTX | D20: =(DCF!G5/DCF!B5)^(1/6)-1 -> 0.061028101 | Q20: Particulars | R20: 2025 | S20: 2026 | T20: 2027 | U20: 2028 | V20: 2029 | W20: 2030 | Y20: Net Income | Z20: {=Financials!AF10:AJ10} -> 2769 | AA20: 7005 | AB20: 4896 | AC20: 2056 | AD20: 4174 | AG20: Revenue | AH20: {=DCF!AH3:AM3} -> 41936.552 | AI20: 42860 | AJ20: 43803.783 | AK20: 44768.348 | AL20: 45754.153 | AM20: 46761.666
A21: =A15 -> 2025-30 | B21: Earnings CAGR | C21: =C15 -> LMC | D21: =D15 -> 0.013894587 | Q21: Revenue | R21: {=DCF!J3:O3} -> 72229.176 | S21: 73435.156 | T21: 74661.273 | U21: 75907.861 | V21: 77175.263 | W21: 78463.826 | Y21: Capex | Z21: {=Financials!AF28:AJ28} -> 1420 | AA21: 1415 | AB21: 1435 | AC21: 1775 | AD21: 1767 | AG21: Operating income | AH21: {=DCF!AH4:AM4} -> 6258.6746 | AI21: 6396.4915 | AJ21: 6537.343 | AK21: 6681.2962 | AL21: 6828.4192 | AM21: 6978.7819
A22: =A16 -> 2025-30 | B22: Earnings CAGR | C22: =C16 -> GD | D22: =D16 -> 0.039018005 | Q22: Operating income | R22: {=DCF!J4:O4} -> 8922.5662 | S22: 9071.5426 | T22: 9223.0064 | U22: 9376.9991 | V22: 9533.563 | W22: 9692.741 | AG22: Net income | AH22: {=DCF!AH5:AM5} -> 4819.1795 | AI22: 4925.2984 | AJ22: 5033.7541 | AK22: 5144.5981 | AL22: 5257.8828 | AM22: 5373.6621
A23: =A17 -> 2025-30 | B23: Earnings CAGR | C23: =C17 -> L3H | D23: =D17 -> 0.026818004 | Q23: Net income | R23: {=DCF!J5:O5} -> 6870.376 | S23: 6985.0878 | T23: 7101.7149 | U23: 7220.2893 | V23: 7340.8435 | W23: 7463.4105 | AG23: Capex | AH23: {=DCF!AH7:AM7} -> 1729.7989 | AI23: 1767.8893 | AJ23: 1806.8185 | AK23: 1846.6048 | AL23: 1887.2673 | AM23: 1928.8252
A24: =A18 -> 2025-30 | B24: Earnings CAGR | C24: =C18 -> NG | D24: =D18 -> 0.018316722 | Q24: Capex | R24: {=DCF!J7:O7} -> 1786.0134 | S24: 1815.8337 | T24: 1846.1519 | U24: 1876.9764 | V24: 1908.3155 | W24: 1940.1778 | Y24: Company | Z24: WACC | AA24: Terminal growth | AB24: Cost of equity | AC24: Intrinsic Value | AD24: Share price | AE24: Upside/Downside | AG24: FCFF | AH24: {=DCF!AH9:AM9} -> 2147.0598 | AI24: 4585.1289 | AJ24: 4686.0941 | AK24: 4789.2825 | AL24: 4894.7431 | AM24: 5002.526
