Workbook

Sheet Company Profile
A1: Company | B1: #VALUE! | C1: #VALUE! | D1: #VALUE! | E1: #VALUE! | F1: #VALUE!
A2: Name | B2: {=_FV(B1,"Official name",TRUE)} -> EXXON MOBIL CORPORATION | C2: {=_FV(C1,"Official name",TRUE)} -> CHEVRON CORPORATION | D2: {=_FV(D1,"Official name",TRUE)} -> CONOCOPHILLIPS | E2: {=_FV(E1,"Official name",TRUE)} -> MARATHON PETROLEUM CORPORATION | F2: {=_FV(F1,"Official name",TRUE)} -> PHILLIPS 66
A3: Share price | B3: {=_FV(B1,"Price")} -> 119.03 | C3: {=_FV(C1,"Price")} -> 153.59 | D3: {=_FV(D1,"Price")} -> 89.66 | E3: {=_FV(E1,"Price")} -> 199.61 | F3: {=_FV(F1,"Price")} -> 138.41
A4: Change (%) | B4: {=_FV(B1,"Change (%)",TRUE)} -> 0.011472 | C4: {=_FV(C1,"Change (%)",TRUE)} -> 0.003135 | D4: {=_FV(D1,"Change (%)",TRUE)} -> 0.010595 | E4: {=_FV(E1,"Change (%)",TRUE)} -> 0.018574 | F4: {=_FV(F1,"Change (%)",TRUE)} -> 0.01288
A5: Shares outstanding | B5: {=_FV(B1,"Shares outstanding",TRUE)} -> 4217166000 | C5: {=_FV(C1,"Shares outstanding",TRUE)} -> 2013522000 | D5: {=_FV(D1,"Shares outstanding",TRUE)} -> 1235718000 | E5: {=_FV(E1,"Shares outstanding",TRUE)} -> 300602500 | F5: {=_FV(F1,"Shares outstanding",TRUE)} -> 402921100
A6: in mn | B6: =B5/1000000 -> 4217.166 | C6: =C5/1000000 -> 2013.522 | D6: =D5/1000000 -> 1235.718 | E6: =E5/1000000 -> 300.6025 | F6: =F5/1000000 -> 402.9211
A7: Market cap | B7: {=_FV(B1,"Market cap",TRUE)} -> 501969268980 | C7: {=_FV(C1,"Market cap",TRUE)} -> 311733400000 | D7: {=_FV(D1,"Market cap",TRUE)} -> 110794475880 | E7: {=_FV(E1,"Market cap",TRUE)} -> 60003265025 | F7: {=_FV(F1,"Market cap",TRUE)} -> 55768309451
A8: in mn | B8: =B7/1000000 -> 501969.27 | C8: =C7/1000000 -> 311733.4 | D8: =D7/1000000 -> 110794.48 | E8: =E7/1000000 -> 60003.265 | F8: =F7/1000000 -> 55768.309
A9: Beta | B9: {=_FV(B1,"Beta")} -> 0.3684 | C9: {=_FV(C1,"Beta")} -> 0.6735 | D9: {=_FV(D1,"Beta")} -> 0.3261 | E9: {=_FV(E1,"Beta")} -> 0.7076 | F9: {=_FV(F1,"Beta")} -> 0.9063
A10: P/E | B10: {=_FV(B1,"P/E",TRUE)} -> 17.3025 | C10: {=_FV(C1,"P/E",TRUE)} -> 21.6919 | D10: {=_FV(D1,"P/E",TRUE)} -> 12.6867 | E10: {=_FV(E1,"P/E",TRUE)} -> 21.1795 | F10: {=_FV(F1,"P/E",TRUE)} -> 37.5996
A11: Year | B11: {=_FV(B1,"Year incorporated",TRUE)} -> 1882 | C11: {=_FV(C1,"Year incorporated",TRUE)} -> 1926 | D11: {=_FV(D1,"Year incorporated",TRUE)} -> 2001 | E11: {=_FV(E1,"Year incorporated",TRUE)} -> 2009 | F11: {=_FV(F1,"Year incorporated",TRUE)} -> 2011

Sheet Financials
A1: INCOME STATEMENT | F1: Exxon | H1: INCOME STATEMENT | M1: Chevron | O1: INCOME STATEMENT | T1: ConocoP | W1: INCOME STATEMENT | AB1: MP | AE1: INCOME STATEMENT | AJ1: Phillips66
A2: Particulars | B2: 2020 | C2: 2021 | D2: 2022 | E2: 2023 | F2: 2024 | H2: Particulars | I2: 2020 | J2: 2021 | K2: 2022 | L2: 2023 | M2: 2024 | O2: Particulars | P2: 2020 | Q2: 2021 | R2: 2022 | S2: 2023 | T2: 2024 | W2: Particulars | X2: 2020 | Y2: 2021 | Z2: 2022 | AA2: 2023 | AB2: 2024 | AE2: Particulars | AF2: 2020 | AG2: 2021 | AH2: 2022 | AI2: 2023 | AJ2: 2024
A3: Revenue | B3: 181502 | C3: 285640 | D3: 413680 | E3: 344582 | F3: 349585 | H3: Revenue | I3: 94692 | J3: 162465 | K3: 246252 | L3: 200949 | M3: 202792 | O3: Revenue | P3: 19256 | Q3: 48349 | R3: 82156 | S3: 58574 | T3: 56953 | W3: Revenue | X3: 69032 | Y3: 120930 | Z3: 179952 | AA3: 150307 | AB3: 140412 | AE3: Revenue | AF3: 65494 | AG3: 114852 | AH3: 175702 | AI3: 149890 | AJ3: 145496
A4: Cost of sales | B4: =94007+30431 -> 124438 | C4: =155164+36035 -> 191199 | D4: =228959+42609 -> 271568 | E4: =36885+193029 -> 229914 | F4: =199454+39609 -> 239063 | H4: Cost of sales | I4: 50488 | J4: 92249 | K4: 145416 | L4: 119196 | M4: 119206 | O4: Cost of sales | P4: 8078 | Q4: 18158 | R4: 33971 | S4: =21975 -> 21975 | T4: 20012 | W4: Cost of sales | X4: 65733 | Y4: 110008 | Z4: 151671 | AA4: =128566 -> 128566 | AB4: 126240 | AE4: Cost of sales | AF4: 57707 | AG4: 102102 | AH4: 149932 | AI4: 128086 | AJ4: 129962
A5: Opex | B5: =10168+1285+1205+26122 -> 38780 | C5: =9574+1054+786+30239 -> 41653 | D5: =10095+1025+482+27919 -> 39521 | E5: =9919+751+714+29011 -> 40395 | F5: =9976+826+121+26288 -> 37211 | H5: Opex | I5: =20323+4213+1537+4499+880 -> 31452 | J5: =20726+4014+549+3963+688 -> 29940 | K5: =24714+4312+974+4032+295 -> 34327 | L5: =24887+4141+914+4220+212 -> 34374 | M5: =27464+4834+995+4716+195 -> 38204 | O5: Opex | P5: =22396-8078-5521-806 -> 7991 | Q5: =35637-7208-884-18158 -> 9387 | R5: =53928-7504-805-33971 -> 11648 | S5: =42286-21975-8270-780 -> 11261 | T5: =43281-20012-9599-783 -> 12887 | W5: Opex | X5: =81279-65733-3375 -> 12171 | Y5: =116630-110008-3364 -> 3258 | Z5: =158483-151671-3215 -> 3597 | AA5: =135793-3307-128566 -> 3920 | AB5: =133616-126240-3337 -> 4039 | AE5: Opex | AF5: =70458-57707-1395-499 -> 10857 | AG5: =113112-102102-1605-581 -> 8824 | AH5: =161063-149932-1629-619 -> 8883 | AI5: =140421-128086-1977-897 -> 9461 | AJ5: =142821-129962-2363-907 -> 9589
A6: Operating income (EBIT) | B6: =B3-B4-B5 -> 18284 | C6: =C3-C4-C5 -> 52788 | D6: =D3-D4-D5 -> 102591 | E6: =E3-E4-E5 -> 74273 | F6: =F3-F4-F5 -> 73311 | H6: Operating income (EBIT) | I6: =I3-I4-I5 -> 12752 | J6: =J3-J4-J5 -> 40276 | K6: =K3-K4-K5 -> 66509 | L6: =L3-L4-L5 -> 47379 | M6: =M3-M4-M5 -> 45382 | O6: Operating income (EBIT) | P6: =P3-P4-P5 -> 3187 | Q6: =Q3-Q4-Q5 -> 20804 | R6: =R3-R4-R5 -> 36537 | S6: =S3-S4-S5 -> 25338 | T6: =T3-T4-T5 -> 24054 | W6: Operating income (EBIT) | X6: =X3-X4-X5 -> -8872 | Y6: =Y3-Y4-Y5 -> 7664 | Z6: =Z3-Z4-Z5 -> 24684 | AA6: =AA3-AA4-AA5 -> 17821 | AB6: =AB3-AB4-AB5 -> 10133 | AE6: Operating income (EBIT) | AF6: =AF3-AF4-AF5 -> -3070 | AG6: =AG3-AG4-AG5 -> 3926 | AH6: =AH3-AH4-AH5 -> 16887 | AI6: =AI3-AI4-AI5 -> 12343 | AJ6: =AJ3-AJ4-AJ5 -> 5945
A7: Depreciation & Amortization | B7: 46009 | C7: 20607 | D7: 24040 | E7: 20641 | F7: 23442 | H7: Depreciation & Amortization | I7: 19508 | J7: 17925 | K7: 16319 | L7: 17326 | M7: 17282 | O7: Depreciation & Amortization | P7: 5521 | Q7: 7208 | R7: 7504 | S7: 8270 | T7: 9599 | W7: Depreciation & Amortization | X7: 3375 | Y7: 3364 | Z7: 3215 | AA7: 3307 | AB7: 3337 | AE7: Depreciation & Amortization | AF7: 1395 | AG7: 1605 | AH7: 1629 | AI7: 1977 | AJ7: 2363
A8: Interest expense | B8: 1158 | C8: 947 | D8: 798 | E8: 849 | F8: 996 | H8: Interest expense | I8: 697 | J8: 712 | K8: 516 | L8: 469 | M8: 594 | O8: Interest expense | P8: 806 | Q8: 884 | R8: 805 | S8: 780 | T8: 783 | W8: Interest expense | X8: 1365 | Y8: 1483 | Z8: 1000 | AA8: 525 | AB8: 839 | AE8: Interest expense | AF8: 499 | AG8: 581 | AH8: 619 | AI8: 897 | AJ8: 907
A9: Income tax | B9: -5632 | C9: 7636 | D9: 20176 | E9: 15429 | F9: 13810 | H9: Income tax | I9: -1892 | J9: 5950 | K9: 14066 | L9: 8173 | M9: 9757 | O9: Income tax | P9: -485 | Q9: 4633 | R9: 9548 | S9: 5331 | T9: 4427 | W9: Income tax | X9: -2430 | Y9: 264 | Z9: 4491 | AA9: 2817 | AB9: 890 | AE9: Income tax | AF9: -1250 | AG9: 146 | AH9: 3248 | AI9: 2230 | AJ9: 500
A10: Net income | B10: =B6-B7-B8-B9 -> -23251 | C10: =C6-C7-C8-C9 -> 23598 | D10: =D6-D7-D8-D9 -> 57577 | E10: =E6-E7-E8-E9 -> 37354 | F10: =F6-F7-F8-F9 -> 35063 | H10: Net income | I10: =I6-I7-I8-I9 -> -5561 | J10: =J6-J7-J8-J9 -> 15689 | K10: =K6-K7-K8-K9 -> 35608 | L10: =L6-L7-L8-L9 -> 21411 | M10: =M6-M7-M8-M9 -> 17749 | O10: Net income | P10: =P6-P7-P8-P9 -> -2655 | Q10: =Q6-Q7-Q8-Q9 -> 8079 | R10: =R6-R7-R8-R9 -> 18680 | S10: =S6-S7-S8-S9 -> 10957 | T10: =T6-T7-T8-T9 -> 9245 | W10: Net income | X10: =X6-X7-X8-X9 -> -11182 | Y10: =Y6-Y7-Y8-Y9 -> 2553 | Z10: =Z6-Z7-Z8-Z9 -> 15978 | AA10: =AA6-AA7-AA8-AA9 -> 11172 | AB10: =AB6-AB7-AB8-AB9 -> 5067 | AE10: Net income | AF10: =AF6-AF7-AF8-AF9 -> -3714 | AG10: =AG6-AG7-AG8-AG9 -> 1594 | AH10: =AH6-AH7-AH8-AH9 -> 11391 | AI10: =AI6-AI7-AI8-AI9 -> 7239 | AJ10: =AJ6-AJ7-AJ8-AJ9 -> 2175
A12: BALANCE SHEET | H12: BALANCE SHEET | O12: BALANCE SHEET | W12: BALANCE SHEET | AE12: BALANCE SHEET
A13: Particulars | B13: 2020 | C13: 2021 | D13: 2022 | E13: 2023 | F13: 2024 | H13: Particulars | I13: 2020 | J13: 2021 | K13: 2022 | L13: 2023 | M13: 2024 | O13: Particulars | P13: 2020 | Q13: 2021 | R13: 2022 | S13: 2023 | T13: 2024 | W13: Particulars | X13: 2020 | Y13: 2021 | Z13: 2022 | AA13: 2023 | AB13: 2024 | AE13: Particulars | AF13: 2020 | AG13: 2021 | AH13: 2022 | AI13: 2023 | AJ13: 2024
A14: Cash & Cash equivalents | B14: 4364 | C14: 6802 | D14: =29640+25 -> 29665 | E14: =31539+29 -> 31568 | F14: =23029+158 -> 23187 | H14: Cash & Cash equivalents | I14: 5596 | J14: 5640 | K14: 17678 | L14: 8178 | M14: 6781 | O14: Cash & Cash equivalents | P14: 2991 | Q14: 5028 | R14: 6458 | S14: 5635 | T14: 5607 | W14: Cash & Cash equivalents | X14: 415 | Y14: 5291 | Z14: 8625 | AA14: 5443 | AB14: 3210 | AE14: Cash & Cash equivalents | AF14: 2514 | AG14: 3147 | AH14: 6133 | AI14: 3323 | AJ14: 1738
A15: Accounts receivables | B15: 20581 | C15: 32383 | D15: 41749 | E15: 38015 | F15: 43681 | H15: Accounts receivables | I15: 11471 | J15: 18419 | K15: 20456 | L15: 19921 | M15: 20684 | O15: Total Assets | P15: 62618 | Q15: 90661 | R15: 93829 | S15: 95924 | T15: 122780 | W15: Total assets | X15: 85158 | Y15: 85373 | Z15: 89904 | AA15: 85987 | AB15: 78858 | AE15: Total assets | AF15: 54721 | AG15: 55594 | AH15: 76442 | AI15: 75501 | AJ15: 72582
A16: Inventories | B16: =14169+4681 -> 18850 | C16: =14519+4261 -> 18780 | D16: =20434+4001 -> 24435 | E16: =20528+4592 -> 25120 | F16: =19444+4080 -> 23524 | H16: Inventories | I16: 5676 | J16: 6795 | K16: 8247 | L16: 8612 | M16: 9074 | O16: Inventories | P16: 1002 | Q16: 1208 | R16: 1219 | S16: 1398 | T16: 1809 | W16: Inventories | X16: 7999 | Y16: 8055 | Z16: 8827 | AA16: 9317 | AB16: 9568 | AE16: Inventories | AF16: 3893 | AG16: 3394 | AH16: 3276 | AI16: 3750 | AJ16: 3995
A17: Total current assets | B17: 44893 | C17: 59154 | D17: 97631 | E17: 96609 | F17: 91990 | H17: Total current assets | I17: 26078 | J17: 33738 | K17: 50343 | L17: 41128 | M17: 40911 | O17: Total current assets | P17: 12066 | Q17: 16050 | R17: 18749 | S17: 14330 | T17: 15647 | W17: Total current assets | X17: 28287 | Y17: 30496 | Z17: 35242 | AA17: 32131 | AB17: 24447 | AE17: Total current assets | AF17: 13276 | AG17: 14697 | AH17: 21922 | AI17: 19941 | AJ17: 17910
A18: PPE | B18: 227553 | C18: 216552 | D18: 204692 | E18: 214940 | F18: 294318 | H18: PPE | I18: 156618 | J18: 146961 | K18: 143591 | L18: 153619 | M18: 147799 | O18: PPE | P18: 39893 | Q18: 64911 | R18: 64866 | S18: 70044 | T18: 94356 | W18: PPE | X18: 39035 | Y18: 37440 | Z18: 35657 | AA18: 35112 | AB18: 35028 | AE18: PPE | AF18: 23716 | AG18: 22435 | AH18: 35163 | AI18: 35712 | AJ18: 35264
A19: Accounts payables | B19: 35221 | C19: 50766 | D19: 63197 | E19: 58037 | F19: 61297 | H19: Accounts payables | I19: 10950 | J19: 16454 | K19: 18955 | L19: 20423 | M19: 22079 | O19: Accounts payables | P19: 2669 | Q19: 5002 | R19: 6113 | S19: 5083 | T19: 5987 | W19: Accounts payables | X19: 7803 | Y19: 13700 | Z19: 15312 | AA19: 13761 | AB19: 13906 | AE19: Accounts payables | AF19: =5171+378 -> 5549 | AG19: 7629 | AH19: 10748 | AI19: 10332 | AJ19: 9792
A20: Total current liabilities | B20: 56363 | C20: 56643 | D20: 69045 | E20: 65316 | F20: 70307 | H20: Total current liabilities | I20: 22183 | J20: 26791 | K20: 34208 | L20: 32258 | M20: 38558 | O20: Total current liabilities | P20: 5366 | Q20: 12021 | R20: 12847 | S20: 10005 | T20: 12124 | W20: Total current liabilities | X20: 15663 | Y20: 17898 | Z20: 20020 | AA20: 20150 | AB20: 20827 | AE20: Total current liabilities | AF20: 9518 | AG20: 12801 | AH20: 15889 | AI20: 15856 | AJ20: 15087
A21: Total debt | B21: =20458+47182 -> 67640 | C21: =4276+43428 -> 47704 | D21: =634+40559 -> 41193 | E21: =4090+37483 -> 41573 | F21: =4955+36755 -> 41710 | H21: Total debt | I21: =1548+42767 -> 44315 | J21: =256+31113 -> 31369 | K21: =1964+21375 -> 23339 | L21: =529+20307 -> 20836 | M21: =4406+20135 -> 24541 | O21: Total debt | P21: =619+14750 -> 15369 | Q21: =1200+18734 -> 19934 | R21: =417+16226 -> 16643 | S21: =1074+17863 -> 18937 | T21: =1035+23289 -> 24324 | W21: Total debt | X21: =2854+28730 -> 31584 | Y21: =571+24968 -> 25539 | Z21: =1066+25634 -> 26700 | AA21: =1954+25329 -> 27283 | AB21: =3049+24432 -> 27481 | AE21: Total debt | AF21: =987+14906 -> 15893 | AG21: =1489+12959 -> 14448 | AH21: =529+16661 -> 17190 | AI21: =1482+17877 -> 19359 | AJ21: =1831+18231 -> 20062
A22: Shareholder's equity | B22: 164130 | C22: 175683 | D22: 202473 | E22: =212538 -> 212538 | F22: 270606 | H22: Shareholder's equity | I22: 132726 | J22: 139940 | K22: 160242 | L22: 161929 | M22: 153157 | O22: Shareholder's equity | P22: 29849 | Q22: 45406 | R22: 48003 | S22: 49279 | T22: 64796 | W22: Shareholder's equity | X22: 29252 | Y22: 32616 | Z22: 34119 | AA22: 30504 | AB22: 24303 | AE22: Shareholder's equity | AF22: 21523 | AG22: 21637 | AH22: 34106 | AI22: 31650 | AJ22: 28463
A24: CASH FLOW STATEMENT | H24: CASH FLOW STATEMENT | O24: CASH FLOW STATEMENT | W24: CASH FLOW STATEMENT | AE24: CASH FLOW STATEMENT
A25: Particulars | B25: 2020 | C25: 2021 | D25: 2022 | E25: 2023 | F25: 2024 | H25: Particulars | I25: 2020 | J25: 2021 | K25: 2022 | L25: 2023 | M25: 2024 | O25: Particulars | P25: 2020 | Q25: 2021 | R25: 2022 | S25: 2023 | T25: 2024 | W25: Particulars | X25: 2020 | Y25: 2021 | Z25: 2022 | AA25: 2023 | AB25: 2024 | AE25: Particulars | AF25: 2020 | AG25: 2021 | AH25: 2022 | AI25: 2023 | AJ25: 2024
A26: Cash flow from operating activities | B26: 14668 | C26: 48129 | D26: 76797 | E26: 55369 | F26: 55022 | H26: Cash flow from operating activities | I26: 10577 | J26: 29187 | K26: 49602 | L26: 35609 | M26: 31492 | O26: Cash flow from operating activities | P26: 4802 | Q26: 16996 | R26: 28314 | S26: 19965 | T26: 20124 | W26: Cash flow from operating activities | X26: 2419 | Y26: 4360 | Z26: 16361 | AA26: 14117 | AB26: 8665 | AE26: Cash flow from operating activities | AF26: 2111 | AG26: 6017 | AH26: 10813 | AI26: 7029 | AJ26: 4191
A27: Capex | B27: 17282 | C27: 12076 | D27: 18407 | E27: 21919 | F27: 24306 | H27: Capex | I27: 8922 | J27: 8056 | K27: 11974 | L27: 15829 | M27: 16448 | O27: Capex | P27: 4715 | Q27: 5324 | R27: 10159 | S27: 11248 | T27: 12118 | W27: Capex | X27: 2787 | Y27: 1464 | Z27: 2420 | AA27: 1890 | AB27: 2533 | AE27: Capex | AF27: 2928 | AG27: 1860 | AH27: 2194 | AI27: 2155 | AJ27: 1859
A28: Dividends paid | B28: =14865+188 -> 15053 | C28: =14924+224 -> 15148 | D28: =14939+267 -> 15206 | E28: =14941+531 -> 15472 | F28: =16704+658 -> 17362 | H28: Dividends paid | I28: 9651 | J28: 10179 | K28: 10968 | L28: 11336 | M28: 11801 | O28: Dividends paid | P28: 1831 | Q28: 2359 | R28: 5726 | S28: 5583 | T28: 3646 | W28: Dividends paid | X28: 1510 | Y28: 1484 | Z28: 1279 | AA28: 1261 | AB28: 1154 | AE28: Dividends paid | AF28: 1575 | AG28: 1585 | AH28: 1793 | AI28: 1882 | AJ28: 1882
A29: Debt repaid | B29: =8+28742 -> 28750 | C29: =8+29396 -> 29404 | D29: =5+8075 -> 8080 | E29: =15+879 -> 894 | F29: =1150+4743 -> 5893 | H29: Debt repaid | I29: 5489 | J29: 7364 | K29: 8742 | L29: 4340 | M29: 1778 | O29: Debt repaid | P29: 254 | Q29: 505 | R29: 6267 | S29: 1379 | T29: 4981 | W29: Debt repaid | X29: =1031+15380 -> 16411 | Y29: =8437+17400 -> 25837 | Z29: =2280 -> 2280 | AA29: 1079 | AB29: 1984 | AE29: Debt repaid | AF29: 1051 | AG29: 2954 | AH29: 2883 | AI29: 4252 | AJ29: 4140
O32: Particulars | P32: 2020 | Q32: 2021 | R32: 2022 | S32: 2023 | T32: 2024 | W32: Particulars | X32: 2020 | Y32: 2021 | Z32: 2022 | AA32: 2023 | AB32: 2024 | AE32: Particulars | AF32: 2020 | AG32: 2021 | AH32: 2022 | AI32: 2023 | AJ32: 2024
O33: Revenue | P33: =P3 -> 19256 | Q33: =Q3 -> 48349 | R33: =R3 -> 82156 | S33: =S3 -> 58574 | T33: =T3 -> 56953 | W33: Revenue | X33: =X3 -> 69032 | Y33: =Y3 -> 120930 | Z33: =Z3 -> 179952 | AA33: =AA3 -> 150307 | AB33: =AB3 -> 140412 | AE33: Revenue | AF33: =AF3 -> 65494 | AG33: =AG3 -> 114852 | AH33: =AH3 -> 175702 | AI33: =AI3 -> 149890 | AJ33: =AJ3 -> 145496
O34: Operating income | P34: =P6 -> 3187 | Q34: =Q6 -> 20804 | R34: =R6 -> 36537 | S34: =S6 -> 25338 | T34: =T6 -> 24054 | W34: Operating income | X34: =X6 -> -8872 | Y34: =Y6 -> 7664 | Z34: =Z6 -> 24684 | AA34: =AA6 -> 17821 | AB34: =AB6 -> 10133 | AE34: Operating income | AF34: =AF6 -> -3070 | AG34: =AG6 -> 3926 | AH34: =AH6 -> 16887 | AI34: =AI6 -> 12343 | AJ34: =AJ6 -> 5945
O35: Net Income | P35: =P10 -> -2655 | Q35: =Q10 -> 8079 | R35: =R10 -> 18680 | S35: =S10 -> 10957 | T35: =T10 -> 9245 | W35: Net Income | X35: =X10 -> -11182 | Y35: =Y10 -> 2553 | Z35: =Z10 -> 15978 | AA35: =AA10 -> 11172 | AB35: =AB10 -> 5067 | AE35: Net Income | AF35: =AF10 -> -3714 | AG35: =AG10 -> 1594 | AH35: =AH10 -> 11391 | AI35: =AI10 -> 7239 | AJ35: =AJ10 -> 2175
O37: Particulars | P37: 2025 | Q37: 2026 | R37: 2027 | S37: 2028 | T37: 2029 | U37: 2030 | W37: Particulars | X37: 2025 | Y37: 2026 | Z37: 2027 | AA37: 2028 | AB37: 2029 | AC37: 2030
O38: Revenue | P38: =DCF!R3 -> 59333.352 | Q38: =DCF!S3 -> 61813.19 | R38: =DCF!T3 -> 64396.674 | S38: =DCF!U3 -> 67088.134 | T38: =DCF!V3 -> 69892.084 | U38: =DCF!W3 -> 72813.225 | W38: Revenue | X38: =DCF!Z3 -> 145754.43 | Y38: =DCF!AA3 -> 151300.13 | Z38: =DCF!AB3 -> 157056.84 | AA38: =DCF!AC3 -> 163032.58 | AB38: =DCF!AD3 -> 169235.68 | AC38: =DCF!AE3 -> 175674.81
O39: Operating income | P39: =DCF!R4 -> 25739.849 | Q39: =DCF!S4 -> 26815.647 | R39: =DCF!T4 -> 27936.408 | S39: =DCF!U4 -> 29104.01 | T39: =DCF!V4 -> 30320.413 | U39: =DCF!W4 -> 31587.655 | W39: Operating income | X39: =DCF!Z4 -> 14856.776 | Y39: =DCF!AA4 -> 15422.051 | Z39: =DCF!AB4 -> 16008.833 | AA39: =DCF!AC4 -> 16617.941 | AB39: =DCF!AD4 -> 17250.225 | AC39: =DCF!AE4 -> 17906.566
O40: Net income | P40: =DCF!R5 -> 20334.481 | Q40: =DCF!S5 -> 21184.361 | R40: =DCF!T5 -> 22069.762 | S40: =DCF!U5 -> 22992.168 | T40: =DCF!V5 -> 23953.126 | U40: =DCF!W5 -> 24954.248 | W40: Net income | X40: =DCF!Z5 -> 11736.853 | Y40: =DCF!AA5 -> 12183.42 | Z40: =DCF!AB5 -> 12646.978 | AA40: =DCF!AC5 -> 13128.173 | AB40: =DCF!AD5 -> 13627.678 | AC40: =DCF!AE5 -> 14146.187
O41: FCFF | P41: =DCF!R9 -> 18348.266 | Q41: =DCF!S9 -> 19732.492 | R41: =DCF!T9 -> 20557.212 | S41: =DCF!U9 -> 21416.401 | T41: =DCF!V9 -> 22311.5 | U41: =DCF!W9 -> 23244.01 | W41: FCFF | X41: =DCF!Z9 -> 5873.4362 | Y41: =DCF!AA9 -> 13036.932 | Z41: =DCF!AB9 -> 13532.964 | AA41: =DCF!AC9 -> 14047.87 | AB41: =DCF!AD9 -> 14582.367 | AC41: =DCF!AE9 -> 15137.2
AE43: Particulars | AF43: 2025 | AG43: 2026 | AH43: 2027 | AI43: 2028 | AJ43: 2029 | AK43: 2030
AE44: Revenue | AF44: =DCF!AH3 -> 154358.01 | AG44: =DCF!AI3 -> 163759.8 | AH44: =DCF!AJ3 -> 173734.24 | AI44: =DCF!AK3 -> 184316.22 | AJ44: =DCF!AL3 -> 195542.73 | AK44: =DCF!AM3 -> 207453.03
AE45: Operating income | AF45: 27280.482 | AG45: 28942.108 | AH45: 30704.942 | AI45: 32575.149 | AJ45: 34559.268 | AK45: 36664.237
AE46: Net income | AF46: 21551.581 | AG46: 22864.266 | AH46: 24256.905 | AI46: 25734.368 | AJ46: 27301.822 | AK46: 28964.748
...

Sheet Assumptions & WACC
A1: Assumptions
A2: Metric | B2: Exxon | C2: Chevron | D2: Conoco | E2: MP | F2: Phillips66 | H2: Current | I2: 2020 | J2: 2021 | K2: 2022 | L2: 2023 | M2: 2024
A3: Revenue CAGR | B3: =(Table1[[#This Row],[2024]]/Table1[[#This Row],[2020]])^(1/5)-1 -> 0.14007724 | C3: =(Table18[[#This Row],[2024]]/Table18[[#This Row],[2020]])^(1/5)-1 -> 0.16452149 | D3: =(Table124[[#This Row],[2024]]/Table124[[#This Row],[2021]])^(1/4)-1 -> 0.041795021 | E3: =(Table1827[[#This Row],[2024]]/Table1827[[#This Row],[2021]])^(1/4)-1 -> 0.038048256 | F3: =(Financials!$AJ3/Financials!$AG3)^(1/4)-1 -> 0.060908974 | H3: WC-Exxon | I3: =Financials!B17-Financials!B20 -> -11470 | J3: =Financials!C17-Financials!C20 -> 2511 | K3: =Financials!D17-Financials!D20 -> 28586 | L3: =Financials!E17-Financials!E20 -> 31293 | M3: =Financials!F17-Financials!F20 -> 21683
A4: Operating margin (EBIT) | B4: =AVERAGE(Financials!B6:F6)/AVERAGE(Financials!B3:F3) -> 0.20396777 | C4: =AVERAGE(Financials!I6:M6)/AVERAGE(Financials!I3:M3) -> 0.23402745 | D4: =AVERAGE(Financials!Q6:T6)/AVERAGE(Financials!Q3:T3) -> 0.43381755 | E4: =AVERAGE(Financials!Y6:AB6)/AVERAGE(Financials!Y3:AB3) -> 0.10193019 | F4: =AVERAGE(Financials!AG6:AJ60)/AVERAGE(Financials!AG3:AJ3) -> 0.17902793 | H4: WC-Chevron | I4: =Financials!I17-Financials!I20 -> 3895 | J4: =Financials!J17-Financials!J20 -> 6947 | K4: =Financials!K17-Financials!K20 -> 16135 | L4: =Financials!L17-Financials!L20 -> 8870 | M4: =Financials!M17-Financials!M20 -> 2353
A5: Depreciation rate | B5: =AVERAGE(Financials!B7:F7)/AVERAGE(Financials!B3:F3) -> 0.085549169 | C5: =AVERAGE(Financials!I7:M7)/AVERAGE(Financials!I3:M3) -> 0.097403957 | D5: =AVERAGE(Financials!P7:T7)/AVERAGE(Financials!P3:T3) -> 0.14362504 | E5: =AVERAGE(Financials!X7:AB7)/AVERAGE(Financials!X3:AB3) -> 0.025124388 | F5: =AVERAGE(Financials!AF7:AJ7)/AVERAGE(Financials!AF3:AJ3) -> 0.013768087 | H5: WC-Conoco | I5: =Financials!P17-Financials!P20 -> 6700 | J5: =Financials!Q17-Financials!Q20 -> 4029 | K5: =Financials!R17-Financials!R20 -> 5902 | L5: =Financials!S17-Financials!S20 -> 4325 | M5: =Financials!T17-Financials!T20 -> 3523
A6: CapEx | B6: =AVERAGE(Financials!B27:F27)/AVERAGE(Financials!B3:F3) -> 0.059676607 | C6: =AVERAGE(Financials!I27:M27)/AVERAGE(Financials!I3:M3) -> 0.067496004 | D6: =AVERAGE(Financials!P27:T27)/AVERAGE(Financials!P3:T3) -> 0.16421399 | E6: =AVERAGE(Financials!X27:AB27)/AVERAGE(Financials!X3:AB3) -> 0.016792985 | F6: =AVERAGE(Financials!AF27:AJ27)/AVERAGE(Financials!AF3:AJ3) -> 0.016879684 | H6: WC-MP | I6: =Financials!X17-Financials!X20 -> 12624 | J6: =Financials!Y17-Financials!Y20 -> 12598 | K6: =Financials!Z17-Financials!Z20 -> 15222 | L6: =Financials!AA17-Financials!AA20 -> 11981 | M6: =Financials!AB17-Financials!AB20 -> 3620
A7: Working capital | B7: =AVERAGE(I3:M3)/AVERAGE(Financials!B3:F3) -> 0.046097465 | C7: =AVERAGE(I4:M4)/AVERAGE(Financials!I3:M3) -> 0.042109905 | D7: =AVERAGE(J5:M5)/AVERAGE(Financials!Q3:T3) -> 0.072262958 | E7: =AVERAGE(J6:M6)/AVERAGE(Financials!Y3:AB3) -> 0.073395752 | F7: =AVERAGE(Table19[[#This Row],[2021]:[2024]])/AVERAGE(Financials!AG3:AJ3) -> 0.025321705 | H7: WC-Phillips66 | I7: =Financials!AF17-Financials!AF20 -> 3758 | J7: =Financials!AG17-Financials!AG20 -> 1896 | K7: =Financials!AH17-Financials!AH20 -> 6033 | L7: =Financials!AI17-Financials!AI20 -> 4085 | M7: =Financials!AJ17-Financials!AJ20 -> 2823
A8: Forecast horizon (yrs) | B8: 6 | C8: 6 | D8: 6 | E8: 6 | F8: 6
A9: Risk-free rate | B9: 0.045 | C9: 0.045 | D9: 0.045 | E9: 0.045 | F9: 0.045 | H9: Forecast | I9: 2025 | J9: 2026 | K9: 2027 | L9: 2028 | M9: 2029 | N9: 2030
A10: Equity risk premium | B10: 0.06 | C10: 0.06 | D10: 0.06 | E10: 0.06 | F10: 0.06 | H10: =H3 -> WC-Exxon | I10: =DCF!B3*'Assumptions & WACC'!$B$7 -> 18372.324 | J10: =DCF!C3*'Assumptions & WACC'!$B$7 -> 20577.003 | K10: =DCF!D3*'Assumptions & WACC'!$B$7 -> 22634.704 | L10: =DCF!E3*'Assumptions & WACC'!$B$7 -> 24445.48 | M10: =DCF!F3*'Assumptions & WACC'!$B$7 -> 25667.754 | N10: =DCF!G3*'Assumptions & WACC'!$B$7 -> 26437.787
A11: Beta | B11: ='Company Profile'!B9 -> 0.3684 | C11: ='Company Profile'!C9 -> 0.6735 | D11: ='Company Profile'!D9 -> 0.3261 | E11: ='Company Profile'!E9 -> 0.7076 | F11: ='Company Profile'!F9 -> 0.9063 | H11: =H4 -> WC-Chevron | I11: =DCF!J3*'Assumptions & WACC'!$C$7 -> 9944.4915 | J11: =DCF!K3*'Assumptions & WACC'!$C$7 -> 11137.831 | K11: =DCF!L3*'Assumptions & WACC'!$C$7 -> 12251.614 | L11: =DCF!M3*'Assumptions & WACC'!$C$7 -> 13231.743 | M11: =DCF!N3*'Assumptions & WACC'!$C$7 -> 13893.33 | N11: =DCF!O3*'Assumptions & WACC'!$C$7 -> 14310.13
A12: Cost of equity | B12: =B9+(B10*B11) -> 0.067104 | C12: =C9+(C10*C11) -> 0.08541 | D12: =D9+(D10*D11) -> 0.064566 | E12: =E9+(E10*E11) -> 0.087456 | F12: =F9+(F10*F11) -> 0.099378 | H12: =H6 -> WC-MP | I12: =DCF!R3*'Assumptions & WACC'!$D$7 -> 4287.6035 | J12: =DCF!S3*'Assumptions & WACC'!$D$7 -> 4466.804 | K12: =DCF!T3*'Assumptions & WACC'!$D$7 -> 4653.4941 | L12: =DCF!U3*'Assumptions & WACC'!$D$7 -> 4847.987 | M12: =DCF!V3*'Assumptions & WACC'!$D$7 -> 5050.6087 | N12: =DCF!W3*'Assumptions & WACC'!$D$7 -> 5261.699
A13: Kd (pre-tax) | B13: =AVERAGE(Financials!B8:F8)/AVERAGE(Financials!B21:F21) -> 0.019798182 | C13: =AVERAGE(Financials!I8:M8)/AVERAGE(Financials!I21:M21) -> 0.020692521 | D13: =AVERAGE(Financials!P8:T8)/AVERAGE(Financials!P21:T21) -> 0.042622916 | E13: =AVERAGE(Financials!X8:AB8)/AVERAGE(Financials!X21:AB21) -> 0.037608145 | F13: =AVERAGE(Financials!AF8:AJ8)/AVERAGE(Financials!AF21:AJ21) -> 0.040286595 | H13: =H7 -> WC-Phillips66 | I13: =DCF!Z3*'Assumptions & WACC'!$E$7 -> 10697.756 | J13: =DCF!AA3*'Assumptions & WACC'!$E$7 -> 11104.787 | K13: =DCF!AB3*'Assumptions & WACC'!$E$7 -> 11527.305 | L13: =DCF!AC3*'Assumptions & WACC'!$E$7 -> 11965.899 | M13: =DCF!AD3*'Assumptions & WACC'!$E$7 -> 12421.18 | N13: =DCF!AE3*'Assumptions & WACC'!$E$7 -> 12893.784
A14: Tax rate | B14: 0.21 | C14: 0.21 | D14: 0.21 | E14: 0.21 | F14: 0.21 | H14: =H5 -> WC-Conoco | I14: =DCF!AH3*'Assumptions & WACC'!$F$7 -> 3908.6081 | J14: =DCF!AI3*'Assumptions & WACC'!$F$7 -> 4146.6774 | K14: =DCF!AJ3*'Assumptions & WACC'!$F$7 -> 4399.2473 | L14: =DCF!AK3*'Assumptions & WACC'!$F$7 -> 4667.2009 | M14: =DCF!AL3*'Assumptions & WACC'!$F$7 -> 4951.4753 | N14: =DCF!AM3*'Assumptions & WACC'!$F$7 -> 5253.0646
A15: Kd (after tax) | B15: =B13*(1-B14) -> 0.015640564 | C15: =C13*(1-C14) -> 0.016347091 | D15: =D13*(1-D14) -> 0.033672104 | E15: =E13*(1-E14) -> 0.029710435 | F15: =F13*(1-F14) -> 0.03182641
A16: Total debt | B16: =Financials!F21 -> 41710 | C16: =Financials!M21 -> 24541 | D16: =Financials!T21 -> 24324 | E16: =Financials!AB21 -> 27481 | F16: =Financials!AJ21 -> 20062
A17: Market cap | B17: ='Company Profile'!B8 -> 501969.27 | C17: ='Company Profile'!C8 -> 311733.4 | D17: ='Company Profile'!D8 -> 110794.48 | E17: ='Company Profile'!E8 -> 60003.265 | F17: ='Company Profile'!F8 -> 55768.309
A18: Total capital | B18: =B16+B17 -> 543679.27 | C18: =C16+C17 -> 336274.4 | D18: =D16+D17 -> 135118.48 | E18: =E16+E17 -> 87484.265 | F18: =F16+F17 -> 75830.309 | H18: Year | I18: 1 | J18: 2 | K18: 3 | L18: 4 | M18: 5 | N18: 6
A19: Debt weight | B19: =B16/B18 -> 0.076718025 | C19: =C16/C18 -> 0.072979091 | D19: =D16/D18 -> 0.18001979 | E19: =E16/E18 -> 0.31412506 | F19: =F16/F18 -> 0.2645644 | H19: Revenue CAGR-Exxon | I19: =B3 -> 0.14007724 | J19: 0.12 | K19: 0.1 | L19: 0.08 | M19: 0.05 | N19: 0.03
A20: Equity weight | B20: =B17/B18 -> 0.92328197 | C20: =C17/C18 -> 0.92702091 | D20: =D17/D18 -> 0.81998021 | E20: =E17/E18 -> 0.68587494 | F20: =F17/F18 -> 0.7354356 | H20: Revenue CAGR-Chevron | I20: =C3 -> 0.16452149 | J20: 0.12 | K20: 0.1 | L20: 0.08 | M20: 0.05 | N20: 0.03
A21: WACC | B21: =(B12*B20)+(B15*B19) -> 0.063155827 | C21: =(C12*C20)+(C15*C19) -> 0.080369852 | D21: =(D12*D20)+(D15*D19) -> 0.059004487 | E21: =(E12*E20)+(E15*E19) -> 0.069316671 | F21: =(F12*F20)+(F15*F19) -> 0.081506254
A22: Terminal year | B22: 2030 | C22: 2030 | D22: 2030 | E22: 2030 | F22: 2030
A23: PV discount rate (terminal year) | B23: =1/(1+B21)^5 -> 0.73623317 | C23: =1/(1+C21)^5 -> 0.67941905 | D23: =1/(1+D21)^5 -> 0.75077707 | E23: =1/(1+E21)^5 -> 0.7152672 | F23: =1/(1+F21)^5 -> 0.67585701
A24: Cash & cash equivalents | B24: =Financials!F14 -> 23187 | C24: =Financials!M14 -> 6781 | D24: =Financials!T14 -> 5607 | E24: =Financials!AB14 -> 3210 | F24: =Financials!AJ14 -> 1738
A25: Terminal growth rate | B25: 0.0025 | C25: 0.0025 | D25: 0.0025 | E25: 0.0025 | F25: 0.0025
A26: Shares Outstanding | B26: ='Company Profile'!B6 -> 4217.166 | C26: ='Company Profile'!C6 -> 2013.522 | D26: ='Company Profile'!D6 -> 1235.718 | E26: ='Company Profile'!E6 -> 300.6025 | F26: ='Company Profile'!F6 -> 402.9211

Sheet DCF
A1: DCF | G1: Exxon | O1: Chevron | Q1: DCF | W1: Conoco | AE1: MP | AG1: DCF | AM1: Phillips66
A2: Particulars | B2: 2025 | C2: 2026 | D2: 2027 | E2: 2028 | F2: 2029 | G2: 2030 | I2: Particulars | J2: 2025 | K2: 2026 | L2: 2027 | M2: 2028 | N2: 2029 | O2: 2030 | Q2: Particulars | R2: 2025 | S2: 2026 | T2: 2027 | U2: 2028 | V2: 2029 | W2: 2030 | Y2: Particulars | Z2: 2025 | AA2: 2026 | AB2: 2027 | AC2: 2028 | AD2: 2029 | AE2: 2030 | AG2: Particulars | AH2: 2025 | AI2: 2026 | AJ2: 2027 | AK2: 2028 | AL2: 2029 | AM2: 2030
A3: Revenue | B3: =Table1[[#This Row],[2024]]*(1+'Assumptions & WACC'!B3) -> 398553.9 | C3: =Table9[[#This Row],[2025]]*(1+'Assumptions & WACC'!J19) -> 446380.37 | D3: =Table9[[#This Row],[2026]]*(1+'Assumptions & WACC'!K19) -> 491018.41 | E3: =Table9[[#This Row],[2027]]*(1+'Assumptions & WACC'!L19) -> 530299.88 | F3: =Table9[[#This Row],[2028]]*(1+'Assumptions & WACC'!M19) -> 556814.87 | G3: =Table9[[#This Row],[2029]]*(1+'Assumptions & WACC'!N19) -> 573519.32 | I3: Revenue | J3: =Table18[[#This Row],[2024]]*(1+'Assumptions & WACC'!C3) -> 236155.64 | K3: =J3*(1+'Assumptions & WACC'!J20) -> 264494.32 | L3: =K3*(1+'Assumptions & WACC'!K20) -> 290943.75 | M3: =L3*(1+'Assumptions & WACC'!L20) -> 314219.25 | N3: =M3*(1+'Assumptions & WACC'!M20) -> 329930.21 | O3: =N3*(1+'Assumptions & WACC'!N20) -> 339828.12 | Q3: Revenue | R3: =Table124[[#This Row],[2024]]*(1+'Assumptions & WACC'!D3) -> 59333.352 | S3: =Table941[[#This Row],[2025]]*(1+'Assumptions & WACC'!$D$3) -> 61813.19 | T3: =Table941[[#This Row],[2026]]*(1+'Assumptions & WACC'!$D$3) -> 64396.674 | U3: =Table941[[#This Row],[2027]]*(1+'Assumptions & WACC'!$D$3) -> 67088.134 | V3: =Table941[[#This Row],[2028]]*(1+'Assumptions & WACC'!$D$3) -> 69892.084 | W3: =Table941[[#This Row],[2029]]*(1+'Assumptions & WACC'!$D$3) -> 72813.225 | Y3: Revenue | Z3: =Table1827[[#This Row],[2024]]*(1+'Assumptions & WACC'!E3) -> 145754.43 | AA3: =Table1042[[#This Row],[2025]]*(1+'Assumptions & WACC'!$E$3) -> 151300.13 | AB3: =Table1042[[#This Row],[2026]]*(1+'Assumptions & WACC'!$E$3) -> 157056.84 | AC3: =Table1042[[#This Row],[2027]]*(1+'Assumptions & WACC'!$E$3) -> 163032.58 | AD3: =Table1042[[#This Row],[2028]]*(1+'Assumptions & WACC'!$E$3) -> 169235.68 | AE3: =Table1042[[#This Row],[2029]]*(1+'Assumptions & WACC'!$E$3) -> 175674.81 | AG3: Revenue | AH3: =Financials!$AJ3*(1+'Assumptions & WACC'!F3) -> 154358.01 | AI3: =Table94145[[#This Row],[2025]]*(1+'Assumptions & WACC'!$F$3) -> 163759.8 | AJ3: =Table94145[[#This Row],[2026]]*(1+'Assumptions & WACC'!$F$3) -> 173734.24 | AK3: =Table94145[[#This Row],[2027]]*(1+'Assumptions & WACC'!$F$3) -> 184316.22 | AL3: =Table94145[[#This Row],[2028]]*(1+'Assumptions & WACC'!$F$3) -> 195542.73 | AM3: =Table94145[[#This Row],[2029]]*(1+'Assumptions & WACC'!$F$3) -> 207453.03
A4: EBIT | B4: =B3*'Assumptions & WACC'!$B$4 -> 81292.152 | C4: =C3*'Assumptions & WACC'!$B$4 -> 91047.21 | D4: =D3*'Assumptions & WACC'!$B$4 -> 100151.93 | E4: =E3*'Assumptions & WACC'!$B$4 -> 108164.09 | F4: =F3*'Assumptions & WACC'!$B$4 -> 113572.29 | G4: =G3*'Assumptions & WACC'!$B$4 -> 116979.46 | I4: EBIT | J4: =J3*'Assumptions & WACC'!$C$4 -> 55266.902 | K4: =K3*'Assumptions & WACC'!$C$4 -> 61898.93 | L4: =L3*'Assumptions & WACC'!$C$4 -> 68088.823 | M4: =M3*'Assumptions & WACC'!$C$4 -> 73535.929 | N4: =N3*'Assumptions & WACC'!$C$4 -> 77212.726 | O4: =O3*'Assumptions & WACC'!$C$4 -> 79529.108 | Q4: EBIT | R4: =R3*'Assumptions & WACC'!$D$4 -> 25739.849 | S4: =S3*'Assumptions & WACC'!$D$4 -> 26815.647 | T4: =T3*'Assumptions & WACC'!$D$4 -> 27936.408 | U4: =U3*'Assumptions & WACC'!$D$4 -> 29104.01 | V4: =V3*'Assumptions & WACC'!$D$4 -> 30320.413 | W4: =W3*'Assumptions & WACC'!$D$4 -> 31587.655 | Y4: EBIT | Z4: =Z3*'Assumptions & WACC'!$E$4 -> 14856.776 | AA4: =AA3*'Assumptions & WACC'!$E$4 -> 15422.051 | AB4: =AB3*'Assumptions & WACC'!$E$4 -> 16008.833 | AC4: =AC3*'Assumptions & WACC'!$E$4 -> 16617.941 | AD4: =AD3*'Assumptions & WACC'!$E$4 -> 17250.225 | AE4: =AE3*'Assumptions & WACC'!$E$4 -> 17906.566 | AG4: EBIT | AH4: =AH3*'Assumptions & WACC'!$F$4 -> 27634.396 | AI4: =AI3*'Assumptions & WACC'!$F$4 -> 29317.578 | AJ4: =AJ3*'Assumptions & WACC'!$F$4 -> 31103.282 | AK4: =AK3*'Assumptions & WACC'!$F$4 -> 32997.751 | AL4: =AL3*'Assumptions & WACC'!$F$4 -> 35007.61 | AM4: =AM3*'Assumptions & WACC'!$F$4 -> 37139.888
A5: NOPAT | B5: =B4*(1-'Assumptions & WACC'!$B$14) -> 64220.8 | C5: =C4*(1-'Assumptions & WACC'!$B$14) -> 71927.296 | D5: =D4*(1-'Assumptions & WACC'!$B$14) -> 79120.026 | E5: =E4*(1-'Assumptions & WACC'!$B$14) -> 85449.628 | F5: =F4*(1-'Assumptions & WACC'!$B$14) -> 89722.109 | G5: =G4*(1-'Assumptions & WACC'!$B$14) -> 92413.772 | I5: NOPAT | J5: =J4*(1-'Assumptions & WACC'!$C$14) -> 43660.853 | K5: =K4*(1-'Assumptions & WACC'!$C$14) -> 48900.155 | L5: =L4*(1-'Assumptions & WACC'!$C$14) -> 53790.171 | M5: =M4*(1-'Assumptions & WACC'!$C$14) -> 58093.384 | N5: =N4*(1-'Assumptions & WACC'!$C$14) -> 60998.053 | O5: =O4*(1-'Assumptions & WACC'!$C$14) -> 62827.995 | Q5: NOPAT | R5: =R4*(1-'Assumptions & WACC'!$B$14) -> 20334.481 | S5: =S4*(1-'Assumptions & WACC'!$B$14) -> 21184.361 | T5: =T4*(1-'Assumptions & WACC'!$B$14) -> 22069.762 | U5: =U4*(1-'Assumptions & WACC'!$B$14) -> 22992.168 | V5: =V4*(1-'Assumptions & WACC'!$B$14) -> 23953.126 | W5: =W4*(1-'Assumptions & WACC'!$B$14) -> 24954.248 | Y5: NOPAT | Z5: =Z4*(1-'Assumptions & WACC'!$C$14) -> 11736.853 | AA5: =AA4*(1-'Assumptions & WACC'!$C$14) -> 12183.42 | AB5: =AB4*(1-'Assumptions & WACC'!$C$14) -> 12646.978 | AC5: =AC4*(1-'Assumptions & WACC'!$C$14) -> 13128.173 | AD5: =AD4*(1-'Assumptions & WACC'!$C$14) -> 13627.678 | AE5: =AE4*(1-'Assumptions & WACC'!$C$14) -> 14146.187 | AG5: NOPAT | AH5: =AH4*(1-'Assumptions & WACC'!$B$14) -> 21831.173 | AI5: =AI4*(1-'Assumptions & WACC'!$B$14) -> 23160.887 | AJ5: =AJ4*(1-'Assumptions & WACC'!$B$14) -> 24571.593 | AK5: =AK4*(1-'Assumptions & WACC'!$B$14) -> 26068.223 | AL5: =AL4*(1-'Assumptions & WACC'!$B$14) -> 27656.012 | AM5: =AM4*(1-'Assumptions & WACC'!$B$14) -> 29340.511
A6: Depreciation | B6: =B3*'Assumptions & WACC'!$B$5 -> 34095.955 | C6: =C3*'Assumptions & WACC'!$B$5 -> 38187.47 | D6: =D3*'Assumptions & WACC'!$B$5 -> 42006.217 | E6: =E3*'Assumptions & WACC'!$B$5 -> 45366.714 | F6: =F3*'Assumptions & WACC'!$B$5 -> 47635.05 | G6: =G3*'Assumptions & WACC'!$B$5 -> 49064.101 | I6: Depreciation | J6: =J3*'Assumptions & WACC'!$C$5 -> 23002.494 | K6: =K3*'Assumptions & WACC'!$C$5 -> 25762.793 | L6: =L3*'Assumptions & WACC'!$C$5 -> 28339.073 | M6: =M3*'Assumptions & WACC'!$C$5 -> 30606.198 | N6: =N3*'Assumptions & WACC'!$C$5 -> 32136.508 | O6: =O3*'Assumptions & WACC'!$C$5 -> 33100.604 | Q6: Depreciation | R6: =R3*'Assumptions & WACC'!$D$5 -> 8521.7551 | S6: =S3*'Assumptions & WACC'!$D$5 -> 8877.922 | T6: =T3*'Assumptions & WACC'!$D$5 -> 9248.975 | U6: =U3*'Assumptions & WACC'!$D$5 -> 9635.5361 | V6: =V3*'Assumptions & WACC'!$D$5 -> 10038.254 | W6: =W3*'Assumptions & WACC'!$D$5 -> 10457.803 | Y6: Depreciation | Z6: =Z3*'Assumptions & WACC'!$E$5 -> 3661.9909 | AA6: =AA3*'Assumptions & WACC'!$E$5 -> 3801.3233 | AB6: =AB3*'Assumptions & WACC'!$E$5 -> 3945.957 | AC6: =AC3*'Assumptions & WACC'!$E$5 -> 4096.0938 | AD6: =AD3*'Assumptions & WACC'!$E$5 -> 4251.943 | AE6: =AE3*'Assumptions & WACC'!$E$5 -> 4413.7221 | AG6: Depreciation | AH6: =AH3*'Assumptions & WACC'!$F$5 -> 2125.2145 | AI6: =AI3*'Assumptions & WACC'!$F$5 -> 2254.6592 | AJ6: =AJ3*'Assumptions & WACC'!$F$5 -> 2391.9882 | AK6: =AK3*'Assumptions & WACC'!$F$5 -> 2537.6817 | AL6: =AL3*'Assumptions & WACC'!$F$5 -> 2692.2493 | AM6: =AM3*'Assumptions & WACC'!$F$5 -> 2856.2314
A7: Capex | B7: =B3*'Assumptions & WACC'!$B$6 -> 23784.345 | C7: =C3*'Assumptions & WACC'!$B$6 -> 26638.466 | D7: =D3*'Assumptions & WACC'!$B$6 -> 29302.313 | E7: =E3*'Assumptions & WACC'!$B$6 -> 31646.498 | F7: =F3*'Assumptions & WACC'!$B$6 -> 33228.822 | G7: =G3*'Assumptions & WACC'!$B$6 -> 34225.687 | I7: Capex | J7: =J3*'Assumptions & WACC'!$C$6 -> 15939.562 | K7: =K3*'Assumptions & WACC'!$C$6 -> 17852.31 | L7: =L3*'Assumptions & WACC'!$C$6 -> 19637.54 | M7: =M3*'Assumptions & WACC'!$C$6 -> 21208.544 | N7: =N3*'Assumptions & WACC'!$C$6 -> 22268.971 | O7: =O3*'Assumptions & WACC'!$C$6 -> 22937.04 | Q7: Capex | R7: =R3*'Assumptions & WACC'!$D$6 -> 9743.3662 | S7: =S3*'Assumptions & WACC'!$D$6 -> 10150.59 | T7: =T3*'Assumptions & WACC'!$D$6 -> 10574.835 | U7: =U3*'Assumptions & WACC'!$D$6 -> 11016.81 | V7: =V3*'Assumptions & WACC'!$D$6 -> 11477.258 | W7: =W3*'Assumptions & WACC'!$D$6 -> 11956.95 | Y7: Capex | Z7: =Z3*'Assumptions & WACC'!$E$6 -> 2447.652 | AA7: =AA3*'Assumptions & WACC'!$E$6 -> 2540.7809 | AB7: =AB3*'Assumptions & WACC'!$E$6 -> 2637.4531 | AC7: =AC3*'Assumptions & WACC'!$E$6 -> 2737.8036 | AD7: =AD3*'Assumptions & WACC'!$E$6 -> 2841.9723 | AE7: =AE3*'Assumptions & WACC'!$E$6 -> 2950.1044 | AG7: Capex | AH7: =AH3*'Assumptions & WACC'!$F$6 -> 2605.5145 | AI7: =AI3*'Assumptions & WACC'!$F$6 -> 2764.2137 | AJ7: =AJ3*'Assumptions & WACC'!$F$6 -> 2932.5791 | AK7: =AK3*'Assumptions & WACC'!$F$6 -> 3111.1995 | AL7: =AL3*'Assumptions & WACC'!$F$6 -> 3300.6994 | AM7: =AM3*'Assumptions & WACC'!$F$6 -> 3501.7416
A8: Change in Working capital | B8: ='Assumptions & WACC'!I10-'Assumptions & WACC'!M3 -> -3310.6756 | C8: ='Assumptions & WACC'!J10-'Assumptions & WACC'!I10 -> 2204.6789 | D8: ='Assumptions & WACC'!K10-'Assumptions & WACC'!J10 -> 2057.7003 | E8: ='Assumptions & WACC'!L10-'Assumptions & WACC'!K10 -> 1810.7763 | F8: ='Assumptions & WACC'!M10-'Assumptions & WACC'!L10 -> 1222.274 | G8: ='Assumptions & WACC'!N10-'Assumptions & WACC'!M10 -> 770.03262 | I8: Change in Working capital | J8: ='Assumptions & WACC'!I11-'Assumptions & WACC'!M4 -> 7591.4915 | K8: ='Assumptions & WACC'!J11-'Assumptions & WACC'!I11 -> 1193.339 | L8: ='Assumptions & WACC'!K11-'Assumptions & WACC'!J11 -> 1113.7831 | M8: ='Assumptions & WACC'!L11-'Assumptions & WACC'!K11 -> 980.12909 | N8: ='Assumptions & WACC'!M11-'Assumptions & WACC'!L11 -> 661.58713 | O8: ='Assumptions & WACC'!N11-'Assumptions & WACC'!M11 -> 416.79989 | Q8: Change in Working capital | R8: ='Assumptions & WACC'!I12-'Assumptions & WACC'!M5 -> 764.60349 | S8: ='Assumptions & WACC'!J12-'Assumptions & WACC'!I12 -> 179.20048 | T8: ='Assumptions & WACC'!K12-'Assumptions & WACC'!J12 -> 186.69016 | U8: ='Assumptions & WACC'!L12-'Assumptions & WACC'!K12 -> 194.49288 | V8: ='Assumptions & WACC'!M12-'Assumptions & WACC'!L12 -> 202.62172 | W8: ='Assumptions & WACC'!N12-'Assumptions & WACC'!M12 -> 211.0903 | Y8: Change in Working capital | Z8: ='Assumptions & WACC'!I13-'Assumptions & WACC'!M6 -> 7077.7561 | AA8: ='Assumptions & WACC'!J13-'Assumptions & WACC'!I13 -> 407.03096 | AB8: ='Assumptions & WACC'!K13-'Assumptions & WACC'!J13 -> 422.51778 | AC8: ='Assumptions & WACC'!L13-'Assumptions & WACC'!K13 -> 438.59384 | AD8: ='Assumptions & WACC'!M13-'Assumptions & WACC'!L13 -> 455.28157 | AE8: ='Assumptions & WACC'!N13-'Assumptions & WACC'!M13 -> 472.60424 | AG8: Change in Working capital | AH8: ='Assumptions & WACC'!I14-'Assumptions & WACC'!M7 -> 1085.6081 | AI8: ='Assumptions & WACC'!J14-'Assumptions & WACC'!I14 -> 238.06931 | AJ8: ='Assumptions & WACC'!K14-'Assumptions & WACC'!J14 -> 252.56986 | AK8: ='Assumptions & WACC'!L14-'Assumptions & WACC'!K14 -> 267.95364 | AL8: ='Assumptions & WACC'!M14-'Assumptions & WACC'!L14 -> 284.27442 | AM8: ='Assumptions & WACC'!N14-'Assumptions & WACC'!M14 -> 301.58928
A9: FCFF | B9: =B5+B6-B7-B8 -> 77843.086 | C9: =C5+C6-C7-C8 -> 81271.621 | D9: =D5+D6-D7-D8 -> 89766.229 | E9: =E5+E6-E7-E8 -> 97359.068 | F9: =F5+F6-F7-F8 -> 102906.06 | G9: =G5+G6-G7-G8 -> 106482.15 | I9: FCFF | J9: =J5+J6-J7-J8 -> 43132.293 | K9: =K5+K6-K7-K8 -> 55617.3 | L9: =L5+L6-L7-L8 -> 61377.92 | M9: =M5+M6-M7-M8 -> 66510.91 | N9: =N5+N6-N7-N8 -> 70204.004 | O9: =O5+O6-O7-O8 -> 72574.759 | Q9: FCFF | R9: =R5+R6-R7-R8 -> 18348.266 | S9: =S5+S6-S7-S8 -> 19732.492 | T9: =T5+T6-T7-T8 -> 20557.212 | U9: =U5+U6-U7-U8 -> 21416.401 | V9: =V5+V6-V7-V8 -> 22311.5 | W9: =W5+W6-W7-W8 -> 23244.01 | Y9: FCFF | Z9: =Z5+Z6-Z7-Z8 -> 5873.4362 | AA9: =AA5+AA6-AA7-AA8 -> 13036.932 | AB9: =AB5+AB6-AB7-AB8 -> 13532.964 | AC9: =AC5+AC6-AC7-AC8 -> 14047.87 | AD9: =AD5+AD6-AD7-AD8 -> 14582.367 | AE9: =AE5+AE6-AE7-AE8 -> 15137.2 | AG9: FCFF | AH9: =AH5+AH6-AH7-AH8 -> 20265.265 | AI9: =AI5+AI6-AI7-AI8 -> 22413.263 | AJ9: =AJ5+AJ6-AJ7-AJ8 -> 23778.432 | AK9: =AK5+AK6-AK7-AK8 -> 25226.752 | AL9: =AL5+AL6-AL7-AL8 -> 26763.287 | AM9: =AM5+AM6-AM7-AM8 -> 28393.412
A12: Metrics | B12: Value | I12: Metrics | J12: Value | Q12: Metrics | R12: Value | Y12: Metrics | Z12: Value | AG12: Metrics | AH12: Value
A13: Terminal Value | B13: =G9*(1+'Assumptions & WACC'!B25)/('Assumptions & WACC'!B21-'Assumptions & WACC'!B25) -> 1759902.8 | I13: Terminal Value | J13: =O9*(1+'Assumptions & WACC'!C25)/('Assumptions & WACC'!C21-'Assumptions & WACC'!C25) -> 934330.73 | Q13: Terminal Value | R13: =W9*(1+'Assumptions & WACC'!D25)/('Assumptions & WACC'!D21-'Assumptions & WACC'!D25) -> 412394.15 | Y13: Terminal Value | Z13: =AE9*(1+'Assumptions & WACC'!E25)/('Assumptions & WACC'!E21-'Assumptions & WACC'!E25) -> 227114.63 | AG13: Terminal Value | AH13: =AM9*(1+'Assumptions & WACC'!F25)/('Assumptions & WACC'!F21-'Assumptions & WACC'!F25) -> 360280.28
A14: PV of Terminal value | B14: =B13*'Assumptions & WACC'!B23 -> 1295698.8 | I14: PV of Terminal value | J14: =J13*'Assumptions & WACC'!C23 -> 634802.1 | Q14: PV of Terminal value | R14: =R13*'Assumptions & WACC'!D23 -> 309616.07 | Y14: PV of Terminal value | Z14: =Z13*'Assumptions & WACC'!E23 -> 162447.65 | AG14: PV of Terminal value | AH14: =AH13*'Assumptions & WACC'!F23 -> 243497.95
A15: PV of FCFF | B15: =NPV('Assumptions & WACC'!B21,DCF!B9:G9) -> 445529.29 | I15: PV of FCFF | J15: =NPV('Assumptions & WACC'!C21,DCF!J9:O9) -> 278406.69 | Q15: PV of FCFF | R15: =NPV('Assumptions & WACC'!D21,DCF!R9:W9) -> 102487.18 | Y15: PV of FCFF | Z15: =NPV('Assumptions & WACC'!E21,DCF!Z9:AE9) -> 59262.394 | AG15: PV of FCFF | AH15: =NPV('Assumptions & WACC'!F21,DCF!AH9:AM9) -> 110968.75
A16: Total enterprise value | B16: =B14+B15 -> 1741228.1 | I16: Total enterprise value | J16: =J14+J15 -> 913208.79 | Q16: Total enterprise value | R16: =R14+R15 -> 412103.25 | Y16: Total enterprise value | Z16: =Z14+Z15 -> 221710.04 | AG16: Total enterprise value | AH16: =AH14+AH15 -> 354466.71
A17: Net debt | B17: ='Assumptions & WACC'!B16-'Assumptions & WACC'!B24 -> 18523 | I17: Net debt | J17: ='Assumptions & WACC'!C16-'Assumptions & WACC'!C24 -> 17760 | Q17: Net debt | R17: ='Assumptions & WACC'!D16-'Assumptions & WACC'!D24 -> 18717 | Y17: Net debt | Z17: ='Assumptions & WACC'!E16-'Assumptions & WACC'!E24 -> 24271 | AG17: Net debt | AH17: ='Assumptions & WACC'!F16-'Assumptions & WACC'!F24 -> 18324
A18: Total equity value | B18: =B16-B17 -> 1722705.1 | I18: Total equity value | J18: =J16-J17 -> 895448.79 | Q18: Total equity value | R18: =R16-R17 -> 393386.25 | Y18: Total equity value | Z18: =Z16-Z17 -> 197439.04 | AG18: Total equity value | AH18: =AH16-AH17 -> 336142.71
A19: Outstanding shares | B19: ='Assumptions & WACC'!B26 -> 4217.166 | I19: Outstanding shares | J19: ='Assumptions & WACC'!C26 -> 2013.522 | Q19: Outstanding shares | R19: ='Assumptions & WACC'!D26 -> 1235.718 | Y19: Outstanding shares | Z19: ='Assumptions & WACC'!E26 -> 300.6025 | AG19: Outstanding shares | AH19: ='Assumptions & WACC'!F26 -> 402.9211
A20: Intrinsic value | B20: =B18/B19 -> 408.49829 | I20: Intrinsic value | J20: =J18/J19 -> 444.71766 | Q20: Intrinsic value | R20: =R18/R19 -> 318.34629 | Y20: Intrinsic value | Z20: =Z18/Z19 -> 656.81103 | AG20: Intrinsic value | AH20: =AH18/AH19 -> 834.26434
A21: Current market price | B21: ='Company Profile'!B3 -> 119.03 | I21: Current market price | J21: ='Company Profile'!C3 -> 153.59 | Q21: Current market price | R21: ='Company Profile'!D3 -> 89.66 | Y21: Current market price | Z21: ='Company Profile'!E3 -> 199.61 | AG21: Current market price | AH21: ='Company Profile'!F3 -> 138.41
A22: Upside/Downside | B22: =(B20-B21)/B21 -> 2.4318936 | I22: Upside/Downside | J22: =(J20-J21)/J21 -> 1.8954858 | Q22: Upside/Downside | R22: =(R20-R21)/R21 -> 2.5505944 | Y22: Upside/Downside | Z22: =(Z20-Z21)/Z21 -> 2.2904716 | AG22: Upside/Downside | AH22: =(AH20-AH21)/AH21 -> 5.027486

Sheet Relative
A1: RELATIVE
A2: Company | B2: EV/EBITDA | C2: P/E | D2: P/S | E2: P/B
A3: #VALUE! | B3: 9.98 | C3: {=_FV(A3,"P/E",TRUE)} -> 24.7344 | D3: 1.78 | E3: 2.01 | H3: Company | I3: EV/EBITDA | J3: P/E | K3: P/S | L3: P/B | M3: Shares
A4: #VALUE! | B4: 6.43 | C4: {=_FV(A4,"P/E",TRUE)} -> 17.3025 | D4: 1.33 | E4: 1.74 | H4: Exxon | I4: =(B23*$B$20)/Relative!M4 -> 126.285 | J4: =(C23*$C$20)/Relative!M4 -> 122.37447 | K4: =(D23*$D$20)/Relative!M4 -> 100.30382 | L4: =(E23*$E$20)/Relative!M4 -> 95.930767 | M4: ='Assumptions & WACC'!B26 -> 4217.166
A5: #VALUE! | B5: 6.67 | C5: {=_FV(A5,"P/E",TRUE)} -> 21.6919 | D5: 1.37 | E5: 1.64 | H5: Chevron | I5: =(B24*$B$20)/Relative!M5 -> 171.30489 | J5: =(C24*$C$20)/Relative!M5 -> 129.74181 | K5: =(D24*$D$20)/Relative!M5 -> 121.86523 | L5: =(E24*$E$20)/Relative!M5 -> 113.71602 | M5: ='Assumptions & WACC'!C26 -> 2013.522
A6: #VALUE! | B6: 5.75 | C6: {=_FV(A6,"P/E",TRUE)} -> 31.0422 | D6: 1.75 | E6: 1.76 | H6: =A25 -> Conoco | I6: =(B25*$B$20)/Relative!M6 -> 149.90373 | J6: =(C25*$C$20)/Relative!M6 -> 110.11589 | K6: =(D25*$D$20)/Relative!M6 -> 55.767683 | L6: =(E25*$E$20)/Relative!M6 -> 78.391688 | M6: ='Assumptions & WACC'!D26 -> 1235.718
A7: #VALUE! | B7: 6.94 | C7: {=_FV(A7,"P/E",TRUE)} -> 9.3829 | D7: 0.25 | E7: 1.06 | H7: =A26 -> MP | I7: =(B26*$B$20)/Relative!M7 -> 246.65108 | J7: =(C26*$C$20)/Relative!M7 -> 248.09657 | K7: =(D26*$D$20)/Relative!M7 -> 565.1933 | L7: =(E26*$E$20)/Relative!M7 -> 120.86721 | M7: ='Assumptions & WACC'!E26 -> 300.6025
A8: #VALUE! | B8: 4.07 | C8: {=_FV(A8,"P/E",TRUE)} -> 15.4901 | D8: 0.68 | E8: 1.02 | H8: =A27 -> Phillips66 | I8: =(B27*$B$20)/Relative!M8 -> 113.49703 | J8: =(C27*$C$20)/Relative!M8 -> 79.451426 | K8: =(D27*$D$20)/Relative!M8 -> 436.93458 | L8: =(E27*$E$20)/Relative!M8 -> 105.60922 | M8: ='Assumptions & WACC'!F26 -> 402.9211
A9: #VALUE! | B9: 3.44 | C9: {=_FV(A9,"P/E",TRUE)} -> 10.0375 | D9: 0.63 | E9: 1.06
A10: #VALUE! | B10: 5.45 | C10: {=_FV(A10,"P/E",TRUE)} -> 12.6867 | D10: 2.11 | E10: 2.54
A11: #VALUE! | B11: 3.73 | C11: 10.7 | D11: 3.18 | E11: 1.95
A12: #VALUE! | B12: 4.3 | C12: {=_FV(A12,"P/E",TRUE)} -> 8.5731 | D12: 0.5 | E12: 0.85
A13: #VALUE! | B13: 1.35 | C13: 1.88 | D13: 0.48 | E13: 0.89
A14: #VALUE! | B14: 12.83 | C14: 20.08 | D14: 2.66 | E14: 2.22 | H14: Company | I14: Target Price | J14: CMP | K14: U/D
A15: #VALUE! | B15: 2.53 | C15: {=_FV(A15,"P/E",TRUE)} -> 18.2492 | D15: 0.47 | E15: 0.79 | H15: =H4 -> Exxon | I15: =AVERAGE(I4:L4) -> 111.22351 | J15: ='Company Profile'!B3 -> 119.03 | K15: =(Table24[[#This Row],[Target Price]]-J15)/J15 -> -0.0655842
A16: #VALUE! | B16: 4.24 | C16: {=_FV(A16,"P/E",TRUE)} -> 14.7243 | D16: 1.2 | E16: 1.41 | H16: =H5 -> Chevron | I16: =AVERAGE(I5:L5) -> 134.15699 | J16: ='Company Profile'!C3 -> 153.59 | K16: =(Table24[[#This Row],[Target Price]]-J16)/J16 -> -0.12652525
A17: #VALUE! | B17: 5.84 | C17: {=_FV(A17,"P/E",TRUE)} -> 7.3606 | D17: 0.28 | E17: 1.62 | H17: =H6 -> Conoco | I17: =AVERAGE(I6:L6) -> 98.544746 | J17: ='Company Profile'!D3 -> 89.66 | K17: =(Table24[[#This Row],[Target Price]]-J17)/J17 -> 0.099093759
A18: #VALUE! | B18: 4.52 | C18: 11.56 | D18: 0.69 | E18: 1.36 | H18: =H7 -> MP | I18: =AVERAGE(I7:L7) -> 295.20204 | J18: ='Company Profile'!E3 -> 199.61 | K18: =(Table24[[#This Row],[Target Price]]-J18)/J18 -> 0.47889405
H19: =H8 -> Phillips66 | I19: =AVERAGE(I8:L8) -> 183.87306 | J19: ='Company Profile'!F3 -> 138.41 | K19: =(Table24[[#This Row],[Target Price]]-J19)/J19 -> 0.32846661
A20: Average | B20: =AVERAGE(B3:B18) -> 5.504375 | C20: =AVERAGE(C3:C18) -> 14.718463 | D20: =AVERAGE(D3:D18) -> 1.21 | E20: =AVERAGE(E3:E18) -> 1.495
A22: Company | B22: EBITDA | C22: Net Income | D22: Revenue | E22: Book Value
A23: =H4 -> Exxon | B23: =Financials!F6+Financials!F7 -> 96753 | C23: =Financials!F10 -> 35063 | D23: =Financials!F3 -> 349585 | E23: =Financials!F22 -> 270606
A24: =H5 -> Chevron | B24: =Financials!M6+Financials!M7 -> 62664 | C24: =Financials!M10 -> 17749 | D24: =Financials!M3 -> 202792 | E24: =Financials!M22 -> 153157
A25: Conoco | B25: =Financials!T6+Financials!T7 -> 33653 | C25: =Financials!T10 -> 9245 | D25: =Financials!T3 -> 56953 | E25: =Financials!T22 -> 64796
A26: MP | B26: =Financials!AB6+Financials!AB7 -> 13470 | C26: =Financials!AB10 -> 5067 | D26: =Financials!AB3 -> 140412 | E26: =Financials!AB22 -> 24303
A27: Phillips66 | B27: =Financials!AJ6+Financials!AJ7 -> 8308 | C27: =Financials!AJ10 -> 2175 | D27: =Financials!AJ3 -> 145496 | E27: =Financials!AJ22 -> 28463

Sheet Calc
A1: Year | B1: Particulars | C1: Company | D1: Value | F1: Company | G1: Change in EBIT (historical) | H1: Change in CE | I1: Incremental ROCE (Historical) | J1: Change in EBIT (Forecast) | K1: Capex | L1: Depreciation | M1: Effective capital | N1: Raw ROCE | O1: Adjusted ROCE (Forecast) | Q1: Particulars | R1: 2020 | S1: 2021 | T1: 2022 | U1: 2023 | V1: 2024
A2: 2020-24 | B2: Avg Capex | C2: =Relative!A23 -> Exxon | D2: =AVERAGE(Financials!B27:F27) -> 18798 | F2: =C2 -> Exxon | G2: =Financials!F6-Financials!B6 -> 55027 | H2: =(453475-Financials!F20)-(332750-Financials!B20) -> 106781 | I2: =G2/H2 -> 0.51532576 | J2: =DCF!G4-DCF!B4 -> 35687.307 | K2: =D8 -> 29804.355 | L2: =AVERAGE(DCF!B6:G6) -> 42725.918 | M2: =IF(K2-L2<=0,K2,MAX(K2-L2,0.1*K2)) -> 29804.355 | N2: =J2/M2 -> 1.1973856 | O2: =MIN(MAX(N2,0.07),0.18) -> 0.18 | Q2: Revenue | R2: {=Financials!B3:F3} -> 181502 | S2: 285640 | T2: 413680 | U2: 344582 | V2: 349585
A3: 2020-24 | B3: Avg Capex | C3: =Relative!A24 -> Chevron | D3: =AVERAGE(Financials!I27:M27) -> 12245.8 | F3: =C3 -> Chevron | G3: =Financials!M6-Financials!I6 -> 32630 | H3: =(256938-Financials!M20)-(237000-Financials!I20) -> 3563 | I3: =G3/H3 -> 9.1580129 | J3: =DCF!O4-DCF!J4 -> 24262.205 | K3: =D9 -> 19973.994 | L3: =AVERAGE(DCF!J6:O6) -> 28824.612 | M3: =IF(K3-L3<=0,K3,MAX(K3-L3,0.1*K3)) -> 19973.994 | N3: =J3/M3 -> 1.2146897 | O3: =MIN(MAX(N3,0.07),0.18) -> 0.18 | Q3: Operating income | R3: {=Financials!B6:F6} -> 18284 | S3: 52788 | T3: 102591 | U3: 74273 | V3: 73311 | Y3: Company | Z3: WACC | AA3: Terminal growth | AB3: Cost of equity | AC3: Intrinsic Value | AD3: Share price | AE3: Upside/Downside
A4: 2020-24 | B4: Avg Capex | C4: ConocoP | D4: =AVERAGE(Financials!P27:T27) -> 8712.8 | F4: =C4 -> ConocoP | G4: =Financials!T6-Financials!P6 -> 20867 | H4: =(Financials!T15-Financials!T20)-(Financials!P15-Financials!P20) -> 53404 | I4: =G4/H4 -> 0.39073852 | J4: =Table941[[#This Row],[2030]]-Table941[[#This Row],[2025]] -> 5847.8058 | K4: =D10 -> 10819.968 | L4: =AVERAGE(DCF!R6:W6) -> 9463.374 | M4: =IF(K4-L4<=0,K4,MAX(K4-L4,0.1*K4)) -> 1356.5941 | N4: =J4/M4 -> 4.3106525 | O4: =MIN(MAX(N4,0.07),0.18) -> 0.18 | Q4: Net Income | R4: {=Financials!B10:F10} -> -23251 | S4: 23598 | T4: 57577 | U4: 37354 | V4: 35063 | Y4: ExxonMobil | Z4: ='Assumptions & WACC'!B21 -> 0.063155827 | AA4: ='Assumptions & WACC'!$B$25 -> 0.0025 | AB4: ='Assumptions & WACC'!B12 -> 0.067104 | AC4: =DCF!B20 -> 408.49829 | AD4: =DCF!B21 -> 119.03 | AE4: =(AC4-AD4)/AD4 -> 2.4318936
A5: 2020-24 | B5: Avg Capex | C5: MP | D5: =AVERAGE(Financials!X27:AB27) -> 2218.8 | F5: =C5 -> MP | G5: =Financials!AB6-Financials!X6 -> 19005 | H5: =(Financials!AB15-Financials!AB20)-(Financials!X15-Financials!X20) -> -11464 | I5: =G5/H5 -> -1.6577983 | J5: =DCF!AE4-DCF!Z4 -> 3049.7894 | K5: =D11 -> 2692.6277 | L5: =AVERAGE(DCF!Z6:AE6) -> 4028.505 | M5: =IF(K5-L5<=0,K5,MAX(K5-L5,0.1*K5)) -> 2692.6277 | N5: =J5/M5 -> 1.1326443 | O5: =MIN(MAX(N5,0.07),0.18) -> 0.18 | Y5: Chevron | Z5: ='Assumptions & WACC'!C21 -> 0.080369852 | AA5: ='Assumptions & WACC'!$B$25 -> 0.0025 | AB5: ='Assumptions & WACC'!C12 -> 0.08541 | AC5: =DCF!J20 -> 444.71766 | AD5: =DCF!J21 -> 153.59 | AE5: =(AC5-AD5)/AD5 -> 1.8954858
A6: 2020-24 | B6: Avg Capex | C6: Phillips66 | D6: =AVERAGE(Financials!AF27:AJ27) -> 2199.2 | F6: =C6 -> Phillips66 | G6: =Financials!$AJ6-Financials!$AF6 -> 9015 | H6: =(Financials!AJ15-Financials!AJ20)-(Financials!AF15-Financials!AF20) -> 12292 | I6: =G6/H6 -> 0.73340384 | J6: =DCF!AM4-DCF!AH4 -> 9505.492 | K6: =D12 -> 3035.9913 | L6: =AVERAGE(Table94145[[#This Row],[2025]:[2030]]) -> 2476.3374 | M6: =IF(K6-L6<=0,K6,MAX(K6-L6,0.1*K6)) -> 559.6539 | N6: =J6/M6 -> 16.98459 | O6: =MIN(MAX(N6,0.07),0.18) -> 0.18 | Q6: Particulars | R6: 2020 | S6: 2021 | T6: 2022 | U6: 2023 | V6: 2024
A7: 2020-24 | B7: Avg Capex | C7: Average | D7: =AVERAGE(D2:D6) -> 8834.92 | H7: Average | I7: =AVERAGE(I2:I6) -> 1.8279365 | M7: Average | N7: =AVERAGE(N2:N3) -> 1.2060377 | O7: =AVERAGE(O2:O3) -> 0.18 | Q7: Revenue | R7: {=Financials!I3:M3} -> 94692 | S7: 162465 | T7: 246252 | U7: 200949 | V7: 202792
A8: 2025-30 | B8: Avg Capex | C8: =C2 -> Exxon | D8: =AVERAGE(DCF!B7:G7) -> 29804.355 | Q8: Operating income | R8: {=Financials!I6:M6} -> 12752 | S8: 40276 | T8: 66509 | U8: 47379 | V8: 45382
A9: 2025-30 | B9: Avg Capex | C9: =C3 -> Chevron | D9: =AVERAGE(DCF!J7:O7) -> 19973.994 | G9: Metric | H9: 2020-24 | I9: 2025-30 | Q9: Net Income | R9: {=Financials!I10:M10} -> -5561 | S9: 15689 | T9: 35608 | U9: 21411 | V9: 17749
A10: 2025-30 | B10: Avg Capex | C10: =C4 -> ConocoP | D10: =AVERAGE(DCF!R7:W7) -> 10819.968 | G10: GDP | H10: =AVERAGE(-0.035,0.058) -> 0.0115 | I10: 0.018
A11: 2025-30 | B11: Avg Capex | C11: =C5 -> MP | D11: =AVERAGE(DCF!Z7:AE7) -> 2692.6277 | G11: GDP | H11: 0.028 | I11: 0.026 | Q11: Particulars | R11: 2025 | S11: 2026 | T11: 2027 | U11: 2028 | V11: 2029 | W11: 2030
A12: 2025-30 | B12: Avg Capex | C12: =C6 -> Phillips66 | D12: =AVERAGE(DCF!AH7:AM7) -> 3035.9913 | G12: Change | H12: =H11-H10 -> 0.0165 | I12: =I11-I10 -> 0.008 | Q12: Revenue | R12: {=DCF!B3:G3} -> 398553.9 | S12: 446380.37 | T12: 491018.41 | U12: 530299.88 | V12: 556814.87 | W12: 573519.32
A13: 2025-30 | B13: Avg Capex | C13: =C7 -> Average | D13: =AVERAGE(D8:D12) -> 13265.387 | G13: Sensitivity | H13: =D61/H12 -> 172.37071 | I13: =D67/I12 -> 41.361066 | Q13: Operating income | R13: {=DCF!B4:G4} -> 81292.152 | S13: 91047.21 | T13: 100151.93 | U13: 108164.09 | V13: 113572.29 | W13: 116979.46
A14: 2025-30 | B14: Capex CAGR | C14: =C8 -> Exxon | D14: =(DCF!G7/DCF!B7)^(1/6)-1 -> 0.062535619 | Q14: Net Income | R14: {=DCF!B5:G5} -> 64220.8 | S14: 71927.296 | T14: 79120.026 | U14: 85449.628 | V14: 89722.109 | W14: 92413.772
A15: 2025-30 | B15: Capex CAGR | C15: =C9 -> Chevron | D15: =(DCF!O7/DCF!J7)^(1/6)-1 -> 0.062535619 | Q15: FCFF | R15: {=DCF!B9:G9} -> 77843.086 | S15: 81271.621 | T15: 89766.229 | U15: 97359.068 | V15: 102906.06 | W15: 106482.15
A16: 2025-30 | B16: Capex CAGR | C16: =C10 -> ConocoP | D16: =(DCF!W7/DCF!R7)^(1/6)-1 -> 0.034709805
A17: 2025-30 | B17: Capex CAGR | C17: =C11 -> MP | D17: =(DCF!AE7/DCF!Z7)^(1/6)-1 -> 0.031607805 | Q17: Particulars | R17: 2025 | S17: 2026 | T17: 2027 | U17: 2028 | V17: 2029 | W17: 2030
A18: 2025-30 | B18: Capex CAGR | C18: =C12 -> Phillips66 | D18: =(DCF!AM7/DCF!AH7)^(1/6)-1 -> 0.050505754 | Q18: Revenue | R18: {=DCF!J3:O3} -> 236155.64 | S18: 264494.32 | T18: 290943.75 | U18: 314219.25 | V18: 329930.21 | W18: 339828.12
A19: 2025-30 | B19: Capex CAGR | C19: =C13 -> Average | D19: =AVERAGE(D14:D18) -> 0.048378921 | Q19: Operating income | R19: {=DCF!J4:O4} -> 55266.902 | S19: 61898.93 | T19: 68088.823 | U19: 73535.929 | V19: 77212.726 | W19: 79529.108
A20: =A14 -> 2025-30 | B20: Earnings CAGR | C20: =C14 -> Exxon | D20: =D14 -> 0.062535619 | Q20: Net Income | R20: {=DCF!J5:O5} -> 43660.853 | S20: 48900.155 | T20: 53790.171 | U20: 58093.384 | V20: 60998.053 | W20: 62827.995
A21: =A15 -> 2025-30 | B21: Earnings CAGR | C21: =C15 -> Chevron | D21: =D15 -> 0.062535619 | Q21: FCFF | R21: {=DCF!J9:O9} -> 43132.293 | S21: 55617.3 | T21: 61377.92 | U21: 66510.91 | V21: 70204.004 | W21: 72574.759
A22: =A16 -> 2025-30 | B22: Earnings CAGR | C22: =C16 -> ConocoP | D22: =D16 -> 0.034709805
A23: =A17 -> 2025-30 | B23: Earnings CAGR | C23: =C17 -> MP | D23: =D17 -> 0.031607805
A24: =A18 -> 2025-30 | B24: Earnings CAGR | C24: =C18 -> Phillips66 | D24: =D18 -> 0.050505754
A25: =A19 -> 2025-30 | B25: Earnings CAGR | C25: =C19 -> Average | D25: =AVERAGE(D20:D24) -> 0.048378921
A26: =A20 -> 2025-30 | B26: Revenue CAGR | C26: =C20 -> Exxon | D26: =D20 -> 0.062535619
A27: =A21 -> 2025-30 | B27: Revenue CAGR | C27: =C21 -> Chevron | D27: =D21 -> 0.062535619
A28: =A22 -> 2025-30 | B28: Revenue CAGR | C28: =C22 -> ConocoP | D28: =D22 -> 0.034709805
A29: =A23 -> 2025-30 | B29: Revenue CAGR | C29: =C23 -> MP | D29: =D23 -> 0.031607805
A30: =A24 -> 2025-30 | B30: Revenue CAGR | C30: =C24 -> Phillips66 | D30: =D24 -> 0.050505754
A31: =A25 -> 2025-30 | B31: Revenue CAGR | C31: =C25 -> Average | D31: =AVERAGE(D26:D30) -> 0.048378921
A32: =A2 -> 2020-24 | B32: EBITDA Margin | C32: =C26 -> Exxon | D32: =(AVERAGE(Financials!B6:F6)+AVERAGE(Financials!B7:F7))/AVERAGE(Financials!B3:F3) -> 0.28951694
A33: =A3 -> 2020-24 | B33: EBITDA Margin | C33: =C27 -> Chevron | D33: =(AVERAGE(Financials!I6:M6)+AVERAGE(Financials!I7:M7))/AVERAGE(Financials!I3:M3) -> 0.33143141
A34: =A4 -> 2020-24 | B34: EBITDA Margin | C34: =C28 -> ConocoP | D34: =(AVERAGE(Financials!P6:T6)+AVERAGE(Financials!P7:T7))/AVERAGE(Financials!P3:T3) -> 0.55796719
A35: =A5 -> 2020-24 | B35: EBITDA Margin | C35: =C29 -> MP | D35: =(AVERAGE(Financials!X6:AB6)+AVERAGE(Financials!X7:AB7))/AVERAGE(Financials!X3:AB3) -> 0.10297397
A36: =A6 -> 2020-24 | B36: EBITDA Margin | C36: =C30 -> Phillips66 | D36: =(AVERAGE(Financials!AF6:AJ6)+AVERAGE(Financials!AF7:AJ7))/AVERAGE(Financials!AF3:AJ3) -> 0.069078372
A37: =$A$36 -> 2020-24 | B37: EBITDA Margin | C37: =C31 -> Average | D37: =AVERAGE(D32:D36) -> 0.27019358
A38: =$A$36 -> 2020-24 | B38: NPM | C38: =C32 -> Exxon | D38: =AVERAGE(Financials!B10:F10)/AVERAGE(Financials!B3:F3) -> 0.082756768
A39: =$A$36 -> 2020-24 | B39: NPM | C39: =C33 -> Chevron | D39: =AVERAGE(Financials!I10:M10)/AVERAGE(Financials!I3:M3) -> 0.093585405
A40: =A32 -> 2020-24 | B40: NPM | C40: =C34 -> ConocoP | D40: =AVERAGE(Financials!P10:T10)/AVERAGE(Financials!P3:T3) -> 0.16701095
...
