Workbook

Sheet Profile
A1: Company | B1: #VALUE! | C1: #VALUE! | D1: #VALUE! | E1: #VALUE! | F1: #VALUE!
A2: Name | B2: {=_FV(B1,"Official name",TRUE)} -> CATERPILLAR INC. | C2: {=_FV(C1,"Official name",TRUE)} -> JACOBS SOLUTIONS INC. | D2: {=_FV(D1,"Official name",TRUE)} -> AECOM | E2: {=_FV(E1,"Official name",TRUE)} -> FLUOR CORPORATION. | F2: {=_FV(F1,"Official name",TRUE)} -> VULCAN MATERIALS COMPANY
A3: Share price | B3: {=_FV(B1,"Price")} -> 555.91 | C3: {=_FV(C1,"Price")} -> 149.2 | D3: {=_FV(D1,"Price")} -> 116.24 | E3: {=_FV(E1,"Price")} -> 42.03 | F3: {=_FV(F1,"Price")} -> 283.87
A4: Change | B4: {=_FV(B1,"Change (%)",TRUE)} -> 0.016512 | C4: {=_FV(C1,"Change (%)",TRUE)} -> -0.010348 | D4: {=_FV(D1,"Change (%)",TRUE)} -> -0.085732 | E4: {=_FV(E1,"Change (%)",TRUE)} -> 0.021882 | F4: {=_FV(F1,"Change (%)",TRUE)} -> 0.007095
A5: Shares outstanding | B5: {=_FV(B1,"Shares outstanding",TRUE)} -> 467979600 | C5: {=_FV(C1,"Shares outstanding",TRUE)} -> 119536500 | D5: {=_FV(D1,"Shares outstanding",TRUE)} -> 132446100 | E5: {=_FV(E1,"Shares outstanding",TRUE)} -> 161182500 | F5: {=_FV(F1,"Shares outstanding",TRUE)} -> 132130900
A6: in mn | B6: =B5/1000000 -> 467.9796 | C6: =C5/1000000 -> 119.5365 | D6: =D5/1000000 -> 132.4461 | E6: =E5/1000000 -> 161.1825 | F6: =F5/1000000 -> 132.1309
A7: Market cap | B7: {=_FV(B1,"Market cap",TRUE)} -> 260154539436 | C7: {=_FV(C1,"Market cap",TRUE)} -> 17834845800 | D7: {=_FV(D1,"Market cap",TRUE)} -> 15395534664 | E7: {=_FV(E1,"Market cap",TRUE)} -> 6774500475 | F7: {=_FV(F1,"Market cap",TRUE)} -> 37507998583
A8: in mn | B8: =B7/1000000 -> 260154.54 | C8: =C7/1000000 -> 17834.846 | D8: =D7/1000000 -> 15395.535 | E8: =E7/1000000 -> 6774.5005 | F8: =F7/1000000 -> 37507.999
A9: Beta | B9: {=_FV(B1,"Beta")} -> 1.5679 | C9: {=_FV(C1,"Beta")} -> 0.8001 | D9: {=_FV(D1,"Beta")} -> 1.0415 | E9: {=_FV(E1,"Beta")} -> 1.3441 | F9: {=_FV(F1,"Beta")} -> 1.0667
A10: P/E | B10: {=_FV(B1,"P/E",TRUE)} -> 28.5236 | C10: {=_FV(C1,"P/E",TRUE)} -> 59.35 | D10: {=_FV(D1,"P/E",TRUE)} -> 24.2784 | E10: {=_FV(E1,"P/E",TRUE)} -> 2.1296 | F10: {=_FV(F1,"P/E",TRUE)} -> 33.5449
A11: Year | B11: {=_FV(B1,"Year incorporated",TRUE)} -> 1986 | C11: {=_FV(C1,"Year incorporated",TRUE)} -> 2022 | D11: {=_FV(D1,"Year incorporated",TRUE)} -> 1980 | E11: {=_FV(E1,"Year incorporated",TRUE)} -> 2000 | F11: {=_FV(F1,"Year incorporated",TRUE)} -> 2007

Sheet Financials
A1: INCOME STATEMENT | F1: Caterpillar | H1: INCOME STATEMENT | M1: Jacobs | O1: INCOME STATEMENT | T1: AECOM | W1: INCOME STATEMENT | AB1: Fluor | AE1: INCOME STATEMENT | AJ1: Vulcan
A2: Particulars | B2: 2020 | C2: 2021 | D2: 2022 | E2: 2023 | F2: 2024 | H2: Particulars | I2: 2020 | J2: 2021 | K2: 2022 | L2: 2023 | M2: 2024 | O2: Particulars | P2: 2020 | Q2: 2021 | R2: 2022 | S2: 2023 | T2: 2024 | W2: Particulars | X2: 2020 | Y2: 2021 | Z2: 2022 | AA2: 2023 | AB2: 2024 | AE2: Particulars | AF2: 2020 | AG2: 2021 | AH2: 2022 | AI2: 2023 | AJ2: 2024
A3: Revenue | B3: 41748 | C3: 50971 | D3: 59427 | E3: 67060 | F3: 64809 | H3: Revenue | I3: 13566.975 | J3: 14092.632 | K3: 14922.825 | L3: 10851.42 | M3: 11500.941 | O3: Revenue | P3: 13239.976 | Q3: 13340.852 | R3: 13148.182 | S3: 14378.461 | T3: 16105.498 | W3: Revenue | X3: 15668.477 | Y3: 14156 | Z3: 13744 | AA3: 15474 | AB3: 16315 | AE3: Revenue | AF3: 4856.826 | AG3: 5552.2 | AH3: 7315.2 | AI3: 7781.9 | AJ3: 7417.7
A4: Cost of sales | B4: 29082 | C4: 35513 | D4: 41350 | E4: 42767 | F4: 40199 | H4: Cost of sales | I4: 10980.307 | J4: 11048.86 | K4: 11595.785 | L4: 8140.56 | M4: 8668.185 | O4: Cost of sales | P4: 12530.416 | Q4: 12542.431 | R4: 12300.208 | S4: 13432.996 | T4: 15021.157 | W4: Cost of sales | X4: 15283.226 | Y4: 13702 | Z4: 13389 | AA4: 14997 | AB4: 15741 | AE4: Cost of sales | AF4: 3575.345 | AG4: 4178.8 | AH4: 5757.5 | AI4: 5833.4 | AJ4: 5418.1
A5: Opex | B5: =37195-29082-589 -> 7524 | C5: =44093-35513-455 -> 8125 | D5: =51523-41350-565 -> 9608 | E5: =54094-42767-1030 -> 10297 | F5: =51737-40199-1286 -> 10252 | H5: Opex | I5: 2050.695 | J5: 2355.683 | K5: 2409.19 | L5: 2034.376 | M5: 2140.32 | O5: Opex | P5: =-48.781+188.535+188.345-11.056 -> 317.043 | Q5: =-35.044+155.072+48.84-17.603 -> 151.265 | R5: =147.309+107.501-53.64-14.152 -> 187.018 | S5: =279.352+153.575+188.404-8.357-40.251 -> 572.723 | T5: =-2.124+160.105+98.918-17.57-58.56 -> 180.769 | W5: Opex | X5: =240.692+305.59-0.406-25.693 -> 520.183 | Y5: =226+290+198+13-17 -> 710 | Z5: =237-24-42-25+94 -> 240 | AA5: =232+98-228 -> 102 | AB5: =203-92-196 -> -85 | AE5: Opex | AF5: =359.772+3.997-29.975-17.54+1.567 -> 317.821 | AG5: =417.6+120.1-4.6-60.5-10.7-1.6 -> 460.3 | AH5: =515.1+10.7-67.9-34-5.1-0.8 -> 418 | AI5: =-76.4+28.3+26.4+2.7-16.5+542.8 -> 507.3 | AJ5: =-52.3+86.6+69.7+531.1 -> 635.1
A6: Operating income (EBIT) | B6: =B3-B4-B5 -> 5142 | C6: =C3-C4-C5 -> 7333 | D6: =D3-D4-D5 -> 8469 | E6: =E3-E4-E5 -> 13996 | F6: =F3-F4-F5 -> 14358 | H6: Operating income (EBIT) | I6: =I3-I4-I5 -> 535.973 | J6: =J3-J4-J5 -> 688.089 | K6: =K3-K4-K5 -> 917.85 | L6: =L3-L4-L5 -> 676.484 | M6: =M3-M4-M5 -> 692.436 | O6: Operating income (EBIT) | P6: =P3-P4-P5 -> 392.517 | Q6: =Q3-Q4-Q5 -> 647.156 | R6: =R3-R4-R5 -> 660.956 | S6: =S3-S4-S5 -> 372.742 | T6: =T3-T4-T5 -> 903.572 | W6: Operating income (EBIT) | X6: =X3-X4-X5 -> -134.932 | Y6: =Y3-Y4-Y5 -> -256 | Z6: =Z3-Z4-Z5 -> 115 | AA6: =AA3-AA4-AA5 -> 375 | AB6: =AB3-AB4-AB5 -> 659 | AE6: Operating income (EBIT) | AF6: =AF3-AF4-AF5 -> 963.66 | AG6: =AG3-AG4-AG5 -> 913.1 | AH6: =AH3-AH4-AH5 -> 1139.7 | AI6: =AI3-AI4-AI5 -> 1441.2 | AJ6: =AJ3-AJ4-AJ5 -> 1364.5
A7: Depreciation & Amortization | B7: 2432 | C7: 2352 | D7: 2219 | E7: 2144 | F7: 2153 | H7: Depreciation & Amortization | I7: =91.07+90.563 -> 181.633 | J7: =101.024+149.776 -> 250.8 | K7: =102.454+198.602 -> 301.056 | L7: =103.346+203.906 -> 307.252 | M7: =99.232+209.507 -> 308.739 | O7: Depreciation & Amortization | P7: 237.376 | Q7: 176.4 | R7: 170.886 | S7: 175.725 | T7: 178.812 | W7: Depreciation & Amortization | X7: =102.451+3.123 -> 105.574 | Y7: 74 | Z7: 73 | AA7: 74 | AB7: 73 | AE7: Depreciation & Amortization | AF7: 396.806 | AG7: 463 | AH7: 587.5 | AI7: 617 | AJ7: 632.2
A8: Interest expense | B8: =514+589 -> 1103 | C8: =455+488 -> 943 | D8: =565+443 -> 1008 | E8: =511+1030 -> 1541 | F8: =1286+512 -> 1798 | H8: Interest expense | I8: 62.206 | J8: 72.714 | K8: 100.246 | L8: 168.085 | M8: 169.058 | O8: Interest expense | P8: 159.914 | Q8: 238.352 | R8: 110.274 | S8: 159.342 | T8: 185.42 | W8: Interest expense | X8: 72.12 | Y8: 90 | Z8: 59 | AA8: 60 | AB8: 46 | AE8: Interest expense | AF8: 135.96 | AG8: 149.3 | AH8: 169.2 | AI8: 196.1 | AJ8: 191.2
A9: Income tax | B9: 1006 | C9: 1742 | D9: 2067 | E9: 2781 | F9: 2629 | H9: Income tax | I9: 55.32 | J9: 274.781 | K9: 160.903 | L9: 101.336 | M9: 131.493 | O9: Income tax | P9: 45.753 | Q9: 89.011 | R9: 136.051 | S9: 56.052 | T9: 152.9 | W9: Income tax | X9: 18.592 | Y9: 20 | Z9: 171 | AA9: 236 | AB9: 634 | AE9: Income tax | AF9: =155.803 -> 155.803 | AG9: =133.5+66.6 -> 200.1 | AH9: =133.4+59.6 -> 193 | AI9: =-44.2+343.6 -> 299.4 | AJ9: =-9.9+261.3 -> 251.4
A10: Net income | B10: =B6-B7-B8-B9 -> 601 | C10: =C6-C7-C8-C9 -> 2296 | D10: =D6-D7-D8-D9 -> 3175 | E10: =E6-E7-E8-E9 -> 7530 | F10: =F6-F7-F8-F9 -> 7778 | H10: Net income | I10: =I6-I7-I8-I9 -> 236.814 | J10: =J6-J7-J8-J9 -> 89.794 | K10: =K6-K7-K8-K9 -> 355.645 | L10: =L6-L7-L8-L9 -> 99.811 | M10: =M6-M7-M8-M9 -> 83.146 | O10: Net income | P10: =P6-P7-P8-P9 -> -50.526 | Q10: =Q6-Q7-Q8-Q9 -> 143.393 | R10: =R6-R7-R8-R9 -> 243.745 | S10: =S6-S7-S8-S9 -> -18.377 | T10: =T6-T7-T8-T9 -> 386.44 | W10: Net income | X10: =X6-X7-X8-X9 -> -331.218 | Y10: =Y6-Y7-Y8-Y9 -> -440 | Z10: =Z6-Z7-Z8-Z9 -> -188 | AA10: =AA6-AA7-AA8-AA9 -> 5 | AB10: =AB6-AB7-AB8-AB9 -> -94 | AE10: Net income | AF10: =AF6-AF7-AF8-AF9 -> 275.091 | AG10: =AG6-AG7-AG8-AG9 -> 100.7 | AH10: =AH6-AH7-AH8-AH9 -> 190 | AI10: =AI6-AI7-AI8-AI9 -> 328.7 | AJ10: =AJ6-AJ7-AJ8-AJ9 -> 289.7
A12: BALANCE SHEET | H12: BALANCE SHEET | O12: BALANCE SHEET | W12: BALANCE SHEET | AE12: BALANCE SHEET
A13: Particulars | B13: 2020 | C13: 2021 | D13: 2022 | E13: 2023 | F13: 2024 | H13: Particulars | I13: 2020 | J13: 2021 | K13: 2022 | L13: 2023 | M13: 2024 | O13: Particulars | P13: 2020 | Q13: 2021 | R13: 2022 | S13: 2023 | T13: 2024 | W13: Particulars | X13: 2020 | Y13: 2021 | Z13: 2022 | AA13: 2023 | AB13: 2024 | AE13: Particulars | AF13: 2020 | AG13: 2021 | AH13: 2022 | AI13: 2023 | AJ13: 2024
A14: Cash & Cash equivalents | B14: 9352 | C14: 9254 | D14: 7004 | E14: 6978 | F14: 6889 | H14: Cash & Cash equivalents | I14: 862.424 | J14: 1014.249 | K14: 1140.479 | L14: 770.853 | M14: 1144.795 | O14: Cash & Cash equivalents | P14: 1708.332 | Q14: 1229.196 | R14: 1172.209 | S14: 1260.206 | T14: 1580.877 | W14: Cash & Cash equivalents | X14: 2198.781 | Y14: 2209 | Z14: 2439 | AA14: 2519 | AB14: 2829 | AE14: Cash & Cash equivalents | AF14: 1197.068 | AG14: 235 | AH14: 161.4 | AI14: 931.1 | AJ14: 559.7
A15: Accounts receivables | B15: =7317+9463 -> 16780 | C15: =8477+8898 -> 17375 | D15: =8856+9013 -> 17869 | E15: =9310+9510 -> 18820 | F15: =9282+9565 -> 18847 | H15: Accounts receivables | I15: 3167.31 | J15: 3101.418 | K15: 3405.381 | L15: 2430.941 | M15: 2845.452 | O15: Total assets | P15: 12998.951 | Q15: 11733.954 | R15: 11139.315 | S15: 11233.398 | T15: 12061.669 | W15: Total assets | X15: 7309.812 | Y15: 7089 | Z15: 6827 | AA15: 6973 | AB15: 9143 | AE15: Total assets | AF15: 11686.905 | AG15: 13682.6 | AH15: 14234.6 | AI15: 14545.7 | AJ15: 17104.8
A16: Inventories | B16: 11402 | C16: 14038 | D16: 18270 | E16: 16565 | F16: 16827 | H16: Inventories | I16: 0 | J16: 0 | K16: 0 | L16: 0 | M16: 0 | O16: Inventories | P16: 0 | Q16: 0 | R16: 0 | S16: 0 | T16: 0 | W16: Inventories | X16: 0 | Y16: 0 | Z16: 0 | AA16: 0 | AB16: 0 | AE16: Inventories | AF16: 448.585 | AG16: 521.3 | AH16: 579.3 | AI16: 615.6 | AJ16: 681.8
A17: Total current assets | B17: 39464 | C17: 43455 | D17: 43785 | E17: 46949 | F17: 45682 | H17: Total current assets | I17: 4539.599 | J17: 4291.895 | K17: 4721.994 | L17: 4690.353 | M17: 4895.58 | O17: Total current assets | P17: 7530.366 | Q17: 6173.543 | R17: 5822.81 | S17: 6169.511 | T17: 7176.059 | W17: Total current assets | X17: 5034.009 | Y17: 5181 | Z17: 5044 | AA17: 5063 | AB17: 5175 | AE17: Total current assets | AF17: 2277.165 | AG17: 1696.6 | AH17: 1902 | AI17: 2524.9 | AJ17: 2265.7
A18: PPE | B18: 12401 | C18: 12090 | D18: 12028 | E18: 12680 | F18: 13361 | H18: PPE | I18: 319.371 | J18: 353.117 | K18: 346.676 | L18: 279.749 | M18: 315.63 | O18: PPE | P18: 381.672 | Q18: 398.876 | R18: 428.239 | S18: 382.638 | T18: 354.377 | W18: PPE | X18: 561.084 | Y18: 456 | Z18: 447 | AA18: 458 | AB18: 494 | AE18: PPE | AF18: 4425.999 | AG18: 5546.8 | AH18: 6051.3 | AI18: 6217.7 | AJ18: 8461.5
A19: Accounts payables | B19: 6128 | C19: 8154 | D19: 8689 | E19: 7906 | F19: 7675 | H19: Accounts payables | I19: 1061.754 | J19: 908.441 | K19: 966.792 | L19: 922.355 | M19: 1029.14 | O19: Accounts payables | P19: 2352.144 | Q19: 2090.479 | R19: 2027.314 | S19: 2190.755 | T19: 2560.122 | W19: Accounts payables | X19: 1232.236 | Y19: 1220 | Z19: 1017 | AA19: 1214 | AB19: 1220 | AE19: Accounts payables | AF19: 273.08 | AG19: 365.5 | AH19: 454.5 | AI19: 390.4 | AJ19: 407
A20: Total current liabilities | B20: 25717 | C20: 29847 | D20: 31531 | E20: 34728 | F20: 32272 | H20: Total current liabilities | I20: 2941.597 | J20: 3209.924 | K20: 3250.845 | L20: 3422.561 | M20: 4079.741 | O20: Total current liabilities | P20: 6090.454 | Q20: 5521.715 | R20: 5404.171 | S20: 5852.283 | T20: 6374.081 | W20: Total current liabilities | X20: 3572.037 | Y20: 3614 | Z20: 3216 | AA20: 3163 | AB20: 3071 | AE20: Total current liabilities | AF20: 1047.883 | AG20: 769.3 | AH20: 956.6 | AI20: 797.6 | AJ20: 1239.1
A21: Total debt | B21: =10+2005+9749+16250 -> 28014 | C21: =9+5395+9746+16287 -> 31437 | D21: =3+5954+9498+16216 -> 31671 | E21: =4643+8763+24472 -> 37878 | F21: =4393+6665+27351 -> 38409 | H21: Total debt | I21: =1676.941 -> 1676.941 | J21: =53.456+2839.933 -> 2893.389 | K21: =50.415+3357.256 -> 3407.671 | L21: =61.43+2813.471 -> 2874.901 | M21: =875.76+1348.594 -> 2224.354 | O21: Total debt | P21: =0.223+20.651+2041.136 -> 2062.01 | Q21: =4.369+49.469+2157.74 -> 2211.578 | R21: =5.032+43.574+2156.686 -> 2205.292 | S21: =3.085+86.369+2113.369 -> 2202.823 | T21: =3.08+63.844+2450.33 -> 2517.254 | W21: Total debt | X21: =25.415+1710.033 -> 1735.448 | Y21: =18+1174 -> 1192 | Z21: =152+978 -> 1130 | AA21: =1158 -> 1158 | AB21: 1104 | AE21: Total debt | AF21: =515.435+2772.24 -> 3287.675 | AG21: =5.2+0+3874.8 -> 3880 | AH21: =0.5+100+3875.2 -> 3975.7 | AI21: =0.5+3877.3 -> 3877.8 | AJ21: =400.5+4906.9 -> 5307.4
A22: Shareholder's equity | B22: 15378 | C22: 16516 | D22: 15891 | E22: 19503 | F22: 19494 | H22: Shareholder's equity | I22: 5855.667 | J22: 5974.837 | K22: 6104.392 | L22: 6600.082 | M22: 4567.303 | O22: Shareholder's equity | P22: 3413.544 | Q22: 2829.577 | R22: =2605.379 -> 2605.379 | S22: 2383.711 | T22: 2370.41 | W22: Shareholder's equity | X22: 1263.227 | Y22: 1567 | Z22: 1996 | AA22: 2052 | AB22: 3992 | AE22: Shareholder's equity | AF22: 6027.33 | AG22: 6567.7 | AH22: 6952.2 | AI22: 7507.9 | AJ22: 8142.5
A24: CASH FLOW STATEMENT | H24: CASH FLOW STATEMENT | O24: CASH FLOW STATEMENT | W24: CASH FLOW STATEMENT | AE24: CASH FLOW STATEMENT
A25: Particulars | B25: 2020 | C25: 2021 | D25: 2022 | E25: 2023 | F25: 2024 | H25: Particulars | I25: 2020 | J25: 2021 | K25: 2022 | L25: 2023 | M25: 2024 | O25: Particulars | P25: 2020 | Q25: 2021 | R25: 2022 | S25: 2023 | T25: 2024 | W25: Particulars | X25: 2020 | Y25: 2021 | Z25: 2022 | AA25: 2023 | AB25: 2024 | AE25: Particulars | AF25: 2020 | AG25: 2021 | AH25: 2022 | AI25: 2023 | AJ25: 2024
A26: Cash flow from operating activities | B26: 6327 | C26: 7198 | D26: 7766 | E26: 12885 | F26: 12035 | H26: Cash flow from operating activities | I26: 806.849 | J26: 726.275 | K26: 474.709 | L26: 974.763 | M26: 1054.673 | O26: Cash flow from operating activities | P26: 329.622 | Q26: 704.67 | R26: 713.636 | S26: 695.98 | T26: 827.49 | W26: Cash flow from operating activities | X26: 185.884 | Y26: 25 | Z26: 31 | AA26: 212 | AB26: 828 | AE26: Cash flow from operating activities | AF26: 1070.359 | AG26: 1011.9 | AH26: 1148.2 | AI26: 1536.8 | AJ26: 1409.6
A27: Capex | B27: 978 | C27: 1093 | D27: 1296 | E27: 1597 | F27: 1988 | H27: Capex | I27: 118.269 | J27: 92.814 | K27: 127.615 | L27: 137.486 | M27: 121.114 | O27: Capex | P27: 114.591 | Q27: 136.262 | R27: 137.017 | S27: 105.6 | T27: 119.597 | W27: Capex | X27: 113.442 | Y27: 75 | Z27: 75 | AA27: 106 | AB27: 164 | AE27: Capex | AF27: 362.194 | AG27: 451.3 | AH27: 612.6 | AI27: 872.6 | AJ27: 603.5
A28: Dividends paid | B28: 2243 | C28: 2332 | D28: 2440 | E28: 2563 | F28: 2646 | H28: Dividends paid | I28: 143.962 | J28: =107.188+48.784 -> 155.972 | K28: =115.948+26.982 -> 142.93 | L28: =128.42+23.156 -> 151.576 | M28: =142.779+21.678 -> 164.457 | O28: Dividends paid | P28: 0 | Q28: 0 | R28: 63.288 | S28: 96.192 | T28: 115.244 | W28: Dividends paid | X28: 28.72 | Y28: 19 | Z28: 39 | AA28: 29 | AB28: 0 | AE28: Dividends paid | AF28: 180.216 | AG28: 196.4 | AH28: 212.6 | AI28: 228.4 | AJ28: 244.4
A29: Debt repaid | B29: =26+8211 -> 8237 | C29: =1919+7877 -> 9796 | D29: =25+7703 -> 7728 | E29: =6318+1345 -> 7663 | F29: =9316+168 -> 9484 | H29: Debt repaid | I29: =2521.467+200.008 -> 2721.475 | J29: =3216.965+7.675 -> 3224.64 | K29: =2420.166+6.359 -> 2426.525 | L29: =4486.679+3.353 -> 4490.032 | M29: =3370.355+866.761 -> 4237.116 | O29: Debt repaid | P29: 5568.32 | Q29: 2726.347 | R29: 3657.308 | S29: 3552.639 | T29: 5878.475 | W29: Debt repaid | X29: 0 | Y29: 0 | Z29: 0 | AA29: 0 | AB29: 0 | AE29: Debt repaid | AF29: =250.025 -> 250.025 | AG29: =1451.7 -> 1451.7 | AH29: =1261+557.7 -> 1818.7 | AI29: =266.1+550.5 -> 816.6 | AJ29: =8+550.5 -> 558.5
O32: Particulars | P32: 2020 | Q32: 2021 | R32: 2022 | S32: 2023 | T32: 2024 | W32: Particulars | X32: 2020 | Y32: 2021 | Z32: 2022 | AA32: 2023 | AB32: 2024 | AE32: Particulars | AF32: 2020 | AG32: 2021 | AH32: 2022 | AI32: 2023 | AJ32: 2024
O33: Revenue | P33: =P3 -> 13239.976 | Q33: =Q3 -> 13340.852 | R33: =R3 -> 13148.182 | S33: =S3 -> 14378.461 | T33: =T3 -> 16105.498 | W33: Revenue | X33: =X3 -> 15668.477 | Y33: =Y3 -> 14156 | Z33: =Z3 -> 13744 | AA33: =AA3 -> 15474 | AB33: =AB3 -> 16315 | AE33: Revenue | AF33: =AF3 -> 4856.826 | AG33: =AG3 -> 5552.2 | AH33: =AH3 -> 7315.2 | AI33: =AI3 -> 7781.9 | AJ33: =AJ3 -> 7417.7
O34: Operating income | P34: =P6 -> 392.517 | Q34: =Q6 -> 647.156 | R34: =R6 -> 660.956 | S34: =S6 -> 372.742 | T34: =T6 -> 903.572 | W34: Operating income | X34: =X6 -> -134.932 | Y34: =Y6 -> -256 | Z34: =Z6 -> 115 | AA34: =AA6 -> 375 | AB34: =AB6 -> 659 | AE34: Operating income | AF34: =AF6 -> 963.66 | AG34: =AG6 -> 913.1 | AH34: =AH6 -> 1139.7 | AI34: =AI6 -> 1441.2 | AJ34: =AJ6 -> 1364.5
O35: Net Income | P35: =P10 -> -50.526 | Q35: =Q10 -> 143.393 | R35: =R10 -> 243.745 | S35: =S10 -> -18.377 | T35: =T10 -> 386.44 | W35: Net Income | X35: =X10 -> -331.218 | Y35: =Y10 -> -440 | Z35: =Z10 -> -188 | AA35: =AA10 -> 5 | AB35: =AB10 -> -94 | AE35: Net Income | AF35: =AF10 -> 275.091 | AG35: =AG10 -> 100.7 | AH35: =AH10 -> 190 | AI35: =AI10 -> 328.7 | AJ35: =AJ10 -> 289.7
O37: Particulars | P37: 2025 | Q37: 2026 | R37: 2027 | S37: 2028 | T37: 2029 | U37: 2030 | W37: Particulars | X37: 2025 | Y37: 2026 | Z37: 2027 | AA37: 2028 | AB37: 2029 | AC37: 2030 | AE37: Particulars | AF37: 2025 | AG37: 2026 | AH37: 2027 | AI37: 2028 | AJ37: 2029 | AK37: 2030
O38: Revenue | P38: =DCF!R3 -> 16749.103 | Q38: =DCF!S3 -> 17418.427 | R38: =DCF!T3 -> 18114.499 | S38: =DCF!U3 -> 18838.388 | T38: =DCF!V3 -> 19591.204 | U38: =DCF!W3 -> 20374.104 | W38: Revenue | X38: =DCF!Z3 -> 16447.471 | Y38: =DCF!AA3 -> 16581.018 | Z38: =DCF!AB3 -> 16715.649 | AA38: =DCF!AC3 -> 16851.374 | AB38: =DCF!AD3 -> 16988.2 | AC38: =DCF!AE3 -> 17126.138 | AE38: Revenue | AF38: =DCF!AH3 -> 8073.3282 | AG38: =DCF!AI3 -> 8786.9054 | AH38: =DCF!AJ3 -> 9563.5536 | AI38: =DCF!AK3 -> 10408.847 | AJ38: =DCF!AL3 -> 11328.854 | AK38: =DCF!AM3 -> 12330.178
O39: Operating income | P39: =DCF!R4 -> 710.14124 | Q39: =DCF!S4 -> 738.51977 | R39: =DCF!T4 -> 768.03235 | S39: =DCF!U4 -> 798.72432 | T39: =DCF!V4 -> 830.64279 | U39: =DCF!W4 -> 863.83678 | W39: Operating income | X39: =DCF!Z4 -> 165.4554 | Y39: =DCF!AA4 -> 166.79883 | Z39: =DCF!AB4 -> 168.15317 | AA39: =DCF!AC4 -> 169.51851 | AB39: =DCF!AD4 -> 170.89493 | AC39: =DCF!AE4 -> 172.28253 | AE39: Operating income | AF39: =DCF!AH4 -> 1427.6654 | AG39: =DCF!AI4 -> 1553.8525 | AH39: =DCF!AJ4 -> 1691.1929 | AI39: =DCF!AK4 -> 1840.6723 | AJ39: =DCF!AL4 -> 2003.3638 | AK39: =DCF!AM4 -> 2180.4351
O40: Net income | P40: =DCF!R5 -> 546.80875 | Q40: =DCF!S5 -> 568.66022 | R40: =DCF!T5 -> 591.38491 | S40: =DCF!U5 -> 615.01773 | T40: =DCF!V5 -> 639.59495 | U40: =DCF!W5 -> 665.15432 | W40: Net income | X40: =DCF!Z5 -> 127.40066 | Y40: =DCF!AA5 -> 128.4351 | Z40: =DCF!AB5 -> 129.47794 | AA40: =DCF!AC5 -> 130.52925 | AB40: =DCF!AD5 -> 131.5891 | AC40: =DCF!AE5 -> 132.65755 | AE40: Net income | AF40: =DCF!AH5 -> 1099.3024 | AG40: =DCF!AI5 -> 1196.4664 | AH40: =DCF!AJ5 -> 1302.2185 | AI40: =DCF!AK5 -> 1417.3177 | AJ40: =DCF!AL5 -> 1542.5901 | AK40: =DCF!AM5 -> 1678.935

Sheet Assumptions & WACC
A1: Assumptions | N1: .
A2: Metric | B2: Caterpillar | C2: Jacobs | D2: AECOM | E2: Fluor | F2: Vulcan | H2: Current | I2: 2020 | J2: 2021 | K2: 2022 | L2: 2023 | M2: 2024
A3: Revenue CAGR | B3: =(Table1[[#This Row],[2024]]/Table1[[#This Row],[2020]])^(1/5)-1 -> 0.091942901 | C3: =(Table18[[#This Row],[2024]]/Table18[[#This Row],[2020]])^(1/5)-1 -> -0.032502013 | D3: =(Table110[[#This Row],[2024]]/Table110[[#This Row],[2020]])^(1/5)-1 -> 0.039961812 | E3: =(Table1813[[#This Row],[2024]]/Table1813[[#This Row],[2020]])^(1/5)-1 -> 0.0081196007 | F3: =(Table181323[[#This Row],[2024]]/Table181323[[#This Row],[2020]])^(1/5)-1 -> 0.088386996 | H3: WC-Caterpillar | I3: =Financials!B17-Financials!B20 -> 13747 | J3: =Financials!C17-Financials!C20 -> 13608 | K3: =Financials!D17-Financials!D20 -> 12254 | L3: =Financials!E17-Financials!E20 -> 12221 | M3: =Financials!F17-Financials!F20 -> 13410
A4: Operating margin (EBIT) | B4: =AVERAGE(Financials!B6:F6)/AVERAGE(Financials!B3:F3) -> 0.17357534 | C4: =AVERAGE(Financials!I6:M6)/AVERAGE(Financials!I3:M3) -> 0.054067039 | D4: =AVERAGE(Financials!P6:T6)/AVERAGE(Financials!P3:T3) -> 0.042398763 | E4: =AVERAGE(Financials!X6:AB6)/AVERAGE(Financials!X3:AB3) -> 0.010059626 | F4: =AVERAGE(Financials!AF6:AJ6)/AVERAGE(Financials!AF3:AJ3) -> 0.17683728 | H4: WC-Jacobs | I4: =Financials!I17-Financials!I20 -> 1598.002 | J4: =Financials!J17-Financials!J20 -> 1081.971 | K4: =Financials!K17-Financials!K20 -> 1471.149 | L4: =Financials!L17-Financials!L20 -> 1267.792 | M4: =Financials!M17-Financials!M20 -> 815.839
A5: Depreciation rate | B5: =AVERAGE(Financials!B7:F7)/AVERAGE(Financials!B3:F3) -> 0.039786631 | C5: =AVERAGE(Financials!I7:M7)/AVERAGE(Financials!I3:M3) -> 0.020782079 | D5: =AVERAGE(Financials!P7:T7)/AVERAGE(Financials!P3:T3) -> 0.013376432 | E5: {=AVERAGE(Financials!X7:AB70/AVERAGE(Financials!X3:AB3))} -> 0.066448292 | F5: =AVERAGE(Financials!AF7:AJ7)/AVERAGE(Financials!AF3:AJ3) -> 0.081901356 | H5: WC-AECOM | I5: =Financials!P15-Financials!P17 -> 5468.585 | J5: =Financials!Q15-Financials!Q17 -> 5560.411 | K5: =Financials!R15-Financials!R17 -> 5316.505 | L5: =Financials!S15-Financials!S17 -> 5063.887 | M5: =Financials!T15-Financials!T17 -> 4885.61
A6: CapEx | B6: =AVERAGE(Financials!B27:F27)/AVERAGE(Financials!B3:F3) -> 0.02447758 | C6: =AVERAGE(Financials!I27:M27)/AVERAGE(Financials!I3:M3) -> 0.0091984277 | D6: =AVERAGE(Financials!P27:T27)/AVERAGE(Financials!P3:T3) -> 0.0087315351 | E6: =AVERAGE(Financials!X27:AB27)/AVERAGE(Financials!X3:AB3) -> 0.0070788198 | F6: =AVERAGE(Financials!AF27:AJ27)/AVERAGE(Financials!AF3:AJ3) -> 0.088148747 | H6: WC-Fluor | I6: =Financials!X17-Financials!X20 -> 1461.972 | J6: =Financials!Y17-Financials!Y20 -> 1567 | K6: =Financials!Z17-Financials!Z20 -> 1828 | L6: =Financials!AA17-Financials!AA20 -> 1900 | M6: =Financials!AB17-Financials!AB20 -> 2104
A7: Working capital | B7: =AVERAGE(I3:M3)/AVERAGE(Financials!B3:F3) -> 0.22970618 | C7: =AVERAGE(I4:M4)/AVERAGE(Financials!I3:M3) -> 0.096015598 | D7: =AVERAGE(I5:M5)/AVERAGE(Financials!P3:T3) -> 0.37450343 | E7: =AVERAGE(I6:M6)/AVERAGE(Financials!X3:AB3) -> 0.11758584 | F7: =AVERAGE(Table19[[#This Row],[2020]:[2024]])/AVERAGE(Financials!AF3:AJ3) -> 0.17786153 | H7: WC-Vulcan | I7: =Financials!AF17-Financials!AF20 -> 1229.282 | J7: =Financials!AG17-Financials!AG20 -> 927.3 | K7: =Financials!AH17-Financials!AH20 -> 945.4 | L7: =Financials!AI17-Financials!AI20 -> 1727.3 | M7: =Financials!AJ17-Financials!AJ20 -> 1026.6
A8: Forecast horizon (yrs) | B8: 6 | C8: 6 | D8: 6 | E8: 6 | F8: 6
A9: Risk-free rate | B9: 0.04059 | C9: 0.04059 | D9: 0.04059 | E9: 0.04059 | F9: 0.04059
A10: Equity risk premium | B10: 0.0411 | C10: 0.0411 | D10: 0.0411 | E10: 0.0411 | F10: 0.0411 | H10: Forecast | I10: 2025 | J10: 2026 | K10: 2027 | L10: 2028 | M10: 2029 | N10: 2030
A11: Beta | B11: =Profile!B9 -> 1.5679 | C11: =Profile!C9 -> 0.8001 | D11: =Profile!D9 -> 1.0415 | E11: =Profile!E9 -> 1.3441 | F11: =Profile!F9 -> 1.0667 | H11: =H3 -> WC-Caterpillar | I11: =DCF!B3*'Assumptions & WACC'!$B$7 -> 16255.784 | J11: =DCF!C3*'Assumptions & WACC'!$B$7 -> 17750.388 | K11: =DCF!D3*'Assumptions & WACC'!$B$7 -> 19382.41 | L11: =DCF!E3*'Assumptions & WACC'!$B$7 -> 21164.485 | M11: =DCF!F3*'Assumptions & WACC'!$B$7 -> 23110.409 | N11: =DCF!G3*'Assumptions & WACC'!$B$7 -> 25235.248
A12: Cost of equity | B12: =B9+(B10*B11) -> 0.10503069 | C12: =C9+(C10*C11) -> 0.07347411 | D12: =D9+(D10*D11) -> 0.08339565 | E12: =E9+(E10*E11) -> 0.09583251 | F12: =F9+(F10*F11) -> 0.08443137 | H12: =H4 -> WC-Jacobs | I12: =DCF!J3*'Assumptions & WACC'!$C$7 -> 1068.3787 | J12: =DCF!K3*'Assumptions & WACC'!$C$7 -> 1033.6543 | K12: =DCF!L3*'Assumptions & WACC'!$C$7 -> 1000.0584 | L12: =DCF!M3*'Assumptions & WACC'!$C$7 -> 967.55453 | M12: =DCF!N3*'Assumptions & WACC'!$C$7 -> 936.10706 | N12: =DCF!O3*'Assumptions & WACC'!$C$7 -> 905.68169
A13: Kd (pre-tax) | B13: =AVERAGE(Financials!B8:F8)/AVERAGE(Financials!B21:F21) -> 0.038187911 | C13: =AVERAGE(Financials!I8:M8)/AVERAGE(Financials!I21:M21) -> 0.043763692 | D13: =AVERAGE(Financials!P8:T8)/AVERAGE(Financials!P21:T21) -> 0.076194774 | E13: =AVERAGE(Financials!X8:AB8)/AVERAGE(Financials!X21:AB21) -> 0.051764015 | F13: =AVERAGE(Financials!AF8:AJ8)/AVERAGE(Financials!AF21:AJ21) -> 0.041407723 | H13: =H5 -> WC-AECOM | I13: =DCF!R3*'Assumptions & WACC'!$D$7 -> 6272.5965 | J13: =DCF!S3*'Assumptions & WACC'!$D$7 -> 6523.2609 | K13: =DCF!T3*'Assumptions & WACC'!$D$7 -> 6783.9422 | L13: =DCF!U3*'Assumptions & WACC'!$D$7 -> 7055.0408 | M13: =DCF!V3*'Assumptions & WACC'!$D$7 -> 7336.973 | N13: =DCF!W3*'Assumptions & WACC'!$D$7 -> 7630.1718
A14: Tax rate | B14: 0.23 | C14: 0.23 | D14: 0.23 | E14: 0.23 | F14: 0.23 | H14: =H6 -> WC-Fluor | I14: =DCF!Z3*'Assumptions & WACC'!$E$7 -> 1933.9897 | J14: =DCF!AA3*'Assumptions & WACC'!$E$7 -> 1949.6929 | K14: =DCF!AB3*'Assumptions & WACC'!$E$7 -> 1965.5236 | L14: =DCF!AC3*'Assumptions & WACC'!$E$7 -> 1981.4829 | M14: =DCF!AD3*'Assumptions & WACC'!$E$7 -> 1997.5717 | N14: =DCF!AE3*'Assumptions & WACC'!$E$7 -> 2013.7912
A15: Kd (after tax) | B15: =B13*(1-B14) -> 0.029404692 | C15: =C13*(1-C14) -> 0.033698043 | D15: =D13*(1-D14) -> 0.058669976 | E15: =E13*(1-E14) -> 0.039858291 | F15: =F13*(1-F14) -> 0.031883947 | H15: =H7 -> WC-Vulcan | I15: =DCF!AH3*'Assumptions & WACC'!$F$7 -> 1435.9345 | J15: =DCF!AI3*'Assumptions & WACC'!$F$7 -> 1562.8524 | K15: =DCF!AJ3*'Assumptions & WACC'!$F$7 -> 1700.9883 | L15: =DCF!AK3*'Assumptions & WACC'!$F$7 -> 1851.3335 | M15: =DCF!AL3*'Assumptions & WACC'!$F$7 -> 2014.9673 | N15: =DCF!AM3*'Assumptions & WACC'!$F$7 -> 2193.0642
A16: Total debt | B16: =Financials!F21 -> 38409 | C16: =Financials!M21 -> 2224.354 | D16: =Financials!T21 -> 2517.254 | E16: =Financials!AB21 -> 1104 | F16: =Financials!AJ21 -> 5307.4
A17: Market cap | B17: =Profile!B8 -> 260154.54 | C17: =Profile!C8 -> 17834.846 | D17: =Profile!D8 -> 15395.535 | E17: =Profile!E8 -> 6774.5005 | F17: =Profile!F8 -> 37507.999
A18: Total capital | B18: =B16+B17 -> 298563.54 | C18: =C16+C17 -> 20059.2 | D18: =D16+D17 -> 17912.789 | E18: =E16+E17 -> 7878.5005 | F18: =F16+F17 -> 42815.399
A19: Debt weight | B19: =B16/B18 -> 0.12864598 | C19: =C16/C18 -> 0.11088947 | D19: =D16/D18 -> 0.14052831 | E19: =E16/E18 -> 0.14012819 | F19: =F16/F18 -> 0.12396007
A20: Equity weight | B20: =B17/B18 -> 0.87135402 | C20: =C17/C18 -> 0.88911053 | D20: =D17/D18 -> 0.85947169 | E20: =E17/E18 -> 0.85987181 | F20: =F17/F18 -> 0.87603993
A21: WACC | B21: =(B12*B20)+(B15*B19) -> 0.095301709 | C21: =(C12*C20)+(C15*C19) -> 0.069063363 | D21: =(D12*D20)+(D15*D19) -> 0.079920993 | E21: =(E12*E20)+(E15*E19) -> 0.087988944 | F21: =(F12*F20)+(F15*F19) -> 0.077917587
A22: Terminal year | B22: 2030 | C22: 2030 | D22: 2030 | E22: 2030 | F22: 2030
A23: PV discount rate (terminal year) | B23: =1/(1+B21)^6 -> 0.57915846 | C23: =1/(1+C21)^6 -> 0.66985271 | D23: =1/(1+D21)^6 -> 0.6304463 | E23: =1/(1+E21)^6 -> 0.60291086 | F23: =1/(1+F21)^6 -> 0.63750949
A24: Cash & cash equivalents | B24: =Financials!F14 -> 6889 | C24: =Financials!M14 -> 1144.795 | D24: =Financials!T14 -> 1580.877 | E24: =Financials!AB14 -> 2829 | F24: =Financials!AJ14 -> 559.7
A25: Terminal growth rate | B25: 0.025 | C25: 0.02 | D25: 0.02 | E25: 0.02 | F25: 0.02
A26: Shares Outstanding | B26: =Profile!B6 -> 467.9796 | C26: =Profile!C6 -> 119.5365 | D26: =Profile!D6 -> 132.4461 | E26: =Profile!E6 -> 161.1825 | F26: =Profile!F6 -> 132.1309

Sheet DCF
A1: DCF | G1: Caterpillar | O1: Jacobs | Q1: DCF | W1: AECOM | AE1: Fluor | AG1: DCF | AM1: Vulcan
A2: Particulars | B2: 2025 | C2: 2026 | D2: 2027 | E2: 2028 | F2: 2029 | G2: 2030 | I2: Particulars | J2: 2025 | K2: 2026 | L2: 2027 | M2: 2028 | N2: 2029 | O2: 2030 | Q2: Particulars | R2: 2025 | S2: 2026 | T2: 2027 | U2: 2028 | V2: 2029 | W2: 2030 | Y2: Particulars | Z2: 2025 | AA2: 2026 | AB2: 2027 | AC2: 2028 | AD2: 2029 | AE2: 2030 | AG2: Particulars | AH2: 2025 | AI2: 2026 | AJ2: 2027 | AK2: 2028 | AL2: 2029 | AM2: 2030
A3: Revenue | B3: =Table1[[#This Row],[2024]]*(1+'Assumptions & WACC'!B3) -> 70767.727 | C3: =Table9[[#This Row],[2025]]*(1+'Assumptions & WACC'!$B$3) -> 77274.318 | D3: =Table9[[#This Row],[2026]]*(1+'Assumptions & WACC'!$B$3) -> 84379.143 | E3: =Table9[[#This Row],[2027]]*(1+'Assumptions & WACC'!$B$3) -> 92137.206 | F3: =Table9[[#This Row],[2028]]*(1+'Assumptions & WACC'!$B$3) -> 100608.57 | G3: =Table9[[#This Row],[2029]]*(1+'Assumptions & WACC'!$B$3) -> 109858.81 | I3: Revenue | J3: =Table18[[#This Row],[2024]]*(1+'Assumptions & WACC'!C3) -> 11127.137 | K3: =Table10[[#This Row],[2025]]*(1+'Assumptions & WACC'!$C$3) -> 10765.483 | L3: =Table10[[#This Row],[2026]]*(1+'Assumptions & WACC'!$C$3) -> 10415.583 | M3: =Table10[[#This Row],[2027]]*(1+'Assumptions & WACC'!$C$3) -> 10077.056 | N3: =Table10[[#This Row],[2028]]*(1+'Assumptions & WACC'!$C$3) -> 9749.531 | O3: =Table10[[#This Row],[2029]]*(1+'Assumptions & WACC'!$C$3) -> 9432.6517 | Q3: Revenue | R3: =Table110[[#This Row],[2024]]*(1+'Assumptions & WACC'!D3) -> 16749.103 | S3: =Table927[[#This Row],[2025]]*(1+'Assumptions & WACC'!$D$3) -> 17418.427 | T3: =Table927[[#This Row],[2026]]*(1+'Assumptions & WACC'!$D$3) -> 18114.499 | U3: =Table927[[#This Row],[2027]]*(1+'Assumptions & WACC'!$D$3) -> 18838.388 | V3: =Table927[[#This Row],[2028]]*(1+'Assumptions & WACC'!$D$3) -> 19591.204 | W3: =Table927[[#This Row],[2029]]*(1+'Assumptions & WACC'!$D$3) -> 20374.104 | Y3: Revenue | Z3: =Table1813[[#This Row],[2024]]*(1+'Assumptions & WACC'!E3) -> 16447.471 | AA3: =Table1028[[#This Row],[2025]]*(1+'Assumptions & WACC'!$E$3) -> 16581.018 | AB3: =Table1028[[#This Row],[2026]]*(1+'Assumptions & WACC'!$E$3) -> 16715.649 | AC3: =Table1028[[#This Row],[2027]]*(1+'Assumptions & WACC'!$E$3) -> 16851.374 | AD3: =Table1028[[#This Row],[2028]]*(1+'Assumptions & WACC'!$E$3) -> 16988.2 | AE3: =Table1028[[#This Row],[2029]]*(1+'Assumptions & WACC'!$E$3) -> 17126.138 | AG3: Revenue | AH3: =Table181323[[#This Row],[2024]]*(1+'Assumptions & WACC'!F3) -> 8073.3282 | AI3: =Table92731[[#This Row],[2025]]*(1+'Assumptions & WACC'!$F$3) -> 8786.9054 | AJ3: =Table92731[[#This Row],[2026]]*(1+'Assumptions & WACC'!$F$3) -> 9563.5536 | AK3: =Table92731[[#This Row],[2027]]*(1+'Assumptions & WACC'!$F$3) -> 10408.847 | AL3: =Table92731[[#This Row],[2028]]*(1+'Assumptions & WACC'!$F$3) -> 11328.854 | AM3: =Table92731[[#This Row],[2029]]*(1+'Assumptions & WACC'!$F$3) -> 12330.178
A4: EBIT | B4: =B3*'Assumptions & WACC'!$B$4 -> 12283.532 | C4: =C3*'Assumptions & WACC'!$B$4 -> 13412.916 | D4: =D3*'Assumptions & WACC'!$B$4 -> 14646.138 | E4: =E3*'Assumptions & WACC'!$B$4 -> 15992.747 | F4: =F3*'Assumptions & WACC'!$B$4 -> 17463.166 | G4: =G3*'Assumptions & WACC'!$B$4 -> 19068.78 | I4: EBIT | J4: =J3*'Assumptions & WACC'!$C$4 -> 601.61137 | K4: =K3*'Assumptions & WACC'!$C$4 -> 582.05779 | L4: =L3*'Assumptions & WACC'!$C$4 -> 563.13974 | M4: =M3*'Assumptions & WACC'!$C$4 -> 544.83656 | N4: =N3*'Assumptions & WACC'!$C$4 -> 527.12828 | O4: =O3*'Assumptions & WACC'!$C$4 -> 509.99555 | Q4: EBIT | R4: =R3*'Assumptions & WACC'!$D$4 -> 710.14124 | S4: =S3*'Assumptions & WACC'!$D$4 -> 738.51977 | T4: =T3*'Assumptions & WACC'!$D$4 -> 768.03235 | U4: =U3*'Assumptions & WACC'!$D$4 -> 798.72432 | V4: =V3*'Assumptions & WACC'!$D$4 -> 830.64279 | W4: =W3*'Assumptions & WACC'!$D$4 -> 863.83678 | Y4: EBIT | Z4: =Z3*'Assumptions & WACC'!$E$4 -> 165.4554 | AA4: =AA3*'Assumptions & WACC'!$E$4 -> 166.79883 | AB4: =AB3*'Assumptions & WACC'!$E$4 -> 168.15317 | AC4: =AC3*'Assumptions & WACC'!$E$4 -> 169.51851 | AD4: =AD3*'Assumptions & WACC'!$E$4 -> 170.89493 | AE4: =AE3*'Assumptions & WACC'!$E$4 -> 172.28253 | AG4: EBIT | AH4: =AH3*'Assumptions & WACC'!$F$4 -> 1427.6654 | AI4: =AI3*'Assumptions & WACC'!$F$4 -> 1553.8525 | AJ4: =AJ3*'Assumptions & WACC'!$F$4 -> 1691.1929 | AK4: =AK3*'Assumptions & WACC'!$F$4 -> 1840.6723 | AL4: =AL3*'Assumptions & WACC'!$F$4 -> 2003.3638 | AM4: =AM3*'Assumptions & WACC'!$F$4 -> 2180.4351
A5: NOPAT | B5: =B4*(1-'Assumptions & WACC'!$B$14) -> 9458.3199 | C5: =C4*(1-'Assumptions & WACC'!$B$14) -> 10327.945 | D5: =D4*(1-'Assumptions & WACC'!$B$14) -> 11277.526 | E5: =E4*(1-'Assumptions & WACC'!$B$14) -> 12314.415 | F5: =F4*(1-'Assumptions & WACC'!$B$14) -> 13446.638 | G5: =G4*(1-'Assumptions & WACC'!$B$14) -> 14682.961 | I5: NOPAT | J5: =J4*(1-'Assumptions & WACC'!$C$14) -> 463.24075 | K5: =K4*(1-'Assumptions & WACC'!$C$14) -> 448.1845 | L5: =L4*(1-'Assumptions & WACC'!$C$14) -> 433.6176 | M5: =M4*(1-'Assumptions & WACC'!$C$14) -> 419.52415 | N5: =N4*(1-'Assumptions & WACC'!$C$14) -> 405.88877 | O5: =O4*(1-'Assumptions & WACC'!$C$14) -> 392.69657 | Q5: NOPAT | R5: =R4*(1-'Assumptions & WACC'!$B$14) -> 546.80875 | S5: =S4*(1-'Assumptions & WACC'!$B$14) -> 568.66022 | T5: =T4*(1-'Assumptions & WACC'!$B$14) -> 591.38491 | U5: =U4*(1-'Assumptions & WACC'!$B$14) -> 615.01773 | V5: =V4*(1-'Assumptions & WACC'!$B$14) -> 639.59495 | W5: =W4*(1-'Assumptions & WACC'!$B$14) -> 665.15432 | Y5: NOPAT | Z5: =Z4*(1-'Assumptions & WACC'!$C$14) -> 127.40066 | AA5: =AA4*(1-'Assumptions & WACC'!$C$14) -> 128.4351 | AB5: =AB4*(1-'Assumptions & WACC'!$C$14) -> 129.47794 | AC5: =AC4*(1-'Assumptions & WACC'!$C$14) -> 130.52925 | AD5: =AD4*(1-'Assumptions & WACC'!$C$14) -> 131.5891 | AE5: =AE4*(1-'Assumptions & WACC'!$C$14) -> 132.65755 | AG5: NOPAT | AH5: =AH4*(1-'Assumptions & WACC'!$B$14) -> 1099.3024 | AI5: =AI4*(1-'Assumptions & WACC'!$B$14) -> 1196.4664 | AJ5: =AJ4*(1-'Assumptions & WACC'!$B$14) -> 1302.2185 | AK5: =AK4*(1-'Assumptions & WACC'!$B$14) -> 1417.3177 | AL5: =AL4*(1-'Assumptions & WACC'!$B$14) -> 1542.5901 | AM5: =AM4*(1-'Assumptions & WACC'!$B$14) -> 1678.935
A6: Depreciation | B6: =B3*'Assumptions & WACC'!$B$5 -> 2815.6095 | C6: =C3*'Assumptions & WACC'!$B$5 -> 3074.4848 | D6: =D3*'Assumptions & WACC'!$B$5 -> 3357.1618 | E6: =E3*'Assumptions & WACC'!$B$5 -> 3665.829 | F6: =F3*'Assumptions & WACC'!$B$5 -> 4002.876 | G6: =G3*'Assumptions & WACC'!$B$5 -> 4370.912 | I6: Depreciation | J6: =J3*'Assumptions & WACC'!$C$5 -> 231.24505 | K6: =K3*'Assumptions & WACC'!$C$5 -> 223.72912 | L6: =L3*'Assumptions & WACC'!$C$5 -> 216.45747 | M6: =M3*'Assumptions & WACC'!$C$5 -> 209.42217 | N6: =N3*'Assumptions & WACC'!$C$5 -> 202.61552 | O6: =O3*'Assumptions & WACC'!$C$5 -> 196.03011 | Q6: Depreciation | R6: =R3*'Assumptions & WACC'!$D$5 -> 224.04323 | S6: =S3*'Assumptions & WACC'!$D$5 -> 232.99641 | T6: =T3*'Assumptions & WACC'!$D$5 -> 242.30737 | U6: =U3*'Assumptions & WACC'!$D$5 -> 251.99041 | V6: =V3*'Assumptions & WACC'!$D$5 -> 262.0604 | W6: =W3*'Assumptions & WACC'!$D$5 -> 272.53281 | Y6: Depreciation | Z6: =Z3*'Assumptions & WACC'!$E$5 -> 1092.9064 | AA6: =AA3*'Assumptions & WACC'!$E$5 -> 1101.7803 | AB6: =AB3*'Assumptions & WACC'!$E$5 -> 1110.7264 | AC6: =AC3*'Assumptions & WACC'!$E$5 -> 1119.745 | AD6: =AD3*'Assumptions & WACC'!$E$5 -> 1128.8369 | AE6: =AE3*'Assumptions & WACC'!$E$5 -> 1138.0026 | AG6: Depreciation | AH6: =AH3*'Assumptions & WACC'!$F$5 -> 661.21653 | AI6: =AI3*'Assumptions & WACC'!$F$5 -> 719.65947 | AJ6: =AJ3*'Assumptions & WACC'!$F$5 -> 783.26801 | AK6: =AK3*'Assumptions & WACC'!$F$5 -> 852.49872 | AL6: =AL3*'Assumptions & WACC'!$F$5 -> 927.84852 | AM6: =AM3*'Assumptions & WACC'!$F$5 -> 1009.8583
A7: Capex | B7: =B3*'Assumptions & WACC'!$B$6 -> 1732.2227 | C7: =C3*'Assumptions & WACC'!$B$6 -> 1891.4883 | D7: =D3*'Assumptions & WACC'!$B$6 -> 2065.3972 | E7: =E3*'Assumptions & WACC'!$B$6 -> 2255.2959 | F7: =F3*'Assumptions & WACC'!$B$6 -> 2462.6543 | G7: =G3*'Assumptions & WACC'!$B$6 -> 2689.0779 | I7: Capex | J7: =J3*'Assumptions & WACC'!$C$6 -> 102.35217 | K7: =K3*'Assumptions & WACC'!$C$6 -> 99.025516 | L7: =L3*'Assumptions & WACC'!$C$6 -> 95.806988 | M7: =M3*'Assumptions & WACC'!$C$6 -> 92.693068 | N7: =N3*'Assumptions & WACC'!$C$6 -> 89.680357 | O7: =O3*'Assumptions & WACC'!$C$6 -> 86.765564 | Q7: Capex | R7: =R3*'Assumptions & WACC'!$D$6 -> 146.24538 | S7: =S3*'Assumptions & WACC'!$D$6 -> 152.08961 | T7: =T3*'Assumptions & WACC'!$D$6 -> 158.16739 | U7: =U3*'Assumptions & WACC'!$D$6 -> 164.48804 | V7: =V3*'Assumptions & WACC'!$D$6 -> 171.06128 | W7: =W3*'Assumptions & WACC'!$D$6 -> 177.8972 | Y7: Capex | Z7: =Z3*'Assumptions & WACC'!$E$6 -> 116.42869 | AA7: =AA3*'Assumptions & WACC'!$E$6 -> 117.37404 | AB7: =AB3*'Assumptions & WACC'!$E$6 -> 118.32707 | AC7: =AC3*'Assumptions & WACC'!$E$6 -> 119.28784 | AD7: =AD3*'Assumptions & WACC'!$E$6 -> 120.25641 | AE7: =AE3*'Assumptions & WACC'!$E$6 -> 121.23284 | AG7: Capex | AH7: =AH3*'Assumptions & WACC'!$F$6 -> 711.65376 | AI7: =AI3*'Assumptions & WACC'!$F$6 -> 774.5547 | AJ7: =AJ3*'Assumptions & WACC'!$F$6 -> 843.01527 | AK7: =AK3*'Assumptions & WACC'!$F$6 -> 917.52685 | AL7: =AL3*'Assumptions & WACC'!$F$6 -> 998.62429 | AM7: =AM3*'Assumptions & WACC'!$F$6 -> 1086.8897
A8: Change in Working capital | B8: ='Assumptions & WACC'!I11-'Assumptions & WACC'!M3 -> 2845.7842 | C8: ='Assumptions & WACC'!J11-'Assumptions & WACC'!I11 -> 1494.604 | D8: ='Assumptions & WACC'!K11-'Assumptions & WACC'!J11 -> 1632.0222 | E8: ='Assumptions & WACC'!L11-'Assumptions & WACC'!K11 -> 1782.075 | F8: ='Assumptions & WACC'!M11-'Assumptions & WACC'!L11 -> 1945.9242 | G8: ='Assumptions & WACC'!N11-'Assumptions & WACC'!M11 -> 2124.8381 | I8: Change in Working capital | J8: ='Assumptions & WACC'!I12-'Assumptions & WACC'!M4 -> 252.53974 | K8: ='Assumptions & WACC'!J12-'Assumptions & WACC'!I12 -> -34.72446 | L8: ='Assumptions & WACC'!K12-'Assumptions & WACC'!J12 -> -33.595845 | M8: ='Assumptions & WACC'!L12-'Assumptions & WACC'!K12 -> -32.503912 | N8: ='Assumptions & WACC'!M12-'Assumptions & WACC'!L12 -> -31.44747 | O8: ='Assumptions & WACC'!N12-'Assumptions & WACC'!M12 -> -30.425364 | Q8: Change in Working capital | R8: ='Assumptions & WACC'!I13-'Assumptions & WACC'!M5 -> 1386.9865 | S8: ='Assumptions & WACC'!J13-'Assumptions & WACC'!I13 -> 250.66432 | T8: ='Assumptions & WACC'!K13-'Assumptions & WACC'!J13 -> 260.68132 | U8: ='Assumptions & WACC'!L13-'Assumptions & WACC'!K13 -> 271.09862 | V8: ='Assumptions & WACC'!M13-'Assumptions & WACC'!L13 -> 281.93222 | W8: ='Assumptions & WACC'!N13-'Assumptions & WACC'!M13 -> 293.19874 | Y8: Change in Working capital | Z8: ='Assumptions & WACC'!I14-'Assumptions & WACC'!M6 -> -170.01032 | AA8: ='Assumptions & WACC'!J14-'Assumptions & WACC'!I14 -> 15.703224 | AB8: ='Assumptions & WACC'!K14-'Assumptions & WACC'!J14 -> 15.830728 | AC8: ='Assumptions & WACC'!L14-'Assumptions & WACC'!K14 -> 15.959267 | AD8: ='Assumptions & WACC'!M14-'Assumptions & WACC'!L14 -> 16.08885 | AE8: ='Assumptions & WACC'!N14-'Assumptions & WACC'!M14 -> 16.219485 | AG8: Change in Working capital | AH8: ='Assumptions & WACC'!I15-'Assumptions & WACC'!M7 -> 409.33449 | AI8: ='Assumptions & WACC'!J15-'Assumptions & WACC'!I15 -> 126.91794 | AJ8: ='Assumptions & WACC'!K15-'Assumptions & WACC'!J15 -> 138.13583 | AK8: ='Assumptions & WACC'!L15-'Assumptions & WACC'!K15 -> 150.34524 | AL8: ='Assumptions & WACC'!M15-'Assumptions & WACC'!L15 -> 163.63381 | AM8: ='Assumptions & WACC'!N15-'Assumptions & WACC'!M15 -> 178.09691
A9: FCFF | B9: =B5+B6-B7-B8 -> 7695.9224 | C9: =C5+C6-C7-C8 -> 10016.338 | D9: =D5+D6-D7-D8 -> 10937.269 | E9: =E5+E6-E7-E8 -> 11942.873 | F9: =F5+F6-F7-F8 -> 13040.935 | G9: =G5+G6-G7-G8 -> 14239.957 | I9: FCFF | J9: =J5+J6-J7-J8 -> 339.59389 | K9: =K5+K6-K7-K8 -> 607.61256 | L9: =L5+L6-L7-L8 -> 587.86392 | M9: =M5+M6-M7-M8 -> 568.75716 | N9: =N5+N6-N7-N8 -> 550.27141 | O9: =O5+O6-O7-O8 -> 532.38648 | Q9: FCFF | R9: =R5+R6-R7-R8 -> -762.37994 | S9: =S5+S6-S7-S8 -> 398.90269 | T9: =T5+T6-T7-T8 -> 414.84357 | U9: =U5+U6-U7-U8 -> 431.42147 | V9: =V5+V6-V7-V8 -> 448.66185 | W9: =W5+W6-W7-W8 -> 466.59119 | Y9: FCFF | Z9: =Z5+Z6-Z7-Z8 -> 1273.8887 | AA9: =AA5+AA6-AA7-AA8 -> 1097.1382 | AB9: =AB5+AB6-AB7-AB8 -> 1106.0465 | AC9: =AC5+AC6-AC7-AC8 -> 1115.0272 | AD9: =AD5+AD6-AD7-AD8 -> 1124.0807 | AE9: =AE5+AE6-AE7-AE8 -> 1133.2078 | AG9: FCFF | AH9: =AH5+AH6-AH7-AH8 -> 639.53066 | AI9: =AI5+AI6-AI7-AI8 -> 1014.6533 | AJ9: =AJ5+AJ6-AJ7-AJ8 -> 1104.3354 | AK9: =AK5+AK6-AK7-AK8 -> 1201.9443 | AL9: =AL5+AL6-AL7-AL8 -> 1308.1805 | AM9: =AM5+AM6-AM7-AM8 -> 1423.8067
A12: Metrics | B12: Value | I12: Metrics | J12: Value | Q12: Metrics | R12: Value | Y12: Metrics | Z12: Value | AG12: Metrics | AH12: Value
A13: Terminal Value | B13: =G9*(1+'Assumptions & WACC'!B25)/('Assumptions & WACC'!B21-'Assumptions & WACC'!B25) -> 207618.79 | I13: Terminal Value | J13: =O9*(1+'Assumptions & WACC'!C25)/('Assumptions & WACC'!C21-'Assumptions & WACC'!C25) -> 11068.019 | Q13: Terminal Value | R13: =W9*(1+'Assumptions & WACC'!D25)/('Assumptions & WACC'!D21-'Assumptions & WACC'!D25) -> 7942.5089 | Y13: Terminal Value | Z13: =AE9*(1+'Assumptions & WACC'!E25)/('Assumptions & WACC'!E21-'Assumptions & WACC'!E25) -> 17000.881 | AG13: Terminal Value | AH13: =AM9*(1+'Assumptions & WACC'!F25)/('Assumptions & WACC'!F21-'Assumptions & WACC'!F25) -> 25074.988
A14: PV of Terminal value | B14: =B13*'Assumptions & WACC'!B23 -> 120244.18 | I14: PV of Terminal value | J14: =J13*'Assumptions & WACC'!C23 -> 7413.9423 | Q14: PV of Terminal value | R14: =R13*'Assumptions & WACC'!D23 -> 5007.3253 | Y14: PV of Terminal value | Z14: =Z13*'Assumptions & WACC'!E23 -> 10250.016 | AG14: PV of Terminal value | AH14: =AH13*'Assumptions & WACC'!F23 -> 15985.543
A15: PV of FCFF | B15: =NPV('Assumptions & WACC'!B21,DCF!B9:G9) -> 48516.726 | I15: PV of FCFF | J15: =NPV('Assumptions & WACC'!C21,DCF!J9:O9) -> 2516.5356 | Q15: PV of FCFF | R15: =NPV('Assumptions & WACC'!D21,DCF!R9:W9) -> 882.29889 | Y15: PV of FCFF | Z15: =NPV('Assumptions & WACC'!E21,DCF!Z9:AE9) -> 5172.8829 | AG15: PV of FCFF | AH15: =NPV('Assumptions & WACC'!F21,DCF!AH9:AM9) -> 5045.2767
A16: Total enterprise value | B16: =B14+B15 -> 168760.91 | I16: Total enterprise value | J16: =J14+J15 -> 9930.4778 | Q16: Total enterprise value | R16: =R14+R15 -> 5889.6242 | Y16: Total enterprise value | Z16: =Z14+Z15 -> 15422.899 | AG16: Total enterprise value | AH16: =AH14+AH15 -> 21030.82
A17: Net debt | B17: ='Assumptions & WACC'!B16-'Assumptions & WACC'!B24 -> 31520 | I17: Net debt | J17: ='Assumptions & WACC'!C16-'Assumptions & WACC'!C24 -> 1079.559 | Q17: Net debt | R17: ='Assumptions & WACC'!D16-'Assumptions & WACC'!D24 -> 936.377 | Y17: Net debt | Z17: ='Assumptions & WACC'!E16-'Assumptions & WACC'!E24 -> -1725 | AG17: Net debt | AH17: ='Assumptions & WACC'!F16-'Assumptions & WACC'!F24 -> 4747.7
A18: Total equity value | B18: =B16-B17 -> 137240.91 | I18: Total equity value | J18: =J16-J17 -> 8850.9188 | Q18: Total equity value | R18: =R16-R17 -> 4953.2472 | Y18: Total equity value | Z18: =Z16-Z17 -> 17147.899 | AG18: Total equity value | AH18: =AH16-AH17 -> 16283.12
A19: Outstanding shares | B19: ='Assumptions & WACC'!B26 -> 467.9796 | I19: Outstanding shares | J19: ='Assumptions & WACC'!C26 -> 119.5365 | Q19: Outstanding shares | R19: ='Assumptions & WACC'!D26 -> 132.4461 | Y19: Outstanding shares | Z19: ='Assumptions & WACC'!E26 -> 161.1825 | AG19: Outstanding shares | AH19: ='Assumptions & WACC'!F26 -> 132.1309
A20: Intrinsic value | B20: =B18/B19 -> 293.26258 | I20: Intrinsic value | J20: =J18/J19 -> 74.04365 | Q20: Intrinsic value | R20: =R18/R19 -> 37.398211 | Y20: Intrinsic value | Z20: =Z18/Z19 -> 106.38809 | AG20: Intrinsic value | AH20: =AH18/AH19 -> 123.23476
A21: Current market price | B21: =Profile!B3 -> 555.91 | I21: Current market price | J21: =Profile!C3 -> 149.2 | Q21: Current market price | R21: =Profile!D3 -> 116.24 | Y21: Current market price | Z21: =Profile!E3 -> 42.03 | AG21: Current market price | AH21: =Profile!F3 -> 283.87
A22: Upside/Downside | B22: =(B20-B21)/B21 -> -0.47246392 | I22: Upside/Downside | J22: =(J20-J21)/J21 -> -0.50372888 | Q22: Upside/Downside | R22: =(R20-R21)/R21 -> -0.67826728 | Y22: Upside/Downside | Z22: =(Z20-Z21)/Z21 -> 1.5312418 | AG22: Upside/Downside | AH22: =(AH20-AH21)/AH21 -> -0.56587607

Sheet Relative
A1: Company | B1: EV/EBITDA | C1: P/E | D1: P/S | E1: P/B | L1: .
A2: #VALUE! | B2: 12.81 | C2: {=_FV(A2,"P/E",TRUE)} -> 28.5236 | D2: 2.74 | E2: 8.94 | H2: Company | I2: EV/EBITDA | J2: P/E | K2: P/S | L2: P/B | M2: Shares
A3: #VALUE! | B3: 13.77 | C3: {=_FV(A3,"P/E",TRUE)} -> 59.35 | D3: 1.46 | E3: 3.61 | H3: Caterpillar | I3: =(B22*$B$19)/Relative!M3 -> 425.0533 | J3: =(C22*$C$19)/Relative!M3 -> 386.42338 | K3: =(D22*$D$19)/Relative!M3 -> 810.23437 | L3: =(E22*$E$19)/Relative!M3 -> 204.34706 | M3: ='Assumptions & WACC'!B26 -> 467.9796
A4: #VALUE! | B4: 6.76 | C4: {=_FV(A4,"P/E",TRUE)} -> 13.9998 | D4: 0.91 | E4: 2.31 | H4: Jacobs | I4: =(B23*$B$19)/Relative!M4 -> 100.90354 | J4: =(C23*$C$19)/Relative!M4 -> 16.17198 | K4: =(D23*$D$19)/Relative!M4 -> 562.905 | L4: =(E23*$E$19)/Relative!M4 -> 187.43627 | M4: ='Assumptions & WACC'!C26 -> 119.5365
A5: #VALUE! | B5: 0 | C5: {=_FV(A5,"P/E",TRUE)} -> 0 | D5: 65.17 | E5: 1.5 | H5: =A24 -> AECOM | I5: =(B24*$B$19)/Relative!M5 -> 98.455306 | J5: =(C24*$C$19)/Relative!M5 -> 67.836787 | K5: =(D24*$D$19)/Relative!M5 -> 711.43831 | L5: =(E24*$E$19)/Relative!M5 -> 87.796791 | M5: ='Assumptions & WACC'!D26 -> 132.4461
A6: #VALUE! | B6: 4.19 | C6: {=_FV(A6,"P/E",TRUE)} -> 14.8236 | D6: 0.19 | E6: 0.89 | H6: =A25 -> Fluor | I6: =(B25*$B$19)/Relative!M6 -> 54.71295 | J6: =(C25*$C$19)/Relative!M6 -> -13.559146 | K6: =(D25*$D$19)/Relative!M6 -> 592.20416 | L6: =(E25*$E$19)/Relative!M6 -> 121.4974 | M6: ='Assumptions & WACC'!E26 -> 161.1825
A7: #VALUE! | B7: 12.11 | C7: {=_FV(A7,"P/E",TRUE)} -> 2.1296 | D7: 0.54 | E7: 3.71 | H7: =A26 -> Vulcan | I7: =(B26*$B$19)/Relative!M7 -> 182.05615 | J7: =(C26*$C$19)/Relative!M7 -> 50.976085 | K7: =(D26*$D$19)/Relative!M7 -> 328.44839 | L7: =(E26*$E$19)/Relative!M7 -> 302.30666 | M7: ='Assumptions & WACC'!F26 -> 132.1309
A8: #VALUE! | B8: 13.92 | C8: {=_FV(A8,"P/E",TRUE)} -> 12.804 | D8: 1.05 | E8: 5.14
A9: #VALUE! | B9: 25.83 | C9: {=_FV(A9,"P/E",TRUE)} -> 65.9651 | D9: 2.07 | E9: 6.6
A10: #VALUE! | B10: 14.43 | C10: {=_FV(A10,"P/E",TRUE)} -> 24.2784 | D10: 0.91 | E10: 6.49
A11: #VALUE! | B11: 19.42 | C11: {=_FV(A11,"P/E",TRUE)} -> 33.54 | D11: 2.1 | E11: 5.56
A12: #VALUE! | B12: 5.68 | C12: {=_FV(A12,"P/E",TRUE)} -> 15.2701 | D12: 0.97 | E12: 3.29 | H12: Company | I12: Target Price | J12: CMP | K12: U/D
A13: #VALUE! | B13: 21.52 | C13: {=_FV(A13,"P/E",TRUE)} -> 11.6744 | D13: 3.25 | E13: 7.75 | H13: =H5 -> AECOM | I13: =AVERAGE(I3:L3) -> 456.51452 | J13: =Profile!B3 -> 555.91 | K13: =(Table24[[#This Row],[Target Price]]-J13)/J13 -> -0.17879778
A14: #VALUE! | B14: 11.68 | C14: {=_FV(A14,"P/E",TRUE)} -> 15.9221 | D14: 0.56 | E14: 1.65 | H14: =H6 -> Fluor | I14: =AVERAGE(I4:L4) -> 216.8542 | J14: =Profile!C3 -> 149.2 | K14: =(Table24[[#This Row],[Target Price]]-J14)/J14 -> 0.45344635
A15: #VALUE! | B15: 2.85 | C15: {=_FV(A15,"P/E",TRUE)} -> 24.894 | D15: 0.32 | E15: 13.54 | H15: =H7 -> Vulcan | I15: =AVERAGE(I5:L5) -> 241.3818 | J15: =Profile!D3 -> 116.24 | K15: =(Table24[[#This Row],[Target Price]]-J15)/J15 -> 1.0765812
A16: #VALUE! | B16: 16.69 | C16: {=_FV(A16,"P/E",TRUE)} -> 27.01 | D16: 9.55 | E16: 4.65 | H16: =H6 -> Fluor | I16: =AVERAGE(I6:L6) -> 188.71384 | J16: =Profile!E3 -> 42.03 | K16: =(Table24[[#This Row],[Target Price]]-J16)/J16 -> 3.4899796
A17: #VALUE! | B17: 11.1 | C17: {=_FV(A17,"P/E",TRUE)} -> 21.8148 | D17: 1.82 | E17: 2.86 | H17: =H7 -> Vulcan | I17: =AVERAGE(I7:L7) -> 215.94682 | J17: =Profile!F3 -> 283.87 | K17: =(Table24[[#This Row],[Target Price]]-J17)/J17 -> -0.23927565
A19: Average | B19: =AVERAGE(B2:B17) -> 12.0475 | C19: =AVERAGE(C2:C17) -> 23.249969 | D19: =AVERAGE(D2:D17) -> 5.850625 | E19: =AVERAGE(E2:E17) -> 4.905625
A21: Company | B21: EBITDA | C21: Net Income | D21: Revenue | E21: Book Value
A22: =H3 -> Caterpillar | B22: =Financials!F6+Financials!F7 -> 16511 | C22: =Financials!F10 -> 7778 | D22: =Financials!F3 -> 64809 | E22: =Table2[[#This Row],[2024]] -> 19494
A23: =H4 -> Jacobs | B23: =Financials!M6+Financials!M7 -> 1001.175 | C23: =Financials!M10 -> 83.146 | D23: =Financials!M3 -> 11500.941 | E23: =Financials!M22 -> 4567.303
A24: AECOM | B24: =Financials!T6+Financials!T7 -> 1082.384 | C24: =Financials!T10 -> 386.44 | D24: =Financials!T3 -> 16105.498 | E24: =Financials!T22 -> 2370.41
A25: Fluor | B25: =Financials!AB6+Financials!AB7 -> 732 | C25: =Financials!AB10 -> -94 | D25: =Financials!AB3 -> 16315 | E25: =Financials!AB22 -> 3992
A26: Vulcan | B26: =Financials!AJ6+Financials!AJ7 -> 1996.7 | C26: =Financials!AJ10 -> 289.7 | D26: =Financials!AJ3 -> 7417.7 | E26: =Financials!AJ22 -> 8142.5

Sheet Calc
A1: Year | B1: Particulars | C1: Company | D1: Value | F1: Company | G1: Change in EBIT (historical) | H1: Change in CE | I1: Incremental ROCE (Historical) | J1: Change in EBIT (Forecast) | K1: Capex | L1: Depreciation | M1: Effective capital | N1: Raw ROCE | O1: Adjusted ROCE (Forecast) | Q1: Particulars | R1: 2020 | S1: 2021 | T1: 2022 | U1: 2023 | V1: 2024 | Y1: Company | Z1: WACC | AA1: Terminal growth | AB1: Cost of equity | AC1: Intrinsic Value | AD1: Share price | AE1: Upside/Downside
A2: 2020-24 | B2: Avg Capex | C2: Caterpillar | D2: =AVERAGE(Financials!B27:F27) -> 1390.4 | F2: =C2 -> Caterpillar | G2: =Financials!F6-Financials!B6 -> 9216 | H2: =(87764-32272)-(78324-25717) -> 2885 | I2: =G2/H2 -> 3.1944541 | J2: =DCF!G4-DCF!B4 -> 6785.2481 | K2: =D8 -> 2182.6894 | L2: =AVERAGE(DCF!B6:G6) -> 3547.8122 | M2: =IF(K2-L2<=0,K2,MAX(K2-L2,0.1*K2)) -> 2182.6894 | N2: =J2/M2 -> 3.1086641 | O2: =MIN(MAX(N2,0.06),0.14) -> 0.14 | Q2: Revenue | R2: {=Financials!B3:F3} -> 41748 | S2: 50971 | T2: 59427 | U2: 67060 | V2: 64809 | Y2: Caterpillar | Z2: ='Assumptions & WACC'!B21 -> 0.095301709 | AA2: ='Assumptions & WACC'!B25 -> 0.025 | AB2: ='Assumptions & WACC'!B12 -> 0.10503069 | AC2: =DCF!B20 -> 293.26258 | AD2: =DCF!B21 -> 555.91 | AE2: =(AC2-AD2)/AD2 -> -0.47246392
A3: 2020-24 | B3: Avg Capex | C3: Jacobs | D3: =AVERAGE(Financials!I27:M27) -> 119.4596 | F3: =C3 -> Jacobs | G3: =Financials!M6-Financials!I6 -> 156.463 | H3: =(11759-4080)-(12354-2942) -> -1733 | I3: =G3/H3 -> -0.090284478 | J3: =DCF!O4-DCF!J4 -> -91.61582 | K3: =D9 -> 94.387277 | L3: =AVERAGE(DCF!J6:O6) -> 213.24991 | M3: =IF(K3-L3<=0,K3,MAX(K3-L3,0.1*K3)) -> 94.387277 | N3: =J3/M3 -> -0.97063739 | O3: =MIN(MAX(N3,0.06),0.14) -> 0.06 | Q3: Operating income | R3: {=Financials!B6:F6} -> 5142 | S3: 7333 | T3: 8469 | U3: 13996 | V3: 14358 | Y3: Jacobs | Z3: ='Assumptions & WACC'!C21 -> 0.069063363 | AA3: ='Assumptions & WACC'!C25 -> 0.02 | AB3: ='Assumptions & WACC'!C12 -> 0.07347411 | AC3: =DCF!J20 -> 74.04365 | AD3: =DCF!J21 -> 149.2 | AE3: =(AC3-AD3)/AD3 -> -0.50372888
A4: 2020-24 | B4: Avg Capex | C4: =Relative!A24 -> AECOM | D4: =AVERAGE(Financials!P27:T27) -> 122.6134 | F4: =C4 -> AECOM | G4: =Financials!T6-Financials!P6 -> 511.055 | H4: =(Financials!T15-Financials!T20)-(Financials!P15-Financials!P20) -> -1220.909 | I4: =G4/H4 -> -0.41858566 | J4: =Table927[[#This Row],[2030]]-Table927[[#This Row],[2025]] -> 153.69555 | K4: =D10 -> 161.65815 | L4: =AVERAGE(DCF!R6:W6) -> 247.6551 | M4: =IF(K4-L4<=0,K4,MAX(K4-L4,0.1*K4)) -> 161.65815 | N4: =J4/M4 -> 0.95074419 | O4: =MIN(MAX(N4,0.06),0.14) -> 0.14 | Q4: Net Income | R4: {=Financials!B10:F10} -> 601 | S4: 2296 | T4: 3175 | U4: 7530 | V4: 7778
A5: 2020-24 | B5: Avg Capex | C5: =Relative!A25 -> Fluor | D5: =AVERAGE(Financials!X27:AB270) -> 3573.0768 | F5: =C5 -> Fluor | G5: =Financials!AB6-Financials!X6 -> 793.932 | H5: =(Financials!AB15-Financials!AB20)-(Financials!X15-Financials!X20) -> 2334.225 | I5: =G5/H5 -> 0.34012659 | J5: =DCF!AE4-DCF!Z4 -> 6.8271296 | K5: =D11 -> 118.81781 | L5: =AVERAGE(DCF!Z6:AE6) -> 1115.3329 | M5: =IF(K5-L5<=0,K5,MAX(K5-L5,0.1*K5)) -> 118.81781 | N5: =J5/M5 -> 0.057458805 | O5: =MIN(MAX(N5,0.06),0.14) -> 0.06 | Q5: Capex | R5: {=Financials!B27:F27} -> 978 | S5: 1093 | T5: 1296 | U5: 1597 | V5: 1988
A6: 2020-24 | B6: Avg Capex | C6: =Relative!A26 -> Vulcan | D6: =AVERAGE(Financials!AF27:AJ27) -> 580.4388 | F6: =C6 -> Vulcan | G6: =Table181323[[#This Row],[2024]]-Table181323[[#This Row],[2020]] -> 400.84 | H6: =(Financials!AJ15-Financials!AJ20)-(Financials!AF15-Financials!AF20) -> 5226.678 | I6: =G6/H6 -> 0.07669116 | J6: =DCF!AM4-DCF!AH4 -> 752.76967 | K6: =D12 -> 888.71076 | L6: =AVERAGE(Table92731[[#This Row],[2025]:[2030]]) -> 825.72492 | M6: =IF(K6-L6<=0,K6,MAX(K6-L6,0.1*K6)) -> 88.871076 | N6: =J6/M6 -> 8.4703562 | O6: =MIN(MAX(N6,0.06),0.14) -> 0.14
C7: Average | D7: =AVERAGE(D2:D6) -> 1157.1977 | H7: Average | I7: =AVERAGE(I2:I6) -> 0.62048034 | M7: Average | N7: =AVERAGE(N2:N6) -> 2.3233172 | O7: =AVERAGE(O2:O6) -> 0.108 | Q7: Particulars | R7: 2020 | S7: 2021 | T7: 2022 | U7: 2023 | V7: 2024
A8: 2025-30 | B8: Avg Capex | C8: =C2 -> Caterpillar | D8: =AVERAGE(DCF!B7:G7) -> 2182.6894 | Q8: Revenue | R8: {=Financials!I3:M3} -> 13566.975 | S8: 14092.632 | T8: 14922.825 | U8: 10851.42 | V8: 11500.941
A9: 2025-30 | B9: Avg Capex | C9: =C3 -> Jacobs | D9: =AVERAGE(DCF!J7:O7) -> 94.387277 | G9: Metric | H9: 2020-24 | I9: 2025-30 | Q9: Operating income | R9: {=Financials!I6:M6} -> 535.973 | S9: 688.089 | T9: 917.85 | U9: 676.484 | V9: 692.436
A10: 2025-30 | B10: Avg Capex | C10: =C4 -> AECOM | D10: =AVERAGE(DCF!R7:W7) -> 161.65815 | G10: GDP | H10: =AVERAGE(-0.035,0.058) -> 0.0115 | I10: 0.021 | Q10: Net Income | R10: {=Financials!I10:M10} -> 236.814 | S10: 89.794 | T10: 355.645 | U10: 99.811 | V10: 83.146
A11: 2025-30 | B11: Avg Capex | C11: =C5 -> Fluor | D11: =AVERAGE(DCF!Z7:AE7) -> 118.81781 | G11: GDP | H11: 0.028 | I11: 0.026 | Q11: Capex | R11: {=Financials!I27:M27} -> 118.269 | S11: 92.814 | T11: 127.615 | U11: 137.486 | V11: 121.114
A12: 2025-30 | B12: Avg Capex | C12: =C6 -> Vulcan | D12: =AVERAGE(DCF!AH7:AM7) -> 888.71076 | G12: Change | H12: =H11-H10 -> 0.0165 | I12: =I11-I10 -> 0.005
B13: Avg Capex | C13: =C7 -> Average | D13: =AVERAGE(D8:D12) -> 689.25268 | G13: Sensitivity | H13: =D61/H12 -> 251.03649 | I13: =D67/I12 -> 47.402682 | Q13: Particulars | R13: 2025 | S13: 2026 | T13: 2027 | U13: 2028 | V13: 2029 | W13: 2030
A14: 2025-30 | B14: Capex CAGR | C14: =C8 -> Caterpillar | D14: =(DCF!G7/DCF!B7)^(1/6)-1 -> 0.076052038 | Q14: Revenue | R14: {=DCF!B3:G3} -> 70767.727 | S14: 77274.318 | T14: 84379.143 | U14: 92137.206 | V14: 100608.57 | W14: 109858.81
A15: 2025-30 | B15: Capex CAGR | C15: =C9 -> Jacobs | D15: =(DCF!O7/DCF!J7)^(1/6)-1 -> -0.027159314 | Q15: Operating income | R15: {=DCF!B4:G4} -> 12283.532 | S15: 13412.916 | T15: 14646.138 | U15: 15992.747 | V15: 17463.166 | W15: 19068.78
A16: 2025-30 | B16: Capex CAGR | C16: =C10 -> AECOM | D16: =(DCF!W7/DCF!R7)^(1/6)-1 -> 0.033192298 | Q16: Net income | R16: {=DCF!B5:G5} -> 9458.3199 | S16: 10327.945 | T16: 11277.526 | U16: 12314.415 | V16: 13446.638 | W16: 14682.961
A17: 2025-30 | B17: Capex CAGR | C17: =C11 -> Fluor | D17: =(DCF!AE7/DCF!Z7)^(1/6)-1 -> 0.00676177 | Q17: Capex | R17: {=DCF!B7:G7} -> 1732.2227 | S17: 1891.4883 | T17: 2065.3972 | U17: 2255.2959 | V17: 2462.6543 | W17: 2689.0779
A18: 2025-30 | B18: Capex CAGR | C18: =C12 -> Vulcan | D18: =(DCF!AM7/DCF!AH7)^(1/6)-1 -> 0.073131114 | Q18: FCFF | R18: {=DCF!B9:G9} -> 7695.9224 | S18: 10016.338 | T18: 10937.269 | U18: 11942.873 | V18: 13040.935 | W18: 14239.957
A19: 2025-30 | B19: Capex CAGR | C19: =C13 -> Average | D19: =AVERAGE(D14:D18) -> 0.032395581
A20: =A14 -> 2025-30 | B20: Earnings CAGR | C20: =C14 -> Caterpillar | D20: =D14 -> 0.076052038 | Q20: Particulars | R20: 2025 | S20: 2026 | T20: 2027 | U20: 2028 | V20: 2029 | W20: 2030
A21: =A15 -> 2025-30 | B21: Earnings CAGR | C21: =C15 -> Jacobs | D21: =D15 -> -0.027159314 | Q21: Revenue | R21: {=DCF!J3:O3} -> 11127.137 | S21: 10765.483 | T21: 10415.583 | U21: 10077.056 | V21: 9749.531 | W21: 9432.6517
A22: =A16 -> 2025-30 | B22: Earnings CAGR | C22: =C16 -> AECOM | D22: =D16 -> 0.033192298 | Q22: Operating income | R22: {=DCF!J4:O4} -> 601.61137 | S22: 582.05779 | T22: 563.13974 | U22: 544.83656 | V22: 527.12828 | W22: 509.99555
A23: =A17 -> 2025-30 | B23: Earnings CAGR | C23: =C17 -> Fluor | D23: =D17 -> 0.00676177 | Q23: Net income | R23: {=DCF!J5:O5} -> 463.24075 | S23: 448.1845 | T23: 433.6176 | U23: 419.52415 | V23: 405.88877 | W23: 392.69657
A24: =A18 -> 2025-30 | B24: Earnings CAGR | C24: =C18 -> Vulcan | D24: =D18 -> 0.073131114 | Q24: Capex | R24: {=DCF!J7:O7} -> 102.35217 | S24: 99.025516 | T24: 95.806988 | U24: 92.693068 | V24: 89.680357 | W24: 86.765564
A25: =A19 -> 2025-30 | B25: Earnings CAGR | C25: =C19 -> Average | D25: =AVERAGE(D20:D24) -> 0.032395581 | Q25: FCFF | R25: {=DCF!J9:O9} -> 339.59389 | S25: 607.61256 | T25: 587.86392 | U25: 568.75716 | V25: 550.27141 | W25: 532.38648
A26: =A20 -> 2025-30 | B26: Revenue CAGR | C26: =C20 -> Caterpillar | D26: =D20 -> 0.076052038
A27: =A21 -> 2025-30 | B27: Revenue CAGR | C27: =C21 -> Jacobs | D27: =D21 -> -0.027159314
A28: =A22 -> 2025-30 | B28: Revenue CAGR | C28: =C22 -> AECOM | D28: =D22 -> 0.033192298
A29: =A23 -> 2025-30 | B29: Revenue CAGR | C29: =C23 -> Fluor | D29: =D23 -> 0.00676177
A30: =A24 -> 2025-30 | B30: Revenue CAGR | C30: =C24 -> Vulcan | D30: =D24 -> 0.073131114
A31: =A25 -> 2025-30 | B31: Revenue CAGR | C31: =C25 -> Average | D31: =AVERAGE(D26:D30) -> 0.032395581
A32: =A2 -> 2020-24 | B32: EBITDA Margin | C32: =C26 -> Caterpillar | D32: =(AVERAGE(Financials!B6:F6)+AVERAGE(Financials!B7:F7))/AVERAGE(Financials!B3:F3) -> 0.21336197
A33: =A3 -> 2020-24 | B33: EBITDA Margin | C33: =C27 -> Jacobs | D33: =(AVERAGE(Financials!I6:M6)+AVERAGE(Financials!I7:M7))/AVERAGE(Financials!I3:M3) -> 0.074849118
A34: =A4 -> 2020-24 | B34: EBITDA Margin | C34: =C28 -> AECOM | D34: =(AVERAGE(Financials!P6:T6)+AVERAGE(Financials!P7:T7))/AVERAGE(Financials!P3:T3) -> 0.055775194
A35: =A5 -> 2020-24 | B35: EBITDA Margin | C35: =C29 -> Fluor | D35: =(AVERAGE(Financials!X6:AB6)+AVERAGE(Financials!X7:AB7))/AVERAGE(Financials!X3:AB3) -> 0.015362006
A36: =A6 -> 2020-24 | B36: EBITDA Margin | C36: =C30 -> Vulcan | D36: =(AVERAGE(Financials!AF6:AJ6)+AVERAGE(Financials!AF7:AJ7))/AVERAGE(Financials!AF3:AJ3) -> 0.25873864
A37: =$A$36 -> 2020-24 | B37: EBITDA Margin | C37: =C31 -> Average | D37: =AVERAGE(D34:D36) -> 0.10995861
A38: =$A$36 -> 2020-24 | B38: NPM | C38: =C32 -> Caterpillar | D38: =AVERAGE(Financials!B10:F10)/AVERAGE(Financials!B3:F3) -> 0.075277714
A39: =$A$36 -> 2020-24 | B39: NPM | C39: =C33 -> Jacobs | D39: =AVERAGE(Financials!I10:M10)/AVERAGE(Financials!I3:M3) -> 0.01332429
A40: =A32 -> 2020-24 | B40: NPM | C40: =C34 -> AECOM | D40: =AVERAGE(Financials!P10:T10)/AVERAGE(Financials!P3:T3) -> 0.010036251
...
