Workbook

Sheet Company Profile
A1: Company | B1: #VALUE! | C1: #VALUE! | D1: #VALUE! | E1: #VALUE! | F1: #VALUE!
A2: Official name | B2: {=_FV(B1,"Official name",TRUE)} -> PFIZER INC. | C2: {=_FV(C1,"Official name",TRUE)} -> MERCK & CO., INC. | D2: {=_FV(D1,"Official name",TRUE)} -> AMGEN INC. | E2: {=_FV(E1,"Official name",TRUE)} -> ELI LILLY AND COMPANY | F2: {=_FV(F1,"Official name",TRUE)} -> JOHNSON & JOHNSON
A3: Share Price | B3: {=_FV(B1,"Price")} -> 24.9 | C3: {=_FV(C1,"Price")} -> 95.05 | D3: {=_FV(D1,"Price")} -> 342.4 | E3: {=_FV(E1,"Price")} -> 1049.09 | F3: {=_FV(F1,"Price")} -> 202.66
A4: Change (%) | B4: {=_FV(B1,"Change (%)",TRUE)} -> -0.021611 | C4: {=_FV(C1,"Change (%)",TRUE)} -> -0.014311 | D4: {=_FV(D1,"Change (%)",TRUE)} -> -0.004622 | E4: {=_FV(E1,"Change (%)",TRUE)} -> 0.018485 | F4: {=_FV(F1,"Change (%)",TRUE)} -> 0.0133
A5: Shares outstanding | B5: {=_FV(B1,"Shares outstanding",TRUE)} -> 5685708000 | C5: {=_FV(C1,"Shares outstanding",TRUE)} -> 2482022000 | D5: {=_FV(D1,"Shares outstanding",TRUE)} -> 538480700 | E5: {=_FV(E1,"Shares outstanding",TRUE)} -> 945383800 | F5: {=_FV(F1,"Shares outstanding",TRUE)} -> 2409295000
A6: in mn | B6: =B5/1000000 -> 5685.708 | C6: =C5/1000000 -> 2482.022 | D6: =D5/1000000 -> 538.4807 | E6: =E5/1000000 -> 945.3838 | F6: =F5/1000000 -> 2409.295
A7: Market cap | B7: {=_FV(B1,"Market cap",TRUE)} -> 141574129200 | C7: {=_FV(C1,"Market cap",TRUE)} -> 235916191100 | D7: {=_FV(D1,"Market cap",TRUE)} -> 184375791680 | E7: {=_FV(E1,"Market cap",TRUE)} -> 991792690741 | F7: {=_FV(F1,"Market cap",TRUE)} -> 488267724700
A8: in mn | B8: =B7/1000000 -> 141574.13 | C8: =C7/1000000 -> 235916.19 | D8: =D7/1000000 -> 184375.79 | E8: =E7/1000000 -> 991792.69 | F8: =F7/1000000 -> 488267.72
A9: Beta | B9: {=_FV(B1,"Beta")} -> 0.408 | C9: {=_FV(C1,"Beta")} -> 0.2832 | D9: {=_FV(D1,"Beta")} -> 0.4103 | E9: {=_FV(E1,"Beta")} -> 0.3349 | F9: {=_FV(F1,"Beta")} -> 0.3372
A10: P/E | B10: {=_FV(B1,"P/E",TRUE)} -> 14.5139 | C10: {=_FV(C1,"P/E",TRUE)} -> 12.5716 | D10: {=_FV(D1,"P/E",TRUE)} -> 26.4661 | E10: {=_FV(E1,"P/E",TRUE)} -> 51.3025 | F10: {=_FV(F1,"P/E",TRUE)} -> 19.5606
A11: Year | B11: {=_FV(B1,"Year incorporated",TRUE)} -> 1942 | C11: {=_FV(C1,"Year incorporated",TRUE)} -> 1970 | D11: {=_FV(D1,"Year incorporated",TRUE)} -> 1986 | E11: {=_FV(E1,"Year incorporated",TRUE)} -> 1901 | F11: {=_FV(F1,"Year incorporated",TRUE)} -> 1887

Sheet Financials
A1: Income Statement | F1: Pfizer | H1: Income Statement | M1: Merck | O1: Income Statement | T1: Amgen | W1: Income Statement | AB1: LLY | AE1: Income Statement | AJ1: J&J
A2: Particulars | B2: 2020 | C2: 2021 | D2: 2022 | E2: 2023 | F2: 2024 | H2: Particulars | I2: 2020 | J2: 2021 | K2: 2022 | L2: 2023 | M2: 2024 | O2: Particulars | P2: 2020 | Q2: 2021 | R2: 2022 | S2: 2023 | T2: 2024 | W2: Particulars | X2: 2020 | Y2: 2021 | Z2: 2022 | AA2: 2023 | AB2: 2024 | AE2: Particulars | AF2: 2020 | AG2: 2021 | AH2: 2022 | AI2: 2023 | AJ2: 2024
A3: Revenue | B3: 41908 | C3: 81288 | D3: 100330 | E3: 59553 | F3: 63627 | H3: Revenue | I3: 47994 | J3: 48704 | K3: 59283 | L3: 60115 | M3: 64168 | O3: Revenue | P3: 25424 | Q3: 25979 | R3: 26323 | S3: 28190 | T3: 33424 | W3: Revenue | X3: 24539.8 | Y3: 28318.4 | Z3: 28541.4 | AA3: 34124.1 | AB3: 45042.7 | AE3: Revenue | AF3: 82584 | AG3: 93775 | AH3: 94943 | AI3: 85159 | AJ3: 88821
A4: Cost of goods sold | B4: 8692 | C4: 30821 | D4: 34344 | E4: 24954 | F4: 17851 | H4: Cost of goods sold | I4: 15485 | J4: 13626 | K4: 17411 | L4: 16126 | M4: 15193 | O4: Cost of goods sold | P4: 6159 | Q4: 6454 | R4: 6406 | S4: 8451 | T4: 12858 | W4: Cost of goods sold | X4: 5483.3 | Y4: 7312.8 | Z4: 6629.8 | AA4: 7082.2 | AB4: 8418.33 | AE4: Cost of goods sold | AF4: 28427 | AG4: 29855 | AH4: 31089 | AI4: 26553 | AJ4: 27471
A5: Gross profit | B5: =B3-B4 -> 33216 | C5: =C3-C4 -> 50467 | D5: =D3-D4 -> 65986 | E5: =E3-E4 -> 34599 | F5: =F3-F4 -> 45776 | H5: Gross profit | I5: =I3-I4 -> 32509 | J5: =J3-J4 -> 35078 | K5: =K3-K4 -> 41872 | L5: =L3-L4 -> 43989 | M5: =M3-M4 -> 48975 | O5: Gross profit | P5: =P3-P4 -> 19265 | Q5: =Q3-Q4 -> 19525 | R5: =R3-R4 -> 19917 | S5: =S3-S4 -> 19739 | T5: =T3-T4 -> 20566 | W5: Gross profit | X5: =X3-X4 -> 19056.5 | Y5: =Y3-Y4 -> 21005.6 | Z5: =Z3-Z4 -> 21911.6 | AA5: =AA3-AA4 -> 27041.9 | AB5: =AB3-AB4 -> 36624.37 | AE5: Gross profit | AF5: =AF3-AF4 -> 54157 | AG5: =AG3-AG4 -> 63920 | AH5: =AH3-AH4 -> 63854 | AI5: =AI3-AI4 -> 58606 | AJ5: =AJ3-AJ4 -> 61350
A6: Opex | B6: =11615+9405+600-6+669 -> 22283 | C6: =12703+10360+3469+802-4878 -> 22456 | D6: =13677+11428+953+1375+217 -> 27650 | E6: =14771+10679+194+2943+222 -> 28809 | F6: =14730+10822+108+2419+4388 -> 32467 | H6: Opex | I6: =10468+13558+578-886 -> 23718 | J6: =9634+12245+661-1341 -> 21199 | K6: =10042+13548+337+1501 -> 25428 | L6: =10504+30531+599+466 -> 42100 | M6: =10816+17938+309-24 -> 29039 | O6: Opex | P6: =4207+5730+189-256 -> 9870 | Q6: =18340-6454-259 -> 11627 | R6: =16757-6406+814 -> 11165 | S6: =20293-8451-2833 -> 9009 | T6: =26166-12858-506 -> 12802 | W6: Opex | X6: =17309.9-5483.3 -> 11826.6 | Y6: =22162.9-7312.8 -> 14850.1 | Z6: =21735-6629.8 -> 15105.2 | AA6: =27569.5-7082.2 -> 20487.3 | AB6: =32362.3-8418.3 -> 23944 | AE6: Opex | AF6: =22084+12159+181-111+2899+247 -> 37459 | AG6: =24659+14714+900-53+489+252 -> 40961 | AH6: =24765+14603+783-490+1871+321 -> 41853 | AI6: =21512+15085+313-1261+6634+489 -> 42772 | AJ6: =22869+17232+211-1332+4694+234 -> 43908
A7: Operating income (EBIT) | B7: =B5-B6 -> 10933 | C7: =C5-C6 -> 28011 | D7: =D5-D6 -> 38336 | E7: =E5-E6 -> 5790 | F7: =F5-F6 -> 13309 | H7: Operating income (EBIT) | I7: =I5-I6 -> 8791 | J7: =J5-J6 -> 13879 | K7: =K5-K6 -> 16444 | L7: =L5-L6 -> 1889 | M7: =M5-M6 -> 19936 | O7: Operating income (EBIT) | P7: =P5-P6 -> 9395 | Q7: =Q5-Q6 -> 7898 | R7: =R5-R6 -> 8752 | S7: =S5-S6 -> 10730 | T7: =T5-T6 -> 7764 | W7: Operating income (EBIT) | X7: =X5-X6 -> 7229.9 | Y7: =Y5-Y6 -> 6155.5 | Z7: =Z5-Z6 -> 6806.4 | AA7: =AA5-AA6 -> 6554.6 | AB7: =AB5-AB6 -> 12680.37 | AE7: Operating income (EBIT) | AF7: =AF5-AF6 -> 16698 | AG7: =AG5-AG6 -> 22959 | AH7: =AH5-AH6 -> 22001 | AI7: =AI5-AI6 -> 15834 | AJ7: =AJ5-AJ6 -> 17442
A8: Depreciation & Amortization | B8: 3436 | C8: 3700 | D8: 3609 | E8: 4733 | F8: 5286 | H8: Depreciation & Amortization | I8: 3625 | J8: 3214 | K8: 3909 | L8: 3872 | M8: 4499 | O8: Depreciation & Amortization | P8: 0 | Q8: 0 | R8: 0 | S8: 0 | T8: 0 | W8: Depreciation & Amortization | X8: 0 | Y8: 0 | Z8: 0 | AA8: 0 | AB8: 0 | AE8: Depreciation & Amortization | AF8: 0 | AG8: 0 | AH8: 0 | AI8: 0 | AJ8: 0
A9: Internet expense | B9: 1291 | C9: 1238 | D9: 2209 | E9: 3091 | F9: 3091 | H9: Internet expense | I9: 831 | J9: 806 | K9: 962 | L9: 1146 | M9: 1271 | O9: Internet expense | P9: 1262 | Q9: 1197 | R9: 1406 | S9: 2875 | T9: 3155 | W9: Internet expense | X9: 360 | Y9: 340 | Z9: 332 | AA9: 781 | AB9: 910 | AE9: Internet expense | AF9: 201 | AG9: 183 | AH9: 276 | AI9: 772 | AJ9: 755
A10: Income tax expense | B10: 477 | C10: 1852 | D10: 3328 | E10: -1115 | F10: -28 | H10: Income tax expense | I10: 1709 | J10: 1521 | K10: 1918 | L10: 1512 | M10: 2803 | O10: Income tax expense | P10: 869 | Q10: 808 | R10: 794 | S10: 1138 | T10: 519 | W10: Income tax expense | X10: 1036.2 | Y10: 573.8 | Z10: 561.6 | AA10: 1314.2 | AB10: 2090.4 | AE10: Income tax expense | AF10: 1783 | AG10: 1898 | AH10: 3784 | AI10: 1736 | AJ10: 2621
A11: Net Income | B11: =B7-B8-B10-B9 -> 5729 | C11: =C7-C8-C10-C9 -> 21221 | D11: =D7-D8-D10-D9 -> 29190 | E11: =E7-E8-E10-E9 -> -919 | F11: =F7-F8-F10-F9 -> 4960 | H11: Net Income | I11: =I7-I8-I9-I10 -> 2626 | J11: =J7-J8-J9-J10 -> 8338 | K11: =K7-K8-K9-K10 -> 9655 | L11: =L7-L8-L9-L10 -> -4641 | M11: =M7-M8-M9-M10 -> 11363 | O11: Net Income | P11: =P7-P8-P10-P9 -> 7264 | Q11: =Q7-Q8-Q10-Q9 -> 5893 | R11: =R7-R8-R10-R9 -> 6552 | S11: =S7-S8-S10-S9 -> 6717 | T11: =T7-T8-T10-T9 -> 4090 | W11: Net Income | X11: =X7-X8-X9-X10 -> 5833.7 | Y11: =Y7-Y8-Y9-Y10 -> 5241.7 | Z11: =Z7-Z8-Z9-Z10 -> 5912.8 | AA11: =AA7-AA8-AA9-AA10 -> 4459.4 | AB11: =AB7-AB8-AB9-AB10 -> 9679.97 | AE11: Net Income | AF11: =AF7-AF8-AF9-AF10 -> 14714 | AG11: =AG7-AG8-AG9-AG10 -> 20878 | AH11: =AH7-AH8-AH9-AH10 -> 17941 | AI11: =AI7-AI8-AI9-AI10 -> 13326 | AJ11: =AJ7-AJ8-AJ9-AJ10 -> 14066
A13: Balance Sheet | H13: Balance Sheet | O13: Balance Sheet | W13: Balance Sheet | AE13: Balance Sheet
A14: Particulars | B14: 2020 | C14: 2021 | D14: 2022 | E14: 2023 | F14: 2024 | H14: Particulars | I14: 2020 | J14: 2021 | K14: 2022 | L14: 2023 | M14: 2024 | O14: Particulars | P14: 2020 | Q14: 2021 | R14: 2022 | S14: 2023 | T14: 2024 | W14: Particulars | X14: 2020 | Y14: 2021 | Z14: 2022 | AA14: 2023 | AB14: 2024 | AE14: Particulars | AF14: 2020 | AG14: 2021 | AH14: 2022 | AI14: 2023 | AJ14: 2024
A15: Cash & Cash equivalents | B15: 1784 | C15: 1944 | D15: 416 | E15: 2853 | F15: 1043 | H15: Cash & Cash equivalents | I15: 8062 | J15: 8096 | K15: 12694 | L15: 6841 | M15: 13242 | O15: Cash & Cash equivalents | P15: 6266 | Q15: 7989 | R15: 7629 | S15: 10944 | T15: 11973 | W15: Cash & Cash equivalents | X15: 3657.1 | Y15: 3818.5 | Z15: 2067 | AA15: 2818.6 | AB15: 3268.4 | AE15: Cash & Cash equivalents | AF15: 13985 | AG15: 14487 | AH15: 14127 | AI15: 21859 | AJ15: 24105
A16: Accounts Receivables | B16: 7930 | C16: 11479 | D16: 10952 | E16: 11566 | F16: 11463 | H16: Accounts Receivables | I16: 7851 | J16: 9230 | K16: 9450 | L16: 10349 | M16: 10278 | O16: Total assets | P16: 62948 | Q16: 61165 | R16: 65121 | S16: 97154 | T16: 91839 | W16: Total assets | X16: 46633.1 | Y16: 48806 | Z16: 49489.8 | AA16: 64006.3 | AB16: 78714.9 | AE16: Total assets | AF16: 174894 | AG16: 182018 | AH16: 187378 | AI16: 167558 | AJ16: 180104
A17: Inventories | B17: 8046 | C17: 9059 | D17: 8981 | E17: 10189 | F17: 10851 | H17: Inventories | I17: 6310 | J17: 5953 | K17: 5911 | L17: 6358 | M17: 6109 | O17: Inventories | P17: 3893 | Q17: 4086 | R17: 4930 | S17: 9518 | T17: 6998 | W17: Inventories | X17: 3980.3 | Y17: 3886 | Z17: 4309.7 | AA17: 5772.8 | AB17: 7589.2 | AE17: Inventories | AF17: 9344 | AG17: 10387 | AH17: 12483 | AI17: 11181 | AJ17: 12444
A18: Total current assets | B18: 35067 | C18: 59693 | D18: 51259 | E18: 43333 | F18: 50358 | H18: Total current assets | I18: 27764 | J18: 30266 | K18: 35722 | L18: 32168 | M18: 38782 | O18: Total current assets | P18: 21144 | Q18: 19385 | R18: 22186 | S18: 30332 | T18: 29030 | W18: Total current assets | X18: 17462.1 | Y18: 18452.4 | Z18: 18034.5 | AA18: 25727 | AB18: 32739.7 | AE18: Total current assets | AF18: 51237 | AG18: 60979 | AH18: 55294 | AI18: 53495 | AJ18: 55893
A19: Accounts payable | B19: 4309 | C19: 5578 | D19: 6809 | E19: 6710 | F19: 5633 | H19: Accounts payable | I19: 4594 | J19: 4609 | K19: 4264 | L19: 3922 | M19: 4079 | O19: Accounts payable | P19: 1421 | Q19: 1366 | R19: 1572 | S19: 1590 | T19: 1908 | W19: Accounts payable | X19: 1606.7 | Y19: 1670.6 | Z19: 1930.6 | AA19: 2598.8 | AB19: 3228.6 | AE19: Accounts payable | AF19: 9505 | AG19: 11055 | AH19: 11703 | AI19: 9632 | AJ19: 10311
A20: Total current liabilities | B20: 25920 | C20: 42671 | D20: 42138 | E20: 47794 | F20: 42995 | H20: Total current liabilities | I20: 27327 | J20: 23872 | K20: 24239 | L20: 25694 | M20: 28420 | O20: Total current liabilities | P20: 11653 | Q20: 12184 | R20: 15687 | S20: 18392 | T20: 23099 | W20: Total current liabilities | X20: 12481.6 | Y20: 15052.7 | Z20: 17138.2 | AA20: 27293.2 | AB20: 28376.6 | AE20: Total current liabilities | AF20: 42493 | AG20: 45226 | AH20: 55802 | AI20: 46282 | AJ20: 50321
A21: PPE | B21: 13900 | C21: 14862 | D21: 16274 | E21: 18940 | F21: 18393 | H21: PPE | I21: 36968 | J21: 37471 | K21: 39407 | L21: 41317 | M21: 42934 | O21: PPE | P21: 4889 | Q21: 5184 | R21: 5427 | S21: 5941 | T21: 6543 | W21: PPE | X21: 8681.9 | Y21: 8985.1 | Z21: 10144 | AA21: 12913.6 | AB21: 17102.4 | AE21: PPE | AF21: 18766 | AG21: 18962 | AH21: 19803 | AI21: 19898 | AJ21: 20518
A22: Total debt | B22: =2703+37133 -> 39836 | C22: =2241+36195 -> 38436 | D22: =2945+32884 -> 35829 | E22: =10350+61538 -> 71888 | F22: =6946+57405 -> 64351 | H22: Total debt | I22: =6431+25360 -> 31791 | J22: =2412+30690 -> 33102 | K22: =1946+28745 -> 30691 | L22: =1372+33683 -> 35055 | M22: =2649+34462 -> 37111 | O22: Total debt | P22: =91+32895 -> 32986 | Q22: =87+33222 -> 33309 | R22: =1591+37354 -> 38945 | S22: =1443+63170 -> 64613 | T22: =3550+56549 -> 60099 | W22: Total debt | X22: =8.7+16586.6 -> 16595.3 | Y22: =1538.3+15346.4 -> 16884.7 | Z22: =1501.1+14737.5 -> 16238.6 | AA22: =6904.5+18320.8 -> 25225.3 | AB22: =5117.1+28527.1 -> 33644.2 | AE22: Total debt | AF22: =2631+32635 -> 35266 | AG22: =3766+29985 -> 33751 | AH22: =12771+26888 -> 39659 | AI22: =3451+25881 -> 29332 | AJ22: =5983+30651 -> 36634
A23: Shareholder's equity | B23: 63473 | C23: =77462 -> 77462 | D23: 95916 | E23: 89288 | F23: 88497 | H23: Shareholder's equity | I23: 25404 | J23: 38257 | K23: 46058 | L23: 37635 | M23: 46372 | O23: Shareholder's equity | P23: 9409 | Q23: 6700 | R23: 3661 | S23: 6232 | T23: 5877 | W23: Shareholder's equity | X23: 5825.2 | Y23: 9154.8 | Z23: 10775.4 | AA23: 10863.7 | AB23: 14271.6 | AE23: Shareholder's equity | AF23: 63278 | AG23: 74023 | AH23: 76804 | AI23: 68774 | AJ23: 71490
A25: Cash flow statement | H25: Cash flow statement | O25: Cash flow statement | W25: Cash flow statement | AE25: Cash flow statement
A26: Particulars | B26: 2020 | C26: 2021 | D26: 2022 | E26: 2023 | F26: 2024 | H26: Particulars | I26: 2020 | J26: 2021 | K26: 2022 | L26: 2023 | M26: 2024 | O26: Particulars | P26: 2020 | Q26: 2021 | R26: 2022 | S26: 2023 | T26: 2024 | W26: Particulars | X26: 2020 | Y26: 2021 | Z26: 2022 | AA26: 2023 | AB26: 2024 | AE26: Particulars | AF26: 2020 | AG26: 2021 | AH26: 2022 | AI26: 2023 | AJ26: 2024
A27: Cash flow from operating activities | B27: 14403 | C27: 32580 | D27: 29267 | E27: 8700 | F27: 12744 | H27: Cash flow from operating activities | I27: 7617 | J27: 13122 | K27: 19095 | L27: 13006 | M27: 21468 | O27: Cash flow from operating activities | P27: 10497 | Q27: 9261 | R27: 9721 | S27: 8471 | T27: 11490 | W27: Cash flow from operating activities | X27: 6499.6 | Y27: 7260.7 | Z27: 7084.4 | AA27: 4240.1 | AB27: 8817.9 | AE27: Cash flow from operating activities | AF27: 22536 | AG27: 23410 | AH27: 21194 | AI27: 22791 | AJ27: 24266
A28: Capex | B28: 2226 | C28: 2711 | D28: 3236 | E28: 3907 | F28: 2909 | H28: Capex | I28: 4429 | J28: 4448 | K28: 4388 | L28: 3863 | M28: 3372 | O28: Capex | P28: 608 | Q28: 880 | R28: 936 | S28: 1112 | T28: 1096 | W28: Capex | X28: 1387.9 | Y28: 1309.8 | Z28: 1854.3 | AA28: 3447.6 | AB28: 5057.8 | AE28: Capex | AF28: 3347 | AG28: 3652 | AH28: 4009 | AI28: 4543 | AJ28: 4424
A29: Dividends paid | B29: 8440 | C29: 8729 | D29: 8983 | E29: 9247 | F29: 9512 | H29: Dividends paid | I29: 6215 | J29: 6610 | K29: 7012 | L29: 7445 | M29: 7840 | O29: Dividends paid | P29: 3755 | Q29: 4013 | R29: 4196 | S29: 4556 | T29: 4832 | W29: Dividends paid | X29: 2687.1 | Y29: 3086.8 | Z29: 3535.8 | AA29: 4069.3 | AB29: 4680.4 | AE29: Dividends paid | AF29: 10481 | AG29: 11032 | AH29: 11682 | AI29: 11770 | AJ29: 11823
A30: Debt paid | B30: =22197+4003 -> 26200 | C30: 2004 | D30: =3887+3298 -> 7185 | E30: =3+2569 -> 2572 | F30: =11226+2250 -> 13476 | H30: Debt paid | I30: 1957 | J30: 2319 | K30: 2251 | L30: 1755 | M30: 1290 | O30: Debt paid | P30: 6450 | Q30: 4150 | R30: 0 | S30: 1454 | T30: 3600 | W30: Debt paid | X30: 276.5 | Y30: 1905.4 | Z30: 1560 | AA30: 0 | AB30: 664.2 | AE30: Debt paid | AF30: =2663+1064 -> 3727 | AG30: =1190+1802 -> 2992 | AH30: =6550+2134 -> 8684 | AI30: =22973+1551 -> 24524 | AJ30: =9463+1453 -> 10916
H31: Depreciation & Amortization | I31: =1899+1726 -> 3625 | J31: =1636+1578 -> 3214 | K31: =2085+1824 -> 3909 | L31: =2044+1828 -> 3872 | M31: =2395+2104 -> 4499 | O31: Depreciation & Amortization | P31: 3601 | Q31: 3398 | R31: 3417 | S31: 4070 | T31: 5590 | W31: Depreciation & Amortization | X31: 1323.9 | Y31: 1547.6 | Z31: 1522.5 | AA31: 1527 | AB31: 1767 | AE31: Depreciation & Amortization | AF31: 7231 | AG31: 7390 | AH31: 6970 | AI31: 7486 | AJ31: 7339
O34: Particulars | P34: 2020 | Q34: 2021 | R34: 2022 | S34: 2023 | T34: 2024 | W34: Particulars | X34: 2020 | Y34: 2021 | Z34: 2022 | AA34: 2023 | AB34: 2024 | AE34: Particulars | AF34: 2020 | AG34: 2021 | AH34: 2022 | AI34: 2023 | AJ34: 2024
O35: Revenue | P35: =P3 -> 25424 | Q35: =Q3 -> 25979 | R35: =R3 -> 26323 | S35: =S3 -> 28190 | T35: =T3 -> 33424 | W35: Revenue | X35: =X3 -> 24539.8 | Y35: =Y3 -> 28318.4 | Z35: =Z3 -> 28541.4 | AA35: =AA3 -> 34124.1 | AB35: =AB3 -> 45042.7 | AE35: Revenue | AF35: =AF3 -> 82584 | AG35: =AG3 -> 93775 | AH35: =AH3 -> 94943 | AI35: =AI3 -> 85159 | AJ35: =AJ3 -> 88821
O36: Operating income | P36: =P7 -> 9395 | Q36: =Q7 -> 7898 | R36: =R7 -> 8752 | S36: =S7 -> 10730 | T36: =T7 -> 7764 | W36: Operating income | X36: =X7 -> 7229.9 | Y36: =Y7 -> 6155.5 | Z36: =Z7 -> 6806.4 | AA36: =AA7 -> 6554.6 | AB36: =AB7 -> 12680.37 | AE36: Operating income | AF36: =AF7 -> 16698 | AG36: =AG7 -> 22959 | AH36: =AH7 -> 22001 | AI36: =AI7 -> 15834 | AJ36: =AJ7 -> 17442
O37: Net income | P37: =P11 -> 7264 | Q37: =Q11 -> 5893 | R37: =R11 -> 6552 | S37: =S11 -> 6717 | T37: =T11 -> 4090 | W37: Net income | X37: =X11 -> 5833.7 | Y37: =Y11 -> 5241.7 | Z37: =Z11 -> 5912.8 | AA37: =AA11 -> 4459.4 | AB37: =AB11 -> 9679.97 | AE37: Net income | AF37: =AF11 -> 14714 | AG37: =AG11 -> 20878 | AH37: =AH11 -> 17941 | AI37: =AI11 -> 13326 | AJ37: =AJ11 -> 14066
O39: Particulars | P39: 2025 | Q39: 2026 | R39: 2027 | S39: 2028 | T39: 2029 | U39: 2030 | W39: Particulars | X39: 2025 | Y39: 2026 | Z39: 2027 | AA39: 2028 | AB39: 2029 | AC39: 2030 | AE39: Particulars | AF39: 2025 | AG39: 2026 | AH39: 2027 | AI39: 2028 | AJ39: 2029 | AK39: 2030
O40: =O35 -> Revenue | P40: =DCF!R3 -> 35303.79 | Q40: =DCF!S3 -> 37289.301 | R40: =DCF!T3 -> 39386.478 | S40: =DCF!U3 -> 41601.602 | T40: =DCF!V3 -> 43941.306 | U40: =DCF!W3 -> 46412.597 | W40: =W35 -> Revenue | X40: =DCF!Z3 -> 50859.852 | Y40: =DCF!AA3 -> 57428.275 | Z40: =DCF!AB3 -> 64844.994 | AA40: =DCF!AC3 -> 73219.563 | AB40: =DCF!AD3 -> 82675.687 | AC40: =DCF!AE3 -> 93353.046 | AE40: =AE35 -> Revenue | AF40: =DCF!AH3 -> 90123.823 | AG40: =DCF!AI3 -> 91445.756 | AH40: =DCF!AJ3 -> 92787.079 | AI40: =DCF!AK3 -> 94148.077 | AJ40: =DCF!AL3 -> 95529.038 | AK40: =DCF!AM3 -> 96930.254
O41: =O36 -> Operating income | P41: =DCF!R4 -> 11284.595 | Q41: =DCF!S4 -> 11919.249 | R41: =DCF!T4 -> 12589.596 | S41: =DCF!U4 -> 13297.644 | T41: =DCF!V4 -> 14045.513 | U41: =DCF!W4 -> 14835.443 | W41: =W36 -> Operating income | X41: =DCF!Z4 -> 12488.539 | Y41: =DCF!AA4 -> 14101.402 | Z41: =DCF!AB4 -> 15922.563 | AA41: =DCF!AC4 -> 17978.923 | AB41: =DCF!AD4 -> 20300.856 | AC41: =DCF!AE4 -> 22922.66 | AE41: =AE36 -> Operating income | AF41: =DCF!AH4 -> 19214.374 | AG41: =DCF!AI4 -> 19496.21 | AH41: =DCF!AJ4 -> 19782.18 | AI41: =DCF!AK4 -> 20072.344 | AJ41: =DCF!AL4 -> 20366.765 | AK41: =DCF!AM4 -> 20665.504
O42: =O37 -> Net income | P42: =DCF!R5 -> 8689.1383 | Q42: =DCF!S5 -> 9177.8218 | R42: =DCF!T5 -> 9693.9891 | S42: =DCF!U5 -> 10239.186 | T42: =DCF!V5 -> 10815.045 | U42: =DCF!W5 -> 11423.291 | W42: =W37 -> Net income | X42: =DCF!Z5 -> 9616.1748 | Y42: =DCF!AA5 -> 10858.08 | Z42: =DCF!AB5 -> 12260.374 | AA42: =DCF!AC5 -> 13843.77 | AB42: =DCF!AD5 -> 15631.659 | AC42: =DCF!AE5 -> 17650.449 | AE42: =AE37 -> Net income | AF42: =DCF!AH5 -> 14795.068 | AG42: =DCF!AI5 -> 15012.082 | AH42: =DCF!AJ5 -> 15232.278 | AI42: =DCF!AK5 -> 15455.705 | AJ42: =DCF!AL5 -> 15682.409 | AK42: =DCF!AM5 -> 15912.438

Sheet Assumptions & WACC
A1: Assumptions & WACC
A2: Metric | B2: Pfizer | C2: Merck | D2: Amgen | E2: LLY | F2: J&J
A3: Revenue CAGR | B3: =(Table1[[#This Row],[2024]]/Table1[[#This Row],[2020]])^(1/5)-1 -> 0.087098515 | C3: =(Table18[[#This Row],[2024]]/Table18[[#This Row],[2020]])^(1/5)-1 -> 0.059805847 | D3: =(Table15[[#This Row],[2024]]/Table15[[#This Row],[2020]])^(1/5)-1 -> 0.056240725 | E3: =(Table1811[[#This Row],[2024]]/Table1811[[#This Row],[2020]])^(1/5)-1 -> 0.12914751 | F3: =(Table181114[[#This Row],[2024]]/Table181114[[#This Row],[2020]])^(1/5)-1 -> 0.014667964 | H3: Particulars | I3: 2020 | J3: 2021 | K3: 2022 | L3: 2023 | M3: 2024
A4: EBIT Margin | B4: =AVERAGE(Financials!B7:F7)/AVERAGE(Financials!B3:F3) -> 0.27798481 | C4: =AVERAGE(Financials!I7:M7)/AVERAGE(Financials!I3:M3) -> 0.21743428 | D4: =AVERAGE(Financials!P7:T7)/AVERAGE(Financials!P3:T3) -> 0.3196426 | E4: =AVERAGE(Financials!X7:AB7)/AVERAGE(Financials!X3:AB3) -> 0.24554807 | F4: =AVERAGE(Financials!AF7:AJ7)/AVERAGE(Financials!AF3:AJ3) -> 0.21319973 | H4: WC-Pfizer | I4: =Financials!B18-Financials!B20 -> 9147 | J4: =Financials!C18-Financials!C20 -> 17022 | K4: =Financials!D18-Financials!D20 -> 9121 | L4: =Financials!E18-Financials!E20 -> -4461 | M4: =Financials!F18-Financials!F20 -> 7363
A5: Depreciation | B5: =AVERAGE(Financials!B8:F8)/AVERAGE(Financials!B3:F3) -> 0.059889359 | C5: =AVERAGE(Financials!I31:M31)/AVERAGE(Financials!I3:M3) -> 0.068217823 | D5: =AVERAGE(Financials!P31:T31)/AVERAGE(Financials!P3:T3) -> 0.14407923 | E5: =AVERAGE(Financials!X31:AB31)/AVERAGE(Financials!X3:AB3) -> 0.047880503 | F5: =AVERAGE(Financials!AF31:AJ31)/AVERAGE(Financials!AF3:AJ3) -> 0.081781882 | H5: WC-Merck | I5: =Financials!I18-Financials!I20 -> 437 | J5: =Financials!J18-Financials!J20 -> 6394 | K5: =Financials!K18-Financials!K20 -> 11483 | L5: =Financials!L18-Financials!L20 -> 6474 | M5: =Financials!M18-Financials!M20 -> 10362
A6: Capex | B6: =AVERAGE(Financials!B28:F28)/AVERAGE(Financials!B3:F3) -> 0.043232595 | C6: =AVERAGE(Financials!I28:M28)/AVERAGE(Financials!I3:M3) -> 0.07314532 | D6: =AVERAGE(Financials!P28:T28)/AVERAGE(Financials!P3:T3) -> 0.033242429 | E6: =AVERAGE(Financials!X28:AB28)/AVERAGE(Financials!X3:AB3) -> 0.081320874 | F6: =AVERAGE(Financials!AF28:AJ28)/AVERAGE(Financials!AF3:AJ3) -> 0.044859213 | H6: WC-Amgen | I6: =Financials!P18-Financials!P20 -> 9491 | J6: =Financials!Q18-Financials!Q20 -> 7201 | K6: =Financials!R18-Financials!R20 -> 6499 | L6: =Financials!S18-Financials!S20 -> 11940 | M6: =Financials!T18-Financials!T20 -> 5931
A7: Working capital | B7: =AVERAGE(I4:M4)/AVERAGE(Financials!B3:F3) -> 0.11015673 | C7: =AVERAGE(I5:M5)/AVERAGE(Financials!I3:M3) -> 0.12541746 | D7: =AVERAGE(I6:M6)/AVERAGE(Financials!P3:T3) -> 0.29468925 | E7: =AVERAGE(Table19[[#This Row],[2020]:[2024]])/AVERAGE(Financials!X3:AB3) -> 0.075192568 | F7: =AVERAGE(I8:M8)/AVERAGE(Financials!AF3:AJ3) -> 0.082585867 | H7: WC-LLY | I7: =Financials!X18-Financials!X20 -> 4980.5 | J7: =Financials!Y18-Financials!Y20 -> 3399.7 | K7: =Financials!Z18-Financials!Z20 -> 896.3 | L7: =Financials!AA18-Financials!AA20 -> -1566.2 | M7: =Financials!AB18-Financials!AB20 -> 4363.1
A8: Project horizon (years) | B8: 6 | C8: 6 | D8: 6 | E8: 6 | F8: 6 | H8: WC-JnJ | I8: =Financials!AF18-Financials!AF20 -> 8744 | J8: =Financials!AG18-Financials!AG20 -> 15753 | K8: =Financials!AH18-Financials!AH20 -> -508 | L8: =Financials!AI18-Financials!AI20 -> 7213 | M8: =Financials!AJ18-Financials!AJ20 -> 5572
A9: Risk-free rate | B9: 0.04059 | C9: 0.04059 | D9: 0.04059 | E9: 0.04059 | F9: 0.04059
A10: Equity risk premium | B10: 0.05 | C10: 0.05 | D10: 0.05 | E10: 0.05 | F10: 0.05
A11: Beta | B11: ='Company Profile'!B9 -> 0.408 | C11: ='Company Profile'!C9 -> 0.2832 | D11: ='Company Profile'!D9 -> 0.4103 | E11: ='Company Profile'!E9 -> 0.3349 | F11: ='Company Profile'!F9 -> 0.3372
A12: Cost of equity | B12: =B9+(B10*B11) -> 0.06099 | C12: =C9+(C10*C11) -> 0.05475 | D12: =D9+(D10*D11) -> 0.061105 | E12: =E9+(E10*E11) -> 0.057335 | F12: =F9+(F10*F11) -> 0.05745 | H12: Particulars | I12: 2025 | J12: 2026 | K12: 2027 | L12: 2028 | M12: 2029 | N12: 2030
A13: Kd (pre-tax) | B13: =AVERAGE(Financials!B9:F9)/AVERAGE(Financials!B22:F22) -> 0.043620676 | C13: =AVERAGE(Financials!I9:M9)/AVERAGE(Financials!I22:M22) -> 0.029901639 | D13: =AVERAGE(Financials!P9:T9)/AVERAGE(Financials!P22:T22) -> 0.043030719 | E13: =AVERAGE(Financials!X9:AB9)/AVERAGE(Financials!X22:AB22) -> 0.025076413 | F13: =AVERAGE(Financials!AF9:AJ9)/AVERAGE(Financials!AF22:AJ22) -> 0.012522761 | H13: WC-Pfizer | I13: =DCF!B3*'Assumptions & WACC'!$B$7 -> 7619.4109 | J13: =DCF!C3*'Assumptions & WACC'!$B$7 -> 8283.0502 | K13: =DCF!D3*'Assumptions & WACC'!$B$7 -> 9004.4916 | L13: =DCF!E3*'Assumptions & WACC'!$B$7 -> 9788.7695 | M13: =DCF!F3*'Assumptions & WACC'!$B$7 -> 10641.357 | N13: =DCF!G3*'Assumptions & WACC'!$B$7 -> 11568.203
A14: Tax rate | B14: 0.23 | C14: 0.23 | D14: 0.23 | E14: 0.23 | F14: 0.23 | H14: WC-Merck | I14: =DCF!J3*'Assumptions & WACC'!$C$7 -> 8529.0926 | J14: =DCF!K3*'Assumptions & WACC'!$C$7 -> 9039.1822 | K14: =DCF!L3*'Assumptions & WACC'!$C$7 -> 9579.7781 | L14: =DCF!M3*'Assumptions & WACC'!$C$7 -> 10152.705 | M14: =DCF!N3*'Assumptions & WACC'!$C$7 -> 10759.896 | N14: =DCF!O3*'Assumptions & WACC'!$C$7 -> 11403.401
A15: Kd (after-tax) | B15: =B13*(1-B14) -> 0.03358792 | C15: =C13*(1-C14) -> 0.023024262 | D15: =D13*(1-D14) -> 0.033133654 | E15: =E13*(1-E14) -> 0.019308838 | F15: =F13*(1-F14) -> 0.0096425259 | H15: =H6 -> WC-Amgen | I15: =DCF!R3*'Assumptions & WACC'!$D$7 -> 10403.647 | J15: =DCF!S3*'Assumptions & WACC'!$D$7 -> 10988.756 | K15: =DCF!T3*'Assumptions & WACC'!$D$7 -> 11606.772 | L15: =DCF!U3*'Assumptions & WACC'!$D$7 -> 12259.545 | M15: =DCF!V3*'Assumptions & WACC'!$D$7 -> 12949.031 | N15: =DCF!W3*'Assumptions & WACC'!$D$7 -> 13677.293
A16: Market cap | B16: ='Company Profile'!B8 -> 141574.13 | C16: ='Company Profile'!C8 -> 235916.19 | D16: ='Company Profile'!D8 -> 184375.79 | E16: ='Company Profile'!E8 -> 991792.69 | F16: ='Company Profile'!F8 -> 488267.72 | H16: =H7 -> WC-LLY | I16: =DCF!Z3*'Assumptions & WACC'!$E$7 -> 3824.2829 | J16: =DCF!AA3*'Assumptions & WACC'!$E$7 -> 4318.1795 | K16: =DCF!AB3*'Assumptions & WACC'!$E$7 -> 4875.8616 | L16: =DCF!AC3*'Assumptions & WACC'!$E$7 -> 5505.567 | M16: =DCF!AD3*'Assumptions & WACC'!$E$7 -> 6216.5972 | N16: =DCF!AE3*'Assumptions & WACC'!$E$7 -> 7019.4553
A17: Total debt | B17: =Financials!F22 -> 64351 | C17: =Financials!M22 -> 37111 | D17: =Financials!T22 -> 60099 | E17: =Financials!AB22 -> 33644.2 | F17: =Financials!AJ22 -> 36634 | H17: =H8 -> WC-JnJ | I17: =DCF!AH3*'Assumptions & WACC'!$F$7 -> 7442.9541 | J17: =DCF!AI3*'Assumptions & WACC'!$F$7 -> 7552.1271 | K17: =DCF!AJ3*'Assumptions & WACC'!$F$7 -> 7662.9014 | L17: =DCF!AK3*'Assumptions & WACC'!$F$7 -> 7775.3006 | M17: =DCF!AL3*'Assumptions & WACC'!$F$7 -> 7889.3484 | N17: =DCF!AM3*'Assumptions & WACC'!$F$7 -> 8005.0691
A18: Total capital | B18: =B16+B17 -> 205925.13 | C18: =C16+C17 -> 273027.19 | D18: =D16+D17 -> 244474.79 | E18: =E16+E17 -> 1025436.9 | F18: =F16+F17 -> 524901.72
A19: Debt weight | B19: =B17/B18 -> 0.31249707 | C19: =C17/C18 -> 0.13592419 | D19: =D17/D18 -> 0.24582903 | E19: =E17/E18 -> 0.032809625 | F19: =F17/F18 -> 0.069792112
A20: Equity weight | B20: =B16/B18 -> 0.68750293 | C20: =C16/C18 -> 0.86407581 | D20: =D16/D18 -> 0.75417097 | E20: =E16/E18 -> 0.96719037 | F20: =F16/F18 -> 0.93020789
A21: WACC | B21: =(B12*B20)+(B15*B19) -> 0.05242693 | C21: =(C12*C20)+(C15*C19) -> 0.050437705 | D21: =(D12*D20)+(D15*D19) -> 0.054228831 | E21: =(E12*E20)+(E15*E19) -> 0.056087376 | F21: =(F12*F20)+(F15*F19) -> 0.054113415
A22: Terminal Growth rate | B22: 0.0225 | C22: 0.0225 | D22: 0.0225 | E22: 0.0225 | F22: 0.0225
A23: PV discount (terminal year) | B23: =1/(1+B21)^6 -> 0.73594996 | C23: =1/(1+C21)^6 -> 0.74435171 | D23: =1/(1+D21)^6 -> 0.72843477 | E23: =1/(1+E21)^6 -> 0.72077695 | F23: =1/(1+F21)^6 -> 0.72891344
A24: Cash & cash equivalents | B24: =Financials!F15 -> 1043 | C24: =Financials!M15 -> 13242 | D24: =Financials!T15 -> 11973 | E24: =Financials!AB15 -> 3268.4 | F24: =Financials!AJ15 -> 24105
A25: Outstanding shares | B25: 5700 | C25: ='Company Profile'!C6 -> 2482.022 | D25: ='Company Profile'!D6 -> 538.4807 | E25: ='Company Profile'!E6 -> 945.3838 | F25: ='Company Profile'!F6 -> 2409.295

Sheet DCF
G1: Pfizer | O1: Merck | W1: Amgen | AE1: LLY | AM1: J&J
A2: Particulars | B2: 2025 | C2: 2026 | D2: 2027 | E2: 2028 | F2: 2029 | G2: 2030 | I2: Particulars | J2: 2025 | K2: 2026 | L2: 2027 | M2: 2028 | N2: 2029 | O2: 2030 | Q2: Particulars | R2: 2025 | S2: 2026 | T2: 2027 | U2: 2028 | V2: 2029 | W2: 2030 | Y2: Particulars | Z2: 2025 | AA2: 2026 | AB2: 2027 | AC2: 2028 | AD2: 2029 | AE2: 2030 | AG2: Particulars | AH2: 2025 | AI2: 2026 | AJ2: 2027 | AK2: 2028 | AL2: 2029 | AM2: 2030
A3: Revenue | B3: =Table1[[#This Row],[2024]]*(1+'Assumptions & WACC'!B3) -> 69168.817 | C3: =Table9[[#This Row],[2025]]*(1+'Assumptions & WACC'!$B$3) -> 75193.318 | D3: =Table9[[#This Row],[2026]]*(1+'Assumptions & WACC'!$B$3) -> 81742.545 | E3: =Table9[[#This Row],[2027]]*(1+'Assumptions & WACC'!$B$3) -> 88862.199 | F3: =Table9[[#This Row],[2028]]*(1+'Assumptions & WACC'!$B$3) -> 96601.965 | G3: =Table9[[#This Row],[2029]]*(1+'Assumptions & WACC'!$B$3) -> 105015.85 | I3: Revenue | J3: =Table18[[#This Row],[2024]]*(1+'Assumptions & WACC'!C3) -> 68005.622 | K3: =Table10[[#This Row],[2025]]*(1+'Assumptions & WACC'!$C$3) -> 72072.755 | L3: =Table10[[#This Row],[2026]]*(1+'Assumptions & WACC'!$C$3) -> 76383.128 | M3: =Table10[[#This Row],[2027]]*(1+'Assumptions & WACC'!$C$3) -> 80951.285 | N3: =Table10[[#This Row],[2028]]*(1+'Assumptions & WACC'!$C$3) -> 85792.645 | O3: =Table10[[#This Row],[2029]]*(1+'Assumptions & WACC'!$C$3) -> 90923.547 | Q3: Revenue | R3: =Table15[[#This Row],[2024]]*(1+'Assumptions & WACC'!D3) -> 35303.79 | S3: =Table931[[#This Row],[2025]]*(1+'Assumptions & WACC'!$D$3) -> 37289.301 | T3: =Table931[[#This Row],[2026]]*(1+'Assumptions & WACC'!$D$3) -> 39386.478 | U3: =Table931[[#This Row],[2027]]*(1+'Assumptions & WACC'!$D$3) -> 41601.602 | V3: =Table931[[#This Row],[2028]]*(1+'Assumptions & WACC'!$D$3) -> 43941.306 | W3: =Table931[[#This Row],[2029]]*(1+'Assumptions & WACC'!$D$3) -> 46412.597 | Y3: Revenue | Z3: =Table1811[[#This Row],[2024]]*(1+'Assumptions & WACC'!E3) -> 50859.852 | AA3: =Table1032[[#This Row],[2025]]*(1+'Assumptions & WACC'!$E$3) -> 57428.275 | AB3: =Table1032[[#This Row],[2026]]*(1+'Assumptions & WACC'!$E$3) -> 64844.994 | AC3: =Table1032[[#This Row],[2027]]*(1+'Assumptions & WACC'!$E$3) -> 73219.563 | AD3: =Table1032[[#This Row],[2028]]*(1+'Assumptions & WACC'!$E$3) -> 82675.687 | AE3: =Table1032[[#This Row],[2029]]*(1+'Assumptions & WACC'!$E$3) -> 93353.046 | AG3: Revenue | AH3: =Table181114[[#This Row],[2024]]*(1+'Assumptions & WACC'!F3) -> 90123.823 | AI3: =Table93135[[#This Row],[2025]]*(1+'Assumptions & WACC'!$F$3) -> 91445.756 | AJ3: =Table93135[[#This Row],[2026]]*(1+'Assumptions & WACC'!$F$3) -> 92787.079 | AK3: =Table93135[[#This Row],[2027]]*(1+'Assumptions & WACC'!$F$3) -> 94148.077 | AL3: =Table93135[[#This Row],[2028]]*(1+'Assumptions & WACC'!$F$3) -> 95529.038 | AM3: =Table93135[[#This Row],[2029]]*(1+'Assumptions & WACC'!$F$3) -> 96930.254
A4: EBIT | B4: =B3*'Assumptions & WACC'!$B$4 -> 19227.88 | C4: =C3*'Assumptions & WACC'!$B$4 -> 20902.6 | D4: =D3*'Assumptions & WACC'!$B$4 -> 22723.185 | E4: =E3*'Assumptions & WACC'!$B$4 -> 24702.341 | F4: =F3*'Assumptions & WACC'!$B$4 -> 26853.878 | G4: =G3*'Assumptions & WACC'!$B$4 -> 29192.811 | I4: EBIT | J4: =J3*'Assumptions & WACC'!$C$4 -> 14786.753 | K4: =K3*'Assumptions & WACC'!$C$4 -> 15671.087 | L4: =L3*'Assumptions & WACC'!$C$4 -> 16608.31 | M4: =M3*'Assumptions & WACC'!$C$4 -> 17601.584 | N4: =N3*'Assumptions & WACC'!$C$4 -> 18654.262 | O4: =O3*'Assumptions & WACC'!$C$4 -> 19769.896 | Q4: EBIT | R4: =R3*'Assumptions & WACC'!$D$4 -> 11284.595 | S4: =S3*'Assumptions & WACC'!$D$4 -> 11919.249 | T4: =T3*'Assumptions & WACC'!$D$4 -> 12589.596 | U4: =U3*'Assumptions & WACC'!$D$4 -> 13297.644 | V4: =V3*'Assumptions & WACC'!$D$4 -> 14045.513 | W4: =W3*'Assumptions & WACC'!$D$4 -> 14835.443 | Y4: EBIT | Z4: =Z3*'Assumptions & WACC'!$E$4 -> 12488.539 | AA4: =AA3*'Assumptions & WACC'!$E$4 -> 14101.402 | AB4: =AB3*'Assumptions & WACC'!$E$4 -> 15922.563 | AC4: =AC3*'Assumptions & WACC'!$E$4 -> 17978.923 | AD4: =AD3*'Assumptions & WACC'!$E$4 -> 20300.856 | AE4: =AE3*'Assumptions & WACC'!$E$4 -> 22922.66 | AG4: EBIT | AH4: =AH3*'Assumptions & WACC'!$F$4 -> 19214.374 | AI4: =AI3*'Assumptions & WACC'!$F$4 -> 19496.21 | AJ4: =AJ3*'Assumptions & WACC'!$F$4 -> 19782.18 | AK4: =AK3*'Assumptions & WACC'!$F$4 -> 20072.344 | AL4: =AL3*'Assumptions & WACC'!$F$4 -> 20366.765 | AM4: =AM3*'Assumptions & WACC'!$F$4 -> 20665.504
A5: NOPAT | B5: =B4*(1-'Assumptions & WACC'!$B$14) -> 14805.468 | C5: =C4*(1-'Assumptions & WACC'!$B$14) -> 16095.002 | D5: =D4*(1-'Assumptions & WACC'!$B$14) -> 17496.853 | E5: =E4*(1-'Assumptions & WACC'!$B$14) -> 19020.803 | F5: =F4*(1-'Assumptions & WACC'!$B$14) -> 20677.486 | G5: =G4*(1-'Assumptions & WACC'!$B$14) -> 22478.465 | I5: NOPAT | J5: =J4*(1-'Assumptions & WACC'!$C$14) -> 11385.8 | K5: =K4*(1-'Assumptions & WACC'!$C$14) -> 12066.737 | L5: =L4*(1-'Assumptions & WACC'!$C$14) -> 12788.399 | M5: =M4*(1-'Assumptions & WACC'!$C$14) -> 13553.22 | N5: =N4*(1-'Assumptions & WACC'!$C$14) -> 14363.782 | O5: =O4*(1-'Assumptions & WACC'!$C$14) -> 15222.82 | Q5: NOPAT | R5: =R4*(1-'Assumptions & WACC'!$B$14) -> 8689.1383 | S5: =S4*(1-'Assumptions & WACC'!$B$14) -> 9177.8218 | T5: =T4*(1-'Assumptions & WACC'!$B$14) -> 9693.9891 | U5: =U4*(1-'Assumptions & WACC'!$B$14) -> 10239.186 | V5: =V4*(1-'Assumptions & WACC'!$B$14) -> 10815.045 | W5: =W4*(1-'Assumptions & WACC'!$B$14) -> 11423.291 | Y5: NOPAT | Z5: =Z4*(1-'Assumptions & WACC'!$C$14) -> 9616.1748 | AA5: =AA4*(1-'Assumptions & WACC'!$C$14) -> 10858.08 | AB5: =AB4*(1-'Assumptions & WACC'!$C$14) -> 12260.374 | AC5: =AC4*(1-'Assumptions & WACC'!$C$14) -> 13843.77 | AD5: =AD4*(1-'Assumptions & WACC'!$C$14) -> 15631.659 | AE5: =AE4*(1-'Assumptions & WACC'!$C$14) -> 17650.449 | AG5: NOPAT | AH5: =AH4*(1-'Assumptions & WACC'!$B$14) -> 14795.068 | AI5: =AI4*(1-'Assumptions & WACC'!$B$14) -> 15012.082 | AJ5: =AJ4*(1-'Assumptions & WACC'!$B$14) -> 15232.278 | AK5: =AK4*(1-'Assumptions & WACC'!$B$14) -> 15455.705 | AL5: =AL4*(1-'Assumptions & WACC'!$B$14) -> 15682.409 | AM5: =AM4*(1-'Assumptions & WACC'!$B$14) -> 15912.438
A6: Depreciation | B6: =B3*'Assumptions & WACC'!$B$5 -> 4142.4761 | C6: =C3*'Assumptions & WACC'!$B$5 -> 4503.2796 | D6: =D3*'Assumptions & WACC'!$B$5 -> 4895.5086 | E6: =E3*'Assumptions & WACC'!$B$5 -> 5321.9001 | F6: =F3*'Assumptions & WACC'!$B$5 -> 5785.4297 | G6: =G3*'Assumptions & WACC'!$B$5 -> 6289.332 | I6: Depreciation | J6: =J3*'Assumptions & WACC'!$C$5 -> 4639.1955 | K6: =K3*'Assumptions & WACC'!$C$5 -> 4916.6465 | L6: =L3*'Assumptions & WACC'!$C$5 -> 5210.6907 | M6: =M3*'Assumptions & WACC'!$C$5 -> 5522.3205 | N6: =N3*'Assumptions & WACC'!$C$5 -> 5852.5875 | O6: =O3*'Assumptions & WACC'!$C$5 -> 6202.6065 | Q6: Depreciation | R6: =R3*'Assumptions & WACC'!$D$5 -> 5086.5429 | S6: =S3*'Assumptions & WACC'!$D$5 -> 5372.6138 | T6: =T3*'Assumptions & WACC'!$D$5 -> 5674.7735 | U6: =U3*'Assumptions & WACC'!$D$5 -> 5993.9268 | V6: =V3*'Assumptions & WACC'!$D$5 -> 6331.0296 | W6: =W3*'Assumptions & WACC'!$D$5 -> 6687.0913 | Y6: Depreciation | Z6: =Z3*'Assumptions & WACC'!$E$5 -> 2435.1953 | AA6: =AA3*'Assumptions & WACC'!$E$5 -> 2749.6947 | AB6: =AB3*'Assumptions & WACC'!$E$5 -> 3104.8109 | AC6: =AC3*'Assumptions & WACC'!$E$5 -> 3505.7895 | AD6: =AD3*'Assumptions & WACC'!$E$5 -> 3958.5535 | AE6: =AE3*'Assumptions & WACC'!$E$5 -> 4469.7908 | AG6: Depreciation | AH6: =AH3*'Assumptions & WACC'!$F$5 -> 7370.4959 | AI6: =AI3*'Assumptions & WACC'!$F$5 -> 7478.6061 | AJ6: =AJ3*'Assumptions & WACC'!$F$5 -> 7588.302 | AK6: =AK3*'Assumptions & WACC'!$F$5 -> 7699.6069 | AL6: =AL3*'Assumptions & WACC'!$F$5 -> 7812.5445 | AM6: =AM3*'Assumptions & WACC'!$F$5 -> 7927.1386
A7: Capex | B7: =B3*'Assumptions & WACC'!$B$6 -> 2990.3474 | C7: =C3*'Assumptions & WACC'!$B$6 -> 3250.8023 | D7: =D3*'Assumptions & WACC'!$B$6 -> 3533.9423 | E7: =E3*'Assumptions & WACC'!$B$6 -> 3841.7434 | F7: =F3*'Assumptions & WACC'!$B$6 -> 4176.3536 | G7: =G3*'Assumptions & WACC'!$B$6 -> 4540.1078 | I7: Capex | J7: =J3*'Assumptions & WACC'!$C$6 -> 4974.293 | K7: =K3*'Assumptions & WACC'!$C$6 -> 5271.7848 | L7: =L3*'Assumptions & WACC'!$C$6 -> 5587.0683 | M7: =M3*'Assumptions & WACC'!$C$6 -> 5921.2077 | N7: =N3*'Assumptions & WACC'!$C$6 -> 6275.3305 | O7: =O3*'Assumptions & WACC'!$C$6 -> 6650.632 | Q7: Capex | R7: =R3*'Assumptions & WACC'!$D$6 -> 1173.5837 | S7: =S3*'Assumptions & WACC'!$D$6 -> 1239.5869 | T7: =T3*'Assumptions & WACC'!$D$6 -> 1309.3022 | U7: =U3*'Assumptions & WACC'!$D$6 -> 1382.9383 | V7: =V3*'Assumptions & WACC'!$D$6 -> 1460.7157 | W7: =W3*'Assumptions & WACC'!$D$6 -> 1542.8675 | Y7: Capex | Z7: =Z3*'Assumptions & WACC'!$E$6 -> 4135.9676 | AA7: =AA3*'Assumptions & WACC'!$E$6 -> 4670.1176 | AB7: =AB3*'Assumptions & WACC'!$E$6 -> 5273.2516 | AC7: =AC3*'Assumptions & WACC'!$E$6 -> 5954.2789 | AD7: =AD3*'Assumptions & WACC'!$E$6 -> 6723.2591 | AE7: =AE3*'Assumptions & WACC'!$E$6 -> 7591.5513 | AG7: Capex | AH7: =AH3*'Assumptions & WACC'!$F$6 -> 4042.8838 | AI7: =AI3*'Assumptions & WACC'!$F$6 -> 4102.1846 | AJ7: =AJ3*'Assumptions & WACC'!$F$6 -> 4162.3553 | AK7: =AK3*'Assumptions & WACC'!$F$6 -> 4223.4086 | AL7: =AL3*'Assumptions & WACC'!$F$6 -> 4285.3574 | AM7: =AM3*'Assumptions & WACC'!$F$6 -> 4348.2149
A8: Change in Working capital | B8: ='Assumptions & WACC'!I13-'Assumptions & WACC'!M4 -> 256.41087 | C8: ='Assumptions & WACC'!J13-'Assumptions & WACC'!I13 -> 663.63937 | D8: ='Assumptions & WACC'!K13-'Assumptions & WACC'!J13 -> 721.44137 | E8: ='Assumptions & WACC'!L13-'Assumptions & WACC'!K13 -> 784.27784 | F8: ='Assumptions & WACC'!M13-'Assumptions & WACC'!L13 -> 852.58728 | G8: ='Assumptions & WACC'!N13-'Assumptions & WACC'!M13 -> 926.84636 | I8: Change in Working capital | J8: ='Assumptions & WACC'!I14-'Assumptions & WACC'!M5 -> -1832.9074 | K8: ='Assumptions & WACC'!J14-'Assumptions & WACC'!I14 -> 510.08961 | L8: ='Assumptions & WACC'!K14-'Assumptions & WACC'!J14 -> 540.59595 | M8: ='Assumptions & WACC'!L14-'Assumptions & WACC'!K14 -> 572.92674 | N8: ='Assumptions & WACC'!M14-'Assumptions & WACC'!L14 -> 607.19111 | O8: ='Assumptions & WACC'!N14-'Assumptions & WACC'!M14 -> 643.50469 | Q8: Change in Working capital | R8: ='Assumptions & WACC'!I15-'Assumptions & WACC'!M6 -> 4472.6474 | S8: ='Assumptions & WACC'!J15-'Assumptions & WACC'!I15 -> 585.10868 | T8: ='Assumptions & WACC'!K15-'Assumptions & WACC'!J15 -> 618.01561 | U8: ='Assumptions & WACC'!L15-'Assumptions & WACC'!K15 -> 652.77326 | V8: ='Assumptions & WACC'!M15-'Assumptions & WACC'!L15 -> 689.4857 | W8: ='Assumptions & WACC'!N15-'Assumptions & WACC'!M15 -> 728.26288 | Y8: Change in Working capital | Z8: ='Assumptions & WACC'!I16-'Assumptions & WACC'!M7 -> -538.81708 | AA8: ='Assumptions & WACC'!J16-'Assumptions & WACC'!I16 -> 493.8966 | AB8: ='Assumptions & WACC'!K16-'Assumptions & WACC'!J16 -> 557.68211 | AC8: ='Assumptions & WACC'!L16-'Assumptions & WACC'!K16 -> 629.70537 | AD8: ='Assumptions & WACC'!M16-'Assumptions & WACC'!L16 -> 711.03024 | AE8: ='Assumptions & WACC'!N16-'Assumptions & WACC'!M16 -> 802.85802 | AG8: Change in Working capital | AH8: ='Assumptions & WACC'!I17-Table19[[#This Row],[2024]] -> 1870.9541 | AI8: ='Assumptions & WACC'!J17-'Assumptions & WACC'!I17 -> 109.17299 | AJ8: ='Assumptions & WACC'!K17-'Assumptions & WACC'!J17 -> 110.77433 | AK8: ='Assumptions & WACC'!L17-'Assumptions & WACC'!K17 -> 112.39916 | AL8: ='Assumptions & WACC'!M17-'Assumptions & WACC'!L17 -> 114.04783 | AM8: ='Assumptions & WACC'!N17-'Assumptions & WACC'!M17 -> 115.72068
A9: FCFF | B9: =B5+B6-B7-B8 -> 15701.186 | C9: =C5+C6-C7-C8 -> 16683.84 | D9: =D5+D6-D7-D8 -> 18136.978 | E9: =E5+E6-E7-E8 -> 19716.681 | F9: =F5+F6-F7-F8 -> 21433.975 | G9: =G5+G6-G7-G8 -> 23300.843 | I9: FCFF | J9: =J5+J6-J7-J8 -> 12883.61 | K9: =K5+K6-K7-K8 -> 11201.509 | L9: =L5+L6-L7-L8 -> 11871.425 | M9: =M5+M6-M7-M8 -> 12581.406 | N9: =N5+N6-N7-N8 -> 13333.847 | O9: =O5+O6-O7-O8 -> 14131.289 | Q9: FCFF | R9: =R5+R6-R7-R8 -> 8129.4502 | S9: =S5+S6-S7-S8 -> 12725.74 | T9: =T5+T6-T7-T8 -> 13441.445 | U9: =U5+U6-U7-U8 -> 14197.401 | V9: =V5+V6-V7-V8 -> 14995.874 | W9: =W5+W6-W7-W8 -> 15839.252 | Y9: FCFF | Z9: =Z5+Z6-Z7-Z8 -> 8454.2195 | AA9: =AA5+AA6-AA7-AA8 -> 8443.7603 | AB9: =AB5+AB6-AB7-AB8 -> 9534.2509 | AC9: =AC5+AC6-AC7-AC8 -> 10765.576 | AD9: =AD5+AD6-AD7-AD8 -> 12155.923 | AE9: =AE5+AE6-AE7-AE8 -> 13725.83 | AG9: FCFF | AH9: =AH5+AH6-AH7-AH8 -> 16251.726 | AI9: =AI5+AI6-AI7-AI8 -> 18279.33 | AJ9: =AJ5+AJ6-AJ7-AJ8 -> 18547.451 | AK9: =AK5+AK6-AK7-AK8 -> 18819.504 | AL9: =AL5+AL6-AL7-AL8 -> 19095.548 | AM9: =AM5+AM6-AM7-AM8 -> 19375.641
A12: Metrics | B12: Value | I12: Metrics | J12: Value | Q12: Metrics | R12: Value | Y12: Metrics | Z12: Value | AG12: Metrics | AH12: Value
A13: Terminal Value | B13: =G9*(1+'Assumptions & WACC'!B22)/('Assumptions & WACC'!B21-'Assumptions & WACC'!B22) -> 796109.43 | I13: Terminal Value | J13: =O9*(1+'Assumptions & WACC'!C21)/('Assumptions & WACC'!C21-'Assumptions & WACC'!C22) -> 531326.37 | Q13: Terminal Value | R13: =W9*(1+'Assumptions & WACC'!D22)/('Assumptions & WACC'!D21-'Assumptions & WACC'!D22) -> 510439.08 | Y13: Terminal Value | Z13: =AE9*(1+'Assumptions & WACC'!E22)/('Assumptions & WACC'!E21-'Assumptions & WACC'!E22) -> 417855.25 | AG13: Terminal Value | AH13: =AM9*(1+'Assumptions & WACC'!F22)/('Assumptions & WACC'!F21-'Assumptions & WACC'!F22) -> 626683.08
A14: PV of Terminal value | B14: =B13*'Assumptions & WACC'!B23 -> 585896.7 | I14: PV of Terminal value | J14: =J13*'Assumptions & WACC'!C23 -> 395493.69 | Q14: PV of Terminal value | R14: =R13*'Assumptions & WACC'!D23 -> 371821.57 | Y14: PV of Terminal value | Z14: =Z13*'Assumptions & WACC'!E23 -> 301180.43 | AG14: PV of Terminal value | AH14: =AH13*'Assumptions & WACC'!F23 -> 456797.72
A15: PV of FCFF | B15: =NPV('Assumptions & WACC'!B21,DCF!B9:G9) -> 95362.755 | I15: PV of FCFF | J15: =NPV('Assumptions & WACC'!C21,DCF!J9:O9) -> 63936.627 | Q15: PV of FCFF | R15: =NPV('Assumptions & WACC'!D21,DCF!R9:W9) -> 65181.236 | Y15: PV of FCFF | Z15: =NPV('Assumptions & WACC'!E21,DCF!Z9:AE9) -> 51471.184 | AG15: PV of FCFF | AH15: =NPV('Assumptions & WACC'!F21,DCF!AH9:AM9) -> 91741.296
A16: Total enterprise value | B16: =B14+B15 -> 681259.46 | I16: Total enterprise value | J16: =J14+J15 -> 459430.32 | Q16: Total enterprise value | R16: =R14+R15 -> 437002.81 | Y16: Total enterprise value | Z16: =Z14+Z15 -> 352651.62 | AG16: Total enterprise value | AH16: =AH14+AH15 -> 548539.02
A17: Net debt | B17: ='Assumptions & WACC'!B17-'Assumptions & WACC'!B24 -> 63308 | I17: Net debt | J17: ='Assumptions & WACC'!C17-'Assumptions & WACC'!C24 -> 23869 | Q17: Net debt | R17: ='Assumptions & WACC'!D17-'Assumptions & WACC'!D24 -> 48126 | Y17: Net debt | Z17: ='Assumptions & WACC'!E17-'Assumptions & WACC'!E24 -> 30375.8 | AG17: Net debt | AH17: ='Assumptions & WACC'!F17-'Assumptions & WACC'!F24 -> 12529
A18: Total equity value | B18: =B16-B17 -> 617951.46 | I18: Total equity value | J18: =J16-J17 -> 435561.32 | Q18: Total equity value | R18: =R16-R17 -> 388876.81 | Y18: Total equity value | Z18: =Z16-Z17 -> 322275.82 | AG18: Total equity value | AH18: =AH16-AH17 -> 536010.02
A19: Outstanding shares | B19: ='Assumptions & WACC'!B25 -> 5700 | I19: Outstanding shares | J19: ='Assumptions & WACC'!C25 -> 2482.022 | Q19: Outstanding shares | R19: ='Assumptions & WACC'!D25 -> 538.4807 | Y19: Outstanding shares | Z19: ='Assumptions & WACC'!E25 -> 945.3838 | AG19: Outstanding shares | AH19: ='Assumptions & WACC'!F25 -> 2409.295
A20: Intrinsic value | B20: =B18/B19 -> 108.41254 | I20: Intrinsic value | J20: =J18/J19 -> 175.48649 | Q20: Intrinsic value | R20: =R18/R19 -> 722.17409 | Y20: Intrinsic value | Z20: =Z18/Z19 -> 340.89416 | AG20: Intrinsic value | AH20: =AH18/AH19 -> 222.47588
A21: Current market price | B21: ='Company Profile'!B3 -> 24.9 | I21: Current market price | J21: ='Company Profile'!C3 -> 95.05 | Q21: Current market price | R21: ='Company Profile'!D3 -> 342.4 | Y21: Current market price | Z21: ='Company Profile'!E3 -> 1049.09 | AG21: Current market price | AH21: ='Company Profile'!F3 -> 202.66
A22: Upside/Downside | B22: =(B20-B21)/B21 -> 3.3539171 | I22: Upside/Downside | J22: =(J20-J21)/J21 -> 0.84625445 | Q22: Upside/Downside | R22: =(R20-R21)/R21 -> 1.1091533 | Y22: Upside/Downside | Z22: =(Z20-Z21)/Z21 -> -0.67505728 | AG22: Upside/Downside | AH22: =(AH20-AH21)/AH21 -> 0.097778924

Sheet Relative
A1: RELATIVE
A2: Company | B2: EV/EBITDA | C2: P/E | D2: P/S | E2: P/B
A3: #VALUE! | B3: 57.58 | C3: {=_FV(A3,"P/E",TRUE)} -> 51.3025 | D3: 17.08 | E3: 48.66 | H3: Company | I3: EV/EBITDA | J3: P/E | K3: P/S | L3: P/B | N3: Shares
A4: #VALUE! | B4: 20.21 | C4: {=_FV(A4,"P/E",TRUE)} -> 13.3668 | D4: 10.18 | E4: 22.72 | H4: Pfizer | I4: =(B23*B20)/$N$4 -> 102.48659 | J4: =(C23*C20)/$N$4 -> 27.909757 | K4: =(D23*D20)/$N$4 -> 61.994465 | L4: =(E23*E20)/$N$4 -> 195.52791 | N4: ='Assumptions & WACC'!B25 -> 5700
A5: #VALUE! | B5: 14.16 | C5: {=_FV(A5,"P/E",TRUE)} -> 19.5606 | D5: 4.01 | E5: 4.96 | H5: Merck | I5: =(B24*B20)/$N$5 -> 309.28042 | J5: =(C24*C20)/$N$5 -> 146.83737 | K5: =(D24*D20)/$N$5 -> 143.58174 | L5: =(E24*E20)/$N$5 -> 235.29097 | N5: ='Assumptions & WACC'!C25 -> 2482.022
A6: #VALUE! | B6: 20.71 | C6: {=_FV(A6,"P/E",TRUE)} -> 175.6961 | D6: 5.67 | E6: 52 | H6: Amgen | I6: =(B25*B20)/$N$6 -> 452.96129 | J6: =(C25*C20)/$N$6 -> 243.61409 | K6: =(D25*D20)/$N$6 -> 344.72645 | L6: =(E25*E20)/$N$6 -> 137.44869 | N6: ='Assumptions & WACC'!D25 -> 538.4807
A7: #VALUE! | B7: 13.93 | C7: {=_FV(A7,"P/E",TRUE)} -> 27.2297 | D7: 3.63 | E7: 7.96 | H7: LLY | I7: =(B26*B20)/$N$7 -> 421.37569 | J7: =(C26*C20)/$N$7 -> 328.40903 | K7: =(D26*D20)/$N$7 -> 264.60777 | L7: =(E26*E20)/$N$7 -> 190.1164 | N7: ='Assumptions & WACC'!E25 -> 945.3838
A8: #VALUE! | B8: 10.76 | C8: {=_FV(A8,"P/E",TRUE)} -> 17.4132 | D8: 4 | E8: 4.44 | H8: J&J | I8: =(B27*B20)/$N$8 -> 227.43223 | J8: =(C27*C20)/$N$8 -> 187.25347 | K8: =(D27*D20)/$N$8 -> 204.74439 | L8: =(E27*E20)/$N$8 -> 373.68906 | N8: ='Assumptions & WACC'!F25 -> 2409.295
A9: #VALUE! | B9: 15.49 | C9: 14.03 | D9: 4.01 | E9: 5
A10: #VALUE! | B10: 14.96 | C10: {=_FV(A10,"P/E",TRUE)} -> 14.5139 | D10: 2.53 | E10: 1.63
A11: #VALUE! | B11: 14.19 | C11: {=_FV(A11,"P/E",TRUE)} -> 26.4661 | D11: 4.33 | E11: 18.59
A12: #VALUE! | B12: 27.79 | C12: {=_FV(A12,"P/E",TRUE)} -> 40.78 | D12: 9.09 | E12: 6.55
A13: #VALUE! | B13: 12.16 | C13: {=_FV(A13,"P/E",TRUE)} -> 17.94 | D13: 3.86 | E13: 3.93 | H13: Company | I13: Target Price | J13: CMP | K13: U/D
A14: #VALUE! | B14: 14.85 | C14: {=_FV(A14,"P/E",TRUE)} -> 16.7977 | D14: 2.38 | E14: 1.6 | H14: Pfizer | I14: =AVERAGE(I4:L4) -> 96.97968 | J14: ='Company Profile'!B3 -> 24.9 | K14: =(Table23[[#This Row],[Target Price]]-J14)/J14 -> 2.8947663
A15: #VALUE! | B15: 10.11 | C15: {=_FV(A15,"P/E",TRUE)} -> 13.1054 | D15: 1.78 | E15: 3.92 | H15: Merck | I15: =AVERAGE(I5:L5) -> 208.74763 | J15: ='Company Profile'!C3 -> 95.05 | K15: =(Table23[[#This Row],[Target Price]]-J15)/J15 -> 1.1961875
A16: #VALUE! | B16: 34.03 | C16: {=_FV(A16,"P/E",TRUE)} -> 19.9049 | D16: 4.08 | E16: 6.23 | H16: Amgen | I16: =AVERAGE(I6:L6) -> 294.68763 | J16: =DCF!R21 -> 342.4 | K16: =(Table23[[#This Row],[Target Price]]-J16)/J16 -> -0.13934687
A17: #VALUE! | B17: 190.55 | C17: {=_FV(A17,"P/E",TRUE)} -> 29.5827 | D17: 9.81 | E17: 6.62 | H17: LLY | I17: =AVERAGE(I7:L7) -> 301.12722 | J17: =DCF!Z21 -> 1049.09 | K17: =(Table23[[#This Row],[Target Price]]-J17)/J17 -> -0.71296341
A18: #VALUE! | B18: 31.17 | C18: {=_FV(A18,"P/E",TRUE)} -> 15.4898 | D18: 2.42 | E18: 6.69 | H18: J&J | I18: =AVERAGE(I8:L8) -> 248.27979 | J18: =DCF!AH21 -> 202.66 | K18: =(Table23[[#This Row],[Target Price]]-J18)/J18 -> 0.22510503
A20: Average | B20: =AVERAGE(B3:B18) -> 31.415625 | C20: =AVERAGE(C3:C18) -> 32.073712 | D20: =AVERAGE(D3:D18) -> 5.55375 | E20: =AVERAGE(E3:E18) -> 12.59375
A22: Company | B22: EBITDA | C22: Net Income | D22: Revenue | E22: Book Value
A23: Pfizer | B23: =Financials!F7+Financials!F8 -> 18595 | C23: =Financials!F11 -> 4960 | D23: =Financials!F3 -> 63627 | E23: =Table2[[#This Row],[2024]] -> 88497
A24: Merck | B24: =Financials!M7+Financials!M8 -> 24435 | C24: =Financials!M11 -> 11363 | D24: =Financials!M3 -> 64168 | E24: =Financials!M23 -> 46372
A25: =H6 -> Amgen | B25: =Financials!T7+Financials!T8 -> 7764 | C25: =Financials!T11 -> 4090 | D25: =Financials!T3 -> 33424 | E25: =Financials!T23 -> 5877
A26: =H7 -> LLY | B26: =Financials!AB7+Financials!AB8 -> 12680.37 | C26: =Financials!AB11 -> 9679.97 | D26: =Financials!AB3 -> 45042.7 | E26: =Financials!AB23 -> 14271.6
A27: =H8 -> J&J | B27: =Financials!AJ7+Financials!AJ8 -> 17442 | C27: =Financials!AJ11 -> 14066 | D27: =Financials!AJ3 -> 88821 | E27: =Financials!AJ23 -> 71490

Sheet Calc
A1: Year | B1: Particulars | C1: Company | D1: Value | F1: Company | G1: Change in EBIT (historical) | H1: Change in CE | I1: Incremental ROCE (Historical) | J1: Change in EBIT (Forecast) | K1: Capex | L1: Depreciation | M1: Effective capital | N1: Raw ROCE | O1: Adjusted ROCE (Forecast) | Q1: Particulars | R1: 2020 | S1: 2021 | T1: 2022 | U1: 2023 | V1: 2024 | Y1: Company | Z1: WACC | AA1: Terminal growth | AB1: Cost of equity | AC1: Intrinsic value | AD1: Share price | AE1: Upside/Downside
A2: 2020-24 | B2: Avg Capex | C2: =Relative!A23 -> Pfizer | D2: =AVERAGE(Financials!B28:F28) -> 2997.8 | F2: =C2 -> Pfizer | G2: =Financials!F7-Financials!B7 -> 2376 | H2: =(213396-Financials!F20)-(154229-Financials!B20) -> 42092 | I2: =G2/H2 -> 0.056447781 | J2: =DCF!G4-DCF!B4 -> 9964.931 | K2: =D8 -> 3722.2161 | L2: =AVERAGE(DCF!B6:G6) -> 5156.321 | M2: =IF(K2-L2<=0,K2,MAX(K2-L2,0.1*K2)) -> 3722.2161 | N2: =J2/M2 -> 2.67715 | O2: =MIN(MAX(N2,0.12),0.28) -> 0.28 | Q2: Revenue | R2: {=Financials!B3:F3} -> 41908 | S2: 81288 | T2: 100330 | U2: 59553 | V2: 63627 | Y2: Pfizer | Z2: ='Assumptions & WACC'!B21 -> 0.05242693 | AA2: ='Assumptions & WACC'!$B$22 -> 0.0225 | AB2: ='Assumptions & WACC'!B12 -> 0.06099 | AC2: =DCF!B20 -> 108.41254 | AD2: =DCF!B21 -> 24.9 | AE2: =(AC2-AD2)/AD2 -> 3.3539171
A3: 2020-24 | B3: Avg Capex | C3: =Relative!A24 -> Merck | D3: =AVERAGE(Financials!I28:M28) -> 4100 | F3: =C3 -> Merck | G3: =Financials!M7-Financials!I7 -> 11145 | H3: =(117106-Financials!M20)-(109160-Financials!I20) -> 6853 | I3: =G3/H3 -> 1.6262951 | J3: =DCF!O4-DCF!J4 -> 4983.1426 | K3: =D9 -> 5780.0527 | L3: =AVERAGE(DCF!J6:O6) -> 5390.6745 | M3: =IF(K3-L3<=0,K3,MAX(K3-L3,0.1*K3)) -> 578.00527 | N3: =J3/M3 -> 8.6212753 | O3: =MIN(MAX(N3,0.12),0.28) -> 0.28 | Q3: Operating income | R3: {=Financials!B7:F7} -> 10933 | S3: 28011 | T3: 38336 | U3: 5790 | V3: 13309 | Y3: Merck | Z3: ='Assumptions & WACC'!C21 -> 0.050437705 | AA3: ='Assumptions & WACC'!$B$22 -> 0.0225 | AB3: ='Assumptions & WACC'!C12 -> 0.05475 | AC3: =DCF!J20 -> 175.48649 | AD3: =DCF!J21 -> 95.05 | AE3: =(AC3-AD3)/AD3 -> 0.84625445
A4: 2020-24 | B4: Avg Capex | C4: Amgen | D4: =AVERAGE(Financials!P28:T28) -> 926.4 | F4: =C4 -> Amgen | G4: =Financials!T7-Financials!P7 -> -1631 | H4: =(Financials!T16-Financials!T20)-(Financials!P16-Financials!P20) -> 17445 | I4: =G4/H4 -> -0.093493838 | J4: =Table931[[#This Row],[2030]]-Table931[[#This Row],[2025]] -> 3550.8481 | K4: =D10 -> 1351.4991 | L4: =AVERAGE(DCF!R6:W6) -> 5857.663 | M4: =IF(K4-L4<=0,K4,MAX(K4-L4,0.1*K4)) -> 1351.4991 | N4: =J4/M4 -> 2.6273404 | O4: =MIN(MAX(N4,0.12),0.28) -> 0.28 | Q4: Net income | R4: {=Financials!B11:F11} -> 5729 | S4: 21221 | T4: 29190 | U4: -919 | V4: 4960
A5: 2020-24 | B5: Avg Capex | C5: Eli Lilly | D5: =AVERAGE(Financials!X28:AB28) -> 2611.48 | F5: =C5 -> Eli Lilly | G5: =Financials!AB7-Financials!X7 -> 5450.47 | H5: =(Financials!AB16-Financials!AB20)-(Financials!X16-Financials!X20) -> 16186.8 | I5: =G5/H5 -> 0.33672313 | J5: =DCF!AE4-DCF!Z4 -> 10434.122 | K5: =D11 -> 5724.7377 | L5: =AVERAGE(DCF!Z6:AE6) -> 3370.6391 | M5: =IF(K5-L5<=0,K5,MAX(K5-L5,0.1*K5)) -> 2354.0986 | N5: =J5/M5 -> 4.4323215 | O5: =MIN(MAX(N5,0.12),0.28) -> 0.28 | Q5: Capex | R5: {=Financials!B28:F28} -> 2226 | S5: 2711 | T5: 3236 | U5: 3907 | V5: 2909
A6: 2020-24 | B6: Avg Capex | C6: J&J | D6: =AVERAGE(Financials!AF28:AJ28) -> 3995 | F6: =C6 -> J&J | G6: =Financials!AJ7-Financials!AF7 -> 744 | H6: =(Financials!AJ16-Financials!AJ20)-(Financials!AF16-Financials!AF20) -> -2618 | I6: =G6/H6 -> -0.2841864 | J6: =DCF!AM4-DCF!AH4 -> 1451.1292 | K6: =D12 -> 4194.0674 | L6: =AVERAGE(Table93135[[#This Row],[2025]:[2030]]) -> 7646.1157 | M6: =IF(K6-L6<=0,K6,MAX(K6-L6,0.1*K6)) -> 4194.0674 | N6: =J6/M6 -> 0.34599567 | O6: =MIN(MAX(N6,0.12),0.28) -> 0.28
A7: 2020-24 | B7: Avg Capex | C7: Average | D7: =AVERAGE(D2:D6) -> 2926.136 | H7: Average | I7: =AVERAGE(I2:I6) -> 0.32835715 | M7: Average | N7: =AVERAGE(N2:N6) -> 3.7408166 | O7: =AVERAGE(O2:O3) -> 0.28 | Q7: Particulars | R7: 2020 | S7: 2021 | T7: 2022 | U7: 2023 | V7: 2024
A8: 2025-30 | B8: Avg Capex | C8: =C2 -> Pfizer | D8: =AVERAGE(DCF!B7:G7) -> 3722.2161 | Q8: Revenue | R8: {=Financials!I3:M3} -> 47994 | S8: 48704 | T8: 59283 | U8: 60115 | V8: 64168
A9: 2025-30 | B9: Avg Capex | C9: =C3 -> Merck | D9: =AVERAGE(DCF!J7:O7) -> 5780.0527 | Q9: Operating income | R9: {=Financials!I7:M7} -> 8791 | S9: 13879 | T9: 16444 | U9: 1889 | V9: 19936
A10: 2025-30 | B10: Avg Capex | C10: =C4 -> Amgen | D10: =AVERAGE(DCF!R7:W7) -> 1351.4991 | F10: Metric | G10: 2020-24 | H10: 2025-30 | Q10: Net income | R10: {=Table18[[#This Row],[2020]:[2024]]} -> 1709 | S10: 1521 | T10: 1918 | U10: 1512 | V10: 2803
A11: 2025-30 | B11: Avg Capex | C11: =C5 -> Eli Lilly | D11: =AVERAGE(DCF!Z7:AE7) -> 5724.7377 | F11: GDP | G11: =AVERAGE(-0.035,0.058) -> 0.0115 | H11: 0.018 | Q11: Capex | R11: {=Financials!I28:M28} -> 4429 | S11: 4448 | T11: 4388 | U11: 3863 | V11: 3372
A12: 2025-30 | B12: Avg Capex | C12: =C6 -> J&J | D12: =AVERAGE(DCF!AH7:AM7) -> 4194.0674 | F12: GDP | G12: 0.028 | H12: 0.026
A13: 2025-30 | B13: Avg Capex | C13: =C7 -> Average | D13: =AVERAGE(D8:D12) -> 4154.5146 | F13: Change | G13: =G12-G11 -> 0.0165 | H13: =H12-H11 -> 0.008 | Q13: Particulars | R13: 2025 | S13: 2026 | T13: 2027 | U13: 2028 | V13: 2029 | W13: 2030
A14: 2025-30 | B14: Capex CAGR | C14: =C8 -> Pfizer | D14: =(DCF!G7/DCF!B7)^(1/6)-1 -> 0.072072325 | F14: Sensitivity | G14: =D61/G13 -> 40.863203 | H14: =D67/H13 -> 52.023424 | Q14: Revenue | R14: {=DCF!B3:G3} -> 69168.817 | S14: 75193.318 | T14: 81742.545 | U14: 88862.199 | V14: 96601.965 | W14: 105015.85
A15: 2025-30 | B15: Capex CAGR | C15: =C9 -> Merck | D15: =(DCF!O7/DCF!J7)^(1/6)-1 -> 0.049595418 | Q15: Operating income | R15: {=DCF!B4:G4} -> 19227.88 | S15: 20902.6 | T15: 22723.185 | U15: 24702.341 | V15: 26853.878 | W15: 29192.811
A16: 2025-30 | B16: Capex CAGR | C16: =C10 -> Amgen | D16: =(DCF!W7/DCF!R7)^(1/6)-1 -> 0.04665228 | Q16: Net income | R16: {=DCF!B5:G5} -> 14805.468 | S16: 16095.002 | T16: 17496.853 | U16: 19020.803 | V16: 20677.486 | W16: 22478.465
A17: 2025-30 | B17: Capex CAGR | C17: =C11 -> Eli Lilly | D17: =(DCF!AE7/DCF!Z7)^(1/6)-1 -> 0.10651906 | Q17: Capex | R17: {=DCF!B7:G7} -> 2990.3474 | S17: 3250.8023 | T17: 3533.9423 | U17: 3841.7434 | V17: 4176.3536 | W17: 4540.1078
A18: 2025-30 | B18: Capex CAGR | C18: =C12 -> J&J | D18: =(DCF!AM7/DCF!AH7)^(1/6)-1 -> 0.012208447 | Q18: FCFF | R18: {=DCF!B9:G9} -> 15701.186 | S18: 16683.84 | T18: 18136.978 | U18: 19716.681 | V18: 21433.975 | W18: 23300.843
A19: 2025-30 | B19: Capex CAGR | C19: =C13 -> Average | D19: =AVERAGE(D14:D18) -> 0.057409506
A20: =A14 -> 2025-30 | B20: Earnings CAGR | C20: =C14 -> Pfizer | D20: =D14 -> 0.072072325 | Q20: Particulars | R20: 2025 | S20: 2026 | T20: 2027 | U20: 2028 | V20: 2029 | W20: 2030
A21: =A15 -> 2025-30 | B21: Earnings CAGR | C21: =C15 -> Merck | D21: =D15 -> 0.049595418 | Q21: Revenue | R21: {=DCF!J3:O3} -> 68005.622 | S21: 72072.755 | T21: 76383.128 | U21: 80951.285 | V21: 85792.645 | W21: 90923.547
A22: =A16 -> 2025-30 | B22: Earnings CAGR | C22: =C16 -> Amgen | D22: =D16 -> 0.04665228 | Q22: Operating income | R22: {=DCF!J4:O4} -> 14786.753 | S22: 15671.087 | T22: 16608.31 | U22: 17601.584 | V22: 18654.262 | W22: 19769.896
A23: =A17 -> 2025-30 | B23: Earnings CAGR | C23: =C17 -> Eli Lilly | D23: =D17 -> 0.10651906 | Q23: Net income | R23: {=DCF!J5:O5} -> 11385.8 | S23: 12066.737 | T23: 12788.399 | U23: 13553.22 | V23: 14363.782 | W23: 15222.82
A24: =A18 -> 2025-30 | B24: Earnings CAGR | C24: =C18 -> J&J | D24: =D18 -> 0.012208447 | Q24: Capex | R24: {=DCF!J7:O7} -> 4974.293 | S24: 5271.7848 | T24: 5587.0683 | U24: 5921.2077 | V24: 6275.3305 | W24: 6650.632
A25: =A19 -> 2025-30 | B25: Earnings CAGR | C25: =C19 -> Average | D25: =AVERAGE(D20:D24) -> 0.057409506 | Q25: FCFF | R25: {=DCF!J9:O9} -> 12883.61 | S25: 11201.509 | T25: 11871.425 | U25: 12581.406 | V25: 13333.847 | W25: 14131.289
A26: =A20 -> 2025-30 | B26: Revenue CAGR | C26: =C20 -> Pfizer | D26: =D20 -> 0.072072325
A27: =A21 -> 2025-30 | B27: Revenue CAGR | C27: =C21 -> Merck | D27: =D21 -> 0.049595418
A28: =A22 -> 2025-30 | B28: Revenue CAGR | C28: =C22 -> Amgen | D28: =D22 -> 0.04665228
A29: =A23 -> 2025-30 | B29: Revenue CAGR | C29: =C23 -> Eli Lilly | D29: =D23 -> 0.10651906
A30: =A24 -> 2025-30 | B30: Revenue CAGR | C30: =C24 -> J&J | D30: =D24 -> 0.012208447
A31: =A25 -> 2025-30 | B31: Revenue CAGR | C31: =C25 -> Average | D31: =AVERAGE(D26:D30) -> 0.057409506
A32: =A2 -> 2020-24 | B32: EBITDA Margin | C32: =C26 -> Pfizer | D32: =(Financials!F7+Financials!F8)/Financials!F3 -> 0.29225015
A33: =A3 -> 2020-24 | B33: EBITDA Margin | C33: =C27 -> Merck | D33: =(Financials!M7+Financials!M8)/Financials!M3 -> 0.38079728
A34: =A4 -> 2020-24 | B34: EBITDA Margin | C34: =C28 -> Amgen | D34: =(Financials!T7+Financials!T31)/Financials!T3 -> 0.39953327
A35: =A5 -> 2020-24 | B35: EBITDA Margin | C35: =C29 -> Eli Lilly | D35: =(Financials!AB7+Financials!AB31)/Financials!AB3 -> 0.32074831
A36: =A6 -> 2020-24 | B36: EBITDA Margin | C36: =C30 -> J&J | D36: =(Financials!AJ7+Financials!AJ31)/Financials!AJ3 -> 0.27899934
A37: =$A$36 -> 2020-24 | B37: EBITDA Margin | C37: =C31 -> Average | D37: =AVERAGE(D32:D36) -> 0.33446567
A38: =$A$36 -> 2020-24 | B38: NPM | C38: =C32 -> Pfizer | D38: =Financials!F11/Financials!F3 -> 0.077954328
A39: =$A$36 -> 2020-24 | B39: NPM | C39: =C33 -> Merck | D39: =Financials!M11/Financials!M3 -> 0.17708203
A40: =A32 -> 2020-24 | B40: NPM | C40: =C34 -> Amgen | D40: =Financials!T11/Financials!T3 -> 0.12236716
...
