Workbook

Sheet Company profile
A1: Company | B1: #VALUE! | C1: #VALUE! | D1: #VALUE! | E1: #VALUE! | F1: #VALUE!
A2: Official name | B2: {=_FV(B1,"Official name",TRUE)} -> THE PROCTER & GAMBLE COMPANY | C2: {=_FV(C1,"Official name",TRUE)} -> PEPSICO, INC. | D2: {=_FV(D1,"Official name",TRUE)} -> THE COCA-COLA COMPANY | E2: {=_FV(E1,"Official name",TRUE)} -> COLGATE-PALMOLIVE COMPANY | F2: {=_FV(F1,"Official name",TRUE)} -> WALMART INC.
A3: Share price | B3: {=_FV(B1,"Price")} -> 147.35 | C3: {=_FV(C1,"Price")} -> 147.815 | D3: {=_FV(D1,"Price")} -> 71.4 | E3: {=_FV(E1,"Price")} -> 78.89 | F3: {=_FV(F1,"Price")} -> 100.515
A4: Change (%) | B4: {=_FV(B1,"Change (%)",TRUE)} -> 0.002449 | C4: {=_FV(C1,"Change (%)",TRUE)} -> -0.006419 | D4: {=_FV(D1,"Change (%)",TRUE)} -> 0.002527 | E4: {=_FV(E1,"Change (%)",TRUE)} -> -0.005546 | F4: {=_FV(F1,"Change (%)",TRUE)} -> -0.00863
A5: Shares outstanding | B5: {=_FV(B1,"Shares outstanding",TRUE)} -> 2336734000 | C5: {=_FV(C1,"Shares outstanding",TRUE)} -> 1367340000 | D5: {=_FV(D1,"Shares outstanding",TRUE)} -> 4301609000 | E5: {=_FV(E1,"Shares outstanding",TRUE)} -> 806064900 | F5: {=_FV(F1,"Shares outstanding",TRUE)} -> 7972851000
A6: in mn | B6: =B5/1000000 -> 2336.734 | C6: =C5/1000000 -> 1367.34 | D6: =D5/1000000 -> 4301.609 | E6: =E5/1000000 -> 806.0649 | F6: =F5/1000000 -> 7972.851
A7: Market cap | B7: {=_FV(B1,"Market cap",TRUE)} -> 344317754900 | C7: {=_FV(C1,"Market cap",TRUE)} -> 202113362100 | D7: {=_FV(D1,"Market cap",TRUE)} -> 307134882600 | E7: {=_FV(E1,"Market cap",TRUE)} -> 63590459961 | F7: {=_FV(F1,"Market cap",TRUE)} -> 801391118265
A8: in mn | B8: =B7/1000000 -> 344317.75 | C8: =C7/1000000 -> 202113.36 | D8: =D7/1000000 -> 307134.88 | E8: =E7/1000000 -> 63590.46 | F8: =F7/1000000 -> 801391.12
A9: Beta | B9: {=_FV(B1,"Beta")} -> 0.3851 | C9: {=_FV(C1,"Beta")} -> 0.413 | D9: {=_FV(D1,"Beta")} -> 0.3853 | E9: {=_FV(E1,"Beta")} -> 0.2863 | F9: {=_FV(F1,"Beta")} -> 0.6451
A10: P/E | B10: {=_FV(B1,"P/E",TRUE)} -> 21.51 | C10: {=_FV(C1,"P/E",TRUE)} -> 28.1071 | D10: {=_FV(D1,"P/E",TRUE)} -> 23.6361 | E10: {=_FV(E1,"P/E",TRUE)} -> 22.1079 | F10: {=_FV(F1,"P/E",TRUE)} -> 37.9216
A11: Year | B11: {=_FV(B1,"Year incorporated",TRUE)} -> 1905 | C11: {=_FV(C1,"Year incorporated",TRUE)} -> 1986 | D11: {=_FV(D1,"Year incorporated",TRUE)} -> 1919 | E11: {=_FV(E1,"Year incorporated",TRUE)} -> 1923 | F11: {=_FV(F1,"Year incorporated",TRUE)} -> 1969

Sheet Financials
A1: INCOME STATEMENT | F1: P&G | H1: INCOME STATEMENT | M1: PepsiCo | O1: INCOME STATEMENT | T1: Coca-Cola | W1: INCOME STATEMENT | AB1: Colgate | AE1: INCOME STATEMENT | AJ1: Walmart
A2: Particulars | B2: 2020 | C2: 2021 | D2: 2022 | E2: 2023 | F2: 2024 | H2: Particulars | I2: 2020 | J2: 2021 | K2: 2022 | L2: 2023 | M2: 2024 | O2: Particulars | P2: 2020 | Q2: 2021 | R2: 2022 | S2: 2023 | T2: 2024 | W2: Particulars | X2: 2020 | Y2: 2021 | Z2: 2022 | AA2: 2023 | AB2: 2024 | AE2: Particulars | AF2: 2020 | AG2: 2021 | AH2: 2022 | AI2: 2023 | AJ2: 2024
A3: Revenue | B3: 70950 | C3: 76118 | D3: 80187 | E3: 82006 | F3: 84039 | H3: Revenue | I3: 70372 | J3: 79474 | K3: 86392 | L3: 91471 | M3: 91854 | O3: Revenue | P3: 33014 | Q3: 38655 | R3: 43004 | S3: 45754 | T3: 47061 | W3: Revenue | X3: 16471 | Y3: 17421 | Z3: 17967 | AA3: 19457 | AB3: 20101 | AE3: Revenue | AF3: 559151 | AG3: 572754 | AH3: 611289 | AI3: 648125 | AJ3: 680985
A4: Cost of sales | B4: 35250 | C4: 37108 | D4: 42157 | E4: 42760 | F4: 40848 | H4: Cost of sales | I4: 31797 | J4: 37075 | K4: 40576 | L4: 41881 | M4: 41744 | O4: Cost of sales | P4: 13433 | Q4: 15357 | R4: 18000 | S4: 18520 | T4: 18324 | W4: Cost of sales | X4: 6454 | Y4: 7046 | Z4: 7719 | AA4: 8131 | AB4: 7940 | AE4: Cost of sales | AF4: 420315 | AG4: 429000 | AH4: 463721 | AI4: 490142 | AJ4: 511753
A5: Opex | B5: =19994+0 -> 19994 | C5: 21024 | D5: 20217 | E5: 21112 | F5: =23305+1341 -> 24646 | H5: Opex | I5: 28495 | J5: 31237 | K5: =34459-3321+3166 -> 34304 | L5: =36677+927 -> 37604 | M5: =37190+33 -> 37223 | O5: Opex | P5: =9731+853-370-978-841 -> 8395 | Q5: =12144+846-276-1438-2000 -> 9276 | R5: =12880+1215-449-1472+262 -> 12436 | S5: =13972+1951-907-1691-570 -> 12755 | T5: =14582+4163-988-1770-1992 -> 13995 | W5: Opex | X5: =6019+113+74 -> 6206 | Y5: =6407+65+571+70 -> 7113 | Z5: =6565+69+721+80 -> 7435 | AA5: =7151+191+360+55 -> 7757 | AB5: =7729+164+87+67 -> 8047 | AE5: Opex | AF5: 116078 | AG5: =117812+3000+2410 -> 123222 | AH5: =127140+1538 -> 128678 | AI5: =130971+3027 -> 133998 | AJ5: =139884+794 -> 140678
A6: Operating income (EBIT) | B6: =B3-B4-B5 -> 15706 | C6: =C3-C4-C5 -> 17986 | D6: =D3-D4-D5 -> 17813 | E6: =E3-E4-E5 -> 18134 | F6: =F3-F4-F5 -> 18545 | H6: Operating income (EBIT) | I6: =I3-I4-I5 -> 10080 | J6: =J3-J4-J5 -> 11162 | K6: =K3-K4-K5 -> 11512 | L6: =L3-L4-L5 -> 11986 | M6: =M3-M4-M5 -> 12887 | O6: Operating income (EBIT) | P6: =P3-P4-P5 -> 11186 | Q6: =Q3-Q4-Q5 -> 14022 | R6: =R3-R4-R5 -> 12568 | S6: =S3-S4-S5 -> 14479 | T6: =T3-T4-T5 -> 14742 | W6: Operating income (EBIT) | X6: =X3-X4-X5 -> 3811 | Y6: =Y3-Y4-Y5 -> 3262 | Z6: =Z3-Z4-Z5 -> 2813 | AA6: =AA3-AA4-AA5 -> 3569 | AB6: =AB3-AB4-AB5 -> 4114 | AE6: Operating income (EBIT) | AF6: =AF3-AF4-AF5 -> 22758 | AG6: =AG3-AG4-AG5 -> 20532 | AH6: =AH3-AH4-AH5 -> 18890 | AI6: =AI3-AI4-AI5 -> 23985 | AJ6: =AJ3-AJ4-AJ5 -> 28554
A7: Depreciation & Amortization | B7: 3013 | C7: 2735 | D7: 2807 | E7: 2714 | F7: 2896 | H7: Depreciation & Amortization | I7: 2548 | J7: 2710 | K7: 2763 | L7: 2948 | M7: 3160 | O7: Depreciation & Amortization | P7: 1536 | Q7: 1452 | R7: 1260 | S7: 1128 | T7: 1075 | W7: Depreciation & Amortization | X7: 539 | Y7: 556 | Z7: 545 | AA7: 567 | AB7: 605 | AE7: Depreciation & Amortization | AF7: 11152 | AG7: 10658 | AH7: 10945 | AI7: 11853 | AJ7: 12973
A8: Interest expense | B8: 465 | C8: 502 | D8: 439 | E8: 756 | F8: 925 | H8: Interest expense | I8: 1128 | J8: 1863 | K8: 939 | L8: 819 | M8: 919 | O8: Interest expense | P8: 1437 | Q8: 1597 | R8: 882 | S8: 1527 | T8: 1656 | W8: Interest expense | X8: 164 | Y8: 175 | Z8: 153 | AA8: 287 | AB8: 292 | AE8: Interest expense | AF8: 2194 | AG8: 1836 | AH8: 1874 | AI8: 2137 | AJ8: 2245
A9: Income tax | B9: 2731 | C9: 3263 | D9: 3202 | E9: 3615 | F9: 3787 | H9: Income tax | I9: 1894 | J9: 2142 | K9: 1727 | L9: 2262 | M9: 2320 | O9: Income tax | P9: 1981 | Q9: 2621 | R9: 2115 | S9: 2249 | T9: 2437 | W9: Income tax | X9: 787 | Y9: 749 | Z9: 693 | AA9: 937 | AB9: 907 | AE9: Income tax | AF9: 6858 | AG9: 4756 | AH9: 5724 | AI9: 5578 | AJ9: 6152
A10: Net income | B10: =B6-B7-B8-B9 -> 9497 | C10: =C6-C7-C8-C9 -> 11486 | D10: =D6-D7-D8-D9 -> 11365 | E10: =E6-E7-E8-E9 -> 11049 | F10: =F6-F7-F8-F9 -> 10937 | H10: Net income | I10: =I6-I7-I8-I9 -> 4510 | J10: =J6-J7-J8-J9 -> 4447 | K10: =K6-K7-K8-K9 -> 6083 | L10: =L6-L7-L8-L9 -> 5957 | M10: =M6-M7-M8-M9 -> 6488 | O10: Net income | P10: =P6-P7-P8-P9 -> 6232 | Q10: =Q6-Q7-Q8-Q9 -> 8352 | R10: =R6-R7-R8-R9 -> 8311 | S10: =S6-S7-S8-S9 -> 9575 | T10: =T6-T7-T8-T9 -> 9574 | W10: Net income | X10: =X6-X7-X8-X9 -> 2321 | Y10: =Y6-Y7-Y8-Y9 -> 1782 | Z10: =Z6-Z7-Z8-Z9 -> 1422 | AA10: =AA6-AA7-AA8-AA9 -> 1778 | AB10: =AB6-AB7-AB8-AB9 -> 2310 | AE10: Net income | AF10: =AF6-AF7-AF8-AF9 -> 2554 | AG10: =AG6-AG7-AG8-AG9 -> 3282 | AH10: =AH6-AH7-AH8-AH9 -> 347 | AI10: =AI6-AI7-AI8-AI9 -> 4417 | AJ10: =AJ6-AJ7-AJ8-AJ9 -> 7184
A12: BALANCE SHEET | H12: BALANCE SHEET | O12: BALANCE SHEET | W12: BALANCE SHEET | AE12: BALANCE SHEET
A13: Particulars | B13: 2020 | C13: 2021 | D13: 2022 | E13: 2023 | F13: 2024 | H13: Particulars | I13: 2020 | J13: 2021 | K13: 2022 | L13: 2023 | M13: 2024 | O13: Particulars | P13: 2020 | Q13: 2021 | R13: 2022 | S13: 2023 | T13: 2024 | W13: Particulars | X13: 2020 | Y13: 2021 | Z13: 2022 | AA13: 2023 | AB13: 2024 | AE13: Particulars | AF13: 2020 | AG13: 2021 | AH13: 2022 | AI13: 2023 | AJ13: 2024
A14: Cash & Cash equivalents | B14: 16181 | C14: 10288 | D14: 7214 | E14: 8246 | F14: 9482 | H14: Cash & Cash equivalents | I14: 8185 | J14: 5596 | K14: 4954 | L14: 9711 | M14: 8505 | O14: Cash & Cash equivalents | P14: 6795 | Q14: 9684 | R14: 9519 | S14: 9366 | T14: 10828 | W14: Cash & Cash equivalents | X14: 888 | Y14: 832 | Z14: 775 | AA14: 966 | AB14: 1096 | AE14: Cash & Cash equivalents | AF14: 17741 | AG14: 14760 | AH14: 8625 | AI14: 9867 | AJ14: 9037
A15: Accounts receivables | B15: 4178 | C15: 4725 | D15: 5143 | E15: 5471 | F15: 6118 | H15: Accounts receivables | I15: 8404 | J15: 8680 | K15: 10163 | L15: 10815 | M15: 10333 | O15: Total assets | P15: 87296 | Q15: 94354 | R15: 92763 | S15: 97703 | T15: 100549 | W15: Total assets | X15: =15920 -> 15920 | Y15: 15040 | Z15: 15731 | AA15: 16393 | AB15: 16046 | AE15: Total assets | AF15: 252496 | AG15: 244860 | AH15: 243197 | AI15: 252399 | AJ15: 260823
A16: Inventories | B16: 5498 | C16: 5983 | D16: 6924 | E16: 7073 | F16: 7016 | H16: Inventories | I16: 4172 | J16: 4347 | K16: 5222 | L16: 5334 | M16: 5306 | O16: Inventories | P16: 3266 | Q16: 3414 | R16: 4233 | S16: 4424 | T16: 4728 | W16: Inventories | X16: 1673 | Y16: 1692 | Z16: 2074 | AA16: 1934 | AB16: 1987 | AE16: Inventories | AF16: 44949 | AG16: 56511 | AH16: 56576 | AI16: 54892 | AJ16: 56435
A17: Total current assets | B17: 27987 | C17: 23091 | D17: 21653 | E17: 22648 | F17: 24709 | H17: Total current assets | I17: 23001 | J17: 21783 | K17: 21539 | L17: 26950 | M17: 25826 | O17: Total current assets | P17: 19240 | Q17: 22545 | R17: 22591 | S17: 26732 | T17: 25997 | W17: Total current assets | X17: 4338 | Y17: 4397 | Z17: 5113 | AA17: 5279 | AB17: 5317 | AE17: Total current assets | AF17: 90067 | AG17: 81070 | AH17: 75655 | AI17: 76877 | AJ17: 79458
A18: PPE | B18: 20692 | C18: 21686 | D18: 21195 | E18: 21909 | F18: 22152 | H18: PPE | I18: 21369 | J18: 22407 | K18: 24291 | L18: 27039 | M18: 28008 | O18: PPE | P18: 10777 | Q18: 9920 | R18: 9841 | S18: 9236 | T18: 10303 | W18: PPE | X18: 3716 | Y18: 3730 | Z18: 4307 | AA18: 4582 | AB18: 4422 | AE18: PPE | AF18: 92201 | AG18: 84515 | AH18: 100760 | AI18: 110810 | AJ18: 119993
A19: Accounts payables | B19: 12071 | C19: 13720 | D19: 14882 | E19: 14598 | F19: 15364 | H19: Accounts payables | I19: 19592 | J19: 21159 | K19: 23371 | L19: 25137 | M19: 24454 | O19: Accounts payables | P19: 11145 | Q19: 14619 | R19: 15749 | S19: 15485 | T19: 21715 | W19: Accounts payables | X19: 1393 | Y19: 1479 | Z19: 1551 | AA19: 1698 | AB19: 1805 | AE19: Accounts payables | AF19: 49141 | AG19: 55261 | AH19: 53742 | AI19: 56812 | AJ19: 58666
A20: Total current liabilities | B20: 32976 | C20: 33132 | D20: 33081 | E20: 35756 | F20: 33627 | H20: Total current liabilities | I20: 23372 | J20: 26220 | K20: 26785 | L20: 31647 | M20: 31536 | O20: Total current liabilities | P20: 14601 | Q20: 19950 | R20: 19724 | S20: 23571 | T20: 25249 | W20: Total current liabilities | X20: 4404 | Y20: 4051 | Z20: 4004 | AA20: 4741 | AB20: 5759 | AE20: Total current liabilities | AF20: 92645 | AG20: 87379 | AH20: 92198 | AI20: 92415 | AJ20: 96584
A21: Total debt | B21: =11183+22537 -> 33720 | C21: =8889+23099 -> 31988 | D21: =8645+22848 -> 31493 | E21: =10229+24378 -> 34607 | F21: =7191+25269 -> 32460 | H21: Total debt | I21: =3780+40370 -> 44150 | J21: =4308+36026 -> 40334 | K21: =3414+35657 -> 39071 | L21: =6510+37595 -> 44105 | M21: =7082+37224 -> 44306 | O21: Total debt | P21: =2183+485+40125 -> 42793 | Q21: =3307+1338+38116 -> 42761 | R21: =2373+399+36377 -> 39149 | S21: =4557+1960+35547 -> 42064 | T21: =1499+648+42375 -> 44522 | W21: Total debt | X21: =258+9+7334 -> 7601 | Y21: =39+12+7194 -> 7245 | Z21: =11+14+8741 -> 8766 | AA21: =330+8219 -> 8549 | AB21: =660+7289 -> 7949 | AE21: Total debt | AF21: =3115+491+41194+12909+3847+1466+224 -> 63246 | AG21: =2803+1483+511+34864+13009+4243+410 -> 57323 | AH21: =4191+1473+567+34649+12828+4843+372 -> 58923 | AI21: =878+3447+1487+725+36132+12943+5709 -> 61321 | AJ21: =3068+2598+1499+800+33401+12825+5923 -> 60114
A22: Shareholder's equity | B22: 46878 | C22: 46654 | D22: 46854 | E22: 47065 | F22: 50559 | H22: Shareholder's equity | I22: 13552 | J22: 16151 | K22: 17273 | L22: 18637 | M22: 18171 | O22: Shareholder's equity | P22: 21284 | Q22: 24860 | R22: 25826 | S22: 27480 | T22: 26372 | W22: Shareholder's equity | X22: 1101 | Y22: 971 | Z22: 806 | AA22: 957 | AB22: 544 | AE22: Shareholder's equity | AF22: 87531 | AG22: 91891 | AH22: 83754 | AI22: 90349 | AJ22: 97421
A24: CASH FLOW STATEMENT | H24: CASH FLOW STATEMENT | O24: CASH FLOW STATEMENT | W24: CASH FLOW STATEMENT | AE24: CASH FLOW STATEMENT
A25: Particulars | B25: 2020 | C25: 2021 | D25: 2022 | E25: 2023 | F25: 2024 | H25: Particulars | I25: 2020 | J25: 2021 | K25: 2022 | L25: 2023 | M25: 2024 | O25: Particulars | P25: 2020 | Q25: 2021 | R25: 2022 | S25: 2023 | T25: 2024 | W25: Particulars | X25: 2020 | Y25: 2021 | Z25: 2022 | AA25: 2023 | AB25: 2024 | AE25: Particulars | AF25: 2020 | AG25: 2021 | AH25: 2022 | AI25: 2023 | AJ25: 2024
A26: Cash flow from operating activities | B26: 17403 | C26: 17403 | D26: 18371 | E26: 16848 | F26: 19846 | H26: Cash flow from operating activities | I26: 10613 | J26: 11616 | K26: 10811 | L26: 13442 | M26: 12507 | O26: Cash flow from operating activities | P26: 9844 | Q26: 12625 | R26: 11018 | S26: 11599 | T26: 6805 | W26: Cash flow from operating activities | X26: =3719 -> 3719 | Y26: 3325 | Z26: 2556 | AA26: 3745 | AB26: 4107 | AE26: Cash flow from operating activities | AF26: 36074 | AG26: 24181 | AH26: 28841 | AI26: 35726 | AJ26: 36443
A27: Capex | B27: 3073 | C27: 2787 | D27: 3156 | E27: 3062 | F27: 3322 | H27: Capex | I27: 4240 | J27: 4625 | K27: 5207 | L27: 5518 | M27: 5318 | O27: Capex | P27: 1177 | Q27: 1367 | R27: 1484 | S27: 1852 | T27: 2064 | W27: Capex | X27: 410 | Y27: 567 | Z27: 696 | AA27: 705 | AB27: 561 | AE27: Capex | AF27: 10264 | AG27: 13106 | AH27: 16857 | AI27: 20606 | AJ27: 23783
A28: Dividends paid | B28: 7789 | C28: 8263 | D28: 8770 | E28: 8999 | F28: 9312 | H28: Dividends paid | I28: 5509 | J28: 5815 | K28: 6172 | L28: 6682 | M28: 7229 | O28: Dividends paid | P28: 7047 | Q28: 7252 | R28: 7616 | S28: 7952 | T28: 8359 | W28: Dividends paid | X28: 1654 | Y28: 1679 | Z28: 1691 | AA28: 1749 | AB28: 1789 | AE28: Dividends paid | AF28: 6116 | AG28: 6152 | AH28: 6114 | AI28: 6140 | AJ28: 6688
A29: Debt repaid | B29: 2447 | C29: 4987 | D29: 2343 | E29: 1878 | F29: 2335 | H29: Debt repaid | I29: =1830+3554 -> 5384 | J29: =3455+397 -> 3852 | K29: =2458+1951 -> 4409 | L29: =3005+3106 -> 6111 | M29: =3886+5639 -> 9525 | O29: Debt repaid | P29: 28796 | Q29: 12866 | R29: 4930 | S29: 5034 | T29: 9533 | W29: Debt repaid | X29: 1061 | Y29: =171+703 -> 874 | Z29: =406 -> 406 | AA29: =906+903 -> 1809 | AB29: 503 | AE29: Debt repaid | AF29: 5382 | AG29: 13010 | AH29: 2689 | AI29: 4217 | AJ29: 3468
O32: Particulars | P32: 2020 | Q32: 2021 | R32: 2022 | S32: 2023 | T32: 2024 | W32: Particulars | X32: 2020 | Y32: 2021 | Z32: 2022 | AA32: 2023 | AB32: 2024 | AE32: Particulars | AF32: 2020 | AG32: 2021 | AH32: 2022 | AI32: 2023 | AJ32: 2024
O33: Revenue | P33: =P3 -> 33014 | Q33: =Q3 -> 38655 | R33: =R3 -> 43004 | S33: =S3 -> 45754 | T33: =T3 -> 47061 | W33: Revenue | X33: =X3 -> 16471 | Y33: =Y3 -> 17421 | Z33: =Z3 -> 17967 | AA33: =AA3 -> 19457 | AB33: =AB3 -> 20101 | AE33: Revenue | AF33: =AF3 -> 559151 | AG33: =AG3 -> 572754 | AH33: =AH3 -> 611289 | AI33: =AI3 -> 648125 | AJ33: =AJ3 -> 680985
O34: Operating income | P34: =P6 -> 11186 | Q34: =Q6 -> 14022 | R34: =R6 -> 12568 | S34: =S6 -> 14479 | T34: =T6 -> 14742 | W34: Operating income | X34: =X6 -> 3811 | Y34: =Y6 -> 3262 | Z34: =Z6 -> 2813 | AA34: =AA6 -> 3569 | AB34: =AB6 -> 4114 | AE34: Operating income | AF34: =AF6 -> 22758 | AG34: =AG6 -> 20532 | AH34: =AH6 -> 18890 | AI34: =AI6 -> 23985 | AJ34: =AJ6 -> 28554
O35: Net income | P35: =P10 -> 6232 | Q35: =Q10 -> 8352 | R35: =R10 -> 8311 | S35: =S10 -> 9575 | T35: =T10 -> 9574 | W35: Net income | X35: =X10 -> 2321 | Y35: =Y10 -> 1782 | Z35: =Z10 -> 1422 | AA35: =AA10 -> 1778 | AB35: =AB10 -> 2310 | AE35: Net income | AF35: =AF10 -> 2554 | AG35: =AG10 -> 3282 | AH35: =AH10 -> 347 | AI35: =AI10 -> 4417 | AJ35: =AJ10 -> 7184
O37: Particulars | P37: 2025 | Q37: 2026 | R37: 2027 | S37: 2028 | T37: 2029 | U37: 2030 | W37: Particulars | X37: 2025 | Y37: 2026 | Z37: 2027 | AA37: 2028 | AB37: 2029 | AC37: 2030 | AE37: Particulars | AF37: 2025 | AG37: 2026 | AH37: 2027 | AI37: 2028 | AJ37: 2029 | AK37: 2030
O38: Revenue | P38: =DCF!R3 -> 50518.884 | Q38: =DCF!S3 -> 54230.843 | R38: =DCF!T3 -> 58215.543 | S38: =DCF!U3 -> 62493.026 | T38: =DCF!V3 -> 67084.804 | U38: =DCF!W3 -> 72013.97 | W38: Revenue | X38: =DCF!Z3 -> 20917.858 | Y38: =DCF!AA3 -> 21767.91 | Z38: =DCF!AB3 -> 22652.507 | AA38: =DCF!AC3 -> 23573.052 | AB38: =DCF!AD3 -> 24531.006 | AC38: =DCF!AE3 -> 25527.889 | AE38: Revenue | AF38: =DCF!AH3 -> 708368.49 | AG38: =DCF!AI3 -> 736853.11 | AH38: =DCF!AJ3 -> 766483.15 | AI38: =DCF!AK3 -> 797304.65 | AJ38: =DCF!AL3 -> 829365.54 | AK38: =DCF!AM3 -> 862715.64
O39: Operating income | P39: =DCF!R4 -> 16312.335 | Q39: =DCF!S4 -> 17510.91 | R39: =DCF!T4 -> 18797.553 | S39: =DCF!U4 -> 20178.735 | T39: =DCF!V4 -> 21661.4 | U39: =DCF!W4 -> 23253.007 | W39: Operating income | X39: =DCF!Z4 -> 4020.1039 | Y39: =DCF!AA4 -> 4183.4715 | Z39: =DCF!AB4 -> 4353.4781 | AA39: =DCF!AC4 -> 4530.3932 | AB39: =DCF!AD4 -> 4714.4978 | AC39: =DCF!AE4 -> 4906.084 | AE39: Operating income | AF39: =DCF!AH4 -> 26450.288 | AG39: =DCF!AI4 -> 27513.896 | AH39: =DCF!AJ4 -> 28620.273 | AI39: =DCF!AK4 -> 29771.14 | AJ39: =DCF!AL4 -> 30968.285 | AK39: =DCF!AM4 -> 32213.569
O40: Net income | P40: =DCF!R5 -> 12560.498 | Q40: =DCF!S5 -> 13483.401 | R40: =DCF!T5 -> 14474.116 | S40: =DCF!U5 -> 15537.626 | T40: =DCF!V5 -> 16679.278 | U40: =DCF!W5 -> 17904.816 | W40: Net income | X40: =DCF!Z5 -> 3095.48 | Y40: =DCF!AA5 -> 3221.2731 | Z40: =DCF!AB5 -> 3352.1781 | AA40: =DCF!AC5 -> 3488.4028 | AB40: =DCF!AD5 -> 3630.1633 | AC40: =DCF!AE5 -> 3777.6847 | AE40: Net income | AF40: =DCF!AH5 -> 20366.722 | AG40: =DCF!AI5 -> 21185.7 | AH40: =DCF!AJ5 -> 22037.61 | AI40: =DCF!AK5 -> 22923.778 | AJ40: =DCF!AL5 -> 23845.579 | AK40: =DCF!AM5 -> 24804.448

Sheet Assumptions & WACC
A1: Assumptions
A2: Metric | B2: P&G | C2: PepsiCo | D2: Coca-Cola | E2: Colgate | F2: Walmart | H2: Current | I2: 2020 | J2: 2021 | K2: 2022 | L2: 2023 | M2: 2024
A3: Revenue CAGR | B3: =(Table1[[#This Row],[2024]]/Table1[[#This Row],[2020]])^(1/5)-1 -> 0.034440928 | C3: =(Table18[[#This Row],[2024]]/Table18[[#This Row],[2020]])^(1/5)-1 -> 0.054725961 | D3: =(Table15[[#This Row],[2024]]/Table15[[#This Row],[2020]])^(1/5)-1 -> 0.073476647 | E3: =(Table1811[[#This Row],[2024]]/Table1811[[#This Row],[2020]])^(1/5)-1 -> 0.040637661 | F3: =(Table181114[[#This Row],[2024]]/Table181114[[#This Row],[2020]])^(1/5)-1 -> 0.040211589 | H3: WC-P&G | I3: =Financials!B17-Financials!B20 -> -4989 | J3: =Financials!C17-Financials!C20 -> -10041 | K3: =Financials!D17-Financials!D20 -> -11428 | L3: =Financials!E17-Financials!E20 -> -13108 | M3: =Financials!F17-Financials!F20 -> -8918
A4: Operating margin (EBIT) | B4: =AVERAGE(Financials!B6:F6)/AVERAGE(Financials!B3:F3) -> 0.22421561 | C4: =AVERAGE(Financials!I6:M6)/AVERAGE(Financials!I3:M3) -> 0.13735005 | D4: =AVERAGE(Financials!P6:T6)/AVERAGE(Financials!P3:T3) -> 0.32289578 | E4: =AVERAGE(Financials!X6:AB6)/AVERAGE(Financials!X3:AB3) -> 0.19218526 | F4: =AVERAGE(Financials!AF6:AJ6)/AVERAGE(Financials!AF3:AJ3) -> 0.037339729 | H4: WC-PepsiCo | I4: =Financials!I17-Financials!I20 -> -371 | J4: =Financials!J17-Financials!J20 -> -4437 | K4: =Financials!K17-Financials!K20 -> -5246 | L4: =Financials!L17-Financials!L20 -> -4697 | M4: =Financials!M17-Financials!M20 -> -5710
A5: Depreciation rate | B5: =AVERAGE(Financials!B7:F7)/AVERAGE(Financials!B3:F3) -> 0.036015764 | C5: =AVERAGE(Financials!I7:M7)/AVERAGE(Financials!I3:M3) -> 0.033675515 | D5: =AVERAGE(Financials!P7:T7)/AVERAGE(Financials!P3:T3) -> 0.031090955 | E5: =AVERAGE(Financials!X7:AB7)/AVERAGE(Financials!X3:AB3) -> 0.030760143 | F5: =AVERAGE(Financials!AF7:AJ7)/AVERAGE(Financials!AF3:AJ3) -> 0.01874196 | H5: WC-CocaCola | I5: =Financials!P17-Financials!P20 -> 4639 | J5: =Financials!Q17-Financials!Q20 -> 2595 | K5: =Financials!R17-Financials!R20 -> 2867 | L5: =Financials!S17-Financials!S20 -> 3161 | M5: =Financials!T17-Financials!T20 -> 748
A6: CapEx | B6: =AVERAGE(Financials!B27:F27)/AVERAGE(Financials!B3:F3) -> 0.039155861 | C6: =AVERAGE(Financials!I27:M27)/AVERAGE(Financials!I3:M3) -> 0.059366531 | D6: =AVERAGE(Financials!P27:T27)/AVERAGE(Financials!P3:T3) -> 0.038286552 | E6: =AVERAGE(Financials!X27:AB27)/AVERAGE(Financials!X3:AB3) -> 0.032149381 | F6: =AVERAGE(Financials!AF27:AJ27)/AVERAGE(Financials!AF3:AJ3) -> 0.027541545 | H6: WC-Colgate | I6: =Financials!X17-Financials!X20 -> -66 | J6: =Financials!Y17-Financials!Y20 -> 346 | K6: =Financials!Z17-Financials!Z20 -> 1109 | L6: =Financials!AA17-Financials!AA20 -> 538 | M6: =Financials!AB17-Financials!AB20 -> -442
A7: Working capital | B7: =AVERAGE(I3:M3)/AVERAGE(Financials!B3:F3) -> -0.12327485 | C7: =AVERAGE(I4:M4)/AVERAGE(Financials!I3:M3) -> -0.048767408 | D7: =AVERAGE(I5:M5)/AVERAGE(Financials!P3:T3) -> 0.067521977 | E7: =AVERAGE(I6:M6)/AVERAGE(Financials!X3:AB3) -> 0.016244243 | F7: =AVERAGE(Table19[[#This Row],[2020]:[2024]])/AVERAGE(Financials!AF3:AJ3) -> -0.018908936 | H7: WC-Walmart | I7: =Financials!AF17-Financials!AF20 -> -2578 | J7: =Financials!AG17-Financials!AG20 -> -6309 | K7: =Financials!AH17-Financials!AH20 -> -16543 | L7: =Financials!AI17-Financials!AI20 -> -15538 | M7: =Financials!AJ17-Financials!AJ20 -> -17126
A8: Forecast horizon (yrs) | B8: 6 | C8: 6 | D8: 6 | E8: 6 | F8: 6
A9: Risk-free rate | B9: 0.04059 | C9: 0.04059 | D9: 0.04059 | E9: 0.04059 | F9: 0.04059
A10: Equity risk premium | B10: 0.048 | C10: 0.048 | D10: 0.048 | E10: 0.048 | F10: 0.048 | H10: Forecast | I10: 2025 | J10: 2026 | K10: 2027 | L10: 2028 | M10: 2029 | N10: 2030
A11: Beta | B11: ='Company profile'!B9 -> 0.3851 | C11: ='Company profile'!C9 -> 0.413 | D11: ='Company profile'!D9 -> 0.3853 | E11: ='Company profile'!E9 -> 0.2863 | F11: ='Company profile'!F9 -> 0.6451 | H11: =H3 -> WC-P&G | I11: =DCF!B3*'Assumptions & WACC'!$B$7 -> -10716.7 | J11: =DCF!C3*'Assumptions & WACC'!$B$7 -> -11085.793 | K11: =DCF!D3*'Assumptions & WACC'!$B$7 -> -11467.598 | L11: =DCF!E3*'Assumptions & WACC'!$B$7 -> -11862.553 | M11: =DCF!F3*'Assumptions & WACC'!$B$7 -> -12271.11 | N11: =DCF!G3*'Assumptions & WACC'!$B$7 -> -12693.738
A12: Cost of equity | B12: =B9+(B10*B11) -> 0.0590748 | C12: =C9+(C10*C11) -> 0.060414 | D12: =D9+(D10*D11) -> 0.0590844 | E12: =E9+(E10*E11) -> 0.0543324 | F12: =F9+(F10*F11) -> 0.0715548 | H12: =H4 -> WC-PepsiCo | I12: =DCF!J3*'Assumptions & WACC'!$C$7 -> -4724.6254 | J12: =DCF!K3*'Assumptions & WACC'!$C$7 -> -4983.1851 | K12: =DCF!L3*'Assumptions & WACC'!$C$7 -> -5255.8947 | L12: =DCF!M3*'Assumptions & WACC'!$C$7 -> -5543.5286 | M12: =DCF!N3*'Assumptions & WACC'!$C$7 -> -5846.9035 | N12: =DCF!O3*'Assumptions & WACC'!$C$7 -> -6166.8809
A13: Kd (pre-tax) | B13: =AVERAGE(Financials!B8:F8)/AVERAGE(Financials!B21:F21) -> 0.018792461 | C13: =AVERAGE(Financials!I8:M8)/AVERAGE(Financials!I21:M21) -> 0.026740138 | D13: =AVERAGE(Financials!P8:T8)/AVERAGE(Financials!P21:T21) -> 0.033598531 | E13: =AVERAGE(Financials!X8:AB8)/AVERAGE(Financials!X21:AB21) -> 0.026701571 | F13: =AVERAGE(Financials!AF8:AJ8)/AVERAGE(Financials!AF21:AJ21) -> 0.034181047 | H13: =H5 -> WC-CocaCola | I13: =DCF!R3*'Assumptions & WACC'!$D$7 -> 3411.135 | J13: =DCF!S3*'Assumptions & WACC'!$D$7 -> 3661.7737 | K13: =DCF!T3*'Assumptions & WACC'!$D$7 -> 3930.8286 | L13: =DCF!U3*'Assumptions & WACC'!$D$7 -> 4219.6527 | M13: =DCF!V3*'Assumptions & WACC'!$D$7 -> 4529.6986 | N13: =DCF!W3*'Assumptions & WACC'!$D$7 -> 4862.5257
A14: Tax rate | B14: 0.23 | C14: 0.23 | D14: 0.23 | E14: 0.23 | F14: 0.23 | H14: =H6 -> WC-Colgate | I14: =DCF!Z3*'Assumptions & WACC'!$E$7 -> 339.79477 | J14: =DCF!AA3*'Assumptions & WACC'!$E$7 -> 353.60324 | K14: =DCF!AB3*'Assumptions & WACC'!$E$7 -> 367.97284 | L14: =DCF!AC3*'Assumptions & WACC'!$E$7 -> 382.9264 | M14: =DCF!AD3*'Assumptions & WACC'!$E$7 -> 398.48763 | N14: =DCF!AE3*'Assumptions & WACC'!$E$7 -> 414.68124
A15: Kd (after tax) | B15: =B13*(1-B14) -> 0.014470195 | C15: =C13*(1-C14) -> 0.020589906 | D15: =D13*(1-D14) -> 0.025870869 | E15: =E13*(1-E14) -> 0.020560209 | F15: =F13*(1-F14) -> 0.026319406 | H15: =H7 -> WC-Walmart | I15: =DCF!AH3*'Assumptions & WACC'!$F$7 -> -13394.494 | J15: =DCF!AI3*'Assumptions & WACC'!$F$7 -> -13933.108 | K15: =DCF!AJ3*'Assumptions & WACC'!$F$7 -> -14493.381 | L15: =DCF!AK3*'Assumptions & WACC'!$F$7 -> -15076.183 | M15: =DCF!AL3*'Assumptions & WACC'!$F$7 -> -15682.42 | N15: =DCF!AM3*'Assumptions & WACC'!$F$7 -> -16313.035
A16: Total debt | B16: =Financials!F21 -> 32460 | C16: =Financials!M21 -> 44306 | D16: =Financials!T21 -> 44522 | E16: =Financials!AB21 -> 7949 | F16: =Financials!AJ21 -> 60114
A17: Market cap | B17: ='Company profile'!B8 -> 344317.75 | C17: ='Company profile'!C8 -> 202113.36 | D17: ='Company profile'!D8 -> 307134.88 | E17: ='Company profile'!E8 -> 63590.46 | F17: ='Company profile'!F8 -> 801391.12
A18: Total capital | B18: =B16+B17 -> 376777.75 | C18: =C16+C17 -> 246419.36 | D18: =D16+D17 -> 351656.88 | E18: =E16+E17 -> 71539.46 | F18: =F16+F17 -> 861505.12
A19: Debt weight | B19: =B16/B18 -> 0.086151583 | C19: =C16/C18 -> 0.17979918 | D19: =D16/D18 -> 0.12660637 | E19: =E16/E18 -> 0.1111135 | F19: =F16/F18 -> 0.069777879
A20: Equity weight | B20: =B17/B18 -> 0.91384842 | C20: =C17/C18 -> 0.82020082 | D20: =D17/D18 -> 0.87339363 | E20: =E17/E18 -> 0.8888865 | F20: =F17/F18 -> 0.93022212
A21: WACC | B21: =(B12*B20)+(B15*B19) -> 0.055232043 | C21: =(C12*C20)+(C15*C19) -> 0.05325366 | D21: =(D12*D20)+(D15*D19) -> 0.054879356 | E21: =(E12*E20)+(E15*E19) -> 0.050579854 | F21: =(F12*F20)+(F15*F19) -> 0.06839837
A22: Terminal year | B22: 2030 | C22: 2030 | D22: 2030 | E22: 2030 | F22: 2030
A23: PV discount rate (terminal year) | B23: =1/(1+B21)^6 -> 0.72428948 | C23: =1/(1+C21)^6 -> 0.73249074 | D23: =1/(1+D21)^6 -> 0.72574365 | E23: =1/(1+E21)^6 -> 0.74374762 | F23: =1/(1+F21)^6 -> 0.67235819
A24: Cash & cash equivalents | B24: =Financials!F14 -> 9482 | C24: =Financials!M14 -> 8505 | D24: =Financials!T14 -> 10828 | E24: =Financials!AB14 -> 1096 | F24: =Financials!AJ14 -> 9037
A25: Terminal growth rate | B25: 0.02 | C25: 0.02 | D25: 0.02 | E25: 0.02 | F25: 0.03
A26: Shares Outstanding | B26: 2354.051 | C26: 1370 | D26: ='Company profile'!D6 -> 4301.609 | E26: ='Company profile'!E6 -> 806.0649 | F26: ='Company profile'!F6 -> 7972.851

Sheet DCF
A1: DCF | G1: P&G | O1: PepsiCo | Q1: DCF | W1: ='Assumptions & WACC'!D2 -> Coca-Cola | AE1: ='Assumptions & WACC'!E2 -> Colgate | AG1: DCF | AM1: ='Assumptions & WACC'!F2 -> Walmart
A2: Particulars | B2: 2025 | C2: 2026 | D2: 2027 | E2: 2028 | F2: 2029 | G2: 2030 | I2: Particulars | J2: 2025 | K2: 2026 | L2: 2027 | M2: 2028 | N2: 2029 | O2: 2030 | Q2: Particulars | R2: 2025 | S2: 2026 | T2: 2027 | U2: 2028 | V2: 2029 | W2: 2030 | Y2: Particulars | Z2: 2025 | AA2: 2026 | AB2: 2027 | AC2: 2028 | AD2: 2029 | AE2: 2030 | AG2: Particulars | AH2: 2025 | AI2: 2026 | AJ2: 2027 | AK2: 2028 | AL2: 2029 | AM2: 2030
A3: Revenue | B3: =Table1[[#This Row],[2024]]*(1+'Assumptions & WACC'!B3) -> 86933.381 | C3: =Table9[[#This Row],[2025]]*(1+'Assumptions & WACC'!$B$3) -> 89927.447 | D3: =Table9[[#This Row],[2026]]*(1+'Assumptions & WACC'!$B$3) -> 93024.632 | E3: =Table9[[#This Row],[2027]]*(1+'Assumptions & WACC'!$B$3) -> 96228.487 | F3: =Table9[[#This Row],[2028]]*(1+'Assumptions & WACC'!$B$3) -> 99542.685 | G3: =Table9[[#This Row],[2029]]*(1+'Assumptions & WACC'!$B$3) -> 102971.03 | I3: Revenue | J3: =Table18[[#This Row],[2024]]*(1+'Assumptions & WACC'!C3) -> 96880.798 | K3: =Table10[[#This Row],[2025]]*(1+'Assumptions & WACC'!$C$3) -> 102182.69 | L3: =Table10[[#This Row],[2026]]*(1+'Assumptions & WACC'!$C$3) -> 107774.74 | M3: =Table10[[#This Row],[2027]]*(1+'Assumptions & WACC'!$C$3) -> 113672.82 | N3: =Table10[[#This Row],[2028]]*(1+'Assumptions & WACC'!$C$3) -> 119893.67 | O3: =Table10[[#This Row],[2029]]*(1+'Assumptions & WACC'!$C$3) -> 126454.97 | Q3: Revenue | R3: =Table15[[#This Row],[2024]]*(1+'Assumptions & WACC'!D3) -> 50518.884 | S3: =Table927[[#This Row],[2025]]*(1+'Assumptions & WACC'!$D$3) -> 54230.843 | T3: =Table927[[#This Row],[2026]]*(1+'Assumptions & WACC'!$D$3) -> 58215.543 | U3: =Table927[[#This Row],[2027]]*(1+'Assumptions & WACC'!$D$3) -> 62493.026 | V3: =Table927[[#This Row],[2028]]*(1+'Assumptions & WACC'!$D$3) -> 67084.804 | W3: =Table927[[#This Row],[2029]]*(1+'Assumptions & WACC'!$D$3) -> 72013.97 | Y3: Revenue | Z3: =Table1811[[#This Row],[2024]]*(1+'Assumptions & WACC'!E3) -> 20917.858 | AA3: =Table1028[[#This Row],[2025]]*(1+'Assumptions & WACC'!$E$3) -> 21767.91 | AB3: =Table1028[[#This Row],[2026]]*(1+'Assumptions & WACC'!$E$3) -> 22652.507 | AC3: =Table1028[[#This Row],[2027]]*(1+'Assumptions & WACC'!$E$3) -> 23573.052 | AD3: =Table1028[[#This Row],[2028]]*(1+'Assumptions & WACC'!$E$3) -> 24531.006 | AE3: =Table1028[[#This Row],[2029]]*(1+'Assumptions & WACC'!$E$3) -> 25527.889 | AG3: Revenue | AH3: =Table181114[[#This Row],[2024]]*(1+'Assumptions & WACC'!F3) -> 708368.49 | AI3: =Table92731[[#This Row],[2025]]*(1+'Assumptions & WACC'!$F$3) -> 736853.11 | AJ3: =Table92731[[#This Row],[2026]]*(1+'Assumptions & WACC'!$F$3) -> 766483.15 | AK3: =Table92731[[#This Row],[2027]]*(1+'Assumptions & WACC'!$F$3) -> 797304.65 | AL3: =Table92731[[#This Row],[2028]]*(1+'Assumptions & WACC'!$F$3) -> 829365.54 | AM3: =Table92731[[#This Row],[2029]]*(1+'Assumptions & WACC'!$F$3) -> 862715.64
A4: EBIT | B4: =B3*'Assumptions & WACC'!$B$4 -> 19491.821 | C4: =C3*'Assumptions & WACC'!$B$4 -> 20163.138 | D4: =D3*'Assumptions & WACC'!$B$4 -> 20857.575 | E4: =E3*'Assumptions & WACC'!$B$4 -> 21575.929 | F4: =F3*'Assumptions & WACC'!$B$4 -> 22319.024 | G4: =G3*'Assumptions & WACC'!$B$4 -> 23087.712 | I4: EBIT | J4: =J3*'Assumptions & WACC'!$C$4 -> 13306.583 | K4: =K3*'Assumptions & WACC'!$C$4 -> 14034.798 | L4: =L3*'Assumptions & WACC'!$C$4 -> 14802.866 | M4: =M3*'Assumptions & WACC'!$C$4 -> 15612.967 | N4: =N3*'Assumptions & WACC'!$C$4 -> 16467.402 | O4: =O3*'Assumptions & WACC'!$C$4 -> 17368.596 | Q4: EBIT | R4: =R3*'Assumptions & WACC'!$D$4 -> 16312.335 | S4: =S3*'Assumptions & WACC'!$D$4 -> 17510.91 | T4: =T3*'Assumptions & WACC'!$D$4 -> 18797.553 | U4: =U3*'Assumptions & WACC'!$D$4 -> 20178.735 | V4: =V3*'Assumptions & WACC'!$D$4 -> 21661.4 | W4: =W3*'Assumptions & WACC'!$D$4 -> 23253.007 | Y4: EBIT | Z4: =Z3*'Assumptions & WACC'!$E$4 -> 4020.1039 | AA4: =AA3*'Assumptions & WACC'!$E$4 -> 4183.4715 | AB4: =AB3*'Assumptions & WACC'!$E$4 -> 4353.4781 | AC4: =AC3*'Assumptions & WACC'!$E$4 -> 4530.3932 | AD4: =AD3*'Assumptions & WACC'!$E$4 -> 4714.4978 | AE4: =AE3*'Assumptions & WACC'!$E$4 -> 4906.084 | AG4: EBIT | AH4: =AH3*'Assumptions & WACC'!$F$4 -> 26450.288 | AI4: =AI3*'Assumptions & WACC'!$F$4 -> 27513.896 | AJ4: =AJ3*'Assumptions & WACC'!$F$4 -> 28620.273 | AK4: =AK3*'Assumptions & WACC'!$F$4 -> 29771.14 | AL4: =AL3*'Assumptions & WACC'!$F$4 -> 30968.285 | AM4: =AM3*'Assumptions & WACC'!$F$4 -> 32213.569
A5: NOPAT | B5: =B4*(1-'Assumptions & WACC'!$B$14) -> 15008.702 | C5: =C4*(1-'Assumptions & WACC'!$B$14) -> 15525.616 | D5: =D4*(1-'Assumptions & WACC'!$B$14) -> 16060.333 | E5: =E4*(1-'Assumptions & WACC'!$B$14) -> 16613.465 | F5: =F4*(1-'Assumptions & WACC'!$B$14) -> 17185.649 | G5: =G4*(1-'Assumptions & WACC'!$B$14) -> 17777.538 | I5: NOPAT | J5: =J4*(1-'Assumptions & WACC'!$C$14) -> 10246.069 | K5: =K4*(1-'Assumptions & WACC'!$C$14) -> 10806.795 | L5: =L4*(1-'Assumptions & WACC'!$C$14) -> 11398.207 | M5: =M4*(1-'Assumptions & WACC'!$C$14) -> 12021.985 | N5: =N4*(1-'Assumptions & WACC'!$C$14) -> 12679.899 | O5: =O4*(1-'Assumptions & WACC'!$C$14) -> 13373.819 | Q5: NOPAT | R5: =R4*(1-'Assumptions & WACC'!$B$14) -> 12560.498 | S5: =S4*(1-'Assumptions & WACC'!$B$14) -> 13483.401 | T5: =T4*(1-'Assumptions & WACC'!$B$14) -> 14474.116 | U5: =U4*(1-'Assumptions & WACC'!$B$14) -> 15537.626 | V5: =V4*(1-'Assumptions & WACC'!$B$14) -> 16679.278 | W5: =W4*(1-'Assumptions & WACC'!$B$14) -> 17904.816 | Y5: NOPAT | Z5: =Z4*(1-'Assumptions & WACC'!$C$14) -> 3095.48 | AA5: =AA4*(1-'Assumptions & WACC'!$C$14) -> 3221.2731 | AB5: =AB4*(1-'Assumptions & WACC'!$C$14) -> 3352.1781 | AC5: =AC4*(1-'Assumptions & WACC'!$C$14) -> 3488.4028 | AD5: =AD4*(1-'Assumptions & WACC'!$C$14) -> 3630.1633 | AE5: =AE4*(1-'Assumptions & WACC'!$C$14) -> 3777.6847 | AG5: NOPAT | AH5: =AH4*(1-'Assumptions & WACC'!$B$14) -> 20366.722 | AI5: =AI4*(1-'Assumptions & WACC'!$B$14) -> 21185.7 | AJ5: =AJ4*(1-'Assumptions & WACC'!$B$14) -> 22037.61 | AK5: =AK4*(1-'Assumptions & WACC'!$B$14) -> 22923.778 | AL5: =AL4*(1-'Assumptions & WACC'!$B$14) -> 23845.579 | AM5: =AM4*(1-'Assumptions & WACC'!$B$14) -> 24804.448
A6: Depreciation | B6: =B3*'Assumptions & WACC'!$B$5 -> 3130.9721 | C6: =C3*'Assumptions & WACC'!$B$5 -> 3238.8057 | D6: =D3*'Assumptions & WACC'!$B$5 -> 3350.3532 | E6: =E3*'Assumptions & WACC'!$B$5 -> 3465.7425 | F6: =F3*'Assumptions & WACC'!$B$5 -> 3585.1059 | G6: =G3*'Assumptions & WACC'!$B$5 -> 3708.5802 | I6: Depreciation | J6: =J3*'Assumptions & WACC'!$C$5 -> 3262.5108 | K6: =K3*'Assumptions & WACC'!$C$5 -> 3441.0548 | L6: =L3*'Assumptions & WACC'!$C$5 -> 3629.3698 | M6: =M3*'Assumptions & WACC'!$C$5 -> 3827.9906 | N6: =N3*'Assumptions & WACC'!$C$5 -> 4037.481 | O6: =O3*'Assumptions & WACC'!$C$5 -> 4258.4361 | Q6: Depreciation | R6: =R3*'Assumptions & WACC'!$D$5 -> 1570.6803 | S6: =S3*'Assumptions & WACC'!$D$5 -> 1686.0887 | T6: =T3*'Assumptions & WACC'!$D$5 -> 1809.9768 | U6: =U3*'Assumptions & WACC'!$D$5 -> 1942.9678 | V6: =V3*'Assumptions & WACC'!$D$5 -> 2085.7306 | W6: =W3*'Assumptions & WACC'!$D$5 -> 2238.9831 | Y6: Depreciation | Z6: =Z3*'Assumptions & WACC'!$E$5 -> 643.43629 | AA6: =AA3*'Assumptions & WACC'!$E$5 -> 669.58404 | AB6: =AB3*'Assumptions & WACC'!$E$5 -> 696.79437 | AC6: =AC3*'Assumptions & WACC'!$E$5 -> 725.11046 | AD6: =AD3*'Assumptions & WACC'!$E$5 -> 754.57726 | AE6: =AE3*'Assumptions & WACC'!$E$5 -> 785.24151 | AG6: Depreciation | AH6: =AH3*'Assumptions & WACC'!$F$5 -> 13276.214 | AI6: =AI3*'Assumptions & WACC'!$F$5 -> 13810.072 | AJ6: =AJ3*'Assumptions & WACC'!$F$5 -> 14365.397 | AK6: =AK3*'Assumptions & WACC'!$F$5 -> 14943.052 | AL6: =AL3*'Assumptions & WACC'!$F$5 -> 15543.936 | AM6: =AM3*'Assumptions & WACC'!$F$5 -> 16168.982
A7: Capex | B7: =B3*'Assumptions & WACC'!$B$6 -> 3403.9514 | C7: =C3*'Assumptions & WACC'!$B$6 -> 3521.1866 | D7: =D3*'Assumptions & WACC'!$B$6 -> 3642.4595 | E7: =E3*'Assumptions & WACC'!$B$6 -> 3767.9092 | F7: =F3*'Assumptions & WACC'!$B$6 -> 3897.6795 | G7: =G3*'Assumptions & WACC'!$B$6 -> 4031.9192 | I7: Capex | J7: =J3*'Assumptions & WACC'!$C$6 -> 5751.477 | K7: =K3*'Assumptions & WACC'!$C$6 -> 6066.2321 | L7: =L3*'Assumptions & WACC'!$C$6 -> 6398.2124 | M7: =M3*'Assumptions & WACC'!$C$6 -> 6748.3608 | N7: =N3*'Assumptions & WACC'!$C$6 -> 7117.6713 | O7: =O3*'Assumptions & WACC'!$C$6 -> 7507.1927 | Q7: Capex | R7: =R3*'Assumptions & WACC'!$D$6 -> 1934.1939 | S7: =S3*'Assumptions & WACC'!$D$6 -> 2076.312 | T7: =T3*'Assumptions & WACC'!$D$6 -> 2228.8724 | U7: =U3*'Assumptions & WACC'!$D$6 -> 2392.6425 | V7: =V3*'Assumptions & WACC'!$D$6 -> 2568.4458 | W7: =W3*'Assumptions & WACC'!$D$6 -> 2757.1666 | Y7: Capex | Z7: =Z3*'Assumptions & WACC'!$E$6 -> 672.49618 | AA7: =AA3*'Assumptions & WACC'!$E$6 -> 699.82486 | AB7: =AB3*'Assumptions & WACC'!$E$6 -> 728.2641 | AC7: =AC3*'Assumptions & WACC'!$E$6 -> 757.85905 | AD7: =AD3*'Assumptions & WACC'!$E$6 -> 788.65667 | AE7: =AE3*'Assumptions & WACC'!$E$6 -> 820.70583 | AG7: Capex | AH7: =AH3*'Assumptions & WACC'!$F$6 -> 19509.563 | AI7: =AI3*'Assumptions & WACC'!$F$6 -> 20294.073 | AJ7: =AJ3*'Assumptions & WACC'!$F$6 -> 21110.13 | AK7: =AK3*'Assumptions & WACC'!$F$6 -> 21959.002 | AL7: =AL3*'Assumptions & WACC'!$F$6 -> 22842.009 | AM7: =AM3*'Assumptions & WACC'!$F$6 -> 23760.522
A8: Change in Working capital | B8: ='Assumptions & WACC'!I11-'Assumptions & WACC'!M3 -> -1798.6999 | C8: ='Assumptions & WACC'!J11-'Assumptions & WACC'!I11 -> -369.09309 | D8: ='Assumptions & WACC'!K11-'Assumptions & WACC'!J11 -> -381.805 | E8: ='Assumptions & WACC'!L11-'Assumptions & WACC'!K11 -> -394.95472 | F8: ='Assumptions & WACC'!M11-'Assumptions & WACC'!L11 -> -408.55732 | G8: ='Assumptions & WACC'!N11-'Assumptions & WACC'!M11 -> -422.62842 | I8: Change in Working capital | J8: ='Assumptions & WACC'!I12-'Assumptions & WACC'!M4 -> 985.37458 | K8: ='Assumptions & WACC'!J12-'Assumptions & WACC'!I12 -> -258.55967 | L8: ='Assumptions & WACC'!K12-'Assumptions & WACC'!J12 -> -272.70959 | M8: ='Assumptions & WACC'!L12-'Assumptions & WACC'!K12 -> -287.63389 | N8: ='Assumptions & WACC'!M12-'Assumptions & WACC'!L12 -> -303.37493 | O8: ='Assumptions & WACC'!N12-'Assumptions & WACC'!M12 -> -319.97741 | Q8: Change in Working capital | R8: ='Assumptions & WACC'!I13-'Assumptions & WACC'!M5 -> 2663.135 | S8: ='Assumptions & WACC'!J13-'Assumptions & WACC'!I13 -> 250.63876 | T8: ='Assumptions & WACC'!K13-'Assumptions & WACC'!J13 -> 269.05485 | U8: ='Assumptions & WACC'!L13-'Assumptions & WACC'!K13 -> 288.8241 | V8: ='Assumptions & WACC'!M13-'Assumptions & WACC'!L13 -> 310.04593 | W8: ='Assumptions & WACC'!N13-'Assumptions & WACC'!M13 -> 332.82706 | Y8: Change in Working capital | Z8: ='Assumptions & WACC'!I14-'Assumptions & WACC'!M6 -> 781.79477 | AA8: ='Assumptions & WACC'!J14-'Assumptions & WACC'!I14 -> 13.808465 | AB8: ='Assumptions & WACC'!K14-'Assumptions & WACC'!J14 -> 14.369609 | AC8: ='Assumptions & WACC'!L14-'Assumptions & WACC'!K14 -> 14.953556 | AD8: ='Assumptions & WACC'!M14-'Assumptions & WACC'!L14 -> 15.561233 | AE8: ='Assumptions & WACC'!N14-'Assumptions & WACC'!M14 -> 16.193606 | AG8: Change in Working capital | AH8: ='Assumptions & WACC'!I15-'Assumptions & WACC'!M7 -> 3731.5055 | AI8: ='Assumptions & WACC'!J15-'Assumptions & WACC'!I15 -> -538.61391 | AJ8: ='Assumptions & WACC'!K15-'Assumptions & WACC'!J15 -> -560.27243 | AK8: ='Assumptions & WACC'!L15-'Assumptions & WACC'!K15 -> -582.80187 | AL8: ='Assumptions & WACC'!M15-'Assumptions & WACC'!L15 -> -606.23726 | AM8: ='Assumptions & WACC'!N15-'Assumptions & WACC'!M15 -> -630.61503
A9: FCFF | B9: =B5+B6-B7-B8 -> 16534.423 | C9: =C5+C6-C7-C8 -> 15612.328 | D9: =D5+D6-D7-D8 -> 16150.031 | E9: =E5+E6-E7-E8 -> 16706.253 | F9: =F5+F6-F7-F8 -> 17281.632 | G9: =G5+G6-G7-G8 -> 17876.828 | I9: FCFF | J9: =J5+J6-J7-J8 -> 6771.7279 | K9: =K5+K6-K7-K8 -> 8440.1771 | L9: =L5+L6-L7-L8 -> 8902.0739 | M9: =M5+M6-M7-M8 -> 9389.2484 | N9: =N5+N6-N7-N8 -> 9903.0841 | O9: =O5+O6-O7-O8 -> 10445.04 | Q9: FCFF | R9: =R5+R6-R7-R8 -> 9533.8492 | S9: =S5+S6-S7-S8 -> 12842.539 | T9: =T5+T6-T7-T8 -> 13786.166 | U9: =U5+U6-U7-U8 -> 14799.127 | V9: =V5+V6-V7-V8 -> 15886.517 | W9: =W5+W6-W7-W8 -> 17053.805 | Y9: FCFF | Z9: =Z5+Z6-Z7-Z8 -> 2284.6254 | AA9: =AA5+AA6-AA7-AA8 -> 3177.2238 | AB9: =AB5+AB6-AB7-AB8 -> 3306.3388 | AC9: =AC5+AC6-AC7-AC8 -> 3440.7006 | AD9: =AD5+AD6-AD7-AD8 -> 3580.5227 | AE9: =AE5+AE6-AE7-AE8 -> 3726.0267 | AG9: FCFF | AH9: =AH5+AH6-AH7-AH8 -> 10401.867 | AI9: =AI5+AI6-AI7-AI8 -> 15240.312 | AJ9: =AJ5+AJ6-AJ7-AJ8 -> 15853.149 | AK9: =AK5+AK6-AK7-AK8 -> 16490.63 | AL9: =AL5+AL6-AL7-AL8 -> 17153.744 | AM9: =AM5+AM6-AM7-AM8 -> 17843.523
A12: Metrics | B12: Value | I12: Metrics | J12: Value | Q12: Metrics | R12: Value | Y12: Metrics | Z12: Value | AG12: Metrics | AH12: Value
A13: Terminal Value | B13: =G9*(1+'Assumptions & WACC'!B25)/('Assumptions & WACC'!B21-'Assumptions & WACC'!B25) -> 517550.58 | I13: Terminal Value | J13: =O9*(1+'Assumptions & WACC'!C25)/('Assumptions & WACC'!C21-'Assumptions & WACC'!C25) -> 320384 | Q13: Terminal Value | R13: =W9*(1+'Assumptions & WACC'!D25)/('Assumptions & WACC'!D21-'Assumptions & WACC'!D25) -> 498715.67 | Y13: Terminal Value | Z13: =AE9*(1+'Assumptions & WACC'!E25)/('Assumptions & WACC'!E21-'Assumptions & WACC'!E25) -> 124282.72 | AG13: Terminal Value | AH13: =AM9*(1+'Assumptions & WACC'!F25)/('Assumptions & WACC'!F21-'Assumptions & WACC'!F25) -> 478635.65
A14: PV of Terminal value | B14: =B13*'Assumptions & WACC'!B23 -> 374856.44 | I14: PV of Terminal value | J14: =J13*'Assumptions & WACC'!C23 -> 234678.31 | Q14: PV of Terminal value | R14: =R13*'Assumptions & WACC'!D23 -> 361939.73 | Y14: PV of Terminal value | Z14: =Z13*'Assumptions & WACC'!E23 -> 92434.975 | AG14: PV of Terminal value | AH14: =AH13*'Assumptions & WACC'!F23 -> 321814.6
A15: PV of FCFF | B15: =NPV('Assumptions & WACC'!B21,DCF!B9:G9) -> 83064.221 | I15: PV of FCFF | J15: =NPV('Assumptions & WACC'!C21,DCF!J9:O9) -> 44577.166 | Q15: PV of FCFF | R15: =NPV('Assumptions & WACC'!D21,DCF!R9:W9) -> 68813.955 | Y15: PV of FCFF | Z15: =NPV('Assumptions & WACC'!E21,DCF!Z9:AE9) -> 16298.053 | AG15: PV of FCFF | AH15: =NPV('Assumptions & WACC'!F21,DCF!AH9:AM9) -> 73062.341
A16: Total enterprise value | B16: =B14+B15 -> 457920.66 | I16: Total enterprise value | J16: =J14+J15 -> 279255.48 | Q16: Total enterprise value | R16: =R14+R15 -> 430753.68 | Y16: Total enterprise value | Z16: =Z14+Z15 -> 108733.03 | AG16: Total enterprise value | AH16: =AH14+AH15 -> 394876.94
A17: Net debt | B17: =Financials!F21-'Assumptions & WACC'!B24 -> 22978 | I17: Net debt | J17: =Financials!M21-'Assumptions & WACC'!C24 -> 35801 | Q17: Net debt | R17: ='Assumptions & WACC'!D16-'Assumptions & WACC'!D24 -> 33694 | Y17: Net debt | Z17: ='Assumptions & WACC'!E16-'Assumptions & WACC'!E24 -> 6853 | AG17: Net debt | AH17: ='Assumptions & WACC'!F16-'Assumptions & WACC'!F24 -> 51077
A18: Total equity value | B18: =B16-B17 -> 434942.66 | I18: Total equity value | J18: =J16-J17 -> 243454.48 | Q18: Total equity value | R18: =R16-R17 -> 397059.68 | Y18: Total equity value | Z18: =Z16-Z17 -> 101880.03 | AG18: Total equity value | AH18: =AH16-AH17 -> 343799.94
A19: Outstanding shares | B19: ='Assumptions & WACC'!B26 -> 2354.051 | I19: Outstanding shares | J19: ='Assumptions & WACC'!C26 -> 1370 | Q19: Outstanding shares | R19: ='Assumptions & WACC'!D26 -> 4301.609 | Y19: Outstanding shares | Z19: ='Assumptions & WACC'!E26 -> 806.0649 | AG19: Outstanding shares | AH19: ='Assumptions & WACC'!F26 -> 7972.851
A20: Intrinsic value | B20: =B18/B19 -> 184.76348 | I20: Intrinsic value | J20: =J18/J19 -> 177.704 | Q20: Intrinsic value | R20: =R18/R19 -> 92.304922 | Y20: Intrinsic value | Z20: =Z18/Z19 -> 126.39184 | AG20: Intrinsic value | AH20: =AH18/AH19 -> 43.121331
A21: Current market price | B21: ='Company profile'!B3 -> 147.35 | I21: Current market price | J21: ='Company profile'!C3 -> 147.815 | Q21: Current market price | R21: ='Company profile'!D3 -> 71.4 | Y21: Current market price | Z21: ='Company profile'!E3 -> 78.89 | AG21: Current market price | AH21: ='Company profile'!F3 -> 100.515
A22: Upside/Downside | B22: =(B20-B21)/B21 -> 0.25390896 | I22: Upside/Downside | J22: =(J20-J21)/J21 -> 0.20220544 | Q22: Upside/Downside | R22: =(R20-R21)/R21 -> 0.29278602 | Y22: Upside/Downside | Z22: =(Z20-Z21)/Z21 -> 0.60212755 | AG22: Upside/Downside | AH22: =(AH20-AH21)/AH21 -> -0.57099606

Sheet Relative
A1: RELATIVE
A2: Company | B2: EV/EBITDA | C2: P/E | D2: P/S | E2: P/B
A3: #VALUE! | B3: 20.89 | C3: {=_FV(A3,"P/E",TRUE)} -> 31.1983 | D3: 3.78 | E3: 8.97 | H3: Company | I3: EV/EBITDA | J3: P/E | K3: P/S | L3: P/B | M3: Shares
A4: #VALUE! | B4: 19.85 | C4: {=_FV(A4,"P/E",TRUE)} -> 37.9216 | D4: 1.18 | E4: 8.94 | H4: P&G | I4: =(B23*B20)/Relative!$M$4 -> 162.74519 | J4: =(C23*C20)/Relative!$M$4 -> 123.38901 | K4: =(D23*D20)/Relative!$M$4 -> 109.37507 | L4: =(E23*E20)/Relative!$M$4 -> 494.8806 | M4: ='Assumptions & WACC'!B26 -> 2354.051
A5: #VALUE! | B5: 37.24 | C5: {=_FV(A5,"P/E",TRUE)} -> 48.5987 | D5: 1.8 | E5: 19.03 | H5: PepsiCo | I5: =(B24*B20)/Relative!$M$5 -> 209.29183 | J5: =(C24*C20)/Relative!$M$5 -> 125.77213 | K5: =(D24*D20)/Relative!$M$5 -> 205.41437 | L5: =(E24*E20)/Relative!$M$5 -> 305.61599 | M5: ='Assumptions & WACC'!C26 -> 1370
A6: #VALUE! | B6: 18.86 | C6: {=_FV(A6,"P/E",TRUE)} -> 22.8748 | D6: 2.64 | E6: 70.73 | H6: =A25 -> Coca-Cola | I6: =(B25*B20)/Relative!$M$6 -> 65.701028 | J6: =(C25*C20)/Relative!$M$6 -> 59.109411 | K6: =(D25*D20)/Relative!$M$6 -> 33.51842 | L6: =(E25*E20)/Relative!$M$6 -> 141.2635 | M6: ='Assumptions & WACC'!D26 -> 4301.609
A7: #VALUE! | B7: 16.91 | C7: {=_FV(A7,"P/E",TRUE)} -> 31.6118 | D7: 2.82 | E7: 6.11 | H7: =A26 -> Colgate | I7: =(B26*B20)/Relative!$M$7 -> 104.60657 | J7: =(C26*C20)/Relative!$M$7 -> 76.109016 | K7: =(D26*D20)/Relative!$M$7 -> 76.40134 | L7: =(E26*E20)/Relative!$M$7 -> 15.550584 | M7: ='Assumptions & WACC'!E26 -> 806.0649
A8: #VALUE! | B8: 14.65 | C8: {=_FV(A8,"P/E",TRUE)} -> 19.0863 | D8: 1.77 | E8: 0 | H8: =A27 -> Walmart | I8: =(B27*B20)/Relative!$M$8 -> 93.067038 | J8: =(C27*C20)/Relative!$M$8 -> 23.930227 | K8: =(D27*D20)/Relative!$M$8 -> 261.68403 | L8: =(E27*E20)/Relative!$M$8 -> 281.55079 | M8: ='Assumptions & WACC'!F26 -> 7972.851
A9: #VALUE! | B9: 12.18 | C9: {=_FV(A9,"P/E",TRUE)} -> 19.1393 | D9: 2.2 | E9: 33.84
A10: #VALUE! | B10: 19.03 | C10: {=_FV(A10,"P/E",TRUE)} -> 21.51 | D10: 4.93 | E10: 7.54
A11: #VALUE! | B11: 15.1 | C11: {=_FV(A11,"P/E",TRUE)} -> 28.1071 | D11: 2.28 | E11: 10.72
A12: #VALUE! | B12: 13 | C12: {=_FV(A12,"P/E",TRUE)} -> 23.1748 | D12: 2.09 | E12: 6.92
A13: #VALUE! | B13: 19.2 | C13: {=_FV(A13,"P/E",TRUE)} -> 30.6913 | D13: 4.6 | E13: 6.44
A14: #VALUE! | B14: 15.35 | C14: {=_FV(A14,"P/E",TRUE)} -> 24.4195 | D14: 5.03 | E14: 0 | H14: Company | I14: Target Price | J14: CMP | K14: U/D
A15: #VALUE! | B15: 19.13 | C15: {=_FV(A15,"P/E",TRUE)} -> 23.6361 | D15: 5.81 | E15: 10.1 | H15: =H6 -> Coca-Cola | I15: =AVERAGE(I4:L4) -> 222.59747 | J15: ='Company profile'!B3 -> 147.35 | K15: =(Table24[[#This Row],[Target Price]]-J15)/J15 -> 0.51067164
A16: #VALUE! | B16: 13.96 | C16: {=_FV(A16,"P/E",TRUE)} -> 19.9532 | D16: 2.12 | E16: 6.68 | H16: =H7 -> Colgate | I16: =AVERAGE(I5:L5) -> 211.52358 | J16: ='Company profile'!C3 -> 147.815 | K16: =(Table24[[#This Row],[Target Price]]-J16)/J16 -> 0.43100214
A17: #VALUE! | B17: 12.83 | C17: {=_FV(A17,"P/E",TRUE)} -> 20.8961 | D17: 2.24 | E17: 2.83 | H17: =A25 -> Coca-Cola | I17: =AVERAGE(I6:L6) -> 74.898089 | J17: ='Company profile'!D3 -> 71.4 | K17: =(Table24[[#This Row],[Target Price]]-J17)/J17 -> 0.048992842
A18: #VALUE! | B18: 17.71 | C18: {=_FV(A18,"P/E",TRUE)} -> 22.1079 | D18: 3.73 | E18: 169.82 | H18: =A26 -> Colgate | I18: =AVERAGE(I7:L7) -> 68.166877 | J18: ='Company profile'!E3 -> 78.89 | K18: =(Table24[[#This Row],[Target Price]]-J18)/J18 -> -0.135925
H19: =A27 -> Walmart | I19: =AVERAGE(I8:L8) -> 165.05802 | J19: ='Company profile'!F3 -> 100.515 | K19: =(Table24[[#This Row],[Target Price]]-J19)/J19 -> 0.64212328
A20: Average | B20: =AVERAGE(B3:B18) -> 17.868125 | C20: =AVERAGE(C3:C18) -> 26.557925 | D20: =AVERAGE(D3:D18) -> 3.06375 | E20: =AVERAGE(E3:E18) -> 23.041875
A22: Company | B22: EBITDA | C22: Net Income | D22: Revenue | E22: Book Value
A23: =H4 -> P&G | B23: =Financials!F6+Financials!F7 -> 21441 | C23: =Financials!F10 -> 10937 | D23: =Financials!F3 -> 84039 | E23: =Financials!F22 -> 50559
A24: =H5 -> PepsiCo | B24: =Financials!M6+Financials!M7 -> 16047 | C24: =Financials!M10 -> 6488 | D24: =Financials!M3 -> 91854 | E24: =Financials!M22 -> 18171
A25: Coca-Cola | B25: =Financials!T6+Financials!T7 -> 15817 | C25: =Financials!T10 -> 9574 | D25: =Financials!T3 -> 47061 | E25: =Financials!T22 -> 26372
A26: Colgate | B26: =Financials!AB6+Financials!AB7 -> 4719 | C26: =Financials!AB10 -> 2310 | D26: =Financials!AB3 -> 20101 | E26: =Financials!AB22 -> 544
A27: Walmart | B27: =Financials!AJ6+Financials!AJ7 -> 41527 | C27: =Financials!AJ10 -> 7184 | D27: =Financials!AJ3 -> 680985 | E27: =Financials!AJ22 -> 97421

Sheet Calc
A1: Year | B1: Particulars | C1: Company | D1: Value | F1: Company | G1: Change in EBIT (historical) | H1: Change in CE | I1: Incremental ROCE (Historical) | J1: Change in EBIT (Forecast) | K1: Capex | L1: Depreciation | M1: Effective capital | N1: Raw ROCE | O1: Adjusted ROCE (Forecast) | Q1: Particulars | R1: 2020 | S1: 2021 | T1: 2022 | U1: 2023 | V1: 2024 | Z1: Company | AA1: WACC | AB1: Terminal growth | AC1: Cost of equity | AD1: Intrinsic value | AE1: Share price | AF1: Upside/Downside
A2: 2020-24 | B2: Avg Capex | C2: =Relative!A23 -> P&G | D2: =AVERAGE(Financials!B27:F27) -> 3080 | F2: =C2 -> P&G | G2: =Financials!F6-Financials!B6 -> 2839 | H2: =(122370-33627)-(120700-32976) -> 1019 | I2: =G2/H2 -> 2.7860648 | J2: =DCF!G4-DCF!B4 -> 3595.8907 | K2: =D8 -> 3710.8509 | L2: =AVERAGE(DCF!B6:G6) -> 3413.2599 | M2: =IF(K2-L2<=0,K2,MAX(K2-L2,0.1*K2)) -> 371.08509 | N2: =J2/M2 -> 9.6902054 | O2: =MIN(MAX(N2,0.15),0.35) -> 0.35 | Q2: Revenue | R2: {=Table1[[#This Row],[2020]:[2024]]} -> #VALUE! | Z2: P&G | AA2: ='Assumptions & WACC'!B21 -> 0.055232043 | AB2: ='Assumptions & WACC'!$B$25 -> 0.02 | AC2: ='Assumptions & WACC'!B12 -> 0.0590748 | AD2: =DCF!B20 -> 184.76348 | AE2: =DCF!B21 -> 147.35 | AF2: =(AD2-AE2)/AE2 -> 0.25390896
A3: 2020-24 | B3: Avg Capex | C3: =Relative!A24 -> PepsiCo | D3: =AVERAGE(Financials!I27:M27) -> 4981.6 | F3: =C3 -> PepsiCo | G3: =Financials!M6-Financials!I6 -> 2807 | H3: =(99467-31536)-(92918-23372) -> -1615 | I3: =G3/H3 -> -1.7380805 | J3: =DCF!O4-DCF!J4 -> 4062.0134 | K3: =D9 -> 6598.191 | L3: =AVERAGE(DCF!J6:O6) -> 3742.8072 | M3: =IF(K3-L3<=0,K3,MAX(K3-L3,0.1*K3)) -> 2855.3839 | N3: =J3/M3 -> 1.4225805 | O3: =MIN(MAX(N3,0.15),0.35) -> 0.35 | Q3: Operating income | R3: {=Financials!B6:F6} -> 15706 | S3: 17986 | T3: 17813 | U3: 18134 | V3: 18545 | Z3: PepsiCo | AA3: ='Assumptions & WACC'!C21 -> 0.05325366 | AB3: ='Assumptions & WACC'!$B$25 -> 0.02 | AC3: ='Assumptions & WACC'!C12 -> 0.060414 | AD3: =DCF!J20 -> 177.704 | AE3: =DCF!J21 -> 147.815 | AF3: =(AD3-AE3)/AE3 -> 0.20220544
A4: 2020-24 | B4: Avg Capex | C4: Coca-Cola | D4: =AVERAGE(Financials!P27:T27) -> 1588.8 | F4: =C4 -> Coca-Cola | G4: =Financials!T6-Financials!P6 -> 3556 | H4: =((Financials!T15-Financials!T20)-(Financials!P15-Financials!P20)) -> 2605 | I4: =G4/H4 -> 1.3650672 | J4: =Table927[[#This Row],[2030]]-Table927[[#This Row],[2025]] -> 6940.6726 | K4: =D10 -> 2326.2722 | L4: =AVERAGE(DCF!R6:W6) -> 1889.0712 | M4: =IF(K4-L4<=0,K4,MAX(K4-L4,0.1*K4)) -> 437.20095 | N4: =J4/M4 -> 15.875246 | O4: =MIN(MAX(N4,0.15),0.35) -> 0.35 | Q4: Net Income | R4: {=Financials!B10:F10} -> 9497 | S4: 11486 | T4: 11365 | U4: 11049 | V4: 10937
A5: 2020-24 | B5: Avg Capex | C5: Colgate | D5: =AVERAGE(Financials!X27:AB27) -> 587.8 | F5: =C5 -> Colgate | G5: =Financials!AB6-Financials!X6 -> 303 | H5: =(Financials!AB15-Financials!AB20)-(Financials!X15-Financials!X20) -> -1229 | I5: =G5/H5 -> -0.2465419 | J5: =DCF!AE4-DCF!Z4 -> 885.98004 | K5: =D11 -> 744.63445 | L5: =AVERAGE(DCF!Z6:AE6) -> 712.45732 | M5: =IF(K5-L5<=0,K5,MAX(K5-L5,0.1*K5)) -> 74.463445 | N5: =J5/M5 -> 11.898188 | O5: =MIN(MAX(N5,0.15),0.35) -> 0.35 | Q5: Capex | R5: {=Financials!B27:F27} -> 3073 | S5: 2787 | T5: 3156 | U5: 3062 | V5: 3322
A6: 2020-24 | B6: Avg Capex | C6: Walmart | D6: =AVERAGE(Financials!AF27:AJ27) -> 16923.2 | F6: =C6 -> Walmart | G6: =Table181114[[#This Row],[2024]]-Table181114[[#This Row],[2020]] -> 5796 | H6: =(Financials!AJ15-Financials!AJ20)-(Financials!AF15-Financials!AF20) -> 4388 | I6: =G6/H6 -> 1.3208751 | J6: =DCF!AM4-DCF!AH4 -> 5763.281 | K6: =D12 -> 21579.217 | L6: =AVERAGE(Table92731[[#This Row],[2025]:[2030]]) -> 14684.609 | M6: =IF(K6-L6<=0,K6,MAX(K6-L6,0.1*K6)) -> 6894.6076 | N6: =J6/M6 -> 0.83591139 | O6: =MIN(MAX(N6,0.15),0.35) -> 0.35
A7: 2020-24 | B7: Avg Capex | C7: Average | D7: =AVERAGE(D2:D6) -> 5432.28 | F7: Average | H7: Average | I7: =AVERAGE(I2:I6) -> 0.69747693 | M7: Average | N7: =AVERAGE(N2:N6) -> 7.9444262 | O7: =AVERAGE(O2:O6) -> 0.35 | Q7: Particulars | R7: 2020 | S7: 2021 | T7: 2022 | U7: 2023 | V7: 2024
A8: 2025-30 | B8: Avg Capex | C8: =C2 -> P&G | D8: =AVERAGE(DCF!B7:G7) -> 3710.8509 | Q8: Revenue | R8: {=Financials!I3:M3} -> 70372 | S8: 79474 | T8: 86392 | U8: 91471 | V8: 91854
A9: 2025-30 | B9: Avg Capex | C9: =C3 -> PepsiCo | D9: =AVERAGE(DCF!J7:O7) -> 6598.191 | Q9: Operating income | R9: {=Financials!I6:M6} -> 10080 | S9: 11162 | T9: 11512 | U9: 11986 | V9: 12887
A10: 2025-30 | B10: Avg Capex | C10: =C4 -> Coca-Cola | D10: =AVERAGE(DCF!R7:W7) -> 2326.2722 | Q10: Net Income | R10: {=Financials!I10:M10} -> 4510 | S10: 4447 | T10: 6083 | U10: 5957 | V10: 6488
A11: 2025-30 | B11: Avg Capex | C11: =C5 -> Colgate | D11: =AVERAGE(DCF!Z7:AE7) -> 744.63445 | Q11: Capex | R11: {=Financials!I27:M27} -> 4240 | S11: 4625 | T11: 5207 | U11: 5518 | V11: 5318
A12: 2025-30 | B12: Avg Capex | C12: =C6 -> Walmart | D12: =AVERAGE(DCF!AH7:AM7) -> 21579.217
B13: Avg Capex | C13: =C7 -> Average | D13: =AVERAGE(D8:D12) -> 6991.833
A14: 2025-30 | B14: Capex CAGR | C14: =C8 -> P&G | D14: =(DCF!G7/DCF!B7)^(1/6)-1 -> 0.028619483 | Q14: Particulars | R14: 2025 | S14: 2026 | T14: 2027 | U14: 2028 | V14: 2029 | W14: 2030
A15: 2025-30 | B15: Capex CAGR | C15: =C9 -> PepsiCo | D15: =(DCF!O7/DCF!J7)^(1/6)-1 -> 0.045401286 | Q15: Revenue | R15: {=DCF!B3:G3} -> 86933.381 | S15: 89927.447 | T15: 93024.632 | U15: 96228.487 | V15: 99542.685 | W15: 102971.03
A16: 2025-30 | B16: Capex CAGR | C16: =C10 -> Coca-Cola | D16: =(DCF!W7/DCF!R7)^(1/6)-1 -> 0.060865927 | J16: Metric | K16: 2020-24 | L16: 2025-30 | Q16: Operating income | R16: {=DCF!B4:G4} -> 19491.821 | S16: 20163.138 | T16: 20857.575 | U16: 21575.929 | V16: 22319.024 | W16: 23087.712
A17: 2025-30 | B17: Capex CAGR | C17: =C11 -> Colgate | D17: =(DCF!AE7/DCF!Z7)^(1/6)-1 -> 0.033751809 | J17: GDP | K17: =AVERAGE(-0.035,0.058) -> 0.0115 | L17: 0.021 | Q17: Net income | R17: {=DCF!B5:G5} -> 15008.702 | S17: 15525.616 | T17: 16060.333 | U17: 16613.465 | V17: 17185.649 | W17: 17777.538
A18: 2025-30 | B18: Capex CAGR | C18: =C12 -> Walmart | D18: =(DCF!AM7/DCF!AH7)^(1/6)-1 -> 0.033399087 | J18: GDP | K18: 0.028 | L18: 0.025 | Q18: Capex | R18: {=DCF!B7:G7} -> 3403.9514 | S18: 3521.1866 | T18: 3642.4595 | U18: 3767.9092 | V18: 3897.6795 | W18: 4031.9192
A19: 2025-30 | B19: Capex CAGR | C19: =C13 -> Average | D19: =AVERAGE(D14:D18) -> 0.040407518 | J19: Change | K19: =K18-K17 -> 0.0165 | L19: =L18-L17 -> 0.004 | Q19: FCFF | R19: {=DCF!B9:G9} -> 16534.423 | S19: 15612.328 | T19: 16150.031 | U19: 16706.253 | V19: 17281.632 | W19: 17876.828
A20: =A14 -> 2025-30 | B20: Earnings CAGR | C20: =C14 -> P&G | D20: =D14 -> 0.028619483 | J20: Sensitivity | K20: =D61/K19 -> 35.570612 | L20: =D67/L19 -> 67.675502
A21: =A15 -> 2025-30 | B21: Earnings CAGR | C21: =C15 -> PepsiCo | D21: =D15 -> 0.045401286 | Q21: Particulars | R21: 2025 | S21: 2026 | T21: 2027 | U21: 2028 | V21: 2029 | W21: 2030
A22: =A16 -> 2025-30 | B22: Earnings CAGR | C22: =C16 -> Coca-Cola | D22: =D16 -> 0.060865927 | Q22: Revenue | R22: {=DCF!J3:O3} -> 96880.798 | S22: 102182.69 | T22: 107774.74 | U22: 113672.82 | V22: 119893.67 | W22: 126454.97
A23: =A17 -> 2025-30 | B23: Earnings CAGR | C23: =C17 -> Colgate | D23: =D17 -> 0.033751809 | Q23: Operating income | R23: {=DCF!J4:O4} -> 13306.583 | S23: 14034.798 | T23: 14802.866 | U23: 15612.967 | V23: 16467.402 | W23: 17368.596
A24: =A18 -> 2025-30 | B24: Earnings CAGR | C24: =C18 -> Walmart | D24: =D18 -> 0.033399087 | Q24: Net income | R24: {=DCF!J5:O5} -> 10246.069 | S24: 10806.795 | T24: 11398.207 | U24: 12021.985 | V24: 12679.899 | W24: 13373.819
A25: =A19 -> 2025-30 | B25: Earnings CAGR | C25: =C19 -> Average | D25: =AVERAGE(D20:D24) -> 0.040407518 | Q25: Capex | R25: {=DCF!J7:O7} -> 5751.477 | S25: 6066.2321 | T25: 6398.2124 | U25: 6748.3608 | V25: 7117.6713 | W25: 7507.1927
A26: =A20 -> 2025-30 | B26: Revenue CAGR | C26: =C20 -> P&G | D26: =(DCF!G3/DCF!B3)^(1/6)-1 -> 0.028619483 | Q26: FCFF | R26: {=DCF!J9:O9} -> 6771.7279 | S26: 8440.1771 | T26: 8902.0739 | U26: 9389.2484 | V26: 9903.0841 | W26: 10445.04
A27: =A21 -> 2025-30 | B27: Revenue CAGR | C27: =C21 -> PepsiCo | D27: =D21 -> 0.045401286
A28: =A22 -> 2025-30 | B28: Revenue CAGR | C28: =C22 -> Coca-Cola | D28: =D22 -> 0.060865927
A29: =A23 -> 2025-30 | B29: Revenue CAGR | C29: =C23 -> Colgate | D29: =D23 -> 0.033751809
A30: =A24 -> 2025-30 | B30: Revenue CAGR | C30: =C24 -> Walmart | D30: =D24 -> 0.033399087
A31: =A25 -> 2025-30 | B31: Revenue CAGR | C31: =C25 -> Average | D31: =AVERAGE(D26:D30) -> 0.040407518
A32: =A2 -> 2020-24 | B32: EBITDA Margin | C32: =C26 -> P&G | D32: =(AVERAGE(Financials!B6:F6)+AVERAGE(Financials!B7:F7))/AVERAGE(Financials!B3:F3) -> 0.26023138
A33: =A3 -> 2020-24 | B33: EBITDA Margin | C33: =C27 -> PepsiCo | D33: =(AVERAGE(Financials!I6:M6)+AVERAGE(Financials!I7:M7))/AVERAGE(Financials!I3:M3) -> 0.17102557
A34: =A4 -> 2020-24 | B34: EBITDA Margin | C34: =C28 -> Coca-Cola | D34: =(AVERAGE(Financials!P6:T6)+AVERAGE(Financials!P7:T7))/AVERAGE(Financials!P3:T3) -> 0.35398674
A35: =A5 -> 2020-24 | B35: EBITDA Margin | C35: =C29 -> Colgate | D35: =(AVERAGE(Financials!X6:AB6)+AVERAGE(Financials!X7:AB7))/AVERAGE(Financials!X3:AB3) -> 0.2229454
A36: =A6 -> 2020-24 | B36: EBITDA Margin | C36: =C30 -> Walmart | D36: =(AVERAGE(Financials!AF6:AJ6)+AVERAGE(Financials!AF7:AJ7))/AVERAGE(Financials!AF3:AJ3) -> 0.05608169
A37: =$A$36 -> 2020-24 | B37: EBITDA Margin | C37: =C31 -> Average | D37: =AVERAGE(D32:D36) -> 0.21285415
A38: =$A$36 -> 2020-24 | B38: NPM | C38: =C32 -> P&G | D38: =AVERAGE(Financials!B10:F10)/AVERAGE(Financials!B3:F3) -> 0.138149
A39: =$A$36 -> 2020-24 | B39: NPM | C39: =C33 -> PepsiCo | D39: =AVERAGE(Financials!I10:M10)/AVERAGE(Financials!I3:M3) -> 0.065508636
A40: =A32 -> 2020-24 | B40: NPM | C40: =C34 -> Coca-Cola | D40: =AVERAGE(Financials!P10:T10)/AVERAGE(Financials!P3:T3) -> 0.20263341
...
