Workbook

Sheet Company Profile
A1: Company | B1: #VALUE! | C1: #VALUE! | D1: #VALUE! | E1: #VALUE! | F1: #VALUE! | G1: #VALUE!
A2: Official name | B2: {=_FV(B1,"Official name",TRUE)} -> NUCOR CORPORATION | C2: {=_FV(C1,"Official name",TRUE)} -> FREEPORT-MCMORAN INC. | D2: {=_FV(D1,"Official name",TRUE)} -> ALCOA CORPORATION | E2: {=_FV(E1,"Official name",TRUE)} -> RF INDUSTRIES, LTD. | F2: {=_FV(F1,"Official name",TRUE)} -> Dow Inc. | G2: {=_FV(G1,"Official name",TRUE)} -> NEWMONT CORPORATION
A3: Share price | B3: {=_FV(B1,"Price")} -> 148.58 | C3: {=_FV(C1,"Price")} -> 41.24 | D3: {=_FV(D1,"Price")} -> 36.72 | E3: {=_FV(E1,"Price")} -> 6.09 | F3: {=_FV(F1,"Price")} -> 21.315 | G3: {=_FV(G1,"Price")} -> 87.42
A4: Change (%) | B4: {=_FV(B1,"Change (%)",TRUE)} -> 0.0004713 | C4: {=_FV(C1,"Change (%)",TRUE)} -> 0.031 | D4: {=_FV(D1,"Change (%)",TRUE)} -> 0.004651 | E4: {=_FV(E1,"Change (%)",TRUE)} -> -0.036392 | F4: {=_FV(F1,"Change (%)",TRUE)} -> -0.024485 | G4: {=_FV(G1,"Change (%)",TRUE)} -> 0.009469
A5: Outstanding shares | B5: {=_FV(B1,"Shares outstanding",TRUE)} -> 228858700 | C5: {=_FV(C1,"Shares outstanding",TRUE)} -> 1435931000 | D5: {=_FV(D1,"Shares outstanding",TRUE)} -> 258964000 | E5: {=_FV(E1,"Shares outstanding",TRUE)} -> 10667450 | F5: {=_FV(F1,"Shares outstanding",TRUE)} -> 710767400 | G5: {=_FV(G1,"Shares outstanding",TRUE)} -> 1091263000
A6: in mn | B6: =B5/1000000 -> 228.8587 | C6: =C5/1000000 -> 1435.931 | D6: =D5/1000000 -> 258.964 | E6: =E5/1000000 -> 10.66745 | F6: =F5/1000000 -> 710.7674 | G6: =G5/1000000 -> 1091.263
A7: Market cap | B7: {=_FV(B1,"Market cap",TRUE)} -> 34003825646 | C7: {=_FV(C1,"Market cap",TRUE)} -> 59217794440 | D7: {=_FV(D1,"Market cap",TRUE)} -> 9509158080 | E7: {=_FV(E1,"Market cap",TRUE)} -> 64964770 | F7: {=_FV(F1,"Market cap",TRUE)} -> 15150007131 | G7: {=_FV(G1,"Market cap",TRUE)} -> 95398211460
A8: in mn | B8: =B7/1000000 -> 34003.826 | C8: =C7/1000000 -> 59217.794 | D8: =D7/1000000 -> 9509.1581 | E8: =E7/1000000 -> 64.96477 | F8: =F7/1000000 -> 15150.007 | G8: =G7/1000000 -> 95398.211
A9: Beta | B9: {=_FV(B1,"Beta")} -> 1.8567 | C9: {=_FV(C1,"Beta")} -> 1.4877 | D9: {=_FV(D1,"Beta")} -> 1.9931 | E9: {=_FV(E1,"Beta")} -> 0.991 | F9: {=_FV(F1,"Beta")} -> 0.7998 | G9: {=_FV(G1,"Beta")} -> 0.4175
A10: P/E | B10: {=_FV(B1,"P/E",TRUE)} -> 20.8826 | C10: {=_FV(C1,"P/E",TRUE)} -> 28.7287 | D10: {=_FV(D1,"P/E",TRUE)} -> 8.3652 | E10: {=_FV(E1,"P/E",TRUE)} -> 0 | G10: {=_FV(G1,"P/E",TRUE)} -> 13.4576
A11: Year | B11: {=_FV(B1,"Year incorporated",TRUE)} -> 1958 | C11: {=_FV(C1,"Year incorporated",TRUE)} -> 1987 | D11: {=_FV(D1,"Year incorporated",TRUE)} -> 2016 | E11: {=_FV(E1,"Year incorporated",TRUE)} -> 1979 | F11: {=_FV(F1,"Year incorporated",TRUE)} -> 2018 | G11: {=_FV(G1,"Year incorporated",TRUE)} -> 2001

Sheet Financials
A1: INCOME STATEMENT | F1: Nucor | H1: INCOME STATEMENT | M1: Freeport | O1: INCOME STATEMENT | T1: Alcoa | W1: INCOME STATEMENT | AB1: RF Ind | AE1: INCOME STATEMENT | AJ1: Dow | AM1: INCOME STATEMENT | AR1: Newmont
A2: Particulars | B2: 2020 | C2: 2021 | D2: 2022 | E2: 2023 | F2: 2024 | H2: Particulars | I2: 2020 | J2: 2021 | K2: 2022 | L2: 2023 | M2: 2024 | O2: Particulars | P2: 2020 | Q2: 2021 | R2: 2022 | S2: 2023 | T2: 2024 | W2: Particulars | X2: 2020 | Y2: 2021 | Z2: 2022 | AA2: 2023 | AB2: 2024 | AE2: Particulars | AF2: 2020 | AG2: 2021 | AH2: 2022 | AI2: 2023 | AJ2: 2024 | AM2: Particulars | AN2: 2020 | AO2: 2021 | AP2: 2022 | AQ2: 2023 | AR2: 2024 | AU2: Particulars | AV2: 2020 | AW2: 2021 | AX2: 2022 | AY2: 2023 | AZ2: 2024 | BC2: Company | BD2: WACC | BE2: Terminal growth | BF2: Cost of equity | BG2: Intrinsic value | BH2: Share price | BI2: Upside/Downside
A3: Revenue | B3: 20139.658 | C3: 36483.939 | D3: 41512.467 | E3: 34714 | F3: 30734 | H3: Revenue | I3: 14198 | J3: 22845 | K3: 22780 | L3: 22855 | M3: 25455 | O3: Revenue | P3: 9286 | Q3: 12152 | R3: 12451 | S3: 10551 | T3: 11895 | W3: Revenue | X3: 4124 | Y3: 6538 | Z3: 11186 | AA3: 6631 | AB3: 5936 | AE3: Revenue | AF3: 38542 | AG3: 54968 | AH3: 56902 | AI3: 44622 | AJ3: 42964 | AM3: Revenue | AN3: 11497 | AO3: 12222 | AP3: 11915 | AQ3: 11812 | AR3: 18682 | AU3: Revenue | AV3: {=Table1[[#This Row],[2020]:[2024]]} -> 20139.658 | AW3: 36483.939 | AX3: 41512.467 | AY3: 34714 | AZ3: 30734 | BC3: Nucor | BD3: ='Assumptions & WACC'!B21 -> 0.11326748 | BE3: ='Assumptions & WACC'!$B$25 -> 0.02 | BF3: ='Assumptions & WACC'!B12 -> 0.1305076 | BG3: =DCF!B20 -> 155.77963 | BH3: =DCF!B21 -> 148.58 | BI3: =(BG3-BH3)/BH3 -> 0.048456237
A4: Cost of sales | B4: 17911.708 | C4: 25458.525 | D4: 29009.187 | E4: 26899 | F4: 26632 | H4: Cost of sales | I4: =11655-1528 -> 10127 | J4: =14030-1998 -> 12032 | K4: =15089-2019 -> 13070 | L4: 13627 | M4: 15554 | O4: Cost of sales | P4: 7969 | Q4: 9153 | R4: 10212 | S4: 9813 | T4: 10044 | W4: Cost of sales | X4: 3323 | Y4: 4151 | Z4: 5325 | AA4: 4086 | AB4: 3880 | AE4: Cost of sales | AF4: 33346 | AG4: 44191 | AH4: 48338 | AI4: 39742 | AJ4: 38358 | AM4: Cost of sales | AN4: 5014 | AO4: 5435 | AP4: 6468 | AQ4: 6699 | AR4: 8963 | AU4: Operating income | AV4: {=B6:F6} -> 988.736 | AW4: 9359.712 | AX4: 10415.06 | AY4: 6243 | AZ4: 2872 | BC4: Freeport | BD4: ='Assumptions & WACC'!C21 -> 0.10343434 | BE4: ='Assumptions & WACC'!$B$25 -> 0.02 | BF4: ='Assumptions & WACC'!C12 -> 0.1127956 | BG4: =DCF!J20 -> 59.683858 | BH4: =DCF!J21 -> 41.24 | BI4: =(BG4-BH4)/BH4 -> 0.44723226
A5: Opex | B5: =615.041+10.533+613.64 -> 1239.214 | C5: =1706.609-103.068+62.161 -> 1665.702 | D5: =1997.178-10.714+101.756 -> 2088.22 | E5: =1585-13 -> 1572 | F5: =1123-30+137 -> 1230 | H5: Opex | I5: =370+50+159-473 -> 106 | J5: =383+55+91-80 -> 449 | K5: =420+115+121-2 -> 654 | L5: =479+137+319 -> 935 | M5: =513+156+127 -> 796 | O5: Opex | P5: =206+27+104+8 -> 345 | Q5: =227+31+1128-445 -> 941 | R5: =204+32+696-118 -> 814 | S5: =226+39+184+134 -> 583 | T5: =275+57+341+91 -> 764 | W5: Opex | X5: 189 | Y5: 705 | Z5: 558 | AA5: 307 | AB5: 314 | AE5: Opex | AF5: =768+1471+708+239-18+1269+38 -> 4475 | AG5: =857+1645+6+975+55-35 -> 3503 | AH5: =851+1675+118+268+727+173 -> 3812 | AI5: =829+1627+528-119+280+229 -> 3374 | AJ5: =810+1581+103-6-415+200 -> 2273 | AM5: Opex | AN5: =366+187+122+269+178+49+206 -> 1377 | AO5: =1846+209+154+259+25+571+143 -> 3207 | AP5: =921+231+229+276+1320+82 -> 3059 | AQ5: =1533+265+200+299+1891+517 -> 4705 | AR5: =328+266+197+442+78+1114+191 -> 2616 | AU5: Net income | AV5: {=B10:F10} -> 50.562 | AW5: 6257.807 | AX5: 7018.006 | AY5: 3684 | AZ5: 903
A6: Operating income (EBIT) | B6: =B3-B4-B5 -> 988.736 | C6: =C3-C4-C5 -> 9359.712 | D6: =D3-D4-D5 -> 10415.06 | E6: =E3-E4-E5 -> 6243 | F6: =F3-F4-F5 -> 2872 | H6: Operating income (EBIT) | I6: =I3-I4-I5 -> 3965 | J6: =J3-J4-J5 -> 10364 | K6: =K3-K4-K5 -> 9056 | L6: =L3-L4-L5 -> 8293 | M6: =M3-M4-M5 -> 9105 | O6: Operating income (EBIT) | P6: =P3-P4-P5 -> 972 | Q6: =Q3-Q4-Q5 -> 2058 | R6: =R3-R4-R5 -> 1425 | S6: =S3-S4-S5 -> 155 | T6: =T3-T4-T5 -> 1087 | W6: Operating income (EBIT) | X6: =X3-X4-X5 -> 612 | Y6: =Y3-Y4-Y5 -> 1682 | Z6: =Z3-Z4-Z5 -> 5303 | AA6: =AA3-AA4-AA5 -> 2238 | AB6: =AB3-AB4-AB5 -> 1742 | AE6: Operating income (EBIT) | AF6: =AF3-AF4-AF5 -> 721 | AG6: =AG3-AG4-AG5 -> 7274 | AH6: =AH3-AH4-AH5 -> 4752 | AI6: =AI3-AI4-AI5 -> 1506 | AJ6: =AJ3-AJ4-AJ5 -> 2333 | AM6: Operating income (EBIT) | AN6: =AN3-AN4-AN5 -> 5106 | AO6: =AO3-AO4-AO5 -> 3580 | AP6: =AP3-AP4-AP5 -> 2388 | AQ6: =AQ3-AQ4-AQ5 -> 408 | AR6: =AR3-AR4-AR5 -> 7103 | AU6: Capex | AV6: {=B27:F27} -> 1543.219 | AW6: 1621.989 | AX6: 1947.897 | AY6: 2214 | AZ6: 3173
A7: Depreciation & Amortization | B7: =702.11+83.356 -> 785.466 | C7: =735.406+129.157 -> 864.563 | D7: =826.692+234.942 -> 1061.634 | E7: =931+238 -> 1169 | F7: =1094+262 -> 1356 | H7: Depreciation & Amortization | I7: 1528 | J7: 1998 | K7: 2019 | L7: 2068 | M7: 2241 | O7: Depreciation & Amortization | P7: 653 | Q7: 664 | R7: 617 | S7: 632 | T7: 642 | W7: Depreciation & Amortization | X7: 892 | Y7: 888 | Z7: 850 | AA7: 869 | AB7: 925 | AE7: Depreciation & Amortization | AF7: 401 | AG7: 388 | AH7: 336 | AI7: 324 | AJ7: 310 | AM7: Depreciation & Amortization | AN7: 2300 | AO7: 2323 | AP7: 2185 | AQ7: 2108 | AR7: 2576 | BF7: =(DCF!G5-DCF!B5)/DCF!B5 -> 0.52604379
A8: Interest expense | B8: 153.198 | C8: 158.854 | D8: 170.216 | E8: 30 | F8: 30 | H8: Interest expense | I8: 598 | J8: 602 | K8: 560 | L8: 515 | M8: 319 | O8: Interest expense | P8: 146 | Q8: 195 | R8: 106 | S8: 107 | T8: 156 | W8: Interest expense | X8: 179 | Y8: 184 | Z8: 344 | AA8: 150 | AB8: 121 | AE8: Interest expense | AF8: 827 | AG8: 731 | AH8: 662 | AI8: 746 | AJ8: 811 | AM8: Interest expense | AN8: 308 | AO8: 274 | AP8: 227 | AQ8: 243 | AR8: 375 | AU8: Particulars | AV8: 2020 | AW8: 2021 | AX8: 2022 | AY8: 2023 | AZ8: 2024 | BF8: =(DCF!O5-DCF!J5)/DCF!J5 -> 0.79285815
A9: Income tax | B9: -0.49 | C9: 2078.488 | D9: 2165.204 | E9: 1360 | F9: 583 | H9: Income tax | I9: 944 | J9: 2299 | K9: 2267 | L9: 2270 | M9: 2523 | O9: Income tax | P9: 187 | Q9: 629 | R9: 664 | S9: 189 | T9: 265 | W9: Income tax | X9: 31 | Y9: 283 | Z9: 1158 | AA9: 410 | AB9: 285 | AE9: Income tax | AF9: 777 | AG9: 1740 | AH9: 1450 | AI9: -4 | AJ9: 399 | AM9: Income tax | AN9: 704 | AO9: 1098 | AP9: 455 | AQ9: 526 | AR9: 1397 | AU9: Revenue | AV9: {=I3:M3} -> 14198 | AW9: 22845 | AX9: 22780 | AY9: 22855 | AZ9: 25455 | BF9: =AVERAGE(BF7:BF8) -> 0.65945097
A10: Net income | B10: =B6-B7-B8-B9 -> 50.562 | C10: =C6-C7-C8-C9 -> 6257.807 | D10: =D6-D7-D8-D9 -> 7018.006 | E10: =E6-E7-E8-E9 -> 3684 | F10: =F6-F7-F8-F9 -> 903 | H10: Net income | I10: =I6-I7-I8-I9 -> 895 | J10: =J6-J7-J8-J9 -> 5465 | K10: =K6-K7-K8-K9 -> 4210 | L10: =L6-L7-L8-L9 -> 3440 | M10: =M6-M7-M8-M9 -> 4022 | O10: Net income | P10: =P6-P7-P8-P9 -> -14 | Q10: =Q6-Q7-Q8-Q9 -> 570 | R10: =R6-R7-R8-R9 -> 38 | S10: =S6-S7-S8-S9 -> -773 | T10: =T6-T7-T8-T9 -> 24 | W10: Net income | X10: =X6-X7-X8-X9 -> -490 | Y10: =Y6-Y7-Y8-Y9 -> 327 | Z10: =Z6-Z7-Z8-Z9 -> 2951 | AA10: =AA6-AA7-AA8-AA9 -> 809 | AB10: =AB6-AB7-AB8-AB9 -> 411 | AE10: Net income | AF10: =AF6-AF7-AF8-AF9 -> -1284 | AG10: =AG6-AG7-AG8-AG9 -> 4415 | AH10: =AH6-AH7-AH8-AH9 -> 2304 | AI10: =AI6-AI7-AI8-AI9 -> 440 | AJ10: =AJ6-AJ7-AJ8-AJ9 -> 813 | AM10: Net income | AN10: =AN6-AN7-AN8-AN9 -> 1794 | AO10: =AO6-AO7-AO8-AO9 -> -115 | AP10: =AP6-AP7-AP8-AP9 -> -479 | AQ10: =AQ6-AQ7-AQ8-AQ9 -> -2469 | AR10: =AR6-AR7-AR8-AR9 -> 2755 | AU10: Operating income | AV10: {=I6:M6} -> 3965 | AW10: 10364 | AX10: 9056 | AY10: 8293 | AZ10: 9105
AU11: Net income | AV11: {=I10:M10} -> 895 | AW11: 5465 | AX11: 4210 | AY11: 3440 | AZ11: 4022
A12: BALANCE SHEET | H12: BALANCE SHEET | O12: BALANCE SHEET | W12: BALANCE SHEET | AE12: BALANCE SHEET | AM12: BALANCE SHEET | AU12: Capex | AV12: {=I27:M27} -> 1961 | AW12: 2115 | AX12: 3469 | AY12: 4824 | AZ12: 4808
A13: Particulars | B13: 2020 | C13: 2021 | D13: 2022 | E13: 2023 | F13: 2024 | H13: Particulars | I13: 2020 | J13: 2021 | K13: 2022 | L13: 2023 | M13: 2024 | O13: Particulars | P13: 2020 | Q13: 2021 | R13: 2022 | S13: 2023 | T13: 2024 | W13: Particulars | X13: 2020 | Y13: 2021 | Z13: 2022 | AA13: 2023 | AB13: 2024 | AE13: Particulars | AF13: 2020 | AG13: 2021 | AH13: 2022 | AI13: 2023 | AJ13: 2024 | AM13: Particulars | AN13: 2020 | AO13: 2021 | AP13: 2022 | AQ13: 2023 | AR13: 2024
A14: Cash & Cash equivalents | B14: 2639.671 | C14: 2364.858 | D14: 4280.852 | E14: 6383 | F14: 3558 | H14: Cash & Cash equivalents | I14: 3657 | J14: 8068 | K14: 8146 | L14: 4758 | M14: 3923 | O14: Cash & Cash equivalents | P14: 1607 | Q14: 1814 | R14: 1363 | S14: 944 | T14: 1138 | W14: Cash & Cash equivalents | X14: 683 | Y14: 1628 | Z14: 2323 | AA14: 2032 | AB14: 1614 | AE14: Cash & Cash equivalents | AF14: 5104 | AG14: 2988 | AH14: 3886 | AI14: 2987 | AJ14: 2189 | AM14: Cash & Cash equivalents | AN14: 5540 | AO14: 4992 | AP14: 2877 | AQ14: 3002 | AR14: 3619 | AU14: Particulars | AV14: 2025 | AW14: 2026 | AX14: 2027 | AY14: 2028 | AZ14: 2029 | BA14: 2030
A15: Accounts receivables | B15: 2298.85 | C15: 3853.972 | D15: 3591.03 | E15: 2953 | F15: 2675 | H15: Accounts receivables | I15: 892 | J15: 1168 | K15: 1336 | L15: 1209 | M15: 578 | O15: Accounts receivables | P15: 471 | Q15: 757 | R15: 778 | S15: 656 | T15: 1096 | W15: Accounts receivables | X15: 265 | Y15: 497 | Z15: 582 | AA15: 505 | AB15: 404 | AE15: Accounts receivables | AF15: =4839+2551 -> 7390 | AG15: =6841+2713 -> 9554 | AH15: =5611+2144 -> 7755 | AI15: =4718+1896 -> 6614 | AJ15: =4756+2108 -> 6864 | AM15: Accounts receivables | AN15: 449 | AO15: 337 | AP15: 366 | AQ15: 734 | AR15: 1056 | AU15: Revenue | AV15: {=DCF!B3:G3} -> 33445.099 | AW15: 36395.349 | AX15: 39605.845 | AY15: 43099.545 | AZ15: 46901.43 | BA15: 51038.686
A16: Inventories | B16: 3569.089 | C16: 6011.182 | D16: 5453.531 | E16: 5578 | F16: 5106 | H16: Inventories | I16: =1594+1014+1285 -> 3893 | J16: =1669+1170+1658 -> 4497 | K16: =1964+1383+1833 -> 5180 | L16: =2472+2169+1419 -> 6060 | M16: =3038+2382+1388 -> 6808 | O16: Inventories | P16: 1398 | Q16: 1956 | R16: 2427 | S16: 2158 | T16: 1998 | W16: Inventories | X16: 287 | Y16: 408 | Z16: 474 | AA16: 299 | AB16: 314 | AE16: Inventories | AF16: 5701 | AG16: 7372 | AH16: 6988 | AI16: 6076 | AJ16: 6544 | AM16: Inventories | AN16: 963 | AO16: 930 | AP16: 979 | AQ16: 1663 | AR16: 1423 | AU16: Operating income | AV16: {=DCF!B4:G4} -> 6108.7225 | AW16: 6647.5835 | AX16: 7233.9782 | AY16: 7872.0999 | AZ16: 8566.5114 | BA16: 9322.1781
A17: Total current assets | B17: 9488.662 | C17: 12799.557 | D17: 14691.684 | E17: 16386 | F17: 12475 | H17: Total current assets | I17: 9303 | J17: 14830 | K17: 15613 | L17: 14065 | M17: 13296 | O17: Total current assets | P17: 4520 | Q17: 5026 | R17: 5250 | S17: 4405 | T17: 4914 | W17: Total current assets | X17: 1367 | Y17: 2593 | Z17: 3673 | AA17: 3050 | AB17: 2520 | AE17: Total current assets | AF17: 19084 | AG17: 20848 | AH17: 20477 | AI17: 17614 | AJ17: 16590 | AM17: Total current assets | AN17: 8505 | AO17: 7696 | AP17: 6515 | AQ17: 7512 | AR17: 12275 | AU17: Net income | AV17: {=DCF!B5:G5} -> 4703.7164 | AW17: 5118.6393 | AX17: 5570.1632 | AY17: 6061.5169 | AZ17: 6596.2138 | BA17: 7178.0771
A18: PPE | B18: 6899.11 | C18: 8114.818 | D18: 9616.92 | E18: 11050 | F18: 13243 | H18: PPE | I18: 29818 | J18: 30345 | K18: 32627 | L18: 35295 | M18: 38514 | O18: PPE | P18: 7190 | Q18: 6623 | R18: 6493 | S18: 6785 | T18: 6389 | W18: PPE | X18: 7632 | Y18: 7081 | Z18: 6437 | AA18: 7141 | AB18: 6735 | AE18: PPE | AF18: 20239 | AG18: 20555 | AH18: 20442 | AI18: 21066 | AJ18: 22004 | AM18: PPE | AN18: 24281 | AO18: 24124 | AP18: 24073 | AQ18: 37563 | AR18: 33547 | AU18: Capex | AV18: {=DCF!B7:G7} -> 2146.7681 | AW18: 2336.1382 | AX18: 2542.213 | AY18: 2766.466 | AZ18: 3010.5007 | BA18: 3276.0621
A19: Accounts payables | B19: 1432.159 | C19: 1974.041 | D19: 1649.523 | E19: 2020 | F19: 1832 | H19: Accounts payables | I19: 2708 | J19: 3495 | K19: 4027 | L19: 3729 | M19: 4057 | O19: Accounts payables | P19: 1403 | Q19: 1674 | R19: 1757 | S19: 1714 | T19: 1805 | W19: Accounts payables | X19: 424 | Y19: 565 | Z19: 575 | AA19: 520 | AB19: 603 | AE19: Accounts payables | AF19: =3763+2126 -> 5889 | AG19: =5577+2839 -> 8416 | AH19: =4940+2276 -> 7216 | AI19: =4529+1797 -> 6326 | AJ19: =4847+1694 -> 6541 | AM19: Accounts payables | AN19: 493 | AO19: 518 | AP19: 633 | AQ19: 960 | AR19: 843 | AU19: FCFF | AV19: {=DCF!B9:G9} -> 2098.2418 | AW19: 3151.2728 | AX19: 3429.252 | AY19: 3731.7522 | AZ19: 4060.9365 | BA19: 4419.1587
A20: Total current liabilities | B20: 2627.86 | C20: 5157.413 | D20: 4329.744 | E20: 4595 | F20: 4977 | H20: Total current liabilities | I20: 3417 | J20: 5892 | K20: 6345 | L20: 5815 | M20: 5496 | O20: Total current liabilities | P20: 2761 | Q20: 3223 | R20: 3004 | S20: 3030 | T20: 3395 | W20: Total current liabilities | X20: 906 | Y20: 1432 | Z20: 995 | AA20: 800 | AB20: 818 | AE20: Total current liabilities | AF20: 11108 | AG20: 13226 | AH20: 11331 | AI20: 9957 | AJ20: 10288 | AM20: Total current liabilities | AN20: 3369 | AO20: 2654 | AP20: 2926 | AQ20: 5998 | AR20: 7543
A21: Total debt | B21: =57.906+5271.789 -> 5329.695 | C21: =107.723+4961.41 -> 5069.133 | D21: =49.081+6613.687 -> 6662.768 | E21: =119+6649 -> 6768 | F21: =225+5683 -> 5908 | H21: Total debt | I21: =34+9677 -> 9711 | J21: =372+9078 -> 9450 | K21: =1037+9583 -> 10620 | L21: =766+8656 -> 9422 | M21: =41+8907 -> 8948 | O21: Total debt | P21: =2+2463 -> 2465 | Q21: =1+1726 -> 1727 | R21: =1+1806 -> 1807 | S21: =79+1732 -> 1811 | T21: =75+2470 -> 2545 | W21: Total debt | X21: =249+3712 -> 3961 | Y21: =3465 -> 3465 | Z21: 2965 | AA21: =2968 -> 2968 | AB21: 2971 | AE21: Total debt | AF21: =460+16491 -> 16951 | AG21: =231+14280 -> 14511 | AH21: =362+14698 -> 15060 | AI21: =117+14907 -> 15024 | AJ21: =497+15711 -> 16208 | AM21: Total debt | AN21: =551+5480 -> 6031 | AO21: =87+5565 -> 5652 | AP21: 5571 | AQ21: =1923+6951 -> 8874 | AR21: =924+7552 -> 8476 | AU21: Particulars | AV21: 2025 | AW21: 2026 | AX21: 2027 | AY21: 2028 | AZ21: 2029 | BA21: 2030
A22: Shareholder's equity | B22: 11231.861 | C22: 14603.794 | D22: 19569.906 | E22: 22123 | F22: 21417 | H22: Shareholder's equity | I22: 18668 | J22: 23019 | K22: 24871 | L22: 27310 | M22: 28778 | O22: Shareholder's equity | P22: 5016 | Q22: 6284 | R22: 6589 | S22: 5845 | T22: 5157 | W22: Shareholder's equity | X22: 5603 | Y22: 6036 | Z22: 7853 | AA22: 8373 | AB22: 7592 | AE22: Shareholder's equity | AF22: 13005 | AG22: 18739 | AH22: 21247 | AI22: 19108 | AJ22: 17851 | AM22: Shareholder's equity | AN22: 23845 | AO22: 21813 | AP22: 19533 | AQ22: 29205 | AR22: 30109 | AU22: Revenue | AV22: {=DCF!J3:O3} -> 28607.657 | AW22: 32150.777 | AX22: 36132.72 | AY22: 40607.836 | AZ22: 45637.204 | BA22: 51289.471
AU23: Operating income | AV23: {=DCF!J4:O4} -> 10789.547 | AW23: 12125.856 | AX23: 13627.669 | AY23: 15315.485 | AZ23: 17212.341 | BA23: 19344.127
A24: CASH FLOW STATEMENT | H24: CASH FLOW STATEMENT | O24: CASH FLOW STATEMENT | W24: CASH FLOW STATEMENT | AE24: CASH FLOW STATEMENT | AM24: CASH FLOW STATEMENT | AU24: Net income | AV24: {=DCF!J5:O5} -> 8307.9511 | AW24: 9336.9088 | AX24: 10493.305 | AY24: 11792.924 | AZ24: 13253.503 | BA24: 14894.978
A25: Particulars | B25: 2020 | C25: 2021 | D25: 2022 | E25: 2023 | F25: 2024 | H25: Particulars | I25: 2020 | J25: 2021 | K25: 2022 | L25: 2023 | M25: 2024 | O25: Particulars | P25: 2020 | Q25: 2021 | R25: 2022 | S25: 2023 | T25: 2024 | W25: Particulars | X25: 2020 | Y25: 2021 | Z25: 2022 | AA25: 2023 | AB25: 2024 | AE25: Particulars | AF25: 2020 | AG25: 2021 | AH25: 2022 | AI25: 2023 | AJ25: 2024 | AM25: Particulars | AN25: 2020 | AO25: 2021 | AP25: 2022 | AQ25: 2023 | AR25: 2024 | AU25: Capex | AV25: {=DCF!J7:O7} -> 4544.3456 | AW25: 5107.1726 | AX25: 5739.707 | AY25: 6450.5821 | AZ25: 7249.5007 | BA25: 8147.367
A26: Cash flow from operating activities | B26: 2696.877 | C26: 6230.776 | D26: 10072.054 | E26: 7112 | F26: 3979 | H26: Cash flow from operating activities | I26: 3017 | J26: 7715 | K26: 5139 | L26: 5279 | M26: 7160 | O26: Cash flow from operating activities | P26: 394 | Q26: 920 | R26: 822 | S26: 91 | T26: 622 | W26: Cash flow from operating activities | X26: 1231 | Y26: 2873 | Z26: 3855 | AA26: 2757 | AB26: 2271 | AE26: Cash flow from operating activities | AF26: 6226 | AG26: 7009 | AH26: 7475 | AI26: 5196 | AJ26: 2914 | AM26: Cash flow from operating activities | AN26: 4882 | AO26: 4279 | AP26: 3220 | AQ26: 2763 | AR26: 6363 | AU26: FCFF | AV26: {=DCF!J9:O9} -> 3550.6149 | AW26: 5844.2833 | AX26: 6568.1104 | AY26: 7381.5851 | AZ26: 8295.8104 | BA26: 9323.2645
A27: Capex | B27: 1543.219 | C27: 1621.989 | D27: 1947.897 | E27: 2214 | F27: 3173 | H27: Capex | I27: =428+183+1266+19+65 -> 1961 | J27: =342+162+1296+222+6+87 -> 2115 | K27: =597+304+1575+806+33+154 -> 3469 | L27: =761+368+3411+84+200 -> 4824 | M27: =1033+375+2908+117+375 -> 4808 | O27: Capex | P27: 353 | Q27: 390 | R27: 480 | S27: 531 | T27: 580 | W27: Capex | X27: 309 | Y27: 514 | Z27: 453 | AA27: 499 | AB27: 518 | AE27: Capex | AF27: 1252 | AG27: 1501 | AH27: 1823 | AI27: 2356 | AJ27: 2940 | AM27: Capex | AN27: 1302 | AO27: 1653 | AP27: 2131 | AQ27: 2666 | AR27: 3402
A28: Dividends paid | B28: 491.655 | C28: 483.469 | D28: 533.589 | E28: 515 | F28: 522 | H28: Dividends paid | I28: =73 -> 73 | J28: =331+583 -> 914 | K28: =866+840 -> 1706 | L28: =863+625 -> 1488 | M28: =865+1833 -> 2698 | O28: Dividends paid | P28: 207 | Q28: 215 | R28: 379 | S28: 30 | T28: 49 | W28: Dividends paid | X28: 258 | Y28: 260 | Z28: 306 | AA28: 311 | AB28: 364 | AE28: Dividends paid | AF28: 2071 | AG28: 2073 | AH28: 2006 | AI28: 1972 | AJ28: 1966 | AM28: Dividends paid | AN28: 834 | AO28: 1757 | AP28: 1746 | AQ28: 1415 | AR28: 1145
A29: Debt repaid | B29: 97.15 | C29: 0 | D29: 1111 | E29: 10 | F29: 10 | H29: Debt repaid | I29: 3724 | J29: 1461 | K29: 4515 | L29: 2980 | M29: 2731 | O29: Debt repaid | P29: 1 | Q29: 1294 | R29: 1 | S29: 72 | T29: 679 | W29: Debt repaid | X29: =500 -> 500 | Y29: 518 | Z29: 507 | AA29: 0 | AB29: 0 | AE29: Debt repaid | AF29: =163+4653 -> 4816 | AG29: =130+2771 -> 2901 | AH29: =14+1006 -> 1020 | AI29: =446 -> 446 | AJ29: =17+267 -> 284 | AM29: Debt repaid | AN29: 1160 | AO29: 1382 | AP29: 89 | AQ29: 0 | AR29: 3860
O32: Particulars | P32: 2020 | Q32: 2021 | R32: 2022 | S32: 2023 | T32: 2024 | W32: Particulars | X32: 2020 | Y32: 2021 | Z32: 2022 | AA32: 2023 | AB32: 2024 | AE32: Particulars | AF32: 2020 | AG32: 2021 | AH32: 2022 | AI32: 2023 | AJ32: 2024 | AM32: Particulars | AN32: 2020 | AO32: 2021 | AP32: 2022 | AQ32: 2023 | AR32: 2024
O33: Revenue | P33: =P3 -> 9286 | Q33: =Q3 -> 12152 | R33: =R3 -> 12451 | S33: =S3 -> 10551 | T33: =T3 -> 11895 | W33: Revenue | X33: =X3 -> 4124 | Y33: =Y3 -> 6538 | Z33: =Z3 -> 11186 | AA33: =AA3 -> 6631 | AB33: =AB3 -> 5936 | AE33: Revenue | AF33: =AF3 -> 38542 | AG33: =AG3 -> 54968 | AH33: =AH3 -> 56902 | AI33: =AI3 -> 44622 | AJ33: =AJ3 -> 42964 | AM33: Revenue | AN33: =AN3 -> 11497 | AO33: =AO3 -> 12222 | AP33: =AP3 -> 11915 | AQ33: =AQ3 -> 11812 | AR33: =AR3 -> 18682
O34: Operating income | P34: =P6 -> 972 | Q34: =Q6 -> 2058 | R34: =R6 -> 1425 | S34: =S6 -> 155 | T34: =T6 -> 1087 | W34: Operating income | X34: =X6 -> 612 | Y34: =Y6 -> 1682 | Z34: =Z6 -> 5303 | AA34: =AA6 -> 2238 | AB34: =AB6 -> 1742 | AE34: Operating income | AF34: =AF6 -> 721 | AG34: =AG6 -> 7274 | AH34: =AH6 -> 4752 | AI34: =AI6 -> 1506 | AJ34: =AJ6 -> 2333 | AM34: Operating income | AN34: =AN6 -> 5106 | AO34: =AO6 -> 3580 | AP34: =AP6 -> 2388 | AQ34: =AQ6 -> 408 | AR34: =AR6 -> 7103
O35: Net income | P35: =P10 -> -14 | Q35: =Q10 -> 570 | R35: =R10 -> 38 | S35: =S10 -> -773 | T35: =T10 -> 24 | W35: Net income | X35: =X10 -> -490 | Y35: =Y10 -> 327 | Z35: =Z10 -> 2951 | AA35: =AA10 -> 809 | AB35: =AB10 -> 411 | AE35: Net income | AF35: =AF10 -> -1284 | AG35: =AG10 -> 4415 | AH35: =AH10 -> 2304 | AI35: =AI10 -> 440 | AJ35: =AJ10 -> 813 | AM35: Net income | AN35: =AN10 -> 1794 | AO35: =AO10 -> -115 | AP35: =AP10 -> -479 | AQ35: =AQ10 -> -2469 | AR35: =AR10 -> 2755
O37: Particulars | P37: 2025 | Q37: 2026 | R37: 2027 | S37: 2028 | T37: 2029 | U37: 2030 | W37: Particulars | X37: 2025 | Y37: 2026 | Z37: 2027 | AA37: 2028 | AB37: 2029 | AC37: 2030 | AE37: Particulars | AF37: 2025 | AG37: 2026 | AH37: 2027 | AI37: 2028 | AJ37: 2029 | AK37: 2030 | AM37: Particulars | AN37: 2025 | AO37: 2026 | AP37: 2027 | AQ37: 2028 | AR37: 2029 | AS37: 2030
O38: =O33 -> Revenue | P38: =DCF!R3 -> 12498.894 | Q38: =DCF!S3 -> 13133.448 | R38: =DCF!T3 -> 13800.217 | S38: =DCF!U3 -> 14500.837 | T38: =DCF!V3 -> 15237.026 | U38: =DCF!W3 -> 16010.591 | W38: =W33 -> Revenue | X38: =DCF!Z3 -> 6384.5301 | Y38: =DCF!AA3 -> 6866.9516 | Z38: =DCF!AB3 -> 7385.8253 | AA38: =DCF!AC3 -> 7943.9057 | AB38: =DCF!AD3 -> 8544.1552 | AC38: =DCF!AE3 -> 9189.7601 | AE38: =AE33 -> Revenue | AF38: =DCF!AH3 -> 43907.509 | AG38: =DCF!AI3 -> 44871.738 | AH38: =DCF!AJ3 -> 45857.142 | AI38: =DCF!AK3 -> 46864.186 | AJ38: =DCF!AL3 -> 47893.345 | AK38: =DCF!AM3 -> 48945.105 | AM38: =AM33 -> Revenue | AN38: =DCF!AP3 -> 20586.909 | AO38: =DCF!AQ3 -> 22686.051 | AP38: =DCF!AR3 -> 24999.232 | AQ38: =DCF!AS3 -> 27548.277 | AR38: =DCF!AT3 -> 30357.234 | AS38: =DCF!AU3 -> 33452.607
O39: =O34 -> Operating income | P39: =DCF!R4 -> 1263.978 | Q39: =DCF!S4 -> 1328.1486 | R39: =DCF!T4 -> 1395.5771 | S39: =DCF!U4 -> 1466.4288 | T39: =DCF!V4 -> 1540.8776 | U39: =DCF!W4 -> 1619.106 | W39: =W34 -> Operating income | X39: =DCF!Z4 -> 2147.7177 | Y39: =DCF!AA4 -> 2310.0014 | Z39: =DCF!AB4 -> 2484.5474 | AA39: =DCF!AC4 -> 2672.2823 | AB39: =DCF!AD4 -> 2874.2027 | AC39: =DCF!AE4 -> 3091.3803 | AE39: =AE34 -> Operating income | AF39: =DCF!AH4 -> 3492.4627 | AG39: =DCF!AI4 -> 3569.1587 | AH39: =DCF!AJ4 -> 3647.5391 | AI39: =DCF!AK4 -> 3727.6407 | AJ39: =DCF!AL4 -> 3809.5014 | AK39: =DCF!AM4 -> 3893.1598 | AM39: =AM34 -> Operating income | AN39: =DCF!AP4 -> 5785.8652 | AO39: =DCF!AQ4 -> 6375.8205 | AP39: =DCF!AR4 -> 7025.9305 | AQ39: =DCF!AS4 -> 7742.3289 | AR39: =DCF!AT4 -> 8531.7748 | AS39: =DCF!AU4 -> 9401.7164
O40: =O35 -> Net income | P40: =DCF!R5 -> 973.26307 | Q40: =DCF!S5 -> 1022.6744 | R40: =DCF!T5 -> 1074.5943 | S40: =DCF!U5 -> 1129.1502 | T40: =DCF!V5 -> 1186.4757 | U40: =DCF!W5 -> 1246.7116 | W40: =W35 -> Net income | X40: =DCF!Z5 -> 1653.7426 | Y40: =DCF!AA5 -> 1778.7011 | Z40: =DCF!AB5 -> 1913.1015 | AA40: =DCF!AC5 -> 2057.6574 | AB40: =DCF!AD5 -> 2213.1361 | AC40: =DCF!AE5 -> 2380.3628 | AE40: =AE35 -> Net income | AF40: =DCF!AH5 -> 2689.1962 | AG40: =DCF!AI5 -> 2748.2522 | AH40: =DCF!AJ5 -> 2808.6051 | AI40: =DCF!AK5 -> 2870.2834 | AJ40: =DCF!AL5 -> 2933.3161 | AK40: =DCF!AM5 -> 2997.7331 | AM40: =AM35 -> Net income | AN40: =DCF!AP5 -> 4455.1162 | AO40: =DCF!AQ5 -> 4909.3818 | AP40: =DCF!AR5 -> 5409.9665 | AQ40: =DCF!AS5 -> 5961.5932 | AR40: =DCF!AT5 -> 6569.4666 | AS40: =DCF!AU5 -> 7239.3217

Sheet Assumptions & WACC
A1: Assumptions
A2: Metric | B2: Nucor | C2: Freeport | D2: Alcoa | E2: RF Ind | F2: Dow | G2: Newmount | I2: Current | J2: 2020 | K2: 2021 | L2: 2022 | M2: 2023 | N2: 2024
A3: Revenue CAGR | B3: =(Table1[[#This Row],[2024]]/Table1[[#This Row],[2020]])^(1/5)-1 -> 0.08821172 | C3: =(Table18[[#This Row],[2024]]/Table18[[#This Row],[2020]])^(1/5)-1 -> 0.12385216 | D3: =(Table114[[#This Row],[2024]]/Table114[[#This Row],[2020]])^(1/5)-1 -> 0.050768762 | E3: =(Table1819[[#This Row],[2024]]/Table1819[[#This Row],[2020]])^(1/5)-1 -> 0.075561002 | F3: =(Table11435[[#This Row],[2024]]/Table11435[[#This Row],[2020]])^(1/5)-1 -> 0.021960458 | G3: =(Table181938[[#This Row],[2024]]/Table181938[[#This Row],[2020]])^(1/5)-1 -> 0.10196491 | I3: WC-Nucor | J3: =Financials!B17-Financials!B20 -> 6860.802 | K3: =Financials!C17-Financials!C20 -> 7642.144 | L3: =Financials!D17-Financials!D20 -> 10361.94 | M3: =Financials!E17-Financials!E20 -> 11791 | N3: =Financials!F17-Financials!F20 -> 7498
A4: Operating margin (EBIT) | B4: =AVERAGE(Financials!B6:F6)/AVERAGE(Financials!B3:F3) -> 0.18264926 | C4: =AVERAGE(Financials!I6:M6)/AVERAGE(Financials!I3:M3) -> 0.37715591 | D4: =AVERAGE(Financials!P6:T6)/AVERAGE(Financials!P3:T3) -> 0.10112719 | E4: =AVERAGE(Financials!X6:AB6)/AVERAGE(Financials!X3:AB3) -> 0.33639401 | F4: =AVERAGE(Financials!AG6:AJ6)/AVERAGE(Financials!AG3:AJ3) -> 0.079541352 | G4: =AVERAGE(Financials!AN6:AR6)/AVERAGE(Financials!AN3:AR3) -> 0.28104585 | I4: WC-Freeport | J4: =Financials!I17-Financials!I20 -> 5886 | K4: =Financials!J17-Financials!J20 -> 8938 | L4: =Financials!K17-Financials!K20 -> 9268 | M4: =Financials!L17-Financials!L20 -> 8250 | N4: =Financials!M17-Financials!M20 -> 7800
A5: Depreciation rate | B5: =AVERAGE(Financials!B7:F7)/AVERAGE(Financials!B3:F3) -> 0.032012061 | C5: =AVERAGE(Financials!I7:M7)/AVERAGE(Financials!I3:M3) -> 0.091128518 | D5: =AVERAGE(Financials!P7:T7)/AVERAGE(Financials!P3:T3) -> 0.056945061 | E5: =AVERAGE(Financials!X7:AB7)/AVERAGE(Financials!X3:AB3) -> 0.1285486 | F5: =AVERAGE(Financials!AF7:AJ7)/AVERAGE(Financials!AF3:AJ3) -> 0.0073908184 | G5: =AVERAGE(Financials!AN7:AR7)/AVERAGE(Financials!AN3:AR3) -> 0.17378418
A6: CapEx | B6: =AVERAGE(Financials!B27:F27)/AVERAGE(Financials!B3:F3) -> 0.064187823 | C6: =AVERAGE(Financials!I27:M27)/AVERAGE(Financials!I3:M3) -> 0.15885067 | D6: =AVERAGE(Financials!P27:T27)/AVERAGE(Financials!P3:T3) -> 0.041430727 | E6: =AVERAGE(Financials!X27:AB27)/AVERAGE(Financials!X3:AB3) -> 0.066627924 | F6: =AVERAGE(Financials!AF27:AJ27)/AVERAGE(Financials!AF3:AJ3) -> 0.04147934 | G6: =AVERAGE(Financials!AN27:AR27)/AVERAGE(Financials!AN3:AR3) -> 0.16867288 | I6: Forecast | J6: 2025 | K6: 2026 | L6: 2027 | M6: 2028 | N6: 2029 | O6: 2030
A7: Working capital | B7: =AVERAGE(J3:N3)/AVERAGE(Financials!B3:F3) -> 0.26991557 | C7: =AVERAGE(J4:N4)/AVERAGE(Financials!I3:M3) -> 0.37122802 | D7: =AVERAGE(J11:N11)/AVERAGE(Financials!P3:T3) -> 0.1544688 | E7: =AVERAGE(J12:N12)/AVERAGE(Financials!X3:AB3) -> 0.23977917 | F7: =AVERAGE(J19:N19)/AVERAGE(Financials!AF3:AJ3) -> 0.16261901 | G7: =AVERAGE(J20:N20)/AVERAGE(Financials!AN3:AR3) -> 0.30264033 | I7: =I3 -> WC-Nucor | J7: =DCF!B3*'Assumptions & WACC'!$B$7 -> 9027.353 | K7: =DCF!C3*'Assumptions & WACC'!$B$7 -> 9823.6713 | L7: =DCF!D3*'Assumptions & WACC'!$B$7 -> 10690.234 | M7: =DCF!E3*'Assumptions & WACC'!$B$7 -> 11633.238 | N7: =DCF!F3*'Assumptions & WACC'!$B$7 -> 12659.426 | O7: =DCF!G3*'Assumptions & WACC'!$B$7 -> 13776.136
A8: Forecast horizon (yrs) | B8: 6 | C8: 6 | D8: 6 | E8: 6 | F8: 6 | G8: 6 | I8: =I4 -> WC-Freeport | J8: =DCF!J3*'Assumptions & WACC'!$C$7 -> 10619.964 | K8: =DCF!K3*'Assumptions & WACC'!$C$7 -> 11935.269 | L8: =DCF!L3*'Assumptions & WACC'!$C$7 -> 13413.478 | M8: =DCF!M3*'Assumptions & WACC'!$C$7 -> 15074.767 | N8: =DCF!N3*'Assumptions & WACC'!$C$7 -> 16941.809 | O8: =DCF!O3*'Assumptions & WACC'!$C$7 -> 19040.089
A9: Risk-free rate | B9: =$I$27 -> 0.041386 | C9: =$I$27 -> 0.041386 | D9: =$I$27 -> 0.041386 | E9: =$I$27 -> 0.041386 | F9: =$I$27 -> 0.041386 | G9: =$I$27 -> 0.041386
A10: Equity risk premium | B10: 0.048 | C10: 0.048 | D10: 0.048 | E10: 0.048 | F10: 0.048 | G10: 0.048 | I10: Current | J10: 2020 | K10: 2021 | L10: 2022 | M10: 2023 | N10: 2024
A11: Beta | B11: ='Company Profile'!B9 -> 1.8567 | C11: ='Company Profile'!C9 -> 1.4877 | D11: ='Company Profile'!D9 -> 1.9931 | E11: ='Company Profile'!E9 -> 0.991 | F11: ='Company Profile'!F9 -> 0.7998 | G11: ='Company Profile'!G9 -> 0.4175 | I11: WC-Alcoa | J11: =Financials!P17-Financials!P20 -> 1759 | K11: =Financials!Q17-Financials!Q20 -> 1803 | L11: =Financials!R17-Financials!R20 -> 2246 | M11: =Financials!S17-Financials!S20 -> 1375 | N11: =Financials!T17-Financials!T20 -> 1519
A12: Cost of equity | B12: =B9+(B10*B11) -> 0.1305076 | C12: =C9+(C10*C11) -> 0.1127956 | D12: =D9+(D10*D11) -> 0.1370548 | E12: =E9+(E10*E11) -> 0.088954 | F12: =F9+(F10*F11) -> 0.0797764 | G12: =G9+(G10*G11) -> 0.061426 | I12: WC-RFIL | J12: =Financials!X17-Financials!X20 -> 461 | K12: =Financials!Y17-Financials!Y20 -> 1161 | L12: =Financials!Z17-Financials!Z20 -> 2678 | M12: =Financials!AA17-Financials!AA20 -> 2250 | N12: =Financials!AB17-Financials!AB20 -> 1702
A13: Kd (pre-tax) | B13: =AVERAGE(Financials!B8:F8)/AVERAGE(Financials!B21:F21) -> 0.018235099 | C13: =AVERAGE(Financials!I8:M8)/AVERAGE(Financials!I21:M21) -> 0.053872194 | D13: =AVERAGE(Financials!P8:T8)/AVERAGE(Financials!P21:T21) -> 0.06856591 | E13: =AVERAGE(Financials!X8:AB8)/AVERAGE(Financials!X21:AB21) -> 0.059889773 | F13: =AVERAGE(Financials!AF8:AJ8)/AVERAGE(Financials!AF21:AJ21) -> 0.048576279 | G13: =AVERAGE(Financials!AN8:AR8)/AVERAGE(Financials!AN21:AR21) -> 0.041238007
A14: Tax rate | B14: 0.23 | C14: 0.23 | D14: 0.23 | E14: 0.23 | F14: 0.23 | G14: 0.23 | I14: Forecast | J14: 2025 | K14: 2026 | L14: 2027 | M14: 2028 | N14: 2029 | O14: 2030
A15: Kd (after tax) | B15: =B13*(1-B14) -> 0.014041026 | C15: =C13*(1-C14) -> 0.041481589 | D15: =D13*(1-D14) -> 0.052795751 | E15: =E13*(1-E14) -> 0.046115126 | F15: =F13*(1-F14) -> 0.037403735 | G15: =G13*(1-G14) -> 0.031753266 | I15: =I11 -> WC-Alcoa | J15: =DCF!R3*'Assumptions & WACC'!$D$7 -> 1930.6893 | K15: =DCF!S3*'Assumptions & WACC'!$D$7 -> 2028.708 | L15: =DCF!T3*'Assumptions & WACC'!$D$7 -> 2131.703 | M15: =DCF!U3*'Assumptions & WACC'!$D$7 -> 2239.9269 | N15: =DCF!V3*'Assumptions & WACC'!$D$7 -> 2353.6452 | O15: =DCF!W3*'Assumptions & WACC'!$D$7 -> 2473.1368
A16: Total debt | B16: =Financials!F21 -> 5908 | C16: =Financials!M21 -> 8948 | D16: =Financials!T21 -> 2545 | E16: =Financials!AB21 -> 2971 | F16: =Financials!AJ21 -> 16208 | G16: =Financials!AR21 -> 8476 | I16: =I12 -> WC-RFIL | J16: =DCF!Z3*'Assumptions & WACC'!$E$7 -> 1530.8773 | K16: =DCF!AA3*'Assumptions & WACC'!$E$7 -> 1646.5519 | L16: =DCF!AB3*'Assumptions & WACC'!$E$7 -> 1770.967 | M16: =DCF!AC3*'Assumptions & WACC'!$E$7 -> 1904.7831 | N16: =DCF!AD3*'Assumptions & WACC'!$E$7 -> 2048.7104 | O16: =DCF!AE3*'Assumptions & WACC'!$E$7 -> 2203.513
A17: Market cap | B17: ='Company Profile'!B8 -> 34003.826 | C17: ='Company Profile'!C8 -> 59217.794 | D17: ='Company Profile'!D8 -> 9509.1581 | E17: ='Company Profile'!E8 -> 64.96477 | F17: ='Company Profile'!F8 -> 15150.007 | G17: ='Company Profile'!G8 -> 95398.211
A18: Total capital | B18: =B16+B17 -> 39911.826 | C18: =C16+C17 -> 68165.794 | D18: =D16+D17 -> 12054.158 | E18: =E16+E17 -> 3035.9648 | F18: =F16+F17 -> 31358.007 | G18: =G16+G17 -> 103874.21 | I18: Current | J18: 2020 | K18: 2021 | L18: 2022 | M18: 2023 | N18: 2024
A19: Debt weight | B19: =B16/B18 -> 0.1480263 | C19: =C16/C18 -> 0.13126818 | D19: =D16/D18 -> 0.21113046 | E19: =E16/E18 -> 0.97860161 | F19: =F16/F18 -> 0.51686958 | G19: =G16/G18 -> 0.081598694 | I19: WC-Dow | J19: =Financials!AF17-Financials!AF20 -> 7976 | K19: =Financials!AG17-Financials!AG20 -> 7622 | L19: =Financials!AH17-Financials!AH20 -> 9146 | M19: =Financials!AI17-Financials!AI20 -> 7657 | N19: =Financials!AJ17-Financials!AJ20 -> 6302
A20: Equity weight | B20: =B17/B18 -> 0.8519737 | C20: =C17/C18 -> 0.86873182 | D20: =D17/D18 -> 0.78886954 | E20: =E17/E18 -> 0.021398394 | F20: =F17/F18 -> 0.48313042 | G20: =G17/G18 -> 0.91840131 | I20: WC-Newmount | J20: =Financials!AN17-Table292039[[#This Row],[2020]] -> 5136 | K20: =Financials!AO17-Table292039[[#This Row],[2021]] -> 5042 | L20: =Financials!AP17-Table292039[[#This Row],[2022]] -> 3589 | M20: =Financials!AQ17-Table292039[[#This Row],[2023]] -> 1514 | N20: =Financials!AR17-Table292039[[#This Row],[2024]] -> 4732
A21: WACC | B21: =(B12*B20)+(B15*B19) -> 0.11326748 | C21: =(C12*C20)+(C15*C19) -> 0.10343434 | D21: =(D12*D20)+(D15*D19) -> 0.11926515 | E21: =(E12*E20)+(E15*E19) -> 0.047031809 | F21: =(F12*F20)+(F15*F19) -> 0.057875258 | G21: =(G12*G20)+(G15*G19) -> 0.059004744
A22: Terminal year | B22: 2030 | C22: 2030 | D22: 2030 | E22: 2030 | F22: 2030 | G22: 2030 | I22: Forecast | J22: 2025 | K22: 2026 | L22: 2027 | M22: 2028 | N22: 2029 | O22: 2030
A23: PV discount rate (terminal year) | B23: =1/(1+B21)^6 -> 0.5252945 | C23: =1/(1+C21)^6 -> 0.55401437 | D23: =1/(1+D21)^6 -> 0.50863017 | E23: =1/(1+E21)^6 -> 0.7589982 | F23: =1/(1+F21)^6 -> 0.71349879 | G23: =1/(1+G21)^6 -> 0.70894504 | I23: =I19 -> WC-Dow | J23: =DCF!AH3*'Assumptions & WACC'!$F$7 -> 7140.1958 | K23: =DCF!AI3*'Assumptions & WACC'!$F$7 -> 7296.9978 | L23: =DCF!AJ3*'Assumptions & WACC'!$F$7 -> 7457.2432 | M23: =DCF!AK3*'Assumptions & WACC'!$F$7 -> 7621.0077 | N23: =DCF!AL3*'Assumptions & WACC'!$F$7 -> 7788.3685 | O23: =DCF!AM3*'Assumptions & WACC'!$F$7 -> 7959.4046
A24: Cash & cash equivalents | B24: =Financials!F14 -> 3558 | C24: =Financials!M14 -> 3923 | D24: =Financials!T14 -> 1138 | E24: =Financials!AB14 -> 1614 | F24: =Financials!AJ14 -> 2189 | G24: =Financials!AR14 -> 3619 | I24: =I20 -> WC-Newmount | J24: =DCF!AP3*'Assumptions & WACC'!$G$7 -> 6230.4289 | K24: =DCF!AQ3*'Assumptions & WACC'!$G$7 -> 6865.714 | L24: =DCF!AR3*'Assumptions & WACC'!$G$7 -> 7565.776 | M24: =DCF!AS3*'Assumptions & WACC'!$G$7 -> 8337.2197 | N24: =DCF!AT3*'Assumptions & WACC'!$G$7 -> 9187.3236 | O24: =DCF!AU3*'Assumptions & WACC'!$G$7 -> 10124.108
A25: Terminal growth rate | B25: 0.02 | C25: 0.02 | D25: 0.0225 | E25: 0.002 | F25: 0.02 | G25: 0.03
A26: Shares Outstanding | B26: 238 | C26: 1445 | D26: ='Company Profile'!D6 -> 258.964 | E26: ='Company Profile'!E6 -> 10.66745 | F26: ='Company Profile'!F6 -> 710.7674 | G26: ='Company Profile'!G6 -> 1091.263 | I26: #VALUE!
I27: {=(_FV(I26,"Price",TRUE))/100} -> 0.041386

Sheet DCF
A1: DCF | G1: Nucor | O1: Freeport | Q1: DCF | W1: ='Assumptions & WACC'!D2 -> Alcoa | AE1: ='Assumptions & WACC'!E2 -> RF Ind | AG1: DCF | AM1: ='Assumptions & WACC'!F2 -> Dow | AU1: ='Assumptions & WACC'!G2 -> Newmount
A2: Particulars | B2: 2025 | C2: 2026 | D2: 2027 | E2: 2028 | F2: 2029 | G2: 2030 | I2: Particulars | J2: 2025 | K2: 2026 | L2: 2027 | M2: 2028 | N2: 2029 | O2: 2030 | Q2: Particulars | R2: 2025 | S2: 2026 | T2: 2027 | U2: 2028 | V2: 2029 | W2: 2030 | Y2: Particulars | Z2: 2025 | AA2: 2026 | AB2: 2027 | AC2: 2028 | AD2: 2029 | AE2: 2030 | AG2: Particulars | AH2: 2025 | AI2: 2026 | AJ2: 2027 | AK2: 2028 | AL2: 2029 | AM2: 2030 | AO2: Particulars | AP2: 2025 | AQ2: 2026 | AR2: 2027 | AS2: 2028 | AT2: 2029 | AU2: 2030
A3: Revenue | B3: =Table1[[#This Row],[2024]]*(1+'Assumptions & WACC'!B3) -> 33445.099 | C3: =Table9[[#This Row],[2025]]*(1+'Assumptions & WACC'!$B$3) -> 36395.349 | D3: =Table9[[#This Row],[2026]]*(1+'Assumptions & WACC'!$B$3) -> 39605.845 | E3: =Table9[[#This Row],[2027]]*(1+'Assumptions & WACC'!$B$3) -> 43099.545 | F3: =Table9[[#This Row],[2028]]*(1+'Assumptions & WACC'!$B$3) -> 46901.43 | G3: =Table9[[#This Row],[2029]]*(1+'Assumptions & WACC'!$B$3) -> 51038.686 | I3: Revenue | J3: =Table18[[#This Row],[2024]]*(1+'Assumptions & WACC'!C3) -> 28607.657 | K3: =Table10[[#This Row],[2025]]*(1+'Assumptions & WACC'!$C$3) -> 32150.777 | L3: =Table10[[#This Row],[2026]]*(1+'Assumptions & WACC'!$C$3) -> 36132.72 | M3: =Table10[[#This Row],[2027]]*(1+'Assumptions & WACC'!$C$3) -> 40607.836 | N3: =Table10[[#This Row],[2028]]*(1+'Assumptions & WACC'!$C$3) -> 45637.204 | O3: =Table10[[#This Row],[2029]]*(1+'Assumptions & WACC'!$C$3) -> 51289.471 | Q3: Revenue | R3: =Table114[[#This Row],[2024]]*(1+'Assumptions & WACC'!D3) -> 12498.894 | S3: =Table952[[#This Row],[2025]]*(1+'Assumptions & WACC'!$D$3) -> 13133.448 | T3: =Table952[[#This Row],[2026]]*(1+'Assumptions & WACC'!$D$3) -> 13800.217 | U3: =Table952[[#This Row],[2027]]*(1+'Assumptions & WACC'!$D$3) -> 14500.837 | V3: =Table952[[#This Row],[2028]]*(1+'Assumptions & WACC'!$D$3) -> 15237.026 | W3: =Table952[[#This Row],[2029]]*(1+'Assumptions & WACC'!$D$3) -> 16010.591 | Y3: Revenue | Z3: =Table1819[[#This Row],[2024]]*(1+'Assumptions & WACC'!E3) -> 6384.5301 | AA3: =Table1053[[#This Row],[2025]]*(1+'Assumptions & WACC'!$E$3) -> 6866.9516 | AB3: =Table1053[[#This Row],[2026]]*(1+'Assumptions & WACC'!$E$3) -> 7385.8253 | AC3: =Table1053[[#This Row],[2027]]*(1+'Assumptions & WACC'!$E$3) -> 7943.9057 | AD3: =Table1053[[#This Row],[2028]]*(1+'Assumptions & WACC'!$E$3) -> 8544.1552 | AE3: =Table1053[[#This Row],[2029]]*(1+'Assumptions & WACC'!$E$3) -> 9189.7601 | AG3: Revenue | AH3: =Table11435[[#This Row],[2024]]*(1+'Assumptions & WACC'!F3) -> 43907.509 | AI3: =Table960[[#This Row],[2025]]*(1+'Assumptions & WACC'!$F$3) -> 44871.738 | AJ3: =Table960[[#This Row],[2026]]*(1+'Assumptions & WACC'!$F$3) -> 45857.142 | AK3: =Table960[[#This Row],[2027]]*(1+'Assumptions & WACC'!$F$3) -> 46864.186 | AL3: =Table960[[#This Row],[2028]]*(1+'Assumptions & WACC'!$F$3) -> 47893.345 | AM3: =Table960[[#This Row],[2029]]*(1+'Assumptions & WACC'!$F$3) -> 48945.105 | AO3: Revenue | AP3: =Table181938[[#This Row],[2024]]*(1+'Assumptions & WACC'!$G$3) -> 20586.909 | AQ3: =Table1061[[#This Row],[2025]]*(1+'Assumptions & WACC'!$G$3) -> 22686.051 | AR3: =Table1061[[#This Row],[2026]]*(1+'Assumptions & WACC'!$G$3) -> 24999.232 | AS3: =Table1061[[#This Row],[2027]]*(1+'Assumptions & WACC'!$G$3) -> 27548.277 | AT3: =Table1061[[#This Row],[2028]]*(1+'Assumptions & WACC'!$G$3) -> 30357.234 | AU3: =Table1061[[#This Row],[2029]]*(1+'Assumptions & WACC'!$G$3) -> 33452.607
A4: EBIT | B4: =B3*'Assumptions & WACC'!$B$4 -> 6108.7225 | C4: =C3*'Assumptions & WACC'!$B$4 -> 6647.5835 | D4: =D3*'Assumptions & WACC'!$B$4 -> 7233.9782 | E4: =E3*'Assumptions & WACC'!$B$4 -> 7872.0999 | F4: =F3*'Assumptions & WACC'!$B$4 -> 8566.5114 | G4: =G3*'Assumptions & WACC'!$B$4 -> 9322.1781 | I4: EBIT | J4: =J3*'Assumptions & WACC'!$C$4 -> 10789.547 | K4: =K3*'Assumptions & WACC'!$C$4 -> 12125.856 | L4: =L3*'Assumptions & WACC'!$C$4 -> 13627.669 | M4: =M3*'Assumptions & WACC'!$C$4 -> 15315.485 | N4: =N3*'Assumptions & WACC'!$C$4 -> 17212.341 | O4: =O3*'Assumptions & WACC'!$C$4 -> 19344.127 | Q4: EBIT | R4: =R3*'Assumptions & WACC'!$D$4 -> 1263.978 | S4: =S3*'Assumptions & WACC'!$D$4 -> 1328.1486 | T4: =T3*'Assumptions & WACC'!$D$4 -> 1395.5771 | U4: =U3*'Assumptions & WACC'!$D$4 -> 1466.4288 | V4: =V3*'Assumptions & WACC'!$D$4 -> 1540.8776 | W4: =W3*'Assumptions & WACC'!$D$4 -> 1619.106 | Y4: EBIT | Z4: =Z3*'Assumptions & WACC'!$E$4 -> 2147.7177 | AA4: =AA3*'Assumptions & WACC'!$E$4 -> 2310.0014 | AB4: =AB3*'Assumptions & WACC'!$E$4 -> 2484.5474 | AC4: =AC3*'Assumptions & WACC'!$E$4 -> 2672.2823 | AD4: =AD3*'Assumptions & WACC'!$E$4 -> 2874.2027 | AE4: =AE3*'Assumptions & WACC'!$E$4 -> 3091.3803 | AG4: EBIT | AH4: =AH3*'Assumptions & WACC'!$F$4 -> 3492.4627 | AI4: =AI3*'Assumptions & WACC'!$F$4 -> 3569.1587 | AJ4: =AJ3*'Assumptions & WACC'!$F$4 -> 3647.5391 | AK4: =AK3*'Assumptions & WACC'!$F$4 -> 3727.6407 | AL4: =AL3*'Assumptions & WACC'!$F$4 -> 3809.5014 | AM4: =AM3*'Assumptions & WACC'!$F$4 -> 3893.1598 | AO4: EBIT | AP4: =AP3*'Assumptions & WACC'!$G$4 -> 5785.8652 | AQ4: =AQ3*'Assumptions & WACC'!$G$4 -> 6375.8205 | AR4: =AR3*'Assumptions & WACC'!$G$4 -> 7025.9305 | AS4: =AS3*'Assumptions & WACC'!$G$4 -> 7742.3289 | AT4: =AT3*'Assumptions & WACC'!$G$4 -> 8531.7748 | AU4: =AU3*'Assumptions & WACC'!$G$4 -> 9401.7164
A5: NOPAT | B5: =B4*(1-'Assumptions & WACC'!$B$14) -> 4703.7164 | C5: =C4*(1-'Assumptions & WACC'!$B$14) -> 5118.6393 | D5: =D4*(1-'Assumptions & WACC'!$B$14) -> 5570.1632 | E5: =E4*(1-'Assumptions & WACC'!$B$14) -> 6061.5169 | F5: =F4*(1-'Assumptions & WACC'!$B$14) -> 6596.2138 | G5: =G4*(1-'Assumptions & WACC'!$B$14) -> 7178.0771 | I5: NOPAT | J5: =J4*(1-'Assumptions & WACC'!$C$14) -> 8307.9511 | K5: =K4*(1-'Assumptions & WACC'!$C$14) -> 9336.9088 | L5: =L4*(1-'Assumptions & WACC'!$C$14) -> 10493.305 | M5: =M4*(1-'Assumptions & WACC'!$C$14) -> 11792.924 | N5: =N4*(1-'Assumptions & WACC'!$C$14) -> 13253.503 | O5: =O4*(1-'Assumptions & WACC'!$C$14) -> 14894.978 | Q5: NOPAT | R5: =R4*(1-'Assumptions & WACC'!$B$14) -> 973.26307 | S5: =S4*(1-'Assumptions & WACC'!$B$14) -> 1022.6744 | T5: =T4*(1-'Assumptions & WACC'!$B$14) -> 1074.5943 | U5: =U4*(1-'Assumptions & WACC'!$B$14) -> 1129.1502 | V5: =V4*(1-'Assumptions & WACC'!$B$14) -> 1186.4757 | W5: =W4*(1-'Assumptions & WACC'!$B$14) -> 1246.7116 | Y5: NOPAT | Z5: =Z4*(1-'Assumptions & WACC'!$C$14) -> 1653.7426 | AA5: =AA4*(1-'Assumptions & WACC'!$C$14) -> 1778.7011 | AB5: =AB4*(1-'Assumptions & WACC'!$C$14) -> 1913.1015 | AC5: =AC4*(1-'Assumptions & WACC'!$C$14) -> 2057.6574 | AD5: =AD4*(1-'Assumptions & WACC'!$C$14) -> 2213.1361 | AE5: =AE4*(1-'Assumptions & WACC'!$C$14) -> 2380.3628 | AG5: NOPAT | AH5: =AH4*(1-'Assumptions & WACC'!$B$14) -> 2689.1962 | AI5: =AI4*(1-'Assumptions & WACC'!$B$14) -> 2748.2522 | AJ5: =AJ4*(1-'Assumptions & WACC'!$B$14) -> 2808.6051 | AK5: =AK4*(1-'Assumptions & WACC'!$B$14) -> 2870.2834 | AL5: =AL4*(1-'Assumptions & WACC'!$B$14) -> 2933.3161 | AM5: =AM4*(1-'Assumptions & WACC'!$B$14) -> 2997.7331 | AO5: NOPAT | AP5: =AP4*(1-'Assumptions & WACC'!$C$14) -> 4455.1162 | AQ5: =AQ4*(1-'Assumptions & WACC'!$C$14) -> 4909.3818 | AR5: =AR4*(1-'Assumptions & WACC'!$C$14) -> 5409.9665 | AS5: =AS4*(1-'Assumptions & WACC'!$C$14) -> 5961.5932 | AT5: =AT4*(1-'Assumptions & WACC'!$C$14) -> 6569.4666 | AU5: =AU4*(1-'Assumptions & WACC'!$C$14) -> 7239.3217
A6: Depreciation | B6: =B3*'Assumptions & WACC'!$B$5 -> 1070.6465 | C6: =C3*'Assumptions & WACC'!$B$5 -> 1165.0901 | D6: =D3*'Assumptions & WACC'!$B$5 -> 1267.8647 | E6: =E3*'Assumptions & WACC'!$B$5 -> 1379.7052 | F6: =F3*'Assumptions & WACC'!$B$5 -> 1501.4114 | G6: =G3*'Assumptions & WACC'!$B$5 -> 1633.8535 | I6: Depreciation | J6: =J3*'Assumptions & WACC'!$C$5 -> 2606.9734 | K6: =K3*'Assumptions & WACC'!$C$5 -> 2929.8526 | L6: =L3*'Assumptions & WACC'!$C$5 -> 3292.7212 | M6: =M3*'Assumptions & WACC'!$C$5 -> 3700.5319 | N6: =N3*'Assumptions & WACC'!$C$5 -> 4158.8508 | O6: =O3*'Assumptions & WACC'!$C$5 -> 4673.9334 | Q6: Depreciation | R6: =R3*'Assumptions & WACC'!$D$5 -> 711.7503 | S6: =S3*'Assumptions & WACC'!$D$5 -> 747.88499 | T6: =T3*'Assumptions & WACC'!$D$5 -> 785.85418 | U6: =U3*'Assumptions & WACC'!$D$5 -> 825.75102 | V6: =V3*'Assumptions & WACC'!$D$5 -> 867.67338 | W6: =W3*'Assumptions & WACC'!$D$5 -> 911.72409 | Y6: Depreciation | Z6: =Z3*'Assumptions & WACC'!$E$4 -> 2147.7177 | AA6: =AA3*'Assumptions & WACC'!$E$4 -> 2310.0014 | AB6: =AB3*'Assumptions & WACC'!$E$4 -> 2484.5474 | AC6: =AC3*'Assumptions & WACC'!$E$4 -> 2672.2823 | AD6: =AD3*'Assumptions & WACC'!$E$4 -> 2874.2027 | AE6: =AE3*'Assumptions & WACC'!$E$4 -> 3091.3803 | AG6: Depreciation | AH6: =AH3*'Assumptions & WACC'!$F$5 -> 324.51243 | AI6: =AI3*'Assumptions & WACC'!$F$5 -> 331.63887 | AJ6: =AJ3*'Assumptions & WACC'!$F$5 -> 338.92181 | AK6: =AK3*'Assumptions & WACC'!$F$5 -> 346.36469 | AL6: =AL3*'Assumptions & WACC'!$F$5 -> 353.97101 | AM6: =AM3*'Assumptions & WACC'!$F$5 -> 361.74438 | AO6: Depreciation | AP6: =AP3*'Assumptions & WACC'!$G$5 -> 3577.6789 | AQ6: =AQ3*'Assumptions & WACC'!$G$5 -> 3942.4767 | AR6: =AR3*'Assumptions & WACC'!$G$5 -> 4344.471 | AS6: =AS3*'Assumptions & WACC'!$G$5 -> 4787.4546 | AT6: =AT3*'Assumptions & WACC'!$G$5 -> 5275.607 | AU6: =AU3*'Assumptions & WACC'!$G$5 -> 5813.5338
A7: Capex | B7: =B3*'Assumptions & WACC'!$B$6 -> 2146.7681 | C7: =C3*'Assumptions & WACC'!$B$6 -> 2336.1382 | D7: =D3*'Assumptions & WACC'!$B$6 -> 2542.213 | E7: =E3*'Assumptions & WACC'!$B$6 -> 2766.466 | F7: =F3*'Assumptions & WACC'!$B$6 -> 3010.5007 | G7: =G3*'Assumptions & WACC'!$B$6 -> 3276.0621 | I7: Capex | J7: =J3*'Assumptions & WACC'!$C$6 -> 4544.3456 | K7: =K3*'Assumptions & WACC'!$C$6 -> 5107.1726 | L7: =L3*'Assumptions & WACC'!$C$6 -> 5739.707 | M7: =M3*'Assumptions & WACC'!$C$6 -> 6450.5821 | N7: =N3*'Assumptions & WACC'!$C$6 -> 7249.5007 | O7: =O3*'Assumptions & WACC'!$C$6 -> 8147.367 | Q7: Capex | R7: =R3*'Assumptions & WACC'!$D$6 -> 517.83828 | S7: =S3*'Assumptions & WACC'!$D$6 -> 544.12829 | T7: =T3*'Assumptions & WACC'!$D$6 -> 571.75301 | U7: =U3*'Assumptions & WACC'!$D$6 -> 600.7802 | V7: =V3*'Assumptions & WACC'!$D$6 -> 631.28107 | W7: =W3*'Assumptions & WACC'!$D$6 -> 663.33043 | Y7: Capex | Z7: =Z3*'Assumptions & WACC'!$E$6 -> 425.38799 | AA7: =AA3*'Assumptions & WACC'!$E$6 -> 457.53073 | AB7: =AB3*'Assumptions & WACC'!$E$6 -> 492.10221 | AC7: =AC3*'Assumptions & WACC'!$E$6 -> 529.28595 | AD7: =AD3*'Assumptions & WACC'!$E$6 -> 569.27932 | AE7: =AE3*'Assumptions & WACC'!$E$6 -> 612.29464 | AG7: Capex | AH7: =AH3*'Assumptions & WACC'!$F$6 -> 1821.2545 | AI7: =AI3*'Assumptions & WACC'!$F$6 -> 1861.2501 | AJ7: =AJ3*'Assumptions & WACC'!$F$6 -> 1902.124 | AK7: =AK3*'Assumptions & WACC'!$F$6 -> 1943.8955 | AL7: =AL3*'Assumptions & WACC'!$F$6 -> 1986.5843 | AM7: =AM3*'Assumptions & WACC'!$F$6 -> 2030.2106 | AO7: Capex | AP7: =AP3*'Assumptions & WACC'!$G$6 -> 3472.4531 | AQ7: =AQ3*'Assumptions & WACC'!$G$6 -> 3826.5215 | AR7: =AR3*'Assumptions & WACC'!$G$6 -> 4216.6924 | AS7: =AS3*'Assumptions & WACC'!$G$6 -> 4646.6471 | AT7: =AT3*'Assumptions & WACC'!$G$6 -> 5120.4421 | AU7: =AU3*'Assumptions & WACC'!$G$6 -> 5642.5475
A8: Change in Working capital | B8: ='Assumptions & WACC'!J7-'Assumptions & WACC'!N3 -> 1529.353 | C8: ='Assumptions & WACC'!K7-'Assumptions & WACC'!J7 -> 796.31834 | D8: ='Assumptions & WACC'!L7-'Assumptions & WACC'!K7 -> 866.56295 | E8: ='Assumptions & WACC'!M7-'Assumptions & WACC'!L7 -> 943.00396 | F8: ='Assumptions & WACC'!N7-'Assumptions & WACC'!M7 -> 1026.188 | G8: ='Assumptions & WACC'!O7-'Assumptions & WACC'!N7 -> 1116.7098 | I8: Change in Working capital | J8: =Table20[[#This Row],[2025]]-'Assumptions & WACC'!N4 -> 2819.9639 | K8: =Table20[[#This Row],[2026]]-Table20[[#This Row],[2025]] -> 1315.3055 | L8: =Table20[[#This Row],[2027]]-Table20[[#This Row],[2026]] -> 1478.2089 | M8: =Table20[[#This Row],[2028]]-Table20[[#This Row],[2027]] -> 1661.2883 | N8: =Table20[[#This Row],[2029]]-Table20[[#This Row],[2028]] -> 1867.0425 | O8: =Table20[[#This Row],[2030]]-Table20[[#This Row],[2029]] -> 2098.2797 | Q8: Change in Working capital | R8: ='Assumptions & WACC'!J15-'Assumptions & WACC'!N11 -> 411.68926 | S8: ='Assumptions & WACC'!K15-'Assumptions & WACC'!J15 -> 98.018704 | T8: ='Assumptions & WACC'!L15-'Assumptions & WACC'!K15 -> 102.99499 | U8: ='Assumptions & WACC'!M15-'Assumptions & WACC'!L15 -> 108.22392 | V8: ='Assumptions & WACC'!N15-'Assumptions & WACC'!M15 -> 113.71831 | W8: ='Assumptions & WACC'!O15-'Assumptions & WACC'!N15 -> 119.49165 | Y8: Change in Working capital | Z8: ='Assumptions & WACC'!J16-'Assumptions & WACC'!N12 -> -171.12269 | AA8: ='Assumptions & WACC'!K16-'Assumptions & WACC'!J16 -> 115.67462 | AB8: ='Assumptions & WACC'!L16-'Assumptions & WACC'!K16 -> 124.41511 | AC8: ='Assumptions & WACC'!M16-'Assumptions & WACC'!L16 -> 133.81604 | AD8: ='Assumptions & WACC'!N16-'Assumptions & WACC'!M16 -> 143.92732 | AE8: ='Assumptions & WACC'!O16-'Assumptions & WACC'!N16 -> 154.80261 | AG8: Change in Working capital | AH8: ='Assumptions & WACC'!J23-'Assumptions & WACC'!N19 -> 838.19582 | AI8: ='Assumptions & WACC'!K23-'Assumptions & WACC'!J23 -> 156.80197 | AJ8: ='Assumptions & WACC'!L23-'Assumptions & WACC'!K23 -> 160.24541 | AK8: ='Assumptions & WACC'!M23-'Assumptions & WACC'!L23 -> 163.76447 | AL8: ='Assumptions & WACC'!N23-'Assumptions & WACC'!M23 -> 167.36082 | AM8: ='Assumptions & WACC'!O23-'Assumptions & WACC'!N23 -> 171.03614 | AO8: Change in Working capital | AP8: ='Assumptions & WACC'!J24-'Assumptions & WACC'!N20 -> 1498.4289 | AQ8: ='Assumptions & WACC'!K24-'Assumptions & WACC'!J24 -> 635.28515 | AR8: ='Assumptions & WACC'!L24-'Assumptions & WACC'!K24 -> 700.06194 | AS8: ='Assumptions & WACC'!M24-'Assumptions & WACC'!L24 -> 771.4437 | AT8: ='Assumptions & WACC'!N24-'Assumptions & WACC'!M24 -> 850.10389 | AU8: ='Assumptions & WACC'!O24-'Assumptions & WACC'!N24 -> 936.78466
A9: FCFF | B9: =B5+B6-B7-B8 -> 2098.2418 | C9: =C5+C6-C7-C8 -> 3151.2728 | D9: =D5+D6-D7-D8 -> 3429.252 | E9: =E5+E6-E7-E8 -> 3731.7522 | F9: =F5+F6-F7-F8 -> 4060.9365 | G9: =G5+G6-G7-G8 -> 4419.1587 | I9: FCFF | J9: =J5+J6-J7-J8 -> 3550.6149 | K9: =K5+K6-K7-K8 -> 5844.2833 | L9: =L5+L6-L7-L8 -> 6568.1104 | M9: =M5+M6-M7-M8 -> 7381.5851 | N9: =N5+N6-N7-N8 -> 8295.8104 | O9: =O5+O6-O7-O8 -> 9323.2645 | Q9: FCFF | R9: =R5+R6-R7-R8 -> 755.48584 | S9: =S5+S6-S7-S8 -> 1128.4124 | T9: =T5+T6-T7-T8 -> 1185.7005 | U9: =U5+U6-U7-U8 -> 1245.8971 | V9: =V5+V6-V7-V8 -> 1309.1497 | W9: =W5+W6-W7-W8 -> 1375.6136 | Y9: FCFF | Z9: =Z5+Z6-Z7-Z8 -> 3547.1951 | AA9: =AA5+AA6-AA7-AA8 -> 3515.4972 | AB9: =AB5+AB6-AB7-AB8 -> 3781.1316 | AC9: =AC5+AC6-AC7-AC8 -> 4066.8377 | AD9: =AD5+AD6-AD7-AD8 -> 4374.1321 | AE9: =AE5+AE6-AE7-AE8 -> 4704.6459 | AG9: FCFF | AH9: =AH5+AH6-AH7-AH8 -> 354.25835 | AI9: =AI5+AI6-AI7-AI8 -> 1061.839 | AJ9: =AJ5+AJ6-AJ7-AJ8 -> 1085.1575 | AK9: =AK5+AK6-AK7-AK8 -> 1108.9881 | AL9: =AL5+AL6-AL7-AL8 -> 1133.342 | AM9: =AM5+AM6-AM7-AM8 -> 1158.2307 | AO9: FCFF | AP9: =AP5+AP6-AP7-AP8 -> 3061.9132 | AQ9: =AQ5+AQ6-AQ7-AQ8 -> 4390.0518 | AR9: =AR5+AR6-AR7-AR8 -> 4837.6831 | AS9: =AS5+AS6-AS7-AS8 -> 5330.957 | AT9: =AT5+AT6-AT7-AT8 -> 5874.5276 | AU9: =AU5+AU6-AU7-AU8 -> 6473.5233
A12: Metrics | B12: Value | I12: Metrics | J12: Value | Q12: Metrics | R12: Value | Y12: Metrics | Z12: Value | AG12: Metrics | AH12: Value | AO12: Metrics | AP12: Value
A13: Terminal Value | B13: =G9*(1+'Assumptions & WACC'!B25)/('Assumptions & WACC'!B21-'Assumptions & WACC'!B25) -> 48329.19 | I13: Terminal Value | J13: =O9*(1+'Assumptions & WACC'!C25)/('Assumptions & WACC'!C21-'Assumptions & WACC'!C25) -> 113978.61 | Q13: Terminal Value | R13: =W9*(1+'Assumptions & WACC'!D25)/('Assumptions & WACC'!D21-'Assumptions & WACC'!D25) -> 14535.863 | Y13: Terminal Value | Z13: =AE9*(1+'Assumptions & WACC'!E25)/('Assumptions & WACC'!E21-'Assumptions & WACC'!E25) -> 104682.79 | AG13: Terminal Value | AH13: =AM9*(1+'Assumptions & WACC'!F25)/('Assumptions & WACC'!F21-'Assumptions & WACC'!F25) -> 31191.742 | AO13: Terminal Value | AP13: =AU9*(1+'Assumptions & WACC'!G25)/('Assumptions & WACC'!G21-'Assumptions & WACC'!G25) -> 229884.09
A14: PV of Terminal value | B14: =B13*'Assumptions & WACC'!B23 -> 25387.058 | I14: PV of Terminal value | J14: =J13*'Assumptions & WACC'!C23 -> 63145.786 | Q14: PV of Terminal value | R14: =R13*'Assumptions & WACC'!D23 -> 7393.3785 | Y14: PV of Terminal value | Z14: =Z13*'Assumptions & WACC'!E23 -> 79454.046 | AG14: PV of Terminal value | AH14: =AH13*'Assumptions & WACC'!F23 -> 22255.27 | AO14: PV of Terminal value | AP14: =AP13*'Assumptions & WACC'!G23 -> 162975.18
A15: PV of FCFF | B15: =NPV('Assumptions & WACC'!B21,DCF!B9:G9) -> 14038.494 | I15: PV of FCFF | J15: =NPV('Assumptions & WACC'!C21,DCF!J9:O9) -> 28122.389 | Q15: PV of FCFF | R15: =NPV('Assumptions & WACC'!D21,DCF!R9:W9) -> 4660.1891 | Y15: PV of FCFF | Z15: =NPV('Assumptions & WACC'!E21,DCF!Z9:AE9) -> 20319.581 | AG15: PV of FCFF | AH15: =NPV('Assumptions & WACC'!F21,DCF!AH9:AM9) -> 4767.6657 | AO15: PV of FCFF | AP15: =NPV('Assumptions & WACC'!G21,DCF!AP9:AU9) -> 24117.405
A16: Total enterprise value | B16: =B14+B15 -> 39425.551 | I16: Total enterprise value | J16: =J14+J15 -> 91268.175 | Q16: Total enterprise value | R16: =R14+R15 -> 12053.568 | Y16: Total enterprise value | Z16: =Z14+Z15 -> 99773.627 | AG16: Total enterprise value | AH16: =AH14+AH15 -> 27022.936 | AO16: Total enterprise value | AP16: =AP14+AP15 -> 187092.59
A17: Net debt | B17: ='Assumptions & WACC'!B16-'Assumptions & WACC'!B24 -> 2350 | I17: Net debt | J17: ='Assumptions & WACC'!C16-'Assumptions & WACC'!C24 -> 5025 | Q17: Net debt | R17: ='Assumptions & WACC'!D16-'Assumptions & WACC'!D24 -> 1407 | Y17: Net debt | Z17: ='Assumptions & WACC'!E16-'Assumptions & WACC'!E24 -> 1357 | AG17: Net debt | AH17: ='Assumptions & WACC'!F16-'Assumptions & WACC'!F24 -> 14019 | AO17: Net debt | AP17: ='Assumptions & WACC'!G16-'Assumptions & WACC'!G24 -> 4857
A18: Total equity value | B18: =B16-B17 -> 37075.551 | I18: Total equity value | J18: =J16-J17 -> 86243.175 | Q18: Total equity value | R18: =R16-R17 -> 10646.568 | Y18: Total equity value | Z18: =Z16-Z17 -> 98416.627 | AG18: Total equity value | AH18: =AH16-AH17 -> 13003.936 | AO18: Total equity value | AP18: =AP16-AP17 -> 182235.59
A19: Outstanding shares | B19: ='Assumptions & WACC'!B26 -> 238 | I19: Outstanding shares | J19: ='Assumptions & WACC'!C26 -> 1445 | Q19: Outstanding shares | R19: ='Assumptions & WACC'!D26 -> 258.964 | Y19: Outstanding shares | Z19: ='Assumptions & WACC'!E26 -> 10.66745 | AG19: Outstanding shares | AH19: ='Assumptions & WACC'!F26 -> 710.7674 | AO19: Outstanding shares | AP19: ='Assumptions & WACC'!G26 -> 1091.263
A20: Intrinsic value | B20: =B18/B19 -> 155.77963 | I20: Intrinsic value | J20: =J18/J19 -> 59.683858 | Q20: Intrinsic value | R20: =R18/R19 -> 41.112153 | Y20: Intrinsic value | Z20: =Z18/Z19 -> 9225.8813 | AG20: Intrinsic value | AH20: =AH18/AH19 -> 18.295628 | AO20: Intrinsic value | AP20: =AP18/AP19 -> 166.99511
A21: Current market price | B21: ='Company Profile'!B3 -> 148.58 | I21: Current market price | J21: ='Company Profile'!C3 -> 41.24 | Q21: Current market price | R21: ='Company Profile'!D3 -> 36.72 | Y21: Current market price | Z21: ='Company Profile'!E3 -> 6.09 | AG21: Current market price | AH21: ='Company Profile'!F3 -> 21.315 | AO21: Current market price | AP21: ='Company Profile'!G3 -> 87.42
A22: Upside/Downside | B22: =(B20-B21)/B21 -> 0.048456237 | I22: Upside/Downside | J22: =(J20-J21)/J21 -> 0.44723226 | Q22: Upside/Downside | R22: =(R20-R21)/R21 -> 0.11961202 | Y22: Upside/Downside | Z22: =(Z20-Z21)/Z21 -> 1513.923 | AG22: Upside/Downside | AH22: =(AH20-AH21)/AH21 -> -0.14165482 | AO22: Upside/Downside | AP22: =(AP20-AP21)/AP21 -> 0.9102621

Sheet Relative
A1: RELATIVE
A2: Company | B2: EV/EBITDA | C2: P/E | D2: P/S | E2: P/B
A3: #VALUE! | B3: 6.87 | C3: {=_FV(A3,"P/E",TRUE)} -> 20.5136 | D3: 1.01 | E3: 1.9 | H3: Company | I3: EV/EBITDA | J3: P/E | K3: P/S | L3: P/B | M3: Shares
A4: #VALUE! | B4: 7.64 | C4: {=_FV(A4,"P/E",TRUE)} -> 79.8587 | D4: 0.91 | E4: 1.63 | H4: Nucor | I4: =(B23*$B$20)/$M$4 -> 181.48868 | J4: =(C23*$B$20)/$M$4 -> 38.761654 | K4: =(D23*$B$20)/$M$4 -> 1319.2699 | L4: =(E23*$B$20)/$M$4 -> 919.33372 | M4: ='Assumptions & WACC'!B26 -> 238
A5: #VALUE! | B5: 9.86 | C5: {=_FV(A5,"P/E",TRUE)} -> 11.9589 | D5: 0.3 | E5: 0.33 | H5: Freeport | I5: =(B24*$B$20)/$M$5 -> 80.217005 | J5: =(C24*$B$20)/$M$5 -> 28.435818 | K5: =(D24*$B$20)/$M$5 -> 179.96861 | L5: =(E24*$B$20)/$M$5 -> 203.46245 | M5: ='Assumptions & WACC'!C26 -> 1445
A6: #VALUE! | B6: 4.24 | C6: 7.81 | D6: 0.58 | E6: 0.66 | H6: Alcoa | I6: =(B25*$B$20)/$M$6 -> 68.209853 | J6: =(C25*$B$20)/$M$6 -> 0.94681114 | K6: =(D25*$B$20)/$M$6 -> 469.26327 | L6: =(E25*$B$20)/$M$6 -> 203.44604 | M6: ='Assumptions & WACC'!D26 -> 258.964
A7: #VALUE! | B7: 10.05 | C7: {=_FV(A7,"P/E",TRUE)} -> 31.57 | D7: 0.77 | E7: 1.91 | H7: RFIL | I7: =(B26*$B$20)/$M$7 -> 2554.1942 | J7: =(C26*$B$20)/$M$7 -> 393.61598 | K7: =(D26*$B$20)/$M$7 -> 5684.9256 | L7: =(E26*$B$20)/$M$7 -> 7270.882 | M7: ='Assumptions & WACC'!E26 -> 10.66745
A8: #VALUE! | B8: 3.69 | C8: {=_FV(A8,"P/E",TRUE)} -> 7.58 | D8: 1.86 | E8: 2.46 | H8: Dow | I8: =(B27*$B$20)/$M$8 -> 37.98929 | J8: =(C27*$B$20)/$M$8 -> 11.685695 | K8: =(D27*$B$20)/$M$8 -> 617.54516 | L8: =(E27*$B$20)/$M$8 -> 256.58222 | M8: ='Assumptions & WACC'!F26 -> 710.7674
A9: #VALUE! | B9: 12.53 | C9: {=_FV(A9,"P/E",TRUE)} -> 26.9509 | D9: 6.61 | E9: 8.07 | H9: Newmount | I9: =(B28*$B$20)/$M$9 -> 90.61343 | J9: =(C28*$B$20)/$M$9 -> 25.791921 | K9: =(D28*$B$20)/$M$9 -> 174.89824 | L9: =(E28*$B$20)/$M$9 -> 281.8762 | M9: ='Assumptions & WACC'!G26 -> 1091.263
A10: #VALUE! | B10: 5.95 | C10: {=_FV(A10,"P/E",TRUE)} -> 15.0661 | D10: 2.75 | E10: 3.05
A11: #VALUE! | B11: 10.78 | C11: {=_FV(A11,"P/E",TRUE)} -> 22.1217 | D11: 4.3 | E11: 4.74
A12: #VALUE! | B12: 3.27 | C12: {=_FV(A12,"P/E",TRUE)} -> 9.1261 | D12: 0.93 | E12: 0.99
A13: #VALUE! | B13: 11.42 | C13: 25.84 | D13: 1.5 | E13: 2.09
A14: #VALUE! | B14: 19.42 | C14: {=_FV(A14,"P/E",TRUE)} -> 33.54 | D14: 2.1 | E14: 5.56
A15: #VALUE! | B15: 13.71 | C15: {=_FV(A15,"P/E",TRUE)} -> 18.7707 | D15: 5.72 | E15: 8.31
A16: #VALUE! | B16: 12.27 | C16: {=_FV(A16,"P/E",TRUE)} -> 19.4579 | D16: 2.78 | E16: 1.42
A17: #VALUE! | B17: 13.99 | C17: {=_FV(A17,"P/E",TRUE)} -> 21.9736 | D17: 4.02 | E17: 2
A18: #VALUE! | B18: 17.77 | C18: 32.36 | D18: 5.98 | E18: 7.45
A20: Average | B20: =AVERAGE(B3:B18) -> 10.21625 | C20: =AVERAGE(C3:C18) -> 24.031137 | D20: =AVERAGE(D3:D18) -> 2.6325 | E20: =AVERAGE(E3:E18) -> 3.285625
A22: Company | B22: EBITDA | C22: Net Income | D22: Revenue | E22: Book Value | H22: Company | I22: Target Price | J22: CMP | K22: U/D
A23: =H4 -> Nucor | B23: =Financials!F6+Financials!F7 -> 4228 | C23: =Financials!F10 -> 903 | D23: =Financials!F3 -> 30734 | E23: =Financials!F22 -> 21417 | H23: =H4 -> Nucor | I23: =AVERAGE(I4:L4) -> 614.71348 | J23: ='Company Profile'!B3 -> 148.58 | K23: =(Table24[[#This Row],[Target Price]]-J23)/J23 -> 3.1372559
A24: =H5 -> Freeport | B24: =Financials!M6+Financials!M7 -> 11346 | C24: =Financials!M10 -> 4022 | D24: =Financials!M3 -> 25455 | E24: =Financials!M22 -> 28778 | H24: =H5 -> Freeport | I24: =AVERAGE(I5:L5) -> 123.02097 | J24: ='Company Profile'!C3 -> 41.24 | K24: =(Table24[[#This Row],[Target Price]]-J24)/J24 -> 1.9830497
