Workbook

Sheet Profile
A1: Company | B1: #VALUE! | C1: #VALUE! | D1: #VALUE! | E1: #VALUE! | F1: #VALUE!
A2: Name | B2: {=_FV(B1,"Official name",TRUE)} -> AT&T INC. | C2: {=_FV(C1,"Official name",TRUE)} -> VERIZON COMMUNICATIONS INC. | D2: {=_FV(D1,"Official name",TRUE)} -> CHARTER COMMUNICATIONS, INC. | E2: {=_FV(E1,"Official name",TRUE)} -> COMCAST CORPORATION | F2: {=_FV(F1,"Official name",TRUE)} -> T-MOBILE US, INC.
A3: Share price | B3: {=_FV(B1,"Price")} -> 25.195 | C3: {=_FV(C1,"Price")} -> 41.1098 | D3: {=_FV(D1,"Price")} -> 195.11 | E3: {=_FV(E1,"Price")} -> 26.905 | F3: {=_FV(F1,"Price")} -> 210.79
A4: Change (%) | B4: {=_FV(B1,"Change (%)",TRUE)} -> -0.01582 | C4: {=_FV(C1,"Change (%)",TRUE)} -> -0.008925 | D4: {=_FV(D1,"Change (%)",TRUE)} -> -0.027804 | E4: {=_FV(E1,"Change (%)",TRUE)} -> -0.01663 | F4: {=_FV(F1,"Change (%)",TRUE)} -> -0.010747
A5: Shares Outstanding | B5: {=_FV(B1,"Shares outstanding",TRUE)} -> 7089450000 | C5: {=_FV(C1,"Shares outstanding",TRUE)} -> 4216425000 | D5: {=_FV(D1,"Shares outstanding",TRUE)} -> 129409400 | E5: {=_FV(E1,"Shares outstanding",TRUE)} -> 3643895000 | F5: {=_FV(F1,"Shares outstanding",TRUE)} -> 1118507000
A6: in mn | B6: =B5/1000000 -> 7089.45 | C6: =C5/1000000 -> 4216.425 | D6: =D5/1000000 -> 129.4094 | E6: =E5/1000000 -> 3643.895 | F6: =F5/1000000 -> 1118.507
A7: Market cap | B7: {=_FV(B1,"Market cap",TRUE)} -> 178618692750 | C7: {=_FV(C1,"Market cap",TRUE)} -> 173336388465 | D7: {=_FV(D1,"Market cap",TRUE)} -> 25249068034 | E7: {=_FV(E1,"Market cap",TRUE)} -> 98038994975 | F7: {=_FV(F1,"Market cap",TRUE)} -> 235770090530
A8: in mn | B8: =B7/1000000 -> 178618.69 | C8: =C7/1000000 -> 173336.39 | D8: =D7/1000000 -> 25249.068 | E8: =E7/1000000 -> 98038.995 | F8: =F7/1000000 -> 235770.09
A9: Beta | B9: {=_FV(B1,"Beta")} -> 0.3547 | C9: {=_FV(C1,"Beta")} -> 0.3048 | D9: {=_FV(D1,"Beta")} -> 1.0825 | E9: {=_FV(E1,"Beta")} -> 0.8197 | F9: {=_FV(F1,"Beta")} -> 0.4281
A10: P/E | B10: {=_FV(B1,"P/E",TRUE)} -> 8.1752 | C10: {=_FV(C1,"P/E",TRUE)} -> 8.7641 | D10: {=_FV(D1,"P/E",TRUE)} -> 5.273 | E10: {=_FV(E1,"P/E",TRUE)} -> 4.4671 | F10: {=_FV(F1,"P/E",TRUE)} -> 20.2724
A11: Year | B11: {=_FV(B1,"Year incorporated",TRUE)} -> 1983 | C11: {=_FV(C1,"Year incorporated",TRUE)} -> 1983 | D11: {=_FV(D1,"Year incorporated",TRUE)} -> 2003 | E11: {=_FV(E1,"Year incorporated",TRUE)} -> 2001 | F11: {=_FV(F1,"Year incorporated",TRUE)} -> 2004

Sheet Financials
A1: INCOME STATEMENT | F1: =Relative!H13 -> AT&T | H1: INCOME STATEMENT | M1: =Relative!H14 -> Verizon | O1: INCOME STATEMENT | T1: =DCF!W1 -> Charter | W1: INCOME STATEMENT | AB1: =DCF!AE1 -> Comcast | AE1: INCOME STATEMENT | AJ1: =DCF!AM1 -> T-Mobile
A2: Particulars | B2: 2020 | C2: 2021 | D2: 2022 | E2: 2023 | F2: 2024 | H2: Particulars | I2: 2020 | J2: 2021 | K2: 2022 | L2: 2023 | M2: 2024 | O2: Particulars | P2: 2020 | Q2: 2021 | R2: 2022 | S2: 2023 | T2: 2024 | W2: Particulars | X2: 2020 | Y2: 2021 | Z2: 2022 | AA2: 2023 | AB2: 2024 | AE2: Particulars | AF2: 2020 | AG2: 2021 | AH2: 2022 | AI2: 2023 | AJ2: 2024
A3: Revenue | B3: 171760 | C3: 134038 | D3: 120741 | E3: 122428 | F3: 122336 | H3: Revenue | I3: 128292 | J3: 133613 | K3: 136835 | L3: 133974 | M3: 134788 | O3: Revenue | P3: 48097 | Q3: 51682 | R3: 54022 | S3: 54607 | T3: 55085 | W3: Revenue | X3: 103564 | Y3: 116385 | Z3: 121427 | AA3: 121572 | AB3: 123731 | AE3: Revenue | AF3: 68397 | AG3: 80118 | AH3: 79571 | AI3: 78558 | AJ3: 81400
A4: Cost of sales | B4: =19706+27305+32909 -> 79920 | C4: =23685+8106+28616 -> 60407 | D4: =24009+26839 -> 50848 | E4: =23136+26987 -> 50123 | F4: =22249+26972 -> 49221 | H4: Cost of sales | I4: =31401+19800 -> 51201 | J4: =31234+25067 -> 56301 | K4: =28637+30496 -> 59133 | L4: =28100+26787 -> 54887 | M4: =27997+26100 -> 54097 | O4: Cost of sales | P4: 0 | Q4: 0 | R4: 0 | S4: 0 | T4: 0 | W4: Cost of sales | X4: 0 | Y4: 0 | Z4: 0 | AA4: 0 | AB4: 0 | AE4: Cost of sales | AF4: =11878+16388 -> 28266 | AG4: =13934+22671 -> 36605 | AH4: =14666+21540 -> 36206 | AI4: =11655+18533 -> 30188 | AJ4: =10771+18882 -> 29653
A5: Opex | B5: =38039+18880 -> 56919 | C5: =29669+213 -> 29882 | D5: =28961+27498 -> 56459 | E5: =28874+1193 -> 30067 | F5: =28411+5075 -> 33486 | H5: Opex | I5: =31573 -> 31573 | J5: 28658 | K5: 30136 | L5: =32745+5841 -> 38586 | M5: 34113 | O5: Opex | P5: =39692-9704+143+15+66+31 -> 30243 | Q5: =41156-9345+101 -> 31912 | R5: =42060-8903-56 -> 33101 | S5: =42048-8696+517 -> 33869 | T5: =41967-8673+387 -> 33681 | W5: Opex | X5: =86071-8320-4780-1160 -> 71811 | Y5: =95568-8628-5176-2557 -> 79207 | Z5: =107385-8724-5097+861 -> 94425 | AA5: =98258-8854+5482-1252 -> 93634 | AB5: =100434-8729-6072+490 -> 86123 | AE5: Opex | AF5: =18926+418-29+405 -> 19720 | AG5: =20238+199 -> 20437 | AH5: =21607+477+1087+33 -> 23204 | AI5: =21311-25-68 -> 21218 | AJ5: =20818-113 -> 20705
A6: Operating income (EBIT) | B6: =B3-B4-B5 -> 34921 | C6: =C3-C4-C5 -> 43749 | D6: =D3-D4-D5 -> 13434 | E6: =E3-E4-E5 -> 42238 | F6: =F3-F4-F5 -> 39629 | H6: Operating income (EBIT) | I6: =I3-I4-I5 -> 45518 | J6: =J3-J4-J5 -> 48654 | K6: =K3-K4-K5 -> 47566 | L6: =L3-L4-L5 -> 40501 | M6: =M3-M4-M5 -> 46578 | O6: Operating income (EBIT) | P6: =P3-P4-P5 -> 17854 | Q6: =Q3-Q4-Q5 -> 19770 | R6: =R3-R4-R5 -> 20921 | S6: =S3-S4-S5 -> 20738 | T6: =T3-T4-T5 -> 21404 | W6: Operating income (EBIT) | X6: =X3-X4-X5 -> 31753 | Y6: =Y3-Y4-Y5 -> 37178 | Z6: =Z3-Z4-Z5 -> 27002 | AA6: =AA3-AA4-AA5 -> 27938 | AB6: =AB3-AB4-AB5 -> 37608 | AE6: Operating income (EBIT) | AF6: =AF3-AF4-AF5 -> 20411 | AG6: =AG3-AG4-AG5 -> 23076 | AH6: =AH3-AH4-AH5 -> 20161 | AI6: =AI3-AI4-AI5 -> 27152 | AJ6: =AJ3-AJ4-AJ5 -> 31042
A7: Depreciation & Amortization | B7: 28516 | C7: 17852 | D7: 18021 | E7: 18777 | F7: 20580 | H7: Depreciation & Amortization | I7: 16720 | J7: 16206 | K7: 17099 | L7: 17624 | M7: 17892 | O7: Depreciation & Amortization | P7: 9704 | Q7: 9345 | R7: 8903 | S7: 8696 | T7: 8673 | W7: Depreciation & Amortization | X7: =8320+4780 -> 13100 | Y7: =8628+5176 -> 13804 | Z7: =8724+5097 -> 13821 | AA7: =8854+5482 -> 14336 | AB7: =8729+6072 -> 14801 | AE7: Depreciation & Amortization | AF7: 14151 | AG7: 16383 | AH7: 13651 | AI7: 12818 | AJ7: 12919
A8: Interest expense | B8: 7925 | C8: 6716 | D8: 6108 | E8: 6704 | F8: 6759 | H8: Interest expense | I8: 4247 | J8: 3485 | K8: 3613 | L8: 5524 | M8: 6649 | O8: Interest expense | P8: 3848 | Q8: 4037 | R8: 4556 | S8: 5188 | T8: 5229 | W8: Interest expense | X8: 4588 | Y8: 4281 | Z8: 3896 | AA8: 4087 | AB8: 4134 | AE8: Interest expense | AF8: =2483+247 -> 2730 | AG8: 3342 | AH8: 3364 | AI8: 3335 | AJ8: 3411
A9: Income tax | B9: 965 | C9: 5395 | D9: 3780 | E9: 4225 | F9: 4445 | H9: Income tax | I9: 5619 | J9: 6802 | K9: 6523 | L9: 4892 | M9: 5030 | O9: Income tax | P9: 626 | Q9: 1068 | R9: 1613 | S9: 1593 | T9: 1649 | W9: Income tax | X9: 3364 | Y9: 5259 | Z9: 4359 | AA9: 5371 | AB9: 2796 | AE9: Income tax | AF9: 786 | AG9: 327 | AH9: 556 | AI9: 2682 | AJ9: 3373
A10: Net income | B10: =B6-B7-B8-B9 -> -2485 | C10: =C6-C7-C8-C9 -> 13786 | D10: =D6-D7-D8-D9 -> -14475 | E10: =E6-E7-E8-E9 -> 12532 | F10: =F6-F7-F8-F9 -> 7845 | H10: Net income | I10: =I6-I7-I8-I9 -> 18932 | J10: =J6-J7-J8-J9 -> 22161 | K10: =K6-K7-K8-K9 -> 20331 | L10: =L6-L7-L8-L9 -> 12461 | M10: =M6-M7-M8-M9 -> 17007 | O10: Net income | P10: =P6-P7-P8-P9 -> 3676 | Q10: =Q6-Q7-Q8-Q9 -> 5320 | R10: =R6-R7-R8-R9 -> 5849 | S10: =S6-S7-S8-S9 -> 5261 | T10: =T6-T7-T8-T9 -> 5853 | W10: Net income | X10: =X6-X7-X8-X9 -> 10701 | Y10: =Y6-Y7-Y8-Y9 -> 13834 | Z10: =Z6-Z7-Z8-Z9 -> 4926 | AA10: =AA6-AA7-AA8-AA9 -> 4144 | AB10: =AB6-AB7-AB8-AB9 -> 15877 | AE10: Net income | AF10: =AF6-AF7-AF8-AF9 -> 2744 | AG10: =AG6-AG7-AG8-AG9 -> 3024 | AH10: =AH6-AH7-AH8-AH9 -> 2590 | AI10: =AI6-AI7-AI8-AI9 -> 8317 | AJ10: =AJ6-AJ7-AJ8-AJ9 -> 11339
A12: BALANCE SHEET | H12: BALANCE SHEET | O12: BALANCE SHEET | W12: BALANCE SHEET | AE12: BALANCE SHEET
A13: Particulars | B13: 2020 | C13: 2021 | D13: 2022 | E13: 2023 | F13: 2024 | H13: Particulars | I13: 2020 | J13: 2021 | K13: 2022 | L13: 2023 | M13: 2024 | O13: Particulars | P13: 2020 | Q13: 2021 | R13: 2022 | S13: 2023 | T13: 2024 | W13: Particulars | X13: 2020 | Y13: 2021 | Z13: 2022 | AA13: 2023 | AB13: 2024 | AE13: Particulars | AF13: 2020 | AG13: 2021 | AH13: 2022 | AI13: 2023 | AJ13: 2024
A14: Cash & Cash equivalents | B14: 9740 | C14: 19223 | D14: 3701 | E14: 6722 | F14: 3298 | H14: Cash & Cash equivalents | I14: 22171 | J14: 2921 | K14: 2605 | L14: 2065 | M14: 4194 | O14: Cash & Cash equivalents | P14: 998 | Q14: 601 | R14: 645 | S14: 709 | T14: 459 | W14: Cash & Cash equivalents | X14: 11740 | Y14: 8711 | Z14: 4749 | AA14: 6215 | AB14: 7322 | AE14: Cash & Cash equivalents | AF14: 10385 | AG14: 6631 | AH14: 4507 | AI14: 5135 | AJ14: 5409
A15: Accounts receivables | B15: 20215 | C15: 12313 | D15: 11466 | E15: 10289 | F15: 9638 | H15: Accounts receivables | I15: 23917 | J15: 23846 | K15: 24506 | L15: 25085 | M15: 26109 | O15: Total assets | P15: 144206 | Q15: 142491 | R15: 144523 | S15: 147193 | T15: 150020 | W15: Total assets | X15: 273869 | Y15: 275905 | Z15: 257275 | AA15: 264811 | AB15: 266211 | AE15: Total assets | AF15: 200162 | AG15: 206563 | AH15: 211338 | AI15: 207682 | AJ15: 208035
A16: Inventories | B16: 0 | C16: 3325 | D16: 3123 | E16: 2177 | F16: 2270 | H16: Inventories | I16: 1796 | J16: 3055 | K16: 2388 | L16: 2057 | M16: 2247 | O16: Inventories | P16: 0 | Q16: 0 | R16: 0 | S16: 0 | T16: 0 | W16: Inventories | X16: 0 | Y16: 0 | Z16: 0 | AA16: 0 | AB16: 0 | AE16: Inventories | AF16: 2527 | AG16: 2567 | AH16: 1884 | AI16: 1678 | AJ16: 1607
A17: Total current assets | B17: 52008 | C17: 170768 | D17: 33108 | E17: 36458 | F17: 31168 | H17: Total current assets | I17: 54594 | J17: 36728 | K17: 37857 | L17: 36814 | M17: 40523 | O17: Total current assets | P17: 3906 | Q17: 3566 | R17: 4017 | S17: 4132 | T17: 4233 | W17: Total current assets | X17: 26741 | Y17: 24807 | Z17: 21826 | AA17: 23987 | AB17: 26801 | AE17: Total current assets | AF17: 23885 | AG17: 20891 | AH17: 19067 | AI17: 19015 | AJ17: 18404
A18: PPE | B18: 127315 | C18: 121649 | D18: 127445 | E18: 128489 | F18: 128871 | H18: PPE | I18: 94833 | J18: 99696 | K18: 107434 | L18: 108310 | M18: 108522 | O18: PPE | P18: 34357 | Q18: 34310 | R18: 36039 | S18: 39520 | T18: 42913 | W18: PPE | X18: 51995 | Y18: 54047 | Z18: 55485 | AA18: 59686 | AB18: 62548 | AE18: PPE | AF18: 41175 | AG18: 39803 | AH18: 42086 | AI18: 40432 | AJ18: 38533
A19: Accounts payables | B19: 49032 | C19: 39095 | D19: 42644 | E19: 35852 | F19: 35657 | H19: Accounts payables | I19: 20658 | J19: 24833 | K19: 23977 | L19: 23453 | M19: 23374 | O19: Accounts payables | P19: 8867 | Q19: 9461 | R19: 10555 | S19: 11214 | T19: 11687 | W19: Accounts payables | X19: 11364 | Y19: 12455 | Z19: 12544 | AA19: 12437 | AB19: 11321 | AE19: Accounts payables | AF19: 10196 | AG19: 11405 | AH19: 12275 | AI19: 10373 | AJ19: 8463
A20: Total current liabilities | B20: 63438 | C20: 106230 | D20: 56173 | E20: 51127 | F20: 46872 | H20: Total current liabilities | I20: 39660 | J20: 47160 | K20: 50171 | L20: 53223 | M20: 64771 | O20: Total current liabilities | P20: 9875 | Q20: 12458 | R20: 12065 | S20: 13214 | T20: 13486 | W20: Total current liabilities | X20: 28796 | Y20: 29348 | Z20: 27887 | AA20: 40198 | AB20: 39581 | AE20: Total current liabilities | AF20: 21703 | AG20: 23499 | AH20: 24742 | AI20: 20928 | AJ20: 20174
A21: Total debt | B21: =3470+153775 -> 157245 | C21: =24620+151011 -> 175631 | D21: =7467+128423 -> 135890 | E21: =9477+127854 -> 137331 | F21: =5089+118443 -> 123532 | H21: Total debt | I21: =5889+123173 -> 129062 | J21: =7443+143425 -> 150868 | K21: =9963+140676 -> 150639 | L21: =12973+137701 -> 150674 | M21: =22633+121381 -> 144014 | O21: Total debt | P21: =1008+81744 -> 82752 | Q21: =2997+88564 -> 91561 | R21: =1510+96093 -> 97603 | S21: =2000+95777 -> 97777 | T21: =1799+92134 -> 93933 | W21: Total debt | X21: =3146+100614 -> 103760 | Y21: =2132+92718 -> 94850 | Z21: =1743+93068 -> 94811 | AA21: =2069+95021 -> 97090 | AB21: =4907+94186 -> 99093 | AE21: Total debt | AF21: =4579+61830+4716 -> 71125 | AG21: =3378+2245+67076+1494 -> 74193 | AH21: =5164+65301+1495 -> 71960 | AI21: =3619+69903+1496 -> 75018 | AJ21: =4068+72700+1497 -> 78265
A22: Shareholder's equity | B22: 179240 | C22: 183855 | D22: 106457 | E22: 117442 | F22: 118245 | H22: Shareholder's equity | I22: 69272 | J22: 83200 | K22: 92463 | L22: 93799 | M22: 100575 | O22: Shareholder's equity | P22: 30281 | Q22: 18156 | R22: 12549 | S22: 14718 | T22: 19707 | W22: Shareholder's equity | X22: 91738 | Y22: 97490 | Z22: 81627 | AA22: 83226 | AB22: 86038 | AE22: Shareholder's equity | AF22: 65344 | AG22: 69102 | AH22: 69656 | AI22: 64715 | AJ22: 61741
A24: CASH FLOW STATEMENT | H24: CASH FLOW STATEMENT | O24: CASH FLOW STATEMENT | W24: CASH FLOW STATEMENT | AE24: CASH FLOW STATEMENT
A25: Particulars | B25: 2020 | C25: 2021 | D25: 2022 | E25: 2023 | F25: 2024 | H25: Particulars | I25: 2020 | J25: 2021 | K25: 2022 | L25: 2023 | M25: 2024 | O25: Particulars | P25: 2020 | Q25: 2021 | R25: 2022 | S25: 2023 | T25: 2024 | W25: Particulars | X25: 2020 | Y25: 2021 | Z25: 2022 | AA25: 2023 | AB25: 2024 | AE25: Particulars | AF25: 2020 | AG25: 2021 | AH25: 2022 | AI25: 2023 | AJ25: 2024
A26: Cash flow from operating activities | B26: 43130 | C26: 37170 | D26: 35812 | E26: 38314 | F26: 38771 | H26: Cash flow from operating activities | I26: 41768 | J26: 39539 | K26: 37141 | L26: 37475 | M26: 36912 | O26: Cash flow from operating activities | P26: 14562 | Q26: 16239 | R26: 14925 | S26: 14433 | T26: 14430 | W26: Cash flow from operating activities | X26: 24737 | Y26: 29146 | Z26: 26413 | AA26: 28501 | AB26: 27673 | AE26: Cash flow from operating activities | AF26: 8640 | AG26: 13917 | AH26: 16781 | AI26: 18559 | AJ26: 22293
A27: Capex | B27: 15675 | C27: 15545 | D27: 19626 | E27: 17853 | F27: 20263 | H27: Capex | I27: 18192 | J27: 20286 | K27: 23087 | L27: 18767 | M27: 17090 | O27: Capex | P27: 7415 | Q27: 7635 | R27: 9376 | S27: 11115 | T27: 11269 | W27: Capex | X27: 9179 | Y27: 9174 | Z27: 10626 | AA27: 12242 | AB27: 12181 | AE27: Capex | AF27: 11034 | AG27: 12326 | AH27: 13970 | AI27: 9801 | AJ27: 8840
A28: Dividends paid | B28: 14956 | C28: 15068 | D28: 9859 | E28: 8136 | F28: 8208 | H28: Dividends paid | I28: 10232 | J28: 10445 | K28: 10805 | L28: 11025 | M28: 11249 | O28: Dividends paid | P28: 0 | Q28: 0 | R28: 0 | S28: 0 | T28: 0 | W28: Dividends paid | X28: 4140 | Y28: 4532 | Z28: 4741 | AA28: 4766 | AB28: 4814 | AE28: Dividends paid | AF28: 0 | AG28: 0 | AH28: 0 | AI28: 0 | AJ28: 0
A29: Debt repaid | B29: =9467+39964 -> 49431 | C29: =7510+3039 -> 10549 | D29: =18345+25118 -> 43463 | E29: =3415+12044 -> 15459 | F29: =2487+10297 -> 12784 | H29: Debt repaid | I29: =9775+7413 -> 17188 | J29: =14063+4800 -> 18863 | K29: =8616+4948 -> 13564 | L29: =6181+4443 -> 10624 | M29: =11854+8490 -> 20344 | O29: Debt repaid | P29: =12094+125 -> 12219 | Q29: 12146 | R29: 19311 | S29: 21938 | T29: 29660 | W29: Debt repaid | X29: 18777 | Y29: 11498 | Z29: 2307 | AA29: =660+4015 -> 4675 | AB29: 3573 | AE29: Debt repaid | AF29: =481+20416+18929+82 -> 39908 | AG29: =184+11100+116 -> 11400 | AH29: =5556 -> 5556 | AI29: 5051 | AJ29: 5073
O32: Particulars | P32: 2020 | Q32: 2021 | R32: 2022 | S32: 2023 | T32: 2024 | W32: Particulars | X32: 2020 | Y32: 2021 | Z32: 2022 | AA32: 2023 | AB32: 2024 | AE32: Particulars | AF32: 2020 | AG32: 2021 | AH32: 2022 | AI32: 2023 | AJ32: 2024
O33: Revenue | P33: =P3 -> 48097 | Q33: =Q3 -> 51682 | R33: =R3 -> 54022 | S33: =S3 -> 54607 | T33: =T3 -> 55085 | W33: Revenue | X33: =X3 -> 103564 | Y33: =Y3 -> 116385 | Z33: =Z3 -> 121427 | AA33: =AA3 -> 121572 | AB33: =AB3 -> 123731 | AE33: Revenue | AF33: =AF3 -> 68397 | AG33: =AG3 -> 80118 | AH33: =AH3 -> 79571 | AI33: =AI3 -> 78558 | AJ33: =AJ3 -> 81400
O34: Operating income | P34: =P6 -> 17854 | Q34: =Q6 -> 19770 | R34: =R6 -> 20921 | S34: =S6 -> 20738 | T34: =T6 -> 21404 | W34: Operating income | X34: =X6 -> 31753 | Y34: =Y6 -> 37178 | Z34: =Z6 -> 27002 | AA34: =AA6 -> 27938 | AB34: =AB6 -> 37608 | AE34: Operating income | AF34: =AF6 -> 20411 | AG34: =AG6 -> 23076 | AH34: =AH6 -> 20161 | AI34: =AI6 -> 27152 | AJ34: =AJ6 -> 31042
O35: Net Income | P35: =P10 -> 3676 | Q35: =Q10 -> 5320 | R35: =R10 -> 5849 | S35: =S10 -> 5261 | T35: =T10 -> 5853 | W35: Net Income | X35: =X10 -> 10701 | Y35: =Y10 -> 13834 | Z35: =Z10 -> 4926 | AA35: =AA10 -> 4144 | AB35: =AB10 -> 15877 | AE35: Net Income | AF35: =AF10 -> 2744 | AG35: =AG10 -> 3024 | AH35: =AH10 -> 2590 | AI35: =AI10 -> 8317 | AJ35: =AJ10 -> 11339
O37: Particulars | P37: 2025 | Q37: 2026 | R37: 2027 | S37: 2028 | T37: 2029 | U37: 2030 | W37: Particulars | X37: 2025 | Y37: 2026 | Z37: 2027 | AA37: 2028 | AB37: 2029 | AC37: 2030 | AE37: Particulars | AF37: 2025 | AG37: 2026 | AH37: 2027 | AI37: 2028 | AJ37: 2029 | AK37: 2030
O38: Revenue | P38: =DCF!R3 -> 56599.999 | Q38: =DCF!S3 -> 58156.666 | R38: =DCF!T3 -> 59756.145 | S38: =DCF!U3 -> 61399.615 | T38: =DCF!V3 -> 63088.285 | U38: =DCF!W3 -> 64823.398 | W38: Revenue | X38: =DCF!Z3 -> 128213.12 | Y38: =DCF!AA3 -> 132857.6 | Z38: =DCF!AB3 -> 137670.33 | AA38: =DCF!AC3 -> 142657.39 | AB38: =DCF!AD3 -> 147825.12 | AC38: =DCF!AE3 -> 153180.04 | AE38: Revenue | AF38: =DCF!AH3 -> 84283.367 | AG38: =DCF!AI3 -> 87268.869 | AH38: =DCF!AJ3 -> 90360.124 | AI38: =DCF!AK3 -> 93560.877 | AJ38: =DCF!AL3 -> 96875.009 | AK38: =DCF!AM3 -> 100306.53
O39: Operating income | P39: =DCF!R4 -> 21628.218 | Q39: =DCF!S4 -> 22223.058 | R39: =DCF!T4 -> 22834.257 | S39: =DCF!U4 -> 23462.267 | T39: =DCF!V4 -> 24107.548 | U39: =DCF!W4 -> 24770.576 | W39: Operating income | X39: =DCF!Z4 -> 35289.7 | Y39: =DCF!AA4 -> 36568.059 | Z39: =DCF!AB4 -> 37892.727 | AA39: =DCF!AC4 -> 39265.379 | AB39: =DCF!AD4 -> 40687.756 | AC39: =DCF!AE4 -> 42161.658 | AE39: Operating income | AF39: =DCF!AH4 -> 26464.148 | AG39: =DCF!AI4 -> 27401.567 | AH39: =DCF!AJ4 -> 28372.19 | AI39: =DCF!AK4 -> 29377.195 | AJ39: =DCF!AL4 -> 30417.8 | AK39: =DCF!AM4 -> 31495.265
O40: Net income | P40: =DCF!R5 -> 16653.728 | Q40: =DCF!S5 -> 17111.755 | R40: =DCF!T5 -> 17582.378 | S40: =DCF!U5 -> 18065.945 | T40: =DCF!V5 -> 18562.812 | U40: =DCF!W5 -> 19073.344 | W40: Net income | X40: =DCF!Z5 -> 27173.069 | Y40: =DCF!AA5 -> 28157.406 | Z40: =DCF!AB5 -> 29177.399 | AA40: =DCF!AC5 -> 30234.342 | AB40: =DCF!AD5 -> 31329.572 | AC40: =DCF!AE5 -> 32464.477 | AE40: Net income | AF40: =DCF!AH5 -> 20377.394 | AG40: =DCF!AI5 -> 21099.206 | AH40: =DCF!AJ5 -> 21846.586 | AI40: =DCF!AK5 -> 22620.44 | AJ40: =DCF!AL5 -> 23421.706 | AK40: =DCF!AM5 -> 24251.354

Sheet Assumptions & WACC
A1: Assumptions | N1: .
A2: Metric | B2: =Relative!H13 -> AT&T | C2: =Relative!H14 -> Verizon | D2: Charter | E2: Comcast | F2: T-Mobile | H2: Current WC | I2: 2020 | J2: 2021 | K2: 2022 | L2: 2023 | M2: 2024
A3: Revenue CAGR | B3: =(Table1[[#This Row],[2024]]/Table1[[#This Row],[2020]])^(1/5)-1 -> -0.065613728 | C3: =(Table18[[#This Row],[2024]]/Table18[[#This Row],[2020]])^(1/5)-1 -> 0.0099278085 | D3: =(Table141[[#This Row],[2024]]/Table141[[#This Row],[2020]])^(1/5)-1 -> 0.02750294 | E3: =(Table1844[[#This Row],[2024]]/Table1844[[#This Row],[2020]])^(1/5)-1 -> 0.036224703 | F3: =(Table184447[[#This Row],[2024]]/Table184447[[#This Row],[2020]])^(1/5)-1 -> 0.035422195 | H3: =Relative!H13 -> AT&T | I3: =Financials!B17-Financials!B20 -> -11430 | J3: =Financials!C17-Financials!C20 -> 64538 | K3: =Financials!D17-Financials!D20 -> -23065 | L3: =Financials!E17-Financials!E20 -> -14669 | M3: =Financials!F17-Financials!F20 -> -15704
A4: Operating margin (EBIT) | B4: =(AVERAGE(Financials!B6:F6)/AVERAGE(Financials!B3:F3)) -> 0.25915421 | C4: =AVERAGE(Financials!I6:M6)/AVERAGE(Financials!I3:M3) -> 0.34279598 | D4: =AVERAGE(Financials!P6:T6)/AVERAGE(Financials!P3:T3) -> 0.382124 | E4: =AVERAGE(Financials!X6:AB6)/AVERAGE(Financials!X3:AB3) -> 0.27524251 | F4: =AVERAGE(Financials!AF6:AJ6)/AVERAGE(Financials!AF3:AJ3) -> 0.31399017 | H4: =Relative!H14 -> Verizon | I4: =Financials!I17-Financials!I20 -> 14934 | J4: =Financials!J17-Financials!J20 -> -10432 | K4: =Financials!K17-Financials!K20 -> -12314 | L4: =Financials!L17-Financials!L20 -> -16409 | M4: =Financials!M17-Financials!M20 -> -24248
A5: Depreciation rate | B5: =AVERAGE(Financials!B7:F7)/AVERAGE(Financials!B3:F3) -> 0.15454422 | C5: =AVERAGE(Financials!I7:M7)/AVERAGE(Financials!I3:M3) -> 0.12815093 | D5: =AVERAGE(Financials!P7:T7)/AVERAGE(Financials!P3:T3) -> 0.17200077 | E5: =AVERAGE(Financials!X7:AB7)/AVERAGE(Financials!X3:AB3) -> 0.11908045 | F5: =AVERAGE(Financials!AF7:AJ7)/AVERAGE(Financials!AF3:AJ3) -> 0.18019091 | H5: =Relative!H15 -> Charter | I5: =Financials!P17-Financials!P20 -> -5969 | J5: =Financials!Q17-Financials!Q20 -> -8892 | K5: =Financials!R17-Financials!R20 -> -8048 | L5: =Financials!S17-Financials!S20 -> -9082 | M5: =Financials!T17-Financials!T20 -> -9253
A6: CapEx | B6: =AVERAGE(Financials!B27:F27)/AVERAGE(Financials!B3:F3) -> 0.13252138 | C6: =AVERAGE(Financials!I27:M27)/AVERAGE(Financials!I3:M3) -> 0.14595012 | D6: =AVERAGE(Financials!P27:T27)/AVERAGE(Financials!P3:T3) -> 0.17765178 | E6: =AVERAGE(Financials!X27:AB27)/AVERAGE(Financials!X3:AB3) -> 0.091024223 | F6: =AVERAGE(Financials!AF27:AJ27)/AVERAGE(Financials!AF3:AJ3) -> 0.1442388 | H6: =Relative!H16 -> Comcast | I6: =Financials!X17-Financials!X20 -> -2055 | J6: =Financials!Y17-Financials!Y20 -> -4541 | K6: =Financials!Z17-Financials!Z20 -> -6061 | L6: =Financials!AA17-Financials!AA20 -> -16211 | M6: =Financials!AB17-Financials!AB20 -> -12780
A7: Working capital | B7: =AVERAGE(K3:M3)/AVERAGE(Financials!D3:F3) -> -0.1462032 | C7: =AVERAGE(J4:M4)/AVERAGE(Financials!J3:M3) -> -0.11758499 | D7: =AVERAGE(I5:M5)/AVERAGE(Financials!P3:T3) -> -0.15652788 | E7: =AVERAGE(I6:M6)/AVERAGE(Financials!X3:AB3) -> -0.070989417 | F7: =AVERAGE(Table19[[#This Row],[2020]:[2024]])/AVERAGE(Financials!AF3:AJ3) -> -0.025213636 | H7: =Relative!H17 -> T-Mobile | I7: =Financials!AF17-Financials!AF20 -> 2182 | J7: =Financials!AG17-Financials!AG20 -> -2608 | K7: =Financials!AH17-Financials!AH20 -> -5675 | L7: =Financials!AI17-Financials!AI20 -> -1913 | M7: =Financials!AJ17-Financials!AJ20 -> -1770
A8: Forecast horizon (yrs) | B8: 6 | C8: 6 | D8: 6 | E8: 6 | F8: 6
A9: Risk-free rate | B9: =$H$20 -> 0.041057 | C9: =$H$20 -> 0.041057 | D9: =$H$20 -> 0.041057 | E9: =$H$20 -> 0.041057 | F9: =$H$20 -> 0.041057
A10: Equity risk premium | B10: 0.048 | C10: 0.048 | D10: 0.048 | E10: 0.048 | F10: 0.048 | H10: Forecast WC | I10: 2025 | J10: 2026 | K10: 2027 | L10: 2028 | M10: 2029 | N10: 2030
A11: Beta | B11: =Profile!B9 -> 0.3547 | C11: =Profile!C9 -> 0.3048 | D11: =Profile!D9 -> 1.0825 | E11: =Profile!E9 -> 0.8197 | F11: =Profile!F9 -> 0.4281 | H11: =H3 -> AT&T | I11: =DCF!B3*'Assumptions & WACC'!$B$7 -> -16712.353 | J11: =DCF!C3*'Assumptions & WACC'!$B$7 -> -15615.793 | K11: =DCF!D3*'Assumptions & WACC'!$B$7 -> -14591.183 | L11: =DCF!E3*'Assumptions & WACC'!$B$7 -> -13633.801 | M11: =DCF!F3*'Assumptions & WACC'!$B$7 -> -12739.236 | N11: =DCF!G3*'Assumptions & WACC'!$B$7 -> -11903.368
A12: Cost of equity | B12: =B9+(B10*B11) -> 0.0580826 | C12: =C9+(C10*C11) -> 0.0556874 | D12: =D9+(D10*D11) -> 0.093017 | E12: =E9+(E10*E11) -> 0.0804026 | F12: =F9+(F10*F11) -> 0.0616058 | H12: =H4 -> Verizon | I12: =DCF!J3*'Assumptions & WACC'!$C$7 -> -16006.391 | J12: =DCF!K3*'Assumptions & WACC'!$C$7 -> -16165.3 | K12: =DCF!L3*'Assumptions & WACC'!$C$7 -> -16325.786 | L12: =DCF!M3*'Assumptions & WACC'!$C$7 -> -16487.865 | M12: =DCF!N3*'Assumptions & WACC'!$C$7 -> -16651.553 | N12: =DCF!O3*'Assumptions & WACC'!$C$7 -> -16816.867
A13: Kd (pre-tax) | B13: =AVERAGE(Financials!B8:F8)/AVERAGE(Financials!B21:F21) -> 0.046889584 | C13: =AVERAGE(Financials!I8:M8)/AVERAGE(Financials!I21:M21) -> 0.032427126 | D13: =AVERAGE(Financials!P8:T8)/AVERAGE(Financials!P21:T21) -> 0.049302671 | E13: =AVERAGE(Financials!X8:AB8)/AVERAGE(Financials!X21:AB21) -> 0.042863212 | F13: =AVERAGE(Financials!AF8:AJ8)/AVERAGE(Financials!AF21:AJ21) -> 0.043668924 | H13: =H5 -> Charter | I13: =DCF!R3*'Assumptions & WACC'!$D$7 -> -8859.4778 | J13: =DCF!S3*'Assumptions & WACC'!$D$7 -> -9103.1395 | K13: =DCF!T3*'Assumptions & WACC'!$D$7 -> -9353.5025 | L13: =DCF!U3*'Assumptions & WACC'!$D$7 -> -9610.7514 | M13: =DCF!V3*'Assumptions & WACC'!$D$7 -> -9875.0753 | N13: =DCF!W3*'Assumptions & WACC'!$D$7 -> -10146.669
A14: Tax rate | B14: 0.23 | C14: 0.23 | D14: 0.23 | E14: 0.23 | F14: 0.23 | H14: =H6 -> Comcast | I14: =DCF!Z3*'Assumptions & WACC'!$E$7 -> -9101.7745 | J14: =DCF!AA3*'Assumptions & WACC'!$E$7 -> -9431.4836 | K14: =DCF!AB3*'Assumptions & WACC'!$E$7 -> -9773.1363 | L14: =DCF!AC3*'Assumptions & WACC'!$E$7 -> -10127.165 | M14: =DCF!AD3*'Assumptions & WACC'!$E$7 -> -10494.019 | N14: =DCF!AE3*'Assumptions & WACC'!$E$7 -> -10874.162
A15: Kd (after tax) | B15: =B13*(1-B14) -> 0.036104979 | C15: =C13*(1-C14) -> 0.024968887 | D15: =D13*(1-D14) -> 0.037963056 | E15: =E13*(1-E14) -> 0.033004673 | F15: =F13*(1-F14) -> 0.033625071 | H15: =H7 -> T-Mobile | I15: =DCF!AH3*'Assumptions & WACC'!$F$7 -> -2125.0901 | J15: =DCF!AI3*'Assumptions & WACC'!$F$7 -> -2200.3654 | K15: =DCF!AJ3*'Assumptions & WACC'!$F$7 -> -2278.3072 | L15: =DCF!AK3*'Assumptions & WACC'!$F$7 -> -2359.0099 | M15: =DCF!AL3*'Assumptions & WACC'!$F$7 -> -2442.5712 | N15: =DCF!AM3*'Assumptions & WACC'!$F$7 -> -2529.0924
A16: Total debt | B16: =Financials!F21 -> 123532 | C16: =Financials!M21 -> 144014 | D16: =Financials!T21 -> 93933 | E16: =Financials!AB21 -> 99093 | F16: =Financials!AJ21 -> 78265
A17: Market cap | B17: =Profile!B8 -> 178618.69 | C17: =Profile!C8 -> 173336.39 | D17: =Profile!D8 -> 25249.068 | E17: =Profile!E8 -> 98038.995 | F17: =Profile!F8 -> 235770.09
A18: Total capital | B18: =B16+B17 -> 302150.69 | C18: =C16+C17 -> 317350.39 | D18: =D16+D17 -> 119182.07 | E18: =E16+E17 -> 197131.99 | F18: =F16+F17 -> 314035.09
A19: Debt weight | B19: =B16/B18 -> 0.40884235 | C19: =C16/C18 -> 0.45380124 | D19: =D16/D18 -> 0.78814709 | E19: =E16/E18 -> 0.50267335 | F19: =F16/F18 -> 0.24922374 | H19: #VALUE!
A20: Equity weight | B20: =B17/B18 -> 0.59115765 | C20: =C17/C18 -> 0.54619876 | D20: =D17/D18 -> 0.21185291 | E20: =E17/E18 -> 0.49732665 | F20: =F17/F18 -> 0.75077626 | H20: {=(_FV(H19,"Price"))/100} -> 0.041057
A21: WACC | B21: =(B12*B20)+(B15*B19) -> 0.049097218 | C21: =(C12*C20)+(C15*C19) -> 0.041747301 | D21: =(D12*D20)+(D15*D19) -> 0.049626395 | E21: =(E12*E20)+(E15*E19) -> 0.056576925 | F21: =(F12*F20)+(F15*F19) -> 0.054632338
A22: Terminal year | B22: 2030 | C22: 2030 | D22: 2030 | E22: 2030 | F22: 2030
A23: PV discount rate (terminal year) | B23: =1/(1+B21)^6 -> 0.75007655 | C23: =1/(1+C21)^6 -> 0.78239433 | D23: =1/(1+D21)^6 -> 0.74781047 | E23: =1/(1+E21)^6 -> 0.71877551 | F23: =1/(1+F21)^6 -> 0.72676415
A24: Cash & cash equivalents | B24: =Financials!F14 -> 3298 | C24: =Financials!M14 -> 4194 | D24: =Financials!T14 -> 459 | E24: =Financials!AB14 -> 7322 | F24: =Financials!AJ14 -> 5409
A25: Terminal growth rate | B25: 0.005 | C25: 0.005 | D25: 0.005 | E25: 0.005 | F25: 0.005
A26: Shares Outstanding | B26: =Profile!B6 -> 7089.45 | C26: =Profile!C6 -> 4216.425 | D26: =Profile!D6 -> 129.4094 | E26: =Profile!E6 -> 3643.895 | F26: =Profile!F6 -> 1118.507

Sheet DCF
A1: DCF | G1: AT&T | O1: Verizon | Q1: DCF | W1: Charter | AE1: Comcast | AG1: DCF | AM1: T-Mobile
A2: Particulars | B2: 2025 | C2: 2026 | D2: 2027 | E2: 2028 | F2: 2029 | G2: 2030 | I2: Particulars | J2: 2025 | K2: 2026 | L2: 2027 | M2: 2028 | N2: 2029 | O2: 2030 | Q2: Particulars | R2: 2025 | S2: 2026 | T2: 2027 | U2: 2028 | V2: 2029 | W2: 2030 | Y2: Particulars | Z2: 2025 | AA2: 2026 | AB2: 2027 | AC2: 2028 | AD2: 2029 | AE2: 2030 | AG2: Particulars | AH2: 2025 | AI2: 2026 | AJ2: 2027 | AK2: 2028 | AL2: 2029 | AM2: 2030
A3: Revenue | B3: =Table1[[#This Row],[2024]]*(1+'Assumptions & WACC'!B3) -> 114309.08 | C3: =Table9[[#This Row],[2025]]*(1+'Assumptions & WACC'!$B$3) -> 106808.83 | D3: =Table9[[#This Row],[2026]]*(1+'Assumptions & WACC'!$B$3) -> 99800.708 | E3: =Table9[[#This Row],[2027]]*(1+'Assumptions & WACC'!$B$3) -> 93252.412 | F3: =Table9[[#This Row],[2028]]*(1+'Assumptions & WACC'!$B$3) -> 87133.773 | G3: =Table9[[#This Row],[2029]]*(1+'Assumptions & WACC'!$B$3) -> 81416.602 | I3: Revenue | J3: =Table18[[#This Row],[2024]]*(1+'Assumptions & WACC'!C3) -> 136126.15 | K3: =Table10[[#This Row],[2025]]*(1+'Assumptions & WACC'!$C$3) -> 137477.58 | L3: =Table10[[#This Row],[2026]]*(1+'Assumptions & WACC'!$C$3) -> 138842.43 | M3: =Table10[[#This Row],[2027]]*(1+'Assumptions & WACC'!$C$3) -> 140220.84 | N3: =Table10[[#This Row],[2028]]*(1+'Assumptions & WACC'!$C$3) -> 141612.92 | O3: =Table10[[#This Row],[2029]]*(1+'Assumptions & WACC'!$C$3) -> 143018.83 | Q3: Revenue | R3: =Table141[[#This Row],[2024]]*(1+'Assumptions & WACC'!D3) -> 56599.999 | S3: =Table919[[#This Row],[2025]]*(1+'Assumptions & WACC'!$D$3) -> 58156.666 | T3: =Table919[[#This Row],[2026]]*(1+'Assumptions & WACC'!$D$3) -> 59756.145 | U3: =Table919[[#This Row],[2027]]*(1+'Assumptions & WACC'!$D$3) -> 61399.615 | V3: =Table919[[#This Row],[2028]]*(1+'Assumptions & WACC'!$D$3) -> 63088.285 | W3: =Table919[[#This Row],[2029]]*(1+'Assumptions & WACC'!$D$3) -> 64823.398 | Y3: Revenue | Z3: =Table1844[[#This Row],[2024]]*(1+'Assumptions & WACC'!E3) -> 128213.12 | AA3: =Table1024[[#This Row],[2025]]*(1+'Assumptions & WACC'!$E$3) -> 132857.6 | AB3: =Table1024[[#This Row],[2026]]*(1+'Assumptions & WACC'!$E$3) -> 137670.33 | AC3: =Table1024[[#This Row],[2027]]*(1+'Assumptions & WACC'!$E$3) -> 142657.39 | AD3: =Table1024[[#This Row],[2028]]*(1+'Assumptions & WACC'!$E$3) -> 147825.12 | AE3: =Table1024[[#This Row],[2029]]*(1+'Assumptions & WACC'!$E$3) -> 153180.04 | AG3: Revenue | AH3: =Table184447[[#This Row],[2024]]*(1+'Assumptions & WACC'!F3) -> 84283.367 | AI3: =Table91934[[#This Row],[2025]]*(1+'Assumptions & WACC'!$F$3) -> 87268.869 | AJ3: =Table91934[[#This Row],[2026]]*(1+'Assumptions & WACC'!$F$3) -> 90360.124 | AK3: =Table91934[[#This Row],[2027]]*(1+'Assumptions & WACC'!$F$3) -> 93560.877 | AL3: =Table91934[[#This Row],[2028]]*(1+'Assumptions & WACC'!$F$3) -> 96875.009 | AM3: =Table91934[[#This Row],[2029]]*(1+'Assumptions & WACC'!$F$3) -> 100306.53
A4: EBIT | B4: =B3*'Assumptions & WACC'!$B$4 -> 29623.679 | C4: =C3*'Assumptions & WACC'!$B$4 -> 27679.959 | D4: =D3*'Assumptions & WACC'!$B$4 -> 25863.774 | E4: =E3*'Assumptions & WACC'!$B$4 -> 24166.755 | F4: =F3*'Assumptions & WACC'!$B$4 -> 22581.084 | G4: =G3*'Assumptions & WACC'!$B$4 -> 21099.455 | I4: EBIT | J4: =J3*'Assumptions & WACC'!$C$4 -> 46663.496 | K4: =K3*'Assumptions & WACC'!$C$4 -> 47126.763 | L4: =L3*'Assumptions & WACC'!$C$4 -> 47594.628 | M4: =M3*'Assumptions & WACC'!$C$4 -> 48067.138 | N4: =N3*'Assumptions & WACC'!$C$4 -> 48544.34 | O4: =O3*'Assumptions & WACC'!$C$4 -> 49026.279 | Q4: EBIT | R4: =R3*'Assumptions & WACC'!$D$4 -> 21628.218 | S4: =S3*'Assumptions & WACC'!$D$4 -> 22223.058 | T4: =T3*'Assumptions & WACC'!$D$4 -> 22834.257 | U4: =U3*'Assumptions & WACC'!$D$4 -> 23462.267 | V4: =V3*'Assumptions & WACC'!$D$4 -> 24107.548 | W4: =W3*'Assumptions & WACC'!$D$4 -> 24770.576 | Y4: EBIT | Z4: =Z3*'Assumptions & WACC'!$E$4 -> 35289.7 | AA4: =AA3*'Assumptions & WACC'!$E$4 -> 36568.059 | AB4: =AB3*'Assumptions & WACC'!$E$4 -> 37892.727 | AC4: =AC3*'Assumptions & WACC'!$E$4 -> 39265.379 | AD4: =AD3*'Assumptions & WACC'!$E$4 -> 40687.756 | AE4: =AE3*'Assumptions & WACC'!$E$4 -> 42161.658 | AG4: EBIT | AH4: =AH3*'Assumptions & WACC'!$F$4 -> 26464.148 | AI4: =AI3*'Assumptions & WACC'!$F$4 -> 27401.567 | AJ4: =AJ3*'Assumptions & WACC'!$F$4 -> 28372.19 | AK4: =AK3*'Assumptions & WACC'!$F$4 -> 29377.195 | AL4: =AL3*'Assumptions & WACC'!$F$4 -> 30417.8 | AM4: =AM3*'Assumptions & WACC'!$F$4 -> 31495.265
A5: NOPAT | B5: =B4*(1-'Assumptions & WACC'!$B$14) -> 22810.233 | C5: =C4*(1-'Assumptions & WACC'!$B$14) -> 21313.569 | D5: =D4*(1-'Assumptions & WACC'!$B$14) -> 19915.106 | E5: =E4*(1-'Assumptions & WACC'!$B$14) -> 18608.402 | F5: =F4*(1-'Assumptions & WACC'!$B$14) -> 17387.435 | G5: =G4*(1-'Assumptions & WACC'!$B$14) -> 16246.581 | I5: NOPAT | J5: =J4*(1-'Assumptions & WACC'!$C$14) -> 35930.892 | K5: =K4*(1-'Assumptions & WACC'!$C$14) -> 36287.607 | L5: =L4*(1-'Assumptions & WACC'!$C$14) -> 36647.864 | M5: =M4*(1-'Assumptions & WACC'!$C$14) -> 37011.697 | N5: =N4*(1-'Assumptions & WACC'!$C$14) -> 37379.142 | O5: =O4*(1-'Assumptions & WACC'!$C$14) -> 37750.235 | Q5: NOPAT | R5: =R4*(1-'Assumptions & WACC'!$B$14) -> 16653.728 | S5: =S4*(1-'Assumptions & WACC'!$B$14) -> 17111.755 | T5: =T4*(1-'Assumptions & WACC'!$B$14) -> 17582.378 | U5: =U4*(1-'Assumptions & WACC'!$B$14) -> 18065.945 | V5: =V4*(1-'Assumptions & WACC'!$B$14) -> 18562.812 | W5: =W4*(1-'Assumptions & WACC'!$B$14) -> 19073.344 | Y5: NOPAT | Z5: =Z4*(1-'Assumptions & WACC'!$C$14) -> 27173.069 | AA5: =AA4*(1-'Assumptions & WACC'!$C$14) -> 28157.406 | AB5: =AB4*(1-'Assumptions & WACC'!$C$14) -> 29177.399 | AC5: =AC4*(1-'Assumptions & WACC'!$C$14) -> 30234.342 | AD5: =AD4*(1-'Assumptions & WACC'!$C$14) -> 31329.572 | AE5: =AE4*(1-'Assumptions & WACC'!$C$14) -> 32464.477 | AG5: NOPAT | AH5: =AH4*(1-'Assumptions & WACC'!$B$14) -> 20377.394 | AI5: =AI4*(1-'Assumptions & WACC'!$B$14) -> 21099.206 | AJ5: =AJ4*(1-'Assumptions & WACC'!$B$14) -> 21846.586 | AK5: =AK4*(1-'Assumptions & WACC'!$B$14) -> 22620.44 | AL5: =AL4*(1-'Assumptions & WACC'!$B$14) -> 23421.706 | AM5: =AM4*(1-'Assumptions & WACC'!$B$14) -> 24251.354
A6: Depreciation | B6: =B3*'Assumptions & WACC'!$B$5 -> 17665.808 | C6: =C3*'Assumptions & WACC'!$B$5 -> 16506.688 | D6: =D3*'Assumptions & WACC'!$B$5 -> 15423.623 | E6: =E3*'Assumptions & WACC'!$B$5 -> 14411.621 | F6: =F3*'Assumptions & WACC'!$B$5 -> 13466.021 | G6: =G3*'Assumptions & WACC'!$B$5 -> 12582.465 | I6: Depreciation | J6: =J3*'Assumptions & WACC'!$C$5 -> 17444.692 | K6: =K3*'Assumptions & WACC'!$C$5 -> 17617.88 | L6: =L3*'Assumptions & WACC'!$C$5 -> 17792.787 | M6: =M3*'Assumptions & WACC'!$C$5 -> 17969.43 | N6: =N3*'Assumptions & WACC'!$C$5 -> 18147.827 | O6: =O3*'Assumptions & WACC'!$C$5 -> 18327.995 | Q6: Depreciation | R6: =R3*'Assumptions & WACC'!$D$5 -> 9735.2437 | S6: =S3*'Assumptions & WACC'!$D$5 -> 10002.992 | T6: =T3*'Assumptions & WACC'!$D$5 -> 10278.103 | U6: =U3*'Assumptions & WACC'!$D$5 -> 10560.781 | V6: =V3*'Assumptions & WACC'!$D$5 -> 10851.234 | W6: =W3*'Assumptions & WACC'!$D$5 -> 11149.675 | Y6: Depreciation | Z6: =Z3*'Assumptions & WACC'!$E$5 -> 15267.676 | AA6: =AA3*'Assumptions & WACC'!$E$5 -> 15820.743 | AB6: =AB3*'Assumptions & WACC'!$E$5 -> 16393.845 | AC6: =AC3*'Assumptions & WACC'!$E$5 -> 16987.707 | AD6: =AD3*'Assumptions & WACC'!$E$5 -> 17603.082 | AE6: =AE3*'Assumptions & WACC'!$E$5 -> 18240.748 | AG6: Depreciation | AH6: =AH3*'Assumptions & WACC'!$F$5 -> 15187.096 | AI6: =AI3*'Assumptions & WACC'!$F$5 -> 15725.057 | AJ6: =AJ3*'Assumptions & WACC'!$F$5 -> 16282.073 | AK6: =AK3*'Assumptions & WACC'!$F$5 -> 16858.819 | AL6: =AL3*'Assumptions & WACC'!$F$5 -> 17455.996 | AM6: =AM3*'Assumptions & WACC'!$F$5 -> 18074.325
A7: Capex | B7: =B3*'Assumptions & WACC'!$B$6 -> 15148.397 | C7: =C3*'Assumptions & WACC'!$B$6 -> 14154.454 | D7: =D3*'Assumptions & WACC'!$B$6 -> 13225.728 | E7: =E3*'Assumptions & WACC'!$B$6 -> 12357.938 | F7: =F3*'Assumptions & WACC'!$B$6 -> 11547.088 | G7: =G3*'Assumptions & WACC'!$B$6 -> 10789.44 | I7: Capex | J7: =J3*'Assumptions & WACC'!$C$6 -> 19867.628 | K7: =K3*'Assumptions & WACC'!$C$6 -> 20064.87 | L7: =L3*'Assumptions & WACC'!$C$6 -> 20264.071 | M7: =M3*'Assumptions & WACC'!$C$6 -> 20465.248 | N7: =N3*'Assumptions & WACC'!$C$6 -> 20668.424 | O7: =O3*'Assumptions & WACC'!$C$6 -> 20873.616 | Q7: Capex | R7: =R3*'Assumptions & WACC'!$D$6 -> 10055.091 | S7: =S3*'Assumptions & WACC'!$D$6 -> 10331.635 | T7: =T3*'Assumptions & WACC'!$D$6 -> 10615.785 | U7: =U3*'Assumptions & WACC'!$D$6 -> 10907.751 | V7: =V3*'Assumptions & WACC'!$D$6 -> 11207.746 | W7: =W3*'Assumptions & WACC'!$D$6 -> 11515.992 | Y7: Capex | Z7: =Z3*'Assumptions & WACC'!$E$6 -> 11670.499 | AA7: =AA3*'Assumptions & WACC'!$E$6 -> 12093.26 | AB7: =AB3*'Assumptions & WACC'!$E$6 -> 12531.335 | AC7: =AC3*'Assumptions & WACC'!$E$6 -> 12985.278 | AD7: =AD3*'Assumptions & WACC'!$E$6 -> 13455.666 | AE7: =AE3*'Assumptions & WACC'!$E$6 -> 13943.094 | AG7: Capex | AH7: =AH3*'Assumptions & WACC'!$F$6 -> 12156.931 | AI7: =AI3*'Assumptions & WACC'!$F$6 -> 12587.557 | AJ7: =AJ3*'Assumptions & WACC'!$F$6 -> 13033.436 | AK7: =AK3*'Assumptions & WACC'!$F$6 -> 13495.108 | AL7: =AL3*'Assumptions & WACC'!$F$6 -> 13973.135 | AM7: =AM3*'Assumptions & WACC'!$F$6 -> 14468.094
A8: Change in Working capital | B8: ='Assumptions & WACC'!I11-'Assumptions & WACC'!M3 -> -1008.3529 | C8: ='Assumptions & WACC'!J11-'Assumptions & WACC'!I11 -> 1096.5598 | D8: ='Assumptions & WACC'!K11-'Assumptions & WACC'!J11 -> 1024.6104 | E8: ='Assumptions & WACC'!L11-'Assumptions & WACC'!K11 -> 957.3819 | F8: ='Assumptions & WACC'!M11-'Assumptions & WACC'!L11 -> 894.56451 | G8: ='Assumptions & WACC'!N11-'Assumptions & WACC'!M11 -> 835.86879 | I8: Change in Working capital | J8: ='Assumptions & WACC'!I12-'Assumptions & WACC'!M4 -> 8241.6087 | K8: ='Assumptions & WACC'!J12-'Assumptions & WACC'!I12 -> -158.90839 | L8: ='Assumptions & WACC'!K12-'Assumptions & WACC'!J12 -> -160.486 | M8: ='Assumptions & WACC'!L12-'Assumptions & WACC'!K12 -> -162.07927 | N8: ='Assumptions & WACC'!M12-'Assumptions & WACC'!L12 -> -163.68837 | O8: ='Assumptions & WACC'!N12-'Assumptions & WACC'!M12 -> -165.31343 | Q8: Change in Working capital | R8: ='Assumptions & WACC'!I13-'Assumptions & WACC'!M5 -> 393.52223 | S8: ='Assumptions & WACC'!J13-'Assumptions & WACC'!I13 -> -243.66168 | T8: ='Assumptions & WACC'!K13-'Assumptions & WACC'!J13 -> -250.36309 | U8: ='Assumptions & WACC'!L13-'Assumptions & WACC'!K13 -> -257.24882 | V8: ='Assumptions & WACC'!M13-'Assumptions & WACC'!L13 -> -264.32391 | W8: ='Assumptions & WACC'!N13-'Assumptions & WACC'!M13 -> -271.5936 | Y8: Change in Working capital | Z8: ='Assumptions & WACC'!I14-'Assumptions & WACC'!M6 -> 3678.2255 | AA8: ='Assumptions & WACC'!J14-'Assumptions & WACC'!I14 -> -329.70908 | AB8: ='Assumptions & WACC'!K14-'Assumptions & WACC'!J14 -> -341.65269 | AC8: ='Assumptions & WACC'!L14-'Assumptions & WACC'!K14 -> -354.02896 | AD8: ='Assumptions & WACC'!M14-'Assumptions & WACC'!L14 -> -366.85355 | AE8: ='Assumptions & WACC'!N14-'Assumptions & WACC'!M14 -> -380.14271 | AG8: Change in Working capital | AH8: ='Assumptions & WACC'!I15-'Assumptions & WACC'!M7 -> -355.09009 | AI8: ='Assumptions & WACC'!J15-'Assumptions & WACC'!I15 -> -75.275356 | AJ8: ='Assumptions & WACC'!K15-'Assumptions & WACC'!J15 -> -77.941775 | AK8: ='Assumptions & WACC'!L15-'Assumptions & WACC'!K15 -> -80.702644 | AL8: ='Assumptions & WACC'!M15-'Assumptions & WACC'!L15 -> -83.561308 | AM8: ='Assumptions & WACC'!N15-'Assumptions & WACC'!M15 -> -86.521233
A9: FCFF | B9: =B5+B6-B7-B8 -> 26335.997 | C9: =C5+C6-C7-C8 -> 22569.243 | D9: =D5+D6-D7-D8 -> 21088.391 | E9: =E5+E6-E7-E8 -> 19704.703 | F9: =F5+F6-F7-F8 -> 18411.804 | G9: =G5+G6-G7-G8 -> 17203.737 | I9: FCFF | J9: =J5+J6-J7-J8 -> 25266.347 | K9: =K5+K6-K7-K8 -> 33999.525 | L9: =L5+L6-L7-L8 -> 34337.066 | M9: =M5+M6-M7-M8 -> 34677.957 | N9: =N5+N6-N7-N8 -> 35022.234 | O9: =O5+O6-O7-O8 -> 35369.928 | Q9: FCFF | R9: =R5+R6-R7-R8 -> 15940.359 | S9: =S5+S6-S7-S8 -> 17026.773 | T9: =T5+T6-T7-T8 -> 17495.059 | U9: =U5+U6-U7-U8 -> 17976.225 | V9: =V5+V6-V7-V8 -> 18470.624 | W9: =W5+W6-W7-W8 -> 18978.62 | Y9: FCFF | Z9: =Z5+Z6-Z7-Z8 -> 27092.02 | AA9: =AA5+AA6-AA7-AA8 -> 32214.598 | AB9: =AB5+AB6-AB7-AB8 -> 33381.562 | AC9: =AC5+AC6-AC7-AC8 -> 34590.799 | AD9: =AD5+AD6-AD7-AD8 -> 35843.841 | AE9: =AE5+AE6-AE7-AE8 -> 37142.273 | AG9: FCFF | AH9: =AH5+AH6-AH7-AH8 -> 23762.649 | AI9: =AI5+AI6-AI7-AI8 -> 24311.981 | AJ9: =AJ5+AJ6-AJ7-AJ8 -> 25173.165 | AK9: =AK5+AK6-AK7-AK8 -> 26064.854 | AL9: =AL5+AL6-AL7-AL8 -> 26988.128 | AM9: =AM5+AM6-AM7-AM8 -> 27944.107
A12: Metrics | B12: Value | I12: Metrics | J12: Value | Q12: Metrics | R12: Value | Y12: Metrics | Z12: Value | AG12: Metrics | AH12: Value
A13: Terminal Value | B13: =G9*(1+'Assumptions & WACC'!B25)/('Assumptions & WACC'!B21-'Assumptions & WACC'!B25) -> 392082.68 | I13: Terminal Value | J13: =O9*(1+'Assumptions & WACC'!C25)/('Assumptions & WACC'!C21-'Assumptions & WACC'!C25) -> 967330.3 | Q13: Terminal Value | R13: =W9*(1+'Assumptions & WACC'!D25)/('Assumptions & WACC'!D21-'Assumptions & WACC'!D25) -> 427404.3 | Y13: Terminal Value | Z13: =AE9*(1+'Assumptions & WACC'!E25)/('Assumptions & WACC'!E21-'Assumptions & WACC'!E25) -> 723734.2 | AG13: Terminal Value | AH13: =AM9*(1+'Assumptions & WACC'!F25)/('Assumptions & WACC'!F21-'Assumptions & WACC'!F25) -> 565837.29
A14: PV of Terminal value | B14: =B13*'Assumptions & WACC'!B23 -> 294092.02 | I14: PV of Terminal value | J14: =J13*'Assumptions & WACC'!C23 -> 756833.75 | Q14: PV of Terminal value | R14: =R13*'Assumptions & WACC'!D23 -> 319617.41 | Y14: PV of Terminal value | Z14: =Z13*'Assumptions & WACC'!E23 -> 520202.41 | AG14: PV of Terminal value | AH14: =AH13*'Assumptions & WACC'!F23 -> 411230.26
A15: PV of FCFF | B15: =NPV('Assumptions & WACC'!B21,DCF!B9:G9) -> 107533.12 | I15: PV of FCFF | J15: =NPV('Assumptions & WACC'!C21,DCF!J9:O9) -> 171617.95 | Q15: PV of FCFF | R15: =NPV('Assumptions & WACC'!D21,DCF!R9:W9) -> 89271.067 | Y15: PV of FCFF | Z15: =NPV('Assumptions & WACC'!E21,DCF!Z9:AE9) -> 164473.58 | AG15: PV of FCFF | AH15: =NPV('Assumptions & WACC'!F21,DCF!AH9:AM9) -> 127914
A16: Total enterprise value | B16: =B14+B15 -> 401625.15 | I16: Total enterprise value | J16: =J14+J15 -> 928451.7 | Q16: Total enterprise value | R16: =R14+R15 -> 408888.48 | Y16: Total enterprise value | Z16: =Z14+Z15 -> 684675.99 | AG16: Total enterprise value | AH16: =AH14+AH15 -> 539144.26
A17: Net debt | B17: ='Assumptions & WACC'!B16-'Assumptions & WACC'!B24 -> 120234 | I17: Net debt | J17: ='Assumptions & WACC'!C16-'Assumptions & WACC'!C24 -> 139820 | Q17: Net debt | R17: ='Assumptions & WACC'!D16-'Assumptions & WACC'!D24 -> 93474 | Y17: Net debt | Z17: ='Assumptions & WACC'!E16-'Assumptions & WACC'!E24 -> 91771 | AG17: Net debt | AH17: ='Assumptions & WACC'!F16-'Assumptions & WACC'!F24 -> 72856
A18: Total equity value | B18: =B16-B17 -> 281391.15 | I18: Total equity value | J18: =J16-J17 -> 788631.7 | Q18: Total equity value | R18: =R16-R17 -> 315414.48 | Y18: Total equity value | Z18: =Z16-Z17 -> 592904.99 | AG18: Total equity value | AH18: =AH16-AH17 -> 466288.26
A19: Outstanding shares | B19: ='Assumptions & WACC'!B26 -> 7089.45 | I19: Outstanding shares | J19: ='Assumptions & WACC'!C26 -> 4216.425 | Q19: Outstanding shares | R19: ='Assumptions & WACC'!D26 -> 129.4094 | Y19: Outstanding shares | Z19: ='Assumptions & WACC'!E26 -> 3643.895 | AG19: Outstanding shares | AH19: ='Assumptions & WACC'!F26 -> 1118.507
A20: Intrinsic value | B20: =B18/B19 -> 39.691534 | I20: Intrinsic value | J20: =J18/J19 -> 187.038 | Q20: Intrinsic value | R20: =R18/R19 -> 2437.3382 | Y20: Intrinsic value | Z20: =Z18/Z19 -> 162.71188 | AG20: Intrinsic value | AH20: =AH18/AH19 -> 416.88452
A21: Current market price | B21: =Profile!B3 -> 25.195 | I21: Current market price | J21: =Profile!C3 -> 41.1098 | Q21: Current market price | R21: =Profile!D3 -> 195.11 | Y21: Current market price | Z21: =Profile!E3 -> 26.905 | AG21: Current market price | AH21: =Profile!F3 -> 210.79
A22: Upside/Downside | B22: =(B20-B21)/B21 -> 0.57537345 | I22: Upside/Downside | J22: =(J20-J21)/J21 -> 3.5497181 | Q22: Upside/Downside | R22: =(R20-R21)/R21 -> 11.492124 | Y22: Upside/Downside | Z22: =(Z20-Z21)/Z21 -> 5.0476445 | AG22: Upside/Downside | AH22: =(AH20-AH21)/AH21 -> 0.97772438

Sheet Relative
A1: Company | B1: EV/EBITDA | C1: P/E | D1: P/S | E1: P/B | L1: .
A2: #VALUE! | B2: 11.96 | C2: {=_FV(A2,"P/E",TRUE)} -> 20.2724 | D2: 3.27 | E2: 3.93 | H2: Company | I2: EV/EBITDA | J2: P/E | K2: P/S | L2: P/B | N2: Shares
A3: #VALUE! | B3: 7.47 | C3: {=_FV(A3,"P/E",TRUE)} -> 8.1752 | D3: 1.34 | E3: 1.6 | H3: AT&T | I3: =(B22*$B$19)/N3 -> 70.038733 | J3: =(C22*$C$19)/N3 -> 21.844695 | K3: =(D22*$D$19)/N3 -> 35.15923 | L3: =(E22*$E$19)/N3 -> 65.027286 | N3: =Profile!B6 -> 7089.45
A4: #VALUE! | B4: 8.63 | C4: {=_FV(A4,"P/E",TRUE)} -> 8.7641 | D4: 1.26 | E4: 1.75 | H4: Verizon | I4: =(B23*$B$19)/N4 -> 126.0964 | J4: =(C23*$C$19)/N4 -> 79.624901 | K4: =(D23*$D$19)/N4 -> 65.133508 | L4: =(E23*$E$19)/N4 -> 92.997452 | N4: =Profile!C6 -> 4216.425
A5: #VALUE! | B5: 7.35 | C5: 78.74 | D5: 1.92 | E5: 1.23 | H5: =A24 -> Charter | I5: =(B24*$B$19)/N5 -> 1916.7175 | J5: =(C24*$C$19)/N5 -> 892.84953 | K5: =(D24*$D$19)/N5 -> 867.29161 | L5: =(E24*$E$19)/N5 -> 593.71782 | N5: =Profile!D6 -> 129.4094
A6: #VALUE! | B6: 3.71 | C6: {=_FV(A6,"P/E",TRUE)} -> 11.0162 | D6: 1.29 | E6: 2.41 | H6: =A25 -> Comcast | I6: =(B25*$B$19)/N6 -> 118.61222 | J6: =(C25*$C$19)/N6 -> 86.013806 | K6: =(D25*$D$19)/N6 -> 69.184736 | L6: =(E25*$E$19)/N6 -> 92.055521 | N6: =Profile!E6 -> 3643.895
A7: #VALUE! | B7: 14.93 | C7: {=_FV(A7,"P/E",TRUE)} -> 32.31 | D7: 6.05 | E7: 11.09 | H7: =A26 -> T-Mobile | I7: =(B26*$B$19)/N7 -> 324.12928 | J7: =(C26*$C$19)/N7 -> 200.12513 | K7: =(D26*$D$19)/N7 -> 148.28025 | L7: =(E26*$E$19)/N7 -> 215.20896 | N7: =Profile!F6 -> 1118.507
A8: #VALUE! | B8: 6.22 | C8: {=_FV(A8,"P/E",TRUE)} -> 4.4671 | D8: 1.21 | E8: 1.66
A9: #VALUE! | B9: 21.06 | C9: {=_FV(A9,"P/E",TRUE)} -> 28.73 | D9: 7.68 | E9: 23.54
A10: #VALUE! | B10: 5.24 | C10: 13.76 | D10: 0.67 | E10: 0.44
A11: #VALUE! | B11: 1.58 | C11: {=_FV(A11,"P/E",TRUE)} -> 43.525 | D11: 0.74 | E11: 1.2
A12: #VALUE! | B12: 16.46 | C12: 0 | D12: 1.58 | E12: 4.2 | H12: Company | I12: Target Price | J12: CMP | K12: U/D
A13: #VALUE! | B13: 5.98 | C13: {=_FV(A13,"P/E",TRUE)} -> 11.9771 | D13: 0.96 | E13: 1.29 | H13: =H3 -> AT&T | I13: =AVERAGE(I3:L3) -> 48.017486 | J13: =Profile!B3 -> 25.195 | K13: =(Table24[[#This Row],[Target Price]]-J13)/J13 -> 0.90583393
A14: #VALUE! | B14: 3.55 | C14: {=_FV(A14,"P/E",TRUE)} -> 11.75 | D14: 0.84 | E14: 0.96 | H14: =H4 -> Verizon | I14: =AVERAGE(I4:L4) -> 90.963066 | J14: =Profile!C3 -> 41.1098 | K14: =(Table24[[#This Row],[Target Price]]-J14)/J14 -> 1.2126857
A15: #VALUE! | B15: 8.41 | C15: 24.51 | D15: 2.47 | E15: 3.97 | H15: =H5 -> Charter | I15: =AVERAGE(I5:L5) -> 1067.6441 | J15: =Profile!D3 -> 195.11 | K15: =(Table24[[#This Row],[Target Price]]-J15)/J15 -> 4.4720112
A16: #VALUE! | B16: 2.63 | C16: {=_FV(A16,"P/E",TRUE)} -> 12.5833 | D16: 0.42 | E16: 0.64 | H16: =H6 -> Comcast | I16: =AVERAGE(I6:L6) -> 91.46657 | J16: =Profile!E3 -> 26.905 | K16: =(Table24[[#This Row],[Target Price]]-J16)/J16 -> 2.3996124
A17: #VALUE! | B17: 6.77 | C17: {=_FV(A17,"P/E",TRUE)} -> 5.273 | D17: 0.9 | E17: 2.47 | H17: =H7 -> T-Mobile | I17: =AVERAGE(I7:L7) -> 221.9359 | J17: =Profile!F3 -> 210.79 | K17: =(Table24[[#This Row],[Target Price]]-J17)/J17 -> 0.052876819
A19: Average | B19: =AVERAGE(B2:B17) -> 8.246875 | C19: =AVERAGE(C2:C17) -> 19.740837 | D19: =AVERAGE(D2:D17) -> 2.0375 | E19: =AVERAGE(E2:E17) -> 3.89875
A21: Company | B21: EBITDA | C21: Net Income | D21: Revenue | E21: Book Value
A22: =H3 -> AT&T | B22: =Financials!F6+Financials!F7 -> 60209 | C22: =Financials!F10 -> 7845 | D22: =Financials!F3 -> 122336 | E22: =Table2[[#This Row],[2024]] -> 118245
A23: =H4 -> Verizon | B23: =Financials!M6+Financials!M7 -> 64470 | C23: =Financials!M10 -> 17007 | D23: =Financials!M3 -> 134788 | E23: =Financials!M22 -> 100575
A24: Charter | B24: =Financials!T6+Financials!T7 -> 30077 | C24: =Financials!T10 -> 5853 | D24: =Financials!T3 -> 55085 | E24: =Financials!T22 -> 19707
A25: Comcast | B25: =Financials!AB6+Financials!AB7 -> 52409 | C25: =Financials!AB10 -> 15877 | D25: =Financials!AB3 -> 123731 | E25: =Financials!AB22 -> 86038
A26: T-Mobile | B26: =Financials!AJ6+Financials!AJ7 -> 43961 | C26: =Financials!AJ10 -> 11339 | D26: =Financials!AJ3 -> 81400 | E26: =Financials!AJ22 -> 61741

Sheet Calc
A1: Year | B1: Particulars | C1: Company | D1: Value | F1: Company | G1: Change in EBIT (historical) | H1: Change in CE | I1: Incremental ROCE (Historical) | J1: Change in EBIT (Forecast) | K1: Capex | L1: Depreciation | M1: Effective capital | N1: Raw ROCE | O1: Adjusted ROCE (Forecast) | Q1: Particulars | R1: 2020 | S1: 2021 | T1: 2022 | U1: 2023 | V1: 2024
A2: 2020-24 | B2: Avg Capex | C2: AT&T | D2: =AVERAGE(Financials!B27:F27) -> 17792.4 | F2: =C2 -> AT&T | G2: =Financials!F6-Financials!B6 -> 4708 | H2: =(394795-46872)-(525761-63438) -> -114400 | I2: =G2/H2 -> -0.041153846 | J2: =DCF!G4-DCF!B4 -> -8524.2241 | K2: =D8 -> 12870.508 | L2: =AVERAGE(DCF!B6:G6) -> 15009.371 | M2: =IF(K2-L2<=0,K2,MAX(K2-L2,0.1*K2)) -> 12870.508 | N2: =J2/M2 -> -0.66230675 | O2: =MIN(MAX(N2,0.05),0.15) -> 0.05 | Q2: Revenue | R2: {=Financials!B3:F3} -> 171760 | S2: 134038 | T2: 120741 | U2: 122428 | V2: 122336
A3: 2020-24 | B3: Avg Capex | C3: Verizon | D3: =AVERAGE(Financials!I27:M27) -> 19484.4 | F3: =C3 -> Verizon | G3: =Financials!M6-Financials!I6 -> 1060 | H3: =(384711-64771)-(316481-39660) -> 43119 | I3: =G3/H3 -> 0.02458313 | J3: =DCF!O4-DCF!J4 -> 2362.7823 | K3: =D9 -> 20367.31 | L3: =AVERAGE(DCF!J6:O6) -> 17883.435 | M3: =IF(K3-L3<=0,K3,MAX(K3-L3,0.1*K3)) -> 2483.8743 | N3: =J3/M3 -> 0.95124875 | O3: =MIN(MAX(N3,0.05),0.15) -> 0.15 | Q3: Operating Income | R3: {=Financials!B6:F6} -> 34921 | S3: 43749 | T3: 13434 | U3: 42238 | V3: 39629
A4: 2020-24 | B4: Avg Capex | C4: Charter | D4: =AVERAGE(Financials!P27:T27) -> 9362 | F4: =C4 -> Charter | G4: =Financials!T6-Financials!P6 -> 3550 | H4: =(Financials!T15-Financials!T20)-(Financials!P15-Financials!P20) -> 2203 | I4: =G4/H4 -> 1.6114389 | J4: =Table919[[#This Row],[2030]]-Table919[[#This Row],[2025]] -> 3142.3579 | K4: =D10 -> 10772.333 | L4: =AVERAGE(DCF!R6:W6) -> 10429.671 | M4: =IF(K4-L4<=0,K4,MAX(K4-L4,0.1*K4)) -> 1077.2333 | N4: =J4/M4 -> 2.9170634 | O4: =MIN(MAX(N4,0.05),0.15) -> 0.15 | Q4: Net Income | R4: {=Financials!B10:F10} -> -2485 | S4: 13786 | T4: -14475 | U4: 12532 | V4: 7845
A5: 2020-24 | B5: Avg Capex | C5: Comcast | D5: =AVERAGE(Financials!X27:AB27) -> 10680.4 | F5: =C5 -> Comcast | G5: =Financials!AB6-Financials!X6 -> 5855 | H5: =(Financials!AB15-Financials!AB20)-(Financials!X15-Financials!X20) -> -18443 | I5: =G5/H5 -> -0.31746462 | J5: =DCF!AE4-DCF!Z4 -> 6871.9573 | K5: =D11 -> 12779.855 | L5: =AVERAGE(DCF!Z6:AE6) -> 16718.967 | M5: =IF(K5-L5<=0,K5,MAX(K5-L5,0.1*K5)) -> 12779.855 | N5: =J5/M5 -> 0.53771792 | O5: =MIN(MAX(N5,0.05),0.15) -> 0.15
A6: 2020-24 | B6: Avg Capex | C6: T-Mobile | D6: =AVERAGE(Financials!AF27:AJ27) -> 11194.2 | F6: =C6 -> T-Mobile | G6: =Table184447[[#This Row],[2024]]-Table184447[[#This Row],[2020]] -> 10631 | H6: =(Financials!AJ15-Financials!AJ20)-(Financials!AF15-Financials!AF20) -> 9402 | I6: =G6/H6 -> 1.1307169 | J6: =DCF!AM4-DCF!AH4 -> 5031.1172 | K6: =D12 -> 13285.71 | L6: =AVERAGE(Table91934[[#This Row],[2025]:[2030]]) -> 16597.228 | M6: =IF(K6-L6<=0,K6,MAX(K6-L6,0.1*K6)) -> 13285.71 | N6: =J6/M6 -> 0.37868636 | O6: =MIN(MAX(N6,0.05),0.15) -> 0.15 | Q6: Particulars | R6: 2020 | S6: 2021 | T6: 2022 | U6: 2023 | V6: 2024
A7: 2020-24 | B7: Avg Capex | C7: Average | D7: =AVERAGE(D2:D6) -> 13702.68 | H7: Average | I7: =AVERAGE(I2:I6) -> 0.4816241 | M7: Average | N7: =AVERAGE(N2:N6) -> 0.82448194 | O7: =AVERAGE(O2:O6) -> 0.13 | Q7: Revenue | R7: {=Financials!I3:M3} -> 128292 | S7: 133613 | T7: 136835 | U7: 133974 | V7: 134788 | Z7: Company | AA7: WACC | AB7: Terminal Growth | AC7: Cost of equity | AD7: Intrinsic Value | AE7: Share price | AF7: Upside/Downside
A8: 2025-30 | B8: Avg Capex | C8: =C2 -> AT&T | D8: =AVERAGE(DCF!B7:G7) -> 12870.508 | Q8: Operating Income | R8: {=Financials!I6:M6} -> 45518 | S8: 48654 | T8: 47566 | U8: 40501 | V8: 46578 | Z8: AT&T | AA8: ='Assumptions & WACC'!B21 -> 0.049097218 | AB8: ='Assumptions & WACC'!$B$25 -> 0.005 | AC8: ='Assumptions & WACC'!B12 -> 0.0580826 | AD8: =DCF!B20 -> 39.691534 | AE8: =DCF!B21 -> 25.195 | AF8: =(AD8-AE8)/AE8 -> 0.57537345
A9: 2025-30 | B9: Avg Capex | C9: =C3 -> Verizon | D9: =AVERAGE(DCF!J7:O7) -> 20367.31 | Q9: Net Income | R9: {=Table18[[#This Row],[2020]:[2024]]} -> 5619 | S9: 6802 | T9: 6523 | U9: 4892 | V9: 5030 | Z9: Verizon | AA9: ='Assumptions & WACC'!C21 -> 0.041747301 | AB9: ='Assumptions & WACC'!$B$25 -> 0.005 | AC9: ='Assumptions & WACC'!C12 -> 0.0556874 | AD9: =DCF!J20 -> 187.038 | AE9: =DCF!J21 -> 41.1098 | AF9: =(AD9-AE9)/AE9 -> 3.5497181
A10: 2025-30 | B10: Avg Capex | C10: =C4 -> Charter | D10: =AVERAGE(DCF!R7:W7) -> 10772.333 | G10: Metric | H10: 2020-24 | I10: 2025-30
A11: 2025-30 | B11: Avg Capex | C11: =C5 -> Comcast | D11: =AVERAGE(DCF!Z7:AE7) -> 12779.855 | G11: GDP | H11: =AVERAGE(-0.035,0.058) -> 0.0115 | I11: 0.018
A12: 2025-30 | B12: Avg Capex | C12: =C6 -> T-Mobile | D12: =AVERAGE(DCF!AH7:AM7) -> 13285.71 | G12: GDP | H12: 0.028 | I12: 0.026 | Q12: Particulars | R12: 2025 | S12: 2026 | T12: 2027 | U12: 2028 | V12: 2029 | W12: 2030
A13: 2025-30 | B13: Avg Capex | C13: =C7 -> Average | D13: =AVERAGE(D8:D12) -> 14015.143 | G13: Change | H13: =H12-H11 -> 0.0165 | I13: =I12-I11 -> 0.008 | Q13: Revenue | R13: {=DCF!B3:G3} -> 114309.08 | S13: 106808.83 | T13: 99800.708 | U13: 93252.412 | V13: 87133.773 | W13: 81416.602
A14: 2025-30 | B14: Capex CAGR | C14: =C8 -> AT&T | D14: =(DCF!G7/DCF!B7)^(1/6)-1 -> -0.054984988 | G14: Sensitivity | H14: =D61/H13 -> 100.16319 | I14: =D67/I13 -> 7.3253594 | Q14: Operating income | R14: {=DCF!B4:G4} -> 29623.679 | S14: 27679.959 | T14: 25863.774 | U14: 24166.755 | V14: 22581.084 | W14: 21099.455
A15: 2025-30 | B15: Capex CAGR | C15: =C9 -> Verizon | D15: =(DCF!O7/DCF!J7)^(1/6)-1 -> 0.0082663555 | Q15: Net income | R15: {=DCF!B5:G5} -> 22810.233 | S15: 21313.569 | T15: 19915.106 | U15: 18608.402 | V15: 17387.435 | W15: 16246.581
A16: 2025-30 | B16: Capex CAGR | C16: =C10 -> Charter | D16: =(DCF!W7/DCF!R7)^(1/6)-1 -> 0.022867141 | Q16: FCFF | R16: {=DCF!B9:G9} -> 26335.997 | S16: 22569.243 | T16: 21088.391 | U16: 19704.703 | V16: 18411.804 | W16: 17203.737
A17: 2025-30 | B17: Capex CAGR | C17: =C11 -> Comcast | D17: =(DCF!AE7/DCF!Z7)^(1/6)-1 -> 0.030097385
A18: 2025-30 | B18: Capex CAGR | C18: =C12 -> T-Mobile | D18: =(DCF!AM7/DCF!AH7)^(1/6)-1 -> 0.02943254 | Q18: Particulars | R18: 2025 | S18: 2026 | T18: 2027 | U18: 2028 | V18: 2029 | W18: 2030
A19: 2025-30 | B19: Capex CAGR | C19: =C13 -> Average | D19: =AVERAGE(D14:D18) -> 0.0071356866 | Q19: Revenue | R19: {=DCF!J3:O3} -> 136126.15 | S19: 137477.58 | T19: 138842.43 | U19: 140220.84 | V19: 141612.92 | W19: 143018.83
A20: =A14 -> 2025-30 | B20: Earnings CAGR | C20: =C14 -> AT&T | D20: =D14 -> -0.054984988 | Q20: Operating income | R20: {=DCF!J4:O4} -> 46663.496 | S20: 47126.763 | T20: 47594.628 | U20: 48067.138 | V20: 48544.34 | W20: 49026.279
A21: =A15 -> 2025-30 | B21: Earnings CAGR | C21: =C15 -> Verizon | D21: =D15 -> 0.0082663555 | Q21: Net income | R21: {=DCF!J5:O5} -> 35930.892 | S21: 36287.607 | T21: 36647.864 | U21: 37011.697 | V21: 37379.142 | W21: 37750.235
A22: =A16 -> 2025-30 | B22: Earnings CAGR | C22: =C16 -> Charter | D22: =D16 -> 0.022867141 | Q22: FCFF | R22: {=DCF!J9:O9} -> 25266.347 | S22: 33999.525 | T22: 34337.066 | U22: 34677.957 | V22: 35022.234 | W22: 35369.928
A23: =A17 -> 2025-30 | B23: Earnings CAGR | C23: =C17 -> Comcast | D23: =D17 -> 0.030097385
A24: =A18 -> 2025-30 | B24: Earnings CAGR | C24: =C18 -> T-Mobile | D24: =D18 -> 0.02943254
A25: =A19 -> 2025-30 | B25: Earnings CAGR | C25: =C19 -> Average | D25: =AVERAGE(D20:D24) -> 0.0071356866
A26: =A20 -> 2025-30 | B26: Revenue CAGR | C26: =C20 -> AT&T | D26: =D20 -> -0.054984988
A27: =A21 -> 2025-30 | B27: Revenue CAGR | C27: =C21 -> Verizon | D27: =D21 -> 0.0082663555
A28: =A22 -> 2025-30 | B28: Revenue CAGR | C28: =C22 -> Charter | D28: =D22 -> 0.022867141
A29: =A23 -> 2025-30 | B29: Revenue CAGR | C29: =C23 -> Comcast | D29: =D23 -> 0.030097385
A30: =A24 -> 2025-30 | B30: Revenue CAGR | C30: =C24 -> T-Mobile | D30: =D24 -> 0.02943254
A31: =A25 -> 2025-30 | B31: Revenue CAGR | C31: =C25 -> Average | D31: =AVERAGE(D26:D30) -> 0.0071356866
A32: =A2 -> 2020-24 | B32: EBITDA Margin | C32: =C26 -> AT&T | D32: =(Financials!F6+Financials!F7)/Financials!F3 -> 0.49216093
A33: =A3 -> 2020-24 | B33: EBITDA Margin | C33: =C27 -> Verizon | D33: =(Financials!M6+Financials!M7)/Financials!M3 -> 0.47830667
A34: =A4 -> 2020-24 | B34: EBITDA Margin | C34: =C28 -> Charter | D34: =(Financials!T6+Financials!T7)/Financials!T3 -> 0.54601071
A35: =A5 -> 2020-24 | B35: EBITDA Margin | C35: =C29 -> Comcast | D35: =(Financials!AB6+Financials!AB7)/Financials!AB3 -> 0.4235721
A36: =A6 -> 2020-24 | B36: EBITDA Margin | C36: =C30 -> T-Mobile | D36: =(Financials!AJ6+Financials!AJ7)/Financials!AJ3 -> 0.54006143
A37: =$A$36 -> 2020-24 | B37: EBITDA Margin | C37: =C31 -> Average | D37: =AVERAGE(D32:D36) -> 0.49602237
A38: =$A$36 -> 2020-24 | B38: NPM | C38: =C32 -> AT&T | D38: =Financials!F10/Financials!F3 -> 0.064126668
A39: =$A$36 -> 2020-24 | B39: NPM | C39: =C33 -> Verizon | D39: =Financials!M10/Financials!M3 -> 0.12617592
A40: =A32 -> 2020-24 | B40: NPM | C40: =C34 -> Charter | D40: =Financials!T10/Financials!T3 -> 0.10625397
...
