Workbook

Sheet Company Profile
A1: Company | B1: #VALUE! | C1: #VALUE! | D1: #VALUE! | E1: #VALUE! | F1: #VALUE!
A2: Official name | B2: {=_FV(B1,"Official name",TRUE)} -> ACCENTURE PUBLIC LIMITED COMPANY | C2: {=_FV(C1,"Official name",TRUE)} -> INTERNATIONAL BUSINESS MACHINES CORPORATION | D2: {=_FV(D1,"Official name",TRUE)} -> ALPHABET INC. | E2: {=_FV(E1,"Official name",TRUE)} -> MICROSOFT CORPORATION | F2: {=_FV(F1,"Official name",TRUE)} -> ORACLE CORPORATION
A3: Share price | B3: {=_FV(B1,"Price")} -> 244.16 | C3: {=_FV(C1,"Price")} -> 289.86 | D3: {=_FV(D1,"Price")} -> 300.64 | E3: {=_FV(E1,"Price")} -> 493.825 | F3: {=_FV(F1,"Price")} -> 227.385
A4: Change (%) | B4: {=_FV(B1,"Change (%)",TRUE)} -> 0.017333 | C4: {=_FV(C1,"Change (%)",TRUE)} -> -0.0003104 | D4: {=_FV(D1,"Change (%)",TRUE)} -> 0.057549 | E4: {=_FV(E1,"Change (%)",TRUE)} -> 7.088e-05 | F4: {=_FV(F1,"Change (%)",TRUE)} -> 0.031271
A5: Shares outstanding | B5: {=_FV(B1,"Shares outstanding",TRUE)} -> 620138900 | C5: {=_FV(C1,"Shares outstanding",TRUE)} -> 934735200 | D5: {=_FV(D1,"Shares outstanding",TRUE)} -> 12067000000 | E5: {=_FV(E1,"Shares outstanding",TRUE)} -> 7432377000 | F5: {=_FV(F1,"Shares outstanding",TRUE)} -> 2850793000
A6: in mn | B6: =B5/1000000 -> 620.1389 | C6: =C5/1000000 -> 934.7352 | D6: =D5/1000000 -> 12067 | E6: =E5/1000000 -> 7432.377 | F6: =F5/1000000 -> 2850.793
A7: Market cap | B7: {=_FV(B1,"Market cap",TRUE)} -> 151413113824 | C7: {=_FV(C1,"Market cap",TRUE)} -> 270942345072 | D7: {=_FV(D1,"Market cap",TRUE)} -> 3434084000000 | E7: {=_FV(E1,"Market cap",TRUE)} -> 3670293572025 | F7: {=_FV(F1,"Market cap",TRUE)} -> 648227566305
A8: in mn | B8: =B7/1000000 -> 151413.11 | C8: =C7/1000000 -> 270942.35 | D8: =D7/1000000 -> 3434084 | E8: =E7/1000000 -> 3670293.6 | F8: =F7/1000000 -> 648227.57
A9: Beta | B9: {=_FV(B1,"Beta")} -> 1.2608 | C9: {=_FV(C1,"Beta")} -> 0.6968 | D9: {=_FV(D1,"Beta")} -> 1.0733 | E9: {=_FV(E1,"Beta")} -> 1.0728 | F9: {=_FV(F1,"Beta")} -> 1.6774
A10: P/E | B10: {=_FV(B1,"P/E",TRUE)} -> 20.1024 | C10: {=_FV(C1,"P/E",TRUE)} -> 35.9138 | D10: {=_FV(D1,"P/E",TRUE)} -> 29.6463 | E10: {=_FV(E1,"P/E",TRUE)} -> 35.1342 | F10: {=_FV(F1,"P/E",TRUE)} -> 52.6293
A11: Year | B11: {=_FV(B1,"Year incorporated",TRUE)} -> 2009 | C11: {=_FV(C1,"Year incorporated",TRUE)} -> 1911 | D11: {=_FV(D1,"Year incorporated",TRUE)} -> 2015 | E11: {=_FV(E1,"Year incorporated",TRUE)} -> 1993 | F11: {=_FV(F1,"Year incorporated",TRUE)} -> 2005

Sheet Financials
A1: INCOME STATEMENT | F1: Accenture | H1: INCOME STATEMENT | M1: IBM | O1: INCOME STATEMENT | T1: Alphabet | W1: INCOME STATEMENT | AB1: Microsoft | AE1: INCOME STATEMENT | AJ1: Oracle
A2: Particulars | B2: 2020 | C2: 2021 | D2: 2022 | E2: 2023 | F2: 2024 | H2: Particulars | I2: 2020 | J2: 2021 | K2: 2022 | L2: 2023 | M2: 2024 | O2: Particulars | P2: 2020 | Q2: 2021 | R2: 2022 | S2: 2023 | T2: 2024 | W2: Particulars | X2: 2020 | Y2: 2021 | Z2: 2022 | AA2: 2023 | AB2: 2024 | AE2: Particulars | AF2: 2020 | AG2: 2021 | AH2: 2022 | AI2: 2023 | AJ2: 2024
A3: Revenue | B3: 44327.039 | C3: 50533.389 | D3: 61594.305 | E3: 64111.745 | F3: 64896.464 | H3: Revenue | I3: 55179 | J3: 57350 | K3: 60530 | L3: 61860 | M3: 62753 | O3: Revenue | P3: 182527 | Q3: 257637 | R3: 282836 | S3: 307394 | T3: 350018 | W3: Revenue | X3: 168088 | Y3: 198270 | Z3: 211915 | AA3: 245122 | AB3: 281724 | AE3: Revenue | AF3: 40479 | AG3: 42440 | AH3: 49954 | AI3: 52961 | AJ3: 57399
A4: Cost of sales | B4: 30350.881 | C4: 34169.261 | D4: 41892.766 | E4: 43380.138 | F4: 43734.147 | H4: Cost of sales | I4: 24314 | J4: 25865 | K4: 27842 | L4: 27560 | M4: 27201 | O4: Cost of sales | P4: 84732 | Q4: 110939 | R4: 126203 | S4: 133332 | T4: 146306 | W4: Cost of sales | X4: 52232 | Y4: 62650 | Z4: 65863 | AA4: 74114 | AB4: 87831 | AE4: Cost of sales | AF4: 0 | AG4: 0 | AH4: 0 | AI4: 0 | AJ4: 0
A5: Opex | B5: =4625.929+2836.585 -> 7462.514 | C5: =5288.237+3454.362 -> 8742.599 | D5: =6108.401+4225.957 -> 10334.358 | E5: =6582.629+4275.943+1063.146 -> 11921.718 | F5: =6846.714+4281.316+438.44 -> 11566.47 | H5: Opex | I5: =28293-1288 -> 27005 | J5: =26649-1155 -> 25494 | K5: =31531-1216 -> 30315 | L5: =25610-1607 -> 24003 | M5: =29754-1712 -> 28042 | O5: Opex | P5: =141303-84732-6858 -> 49713 | Q5: =178923-110939-12020 -> 55964 | R5: =207994-126203+3514 -> 85305 | S5: =223101-133332-1424 -> 88345 | T5: =237628-146306-7425 -> 83897 | W5: Opex | X5: =20716+20117+5107-1186 -> 44754 | Y5: =24512+21825+5900-333 -> 51904 | Z5: =27195+22759+7575-788 -> 56741 | AA5: =29510+24456+7609+1646 -> 63221 | AB5: =32488+25654+7223+4901 -> 70266 | AE5: Opex | AF5: =25266-1379-282 -> 23605 | AG5: =31514+522-1150 -> 30886 | AH5: =36861+462-3582 -> 33741 | AI5: =37608-3010+98 -> 34696 | AJ5: =39721-2307-60 -> 37354
A6: Operating income (EBIT) | B6: =B3-B4-B5 -> 6513.644 | C6: =C3-C4-C5 -> 7621.529 | D6: =D3-D4-D5 -> 9367.181 | E6: =E3-E4-E5 -> 8809.889 | F6: =F3-F4-F5 -> 9595.847 | H6: Operating income (EBIT) | I6: =I3-I4-I5 -> 3860 | J6: =J3-J4-J5 -> 5991 | K6: =K3-K4-K5 -> 2373 | L6: =L3-L4-L5 -> 10297 | M6: =M3-M4-M5 -> 7510 | O6: Operating income (EBIT) | P6: =P3-P4-P5 -> 48082 | Q6: =Q3-Q4-Q5 -> 90734 | R6: =R3-R4-R5 -> 71328 | S6: =S3-S4-S5 -> 85717 | T6: =T3-T4-T5 -> 119815 | W6: Operating income (EBIT) | X6: =X3-X4-X5 -> 71102 | Y6: =Y3-Y4-Y5 -> 83716 | Z6: =Z3-Z4-Z5 -> 89311 | AA6: =AA3-AA4-AA5 -> 107787 | AB6: =AB3-AB4-AB5 -> 123627 | AE6: Operating income (EBIT) | AF6: =AF3-AF5-AF4 -> 16874 | AG6: =AG3-AG5-AG4 -> 11554 | AH6: =AH3-AH5-AH4 -> 16213 | AI6: =AI3-AI5-AI4 -> 18265 | AJ6: =AJ3-AJ5-AJ4 -> 20045
A7: Depreciation & Amortization | B7: 1773.124 | C7: 1891.242 | D7: 2088.216 | E7: 2281.085 | F7: 2168.038 | H7: Depreciation & Amortization | I7: =4227+2468 -> 6695 | J7: =3888+2529 -> 6417 | K7: =2407+2395 -> 4802 | L7: =2109+2287 -> 4396 | M7: =2168+2499 -> 4667 | O7: Depreciation & Amortization | P7: =12905+792 -> 13697 | Q7: =11555+886 -> 12441 | R7: =15287+641 -> 15928 | S7: 11946 | T7: 15311 | W7: Depreciation & Amortization | X7: 11686 | Y7: 14460 | Z7: 13861 | AA7: 22287 | AB7: 34153 | AE7: Depreciation & Amortization | AF7: 1379 | AG7: 1150 | AH7: 3582 | AI7: 3010 | AJ7: 2307
A8: Interest expense | B8: 33.071 | C8: 59.492 | D8: 47.32 | E8: 47.525 | F8: 58.969 | H8: Interest expense | I8: 1288 | J8: 1155 | K8: 1216 | L8: 1607 | M8: 1712 | O8: Interest expense | P8: 135 | Q8: 346 | R8: 357 | S8: 308 | T8: 268 | W8: Interest expense | X8: 2330 | Y8: 2047 | Z8: 1995 | AA8: 2983 | AB8: 2425 | AE8: Interest expense | AF8: 2496 | AG8: 2755 | AH8: 3505 | AI8: 3514 | AJ8: 3578
A9: Income tax | B9: 1589.018 | C9: 1770.571 | D9: 2207.207 | E9: 2135.802 | F9: 2280.126 | H9: Income tax | I9: -1360 | J9: 124 | K9: -626 | L9: 1176 | M9: -218 | O9: Income tax | P9: 7813 | Q9: 14701 | R9: 11356 | S9: 11922 | T9: 19697 | W9: Income tax | X9: 9831 | Y9: 10978 | Z9: 16950 | AA9: 19651 | AB9: 21795 | AE9: Income tax | AF9: 747 | AG9: 932 | AH9: 623 | AI9: 1274 | AJ9: 1717
A10: Net income | B10: =B6-B7-B8-B9 -> 3118.431 | C10: =C6-C7-C8-C9 -> 3900.224 | D10: =D6-D7-D8-D9 -> 5024.438 | E10: =E6-E7-E8-E9 -> 4345.477 | F10: =F6-F7-F8-F9 -> 5088.714 | H10: Net income | I10: =I6-I7-I8-I9 -> -2763 | J10: =J6-J7-J8-J9 -> -1705 | K10: =K6-K7-K8-K9 -> -3019 | L10: =L6-L7-L8-L9 -> 3118 | M10: =M6-M7-M8-M9 -> 1349 | O10: Net income | P10: =P6-P7-P8-P9 -> 26437 | Q10: =Q6-Q7-Q8-Q9 -> 63246 | R10: =R6-R7-R8-R9 -> 43687 | S10: =S6-S7-S8-S9 -> 61541 | T10: =T6-T7-T8-T9 -> 84539 | W10: Net income | X10: =X6-X7-X8-X9 -> 47255 | Y10: =Y6-Y7-Y8-Y9 -> 56231 | Z10: =Z6-Z7-Z8-Z9 -> 56505 | AA10: =AA6-AA7-AA8-AA9 -> 62866 | AB10: =AB6-AB7-AB8-AB9 -> 65254 | AE10: Net income | AF10: =AF6-AF7-AF8-AF9 -> 12252 | AG10: =AG6-AG7-AG8-AG9 -> 6717 | AH10: =AH6-AH7-AH8-AH9 -> 8503 | AI10: =AI6-AI7-AI8-AI9 -> 10467 | AJ10: =AJ6-AJ7-AJ8-AJ9 -> 12443
A12: BALANCE SHEET | H12: BALANCE SHEET | O12: BALANCE SHEET | W12: BALANCE SHEET | AE12: BALANCE SHEET
A13: Particulars | B13: 2020 | C13: 2021 | D13: 2022 | E13: 2023 | F13: 2024 | H13: Particulars | I13: 2020 | J13: 2021 | K13: 2022 | L13: 2023 | M13: 2024 | O13: Particulars | P13: 2020 | Q13: 2021 | R13: 2022 | S13: 2023 | T13: 2024 | W13: Particulars | X13: 2020 | Y13: 2021 | Z13: 2022 | AA13: 2023 | AB13: 2024 | AE13: Particulars | AF13: 2020 | AG13: 2021 | AH13: 2022 | AI13: 2023 | AJ13: 2024
A14: Cash & Cash equivalents | B14: 8415.33 | C14: 8168.174 | D14: 7889.833 | E14: 9045.032 | F14: 5004.469 | H14: Cash & Cash equivalents | I14: 13212 | J14: 6650 | K14: 7886 | L14: 13068 | M14: 13947 | O14: Cash & Cash equivalents | P14: 136694 | Q14: 139649 | R14: 113762 | S14: 110916 | T14: 95657 | W14: Cash & Cash equivalents | X14: 130334 | Y14: 104757 | Z14: 111262 | AA14: 75543 | AB14: 94565 | AE14: Cash & Cash equivalents | AF14: 30098 | AG14: 21383 | AH14: 9765 | AI14: 10454 | AJ14: 10786
A15: Accounts receivables | B15: 7846.892 | C15: 9728.212 | D15: 11776.775 | E15: 12227.186 | F15: 13664.847 | H15: Accounts receivables | I15: =7132+10892+714 -> 18738 | J15: =6754+7221+793+1002 -> 15770 | K15: =6541+6851+939+817 -> 15148 | L15: =7214+6102+692+640 -> 14648 | M15: =6804+6259+900+947 -> 14910 | O15: Total assets | P15: 319616 | Q15: 365264 | R15: 359268 | S15: 402392 | T15: 450256 | W15: Total assets | X15: 333779 | Y15: 364840 | Z15: 411976 | AA15: 512163 | AB15: 619003 | AE15: Total assets | AF15: 131107 | AG15: 109297 | AH15: 134384 | AI15: 140976 | AJ15: 168361
A16: Inventories | B16: 0 | C16: 0 | D16: 0 | E16: 0 | F16: 0 | H16: Inventories | I16: 1839 | J16: 1649 | K16: 1552 | L16: 1161 | M16: 1289 | O16: Inventories | P16: 728 | Q16: 1170 | R16: 2670 | S16: 0 | T16: 0 | W16: Inventories | X16: 2636 | Y16: 3742 | Z16: 2500 | AA16: 1246 | AB16: 938 | AE16: Inventories | AF16: 0 | AG16: 0 | AH16: 0 | AI16: 0 | AJ16: 0
A17: Total current assets | B17: 17749.756 | C17: 19666.511 | D17: 21610.871 | E17: 23381.931 | F17: 20857.781 | H17: Total current assets | I17: 39165 | J17: 29539 | K17: 29118 | L17: 32908 | M17: 34482 | O17: Total current assets | P17: 174296 | Q17: 188143 | R17: 164795 | S17: 171530 | T17: 163711 | W17: Total current assets | X17: 184406 | Y17: 169684 | Z17: 184257 | AA17: 159734 | AB17: 191131 | AE17: Total current assets | AF17: 55567 | AG17: 31633 | AH17: 21004 | AI17: 22554 | AJ17: 24579
A18: PPE | B18: 1545.568 | C18: 1639.105 | D18: 1659.14 | E18: 1530.007 | F18: 1521.119 | H18: PPE | I18: 10040 | J18: 5694 | K18: 5334 | L18: 5501 | M18: 5731 | O18: PPE | P18: 84749 | Q18: 97599 | R18: 112668 | S18: 134345 | T18: 171036 | W18: PPE | X18: 59715 | Y18: 74398 | Z18: 95641 | AA18: 135591 | AB18: 204966 | AE18: PPE | AF18: 7049 | AG18: 9716 | AH18: 17069 | AI18: 21536 | AJ18: 43522
A19: Accounts payables | B19: 1349.874 | C19: 2274.057 | D19: 2559.485 | E19: 2491.173 | F19: 2743.807 | H19: Accounts payables | I19: 4908 | J19: 3955 | K19: 4051 | L19: 4132 | M19: 4032 | O19: Accounts payables | P19: 5589 | Q19: 6037 | R19: 5128 | S19: 7493 | T19: 7987 | W19: Accounts payables | X19: 15163 | Y19: 19000 | Z19: 18095 | AA19: 21996 | AB19: 27724 | AE19: Accounts payables | AF19: 745 | AG19: 1317 | AH19: 1204 | AI19: 2357 | AJ19: 5113
A20: Total current liabilities | B20: 12662.59 | C20: 15708.867 | D20: 17523.496 | E20: 18009.038 | F20: 18976.127 | H20: Total current liabilities | I20: 39869 | J20: 33619 | K20: 31505 | L20: 34122 | M20: 33142 | O20: Total current liabilities | P20: 56834 | Q20: 64254 | R20: 69300 | S20: 81814 | T20: 89122 | W20: Total current liabilities | X20: 88657 | Y20: 95082 | Z20: 104149 | AA20: 125286 | AB20: 141218 | AE20: Total current liabilities | AF20: 24164 | AG20: 19511 | AH20: 23090 | AI20: 31544 | AJ20: 32643
A21: Total debt | B21: =7.82+54.052 -> 61.872 | C21: =12.08+53.473 -> 65.553 | D21: =9.175+45.893 -> 55.068 | E21: =104.81+43.093 -> 147.903 | F21: =946.229+78.628 -> 1024.857 | H21: Total debt | I21: =7183+54355 -> 61538 | J21: =6787+44917 -> 51704 | K21: =4760+46189 -> 50949 | L21: =6426+50121 -> 56547 | M21: =5089+49884 -> 54973 | O21: Total debt | P21: =13932 -> 13932 | Q21: =14817 -> 14817 | R21: 14701 | S21: =11870 -> 11870 | T21: 10883 | W21: Total debt | X21: =8072+50074 -> 58146 | Y21: =2749+47032 -> 49781 | Z21: =5247+41990 -> 47237 | AA21: =6693+2249+42688 -> 51630 | AB21: =2999+40152 -> 43151 | AE21: Total debt | AF21: =75995 -> 75995 | AG21: =3749+72110 -> 75859 | AH21: =4061+86420 -> 90481 | AI21: =10605+76264 -> 86869 | AJ21: =7271+85297 -> 92568
A22: Shareholder's equity | B22: 17499.173 | C22: 20097.114 | D22: 22747.088 | E22: 26458.593 | F22: 29168.248 | H22: Shareholder's equity | I22: 20727 | J22: 18996 | K22: 22021 | L22: 22613 | M22: 27393 | O22: Shareholder's equity | P22: 222544 | Q22: 251635 | R22: 256144 | S22: 283379 | T22: 325084 | W22: Shareholder's equity | X22: 141988 | Y22: 166542 | Z22: 206223 | AA22: 268477 | AB22: 343479 | AE22: Shareholder's equity | AF22: 5952 | AG22: -5768 | AH22: 1556 | AI22: 9239 | AJ22: 20969
A24: CASH FLOW STATEMENT | H24: CASH FLOW STATEMENT | O24: CASH FLOW STATEMENT | W24: CASH FLOW STATEMENT | AE24: CASH FLOW STATEMENT
A25: Particulars | B25: 2020 | C25: 2021 | D25: 2022 | E25: 2023 | F25: 2024 | H25: Particulars | I25: 2020 | J25: 2021 | K25: 2022 | L25: 2023 | M25: 2024 | O25: Particulars | P25: 2020 | Q25: 2021 | R25: 2022 | S25: 2023 | T25: 2024 | W25: Particulars | X25: 2020 | Y25: 2021 | Z25: 2022 | AA25: 2023 | AB25: 2024 | AE25: Particulars | AF25: 2020 | AG25: 2021 | AH25: 2022 | AI25: 2023 | AJ25: 2024
A26: Cash flow from operating activities | B26: 8215.152 | C26: 8975.148 | D26: 9541.129 | E26: 9524.268 | F26: 9131.027 | H26: Cash flow from operating activities | I26: 18197 | J26: 12796 | K26: 10435 | L26: 13931 | M26: 13445 | O26: Cash flow from operating activities | P26: 65124 | Q26: 91652 | R26: 91495 | S26: 101746 | T26: 125299 | W26: Cash flow from operating activities | X26: 76740 | Y26: 89035 | Z26: 87582 | AA26: 118548 | AB26: 136162 | AE26: Cash flow from operating activities | AF26: 15887 | AG26: 9539 | AH26: 17165 | AI26: 18673 | AJ26: 20821
A27: Capex | B27: 599.132 | C27: 580.132 | D27: 717.998 | E27: 528.172 | F27: 516.509 | H27: Capex | I27: 2618 | J27: 2062 | K27: 1346 | L27: 1245 | M27: 1048 | O27: Capex | P27: 22281 | Q27: 24640 | R27: 31485 | S27: 32251 | T27: 52535 | W27: Capex | X27: 20622 | Y27: 23886 | Z27: 28107 | AA27: 44477 | AB27: 64551 | AE27: Capex | AF27: 2135 | AG27: 4511 | AH27: 8695 | AI27: 6866 | AJ27: 21215
A28: Dividends paid | B28: 2037.733 | C28: 2236.094 | D28: 2457.306 | E28: 2827.394 | F28: 3241.479 | H28: Dividends paid | I28: 5797 | J28: 5869 | K28: 5948 | L28: 6040 | M28: 6147 | O28: Dividends paid | P28: 0 | Q28: 0 | R28: 0 | S28: 0 | T28: 7363 | W28: Dividends paid | X28: 16521 | Y28: 18135 | Z28: 19800 | AA28: 21771 | AB28: 24082 | AE28: Dividends paid | AF28: 3063 | AG28: 3457 | AH28: 3668 | AI28: 4391 | AJ28: 4743
A29: Debt repaid | B29: 6.719 | C29: 7.798 | D29: 16.453 | E29: 0 | F29: 771.246 | H29: Debt repaid | I29: =13365+853 -> 14218 | J29: =8597+40 -> 8637 | K29: =6800-217 -> 6583 | L29: =5082+7 -> 5089 | M29: =6615-30 -> 6585 | O29: Debt repaid | P29: =2100 -> 2100 | Q29: 21435 | R29: 54068 | S29: 11550 | T29: 12701 | W29: Debt repaid | X29: 3750 | Y29: 9023 | Z29: 2750 | AA29: 29070 | AB29: 3216 | AE29: Debt repaid | AF29: 2631 | AG29: 8250 | AH29: 21050 | AI29: 3500 | AJ29: 15841
O32: Particulars | P32: 2020 | Q32: 2021 | R32: 2022 | S32: 2023 | T32: 2024 | W32: Particulars | X32: 2020 | Y32: 2021 | Z32: 2022 | AA32: 2023 | AB32: 2024 | AE32: Particulars | AF32: 2020 | AG32: 2021 | AH32: 2022 | AI32: 2023 | AJ32: 2024
O33: Revenue | P33: =P3 -> 182527 | Q33: =Q3 -> 257637 | R33: =R3 -> 282836 | S33: =S3 -> 307394 | T33: =T3 -> 350018 | W33: Revenue | X33: =X3 -> 168088 | Y33: =Y3 -> 198270 | Z33: =Z3 -> 211915 | AA33: =AA3 -> 245122 | AB33: =AB3 -> 281724 | AE33: Revenue | AF33: =AF3 -> 40479 | AG33: =AG3 -> 42440 | AH33: =AH3 -> 49954 | AI33: =AI3 -> 52961 | AJ33: =AJ3 -> 57399
O34: Operating income | P34: =P6 -> 48082 | Q34: =Q6 -> 90734 | R34: =R6 -> 71328 | S34: =S6 -> 85717 | T34: =T6 -> 119815 | W34: Operating income | X34: =X6 -> 71102 | Y34: =Y6 -> 83716 | Z34: =Z6 -> 89311 | AA34: =AA6 -> 107787 | AB34: =AB6 -> 123627 | AE34: Operating income | AF34: =AF6 -> 16874 | AG34: =AG6 -> 11554 | AH34: =AH6 -> 16213 | AI34: =AI6 -> 18265 | AJ34: =AJ6 -> 20045
O35: Net income | P35: =P10 -> 26437 | Q35: =Q10 -> 63246 | R35: =R10 -> 43687 | S35: =S10 -> 61541 | T35: =T10 -> 84539 | W35: Net income | X35: =X10 -> 47255 | Y35: =Y10 -> 56231 | Z35: =Z10 -> 56505 | AA35: =AA10 -> 62866 | AB35: =AB10 -> 65254 | AE35: Net income | AF35: =AF10 -> 12252 | AG35: =AG10 -> 6717 | AH35: =AH10 -> 8503 | AI35: =AI10 -> 10467 | AJ35: =AJ10 -> 12443
O37: Particulars | P37: 2025 | Q37: 2026 | R37: 2027 | S37: 2028 | T37: 2029 | U37: 2030 | W37: Particulars | X37: 2025 | Y37: 2026 | Z37: 2027 | AA37: 2028 | AB37: 2029 | AC37: 2030 | AE37: Particulars | AF37: 2025 | AG37: 2026 | AH37: 2027 | AI37: 2028 | AJ37: 2029 | AK37: 2030
O38: Revenue | P38: =DCF!R3 -> 398697.06 | Q38: =DCF!S3 -> 453591.71 | R38: =DCF!T3 -> 512921.89 | S38: =DCF!U3 -> 573303.45 | T38: =DCF!V3 -> 634044.21 | U38: =DCF!W3 -> 694502.75 | W38: Revenue | X38: =DCF!Z3 -> 312378.6 | Y38: =DCF!AA3 -> 347388.45 | Z38: =DCF!AB3 -> 388658.05 | AA38: =DCF!AC3 -> 435753.91 | AB38: =DCF!AD3 -> 488028.61 | AC38: =DCF!AE3 -> 540719.81 | AE38: Revenue | AF38: =DCF!AH3 -> 61551.584 | AG38: =DCF!AI3 -> 66004.591 | AH38: =DCF!AJ3 -> 70779.755 | AI38: =DCF!AK3 -> 75900.383 | AJ38: =DCF!AL3 -> 81391.467 | AK38: =DCF!AM3 -> 87279.809
O39: Operating income | P39: =DCF!R4 -> 120057.49 | Q39: =DCF!S4 -> 136587.62 | R39: =DCF!T4 -> 154453.4 | S39: =DCF!U4 -> 172635.77 | T39: =DCF!V4 -> 190926.3 | U39: =DCF!W4 -> 209131.86 | W39: Operating income | X39: =DCF!Z4 -> 134419.42 | Y39: =DCF!AA4 -> 149484.49 | Z39: =DCF!AB4 -> 167243.18 | AA39: =DCF!AC4 -> 187508.97 | AB39: =DCF!AD4 -> 210003.26 | AC39: =DCF!AE4 -> 232676.77 | AE39: Operating income | AF39: =DCF!AH4 -> 20991.253 | AG39: =DCF!AI4 -> 22509.885 | AH39: =DCF!AJ4 -> 24138.384 | AI39: =DCF!AK4 -> 25884.698 | AJ39: =DCF!AL4 -> 27757.35 | AK39: =DCF!AM4 -> 29765.482
O40: Net income | P40: =DCF!R5 -> 92444.267 | Q40: =DCF!S5 -> 105172.47 | R40: =DCF!T5 -> 118929.11 | S40: =DCF!U5 -> 132929.54 | T40: =DCF!V5 -> 147013.25 | U40: =DCF!W5 -> 161031.53 | W40: Net income | X40: =DCF!Z5 -> 103502.95 | Y40: =DCF!AA5 -> 115103.06 | Z40: =DCF!AB5 -> 128777.25 | AA40: =DCF!AC5 -> 144381.91 | AB40: =DCF!AD5 -> 161702.51 | AC40: =DCF!AE5 -> 179161.11 | AE40: Net income | AF40: =DCF!AH5 -> 16163.265 | AG40: =DCF!AI5 -> 17332.611 | AH40: =DCF!AJ5 -> 18586.555 | AI40: =DCF!AK5 -> 19931.217 | AJ40: =DCF!AL5 -> 21373.16 | AK40: =DCF!AM5 -> 22919.421
O41: FCFF | P41: =DCF!R9 -> -4823.1964 | Q41: =DCF!S9 -> 54398.705 | R41: =DCF!T9 -> 62510.562 | S41: =DCF!U9 -> 72023.304 | T41: =DCF!V9 -> 81846.198 | U41: =DCF!W9 -> 91855.706 | W41: FCFF | X41: =DCF!Z9 -> 34692.079 | Y41: =DCF!AA9 -> 77715.131 | Z41: =DCF!AB9 -> 86311.235 | AA41: =DCF!AC9 -> 96519.977 | AB41: =DCF!AD9 -> 108241.57 | AC41: =DCF!AE9 -> 121511.91 | AE41: FCFF | AF41: =DCF!AH9 -> 11509.308 | AG41: =DCF!AI9 -> 13640.671 | AH41: =DCF!AJ9 -> 14627.518 | AI41: =DCF!AK9 -> 15685.759 | AJ41: =DCF!AL9 -> 16820.56 | AK41: =DCF!AM9 -> 18037.459

Sheet Assumptions & WACC
A1: Assumptions
A2: Metric | B2: Accenture | C2: IBM | D2: Alphabet | E2: Microsoft | F2: Oracle | H2: Current | I2: 2020 | J2: 2021 | K2: 2022 | L2: 2023 | M2: 2024
A3: Revenue CAGR | B3: =(Table1[[#This Row],[2024]]/Table1[[#This Row],[2020]])^(1/5)-1 -> 0.079221186 | C3: =(Table18[[#This Row],[2024]]/Table18[[#This Row],[2020]])^(1/5)-1 -> 0.026058526 | D3: =((Table120[[#This Row],[2024]]/Table120[[#This Row],[2020]])^(1/5)-1) -> 0.13907587 | E3: =(Table1826[[#This Row],[2024]]/Table1826[[#This Row],[2020]])^(1/5)-1 -> 0.10881075 | F3: =(Financials!$AJ3/Financials!$AF3)^(1/5)-1 -> 0.072345936 | H3: WC-Accenture | I3: =Financials!B17-Financials!B20 -> 5087.166 | J3: =Financials!C17-Financials!C20 -> 3957.644 | K3: =Financials!D17-Financials!D20 -> 4087.375 | L3: =Financials!E17-Financials!E20 -> 5372.893 | M3: =Financials!F17-Financials!F20 -> 1881.654
A4: Operating margin (EBIT) | B4: =AVERAGE(Financials!B6:F6)/AVERAGE(Financials!B3:F3) -> 0.14680746 | C4: =AVERAGE(Financials!I6:M6)/AVERAGE(Financials!I3:M3) -> 0.10088621 | D4: =AVERAGE(Financials!P6:T6)/AVERAGE(Financials!P3:T3) -> 0.30112459 | E4: =AVERAGE(Financials!X6:AB6)/AVERAGE(Financials!X3:AB3) -> 0.43030932 | F4: =AVERAGE(Financials!AF6:AJ6)/AVERAGE(Financials!AF3:AJ3) -> 0.34103514 | H4: WC-IBM | I4: =Financials!I17-Financials!I20 -> -704 | J4: =Financials!J17-Financials!J20 -> -4080 | K4: =Financials!K17-Financials!K20 -> -2387 | L4: =Financials!L17-Financials!L20 -> -1214 | M4: =Financials!M17-Financials!M20 -> 1340
A5: Depreciation rate | B5: =AVERAGE(Financials!B7:F7)/AVERAGE(Financials!B3:F3) -> 0.035737406 | C5: =AVERAGE(Financials!I7:M7)/AVERAGE(Financials!I3:M3) -> 0.090626596 | D5: =AVERAGE(Financials!P7:T7)/AVERAGE(Financials!P3:T3) -> 0.050219065 | E5: =AVERAGE(Financials!X7:AB7)/AVERAGE(Financials!X3:AB3) -> 0.087272954 | F5: =AVERAGE(Financials!AH7:AJ7)/AVERAGE(Financials!AH3:AJ3) -> 0.055509812 | H5: WC-Alphabet | I5: =Financials!P17-Financials!P20 -> 117462 | J5: =Financials!Q17-Financials!Q20 -> 123889 | K5: =Financials!R17-Financials!R20 -> 95495 | L5: =Financials!S17-Financials!S20 -> 89716 | M5: =Financials!T17-Financials!T20 -> 74589
A6: CapEx | B6: =AVERAGE(Financials!B27:F27)/AVERAGE(Financials!B3:F3) -> 0.010305867 | C6: =AVERAGE(Financials!I27:M27)/AVERAGE(Financials!I3:M3) -> 0.027946868 | D6: =AVERAGE(Financials!P27:T27)/AVERAGE(Financials!P3:T3) -> 0.11821978 | E6: =AVERAGE(Financials!X27:AB27)/AVERAGE(Financials!X3:AB3) -> 0.1643651 | F6: =AVERAGE(Financials!AF27:AI27)/AVERAGE(Financials!AF3:AI3) -> 0.11949912 | H6: WC-Microsoft | I6: =Financials!X17-Financials!X20 -> 95749 | J6: =Financials!Y17-Financials!Y20 -> 74602 | K6: =Financials!Z17-Financials!Z20 -> 80108 | L6: =Financials!AA17-Financials!AA20 -> 34448 | M6: =Financials!AB17-Financials!AB20 -> 49913
A7: Working capital | B7: =AVERAGE(I3:M3)/AVERAGE(Financials!B3:F3) -> 0.071416387 | C7: =AVERAGE(I4:M4)/AVERAGE(Financials!I3:M3) -> -0.023666989 | D7: =AVERAGE(I5:M5)/AVERAGE(Financials!P3:T3) -> 0.36304451 | E7: =AVERAGE(I6:M6)/AVERAGE(Financials!X3:AB3) -> 0.3029719 | F7: =AVERAGE(Table19[[#This Row],[2022]:[2024]])/AVERAGE(Financials!AH3:AJ3) -> -0.1193907 | H7: WC-Oracle | I7: =Financials!AF17-Financials!AF20 -> 31403 | J7: =Financials!AG17-Financials!AG20 -> 12122 | K7: =Financials!AH17-Financials!AH20 -> -2086 | L7: =Financials!AI17-Financials!AI20 -> -8990 | M7: =Financials!AJ17-Financials!AJ20 -> -8064
A8: Forecast horizon (yrs) | B8: 6 | C8: 6 | D8: 6 | E8: 6 | F8: 6
A9: Risk-free rate | B9: =$I$24 -> 0.04125 | C9: =$I$24 -> 0.04125 | D9: =$I$24 -> 0.04125 | E9: =$I$24 -> 0.04125 | F9: =$I$24 -> 0.04125
A10: Equity risk premium | B10: 0.048 | C10: 0.048 | D10: 0.048 | E10: 0.048 | F10: 0.048 | H10: Forecast | I10: 2025 | J10: 2026 | K10: 2027 | L10: 2028 | M10: 2029 | N10: 2030
A11: Beta | B11: ='Company Profile'!B9 -> 1.2608 | C11: ='Company Profile'!C9 -> 0.6968 | D11: ='Company Profile'!D9 -> 1.0733 | E11: ='Company Profile'!E9 -> 1.0728 | F11: ='Company Profile'!F9 -> 1.6774 | H11: =H3 -> WC-Accenture | I11: =DCF!B3*'Assumptions & WACC'!$B$7 -> 5001.8351 | J11: =DCF!C3*'Assumptions & WACC'!$B$7 -> 5398.0865 | K11: =DCF!D3*'Assumptions & WACC'!$B$7 -> 5825.7293 | L11: =DCF!E3*'Assumptions & WACC'!$B$7 -> 6287.2504 | M11: =DCF!F3*'Assumptions & WACC'!$B$7 -> 6785.3339 | N11: =DCF!G3*'Assumptions & WACC'!$B$7 -> 7322.8761
A12: Cost of equity | B12: =B9+(B10*B11) -> 0.1017684 | C12: =C9+(C10*C11) -> 0.0746964 | D12: =D9+(D10*D11) -> 0.0927684 | E12: =E9+(E10*E11) -> 0.0927444 | F12: =F9+(F10*F11) -> 0.1217652 | H12: =H4 -> WC-IBM | I12: =DCF!J3*'Assumptions & WACC'!$C$7 -> -1523.876 | J12: =DCF!K3*'Assumptions & WACC'!$C$7 -> -1563.586 | K12: =DCF!L3*'Assumptions & WACC'!$C$7 -> -1604.3307 | L12: =DCF!M3*'Assumptions & WACC'!$C$7 -> -1646.1372 | M12: =DCF!N3*'Assumptions & WACC'!$C$7 -> -1689.0331 | N12: =DCF!O3*'Assumptions & WACC'!$C$7 -> -1733.0469
A13: Kd (pre-tax) | B13: =AVERAGE(Financials!B8:F8)/AVERAGE(Financials!B21:F21) -> 0.1817941 | C13: =AVERAGE(Financials!I8:M8)/AVERAGE(Financials!I21:M21) -> 0.02530911 | D13: =AVERAGE(Financials!P8:T8)/AVERAGE(Financials!P21:T21) -> 0.021358549 | E13: =AVERAGE(Financials!X8:AB8)/AVERAGE(Financials!X21:AB21) -> 0.047130369 | F13: =AVERAGE(Financials!AF8:AJ8)/AVERAGE(Financials!AF21:AJ21) -> 0.037574803 | H13: =H5 -> WC-Alphabet | I13: =DCF!R3*'Assumptions & WACC'!$D$7 -> 144744.78 | J13: =DCF!S3*'Assumptions & WACC'!$D$7 -> 164673.98 | K13: =DCF!T3*'Assumptions & WACC'!$D$7 -> 186213.48 | L13: =DCF!U3*'Assumptions & WACC'!$D$7 -> 208134.67 | M13: =DCF!V3*'Assumptions & WACC'!$D$7 -> 230186.27 | N13: =DCF!W3*'Assumptions & WACC'!$D$7 -> 252135.41
A14: Tax rate | B14: 0.23 | C14: 0.23 | D14: 0.23 | E14: 0.23 | F14: 0.23 | H14: =H6 -> WC-Microsoft | I14: =DCF!Z3*'Assumptions & WACC'!$E$7 -> 94641.937 | J14: =DCF!AA3*'Assumptions & WACC'!$E$7 -> 105248.94 | K14: =DCF!AB3*'Assumptions & WACC'!$E$7 -> 117752.47 | L14: =DCF!AC3*'Assumptions & WACC'!$E$7 -> 132021.19 | M14: =DCF!AD3*'Assumptions & WACC'!$E$7 -> 147858.96 | N14: =DCF!AE3*'Assumptions & WACC'!$E$7 -> 163822.91
A15: Kd (after tax) | B15: =B13*(1-B14) -> 0.13998146 | C15: =C13*(1-C14) -> 0.019488015 | D15: =D13*(1-D14) -> 0.016446083 | E15: =E13*(1-E14) -> 0.036290384 | F15: =F13*(1-F14) -> 0.028932599 | H15: =H7 -> WC-Oracle | I15: =DCF!AH3*'Assumptions & WACC'!$F$7 -> -7348.6865 | J15: =DCF!AI3*'Assumptions & WACC'!$F$7 -> -7880.3341 | K15: =DCF!AJ3*'Assumptions & WACC'!$F$7 -> -8450.4442 | L15: =DCF!AK3*'Assumptions & WACC'!$F$7 -> -9061.7995 | M15: =DCF!AL3*'Assumptions & WACC'!$F$7 -> -9717.3839 | N15: =DCF!AM3*'Assumptions & WACC'!$F$7 -> -10420.397
A16: Total debt | B16: =Financials!F21 -> 1024.857 | C16: =Financials!M21 -> 54973 | D16: =Financials!T21 -> 10883 | E16: =Financials!AB21 -> 43151 | F16: =Financials!AJ21 -> 92568
A17: Market cap | B17: ='Company Profile'!B8 -> 151413.11 | C17: ='Company Profile'!C8 -> 270942.35 | D17: ='Company Profile'!D8 -> 3434084 | E17: ='Company Profile'!E8 -> 3670293.6 | F17: ='Company Profile'!F8 -> 648227.57
A18: Total capital | B18: =B16+B17 -> 152437.97 | C18: =C16+C17 -> 325915.35 | D18: =D16+D17 -> 3444967 | E18: =E16+E17 -> 3713444.6 | F18: =F16+F17 -> 740795.57 | H18: Company | I18: 2025 | J18: 2026 | K18: 2027 | L18: 2028 | M18: 2029 | N18: 2030
A19: Debt weight | B19: =B16/B18 -> 0.0067231084 | C19: =C16/C18 -> 0.16867263 | D19: =D16/D18 -> 0.0031591014 | E19: =E16/E18 -> 0.011620208 | F19: =F16/F18 -> 0.12495755 | H19: Alphabet | I19: =D3 -> 0.13907587 | J19: =I19*(1-0.01) -> 0.13768511 | K19: =J19*(1-0.05) -> 0.13080086 | L19: =K19*(1-0.1) -> 0.11772077 | M19: =L19*(1-0.1) -> 0.10594869 | N19: =M19*(1-0.1) -> 0.095353825
A20: Equity weight | B20: =B17/B18 -> 0.99327689 | C20: =C17/C18 -> 0.83132737 | D20: =D17/D18 -> 0.9968409 | E20: =E17/E18 -> 0.98837979 | F20: =F17/F18 -> 0.87504245 | H20: Microsoft | I20: =E3 -> 0.10881075 | J20: =I20*(1+0.03) -> 0.11207507 | K20: =J20*(1+0.06) -> 0.11879958 | L20: =K20*(1+0.02) -> 0.12117557 | M20: =L20*(1-0.01) -> 0.11996381 | N20: =M20*(1-0.1) -> 0.10796743
A21: WACC | B21: =(B12*B20)+(B15*B19) -> 0.10202531 | C21: =(C12*C20)+(C15*C19) -> 0.065384256 | D21: =(D12*D20)+(D15*D19) -> 0.09252729 | E21: =(E12*E20)+(E15*E19) -> 0.092088393 | F21: =(F12*F20)+(F15*F19) -> 0.11016507
A22: Terminal year | B22: 2030 | C22: 2030 | D22: 2030 | E22: 2030 | F22: 2030
A23: PV discount rate (terminal year) | B23: =1/(1+B21)^6 -> 0.55827809 | C23: =1/(1+C21)^6 -> 0.68385236 | D23: =1/(1+D21)^6 -> 0.58803914 | E23: =1/(1+E21)^6 -> 0.58945853 | F23: =1/(1+F21)^6 -> 0.53416405 | I23: #VALUE!
A24: Cash & cash equivalents | B24: =Financials!F14 -> 5004.469 | C24: =Financials!M14 -> 13947 | D24: =Financials!T14 -> 95657 | E24: =Financials!AB14 -> 94565 | F24: =Financials!AJ14 -> 10786 | I24: {=(_FV(I23,"Price"))/100} -> 0.04125
A25: Terminal growth rate | B25: 0.025 | C25: 0.025 | D25: 0.04 | E25: 0.03 | F25: 0.045
A26: Shares Outstanding | B26: ='Company Profile'!B6 -> 620.1389 | C26: ='Company Profile'!C6 -> 934.7352 | D26: ='Company Profile'!D6 -> 12067 | E26: ='Company Profile'!E6 -> 7432.377 | F26: ='Company Profile'!F6 -> 2850.793

Sheet DCF
A1: DCF | G1: Accenture | O1: IBM | Q1: DCF | W1: Alphabet | AE1: Microsoft | AG1: DCF | AM1: Oracle
A2: Particulars | B2: 2025 | C2: 2026 | D2: 2027 | E2: 2028 | F2: 2029 | G2: 2030 | I2: Particulars | J2: 2025 | K2: 2026 | L2: 2027 | M2: 2028 | N2: 2029 | O2: 2030 | Q2: Particulars | R2: 2025 | S2: 2026 | T2: 2027 | U2: 2028 | V2: 2029 | W2: 2030 | Y2: Particulars | Z2: 2025 | AA2: 2026 | AB2: 2027 | AC2: 2028 | AD2: 2029 | AE2: 2030 | AG2: Particulars | AH2: 2025 | AI2: 2026 | AJ2: 2027 | AK2: 2028 | AL2: 2029 | AM2: 2030
A3: Revenue | B3: =Table1[[#This Row],[2024]]*(1+'Assumptions & WACC'!B3) -> 70037.639 | C3: =Table9[[#This Row],[2025]]*(1+'Assumptions & WACC'!$B$3) -> 75586.104 | D3: =Table9[[#This Row],[2026]]*(1+'Assumptions & WACC'!$B$3) -> 81574.125 | E3: =Table9[[#This Row],[2027]]*(1+'Assumptions & WACC'!$B$3) -> 88036.523 | F3: =Table9[[#This Row],[2028]]*(1+'Assumptions & WACC'!$B$3) -> 95010.881 | G3: =Table9[[#This Row],[2029]]*(1+'Assumptions & WACC'!$B$3) -> 102537.76 | I3: Revenue | J3: =Table18[[#This Row],[2024]]*(1+'Assumptions & WACC'!C3) -> 64388.251 | K3: =Table10[[#This Row],[2025]]*(1+'Assumptions & WACC'!$C$3) -> 66066.114 | L3: =Table10[[#This Row],[2026]]*(1+'Assumptions & WACC'!$C$3) -> 67787.699 | M3: =Table10[[#This Row],[2027]]*(1+'Assumptions & WACC'!$C$3) -> 69554.147 | N3: =Table10[[#This Row],[2028]]*(1+'Assumptions & WACC'!$C$3) -> 71366.625 | O3: =Table10[[#This Row],[2029]]*(1+'Assumptions & WACC'!$C$3) -> 73226.334 | Q3: Revenue | R3: =Table120[[#This Row],[2024]]*(1+'Assumptions & WACC'!I19) -> 398697.06 | S3: =Table933[[#This Row],[2025]]*(1+'Assumptions & WACC'!J19) -> 453591.71 | T3: =Table933[[#This Row],[2026]]*(1+'Assumptions & WACC'!K19) -> 512921.89 | U3: =Table933[[#This Row],[2027]]*(1+'Assumptions & WACC'!L19) -> 573303.45 | V3: =Table933[[#This Row],[2028]]*(1+'Assumptions & WACC'!M19) -> 634044.21 | W3: =Table933[[#This Row],[2029]]*(1+'Assumptions & WACC'!N19) -> 694502.75 | Y3: Revenue | Z3: =Table1826[[#This Row],[2024]]*(1+'Assumptions & WACC'!I20) -> 312378.6 | AA3: =Table1034[[#This Row],[2025]]*(1+'Assumptions & WACC'!J20) -> 347388.45 | AB3: =Table1034[[#This Row],[2026]]*(1+'Assumptions & WACC'!K20) -> 388658.05 | AC3: =Table1034[[#This Row],[2027]]*(1+'Assumptions & WACC'!L20) -> 435753.91 | AD3: =Table1034[[#This Row],[2028]]*(1+'Assumptions & WACC'!M20) -> 488028.61 | AE3: =Table1034[[#This Row],[2029]]*(1+'Assumptions & WACC'!N20) -> 540719.81 | AG3: Revenue | AH3: =Financials!$AJ$3*(1+'Assumptions & WACC'!F3) -> 61551.584 | AI3: =Table93337[[#This Row],[2025]]*(1+'Assumptions & WACC'!$F$3) -> 66004.591 | AJ3: =Table93337[[#This Row],[2026]]*(1+'Assumptions & WACC'!$F$3) -> 70779.755 | AK3: =Table93337[[#This Row],[2027]]*(1+'Assumptions & WACC'!$F$3) -> 75900.383 | AL3: =Table93337[[#This Row],[2028]]*(1+'Assumptions & WACC'!$F$3) -> 81391.467 | AM3: =Table93337[[#This Row],[2029]]*(1+'Assumptions & WACC'!$F$3) -> 87279.809
A4: EBIT | B4: =B3*'Assumptions & WACC'!$B$4 -> 10282.048 | C4: =C3*'Assumptions & WACC'!$B$4 -> 11096.604 | D4: =D3*'Assumptions & WACC'!$B$4 -> 11975.69 | E4: =E3*'Assumptions & WACC'!$B$4 -> 12924.419 | F4: =F3*'Assumptions & WACC'!$B$4 -> 13948.306 | G4: =G3*'Assumptions & WACC'!$B$4 -> 15053.308 | I4: EBIT | J4: =J3*'Assumptions & WACC'!$C$4 -> 6495.8866 | K4: =K3*'Assumptions & WACC'!$C$4 -> 6665.1598 | L4: =L3*'Assumptions & WACC'!$C$4 -> 6838.8441 | M4: =M3*'Assumptions & WACC'!$C$4 -> 7017.0543 | N4: =N3*'Assumptions & WACC'!$C$4 -> 7199.9084 | O4: =O3*'Assumptions & WACC'!$C$4 -> 7387.5274 | Q4: EBIT | R4: =R3*'Assumptions & WACC'!$D$4 -> 120057.49 | S4: =S3*'Assumptions & WACC'!$D$4 -> 136587.62 | T4: =T3*'Assumptions & WACC'!$D$4 -> 154453.4 | U4: =U3*'Assumptions & WACC'!$D$4 -> 172635.77 | V4: =V3*'Assumptions & WACC'!$D$4 -> 190926.3 | W4: =W3*'Assumptions & WACC'!$D$4 -> 209131.86 | Y4: EBIT | Z4: =Z3*'Assumptions & WACC'!$E$4 -> 134419.42 | AA4: =AA3*'Assumptions & WACC'!$E$4 -> 149484.49 | AB4: =AB3*'Assumptions & WACC'!$E$4 -> 167243.18 | AC4: =AC3*'Assumptions & WACC'!$E$4 -> 187508.97 | AD4: =AD3*'Assumptions & WACC'!$E$4 -> 210003.26 | AE4: =AE3*'Assumptions & WACC'!$E$4 -> 232676.77 | AG4: EBIT | AH4: =AH3*'Assumptions & WACC'!$F$4 -> 20991.253 | AI4: =AI3*'Assumptions & WACC'!$F$4 -> 22509.885 | AJ4: =AJ3*'Assumptions & WACC'!$F$4 -> 24138.384 | AK4: =AK3*'Assumptions & WACC'!$F$4 -> 25884.698 | AL4: =AL3*'Assumptions & WACC'!$F$4 -> 27757.35 | AM4: =AM3*'Assumptions & WACC'!$F$4 -> 29765.482
A5: NOPAT | B5: =B4*(1-'Assumptions & WACC'!$B$14) -> 7917.177 | C5: =C4*(1-'Assumptions & WACC'!$B$14) -> 8544.3851 | D5: =D4*(1-'Assumptions & WACC'!$B$14) -> 9221.2814 | E5: =E4*(1-'Assumptions & WACC'!$B$14) -> 9951.8023 | F5: =F4*(1-'Assumptions & WACC'!$B$14) -> 10740.196 | G5: =G4*(1-'Assumptions & WACC'!$B$14) -> 11591.047 | I5: NOPAT | J5: =J4*(1-'Assumptions & WACC'!$C$14) -> 5001.8327 | K5: =K4*(1-'Assumptions & WACC'!$C$14) -> 5132.1731 | L5: =L4*(1-'Assumptions & WACC'!$C$14) -> 5265.9099 | M5: =M4*(1-'Assumptions & WACC'!$C$14) -> 5403.1318 | N5: =N4*(1-'Assumptions & WACC'!$C$14) -> 5543.9294 | O5: =O4*(1-'Assumptions & WACC'!$C$14) -> 5688.3961 | Q5: NOPAT | R5: =R4*(1-'Assumptions & WACC'!$B$14) -> 92444.267 | S5: =S4*(1-'Assumptions & WACC'!$B$14) -> 105172.47 | T5: =T4*(1-'Assumptions & WACC'!$B$14) -> 118929.11 | U5: =U4*(1-'Assumptions & WACC'!$B$14) -> 132929.54 | V5: =V4*(1-'Assumptions & WACC'!$B$14) -> 147013.25 | W5: =W4*(1-'Assumptions & WACC'!$B$14) -> 161031.53 | Y5: NOPAT | Z5: =Z4*(1-'Assumptions & WACC'!$C$14) -> 103502.95 | AA5: =AA4*(1-'Assumptions & WACC'!$C$14) -> 115103.06 | AB5: =AB4*(1-'Assumptions & WACC'!$C$14) -> 128777.25 | AC5: =AC4*(1-'Assumptions & WACC'!$C$14) -> 144381.91 | AD5: =AD4*(1-'Assumptions & WACC'!$C$14) -> 161702.51 | AE5: =AE4*(1-'Assumptions & WACC'!$C$14) -> 179161.11 | AG5: NOPAT | AH5: =AH4*(1-'Assumptions & WACC'!$B$14) -> 16163.265 | AI5: =AI4*(1-'Assumptions & WACC'!$B$14) -> 17332.611 | AJ5: =AJ4*(1-'Assumptions & WACC'!$B$14) -> 18586.555 | AK5: =AK4*(1-'Assumptions & WACC'!$B$14) -> 19931.217 | AL5: =AL4*(1-'Assumptions & WACC'!$B$14) -> 21373.16 | AM5: =AM4*(1-'Assumptions & WACC'!$B$14) -> 22919.421
A6: Depreciation | B6: =B3*'Assumptions & WACC'!$B$5 -> 2502.9635 | C6: =C3*'Assumptions & WACC'!$B$5 -> 2701.2513 | D6: =D3*'Assumptions & WACC'!$B$5 -> 2915.2476 | E6: =E3*'Assumptions & WACC'!$B$5 -> 3146.197 | F6: =F3*'Assumptions & WACC'!$B$5 -> 3395.4424 | G6: =G3*'Assumptions & WACC'!$B$5 -> 3664.4334 | I6: Depreciation | J6: =J3*'Assumptions & WACC'!$C$5 -> 5835.288 | K6: =K3*'Assumptions & WACC'!$C$5 -> 5987.347 | L6: =L3*'Assumptions & WACC'!$C$5 -> 6143.3684 | M6: =M3*'Assumptions & WACC'!$C$5 -> 6303.4555 | N6: =N3*'Assumptions & WACC'!$C$5 -> 6467.7143 | O6: =O3*'Assumptions & WACC'!$C$5 -> 6636.2534 | Q6: Depreciation | R6: =R3*'Assumptions & WACC'!$D$5 -> 20022.194 | S6: =S3*'Assumptions & WACC'!$D$5 -> 22778.951 | T6: =T3*'Assumptions & WACC'!$D$5 -> 25758.458 | U6: =U3*'Assumptions & WACC'!$D$5 -> 28790.763 | V6: =V3*'Assumptions & WACC'!$D$5 -> 31841.107 | W6: =W3*'Assumptions & WACC'!$D$5 -> 34877.279 | Y6: Depreciation | Z6: =Z3*'Assumptions & WACC'!$E$5 -> 27262.203 | AA6: =AA3*'Assumptions & WACC'!$E$5 -> 30317.617 | AB6: =AB3*'Assumptions & WACC'!$E$5 -> 33919.337 | AC6: =AC3*'Assumptions & WACC'!$E$5 -> 38029.531 | AD6: =AD3*'Assumptions & WACC'!$E$5 -> 42591.699 | AE6: =AE3*'Assumptions & WACC'!$E$5 -> 47190.215 | AG6: Depreciation | AH6: =AH3*'Assumptions & WACC'!$F$5 -> 3416.7169 | AI6: =AI3*'Assumptions & WACC'!$F$5 -> 3663.9025 | AJ6: =AJ3*'Assumptions & WACC'!$F$5 -> 3928.9709 | AK6: =AK3*'Assumptions & WACC'!$F$5 -> 4213.216 | AL6: =AL3*'Assumptions & WACC'!$F$5 -> 4518.025 | AM6: =AM3*'Assumptions & WACC'!$F$5 -> 4844.8858
A7: Capex | B7: =B3*'Assumptions & WACC'!$B$6 -> 721.79856 | C7: =C3*'Assumptions & WACC'!$B$6 -> 778.9803 | D7: =D3*'Assumptions & WACC'!$B$6 -> 840.69205 | E7: =E3*'Assumptions & WACC'!$B$6 -> 907.29267 | F7: =F3*'Assumptions & WACC'!$B$6 -> 979.16947 | G7: =G3*'Assumptions & WACC'!$B$6 -> 1056.7404 | I7: Capex | J7: =J3*'Assumptions & WACC'!$C$6 -> 1799.4499 | K7: =K3*'Assumptions & WACC'!$C$6 -> 1846.3409 | L7: =L3*'Assumptions & WACC'!$C$6 -> 1894.4539 | M7: =M3*'Assumptions & WACC'!$C$6 -> 1943.8205 | N7: =N3*'Assumptions & WACC'!$C$6 -> 1994.4736 | O7: =O3*'Assumptions & WACC'!$C$6 -> 2046.4467 | Q7: Capex | R7: =R3*'Assumptions & WACC'!$D$6 -> 47133.878 | S7: =S3*'Assumptions & WACC'!$D$6 -> 53623.511 | T7: =T3*'Assumptions & WACC'!$D$6 -> 60637.512 | U7: =U3*'Assumptions & WACC'!$D$6 -> 67775.807 | V7: =V3*'Assumptions & WACC'!$D$6 -> 74956.565 | W7: =W3*'Assumptions & WACC'!$D$6 -> 82103.96 | Y7: Capex | Z7: =Z3*'Assumptions & WACC'!$E$6 -> 51344.141 | AA7: =AA3*'Assumptions & WACC'!$E$6 -> 57098.539 | AB7: =AB3*'Assumptions & WACC'!$E$6 -> 63881.822 | AC7: =AC3*'Assumptions & WACC'!$E$6 -> 71622.738 | AD7: =AD3*'Assumptions & WACC'!$E$6 -> 80214.874 | AE7: =AE3*'Assumptions & WACC'!$E$6 -> 88875.468 | AG7: Capex | AH7: =AH3*'Assumptions & WACC'!$F$6 -> 7355.3603 | AI7: =AI3*'Assumptions & WACC'!$F$6 -> 7887.4908 | AJ7: =AJ3*'Assumptions & WACC'!$F$6 -> 8458.1187 | AK7: =AK3*'Assumptions & WACC'!$F$6 -> 9070.0292 | AL7: =AL3*'Assumptions & WACC'!$F$6 -> 9726.2089 | AM7: =AM3*'Assumptions & WACC'!$F$6 -> 10429.861
A8: Change in Working capital | B8: ='Assumptions & WACC'!I11-'Assumptions & WACC'!M3 -> 3120.1811 | C8: ='Assumptions & WACC'!J11-'Assumptions & WACC'!I11 -> 396.25131 | D8: ='Assumptions & WACC'!K11-'Assumptions & WACC'!J11 -> 427.64281 | E8: ='Assumptions & WACC'!L11-'Assumptions & WACC'!K11 -> 461.52118 | F8: ='Assumptions & WACC'!M11-'Assumptions & WACC'!L11 -> 498.08344 | G8: ='Assumptions & WACC'!N11-'Assumptions & WACC'!M11 -> 537.5422 | I8: Change in Working capital | J8: ='Assumptions & WACC'!I12-'Assumptions & WACC'!M4 -> -2863.876 | K8: ='Assumptions & WACC'!J12-'Assumptions & WACC'!I12 -> -39.709963 | L8: ='Assumptions & WACC'!K12-'Assumptions & WACC'!J12 -> -40.744746 | M8: ='Assumptions & WACC'!L12-'Assumptions & WACC'!K12 -> -41.806494 | N8: ='Assumptions & WACC'!M12-'Assumptions & WACC'!L12 -> -42.89591 | O8: ='Assumptions & WACC'!N12-'Assumptions & WACC'!M12 -> -44.013714 | Q8: Change in Working capital | R8: ='Assumptions & WACC'!I13-'Assumptions & WACC'!M5 -> 70155.779 | S8: ='Assumptions & WACC'!J13-'Assumptions & WACC'!I13 -> 19929.201 | T8: ='Assumptions & WACC'!K13-'Assumptions & WACC'!J13 -> 21539.498 | U8: ='Assumptions & WACC'!L13-'Assumptions & WACC'!K13 -> 21921.194 | V8: ='Assumptions & WACC'!M13-'Assumptions & WACC'!L13 -> 22051.597 | W8: ='Assumptions & WACC'!N13-'Assumptions & WACC'!M13 -> 21949.141 | Y8: Change in Working capital | Z8: ='Assumptions & WACC'!I14-'Assumptions & WACC'!M6 -> 44728.937 | AA8: ='Assumptions & WACC'!J14-'Assumptions & WACC'!I14 -> 10607.002 | AB8: ='Assumptions & WACC'!K14-'Assumptions & WACC'!J14 -> 12503.529 | AC8: ='Assumptions & WACC'!L14-'Assumptions & WACC'!K14 -> 14268.722 | AD8: ='Assumptions & WACC'!M14-'Assumptions & WACC'!L14 -> 15837.765 | AE8: ='Assumptions & WACC'!N14-'Assumptions & WACC'!M14 -> 15963.951 | AG8: Change in Working capital | AH8: ='Assumptions & WACC'!I15-'Assumptions & WACC'!M7 -> 715.31352 | AI8: ='Assumptions & WACC'!J15-'Assumptions & WACC'!I15 -> -531.6476 | AJ8: ='Assumptions & WACC'!K15-'Assumptions & WACC'!J15 -> -570.11015 | AK8: ='Assumptions & WACC'!L15-'Assumptions & WACC'!K15 -> -611.3553 | AL8: ='Assumptions & WACC'!M15-'Assumptions & WACC'!L15 -> -655.58437 | AM8: ='Assumptions & WACC'!N15-'Assumptions & WACC'!M15 -> -703.01323
A9: FCFF | B9: =B5+B6-B7-B8 -> 6578.1608 | C9: =C5+C6-C7-C8 -> 10070.405 | D9: =D5+D6-D7-D8 -> 10868.194 | E9: =E5+E6-E7-E8 -> 11729.185 | F9: =F5+F6-F7-F8 -> 12658.385 | G9: =G5+G6-G7-G8 -> 13661.198 | I9: FCFF | J9: =J5+J6-J7-J8 -> 11901.547 | K9: =K5+K6-K7-K8 -> 9312.8891 | L9: =L5+L6-L7-L8 -> 9555.5692 | M9: =M5+M6-M7-M8 -> 9804.5733 | N9: =N5+N6-N7-N8 -> 10060.066 | O9: =O5+O6-O7-O8 -> 10322.216 | Q9: FCFF | R9: =R5+R6-R7-R8 -> -4823.1964 | S9: =S5+S6-S7-S8 -> 54398.705 | T9: =T5+T6-T7-T8 -> 62510.562 | U9: =U5+U6-U7-U8 -> 72023.304 | V9: =V5+V6-V7-V8 -> 81846.198 | W9: =W5+W6-W7-W8 -> 91855.706 | Y9: FCFF | Z9: =Z5+Z6-Z7-Z8 -> 34692.079 | AA9: =AA5+AA6-AA7-AA8 -> 77715.131 | AB9: =AB5+AB6-AB7-AB8 -> 86311.235 | AC9: =AC5+AC6-AC7-AC8 -> 96519.977 | AD9: =AD5+AD6-AD7-AD8 -> 108241.57 | AE9: =AE5+AE6-AE7-AE8 -> 121511.91 | AG9: FCFF | AH9: =AH5+AH6-AH7-AH8 -> 11509.308 | AI9: =AI5+AI6-AI7-AI8 -> 13640.671 | AJ9: =AJ5+AJ6-AJ7-AJ8 -> 14627.518 | AK9: =AK5+AK6-AK7-AK8 -> 15685.759 | AL9: =AL5+AL6-AL7-AL8 -> 16820.56 | AM9: =AM5+AM6-AM7-AM8 -> 18037.459
A12: Metrics | B12: Value | I12: Metrics | J12: Value | Q12: Metrics | R12: Value | Y12: Metrics | Z12: Value | AG12: Metrics | AH12: Value
A13: Terminal Value | B13: =G9*(1+'Assumptions & WACC'!B25)/('Assumptions & WACC'!B21-'Assumptions & WACC'!B25) -> 181793.85 | I13: Terminal Value | J13: =O9*(1+'Assumptions & WACC'!C25)/('Assumptions & WACC'!C21-'Assumptions & WACC'!C25) -> 261990.02 | Q13: Terminal Value | R13: =W9*(1+'Assumptions & WACC'!D25)/('Assumptions & WACC'!D21-'Assumptions & WACC'!D25) -> 1818672.4 | Y13: Terminal Value | Z13: =AE9*(1+'Assumptions & WACC'!E25)/('Assumptions & WACC'!E21-'Assumptions & WACC'!E25) -> 2015791.7 | AG13: Terminal Value | AH13: =AM9*(1+'Assumptions & WACC'!F25)/('Assumptions & WACC'!F21-'Assumptions & WACC'!F25) -> 289252.3
A14: PV of Terminal value | B14: =B13*'Assumptions & WACC'!B23 -> 101491.52 | I14: PV of Terminal value | J14: =J13*'Assumptions & WACC'!C23 -> 179162.49 | Q14: PV of Terminal value | R14: =R13*'Assumptions & WACC'!D23 -> 1069450.6 | Y14: PV of Terminal value | Z14: =Z13*'Assumptions & WACC'!E23 -> 1188225.6 | AG14: PV of Terminal value | AH14: =AH13*'Assumptions & WACC'!F23 -> 154508.18
A15: PV of FCFF | B15: =NPV('Assumptions & WACC'!B21,DCF!B9:G9) -> 45748.851 | I15: PV of FCFF | J15: =NPV('Assumptions & WACC'!C21,DCF!J9:O9) -> 49276.638 | Q15: PV of FCFF | R15: =NPV('Assumptions & WACC'!D21,DCF!R9:W9) -> 246244.81 | Y15: PV of FCFF | Z15: =NPV('Assumptions & WACC'!E21,DCF!Z9:AE9) -> 372355.96 | AG15: PV of FCFF | AH15: =NPV('Assumptions & WACC'!F21,DCF!AH9:AM9) -> 62062.01
A16: Total enterprise value | B16: =B14+B15 -> 147240.37 | I16: Total enterprise value | J16: =J14+J15 -> 228439.13 | Q16: Total enterprise value | R16: =R14+R15 -> 1315695.4 | Y16: Total enterprise value | Z16: =Z14+Z15 -> 1560581.6 | AG16: Total enterprise value | AH16: =AH14+AH15 -> 216570.19
A17: Net debt | B17: ='Assumptions & WACC'!B16-'Assumptions & WACC'!B24 -> -3979.612 | I17: Net debt | J17: ='Assumptions & WACC'!C16-'Assumptions & WACC'!C24 -> 41026 | Q17: Net debt | R17: ='Assumptions & WACC'!D16-'Assumptions & WACC'!D24 -> -84774 | Y17: Net debt | Z17: ='Assumptions & WACC'!E16-'Assumptions & WACC'!E24 -> -51414 | AG17: Net debt | AH17: ='Assumptions & WACC'!F16-'Assumptions & WACC'!F24 -> 81782
A18: Total equity value | B18: =B16-B17 -> 151219.99 | I18: Total equity value | J18: =J16-J17 -> 187413.13 | Q18: Total equity value | R18: =R16-R17 -> 1400469.4 | Y18: Total equity value | Z18: =Z16-Z17 -> 1611995.6 | AG18: Total equity value | AH18: =AH16-AH17 -> 134788.19
A19: Outstanding shares | B19: ='Assumptions & WACC'!B26 -> 620.1389 | I19: Outstanding shares | J19: ='Assumptions & WACC'!C26 -> 934.7352 | Q19: Outstanding shares | R19: ='Assumptions & WACC'!D26 -> 12067 | Y19: Outstanding shares | Z19: ='Assumptions & WACC'!E26 -> 7432.377 | AG19: Outstanding shares | AH19: ='Assumptions & WACC'!F26 -> 2850.793
A20: Intrinsic value | B20: =B18/B19 -> 243.84857 | I20: Intrinsic value | J20: =J18/J19 -> 200.49863 | Q20: Intrinsic value | R20: =R18/R19 -> 116.05779 | Y20: Intrinsic value | Z20: =Z18/Z19 -> 216.88829 | AG20: Intrinsic value | AH20: =AH18/AH19 -> 47.280947
A21: Current market price | B21: ='Company Profile'!B3 -> 244.16 | I21: Current market price | J21: ='Company Profile'!C3 -> 289.86 | Q21: Current market price | R21: ='Company Profile'!D3 -> 300.64 | Y21: Current market price | Z21: ='Company Profile'!E3 -> 493.825 | AG21: Current market price | AH21: ='Company Profile'!F3 -> 227.385
A22: Upside/Downside | B22: =(B20-B21)/B21 -> -0.0012755063 | I22: Upside/Downside | J22: =(J20-J21)/J21 -> -0.30829148 | Q22: Upside/Downside | R22: =(R20-R21)/R21 -> -0.61396423 | Y22: Upside/Downside | Z22: =(Z20-Z21)/Z21 -> -0.56079928 | AG22: Upside/Downside | AH22: =(AH20-AH21)/AH21 -> -0.79206655

Sheet Relative
A1: Company | B1: EV/EBITDA | C1: P/E | D1: P/S | E1: P/B
A2: #VALUE! | B2: 28.28 | C2: {=_FV(A2,"P/E",TRUE)} -> 36.5484 | D2: 9.87 | E2: 66.14 | H2: Company | I2: EV/EBITDA | J2: P/E | K2: P/S | L2: P/B | M2: Share
A3: #VALUE! | B3: 22.34 | C3: {=_FV(A3,"P/E",TRUE)} -> 35.1342 | D3: 12.39 | E3: 10.89 | H3: Accenture | I3: =(B22*$B$19)/Relative!M3 -> 344.12327 | J3: =(C22*$C$19)/Relative!M3 -> 208.25006 | K3: =(D22*$D$19)/Relative!M3 -> 543.25534 | L3: =(E22*$E$19)/Relative!M3 -> 556.51252 | M3: ='Assumptions & WACC'!B26 -> 620.1389
A4: #VALUE! | B4: 17.77 | C4: {=_FV(A4,"P/E",TRUE)} -> 29.726 | D4: 7.01 | E4: 7.4 | H4: IBM | I4: =(B23*$B$19)/Relative!M4 -> 236.32189 | J4: =(C23*$C$19)/Relative!M4 -> 36.625993 | K4: =(D23*$D$19)/Relative!M4 -> 348.51208 | L4: =(E23*$E$19)/Relative!M4 -> 346.7405 | M4: ='Assumptions & WACC'!C26 -> 934.7352
A5: #VALUE! | B5: 20.59 | C5: {=_FV(A5,"P/E",TRUE)} -> 23.0364 | D5: 5.97 | E5: 14.6 | H5: Alphabet | I5: =(B24*$B$19)/Relative!M5 -> 203.13832 | J5: =(C24*$C$19)/Relative!M5 -> 177.79676 | K5: =(D24*$D$19)/Relative!M5 -> 150.57852 | L5: =(E24*$E$19)/Relative!M5 -> 318.74975 | M5: ='Assumptions & WACC'!D26 -> 12067
A6: #VALUE! | B6: 18.57 | C6: {=_FV(A6,"P/E",TRUE)} -> 20.3584 | D6: 9.83 | E6: 9.02 | H6: Microsoft | I6: =(B25*$B$19)/Relative!M6 -> 385.10261 | J6: =(C25*$C$19)/Relative!M6 -> 222.81553 | K6: =(D25*$D$19)/Relative!M6 -> 196.77416 | L6: =(E25*$E$19)/Relative!M6 -> 546.79689 | M6: ='Assumptions & WACC'!E26 -> 7432.377
A7: #VALUE! | B7: 23.9 | C7: {=_FV(A7,"P/E",TRUE)} -> 52.6293 | D7: 8.59 | E7: 33.86 | H7: Oracle | I7: =(B26*$B$19)/Relative!M7 -> 142.23385 | J7: =(C26*$C$19)/Relative!M7 -> 110.77085 | K7: =(D26*$D$19)/Relative!M7 -> 104.52269 | L7: =(E26*$E$19)/Relative!M7 -> 87.029324 | M7: ='Assumptions & WACC'!F26 -> 2850.793
A8: #VALUE! | B8: 40.7 | C8: {=_FV(A8,"P/E",TRUE)} -> 37.1171 | D8: 8.33 | E8: 6.7
A9: #VALUE! | B9: 5.98 | C9: {=_FV(A9,"P/E",TRUE)} -> 11.9771 | D9: 0.96 | E9: 1.29
A10: #VALUE! | B10: 10.74 | C10: 15.53 | D10: 1.97 | E10: 2.63
A11: #VALUE! | B11: 19.71 | C11: {=_FV(A11,"P/E",TRUE)} -> 22.7044 | D11: 4.86 | E11: 8.41
A12: #VALUE! | B12: 13.6 | C12: {=_FV(A12,"P/E",TRUE)} -> 15.2833 | D12: 1.38 | E12: 2.88 | H12: Company | I12: Target Price | J12: CMP | K12: U/D | L12: Mcap (TP) | M12: Mcap (CMP) | N12: Gap
A13: #VALUE! | B13: 14.82 | C13: {=_FV(A13,"P/E",TRUE)} -> 26.5398 | D13: 3.75 | E13: 6.26 | H13: =H3 -> Accenture | I13: =AVERAGE(I3:L3) -> 413.0353 | J13: ='Company Profile'!B3 -> 244.16 | K13: =(Table24[[#This Row],[Target Price]]-J13)/J13 -> 0.69165833 | L13: =Table24[[#This Row],[Target Price]]*M3 -> 256139.25 | M13: =Table24[[#This Row],[CMP]]*M3 -> 151413.11 | N13: =Table24[[#This Row],[Mcap (TP)]]-M13 -> 104726.14
A14: #VALUE! | B14: 8.06 | C14: {=_FV(A14,"P/E",TRUE)} -> 13.9377 | D14: 0.99 | E14: 1.91 | H14: =H4 -> IBM | I14: =AVERAGE(I4:L4) -> 242.05012 | J14: =DCF!J21 -> 289.86 | K14: =(Table24[[#This Row],[Target Price]]-J14)/J14 -> -0.16494129 | L14: =Table24[[#This Row],[Target Price]]*M4 -> 226252.76 | M14: =Table24[[#This Row],[CMP]]*M4 -> 270942.35 | N14: =Table24[[#This Row],[Mcap (TP)]]-M14 -> -44689.58
A15: #VALUE! | B15: 19.77 | C15: {=_FV(A15,"P/E",TRUE)} -> 35.9138 | D15: 3.28 | E15: 8.33 | H15: =H5 -> Alphabet | I15: =AVERAGE(I5:L5) -> 212.56584 | J15: ='Company Profile'!D3 -> 300.64 | K15: =(Table24[[#This Row],[Target Price]]-J15)/J15 -> -0.29295557 | L15: =Table24[[#This Row],[Target Price]]*M5 -> 2565032 | M15: =Table24[[#This Row],[CMP]]*M5 -> 3627822.9 | N15: =Table24[[#This Row],[Mcap (TP)]]-M15 -> -1062790.9
A16: #VALUE! | B16: 19.52 | C16: {=_FV(A16,"P/E",TRUE)} -> 20.1024 | D16: 3.34 | E16: 7.48 | H16: =H6 -> Microsoft | I16: =AVERAGE(I6:L6) -> 337.8723 | J16: ='Company Profile'!E3 -> 493.825 | K16: =(Table24[[#This Row],[Target Price]]-J16)/J16 -> -0.3158056 | L16: =Table24[[#This Row],[Target Price]]*M6 -> 2511194.3 | M16: =Table24[[#This Row],[CMP]]*M6 -> 3670293.6 | N16: =Table24[[#This Row],[Mcap (TP)]]-M16 -> -1159099.3
A17: #VALUE! | B17: 5.9 | C17: {=_FV(A17,"P/E",TRUE)} -> 9.5178 | D17: 0.54 | E17: 1.51 | H17: =H7 -> Oracle | I17: =AVERAGE(I7:L7) -> 111.13918 | J17: ='Company Profile'!F3 -> 227.385 | K17: =(Table24[[#This Row],[Target Price]]-J17)/J17 -> -0.51122907 | L17: =Table24[[#This Row],[Target Price]]*M7 -> 316834.79 | M17: =Table24[[#This Row],[CMP]]*M7 -> 648227.57 | N17: =Table24[[#This Row],[Mcap (TP)]]-M17 -> -331392.78
A19: Average | B19: =AVERAGE(B2:B17) -> 18.140625 | C19: =AVERAGE(C2:C17) -> 25.378506 | D19: =AVERAGE(D2:D17) -> 5.19125 | E19: =AVERAGE(E2:E17) -> 11.831875
A21: Company | B21: EBITDA | C21: Net Income | D21: Revenue | E21: Book Value
A22: =H3 -> Accenture | B22: =Financials!F6+Financials!F7 -> 11763.885 | C22: =Financials!F10 -> 5088.714 | D22: =Financials!F3 -> 64896.464 | E22: =Table2[[#This Row],[2024]] -> 29168.248
A23: =H4 -> IBM | B23: =Financials!M6+Financials!M7 -> 12177 | C23: =Financials!M10 -> 1349 | D23: =Financials!M3 -> 62753 | E23: =Financials!M22 -> 27393
A24: Alphabet | B24: =Financials!T6+Financials!T7 -> 135126 | C24: =Financials!T10 -> 84539 | D24: =Financials!T3 -> 350018 | E24: =Financials!T22 -> 325084
A25: Microsoft | B25: =Financials!AB6+Financials!AB7 -> 157780 | C25: =Financials!AB10 -> 65254 | D25: =Financials!AB3 -> 281724 | E25: =Financials!AB22 -> 343479
A26: Oracle | B26: =Financials!AJ6+Financials!AJ7 -> 22352 | C26: =Financials!AJ10 -> 12443 | D26: =Financials!AJ3 -> 57399 | E26: =Financials!AJ22 -> 20969

Sheet Calc
A1: Year | B1: Particulars | C1: Company | D1: Value | F1: Company | G1: Change in EBIT (historical) | H1: Change in CE | I1: Incremental ROCE (Historical) | J1: Change in EBIT (Forecast) | K1: Capex | L1: Depreciation | M1: Effective capital | N1: Raw ROCE | O1: Adjusted ROCE (Forecast) | Q1: Particulars | R1: 2020 | S1: 2021 | T1: 2022 | U1: 2023 | V1: 2024
A2: 2020-24 | B2: Avg Capex | C2: =Relative!H13 -> Accenture | D2: =AVERAGE(Financials!B27:F27) -> 588.3886 | F2: =C2 -> Accenture | G2: =Financials!F6-Financials!B6 -> 3082.203 | H2: =(65395-18976)-(43176-15709) -> 18952 | I2: =G2/H2 -> 0.16263207 | J2: =DCF!G4-DCF!B4 -> 4771.2597 | K2: =D8 -> 880.77891 | L2: =AVERAGE(DCF!B6:G6) -> 3054.2559 | M2: =IF(K2-L2<=0,K2,MAX(K2-L2,0.1*K2)) -> 880.77891 | N2: =J2/M2 -> 5.4170912 | O2: =MIN(MAX(N2,0.18),0.5) -> 0.5 | Q2: Revenue | R2: {=Financials!B3:F3} -> 44327.039 | S2: 50533.389 | T2: 61594.305 | U2: 64111.745 | V2: 64896.464
A3: 2020-24 | B3: Avg Capex | C3: =Relative!H14 -> IBM | D3: =AVERAGE(Financials!I27:M27) -> 1663.8 | F3: =C3 -> IBM | G3: =Financials!M6-Financials!I6 -> 3650 | H3: =(137175-33142)-(135241-34122) -> 2914 | I3: =G3/H3 -> 1.2525738 | J3: =DCF!O4-DCF!J4 -> 891.64075 | K3: =D9 -> 1920.8309 | L3: =AVERAGE(DCF!J6:O6) -> 6228.9044 | M3: =IF(K3-L3<=0,K3,MAX(K3-L3,0.1*K3)) -> 1920.8309 | N3: =J3/M3 -> 0.46419533 | O3: =MIN(MAX(N3,0.18),0.5) -> 0.46419533 | Q3: Operating income | R3: {=Table1[[#This Row],[2020]:[2024]]} -> 44327.039 | S3: 50533.389 | T3: 61594.305 | U3: 64111.745 | V3: 64896.464
A4: 2020-24 | B4: Avg Capex | C4: Alphabet | D4: =AVERAGE(Financials!P27:T27) -> 32638.4 | F4: =C4 -> Alphabet | G4: =Financials!T6-Financials!P6 -> 71733 | H4: =(Financials!T15-Financials!T20)-(Financials!P15-Financials!P20) -> 98352 | I4: =G4/H4 -> 0.72934968 | J4: =Table933[[#This Row],[2030]]-Table933[[#This Row],[2025]] -> 89074.367 | K4: =D10 -> 64371.872 | L4: =AVERAGE(DCF!R6:W6) -> 27344.792 | M4: =IF(K4-L4<=0,K4,MAX(K4-L4,0.1*K4)) -> 37027.08 | N4: =J4/M4 -> 2.4056546 | O4: =MIN(MAX(N4,0.18),0.5) -> 0.5 | Q4: Net Income | R4: {=Financials!B10:F10} -> 3118.431 | S4: 3900.224 | T4: 5024.438 | U4: 4345.477 | V4: 5088.714
A5: 2020-24 | B5: Avg Capex | C5: Microsoft | D5: =AVERAGE(Financials!X27:AB27) -> 36328.6 | F5: =C5 -> Microsoft | G5: =Financials!AB6-Financials!X6 -> 52525 | H5: =(Financials!AB15-Financials!AB20)-(Financials!X15-Financials!X20) -> 232663 | I5: =G5/H5 -> 0.22575571 | J5: =DCF!AE4-DCF!Z4 -> 98257.35 | K5: =D11 -> 68839.597 | L5: =AVERAGE(DCF!Z6:AE6) -> 36551.767 | M5: =IF(K5-L5<=0,K5,MAX(K5-L5,0.1*K5)) -> 32287.83 | N5: =J5/M5 -> 3.0431698 | O5: =MIN(MAX(N5,0.18),0.5) -> 0.5
A6: 2020-24 | B6: Avg Capex | C6: Oracle | D6: =AVERAGE(Financials!AF27:AJ27) -> 8684.4 | F6: =C6 -> Oracle | G6: =Financials!$AJ6-Financials!$AF6 -> 3171 | H6: =(Financials!AJ15-Financials!AJ20)-(Financials!AF15-Financials!AF20) -> 28775 | I6: =G6/H6 -> 0.11019983 | J6: =DCF!AM4-DCF!AH4 -> 8774.2287 | K6: =D12 -> 8821.1781 | L6: =AVERAGE(Table93337[[#This Row],[2025]:[2030]]) -> 4097.6195 | M6: =IF(K6-L6<=0,K6,MAX(K6-L6,0.1*K6)) -> 4723.5586 | N6: =J6/M6 -> 1.8575463 | O6: =MIN(MAX(N6,0.18),0.5) -> 0.5 | Q6: Particulars | R6: 2020 | S6: 2021 | T6: 2022 | U6: 2023 | V6: 2024 | Z6: Company | AA6: WACC | AB6: Terminal growth | AC6: Cost of equity | AD6: Intrinsic Value | AE6: Share price | AF6: Upside/Downside
A7: 2020-24 | B7: Avg Capex | C7: Average | D7: =AVERAGE(D2:D6) -> 15980.718 | H7: Average | I7: =AVERAGE(I2:I6) -> 0.49610221 | M7: Average | N7: =AVERAGE(N2:N6) -> 2.6375315 | O7: =AVERAGE(O2:O6) -> 0.49283907 | Q7: Revenue | R7: {=Financials!I3:M3} -> 55179 | S7: 57350 | T7: 60530 | U7: 61860 | V7: 62753 | Z7: Accenture | AA7: ='Assumptions & WACC'!B21 -> 0.10202531 | AB7: ='Assumptions & WACC'!$B$25 -> 0.025 | AC7: ='Assumptions & WACC'!B12 -> 0.1017684 | AD7: =DCF!B20 -> 243.84857 | AE7: =DCF!B21 -> 244.16 | AF7: =(AD7-AE7)/AE7 -> -0.0012755063
A8: 2025-30 | B8: Avg Capex | C8: =C2 -> Accenture | D8: =AVERAGE(DCF!B7:G7) -> 880.77891 | Q8: Operating income | R8: {=Financials!I6:M6} -> 3860 | S8: 5991 | T8: 2373 | U8: 10297 | V8: 7510 | Z8: IBM | AA8: ='Assumptions & WACC'!C21 -> 0.065384256 | AB8: ='Assumptions & WACC'!$B$25 -> 0.025 | AC8: ='Assumptions & WACC'!C12 -> 0.0746964 | AD8: =DCF!J20 -> 200.49863 | AE8: =DCF!J21 -> 289.86 | AF8: =(AD8-AE8)/AE8 -> -0.30829148
A9: 2025-30 | B9: Avg Capex | C9: =C3 -> IBM | D9: =AVERAGE(DCF!J7:O7) -> 1920.8309 | G9: Metric | H9: 2020-24 | I9: 2025-30 | Q9: Net Income | R9: {=Financials!I10:M10} -> -2763 | S9: -1705 | T9: -3019 | U9: 3118 | V9: 1349
A10: 2025-30 | B10: Avg Capex | C10: =C4 -> Alphabet | D10: =AVERAGE(DCF!R7:W7) -> 64371.872 | G10: GDP | H10: =AVERAGE(-0.035,0.058) -> 0.0115 | I10: 0.018
A11: 2025-30 | B11: Avg Capex | C11: =C5 -> Microsoft | D11: =AVERAGE(DCF!Z7:AE7) -> 68839.597 | G11: GDP | H11: 0.028 | I11: 0.026 | Q11: Particulars | R11: 2025 | S11: 2026 | T11: 2027 | U11: 2028 | V11: 2029 | W11: 2030
A12: 2025-30 | B12: Avg Capex | C12: =C6 -> Oracle | D12: =AVERAGE(DCF!AH7:AM7) -> 8821.1781 | G12: Change | H12: =H11-H10 -> 0.0165 | I12: =I11-I10 -> 0.008 | Q12: Revenue | R12: {=DCF!B3:G3} -> 70037.639 | S12: 75586.104 | T12: 81574.125 | U12: 88036.523 | V12: 95010.881 | W12: 102537.76
A13: 2025-30 | B13: Avg Capex | C13: =C7 -> Average | D13: =AVERAGE(D8:D12) -> 28966.851 | G13: Sensitivity | H13: =D61/H12 -> 57.142903 | I13: =D67/I12 -> 62.305039 | Q13: Operating income | R13: {=DCF!B4:G4} -> 10282.048 | S13: 11096.604 | T13: 11975.69 | U13: 12924.419 | V13: 13948.306 | W13: 15053.308
A14: 2025-30 | B14: Capex CAGR | C14: =C8 -> Accenture | D14: =(DCF!G7/DCF!B7)^(1/6)-1 -> 0.065594701 | Q14: Net Income | R14: {=DCF!B5:G5} -> 7917.177 | S14: 8544.3851 | T14: 9221.2814 | U14: 9951.8023 | V14: 10740.196 | W14: 11591.047
A15: 2025-30 | B15: Capex CAGR | C15: =C9 -> IBM | D15: =(DCF!O7/DCF!J7)^(1/6)-1 -> 0.021668753 | Q15: FCFF | R15: {=DCF!B9:G9} -> 6578.1608 | S15: 10070.405 | T15: 10868.194 | U15: 11729.185 | V15: 12658.385 | W15: 13661.198
A16: 2025-30 | B16: Capex CAGR | C16: =C10 -> Alphabet | D16: =(DCF!W7/DCF!R7)^(1/6)-1 -> 0.096912088
A17: 2025-30 | B17: Capex CAGR | C17: =C11 -> Microsoft | D17: =(DCF!AE7/DCF!Z7)^(1/6)-1 -> 0.095759306 | Q17: Particulars | R17: 2025 | S17: 2026 | T17: 2027 | U17: 2028 | V17: 2029 | W17: 2030
A18: 2025-30 | B18: Capex CAGR | C18: =C12 -> Oracle | D18: =(DCF!AM7/DCF!AH7)^(1/6)-1 -> 0.059934655 | Q18: Revenue | R18: {=DCF!J3:O3} -> 64388.251 | S18: 66066.114 | T18: 67787.699 | U18: 69554.147 | V18: 71366.625 | W18: 73226.334
A19: 2025-30 | B19: Capex CAGR | C19: =C13 -> Average | D19: =AVERAGE(D14:D18) -> 0.067973901 | Q19: Operating income | R19: {=DCF!J4:O4} -> 6495.8866 | S19: 6665.1598 | T19: 6838.8441 | U19: 7017.0543 | V19: 7199.9084 | W19: 7387.5274
A20: =A14 -> 2025-30 | B20: Earnings CAGR | C20: =C14 -> Accenture | D20: =D14 -> 0.065594701 | Q20: Net Income | R20: {=DCF!J5:O5} -> 5001.8327 | S20: 5132.1731 | T20: 5265.9099 | U20: 5403.1318 | V20: 5543.9294 | W20: 5688.3961
A21: =A15 -> 2025-30 | B21: Earnings CAGR | C21: =C15 -> IBM | D21: =D15 -> 0.021668753 | Q21: FCFF | R21: {=DCF!J9:O9} -> 11901.547 | S21: 9312.8891 | T21: 9555.5692 | U21: 9804.5733 | V21: 10060.066 | W21: 10322.216
A22: =A16 -> 2025-30 | B22: Earnings CAGR | C22: =C16 -> Alphabet | D22: =D16 -> 0.096912088
A23: =A17 -> 2025-30 | B23: Earnings CAGR | C23: =C17 -> Microsoft | D23: =D17 -> 0.095759306
A24: =A18 -> 2025-30 | B24: Earnings CAGR | C24: =C18 -> Oracle | D24: =D18 -> 0.059934655
A25: =A19 -> 2025-30 | B25: Earnings CAGR | C25: =C19 -> Average | D25: =AVERAGE(D20:D24) -> 0.067973901
A26: =A20 -> 2025-30 | B26: Revenue CAGR | C26: =C20 -> Accenture | D26: =D20 -> 0.065594701
A27: =A21 -> 2025-30 | B27: Revenue CAGR | C27: =C21 -> IBM | D27: =D21 -> 0.021668753
A28: =A22 -> 2025-30 | B28: Revenue CAGR | C28: =C22 -> Alphabet | D28: =D22 -> 0.096912088
A29: =A23 -> 2025-30 | B29: Revenue CAGR | C29: =C23 -> Microsoft | D29: =D23 -> 0.095759306
A30: =A24 -> 2025-30 | B30: Revenue CAGR | C30: =C24 -> Oracle | D30: =D24 -> 0.059934655
A31: =A25 -> 2025-30 | B31: Revenue CAGR | C31: =C25 -> Average | D31: =AVERAGE(D26:D30) -> 0.067973901
A32: =A2 -> 2020-24 | B32: EBITDA Margin | C32: =C26 -> Accenture | D32: =(AVERAGE(Financials!B6:F6)+AVERAGE(Financials!B7:F7))/AVERAGE(Financials!B3:F3) -> 0.18254487
A33: =A3 -> 2020-24 | B33: EBITDA Margin | C33: =C27 -> IBM | D33: =(AVERAGE(Financials!I6:M6)+AVERAGE(Financials!I7:M7))/AVERAGE(Financials!I3:M3) -> 0.19151281
A34: =A4 -> 2020-24 | B34: EBITDA Margin | C34: =C28 -> Alphabet | D34: =(AVERAGE(Financials!P6:T6)+AVERAGE(Financials!P7:T7))/AVERAGE(Financials!P3:T3) -> 0.35134366
A35: =A5 -> 2020-24 | B35: EBITDA Margin | C35: =C29 -> Microsoft | D35: =(AVERAGE(Financials!X6:AB6)+AVERAGE(Financials!X7:AB7))/AVERAGE(Financials!X3:AB3) -> 0.51758227
A36: =A6 -> 2020-24 | B36: EBITDA Margin | C36: =C30 -> Oracle | D36: =(AVERAGE(Financials!AF6:AJ6)+AVERAGE(Financials!AF7:AJ7))/AVERAGE(Financials!AF3:AJ3) -> 0.3880189
A37: =$A$36 -> 2020-24 | B37: EBITDA Margin | C37: =C31 -> Average | D37: =AVERAGE(D32:D36) -> 0.3262005
A38: =$A$36 -> 2020-24 | B38: NPM | C38: =C32 -> Accenture | D38: =AVERAGE(Financials!B10:F10)/AVERAGE(Financials!B3:F3) -> 0.07523668
A39: =$A$36 -> 2020-24 | B39: NPM | C39: =C33 -> IBM | D39: =AVERAGE(Financials!I10:M10)/AVERAGE(Financials!I3:M3) -> -0.010145395
A40: =A32 -> 2020-24 | B40: NPM | C40: =C34 -> Alphabet | D40: =AVERAGE(Financials!P10:T10)/AVERAGE(Financials!P3:T3) -> 0.20243956
...
