Workbook

Sheet Company Profile
A1: Company | B1: #VALUE! | C1: #VALUE! | D1: #VALUE! | E1: #VALUE! | F1: #VALUE! | G1: #VALUE!
A2: Official Name | B2: {=_FV(B1,"Official name",TRUE)} -> FORD MOTOR COMPANY | C2: {=_FV(C1,"Official name",TRUE)} -> GENERAL MOTORS COMPANY | D2: {=_FV(D1,"Official name",TRUE)} -> HARLEY-DAVIDSON, INC. | E2: {=_FV(E1,"Official name",TRUE)} -> RIVIAN AUTOMOTIVE, INC. | F2: {=_FV(F1,"Official name",TRUE)} -> Stellantis NV | G2: {=_FV(G1,"Official name",TRUE)} -> TESLA, INC.
A3: Share Price | B3: {=_FV(B1,"Price")} -> 13.0299 | C3: {=_FV(C1,"Price")} -> 68.25 | D3: {=_FV(D1,"Price")} -> 23.75 | E3: {=_FV(E1,"Price")} -> 15.015 | F3: {=_FV(F1,"Price")} -> 9.77 | G3: {=_FV(G1,"Price")} -> 403.74
A4: Change (%) | B4: {=_FV(B1,"Change (%)",TRUE)} -> 0.011638 | C4: {=_FV(C1,"Change (%)",TRUE)} -> 0.005007 | D4: {=_FV(D1,"Change (%)",TRUE)} -> -0.00586 | E4: {=_FV(E1,"Change (%)",TRUE)} -> 0.009751 | F4: {=_FV(F1,"Change (%)",TRUE)} -> -0.021042 | G4: {=_FV(G1,"Change (%)",TRUE)} -> -0.012668
A5: Beta | B5: {=_FV(B1,"Beta")} -> 1.5995 | C5: {=_FV(C1,"Beta")} -> 1.3095 | D5: {=_FV(D1,"Beta")} -> 1.3438 | E5: {=_FV(E1,"Beta")} -> 1.7784 | F5: {=_FV(F1,"Beta")} -> 1.6129 | G5: {=_FV(G1,"Beta")} -> 1.8911
A6: Shares Outstanding | B6: {=_FV(B1,"Shares outstanding",TRUE)} -> 3984499000 | C6: {=_FV(C1,"Shares outstanding",TRUE)} -> 932861300 | D6: {=_FV(D1,"Shares outstanding",TRUE)} -> 118141900 | E6: {=_FV(E1,"Shares outstanding",TRUE)} -> 1225913000 | F6: {=_FV(F1,"Shares outstanding",TRUE)} -> 2896073000 | G6: {=_FV(G1,"Shares outstanding",TRUE)} -> 3325819000
A7: in mn | B7: =B6/1000000 -> 3984.499 | C7: =C6/1000000 -> 932.8613 | D7: =D6/1000000 -> 118.1419 | E7: =E6/1000000 -> 1225.913 | F7: =F6/1000000 -> 2896.073 | G7: =G6/1000000 -> 3325.819
A8: Market Cap | B8: {=_FV(B1,"Market cap",TRUE)} -> 51917623520 | C8: {=_FV(C1,"Market cap",TRUE)} -> 63667783725 | D8: {=_FV(D1,"Market cap",TRUE)} -> 2822409000 | E8: {=_FV(E1,"Market cap",TRUE)} -> 18407083695 | F8: {=_FV(F1,"Market cap",TRUE)} -> 25439110000 | G8: {=_FV(G1,"Market cap",TRUE)} -> 1342766163060
A9: in mn | B9: =B8/1000000 -> 51917.624 | C9: =C8/1000000 -> 63667.784 | D9: =D8/1000000 -> 2822.409 | E9: =E8/1000000 -> 18407.084 | F9: =F8/1000000 -> 25439.11 | G9: =G8/1000000 -> 1342766.2
A10: P/E | B10: {=_FV(B1,"P/E",TRUE)} -> 11.1893 | C10: {=_FV(C1,"P/E",TRUE)} -> 13.127 | D10: {=_FV(D1,"P/E",TRUE)} -> 5.7606 | G10: {=_FV(G1,"P/E",TRUE)} -> 279.9279
A11: Year | B11: {=_FV(B1,"Year incorporated",TRUE)} -> 1919 | C11: {=_FV(C1,"Year incorporated",TRUE)} -> 2009 | D11: {=_FV(D1,"Year incorporated",TRUE)} -> 1991 | E11: {=_FV(E1,"Year incorporated",TRUE)} -> 2015 | F11: {=_FV(F1,"Year incorporated",TRUE)} -> 2014 | G11: {=_FV(G1,"Year incorporated",TRUE)} -> 2024

Sheet Financials
A1: Income Statement | F1: Ford | H1: Income Statement | L1: General Motors | O1: Income Statement | T1: Harley | V1: Income Statement | Z1: Rivian | AC1: Income Statement | AH1: Stellantis | AJ1: Income Statement | AN1: Tesla
A2: Particulars | B2: 2020 | C2: 2021 | D2: 2022 | E2: 2023 | F2: 2024 | H2: Particulars | I2: 2020 | J2: 2021 | K2: 2022 | L2: 2023 | M2: 2024 | O2: Particulars | P2: 2020 | Q2: 2021 | R2: 2022 | S2: 2023 | T2: 2024 | V2: Particulars | W2: 2020 | X2: 2021 | Y2: 2022 | Z2: 2023 | AA2: 2024 | AC2: Particulars | AD2: 2020 | AE2: 2021 | AF2: 2022 | AG2: 2023 | AH2: 2024 | AJ2: Particulars | AK2: 2020 | AL2: 2021 | AM2: 2022 | AN2: 2023 | AO2: 2024
A3: Total Revenue | B3: 127144 | C3: 136341 | D3: 158057 | E3: 176191 | F3: 184992 | H3: Total Revenue | I3: 122485 | J3: 127004 | K3: 156735 | L3: 171842 | M3: 187442 | O3: Total Revenue | P3: 4054.377 | Q3: 5336.308 | R3: 5755.13 | S3: 5836.478 | T3: 5186.802 | V3: Total Revenue | W3: 0 | X3: 55 | Y3: 1658 | Z3: 4434 | AA3: 4970 | AC3: Total Revenue | AD3: 86676 | AE3: 149419 | AF3: 179592 | AG3: 189544 | AH3: 156878 | AJ3: Total Revenue | AK3: 31536 | AL3: 53823 | AM3: 81462 | AN3: 96773 | AO3: 97690
A4: Cost of Goods Sold | B4: 112752 | C4: 114651 | D4: 134397 | E4: 150550 | F4: 158434 | H4: Cost of Goods Sold | I4: 97539 | J4: 100544 | K4: 126892 | L4: 141330 | M4: 151065 | O4: Cost of Goods Sold | P4: 2435.745 | Q4: 3243.287 | R4: 3403.728 | S4: 3322.306 | T4: 3005.94 | V4: Cost of Goods Sold | W4: 0 | X4: 520 | Y4: 4781 | Z4: 6464 | AA4: 6170 | AC4: Cost of Goods Sold | AD4: 75962 | AE4: 119943 | AF4: 144327 | AG4: 151400 | AH4: 136360 | AJ4: Cost of Goods Sold | AK4: 24906 | AL4: 40217 | AM4: 60609 | AN4: 79113 | AO4: 80240
A5: Gross Profit | B5: =B3-B4 -> 14392 | C5: =C3-C4 -> 21690 | D5: =D3-D4 -> 23660 | E5: =E3-E4 -> 25641 | F5: =F3-F4 -> 26558 | H5: Gross Profit | I5: =I3-I4 -> 24946 | J5: =J3-J4 -> 26460 | K5: =K3-K4 -> 29843 | L5: =L3-L4 -> 30512 | M5: =M3-M4 -> 36377 | O5: Gross Profit | P5: =P3-P4 -> 1618.632 | Q5: =Q3-Q4 -> 2093.021 | R5: =R3-R4 -> 2351.402 | S5: =S3-S4 -> 2514.172 | T5: =T3-T4 -> 2180.862 | V5: Gross Profit | W5: 0 | X5: =X3-X4 -> -465 | Y5: =Y3-Y4 -> -3123 | Z5: =Z3-Z4 -> -2030 | AA5: =AA3-AA4 -> -1200 | AC5: Gross Profit | AD5: =AD3-AD4 -> 10714 | AE5: =AE3-AE4 -> 29476 | AF5: =AF3-AF4 -> 35265 | AG5: =AG3-AG4 -> 38144 | AH5: =AH3-AH4 -> 20518 | AJ5: Gross Profit | AK5: =AK3-AK4 -> 6630 | AL5: =AL3-AL4 -> 13606 | AM5: =AM3-AM4 -> 20853 | AN5: =AN3-AN4 -> 17660 | AO5: =AO3-AO4 -> 17450
A6: Operating expenses | B6: =10193+8607 -> 18800 | C6: =11915+5252 -> 17167 | D6: =10888+6496 -> 17384 | E6: =10702+9481 -> 20183 | F6: =10287+11052 -> 21339 | H6: Operating expenses | I6: =11274+7038 -> 18312 | J6: =8582+8554 -> 17136 | K6: =8862+10667 -> 19529 | L6: =11374+9840 -> 21214 | M6: =12972+10621 -> 23593 | O6: Operating expenses | P6: =246.447+181.87+1050.627+130.009 -> 1608.953 | Q6: =192.944+25.049+1048.174+3.415 -> 1269.582 | R6: =217.653+145.133+1079.882-0.544 -> 1442.124 | S6: =332.38+227.158+1175.55 -> 1735.088 | T6: =371.766+247.225+1145.244 -> 1764.235 | V6: Operating expenses | W6: 0 | X6: 3755 | Y6: 3733 | Z6: 3709 | AA6: 3489 | AC6: Operating expenses | AD6: =5501+2979+184+73 -> 8737 | AE6: =9130+4487+698-35 -> 14280 | AF6: =8981+5200+72+1144 -> 15397 | AG6: =9541+5619+20+1119+491 -> 16790 | AH6: =9299+5784+1617-98-33 -> 16569 | AJ6: Operating expenses | AK6: 4636 | AL6: 7083 | AM6: 7197 | AN6: 8769 | AO6: 10374
A7: Operating income (EBIT) | B7: =B5-B6 -> -4408 | C7: =C5-C6 -> 4523 | D7: =D5-D6 -> 6276 | E7: =E5-E6 -> 5458 | F7: =F5-F6 -> 5219 | H7: Operating income (EBIT) | I7: =I5-I6 -> 6634 | J7: =J5-J6 -> 9324 | K7: =K5-K6 -> 10314 | L7: =L5-L6 -> 9298 | M7: =M5-M6 -> 12784 | O7: Operating income (EBIT) | P7: =P5-P6 -> 9.679 | Q7: =Q5-Q6 -> 823.439 | R7: =R5-R6 -> 909.278 | S7: =S5-S6 -> 779.084 | T7: =T5-T6 -> 416.627 | V7: Operating income (EBIT) | W7: 0 | X7: =X5-X6 -> -4220 | Y7: =Y5-Y6 -> -6856 | Z7: =Z5-Z6 -> -5739 | AA7: =AA5-AA6 -> -4689 | AC7: Operating income (EBIT) | AD7: =AD5-AD6 -> 1977 | AE7: =AE5-AE6 -> 15196 | AF7: =AF5-AF6 -> 19868 | AG7: =AG5-AG6 -> 21354 | AH7: =AH5-AH6 -> 3949 | AJ7: Operating income (EBIT) | AK7: =AK5-AK6 -> 1994 | AL7: =AL5-AL6 -> 6523 | AM7: =AM5-AM6 -> 13656 | AN7: =AN5-AN6 -> 8891 | AO7: =AO5-AO6 -> 7076 | AQ7: Particulars | AR7: 2020 | AS7: 2021 | AT7: 2022 | AU7: 2023 | AV7: 2024
A8: Interest expense | B8: 1649 | C8: 1803 | D8: 1259 | E8: 1302 | F8: 1115 | H8: Interest expense | I8: 1098 | J8: 950 | K8: 987 | L8: 911 | M8: 846 | O8: Interest expense | P8: 31.121 | Q8: 30.972 | R8: 31.235 | S8: 30.787 | T8: =30.748 -> 30.748 | V8: Interest expense | W8: 0 | X8: 29 | Y8: 103 | Z8: 220 | AA8: 318 | AC8: Interest expense | AD8: 988 | AE8: 734 | AF8: 768 | AG8: -42 | AH8: -345 | AJ8: Interest expense | AK8: 748 | AL8: 371 | AM8: 191 | AN8: 156 | AO8: 350 | AQ8: Revenue | AR8: {=B3:F3} -> 127144 | AS8: 136341 | AT8: 158057 | AU8: 176191 | AV8: 184992
A9: Income tax | B9: 160 | C9: -130 | D9: -864 | E9: -362 | F9: 1339 | H9: Income tax | I9: 1774 | J9: 2771 | K9: 1888 | L9: 563 | M9: 2556 | O9: Income tax | P9: -17.028 | Q9: 169.213 | R9: 192.019 | S9: 171.83 | T9: 71.963 | V9: Income tax | W9: 0 | X9: 0 | Y9: 4 | Z9: 1 | AA9: 5 | AC9: Income tax | AD9: 1332 | AE9: 1911 | AF9: 2729 | AG9: 3793 | AH9: -1488 | AJ9: Income tax | AK9: 292 | AL9: 699 | AM9: 1132 | AN9: -5001 | AO9: 1837 | AQ9: Operating income | AR9: {=B7:F7} -> -4408 | AS9: 4523 | AT9: 6276 | AU9: 5458 | AV9: 5219
A10: Net Income | B10: =B7-B8-B9 -> -6217 | C10: =C7-C8-C9 -> 2850 | D10: =D7-D8-D9 -> 5881 | E10: =E7-E8-E9 -> 4518 | F10: =F7-F8-F9 -> 2765 | H10: Net Income | I10: =I7-I8-I9 -> 3762 | J10: =J7-J8-J9 -> 5603 | K10: =K7-K8-K9 -> 7439 | L10: =L7-L8-L9 -> 7824 | M10: =M7-M8-M9 -> 9382 | O10: Net Income | P10: =P7-P8-P9 -> -4.414 | Q10: =Q7-Q8-Q9 -> 623.254 | R10: =R7-R8-R9 -> 686.024 | S10: =S7-S8-S9 -> 576.467 | T10: =T7-T8-T9 -> 313.916 | V10: Net Income | W10: 0 | X10: =X7-X8-X9 -> -4249 | Y10: =Y7-Y8-Y9 -> -6963 | Z10: =Z7-Z8-Z9 -> -5960 | AA10: =AA7-AA8-AA9 -> -5012 | AC10: Net Income | AD10: =AD7-AD8-AD9 -> -343 | AE10: =AE7-AE8-AE9 -> 12551 | AF10: =AF7-AF8-AF9 -> 16371 | AG10: =AG7-AG8-AG9 -> 17603 | AH10: =AH7-AH8-AH9 -> 5782 | AJ10: Net Income | AK10: =AK7-AK8-AK9 -> 954 | AL10: =AL7-AL8-AL9 -> 5453 | AM10: =AM7-AM8-AM9 -> 12333 | AN10: =AN7-AN8-AN9 -> 13736 | AO10: =AO7-AO8-AO9 -> 4889 | AQ10: Net Income | AR10: {=Table1[[#This Row],[2020]:[2024]]} -> -6217 | AS10: 2850 | AT10: 5881 | AU10: 4518 | AV10: 2765
A12: Balance Sheet | H12: Balance Sheet | O12: Balance Sheet | V12: Balance Sheet | AC12: Balance Sheet | AJ12: Balance Sheet | AQ12: Particulars | AR12: 2020 | AS12: 2021 | AT12: 2022 | AU12: 2023 | AV12: 2024
A13: Particulars | B13: 2020 | C13: 2021 | D13: 2022 | E13: 2023 | F13: 2024 | H13: Particulars | I13: 2020 | J13: 2021 | K13: 2022 | L13: 2023 | M13: 2024 | O13: Particulars | P13: 2020 | Q13: 2021 | R13: 2022 | S13: 2023 | T13: 2024 | V13: Particulars | W13: 2020 | X13: 2021 | Y13: 2022 | Z13: 2023 | AA13: 2024 | AC13: Particulars | AD13: 2020 | AE13: 2021 | AF13: 2022 | AG13: 2023 | AH13: 2024 | AJ13: Particulars | AK13: 2020 | AL13: 2021 | AM13: 2022 | AN13: 2023 | AO13: 2024 | AQ13: Revenue | AR13: {=I3:M3} -> 122485 | AS13: 127004 | AT13: 156735 | AU13: 171842 | AV13: 187442
A14: Total Current assets | B14: 116744 | C14: 108996 | D14: 116476 | E14: 121481 | F14: 124474 | H14: Total Current assets | I14: 80924 | J14: 82103 | K14: 100451 | L14: 101618 | M14: 108545 | O14: Total Current assets | P14: 5845.433 | Q14: 4550.091 | R14: 4750.653 | S14: 5163.729 | T14: 4996.637 | V14: Total Current assets | W14: 3016 | X14: 18559 | Y14: 13130 | Z14: 12313 | AA14: 10583 | AC14: Total Current assets | AD14: 40053 | AE14: 74795 | AF14: 84776 | AG14: 91520 | AH14: 81578 | AJ14: Total Current assets | AK14: 26217 | AL14: 27100 | AM14: 40917 | AN14: 49616 | AO14: 58360 | AQ14: Operating income | AR14: {=I7:M7} -> 6634 | AS14: 9324 | AT14: 10314 | AU14: 9298 | AV14: 12784
A15: Cash and cash equivalents | B15: 25243 | C15: 20540 | D15: 25134 | E15: 24862 | F15: 22935 | H15: Cash and cash equivalents | I15: 19992 | J15: 20067 | K15: 19153 | L15: 18853 | M15: 19872 | O15: Cash and cash equivalents | P15: 3257.203 | Q15: 1874.745 | R15: 1433.175 | S15: 1533.806 | T15: 1589.608 | V15: Cash and cash equivalents | W15: 2979 | X15: 18133 | Y15: 11568 | Z15: 7857 | AA15: 5294 | AC15: Cash and cash equivalents | AD15: 23846 | AE15: 49629 | AF15: 46433 | AG15: 43669 | AH15: 34100 | AJ15: Cash and cash equivalents | AK15: 19384 | AL15: 17576 | AM15: 16253 | AN15: 16398 | AO15: 16139 | AQ15: Net Income | AR15: {=I10:M10} -> 3762 | AS15: 5603 | AT15: 7439 | AU15: 7824 | AV15: 9382
A16: Total current liabilities | B16: 97192 | C16: 90727 | D16: 96866 | E16: 101531 | F16: 106859 | H16: Total current liabilities | I16: 79910 | J16: 74408 | K16: 91173 | L16: 94445 | M16: 96265 | O16: Total current liabilities | P16: 3981.954 | Q16: 3342.887 | R16: 3533.907 | S16: 3384.264 | T16: 3557.494 | V16: Total current liabilities | W16: 611 | X16: 1313 | Y16: 2424 | Z16: 2487 | AA16: 2251 | AC16: Total current liabilities | AD16: 39037 | AE16: 64857 | AF16: 66825 | AG16: 73940 | AH16: 75186 | AJ16: Total current liabilities | AK16: 14248 | AL16: 19705 | AM16: 26709 | AN16: 28748 | AO16: 28821
A17: Inventories | B17: 10808 | C17: 12066 | D17: 14080 | E17: 15651 | F17: 14951 | H17: Inventories | I17: 10235 | J17: 12988 | K17: 15366 | L17: 16461 | M17: 14564 | O17: Inventories | P17: 523.497 | Q17: 712.942 | R17: 950.96 | S17: 929.951 | T17: 745.793 | V17: Inventories | W17: 0 | X17: 274 | Y17: 1348 | Z17: 2620 | AA17: 2248 | AC17: Inventories | AD17: 8094 | AE17: 11361 | AF17: 17360 | AG17: 21414 | AH17: 20861 | AJ17: Inventories | AK17: 4101 | AL17: 5757 | AM17: 12839 | AN17: 13626 | AO17: 12017 | AQ17: Particulars | AR17: 2025 | AS17: 2026 | AT17: 2027 | AU17: 2028 | AV17: 2029 | AW17: 2030
A18: Receivables | B18: 9993 | C18: 11370 | D18: 15729 | E18: 15601 | F18: 14723 | H18: Receivables | I18: 8035 | J18: 7394 | K18: 13333 | L18: 12378 | M18: 12827 | O18: Receivables | P18: 143.082 | Q18: 182.148 | R18: 252.225 | S18: 267.2 | T18: 234.315 | V18: Receivables | W18: 6 | X18: 26 | Y18: 102 | Z18: 161 | AA18: 443 | AC18: Receivables | AD18: 5545 | AE18: 2998 | AF18: 4928 | AG18: 6426 | AH18: 5506 | AJ18: Receivables | AK18: 1886 | AL18: 1913 | AM18: 2952 | AN18: 3508 | AO18: 4418 | AQ18: Revenue | AR18: {=DCF!B3:G3} -> 199399.64 | AS18: 214929.38 | AT18: 231668.61 | AU18: 249711.54 | AV18: 269159.69 | AW18: 290122.52
A19: Payables | B19: 22204 | C19: 22349 | D19: 25605 | E19: 25992 | F19: 24128 | H19: Payables | I19: 19928 | J19: 20391 | K19: 27486 | L19: 28114 | M19: 25680 | O19: Payables | P19: 290.904 | Q19: 374.978 | R19: 378.002 | S19: 349.162 | T19: 298.718 | V19: Payables | W19: 90 | X19: 483 | Y19: 1000 | Z19: 981 | AA19: 499 | AC19: Payables | AD19: 20576 | AE19: 28181 | AF19: 31726 | AG19: 33008 | AH19: 29684 | AJ19: Payables | AK19: 6051 | AL19: 10025 | AM19: 15255 | AN19: 14431 | AO19: 12474 | AQ19: Operating income | AR19: {=DCF!B4:G4} -> 6532.0786 | AS19: 7040.8131 | AT19: 7589.1691 | AU19: 8180.2325 | AV19: 8817.3293 | AW19: 9504.0449
A20: PPE | B20: 37083 | C20: 37139 | D20: 37265 | E20: 40821 | F20: 41928 | H20: PPE | I20: 37632 | J20: 41115 | K20: 45248 | L20: 50321 | M20: 51904 | O20: PPE | P20: 743.784 | Q20: 683.984 | R20: 689.886 | S20: 731.724 | T20: 757.072 | V20: PPE | W20: 1445 | X20: 3183 | Y20: 3758 | Z20: 3874 | AA20: 3965 | AC20: PPE | AD20: 27582 | AE20: 35488 | AF20: 36205 | AG20: 37687 | AH20: 45011 | AJ20: PPE | AK20: 12747 | AL20: 18884 | AM20: 23548 | AN20: 35836 | AO20: 29725 | AQ20: Net income | AR20: {=DCF!B5:G5} -> 5029.7005 | AS20: 5421.4261 | AT20: 5843.6602 | AU20: 6298.779 | AV20: 6789.3436 | AW20: 7318.1145
A21: Total debt | B21: 139485 | C21: 151107 | D21: 140474 | E21: 50150 | F21: 55507 | H21: Total debt | I21: =1276+35637+16193+56788 -> 109894 | J21: =463+33257+16355+59304 -> 109379 | K21: =1959+36819+15885+60036 -> 114699 | L21: =428+38540+15985+66788 -> 121741 | M21: =2141+37291+13327+76973 -> 129732 | O21: Total debt | P21: =1014.274+2039.597+5932.933 -> 8986.804 | Q21: =751.286+1542.496+4595.617 -> 6889.399 | R21: =770.468+1684.782+4457.052 -> 6912.302 | S21: =878.935+1255.999+4990.586 -> 7125.52 | T21: =640.204+1851.513+4468.665 -> 6960.382 | V21: Total debt | W21: =28+47 -> 75 | X21: =1226 -> 1226 | Y21: =270+1231 -> 1501 | Z21: =361+4431 -> 4792 | AA21: =917+4441 -> 5358 | AC21: Total debt | AD21: =17036+4081 -> 21117 | AE21: =22624+10958 -> 33582 | AF21: =19469+7684 -> 27153 | AG21: =20001+9462 -> 29463 | AH21: =25028+12199 -> 37227 | AJ21: Total debt | AK21: =2132+9556 -> 11688 | AL21: =1589+5245 -> 6834 | AM21: =1502+1597 -> 3099 | AN21: =2373+2857 -> 5230 | AO21: =2456+5757 -> 8213 | AQ21: FCFE | AR21: {=DCF!B9:G9} -> -737.07071 | AS21: 4418.9092 | AT21: 4763.0648 | AU21: 5134.0241 | AV21: 5533.8747 | AW21: 5964.8666
A22: Shareholder's equity | B22: 30811 | C22: 48622 | D22: 43167 | E22: 42798 | F22: 44858 | H22: Shareholder's equity | I22: 49677 | J22: 65815 | K22: 71927 | L22: 68189 | M22: 65590 | O22: Shareholder's equity | P22: 1722.785 | Q22: 2553.244 | R22: 2906.808 | S22: 3252.295 | T22: 3158.5 | V22: Shareholder's equity | W22: -1384 | X22: 19514 | Y22: 13799 | Z22: 9141 | AA22: 6562 | AC22: Shareholder's equity | AD22: 25861 | AE22: 56307 | AF22: 72382 | AG22: 82120 | AH22: 82115 | AJ22: Shareholder's equity | AK22: 22225 | AL22: 30189 | AM22: 44704 | AN22: 62634 | AO22: 72913
AQ23: Particulars | AR23: 2025 | AS23: 2026 | AT23: 2027 | AU23: 2028 | AV23: 2029 | AW23: 2030
A24: Cash flow statement | H24: Cash flow statement | O24: Cash flow statement | V24: Cash flow statement | AC24: Cash flow statement | AJ24: Cash flow statement | AQ24: Revenue | AR24: {=DCF!J3:O3} -> 204090.93 | AS24: 222218.65 | AT24: 241956.51 | AU24: 263447.52 | AV24: 286847.4 | AW24: 312325.69
A25: Particulars | B25: 2020 | C25: 2021 | D25: 2022 | E25: 2023 | F25: 2024 | H25: Particulars | I25: 2020 | J25: 2021 | K25: 2022 | L25: 2023 | M25: 2024 | O25: Particulars | P25: 2020 | Q25: 2021 | R25: 2022 | S25: 2023 | T25: 2024 | V25: Particulars | W25: 2020 | X25: 2021 | Y25: 2022 | Z25: 2023 | AA25: 2024 | AC25: Particulars | AD25: 2020 | AE25: 2021 | AF25: 2022 | AG25: 2023 | AH25: 2024 | AJ25: Particulars | AK25: 2020 | AL25: 2021 | AM25: 2022 | AN25: 2023 | AO25: 2024 | AQ25: Operating income | AR25: {=DCF!J4:O4} -> 12891.587 | AS25: 14036.641 | AT25: 15283.4 | AU25: 16640.899 | AV25: 18118.973 | AW25: 19728.333
A26: Net cash flow Operating activities | B26: 24269 | C26: 15787 | D26: 6853 | E26: 14918 | F26: 15423 | H26: Net cash flow Operating activities | I26: 16670 | J26: 15188 | K26: 16043 | L26: 20930 | M26: 20129 | O26: Net cash flow Operating activities | P26: 1177.89 | Q26: 975.701 | R26: 548.461 | S26: 754.887 | T26: 1063.833 | V26: Net cash flow Operating activities | W26: -848 | X26: -2622 | Y26: 5052 | Z26: -4866 | AA26: -1716 | AC26: Net cash flow Operating activities | AD26: 9183 | AE26: 18646 | AF26: 19959 | AG26: 22485 | AH26: 4008 | AJ26: Net cash flow Operating activities | AK26: 5943 | AL26: 11497 | AM26: 14724 | AN26: 13256 | AO26: 14923 | AQ26: Net income | AR26: {=DCF!J5:O5} -> 9926.522 | AS26: 10808.213 | AT26: 11768.218 | AU26: 12813.492 | AV26: 13951.609 | AW26: 15190.816
A27: Capex | B27: 5742 | C27: 6227 | D27: 6866 | E27: 8236 | F27: 8684 | H27: Capex | I27: 5300 | J27: 7509 | K27: 9238 | L27: 10970 | M27: 10830 | O27: Capex | P27: 131.05 | Q27: 120.181 | R27: 151.669 | S27: 207.404 | T27: 196.563 | V27: Capex | W27: 914 | X27: 1794 | Y27: 1369 | Z27: 1026 | AA27: 1141 | AC27: Capex | AD27: 8600 | AE27: 8687 | AF27: 8615 | AG27: 10193 | AH27: 11060 | AJ27: Capex | AK27: 3157 | AL27: 6482 | AM27: 7158 | AN27: 8899 | AO27: 11342 | AQ27: FCFE | AR27: {=DCF!J9:O9} -> 7644.4897 | AS27: 6514.1091 | AT27: 7092.7039 | AU27: 7722.6905 | AV27: 8408.6336 | AW27: 9155.5035
A28: Depreciation & Amortization | B28: 8751 | C28: 7318 | D28: 7642 | E28: 7690 | F28: 7567 | H28: Depreciation & Amortization | I28: 5637 | J28: 5975 | K28: 6451 | L28: 6984 | M28: 7545 | O28: Depreciation & Amortization | P28: 185.715 | Q28: 165.185 | R28: 151.942 | S28: 158.112 | T28: 160.673 | V28: Depreciation & Amortization | W28: 29 | X28: 197 | Y28: 652 | Z28: 937 | AA28: 1031 | AC28: Depreciation & Amortization | AD28: 5143 | AE28: 5871 | AF28: 6797 | AG28: 7549 | AH28: 7226 | AJ28: Depreciation & Amortization | AK28: 2322 | AL28: 2911 | AM28: 3747 | AN28: 4667 | AO28: 5368
A29: Debt repaid | B29: 60514 | C29: 54164 | D29: 45655 | E29: 41965 | F29: 45680 | H29: Debt repaid | I29: 72663 | J29: 47806 | K29: 39606 | L29: 44675 | M29: 43399 | O29: Debt repaid | P29: =1400+1041.751+318.828 -> 2760.579 | Q29: =1400+1340.638+261.367 -> 3002.005 | R29: =950+1442.86+302.922 -> 2695.782 | S29: =1056.68+1193.526+237.37 -> 2487.576 | T29: =660.78+1078.248+258.077 -> 1997.105 | V29: Debt repaid | W29: 6 | X29: 86 | Y29: 3 | Z29: 0 | AA29: 0 | AC29: Debt repaid | AD29: =1376+8295 -> 9671 | AE29: 0 | AF29: 0 | AG29: 0 | AH29: 0 | AJ29: Debt repaid | AK29: =11623+338 -> 11961 | AL29: =14167+439 -> 14606 | AM29: =3364+502 -> 3866 | AN29: 1351 | AO29: 2500
A30: Dividends paid | B30: 596 | C30: 403 | D30: 2009 | E30: 4995 | F30: 3118 | H30: Dividends paid | I30: 669 | J30: 186 | K30: 397 | L30: 597 | M30: 653 | O30: Dividends paid | P30: =68.087 -> 68.087 | Q30: 92.426 | R30: 93.18 | S30: 96.31 | T30: 91.224 | V30: Dividends paid | W30: 0 | X30: 0 | Y30: 0 | Z30: 0 | AA30: 0 | AC30: Dividends paid | AD30: 2 | AE30: 4204 | AF30: 3354 | AG30: 4208 | AH30: 4661 | AJ30: Dividends paid | AK30: =208 -> 208 | AL30: =161 -> 161 | AM30: 157 | AN30: 144 | AO30: 104
O32: Particulars | P32: 2020 | Q32: 2021 | R32: 2022 | S32: 2023 | T32: 2024 | V32: Particulars | W32: 2020 | X32: 2021 | Y32: 2022 | Z32: 2023 | AA32: 2024 | AC32: Particulars | AD32: 2020 | AE32: 2021 | AF32: 2022 | AG32: 2023 | AH32: 2024 | AJ32: Particulars | AK32: 2020 | AL32: 2021 | AM32: 2022 | AN32: 2023 | AO32: 2024
O33: Revenue | P33: =P3 -> 4054.377 | Q33: =Q3 -> 5336.308 | R33: =R3 -> 5755.13 | S33: =S3 -> 5836.478 | T33: =T3 -> 5186.802 | V33: Revenue | W33: =W3 -> 0 | X33: =X3 -> 55 | Y33: =Y3 -> 1658 | Z33: =Z3 -> 4434 | AA33: =AA3 -> 4970 | AC33: Revenue | AD33: =AD3 -> 86676 | AE33: =AE3 -> 149419 | AF33: =AF3 -> 179592 | AG33: =AG3 -> 189544 | AH33: =AH3 -> 156878 | AJ33: Revenue | AK33: =AK3 -> 31536 | AL33: =AL3 -> 53823 | AM33: =AM3 -> 81462 | AN33: =AN3 -> 96773 | AO33: =AO3 -> 97690
O34: Operating income | P34: =P7 -> 9.679 | Q34: =Q7 -> 823.439 | R34: =R7 -> 909.278 | S34: =S7 -> 779.084 | T34: =T7 -> 416.627 | V34: Operating income | W34: =W7 -> 0 | X34: =X7 -> -4220 | Y34: =Y7 -> -6856 | Z34: =Z7 -> -5739 | AA34: =AA7 -> -4689 | AC34: Operating income | AD34: =AD7 -> 1977 | AE34: =AE7 -> 15196 | AF34: =AF7 -> 19868 | AG34: =AG7 -> 21354 | AH34: =AH7 -> 3949 | AJ34: Operating income | AK34: =AK7 -> 1994 | AL34: =AL7 -> 6523 | AM34: =AM7 -> 13656 | AN34: =AN7 -> 8891 | AO34: =AO7 -> 7076
O35: Net Income | P35: =P10 -> -4.414 | Q35: =Q10 -> 623.254 | R35: =R10 -> 686.024 | S35: =S10 -> 576.467 | T35: =T10 -> 313.916 | V35: Net Income | W35: =W10 -> 0 | X35: =X10 -> -4249 | Y35: =Y10 -> -6963 | Z35: =Z10 -> -5960 | AA35: =AA10 -> -5012 | AC35: Net Income | AD35: =AD10 -> -343 | AE35: =AE10 -> 12551 | AF35: =AF10 -> 16371 | AG35: =AG10 -> 17603 | AH35: =AH10 -> 5782 | AJ35: Net Income | AK35: =AK10 -> 954 | AL35: =AL10 -> 5453 | AM35: =AM10 -> 12333 | AN35: =AN10 -> 13736 | AO35: =AO10 -> 4889
O37: Particulars | P37: 2025 | Q37: 2026 | R37: 2027 | S37: 2028 | T37: 2029 | U37: 2030 | AC37: Particulars | AD37: 2025 | AE37: 2026 | AF37: 2027 | AG37: 2028 | AH37: 2029 | AI37: 2030
O38: Revenue | P38: =DCF!R3 -> 5448.7236 | Q38: =DCF!S3 -> 5723.8716 | R38: =DCF!T3 -> 6012.914 | S38: =DCF!U3 -> 6316.5524 | T38: =DCF!V3 -> 6635.5238 | U38: =DCF!W3 -> 6970.6025 | AC38: Revenue | AD38: =DCF!AH3 -> 158800.22 | AE38: =DCF!AI3 -> 160745.99 | AF38: =DCF!AJ3 -> 162715.61 | AG38: =DCF!AK3 -> 164709.35 | AH38: =DCF!AL3 -> 166727.53 | AI38: =DCF!AM3 -> 168770.44
O39: Operating income | P39: =DCF!R4 -> 611.74958 | Q39: =DCF!S4 -> 642.64153 | R39: =DCF!T4 -> 675.09346 | S39: =DCF!U4 -> 709.18413 | T39: =DCF!V4 -> 744.9963 | U39: =DCF!W4 -> 782.6169 | AC39: Operating income | AD39: =DCF!AH4 -> 12990.584 | AE39: =DCF!AI4 -> 13149.757 | AF39: =DCF!AJ4 -> 13310.88 | AG39: =DCF!AK4 -> 13473.978 | AH39: =DCF!AL4 -> 13639.074 | AI39: =DCF!AM4 -> 13806.193
O40: Net Income | P40: =DCF!R5 -> 471.04718 | Q40: =DCF!S5 -> 494.83398 | R40: =DCF!T5 -> 519.82196 | S40: =DCF!U5 -> 546.07178 | T40: =DCF!V5 -> 573.64715 | U40: =DCF!W5 -> 602.61501 | AC40: Net Income | AD40: =DCF!AH5 -> 10002.75 | AE40: =DCF!AI5 -> 10125.313 | AF40: =DCF!AJ5 -> 10249.378 | AG40: =DCF!AK5 -> 10374.963 | AH40: =DCF!AL5 -> 10502.087 | AI40: =DCF!AM5 -> 10630.769
O41: FCFF | P41: =DCF!R9 -> 369.70847 | Q41: =DCF!S9 -> 439.4096 | R41: =DCF!T9 -> 461.59878 | S41: =DCF!U9 -> 484.90846 | T41: =DCF!V9 -> 509.39522 | U41: =DCF!W9 -> 535.11851 | AC41: FCFF | AD41: =DCF!AH9 -> 4853.6313 | AE41: =DCF!AI9 -> 10635.757 | AF41: =DCF!AJ9 -> 10766.077 | AG41: =DCF!AK9 -> 10897.993 | AH41: =DCF!AL9 -> 11031.526 | AI41: =DCF!AM9 -> 11166.695
V42: Particulars | W42: 2025 | X42: 2026 | Y42: 2027 | Z42: 2028 | AA42: 2029 | AB42: 2030 | AJ42: Particulars | AK42: 2025 | AL42: 2026 | AM42: 2027 | AN42: 2028 | AO42: 2029 | AP42: 2030
V43: Revenue | W43: =DCF!Z3 -> 5261.8291 | X43: =DCF!AA3 -> 5570.7939 | Y43: =DCF!AB3 -> 5897.9005 | Z43: =DCF!AC3 -> 6244.2141 | AA43: =DCF!AD3 -> 6610.8627 | AB43: =DCF!AE3 -> 6999.0402 | AJ43: Revenue | AK43: =DCF!AP3 -> 122478.2 | AL43: =DCF!AQ3 -> 153556.25 | AM43: =DCF!AR3 -> 192520.16 | AN43: =DCF!AS3 -> 241370.9 | AO43: =DCF!AT3 -> 302617.2 | AP43: =DCF!AU3 -> 379404.36
...

Sheet Assumptions & WACC
A1: Assumptions
A2: Metric | B2: Ford | C2: GM | D2: Harley | E2: Rivian | F2: Stellantis | G2: Tesla
A3: Revenue CAGR | B3: =(Table1[[#This Row],[2024]]/Table1[[#This Row],[2020]])^(1/5)-1 -> 0.077882486 | C3: =(Table4[[#This Row],[2024]]/Table4[[#This Row],[2020]])^(1/5)-1 -> 0.088821783 | D3: =(Table18[[#This Row],[2024]]/Table18[[#This Row],[2020]])^(1/5)-1 -> 0.050497705 | E3: =(Table417[[#This Row],[2024]]/Table417[[#This Row],[2023]])^(1/2)-1 -> 0.058718129 | F3: =(Table1826[[#This Row],[2024]]/Table1826[[#This Row],[2021]])^(1/4)-1 -> 0.012252958 | G3: =(Table41729[[#This Row],[2024]]/Table41729[[#This Row],[2020]])^(1/5)-1 -> 0.25374352
A4: Operating margin | B4: =AVERAGE(Financials!C7:F7)/AVERAGE(Financials!C3:F3) -> 0.032758729 | C4: =AVERAGE(Financials!I7:M7)/AVERAGE(Financials!I3:M3) -> 0.063165898 | D4: =AVERAGE(Financials!P7:T7)/AVERAGE(Financials!P3:T3) -> 0.11227392 | E4: =(Financials!AA7/Financials!Y7)^(1/3)-1 -> -0.11894475 | F4: =AVERAGE(Financials!AD7:AH7)/AVERAGE(Financials!AD3:AH3) -> 0.081804571 | G4: =AVERAGE(Financials!AM7:AO7)/AVERAGE(Financials!AM3:AO3) -> 0.10735888
A5: Depreciation rate | B5: =AVERAGE(Financials!B28:F28)/AVERAGE(Financials!B3:F3) -> 0.049785046 | C5: =AVERAGE(Financials!I28:M28)/AVERAGE(Financials!I3:M3) -> 0.042575649 | D5: =AVERAGE(Financials!P28:T28)/AVERAGE(Financials!P3:T3) -> 0.031396844 | E5: =AVERAGE(Financials!X28:AA28)/AVERAGE(Financials!X3:AA3) -> 0.2533957 | F5: =AVERAGE(Financials!AD28:AH28)/AVERAGE(Financials!AD3:AH3) -> 0.042757663 | G5: =AVERAGE(Financials!AK28:AO28)/AVERAGE(Financials!AK3:AO3) -> 0.052631725
A6: Capex | B6: =AVERAGE(Financials!B27:F27)/AVERAGE(Financials!B3:F3) -> 0.045680156 | C6: =AVERAGE(Financials!I27:M27)/AVERAGE(Financials!I3:M3) -> 0.057278304 | D6: =AVERAGE(Financials!P27:T27)/AVERAGE(Financials!P3:T3) -> 0.03083282 | E6: =AVERAGE(Financials!X27:AA27)/AVERAGE(Financials!X3:AA3) -> 0.47944589 | F6: =AVERAGE(Financials!AD27:AH27)/AVERAGE(Financials!AD3:AH3) -> 0.061874351 | G6: =AVERAGE(Financials!AK27:AO27)/AVERAGE(Financials!AK3:AO3) -> 0.10251769 | N6: Ford | V6: =Financials!T1 -> Harley | AD6: =Financials!AH1 -> Stellantis
A7: Working capital | B7: =AVERAGE(J8:N8)/AVERAGE(Financials!B3:F3) -> 0.12136574 | C7: =AVERAGE(K15:N15)/AVERAGE(Financials!J3:M3) -> 0.056648051 | D7: =AVERAGE(R8:V8)/AVERAGE(Financials!P3:T3) -> 0.2868283 | E7: =AVERAGE(U15:V15)/AVERAGE(Financials!Z3:AA3) -> 1.9308805 | F7: =AVERAGE(AA8:AD8)/AVERAGE(Financials!AE3:AH3) -> 0.076781857 | G7: =AVERAGE(Z15:AD15)/AVERAGE(Financials!AK3:AO3) -> 0.23244594 | I7: Particulars | J7: 2020 | K7: 2021 | L7: 2022 | M7: 2023 | N7: 2024 | Q7: Particulars | R7: 2020 | S7: 2021 | T7: 2022 | U7: 2023 | V7: 2024 | Y7: Particulars | Z7: 2020 | AA7: 2021 | AB7: 2022 | AC7: 2023 | AD7: 2024
A8: Beta | B8: ='Company Profile'!B5 -> 1.5995 | C8: ='Company Profile'!C5 -> 1.3095 | D8: ='Company Profile'!D5 -> 1.3438 | E8: ='Company Profile'!E5 -> 1.7784 | F8: ='Company Profile'!F5 -> 1.6129 | G8: ='Company Profile'!G5 -> 1.8911 | I8: Working Capital | J8: =Financials!B14-Financials!B16 -> 19552 | K8: =Financials!C14-Financials!C16 -> 18269 | L8: =Financials!D14-Financials!D16 -> 19610 | M8: =Financials!E14-Financials!E16 -> 19950 | N8: =Financials!F14-Financials!F16 -> 17615 | Q8: Working capital | R8: =Financials!P14-Financials!P16 -> 1863.479 | S8: =Financials!Q14-Financials!Q16 -> 1207.204 | T8: =Financials!R14-Financials!R16 -> 1216.746 | U8: =Financials!S14-Financials!S16 -> 1779.465 | V8: =Financials!T14-Financials!T16 -> 1439.143 | Y8: Working capital | Z8: =Financials!AD14-Financials!AD16 -> 1016 | AA8: =Financials!AE14-Financials!AE16 -> 9938 | AB8: =Financials!AF14-Financials!AF16 -> 17951 | AC8: =Financials!AG14-Financials!AG16 -> 17580 | AD8: =Financials!AH14-Financials!AH16 -> 6392
A9: Equity risk premium | B9: 0.041 | C9: 0.041 | D9: 0.041 | E9: 0.041 | F9: 0.041 | G9: 0.041
A10: Risk free rate | B10: 0.0411 | C10: 0.0411 | D10: 0.0411 | E10: 0.0411 | F10: 0.0411 | G10: 0.0411 | I10: Particulars | J10: 2025 | K10: 2026 | L10: 2027 | M10: 2028 | N10: 2029 | O10: 2030 | Q10: Particulars | R10: 2025 | S10: 2026 | T10: 2027 | U10: 2028 | V10: 2029 | W10: 2030 | Y10: Particulars | Z10: 2025 | AA10: 2026 | AB10: 2027 | AC10: 2028 | AD10: 2029 | AE10: 2030
A11: Cost of equity | B11: =B10+(B8*B9) -> 0.1066795 | C11: =C10+(C8*C9) -> 0.0947895 | D11: =D10+(D8*D9) -> 0.0961958 | E11: =E10+(E8*E9) -> 0.1140144 | F11: =F10+(F8*F9) -> 0.1072289 | G11: =G10+(G8*G9) -> 0.1186351 | I11: Working capital | J11: =DCF!B3*'Assumptions & WACC'!$B$7 -> 24200.285 | K11: =DCF!C3*'Assumptions & WACC'!$B$7 -> 26085.063 | L11: =DCF!D3*'Assumptions & WACC'!$B$7 -> 28116.633 | M11: =DCF!E3*'Assumptions & WACC'!$B$7 -> 30306.426 | N11: =DCF!F3*'Assumptions & WACC'!$B$7 -> 32666.766 | O11: =DCF!G3*'Assumptions & WACC'!$B$7 -> 35210.935 | Q11: WC-F | R11: =DCF!R3*'Assumptions & WACC'!$D$7 -> 1562.8481 | S11: =DCF!S3*'Assumptions & WACC'!$D$7 -> 1641.7684 | T11: =DCF!T3*'Assumptions & WACC'!$D$7 -> 1724.6739 | U11: =DCF!U3*'Assumptions & WACC'!$D$7 -> 1811.766 | V11: =DCF!V3*'Assumptions & WACC'!$D$7 -> 1903.256 | W11: =DCF!W3*'Assumptions & WACC'!$D$7 -> 1999.3661 | Y11: WC-F | Z11: =DCF!AH3*'Assumptions & WACC'!$F$7 -> 12192.976 | AA11: =DCF!AI3*'Assumptions & WACC'!$F$7 -> 12342.376 | AB11: =DCF!AJ3*'Assumptions & WACC'!$F$7 -> 12493.606 | AC11: =DCF!AK3*'Assumptions & WACC'!$F$7 -> 12646.69 | AD11: =DCF!AL3*'Assumptions & WACC'!$F$7 -> 12801.649 | AE11: =DCF!AM3*'Assumptions & WACC'!$F$7 -> 12958.507
A12: Cost of debt (pre-tax) | B12: =AVERAGE(Financials!B8:F8)/AVERAGE(Financials!B21:F21) -> 0.013280594 | C12: =Financials!M8/Financials!M21 -> 0.0065211359 | D12: =AVERAGE(Financials!P8:T8)/AVERAGE(Financials!P21:T21) -> 0.0041997421 | E12: =AVERAGE(Financials!X8:AA8)/AVERAGE(Financials!X21:AA21) -> 0.052030753 | F12: =AVERAGE(Financials!AD8:AH8)/AVERAGE(Financials!AD21:AH21) -> 0.014157612 | G12: =AVERAGE(Financials!AK8:AO8)/AVERAGE(Financials!AK21:AO21) -> 0.051791011
A13: Tax rate | B13: 0.23 | C13: 0.23 | D13: 0.23 | E13: 0.23 | F13: 0.23 | G13: 0.23 | N13: GM | V13: =Financials!Z1 -> Rivian | AD13: =Financials!AN1 -> Tesla
A14: Cost of debt (after-tax) | B14: =B12*(1-B13) -> 0.010226057 | C14: =C12*(1-C13) -> 0.0050212746 | D14: =D12*(1-D13) -> 0.0032338014 | E14: =E12*(1-E13) -> 0.040063679 | F14: =F12*(1-F13) -> 0.010901361 | G14: =G12*(1-G13) -> 0.039879078 | I14: Particulars | J14: 2020 | K14: 2021 | L14: 2022 | M14: 2023 | N14: 2024 | Q14: Particulars | R14: 2020 | S14: 2021 | T14: 2022 | U14: 2023 | V14: 2024 | Y14: Particulars | Z14: 2020 | AA14: 2021 | AB14: 2022 | AC14: 2023 | AD14: 2024
A15: Total Debt | B15: =Financials!F21 -> 55507 | C15: =Financials!M21 -> 129732 | D15: =Financials!T21 -> 6960.382 | E15: =Financials!AA21 -> 5358 | F15: =Financials!AH21 -> 37227 | G15: =Financials!AO21 -> 8213 | I15: Working Capital | J15: =Financials!I14-Financials!I16 -> 1014 | K15: =Financials!J14-Financials!J16 -> 7695 | L15: =Financials!K14-Financials!K16 -> 9278 | M15: =Financials!L14-Financials!L16 -> 7173 | N15: =Financials!M14-Financials!M16 -> 12280 | Q15: Working capital | R15: =Financials!W14-Financials!W16 -> 2405 | S15: =Financials!X14-Financials!X16 -> 17246 | T15: =Financials!Y14-Financials!Y16 -> 10706 | U15: =Financials!Z14-Financials!Z16 -> 9826 | V15: =Financials!AA14-Financials!AA16 -> 8332 | Y15: Working capital | Z15: =Financials!AK14-Financials!AK16 -> 11969 | AA15: =Financials!AL14-Financials!AL16 -> 7395 | AB15: =Financials!AM14-Financials!AM16 -> 14208 | AC15: =Financials!AN14-Financials!AN16 -> 20868 | AD15: =Financials!AO14-Financials!AO16 -> 29539
A16: Market cap | B16: ='Company Profile'!B9 -> 51917.624 | C16: ='Company Profile'!C9 -> 63667.784 | D16: ='Company Profile'!D9 -> 2822.409 | E16: ='Company Profile'!E9 -> 18407.084 | F16: ='Company Profile'!F9 -> 25439.11 | G16: ='Company Profile'!G9 -> 1342766.2
A17: Total Capital | B17: =B15+B16 -> 107424.62 | C17: =C15+C16 -> 193399.78 | D17: =D15+D16 -> 9782.791 | E17: =E15+E16 -> 23765.084 | F17: =F15+F16 -> 62666.11 | G17: =G15+G16 -> 1350979.2 | I17: Particulars | J17: 2025 | K17: 2026 | L17: 2027 | M17: 2028 | N17: 2029 | O17: 2030 | Q17: Particulars | R17: 2025 | S17: 2026 | T17: 2027 | U17: 2028 | V17: 2029 | W17: 2030 | Y17: Particulars | Z17: 2025 | AA17: 2026 | AB17: 2027 | AC17: 2028 | AD17: 2029 | AE17: 2030
A18: Weight of debt | B18: =B15/B17 -> 0.51670649 | C18: =C15/C17 -> 0.67079703 | D18: =D15/D17 -> 0.71149246 | E18: =E15/E17 -> 0.22545681 | F18: =F15/F17 -> 0.59405315 | G18: =G15/G17 -> 0.0060792944 | I18: Working capital | J18: =DCF!J3*'Assumptions & WACC'!$C$7 -> 11561.354 | K18: =DCF!K3*'Assumptions & WACC'!$C$7 -> 12588.254 | L18: =DCF!L3*'Assumptions & WACC'!$C$7 -> 13706.365 | M18: =DCF!M3*'Assumptions & WACC'!$C$7 -> 14923.789 | N18: =DCF!N3*'Assumptions & WACC'!$C$7 -> 16249.346 | O18: =DCF!O3*'Assumptions & WACC'!$C$7 -> 17692.642 | Q18: WC-F | R18: =DCF!Z3*'Assumptions & WACC'!E7 -> 10159.963 | S18: =DCF!AA3*'Assumptions & WACC'!E7 -> 10756.537 | T18: =DCF!AB3*'Assumptions & WACC'!$E$7 -> 11388.141 | U18: =DCF!AC3*'Assumptions & WACC'!$E$7 -> 12056.831 | V18: =DCF!AD3*'Assumptions & WACC'!$E$7 -> 12764.786 | W18: =DCF!AE3*'Assumptions & WACC'!$E$7 -> 13514.31 | Y18: WC-F | Z18: =DCF!AP3*'Assumptions & WACC'!$G$7 -> 28469.562 | AA18: =DCF!AQ3*'Assumptions & WACC'!$G$7 -> 35693.528 | AB18: =DCF!AR3*'Assumptions & WACC'!$G$7 -> 44750.53 | AC18: =DCF!AS3*'Assumptions & WACC'!$G$7 -> 56105.687 | AD18: =DCF!AT3*'Assumptions & WACC'!$G$7 -> 70342.141 | AE18: =DCF!AU3*'Assumptions & WACC'!$G$7 -> 88191.003
A19: Weight of equity | B19: =B16/B17 -> 0.48329351 | C19: =C16/C17 -> 0.32920297 | D19: =D16/D17 -> 0.28850754 | E19: =E16/E17 -> 0.77454319 | F19: =F16/F17 -> 0.40594685 | G19: =G16/G17 -> 0.99392071
A20: WACC | B20: =(B11*B19)+(B14*B18) -> 0.05684138 | C20: =(C11*C19)+(C14*C18) -> 0.034573241 | D20: =(D11*D19)+(D14*D18) -> 0.030054039 | E20: =(E11*E19)+(E14*E18) -> 0.097341706 | F20: =(F11*F19)+(F14*F18) -> 0.050005222 | G20: =(G11*G19)+(G14*G18) -> 0.11815632
A21: Terminal Growth | B21: 0.02 | C21: 0.015 | D21: 0.003 | E21: 0.03 | F21: 0.005 | G21: 0.035
A22: Outstanding shares | B22: 3985 | C22: 1100 | D22: ='Company Profile'!D7 -> 118.1419 | E22: ='Company Profile'!E7 -> 1225.913 | F22: ='Company Profile'!F7 -> 2896.073 | G22: ='Company Profile'!G7 -> 3325.819

Sheet DCF
A1: DCF | G1: Ford | O1: GM | Q1: DCF | W1: ='Assumptions & WACC'!D2 -> Harley | AE1: ='Assumptions & WACC'!E2 -> Rivian | AG1: DCF | AM1: ='Assumptions & WACC'!F2 -> Stellantis | AU1: ='Assumptions & WACC'!G2 -> Tesla
A2: Particulars | B2: 2025 | C2: 2026 | D2: 2027 | E2: 2028 | F2: 2029 | G2: 2030 | I2: Particulars | J2: 2025 | K2: 2026 | L2: 2027 | M2: 2028 | N2: 2029 | O2: 2030 | Q2: Particulars | R2: 2025 | S2: 2026 | T2: 2027 | U2: 2028 | V2: 2029 | W2: 2030 | Y2: Particulars | Z2: 2025 | AA2: 2026 | AB2: 2027 | AC2: 2028 | AD2: 2029 | AE2: 2030 | AG2: Particulars | AH2: 2025 | AI2: 2026 | AJ2: 2027 | AK2: 2028 | AL2: 2029 | AM2: 2030 | AO2: Particulars | AP2: 2025 | AQ2: 2026 | AR2: 2027 | AS2: 2028 | AT2: 2029 | AU2: 2030
A3: Revenue | B3: =Table1[[#This Row],[2024]]*(1+'Assumptions & WACC'!$B3) -> 199399.64 | C3: =B3*(1+'Assumptions & WACC'!$B$3) -> 214929.38 | D3: =C3*(1+'Assumptions & WACC'!$B$3) -> 231668.61 | E3: =D3*(1+'Assumptions & WACC'!$B$3) -> 249711.54 | F3: =E3*(1+'Assumptions & WACC'!$B$3) -> 269159.69 | G3: =F3*(1+'Assumptions & WACC'!$B$3) -> 290122.52 | I3: Revenue | J3: =Table4[[#This Row],[2024]]*(1+'Assumptions & WACC'!C3) -> 204090.93 | K3: =Table10[[#This Row],[2025]]*(1+'Assumptions & WACC'!$C$3) -> 222218.65 | L3: =Table10[[#This Row],[2026]]*(1+'Assumptions & WACC'!$C$3) -> 241956.51 | M3: =Table10[[#This Row],[2027]]*(1+'Assumptions & WACC'!$C$3) -> 263447.52 | N3: =Table10[[#This Row],[2028]]*(1+'Assumptions & WACC'!$C$3) -> 286847.4 | O3: =Table10[[#This Row],[2029]]*(1+'Assumptions & WACC'!$C$3) -> 312325.69 | Q3: Revenue | R3: =Table18[[#This Row],[2024]]*(1+'Assumptions & WACC'!D3) -> 5448.7236 | S3: =Table938[[#This Row],[2025]]*(1+'Assumptions & WACC'!$D$3) -> 5723.8716 | T3: =Table938[[#This Row],[2026]]*(1+'Assumptions & WACC'!$D$3) -> 6012.914 | U3: =Table938[[#This Row],[2027]]*(1+'Assumptions & WACC'!$D$3) -> 6316.5524 | V3: =Table938[[#This Row],[2028]]*(1+'Assumptions & WACC'!$D$3) -> 6635.5238 | W3: =Table938[[#This Row],[2029]]*(1+'Assumptions & WACC'!$D$3) -> 6970.6025 | Y3: Revenue | Z3: =Table417[[#This Row],[2024]]*(1+'Assumptions & WACC'!E3) -> 5261.8291 | AA3: =Table1039[[#This Row],[2025]]*(1+'Assumptions & WACC'!$E$3) -> 5570.7939 | AB3: =Table1039[[#This Row],[2026]]*(1+'Assumptions & WACC'!$E$3) -> 5897.9005 | AC3: =Table1039[[#This Row],[2027]]*(1+'Assumptions & WACC'!$E$3) -> 6244.2141 | AD3: =Table1039[[#This Row],[2028]]*(1+'Assumptions & WACC'!$E$3) -> 6610.8627 | AE3: =Table1039[[#This Row],[2029]]*(1+'Assumptions & WACC'!$E$3) -> 6999.0402 | AG3: Revenue | AH3: =Table1826[[#This Row],[2024]]*(1+'Assumptions & WACC'!F3) -> 158800.22 | AI3: =Table942[[#This Row],[2025]]*(1+'Assumptions & WACC'!$F$3) -> 160745.99 | AJ3: =Table942[[#This Row],[2026]]*(1+'Assumptions & WACC'!$F$3) -> 162715.61 | AK3: =Table942[[#This Row],[2027]]*(1+'Assumptions & WACC'!$F$3) -> 164709.35 | AL3: =Table942[[#This Row],[2028]]*(1+'Assumptions & WACC'!$F$3) -> 166727.53 | AM3: =Table942[[#This Row],[2029]]*(1+'Assumptions & WACC'!$F$3) -> 168770.44 | AO3: Revenue | AP3: =Table41729[[#This Row],[2024]]*(1+'Assumptions & WACC'!G3) -> 122478.2 | AQ3: =Table1043[[#This Row],[2025]]*(1+'Assumptions & WACC'!$G$3) -> 153556.25 | AR3: =Table1043[[#This Row],[2026]]*(1+'Assumptions & WACC'!$G$3) -> 192520.16 | AS3: =Table1043[[#This Row],[2027]]*(1+'Assumptions & WACC'!$G$3) -> 241370.9 | AT3: =Table1043[[#This Row],[2028]]*(1+'Assumptions & WACC'!$G$3) -> 302617.2 | AU3: =Table1043[[#This Row],[2029]]*(1+'Assumptions & WACC'!$G$3) -> 379404.36
A4: EBIT | B4: =B3*'Assumptions & WACC'!$B$4 -> 6532.0786 | C4: =C3*'Assumptions & WACC'!$B$4 -> 7040.8131 | D4: =D3*'Assumptions & WACC'!$B$4 -> 7589.1691 | E4: =E3*'Assumptions & WACC'!$B$4 -> 8180.2325 | F4: =F3*'Assumptions & WACC'!$B$4 -> 8817.3293 | G4: =G3*'Assumptions & WACC'!$B$4 -> 9504.0449 | I4: EBIT | J4: =J3*'Assumptions & WACC'!$C$4 -> 12891.587 | K4: =K3*'Assumptions & WACC'!$C$4 -> 14036.641 | L4: =L3*'Assumptions & WACC'!$C$4 -> 15283.4 | M4: =M3*'Assumptions & WACC'!$C$4 -> 16640.899 | N4: =N3*'Assumptions & WACC'!$C$4 -> 18118.973 | O4: =O3*'Assumptions & WACC'!$C$4 -> 19728.333 | Q4: EBIT | R4: =R3*'Assumptions & WACC'!$D$4 -> 611.74958 | S4: =S3*'Assumptions & WACC'!$D$4 -> 642.64153 | T4: =T3*'Assumptions & WACC'!$D$4 -> 675.09346 | U4: =U3*'Assumptions & WACC'!$D$4 -> 709.18413 | V4: =V3*'Assumptions & WACC'!$D$4 -> 744.9963 | W4: =W3*'Assumptions & WACC'!$D$4 -> 782.6169 | Y4: EBIT | Z4: =Financials!AA7*(1+'Assumptions & WACC'!E4) -> -4131.268 | AA4: =Z4*(1+'Assumptions & WACC'!$E$4) -> -3639.8754 | AB4: =AA4*(1+'Assumptions & WACC'!$E$4) -> -3206.9313 | AC4: =AB4*(1+'Assumptions & WACC'!$E$4) -> -2825.4836 | AD4: =AC4*(1+'Assumptions & WACC'!$E$4) -> -2489.4072 | AE4: =AD4*(1+'Assumptions & WACC'!$E$4) -> -2193.3053 | AG4: EBIT | AH4: =AH3*'Assumptions & WACC'!$F$4 -> 12990.584 | AI4: =AI3*'Assumptions & WACC'!$F$4 -> 13149.757 | AJ4: =AJ3*'Assumptions & WACC'!$F$4 -> 13310.88 | AK4: =AK3*'Assumptions & WACC'!$F$4 -> 13473.978 | AL4: =AL3*'Assumptions & WACC'!$F$4 -> 13639.074 | AM4: =AM3*'Assumptions & WACC'!$F$4 -> 13806.193 | AO4: EBIT | AP4: =AP3*'Assumptions & WACC'!$G$4 -> 13149.123 | AQ4: =AQ3*'Assumptions & WACC'!$G$4 -> 16485.628 | AR4: =AR3*'Assumptions & WACC'!$G$4 -> 20668.749 | AS4: =AS3*'Assumptions & WACC'!$G$4 -> 25913.311 | AT4: =AT3*'Assumptions & WACC'!$G$4 -> 32488.645 | AU4: =AU3*'Assumptions & WACC'!$G$4 -> 40732.428
A5: NOPAT | B5: =B4*(1-'Assumptions & WACC'!$B$13) -> 5029.7005 | C5: =C4*(1-'Assumptions & WACC'!$B$13) -> 5421.4261 | D5: =D4*(1-'Assumptions & WACC'!$B$13) -> 5843.6602 | E5: =E4*(1-'Assumptions & WACC'!$B$13) -> 6298.779 | F5: =F4*(1-'Assumptions & WACC'!$B$13) -> 6789.3436 | G5: =G4*(1-'Assumptions & WACC'!$B$13) -> 7318.1145 | I5: NOPAT | J5: =J4*(1-'Assumptions & WACC'!$C$13) -> 9926.522 | K5: =K4*(1-'Assumptions & WACC'!$C$13) -> 10808.213 | L5: =L4*(1-'Assumptions & WACC'!$C$13) -> 11768.218 | M5: =M4*(1-'Assumptions & WACC'!$C$13) -> 12813.492 | N5: =N4*(1-'Assumptions & WACC'!$C$13) -> 13951.609 | O5: =O4*(1-'Assumptions & WACC'!$C$13) -> 15190.816 | Q5: NOPAT | R5: =R4*(1-'Assumptions & WACC'!$B$13) -> 471.04718 | S5: =S4*(1-'Assumptions & WACC'!$B$13) -> 494.83398 | T5: =T4*(1-'Assumptions & WACC'!$B$13) -> 519.82196 | U5: =U4*(1-'Assumptions & WACC'!$B$13) -> 546.07178 | V5: =V4*(1-'Assumptions & WACC'!$B$13) -> 573.64715 | W5: =W4*(1-'Assumptions & WACC'!$B$13) -> 602.61501 | Y5: NOPAT | Z5: =Z4 -> -4131.268 | AA5: =AA4 -> -3639.8754 | AB5: =AB4 -> -3206.9313 | AC5: =AC4 -> -2825.4836 | AD5: =AD4 -> -2489.4072 | AE5: =AE4 -> -2193.3053 | AG5: NOPAT | AH5: =AH4*(1-'Assumptions & WACC'!$B$13) -> 10002.75 | AI5: =AI4*(1-'Assumptions & WACC'!$B$13) -> 10125.313 | AJ5: =AJ4*(1-'Assumptions & WACC'!$B$13) -> 10249.378 | AK5: =AK4*(1-'Assumptions & WACC'!$B$13) -> 10374.963 | AL5: =AL4*(1-'Assumptions & WACC'!$B$13) -> 10502.087 | AM5: =AM4*(1-'Assumptions & WACC'!$B$13) -> 10630.769 | AO5: NOPAT | AP5: =AP4*(1-'Assumptions & WACC'!$C$13) -> 10124.825 | AQ5: =AQ4*(1-'Assumptions & WACC'!$C$13) -> 12693.934 | AR5: =AR4*(1-'Assumptions & WACC'!$C$13) -> 15914.937 | AS5: =AS4*(1-'Assumptions & WACC'!$C$13) -> 19953.249 | AT5: =AT4*(1-'Assumptions & WACC'!$C$13) -> 25016.257 | AU5: =AU4*(1-'Assumptions & WACC'!$C$13) -> 31363.97
A6: Depreciation | B6: =B3*'Assumptions & WACC'!$B$5 -> 9927.1201 | C6: =C3*'Assumptions & WACC'!$B$5 -> 10700.269 | D6: =D3*'Assumptions & WACC'!$B$5 -> 11533.632 | E6: =E3*'Assumptions & WACC'!$B$5 -> 12431.9 | F6: =F3*'Assumptions & WACC'!$B$5 -> 13400.128 | G6: =G3*'Assumptions & WACC'!$B$5 -> 14443.763 | I6: Depreciation | J6: =J3*'Assumptions & WACC'!$C$5 -> 8689.3039 | K6: =K3*'Assumptions & WACC'!$C$5 -> 9461.1034 | L6: =L3*'Assumptions & WACC'!$C$5 -> 10301.455 | M6: =M3*'Assumptions & WACC'!$C$5 -> 11216.449 | N6: =N3*'Assumptions & WACC'!$C$5 -> 12212.714 | O6: =O3*'Assumptions & WACC'!$C$5 -> 13297.469 | Q6: Depreciation | R6: =R3*'Assumptions & WACC'!$B$5 -> 271.26495 | S6: =S3*'Assumptions & WACC'!$B$5 -> 284.96321 | T6: =T3*'Assumptions & WACC'!$B$5 -> 299.3532 | U6: =U3*'Assumptions & WACC'!$B$5 -> 314.46985 | V6: =V3*'Assumptions & WACC'!$B$5 -> 330.34986 | W6: =W3*'Assumptions & WACC'!$B$5 -> 347.03177 | Y6: Depreciation | Z6: =Z3*'Assumptions & WACC'!$E$5 -> 1333.3249 | AA6: =AA3*'Assumptions & WACC'!$E$5 -> 1411.6152 | AB6: =AB3*'Assumptions & WACC'!$E$5 -> 1494.5026 | AC6: =AC3*'Assumptions & WACC'!$E$5 -> 1582.257 | AD6: =AD3*'Assumptions & WACC'!$E$5 -> 1675.1642 | AE6: =AE3*'Assumptions & WACC'!$E$5 -> 1773.5267 | AG6: Depreciation | AH6: =AH3*'Assumptions & WACC'!$B$5 -> 7905.8762 | AI6: =AI3*'Assumptions & WACC'!$B$5 -> 8002.7466 | AJ6: =AJ3*'Assumptions & WACC'!$B$5 -> 8100.8039 | AK6: =AK3*'Assumptions & WACC'!$B$5 -> 8200.0627 | AL6: =AL3*'Assumptions & WACC'!$B$5 -> 8300.5377 | AM6: =AM3*'Assumptions & WACC'!$B$5 -> 8402.2439 | AO6: Depreciation | AP6: =AP3*'Assumptions & WACC'!$C$5 -> 5214.589 | AQ6: =AQ3*'Assumptions & WACC'!$C$5 -> 6537.7572 | AR6: =AR3*'Assumptions & WACC'!$C$5 -> 8196.6707 | AS6: =AS3*'Assumptions & WACC'!$C$5 -> 10276.523 | AT6: =AT3*'Assumptions & WACC'!$C$5 -> 12884.124 | AU6: =AU3*'Assumptions & WACC'!$C$5 -> 16153.387
A7: Capex | B7: =B3*'Assumptions & WACC'!$B$6 -> 9108.6065 | C7: =C3*'Assumptions & WACC'!$B$6 -> 9818.0074 | D7: =D3*'Assumptions & WACC'!$B$6 -> 10582.658 | E7: =E3*'Assumptions & WACC'!$B$6 -> 11406.862 | F7: =F3*'Assumptions & WACC'!$B$6 -> 12295.257 | G7: =G3*'Assumptions & WACC'!$B$6 -> 13252.842 | I7: Capex | J7: =J3*'Assumptions & WACC'!$C$6 -> 11689.982 | K7: =K3*'Assumptions & WACC'!$C$6 -> 12728.308 | L7: =L3*'Assumptions & WACC'!$C$6 -> 13858.859 | M7: =M3*'Assumptions & WACC'!$C$6 -> 15089.827 | N7: =N3*'Assumptions & WACC'!$C$6 -> 16430.132 | O7: =O3*'Assumptions & WACC'!$C$6 -> 17889.486 | Q7: Capex | R7: =R3*'Assumptions & WACC'!$B$6 -> 248.89854 | S7: =S3*'Assumptions & WACC'!$B$6 -> 261.46735 | T7: =T3*'Assumptions & WACC'!$B$6 -> 274.67085 | U7: =U3*'Assumptions & WACC'!$B$6 -> 288.5411 | V7: =V3*'Assumptions & WACC'!$B$6 -> 303.11176 | W7: =W3*'Assumptions & WACC'!$B$6 -> 318.41821 | Y7: Capex | Z7: =Z3*'Assumptions & WACC'!$E$6 -> 2522.7624 | AA7: =AA3*'Assumptions & WACC'!$E$6 -> 2670.8942 | AB7: =AB3*'Assumptions & WACC'!$E$6 -> 2827.7242 | AC7: =AC3*'Assumptions & WACC'!$E$6 -> 2993.7628 | AD7: =AD3*'Assumptions & WACC'!$E$6 -> 3169.551 | AE7: =AE3*'Assumptions & WACC'!$E$6 -> 3355.6611 | AG7: Capex | AH7: =AH3*'Assumptions & WACC'!$B$6 -> 7254.0188 | AI7: =AI3*'Assumptions & WACC'!$B$6 -> 7342.902 | AJ7: =AJ3*'Assumptions & WACC'!$B$6 -> 7432.8742 | AK7: =AK3*'Assumptions & WACC'!$B$6 -> 7523.9489 | AL7: =AL3*'Assumptions & WACC'!$B$6 -> 7616.1396 | AM7: =AM3*'Assumptions & WACC'!$B$6 -> 7709.4598 | AO7: Capex | AP7: =AP3*'Assumptions & WACC'!$C$6 -> 7015.3438 | AQ7: =AQ3*'Assumptions & WACC'!$C$6 -> 8795.4418 | AR7: =AR3*'Assumptions & WACC'!$C$6 -> 11027.228 | AS7: =AS3*'Assumptions & WACC'!$C$6 -> 13825.316 | AT7: =AT3*'Assumptions & WACC'!$C$6 -> 17333.4 | AU7: =AU3*'Assumptions & WACC'!$C$6 -> 21731.638
A8: Change in Working capital | B8: ='Assumptions & WACC'!J11-'Assumptions & WACC'!N8 -> 6585.2848 | C8: ='Assumptions & WACC'!K11-'Assumptions & WACC'!J11 -> 1884.7783 | D8: ='Assumptions & WACC'!L11-'Assumptions & WACC'!K11 -> 2031.5696 | E8: ='Assumptions & WACC'!M11-'Assumptions & WACC'!L11 -> 2189.7933 | F8: ='Assumptions & WACC'!N11-'Assumptions & WACC'!M11 -> 2360.3398 | G8: ='Assumptions & WACC'!O11-'Assumptions & WACC'!N11 -> 2544.1689 | I8: Change in Working capital | J8: ='Assumptions & WACC'!J18-'Assumptions & WACC'!N15 -> -718.64635 | K8: ='Assumptions & WACC'!K18-'Assumptions & WACC'!J18 -> 1026.9 | L8: ='Assumptions & WACC'!L18-'Assumptions & WACC'!K18 -> 1118.1111 | M8: ='Assumptions & WACC'!M18-'Assumptions & WACC'!L18 -> 1217.4238 | N8: ='Assumptions & WACC'!N18-'Assumptions & WACC'!M18 -> 1325.5575 | O8: ='Assumptions & WACC'!O18-'Assumptions & WACC'!N18 -> 1443.2959 | Q8: Change in Working capital | R8: ='Assumptions & WACC'!R11-'Assumptions & WACC'!V8 -> 123.70512 | S8: ='Assumptions & WACC'!S11-'Assumptions & WACC'!R11 -> 78.920244 | T8: ='Assumptions & WACC'!T11-'Assumptions & WACC'!S11 -> 82.905535 | U8: ='Assumptions & WACC'!U11-'Assumptions & WACC'!T11 -> 87.092074 | V8: ='Assumptions & WACC'!V11-'Assumptions & WACC'!U11 -> 91.490024 | W8: ='Assumptions & WACC'!W11-'Assumptions & WACC'!V11 -> 96.11006 | Y8: Change in Working capital | Z8: ='Assumptions & WACC'!R18-'Assumptions & WACC'!V15 -> 1827.9631 | AA8: ='Assumptions & WACC'!S18-'Assumptions & WACC'!R18 -> 596.57403 | AB8: ='Assumptions & WACC'!T18-'Assumptions & WACC'!S18 -> 631.60374 | AC8: ='Assumptions & WACC'!U18-'Assumptions & WACC'!T18 -> 668.69033 | AD8: ='Assumptions & WACC'!V18-'Assumptions & WACC'!U18 -> 707.95457 | AE8: ='Assumptions & WACC'!W18-'Assumptions & WACC'!V18 -> 749.52434 | AG8: Change in Working capital | AH8: ='Assumptions & WACC'!Z11-'Assumptions & WACC'!AD8 -> 5800.9757 | AI8: ='Assumptions & WACC'!AA11-'Assumptions & WACC'!Z11 -> 149.40002 | AJ8: ='Assumptions & WACC'!AB11-'Assumptions & WACC'!AA11 -> 151.23061 | AK8: ='Assumptions & WACC'!AC11-'Assumptions & WACC'!AB11 -> 153.08364 | AL8: ='Assumptions & WACC'!AD11-'Assumptions & WACC'!AC11 -> 154.95936 | AM8: ='Assumptions & WACC'!AE11-'Assumptions & WACC'!AD11 -> 156.85807 | AO8: Change in Working capital | AP8: ='Assumptions & WACC'!Z18-'Assumptions & WACC'!AD15 -> -1069.4383 | AQ8: ='Assumptions & WACC'!AA18-'Assumptions & WACC'!Z18 -> 7223.9667 | AR8: ='Assumptions & WACC'!AB18-'Assumptions & WACC'!AA18 -> 9057.0014 | AS8: ='Assumptions & WACC'!AC18-'Assumptions & WACC'!AB18 -> 11355.157 | AT8: ='Assumptions & WACC'!AD18-'Assumptions & WACC'!AC18 -> 14236.454 | AU8: ='Assumptions & WACC'!AE18-'Assumptions & WACC'!AD18 -> 17848.862
A9: FCFF | B9: =B5+B6-B7-B8 -> -737.07071 | C9: =C5+C6-C7-C8 -> 4418.9092 | D9: =D5+D6-D7-D8 -> 4763.0648 | E9: =E5+E6-E7-E8 -> 5134.0241 | F9: =F5+F6-F7-F8 -> 5533.8747 | G9: =G5+G6-G7-G8 -> 5964.8666 | I9: FCFF | J9: =J5+J6-J7-J8 -> 7644.4897 | K9: =K5+K6-K7-K8 -> 6514.1091 | L9: =L5+L6-L7-L8 -> 7092.7039 | M9: =M5+M6-M7-M8 -> 7722.6905 | N9: =N5+N6-N7-N8 -> 8408.6336 | O9: =O5+O6-O7-O8 -> 9155.5035 | Q9: FCFF | R9: =R5+R6-R7-R8 -> 369.70847 | S9: =S5+S6-S7-S8 -> 439.4096 | T9: =T5+T6-T7-T8 -> 461.59878 | U9: =U5+U6-U7-U8 -> 484.90846 | V9: =V5+V6-V7-V8 -> 509.39522 | W9: =W5+W6-W7-W8 -> 535.11851 | Y9: FCFF | Z9: =Z5+Z6-Z7-Z8 -> -7148.6686 | AA9: =AA5+AA6-AA7-AA8 -> -5495.7284 | AB9: =AB5+AB6-AB7-AB8 -> -5171.7566 | AC9: =AC5+AC6-AC7-AC8 -> -4905.6798 | AD9: =AD5+AD6-AD7-AD8 -> -4691.7486 | AE9: =AE5+AE6-AE7-AE8 -> -4524.964 | AG9: FCFF | AH9: =AH5+AH6-AH7-AH8 -> 4853.6313 | AI9: =AI5+AI6-AI7-AI8 -> 10635.757 | AJ9: =AJ5+AJ6-AJ7-AJ8 -> 10766.077 | AK9: =AK5+AK6-AK7-AK8 -> 10897.993 | AL9: =AL5+AL6-AL7-AL8 -> 11031.526 | AM9: =AM5+AM6-AM7-AM8 -> 11166.695 | AO9: FCFF | AP9: =AP5+AP6-AP7-AP8 -> 9393.5085 | AQ9: =AQ5+AQ6-AQ7-AQ8 -> 3212.2823 | AR9: =AR5+AR6-AR7-AR8 -> 4027.3781 | AS9: =AS5+AS6-AS7-AS8 -> 5049.2992 | AT9: =AT5+AT6-AT7-AT8 -> 6330.5261 | AU9: =AU5+AU6-AU7-AU8 -> 7936.8561
A12: Metrics | B12: Value | I12: Metrics | J12: Value | Q12: Metrics | R12: Value | Y12: Metrics | Z12: Value | AG12: Metrics | AH12: Value | AO12: Metrics | AP12: Value
A13: Terminal Value | B13: =G9*(1+'Assumptions & WACC'!B21)/('Assumptions & WACC'!B20-'Assumptions & WACC'!B21) -> 165144.84 | I13: Terminal Value | J13: =O9*(1+'Assumptions & WACC'!C21)/('Assumptions & WACC'!C20-'Assumptions & WACC'!C21) -> 474772.47 | Q13: Terminal Value | R13: =W9*(1+'Assumptions & WACC'!D21)/('Assumptions & WACC'!D20-'Assumptions & WACC'!D21) -> 19838.955 | Y13: Terminal Value | Z13: =AE9*(1+'Assumptions & WACC'!E21)/('Assumptions & WACC'!E20-'Assumptions & WACC'!E21) -> -69209.902 | AG13: Terminal Value | AH13: =AM9*(1+'Assumptions & WACC'!F21)/('Assumptions & WACC'!F20-'Assumptions & WACC'!F21) -> 249360.58 | AO13: Terminal Value | AP13: =AU9*(1+'Assumptions & WACC'!G21)/('Assumptions & WACC'!G20-'Assumptions & WACC'!G21) -> 98785.59
A14: PV of Terminal value | B14: =B13/(1+'Assumptions & WACC'!B20)^6 -> 118523.96 | I14: PV of Terminal value | J14: =J13/(1+'Assumptions & WACC'!C20)^6 -> 387184.6 | Q14: PV of Terminal value | R14: =R13/(1+'Assumptions & WACC'!D20)^6 -> 16609.583 | Y14: PV of Terminal value | Z14: =Z13/(1+'Assumptions & WACC'!E20)^6 -> -39638.474 | AG14: PV of Terminal value | AH14: =AH13/(1+'Assumptions & WACC'!F20)^6 -> 186071.15 | AO14: PV of Terminal value | AP14: =AP13/(1+'Assumptions & WACC'!G20)^6 -> 50545.03
A15: PV of FCFF | B15: =NPV('Assumptions & WACC'!B20,DCF!B9:G9) -> 19887.883 | I15: PV of FCFF | J15: =NPV('Assumptions & WACC'!C20,DCF!J9:O9) -> 41182.076 | Q15: PV of FCFF | R15: =NPV('Assumptions & WACC'!D20,DCF!R9:W9) -> 2513.4757 | Y15: PV of FCFF | Z15: =NPV('Assumptions & WACC'!E20,DCF!Z9:AE9) -> -23915.884 | AG15: PV of FCFF | AH15: =NPV('Assumptions & WACC'!AH20,DCF!AH9:AM9) -> 59351.679 | AO15: PV of FCFF | AP15: =NPV('Assumptions & WACC'!AI20,DCF!AP9:AU9) -> 35949.85
A16: Total enterprise value | B16: =B14+B15 -> 138411.85 | I16: Total enterprise value | J16: =J14+J15 -> 428366.68 | Q16: Total enterprise value | R16: =R14+R15 -> 19123.059 | Y16: Total enterprise value | Z16: =Z14+Z15 -> -63554.358 | AG16: Total enterprise value | AH16: =AH14+AH15 -> 245422.83 | AO16: Total enterprise value | AP16: =AP14+AP15 -> 86494.881
A17: Net debt | B17: =Financials!F21-Financials!F15 -> 32572 | I17: Net debt | J17: ='Assumptions & WACC'!C15-Financials!M15 -> 109860 | Q17: Net debt | R17: ='Assumptions & WACC'!D15-Financials!T15 -> 5370.774 | Y17: Net debt | Z17: ='Assumptions & WACC'!E15-Financials!AA15 -> 64 | AG17: Net debt | AH17: ='Assumptions & WACC'!F15-Financials!AH15 -> 3127 | AO17: Net debt | AP17: ='Assumptions & WACC'!G15-Financials!AO15 -> -7926
A18: Total equity value | B18: =B16-B17 -> 105839.85 | I18: Total equity value | J18: =J16-J17 -> 318506.68 | Q18: Total equity value | R18: =R16-R17 -> 13752.285 | Y18: Total equity value | Z18: =Z16-Z17 -> -63618.358 | AG18: Total equity value | AH18: =AH16-AH17 -> 242295.83 | AO18: Total equity value | AP18: =AP16-AP17 -> 94420.881
A19: Outstanding shares | B19: ='Assumptions & WACC'!B22 -> 3985 | I19: Outstanding shares | J19: ='Assumptions & WACC'!C22 -> 1100 | Q19: Outstanding shares | R19: ='Assumptions & WACC'!D22 -> 118.1419 | Y19: Outstanding shares | Z19: ='Assumptions & WACC'!E22 -> 1225.913 | AG19: Outstanding shares | AH19: ='Assumptions & WACC'!F22 -> 2896.073 | AO19: Outstanding shares | AP19: ='Assumptions & WACC'!G22 -> 3325.819
A20: Intrinsic value | B20: =B18/B19 -> 26.55956 | I20: Intrinsic value | J20: =J18/J19 -> 289.55152 | Q20: Intrinsic value | R20: =R18/R19 -> 116.40481 | Y20: Intrinsic value | Z20: =Z18/Z19 -> -51.894676 | AG20: Intrinsic value | AH20: =AH18/AH19 -> 83.663578 | AO20: Intrinsic value | AP20: =AP18/AP19 -> 28.390264
A21: Current market price | B21: ='Company Profile'!B3 -> 13.0299 | I21: Current market price | J21: ='Company Profile'!C3 -> 68.25 | Q21: Current market price | R21: ='Company Profile'!D3 -> 23.75 | Y21: Current market price | Z21: ='Company Profile'!E3 -> 15.015 | AG21: Current market price | AH21: ='Company Profile'!F3 -> 9.77 | AO21: Current market price | AP21: ='Company Profile'!G3 -> 403.74
A22: Upside/Downside | B22: =(B20-B21)/B21 -> 1.0383548 | I22: Upside/Downside | J22: =(J20-J21)/J21 -> 3.2425132 | Q22: Upside/Downside | R22: =(R20-R21)/R21 -> 3.901255 | Y22: Upside/Downside | Z22: =(Z20-Z21)/Z21 -> -4.4561889 | AG22: Upside/Downside | AH22: =(AH20-AH21)/AH21 -> 7.563314 | AO22: Upside/Downside | AP22: =(AP20-AP21)/AP21 -> -0.92968181

Sheet Relative
A1: Relative Valuation
A2: Company | B2: EV/EBITDA | C2: P/E | D2: P/S | E2: P/B | G2: Company | H2: EV/EBITDA | I2: P/E | J2: P/S | K2: P/B | L2: Shares | M2: Target price | N2: Current price | O2: U/D
A3: #VALUE! | B3: 2.53 | C3: {=_FV(A3,"P/E",TRUE)} -> 9.5783 | D3: 0.33 | E3: 0.56 | G3: Ford Motors | H3: =B20*$B$17 -> 88476.235 | I3: =C20*$C$17 -> 53107.291 | J3: =D20*$D$17 -> 309790.45 | K3: =E20*$E$17 -> 127362.21 | L3: ='Assumptions & WACC'!B22 -> 3985 | M3: =AVERAGE(Table15[[#This Row],[EV/EBITDA]:[P/B]])/L3 -> 36.307164 | N3: ='Company Profile'!B3 -> 13.0299 | O3: =(Table15[[#This Row],[Target price]]-N3)/N3 -> 1.7864499
A4: #VALUE! | B4: 5.87 | C4: {=_FV(A4,"P/E",TRUE)} -> 13.127 | D4: 0.35 | E4: 0.75 | G4: General Motors | H4: =B21*$B$17 -> 190390.13 | I4: =C21*$C$17 -> 180199.86 | J4: =D21*$D$17 -> 313893.26 | K4: =E21*$E$17 -> 186225.15 | L4: ='Assumptions & WACC'!C22 -> 1100 | M4: =AVERAGE(Table15[[#This Row],[EV/EBITDA]:[P/B]])/L4 -> 197.88827 | N4: ='Company Profile'!C3 -> 68.25 | O4: =(Table15[[#This Row],[Target price]]-N4)/N4 -> 1.8994618
A5: #VALUE! | B5: 92.37 | C5: 110.64 | D5: 14.51 | E5: 18.57 | G5: =A22 -> Harley | H5: =B22*$B$17 -> 8063.9928 | I5: =C22*$C$17 -> 6029.3774 | J5: =D22*$D$17 -> 8685.8984 | K5: =E22*$E$17 -> 8967.7104 | L5: ='Assumptions & WACC'!D22 -> 118.1419 | M5: =AVERAGE(Table15[[#This Row],[EV/EBITDA]:[P/B]])/L5 -> 67.179762 | N5: ='Company Profile'!D3 -> 23.75 | O5: =(Table15[[#This Row],[Target price]]-N5)/N5 -> 1.8286216
A6: #VALUE! | B6: 15.54 | C6: 11.25 | D6: 0.22 | E6: 0.89 | G6: =A23 -> Rivian | H6: =B23*$B$17 -> -51096.632 | I6: =C23*$C$17 -> -96265.368 | J6: =D23*$D$17 -> 8322.8385 | K6: =E23*$E$17 -> 18631.032 | L6: ='Assumptions & WACC'!E22 -> 1225.913 | M6: =AVERAGE(Table15[[#This Row],[EV/EBITDA]:[P/B]])/L6 -> -24.554787 | N6: ='Company Profile'!E3 -> 15.015 | O6: =(Table15[[#This Row],[Target price]]-N6)/N6 -> -2.6353504
A7: #VALUE! | B7: 3.1 | C7: 3.64 | D7: 0.14 | E7: 0.25 | G7: =A24 -> Stellantis | H7: =B24*$B$17 -> 156097.56 | I7: =C24*$C$17 -> 111054.74 | J7: =D24*$D$17 -> 262710.31 | K7: =E24*$E$17 -> 233143.43 | L7: ='Assumptions & WACC'!F22 -> 2896.073 | M7: =AVERAGE(Table15[[#This Row],[EV/EBITDA]:[P/B]])/L7 -> 65.865574 | N7: ='Company Profile'!F3 -> 9.77 | O7: =(Table15[[#This Row],[Target price]]-N7)/N7 -> 5.7416146
A8: #VALUE! | B8: 4.68 | C8: 8.22 | D8: 0.52 | E8: 3.07 | G8: =A25 -> Tesla | H8: =B25*$B$17 -> 173823.54 | I8: =C25*$C$17 -> 93902.91 | J8: =D25*$D$17 -> 163593.18 | K8: =E25*$E$17 -> 207016.83 | L8: ='Assumptions & WACC'!G22 -> 3325.819 | M8: =AVERAGE(Table15[[#This Row],[EV/EBITDA]:[P/B]])/L8 -> 47.983403 | N8: ='Company Profile'!G3 -> 403.74 | O8: =(Table15[[#This Row],[Target price]]-N8)/N8 -> -0.88115271
A9: #VALUE! | B9: 7.2 | C9: 4.24 | D9: 0.2 | E9: 0.55 | G9: Target Price | L9: U/D | M9: U/D | N9: U/D | O9: U/D
A10: #VALUE! | B10: 2.43 | C10: 15.51 | D10: 0.2 | E10: 0.61 | G10: =G3 -> Ford Motors | H10: =H3/$L$3 -> 22.202318 | I10: =I3/$L$3 -> 13.326798 | J10: =J3/$L$3 -> 77.739134 | K10: =K3/$L$3 -> 31.960405 | L10: =(Table15[[#This Row],[EV/EBITDA]]-$N$3)/$N$3 -> 0.70395149 | M10: =(Table15[[#This Row],[P/E]]-$N$3)/$N$3 -> 0.022785923 | N10: =(Table15[[#This Row],[P/S]]-$N$3)/$N$3 -> 4.9662111 | O10: =(Table15[[#This Row],[P/B]]-$N$3)/$N$3 -> 1.4528511
A11: #VALUE! | B11: 4.5 | C11: {=_FV(A11,"P/E",TRUE)} -> 7.4454 | D11: 0.3 | E11: 0.54 | G11: =G4 -> General Motors | H11: =H4/$L$4 -> 173.08194 | I11: =I4/$L$4 -> 163.81805 | J11: =J4/$L$4 -> 285.35751 | K11: =K4/$L$4 -> 169.29559 | L11: =(Table15[[#This Row],[EV/EBITDA]]-$N$4)/$N$4 -> 1.5359991 | M11: =(Table15[[#This Row],[P/E]]-$N$4)/$N$4 -> 1.4002645 | N11: =(Table15[[#This Row],[P/S]]-$N$4)/$N$4 -> 3.1810624 | O11: =(Table15[[#This Row],[P/B]]-$N$4)/$N$4 -> 1.4805214
A12: #VALUE! | B12: 7.54 | C12: {=_FV(A12,"P/E",TRUE)} -> 8.1046 | D12: 0.91 | E12: 1.2 | G12: =G5 -> Harley | H12: =H5/$L$5 -> 68.256841 | I12: =I5/$L$5 -> 51.035047 | J12: =J5/$L$5 -> 73.520897 | K12: =K5/$L$5 -> 75.906265 | L12: =(Table15[[#This Row],[EV/EBITDA]]-$N$5)/$N$5 -> 1.8739722 | M12: =(Table15[[#This Row],[P/E]]-$N$5)/$N$5 -> 1.1488441 | N12: =(Table15[[#This Row],[P/S]]-$N$5)/$N$5 -> 2.0956167 | O12: =(Table15[[#This Row],[P/B]]-$N$5)/$N$5 -> 2.1960533
A13: #VALUE! | B13: 13.91 | C13: 24.91 | D13: 2.51 | E13: 4.06 | G13: =G6 -> Rivian | H13: =H6/$L$6 -> -41.680472 | I13: =I6/$L$6 -> -78.525449 | J13: =J6/$L$6 -> 6.7890939 | K13: =K6/$L$6 -> 15.197679 | L13: =(Table15[[#This Row],[EV/EBITDA]]-$N$6)/$N$6 -> -3.7759222 | M13: =(Table15[[#This Row],[P/E]]-$N$6)/$N$6 -> -6.2298001 | N13: =(Table15[[#This Row],[P/S]]-$N$6)/$N$6 -> -0.54784589 | O13: =(Table15[[#This Row],[P/B]]-$N$6)/$N$6 -> 0.012166436
