Workbook

Sheet Company Profile
A1: Company | B1: #VALUE! | C1: #VALUE! | D1: #VALUE! | E1: #VALUE! | F1: #VALUE!
A2: Official name | B2: {=_FV(B1,"Official name",TRUE)} -> NEXTERA ENERGY, INC. | C2: {=_FV(C1,"Official name",TRUE)} -> DUKE ENERGY CORPORATION | D2: {=_FV(D1,"Official name",TRUE)} -> Dominion Energy, Inc. | E2: {=_FV(E1,"Official name",TRUE)} -> THE SOUTHERN COMPANY | F2: {=_FV(F1,"Official name",TRUE)} -> Xcel Energy Inc.
A3: Share price | B3: {=_FV(B1,"Price")} -> 84.7 | C3: {=_FV(C1,"Price")} -> 24.89 | D3: {=_FV(D1,"Price")} -> 61.45 | E3: {=_FV(E1,"Price")} -> 90.76 | F3: {=_FV(F1,"Price")} -> 81
A4: Change (%) | B4: {=_FV(B1,"Change (%)",TRUE)} -> -0.012245 | C4: {=_FV(C1,"Change (%)",TRUE)} -> 0.00161 | D4: {=_FV(D1,"Change (%)",TRUE)} -> -0.000813 | E4: {=_FV(E1,"Change (%)",TRUE)} -> 0.001987 | F4: {=_FV(F1,"Change (%)",TRUE)} -> -0.003813
A5: Beta | B5: {=_FV(B1,"Beta")} -> 0.7215 | C5: {=_FV(C1,"Beta")} -> 0.4737 | D5: {=_FV(D1,"Beta")} -> 0.6708 | E5: {=_FV(E1,"Beta")} -> 0.4486 | F5: {=_FV(F1,"Beta")} -> 0.4519
A6: Shares outstanding | B6: {=_FV(B1,"Shares outstanding",TRUE)} -> 2082610000 | C6: {=_FV(C1,"Shares outstanding",TRUE)} -> 777661200 | D6: {=_FV(D1,"Shares outstanding",TRUE)} -> 853913300 | E6: {=_FV(E1,"Shares outstanding",TRUE)} -> 1101105000 | F6: {=_FV(F1,"Shares outstanding",TRUE)} -> 591539800
A7: in mn | B7: =B6/1000000 -> 2082.61 | C7: =C6/1000000 -> 777.6612 | D7: =D6/1000000 -> 853.9133 | E7: =E6/1000000 -> 1101.105 | F7: =F6/1000000 -> 591.5398
A8: Market cap | B8: {=_FV(B1,"Market cap",TRUE)} -> 176397067000 | C8: {=_FV(C1,"Market cap",TRUE)} -> 97347630000 | D8: {=_FV(D1,"Market cap",TRUE)} -> 52472972285 | E8: {=_FV(E1,"Market cap",TRUE)} -> 99936289800 | F8: {=_FV(F1,"Market cap",TRUE)} -> 47914723800
A9: in mn | B9: =B8/1000000 -> 176397.07 | C9: =C8/1000000 -> 97347.63 | D9: =D8/1000000 -> 52472.972 | E9: =E8/1000000 -> 99936.29 | F9: =F8/1000000 -> 47914.724
A10: P/E | B10: {=_FV(B1,"P/E",TRUE)} -> 26.8814 | C10: =Relative!C6 -> 19.4508 | D10: =Relative!D6 -> 2.75 | E10: =Relative!E6 -> 1.74 | F10: =Relative!F6 -> 0
A11: Year | B11: {=_FV(B1,"Year incorporated",TRUE)} -> 1984 | C11: {=_FV(C1,"Year incorporated",TRUE)} -> 2005 | D11: {=_FV(D1,"Year incorporated",TRUE)} -> 1983 | E11: {=_FV(E1,"Year incorporated",TRUE)} -> 1945 | F11: {=_FV(F1,"Year incorporated",TRUE)} -> 1909

Sheet Financials
A1: INCOME STATEMENTS | F1: NExtEra | H1: INCOME STATEMENTS | M1: Duke | O1: INCOME STATEMENTS | T1: DE | V1: INCOME STATEMENTS | AA1: SC | AC1: INCOME STATEMENTS | AH1: XCE
A2: Particulars | B2: 2020 | C2: 2021 | D2: 2022 | E2: 2023 | F2: 2024 | H2: Particulars | I2: 2020 | J2: 2021 | K2: 2022 | L2: 2023 | M2: 2024 | O2: Particulars | P2: 2020 | Q2: 2021 | R2: 2022 | S2: 2023 | T2: 2024 | V2: Particulars | W2: 2020 | X2: 2021 | Y2: 2022 | Z2: 2023 | AA2: 2024 | AC2: Particulars | AD2: 2020 | AE2: 2021 | AF2: 2022 | AG2: 2023 | AH2: 2024
A3: Revenue | B3: 17997 | C3: 17069 | D3: 20956 | E3: 28114 | F3: 24753 | H3: Revenue | I3: 23868 | J3: 25097 | K3: 28768 | L3: 29060 | M3: 30357 | O3: Revenue | P3: 14172 | Q3: 13964 | R3: 17174 | S3: 14393 | T3: 14459 | V3: Revenue | W3: 20375 | X3: 23113 | Y3: 29279 | Z3: 25253 | AA3: 26724 | AC3: Revenue | AD3: 11526 | AE3: 13431 | AF3: 15310 | AG3: 14206 | AH3: 13441
A4: Operating expenses | B4: =3539+3934 -> 7473 | C4: =4527+3981 -> 8508 | D4: =6389+4428 -> 10817 | E4: =5457+4681 -> 10138 | F4: =5029+4857 -> 9886 | H4: OpEx | I4: =19325-4705 -> 14620 | J4: =19737-4990 -> 14747 | K4: =22778-5086 -> 17692 | L4: =22042-5253 -> 16789 | M4: =22457-5793 -> 16664 | O4: Operating expenses | P4: =12117-733-2332 -> 9052 | Q4: =10945-2478-276-1157 -> 7034 | R4: =15578-2830-299-124 -> 12325 | S4: =10979-2580-984 -> 7415 | T4: =11212-2345-822 -> 8045 | V4: OpEx | W4: =15490-3518-149-153+206-336 -> 11540 | X4: =19415-3565-190-76+7-456 -> 15135 | Y4: =23909-3663-224-151-500 -> 19371 | Z4: =19427-4525-268-144-553 -> 13937 | AA4: =19656-235-139-530-4755 -> 13997 | AC4: OpEx | AD4: =9410-1948+6-40-115 -> 7313 | AE4: =11228-2121-5-62-73 -> 8967 | AF4: =12882-2413-36-75 -> 10358 | AG4: =11725-2448-22-35-91 -> 9129 | AH4: =11055-143-19-168-2744 -> 7981
A5: Operating income (EBIT) | B5: =B3-B4 -> 10524 | C5: =C3-C4 -> 8561 | D5: =D3-D4 -> 10139 | E5: =E3-E4 -> 17976 | F5: =F3-F4 -> 14867 | H5: Operating income (EBIT) | I5: =I3-I4 -> 9248 | J5: =J3-J4 -> 10350 | K5: =K3-K4 -> 11076 | L5: =L3-L4 -> 12271 | M5: =M3-M4 -> 13693 | O5: Operating income (EBIT) | P5: =P3-P4 -> 5120 | Q5: =Q3-Q4 -> 6930 | R5: =R3-R4 -> 4849 | S5: =S3-S4 -> 6978 | T5: =T3-T4 -> 6414 | V5: Operating income (EBIT) | W5: =W3-W4 -> 8835 | X5: =X3-X4 -> 7978 | Y5: =Y3-Y4 -> 9908 | Z5: =Z3-Z4 -> 11316 | AA5: =AA3-AA4 -> 12727 | AC5: Operating income (EBIT) | AD5: =AD3-AD4 -> 4213 | AE5: =AE3-AE4 -> 4464 | AF5: =AF3-AF4 -> 4952 | AG5: =AG3-AG4 -> 5077 | AH5: =AH3-AH4 -> 5460
A6: Depreciation & Amortization | B6: =4052 -> 4052 | C6: 3924 | D6: 4503 | E6: 5879 | F6: 5462 | H6: Depreciation & Amortization | I6: 4705 | J6: 4990 | K6: 5086 | L6: 5253 | M6: 5793 | O6: Depreciation & Amortization | P6: 2332 | Q6: 2478 | R6: 2830 | S6: 2580 | T6: 2345 | V6: Depreciation & Amortization | W6: 3518 | X6: 3565 | Y6: 3663 | Z6: 4525 | AA6: 4755 | AC6: Depreciation & Amortization | AD6: 1948 | AE6: 2121 | AF6: 2413 | AG6: 2448 | AH6: 2744
A7: Interest expense | B7: 1950 | C7: 1270 | D7: 585 | E7: 3324 | F7: 2235 | H7: Interest expense | I7: 2162 | J7: 2280 | K7: 2439 | L7: 3014 | M7: 3384 | O7: Interest expense | P7: 1377 | Q7: 1354 | R7: 966 | S7: 1674 | T7: 1887 | V7: Interest expense | W7: 1821 | X7: 1837 | Y7: 2022 | Z7: 2446 | AA7: 2743 | AC7: Interest expense | AD7: =840+42 -> 882 | AE7: =842+26 -> 868 | AF7: =953+28 -> 981 | AG7: =1055+51 -> 1106 | AH7: =1255+73 -> 1328
A8: Income tax expense | B8: 44 | C8: 348 | D8: 586 | E8: 1006 | F8: 339 | H8: Income tax expense | I8: 236 | J8: -192 | K8: 300 | L8: 438 | M8: 590 | O8: Income tax expense | P8: 83 | Q8: 425 | R8: 68 | S8: 568 | T8: 308 | V8: Income tax expense | W8: 393 | X8: 267 | Y8: 795 | Z8: 496 | AA8: 969 | AC8: Income tax expense | AD8: -6 | AE8: -70 | AF8: -135 | AG8: -146 | AH8: -402
A9: Net Income | B9: =B5-B6-B7-B8 -> 4478 | C9: =C5-C6-C7-C8 -> 3019 | D9: =D5-D6-D7-D8 -> 4465 | E9: =E5-E6-E7-E8 -> 7767 | F9: =F5-F6-F7-F8 -> 6831 | H9: Net Income | I9: =I5-I6-I7-I8 -> 2145 | J9: =J5-J6-J7-J8 -> 3272 | K9: =K5-K6-K7-K8 -> 3251 | L9: =L5-L6-L7-L8 -> 3566 | M9: =M5-M6-M7-M8 -> 3926 | O9: Net Income | P9: =P5-P6-P7-P8 -> 1328 | Q9: =Q5-Q6-Q7-Q8 -> 2673 | R9: =R5-R6-R7-R8 -> 985 | S9: =S5-S6-S7-S8 -> 2156 | T9: =T5-T6-T7-T8 -> 1874 | V9: Net Income | W9: =W5-W6-W7-W8 -> 3103 | X9: =X5-X6-X7-X8 -> 2309 | Y9: =Y5-Y6-Y7-Y8 -> 3428 | Z9: =Z5-Z6-Z7-Z8 -> 3849 | AA9: =AA5-AA6-AA7-AA8 -> 4260 | AC9: Net Income | AD9: =AD5-AD6-AD7-AD8 -> 1389 | AE9: =AE5-AE6-AE7-AE8 -> 1545 | AF9: =AF5-AF6-AF7-AF8 -> 1693 | AG9: =AG5-AG6-AG7-AG8 -> 1669 | AH9: =AH5-AH6-AH7-AH8 -> 1790
A11: BALANCE SHEET | H11: BALANCE SHEET | O11: BALANCE SHEET | V11: BALANCE SHEET | AC11: BALANCE SHEET
A12: Particulars | B12: 2020 | C12: 2021 | D12: 2022 | E12: 2023 | F12: 2024 | H12: Particulars | I12: 2020 | J12: 2021 | K12: 2022 | L12: 2023 | M12: 2024 | O12: Particulars | P12: 2020 | Q12: 2021 | R12: 2022 | S12: 2023 | T12: 2024 | V12: Particulars | W12: 2020 | X12: 2021 | Y12: 2022 | Z12: 2023 | AA12: 2024 | AC12: Particulars | AD12: 2020 | AE12: 2021 | AF12: 2022 | AG12: 2023 | AH12: 2024
A13: Cash & Cash equivalents | B13: 1105 | C13: 639 | D13: 1601 | E13: 2690 | F13: 1487 | H13: Cash & Cash equivalents | I13: 259 | J13: 343 | K13: 409 | L13: 253 | M13: 314 | O13: Cash & Cash equivalents | P13: 172 | Q13: 283 | R13: 153 | S13: 184 | T13: 310 | V13: Cash & Cash equivalents | W13: 1065 | X13: 1798 | Y13: 1917 | Z13: 748 | AA13: 1070 | AC13: Cash & Cash equivalents | AD13: 129 | AE13: 166 | AF13: 111 | AG13: 129 | AH13: 179
A14: Accounts receivables | B14: =2263+711 -> 2974 | C14: =3378+730 -> 4108 | D14: =4349+744 -> 5093 | E14: =3609+944 -> 4553 | F14: =3336+1180 -> 4516 | H14: Accounts receivables | I14: =1009+2144 -> 3153 | J14: =1173+2437 -> 3610 | K14: =1309+3106 -> 4415 | L14: =1112+3019 -> 4131 | M14: =2232+1889+551 -> 4672 | O14: Total Assets | P14: 95905 | Q14: 99590 | R14: 104243 | S14: 109080 | T14: 102415 | V14: Total assets | W14: 122935 | X14: 127534 | Y14: 134891 | Z14: 139331 | AA14: 145180 | AC14: Total assets | AD14: 53957 | AE14: 57851 | AF14: 61188 | AG14: 64079 | AH14: 70035
A15: Inventories | B15: 1552 | C15: 1561 | D15: 1934 | E15: 2106 | F15: 2214 | H15: Inventories | I15: 3167 | J15: 3199 | K15: 3584 | L15: 4292 | M15: 4509 | O15: Inventories | P15: =1105+349+96 -> 1550 | Q15: =1167+320+144 -> 1631 | R15: =1206+358+165 -> 1729 | S15: =1251+417+30 -> 1698 | T15: =1360+382+22 -> 1764 | V15: Inventories | W15: =1478+550+460 -> 2488 | X15: =1543+450+362 -> 2355 | Y15: =1664+575+438 -> 2677 | Z15: =1989+943+420 -> 3352 | AA15: =2178+803+388 -> 3369 | AC15: Inventories | AD15: 535 | AE15: 631 | AF15: 803 | AG15: 711 | AH15: 666
A16: Accounts Payables | B16: 4615 | C16: 6935 | D16: 8312 | E16: 8504 | F16: 6982 | H16: Accounts Payables | I16: 3144 | J16: 3629 | K16: 4754 | L16: 4228 | M16: 5479 | O16: Accounts Payables | P16: 944 | Q16: 1197 | R16: 1825 | S16: 921 | T16: 1149 | V16: Accounts Payables | W16: 2312 | X16: 2169 | Y16: 3525 | Z16: 2898 | AA16: 3701 | AC16: Accounts Payables | AD16: 1237 | AE16: 1409 | AF16: 1804 | AG16: 1668 | AH16: 1781
A17: Total Current assets | B17: 7382 | C17: 9288 | D17: 13490 | E17: 15361 | F17: 11951 | H17: Total Current assets | I17: 8682 | J17: 9940 | K17: 13222 | L17: 12769 | M17: 12950 | O17: Total Current assets | P17: 6886 | Q17: 7269 | R17: 9850 | S17: 25435 | T17: 6613 | V17: Total Current assets | W17: 8617 | X17: 8965 | Y17: 10416 | Z17: 10432 | AA17: 10694 | AC17: Total Current assets | AD17: 3275 | AE17: 4239 | AF17: 5144 | AG17: 4069 | AH17: 4325
A18: Total Current Liabilities | B18: 15558 | C18: 17437 | D18: 26695 | E18: 27963 | F18: 25355 | H18: Total Current Liabilities | I18: 16305 | J18: 15931 | K18: 18873 | L18: 17283 | M18: 19357 | O18: Total Current Liabilities | P18: 10843 | Q18: 8673 | R18: 13450 | S18: 24476 | T18: 9289 | V18: Total Current Liabilities | W18: 12079 | X18: 10921 | Y18: 15724 | Z18: 13467 | AA18: 15993 | AC18: Total Current Liabilities | AD18: 4239 | AE18: 5046 | AF18: 6078 | AG18: 5652 | AH18: 6459
A19: PPE | B19: 91803 | C19: 99348 | D19: 111059 | E19: 125776 | F19: 138852 | H19: PPE | I19: 106782 | J19: 111408 | K19: 111748 | L19: 115315 | M19: 123303 | O19: PPE | P19: 57848 | Q19: 59774 | R19: 63460 | S19: 58780 | T19: 68862 | V19: PPE | W19: 87634 | X19: 91108 | Y19: 94570 | Z19: 99844 | AA19: 104689 | AC19: PPE | AD19: 42950 | AE19: 45457 | AF19: 48253 | AG19: 51642 | AH19: 57198
A20: Total debt | B20: =1551+458+4138+41944 -> 48091 | C20: =1382+700+1785+50960 -> 54827 | D20: =1709+1368+6633+55256 -> 64966 | E20: =4650+255+6901+61405 -> 73211 | F20: =1670+217+8061+72385 -> 82333 | H20: Total debt | I20: =2873+4238+55625 -> 62736 | J20: =3304+3387+60448 -> 67139 | K20: =3952+3878+65873 -> 73703 | L20: =4288+2800+72452 -> 79540 | M20: =3584+4349+76340 -> 84273 | O20: Total debt | P20: =895+33957 -> 34852 | Q20: =2314+37426 -> 39740 | R20: =3423+38914 -> 42337 | S20: =3956+33248 -> 37204 | T20: =2500+37525 -> 40025 | V20: Total debt | W20: =45073 -> 45073 | X20: =50120 -> 50120 | Y20: 50656 | Z20: =57210 -> 57210 | AA20: 58768 | AC20: Total debt | AD20: =421+584+19645 -> 20650 | AE20: =601+1005+21779 -> 23385 | AF20: =1151+813+22813 -> 24777 | AG20: =552+785+24913 -> 26250 | AH20: =1103+695+27316 -> 29114
A21: Shareholder's equity | B21: 44929 | C21: 45424 | D21: 48326 | E21: 57768 | F21: 60460 | H21: Shareholder's equity | I21: =49184 -> 49184 | J21: 51136 | K21: 51853 | L21: 50187 | M21: =51256 -> 51256 | O21: Shareholder's equity | P21: 26461 | Q21: 27308 | R21: 27881 | S21: 27567 | T21: 30192 | V21: Shareholder's equity | W21: 32234 | X21: 32276 | Y21: 34532 | Z21: 35225 | AA21: 36674 | AC21: Shareholder's equity | AD21: 14575 | AE21: 15612 | AF21: 16675 | AG21: 17616 | AH21: 19522
A23: CASH FLOW STATEMENT | H23: CASH FLOW STATEMENT | O23: CASH FLOW STATEMENT | V23: CASH FLOW STATEMENT | AC23: CASH FLOW STATEMENT
A24: Particulars | B24: 2020 | C24: 2021 | D24: 2022 | E24: 2023 | F24: 2024 | H24: Particulars | I24: 2020 | J24: 2021 | K24: 2022 | L24: 2023 | M24: 2024 | O24: Particulars | P24: 2020 | Q24: 2021 | R24: 2022 | S24: 2023 | T24: 2024 | V24: Particulars | W24: 2020 | X24: 2021 | Y24: 2022 | Z24: 2023 | AA24: 2024 | AC24: Particulars | AD24: 2020 | AE24: 2021 | AF24: 2022 | AG24: 2023 | AH24: 2024
A25: Cash flow from Operating activities | B25: 7983 | C25: 7553 | D25: 8262 | E25: 11301 | F25: 13260 | H25: Cash flow from Operating activities | I25: 8856 | J25: 8290 | K25: 5927 | L25: 9878 | M25: 12328 | O25: Cash flow from Operating activities | P25: 5227 | Q25: 4037 | R25: 3700 | S25: 6572 | T25: 5018 | V25: Cash flow from Operating activities | W25: 6696 | X25: 6169 | Y25: 6302 | Z25: 7553 | AA25: 9788 | AC25: Cash flow from Operating activities | AD25: 2848 | AE25: 2189 | AF25: 3932 | AG25: 5327 | AH25: 4641
A26: Capital expenditures | B26: 7489 | C26: 7408 | D26: 9067 | E26: 9302 | F26: 7992 | H26: Capital expenditures | I26: 9907 | J26: 9715 | K26: 11367 | L26: 12604 | M26: 12280 | O26: Capital expenditures | P26: 6020 | Q26: 5960 | R26: 7591 | S26: 10211 | T26: 12198 | V26: Capital expenditures | W26: 7441 | X26: 7586 | Y26: 7923 | Z26: 9095 | AA26: 8955 | AC26: Capital expenditures | AD26: 5369 | AE26: 4244 | AF26: 4638 | AG26: 5854 | AH26: 7364
A27: Dividends paid | B27: 2743 | C27: 3024 | D27: 3352 | E27: 3782 | F27: 4235 | H27: Dividends paid | I27: 2812 | J27: 3114 | K27: 3179 | L27: 3244 | M27: 3213 | O27: Dividends paid | P27: 2873 | Q27: 2036 | R27: 2209 | S27: 2233 | T27: 2239 | V27: Dividends paid | W27: 2685 | X27: 2777 | Y27: 2907 | Z27: 3035 | AA27: 2954 | AC27: Dividends paid | AD27: 856 | AE27: 935 | AF27: 1012 | AG27: 1092 | AH27: 1175
A28: Debt paid | B28: =6103+2100 -> 8203 | C28: =9594+257 -> 9851 | D28: =4525+1125 -> 5650 | E28: =7978+2613 -> 10591 | F28: =10113+6613 -> 16726 | H28: Debt paid | I28: =4506+2147 -> 6653 | J28: =5294+997 -> 6291 | K28: =4396+287 -> 4683 | L28: =4737+125 -> 4862 | M28: =3357+1096 -> 4453 | O28: Debt paid | P28: =16+1125+2879 -> 4020 | Q28: =1265+225+3750+900 -> 6140 | R28: =1338+450 -> 1788 | S28: =975+5673+900 -> 7548 | T28: =1456+7750+2740+65+450 -> 12461 | V28: Debt paid | W28: =4458+840 -> 5298 | X28: =4327+25 -> 4352 | Y28: =2158+298+1150 -> 3606 | Z28: =4294+1630 -> 5924 | AA28: =2222+1020 -> 3242 | AC28: Debt paid | AD28: =11+1001 -> 1012 | AE28: =417 -> 417 | AF28: =192+601 -> 793 | AG28: =28+1151 -> 1179 | AH28: =90+656 -> 746
O30: PBT | P30: =P5-P6-P7 -> 1411 | Q30: =Q5-Q6-Q7 -> 3098 | R30: =R5-R6-R7 -> 1053 | S30: =S5-S6-S7 -> 2724 | T30: =T5-T6-T7 -> 2182 | AC30: PBT | AD30: =AD5-AD6-AD7 -> 1383 | AE30: =AE5-AE6-AE7 -> 1475 | AF30: =AF5-AF6-AF7 -> 1558 | AG30: =AG5-AG6-AG7 -> 1523 | AH30: =AH5-AH6-AH7 -> 1388
O32: Particulars | P32: 2020 | Q32: 2021 | R32: 2022 | S32: 2023 | T32: 2024 | V32: Particulars | W32: 2020 | X32: 2021 | Y32: 2022 | Z32: 2023 | AA32: 2024 | AC32: Particulars | AD32: 2020 | AE32: 2021 | AF32: 2022 | AG32: 2023 | AH32: 2024
O33: Revenue | P33: =P3 -> 14172 | Q33: =Q3 -> 13964 | R33: =R3 -> 17174 | S33: =S3 -> 14393 | T33: =T3 -> 14459 | V33: Revenue | W33: =W3 -> 20375 | X33: =X3 -> 23113 | Y33: =Y3 -> 29279 | Z33: =Z3 -> 25253 | AA33: =AA3 -> 26724 | AC33: Revenue | AD33: =AD3 -> 11526 | AE33: =AE3 -> 13431 | AF33: =AF3 -> 15310 | AG33: =AG3 -> 14206 | AH33: =AH3 -> 13441
O34: Operating income | P34: =P5 -> 5120 | Q34: =Q5 -> 6930 | R34: =R5 -> 4849 | S34: =S5 -> 6978 | T34: =T5 -> 6414 | V34: Operating income | W34: =W5 -> 8835 | X34: =X5 -> 7978 | Y34: =Y5 -> 9908 | Z34: =Z5 -> 11316 | AA34: =AA5 -> 12727 | AC34: Operating income | AD34: =AD5 -> 4213 | AE34: =AE5 -> 4464 | AF34: =AF5 -> 4952 | AG34: =AG5 -> 5077 | AH34: =AH5 -> 5460
O35: Net income | P35: =P9 -> 1328 | Q35: =Q9 -> 2673 | R35: =R9 -> 985 | S35: =S9 -> 2156 | T35: =T9 -> 1874 | V35: Net income | W35: =W9 -> 3103 | X35: =X9 -> 2309 | Y35: =Y9 -> 3428 | Z35: =Z9 -> 3849 | AA35: =AA9 -> 4260 | AC35: Net income | AD35: =AD9 -> 1389 | AE35: =AE9 -> 1545 | AF35: =AF9 -> 1693 | AG35: =AG9 -> 1669 | AH35: =AH9 -> 1790
O37: Particulars | P37: 2025 | Q37: 2026 | R37: 2027 | S37: 2028 | T37: 2029 | U37: 2030 | AC37: Particulars | AD37: 2025 | AE37: 2026 | AF37: 2027 | AG37: 2028 | AH37: 2029 | AI37: 2030
O38: Revenue | P38: =DCF!R3 -> 14516.836 | Q38: =DCF!S3 -> 14574.903 | R38: =DCF!T3 -> 14633.203 | S38: =DCF!U3 -> 14691.736 | T38: =DCF!V3 -> 14750.503 | U38: =DCF!W3 -> 14809.505 | AC38: Revenue | AD38: =DCF!AH3 -> 13860.605 | AE38: =DCF!AI3 -> 14293.309 | AF38: =DCF!AJ3 -> 14739.521 | AG38: =DCF!AK3 -> 15199.663 | AH38: =DCF!AL3 -> 15674.17 | AI38: =DCF!AM3 -> 16163.49
O39: Operating income | P39: =DCF!R4 -> 5929.3099 | Q39: =DCF!S4 -> 5953.0271 | R39: =DCF!T4 -> 5976.8392 | S39: =DCF!U4 -> 6000.7466 | T39: =DCF!V4 -> 6024.7496 | U39: =DCF!W4 -> 6048.8486 | AC39: Operating income | AD39: =DCF!AH4 -> 4932.0519 | AE39: =DCF!AI4 -> 5086.0219 | AF39: =DCF!AJ4 -> 5244.7987 | AG39: =DCF!AK4 -> 5408.5321 | AH39: =DCF!AL4 -> 5577.3771 | AI39: =DCF!AM4 -> 5751.4931
O40: Net income | P40: =DCF!R5 -> 5092.3587 | Q40: =DCF!S5 -> 5112.7281 | R40: =DCF!T5 -> 5133.1791 | S40: =DCF!U5 -> 5153.7118 | T40: =DCF!V5 -> 5174.3266 | U40: =DCF!W5 -> 5195.0239 | AC40: Net income | AD40: =DCF!AH5 -> 6360.4992 | AE40: =DCF!AI5 -> 6559.0629 | AF40: =DCF!AJ5 -> 6763.8254 | AG40: =DCF!AK5 -> 6974.9802 | AH40: =DCF!AL5 -> 7192.7269 | AI40: =DCF!AM5 -> 7417.2713
O41: FCFF | P41: =DCF!R9 -> 1159.3239 | Q41: =DCF!S9 -> 1760.5007 | R41: =DCF!T9 -> 1767.5427 | S41: =DCF!U9 -> 1774.6129 | T41: =DCF!V9 -> 1781.7114 | U41: =DCF!W9 -> 1788.8382 | V41: Particulars | W41: 2025 | X41: 2026 | Y41: 2027 | Z41: 2028 | AA41: 2029 | AB41: 2030 | AC41: FCFF | AD41: =DCF!AH9 -> 2313.5586 | AE41: =DCF!AI9 -> 3275.7342 | AF41: =DCF!AJ9 -> 3377.9969 | AG41: =DCF!AK9 -> 3483.4521 | AH41: =DCF!AL9 -> 3592.1994 | AI41: =DCF!AM9 -> 3704.3416
V42: Revenue | W42: =DCF!Z3 -> 28213.842 | X42: =DCF!AA3 -> 29786.742 | Y42: =DCF!AB3 -> 31447.329 | Z42: =DCF!AC3 -> 33200.494 | AA42: =DCF!AD3 -> 35051.395 | AB42: =DCF!AE3 -> 37005.483
V43: Operating income | W43: =DCF!Z4 -> 11481.494 | X43: =DCF!AA4 -> 12121.578 | Y43: =DCF!AB4 -> 12797.347 | Z43: =DCF!AC4 -> 13510.789 | AA43: =DCF!AD4 -> 14264.005 | AB43: =DCF!AE4 -> 15059.212
V44: Net income | W44: =DCF!Z5 -> 8840.7504 | X44: =DCF!AA5 -> 9333.6153 | Y44: =DCF!AB5 -> 9853.9571 | Z44: =DCF!AC5 -> 10403.307 | AA44: =DCF!AD5 -> 10983.284 | AB44: =DCF!AE5 -> 11595.593
V45: FCFF | W45: =DCF!Z9 -> 3108.8534 | X45: =DCF!AA9 -> 4565.7094 | Y45: =DCF!AB9 -> 4820.2441 | Z45: =DCF!AC9 -> 5088.969 | AA45: =DCF!AD9 -> 5372.675 | AB45: =DCF!AE9 -> 5672.1974

Sheet Assumptions
A1: ASSUMPTIONS
A3: Assumptions | B3: NextEra | C3: Duke | D3: Dominion | E3: Southern | F3: Xcel
A4: Revenue CAGR | B4: =(Financials!F3/Financials!B3)^(1/5)-1 -> 0.065824122 | C4: =(Financials!M3/Financials!I3)^(1/5)-1 -> 0.049273161 | D4: 0.004 | E4: =(Financials!AA3/Financials!W3)^(1/5)-1 -> 0.05574922 | F4: =(Financials!AH3/Financials!AD3)^(1/5)-1 -> 0.031218257
A5: Operating margin (EBIT) | B5: =AVERAGE(Table1[[#This Row],[2020]:[2024]])/AVERAGE(Financials!B3:F3) -> 0.57000248 | C5: =AVERAGE(Table18[[#This Row],[2020]:[2024]])/AVERAGE(Financials!I3:M3) -> 0.41296391 | D5: =AVERAGE(Table125[[#This Row],[2020]:[2024]])/AVERAGE(Financials!P3:T3) -> 0.40844368 | E5: =AVERAGE(Table1828[[#This Row],[2020]:[2024]])/AVERAGE(Financials!W3:AA3) -> 0.40694542 | F5: =AVERAGE(Table182837[[#This Row],[2020]:[2024]])/AVERAGE(Financials!AD3:AH3) -> 0.35583238
A6: Depreciation rate | B6: =AVERAGE(Table1[[#This Row],[2020]:[2024]])/AVERAGE(Financials!B3:F3) -> 0.21875488 | C6: =AVERAGE(Table18[[#This Row],[2020]:[2024]])/AVERAGE(Financials!I3:M3) -> 0.18831207 | D6: =AVERAGE(Table125[[#This Row],[2020]:[2024]])/AVERAGE(Financials!P3:T3) -> 0.16942639 | E6: =AVERAGE(Table1828[[#This Row],[2020]:[2024]])/AVERAGE(Financials!W3:AA3) -> 0.16053678 | F6: =AVERAGE(Table182837[[#This Row],[2020]:[2024]])/AVERAGE(Financials!AD3:AH3) -> 0.17189387
A7: Capex margin | B7: =AVERAGE(Financials!B26:F26)/AVERAGE(Financials!B3:F3) -> 0.37889961 | C7: =AVERAGE(Financials!I26:M26)/AVERAGE(Financials!I3:M3) -> 0.40738607 | D7: 0.4 | E7: =AVERAGE(Financials!W26:AA26)/AVERAGE(Financials!W3:AA3) -> 0.32867312 | F7: =AVERAGE(Financials!AD26:AH26)/AVERAGE(Financials!AD3:AH3) -> 0.40446741 | H7: Particulars | I7: 2020 | J7: 2021 | K7: 2022 | L7: 2023 | M7: 2024
A8: Working capital | B8: =AVERAGE(I8:M8)/AVERAGE(Financials!B3:F3) -> -0.51002397 | C8: =AVERAGE(I9:M9)/AVERAGE(Financials!I3:M3) -> -0.22009479 | D8: =AVERAGE(I10:M10)/AVERAGE(Financials!P3:T3) -> -0.14398209 | E8: =AVERAGE(I11:M11)/AVERAGE(Financials!W3:AA3) -> -0.15279292 | F8: =AVERAGE(I12:M12)/AVERAGE(Financials!AD3:AH3) -> -0.094560768 | H8: WC-NE | I8: =Financials!B17-Financials!B18 -> -8176 | J8: =Financials!C17-Financials!C18 -> -8149 | K8: =Financials!D17-Financials!D18 -> -13205 | L8: =Financials!E17-Financials!E18 -> -12602 | M8: =Financials!F17-Financials!F18 -> -13404
A9: Forecast horizon | B9: 6 years | C9: 6 years | D9: =$C$9 -> 6 years | E9: =$C$9 -> 6 years | F9: =$C$9 -> 6 years | H9: WC-Duke | I9: =Financials!I17-Financials!I18 -> -7623 | J9: =Financials!J17-Financials!J18 -> -5991 | K9: =Financials!K17-Financials!K18 -> -5651 | L9: =Financials!L17-Financials!L18 -> -4514 | M9: =Financials!M17-Financials!M18 -> -6407
A10: Risk-free rate | B10: 0.0418 | C10: 0.0418 | D10: 0.0418 | E10: 0.0418 | F10: 0.0418 | H10: WC-Dominion | I10: =Financials!P17-Financials!P18 -> -3957 | J10: =Financials!Q17-Financials!Q18 -> -1404 | K10: =Financials!R17-Financials!R18 -> -3600 | L10: =Financials!S17-Financials!S18 -> 959 | M10: =Financials!T17-Financials!T18 -> -2676
A11: Equity risk premium | B11: 0.051 | C11: 0.051 | D11: 0.051 | E11: 0.051 | F11: 0.051 | H11: WC-Southern | I11: =Financials!W17-Financials!W18 -> -3462 | J11: =Financials!X17-Financials!X18 -> -1956 | K11: =Financials!Y17-Financials!Y18 -> -5308 | L11: =Financials!Z17-Financials!Z18 -> -3035 | M11: =Financials!AA17-Financials!AA18 -> -5299
A12: Beta | B12: ='Company Profile'!B5 -> 0.7215 | C12: ='Company Profile'!C5 -> 0.4737 | D12: ='Company Profile'!D5 -> 0.6708 | E12: ='Company Profile'!E5 -> 0.4486 | F12: ='Company Profile'!F5 -> 0.4519 | H12: WC-Xcel | I12: =Financials!AD17-Financials!AD18 -> -964 | J12: =Financials!AE17-Financials!AE18 -> -807 | K12: =Financials!AF17-Financials!AF18 -> -934 | L12: =Financials!AG17-Financials!AG18 -> -1583 | M12: =Financials!AH17-Financials!AH18 -> -2134
A13: Cost of equity | B13: =B10+(B11*B12) -> 0.0785965 | C13: =C10+(C11*C12) -> 0.0659587 | D13: =D10+(D11*D12) -> 0.0760108 | E13: =E10+(E11*E12) -> 0.0646786 | F13: =F10+(F11*F12) -> 0.0648469
A14: Cost of debt (pre-tax) | B14: =AVERAGE(Financials!B7:F7)/AVERAGE(Financials!B20:F20) -> 0.028952348 | C14: =AVERAGE(Financials!I7:M7)/AVERAGE(Financials!I20:M20) -> 0.036144054 | D14: =AVERAGE(Financials!P7:T7)/AVERAGE(Financials!P20:T20) -> 0.037381926 | E14: =AVERAGE(Financials!W7:AA7)/AVERAGE(Financials!W20:AA20) -> 0.041512144 | F14: =AVERAGE(Financials!AD7:AH7)/AVERAGE(Financials!AD20:AH20) -> 0.041594189
A15: Tax rate | B15: 0.23 | C15: 0.23 | D15: =Financials!T8/Financials!T30 -> 0.1411549 | E15: 0.23 | F15: =Financials!AH8/Financials!AH30 -> -0.28962536 | H15: Particulars | I15: 2025 | J15: 2026 | K15: 2027 | L15: 2028 | M15: 2029 | N15: 2030
A16: Cost of debt (after-tax) | B16: =B14*(1-B15) -> 0.022293308 | C16: =C14*(1-C15) -> 0.027830921 | D16: =D14*(1-D15) -> 0.032105284 | E16: =E14*(1-E15) -> 0.031964351 | F16: =F14*(1-F15) -> 0.053640921 | H16: =H8 -> WC-NE | I16: =DCF!B3*Assumptions!$B$8 -> -13455.628 | J16: =DCF!C3*Assumptions!$B$8 -> -14341.333 | K16: =DCF!D3*Assumptions!$B$8 -> -15285.339 | L16: =DCF!E3*Assumptions!$B$8 -> -16291.483 | M16: =DCF!F3*Assumptions!$B$8 -> -17363.855 | N16: =DCF!G3*Assumptions!$B$8 -> -18506.816
A17: Market value of equity | B17: ='Company Profile'!B9 -> 176397.07 | C17: ='Company Profile'!C9 -> 97347.63 | D17: ='Company Profile'!D9 -> 52472.972 | E17: ='Company Profile'!E9 -> 99936.29 | F17: ='Company Profile'!F9 -> 47914.724 | H17: =H9 -> WC-Duke | I17: =DCF!J3*Assumptions!$C$8 -> -7010.632 | J17: =DCF!K3*Assumptions!$C$8 -> -7356.068 | K17: =DCF!L3*Assumptions!$C$8 -> -7718.5247 | L17: =DCF!M3*Assumptions!$C$8 -> -8098.8408 | M17: =DCF!N3*Assumptions!$C$8 -> -8497.8963 | N17: =DCF!O3*Assumptions!$C$8 -> -8916.6145
A18: Total debt | B18: =Financials!F20 -> 82333 | C18: =Financials!M20 -> 84273 | D18: =Financials!T20 -> 40025 | E18: =Financials!AA20 -> 58768 | F18: =Financials!AH20 -> 29114 | H18: =H10 -> WC-Dominion | I18: =DCF!R3*Assumptions!$D$8 -> -2090.1644 | J18: =DCF!S3*Assumptions!$D$8 -> -2098.5251 | K18: =DCF!T3*Assumptions!$D$8 -> -2106.9192 | L18: =DCF!U3*Assumptions!$D$8 -> -2115.3469 | M18: =DCF!V3*Assumptions!$D$8 -> -2123.8083 | N18: =DCF!W3*Assumptions!$D$8 -> -2132.3035
A19: Total capital | B19: =B17+B18 -> 258730.07 | C19: =C17+C18 -> 181620.63 | D19: =D17+D18 -> 92497.972 | E19: =E17+E18 -> 158704.29 | F19: =F17+F18 -> 77028.724 | H19: =H11 -> WC-Southern | I19: =DCF!Z3*Assumptions!$E$8 -> -4310.8753 | J19: =DCF!AA3*Assumptions!$E$8 -> -4551.2033 | K19: =DCF!AB3*Assumptions!$E$8 -> -4804.9293 | L19: =DCF!AC3*Assumptions!$E$8 -> -5072.8003 | M19: =DCF!AD3*Assumptions!$E$8 -> -5355.605 | N19: =DCF!AE3*Assumptions!$E$8 -> -5654.1758
A20: Weight of debt | B20: =B18/B19 -> 0.31821968 | C20: =C18/C19 -> 0.46400566 | D20: =D18/D19 -> 0.43271219 | E20: =E18/E19 -> 0.37029875 | F20: =F18/F19 -> 0.3779629 | H20: =H12 -> WC-Xcel | I20: =DCF!AH3*Assumptions!$F$8 -> -1310.6694 | J20: =DCF!AI3*Assumptions!$F$8 -> -1351.5862 | K20: =DCF!AJ3*Assumptions!$F$8 -> -1393.7804 | L20: =DCF!AK3*Assumptions!$F$8 -> -1437.2918 | M20: =DCF!AL3*Assumptions!$F$8 -> -1482.1615 | N20: =DCF!AM3*Assumptions!$F$8 -> -1528.432
A21: Weight of equity | B21: =B17/B19 -> 0.68178032 | C21: =C17/C19 -> 0.53599434 | D21: =D17/D19 -> 0.56728781 | E21: =E17/E19 -> 0.62970125 | F21: =F17/F19 -> 0.6220371
A22: WACC | B22: =(B13*B21)+(B16*B20) -> 0.060679716 | C22: =(C13*C21)+(C16*C20) -> 0.048267195 | D22: =(D13*D21)+(D16*D20) -> 0.057012348 | E22: =(E13*E21)+(E16*E20) -> 0.052564554 | F22: =(F13*F21)+(F16*F20) -> 0.060611456
A23: Terminal Growth rate | B23: 0.02 | C23: 0.02 | D23: 0.0275 | E23: 0.018 | F23: 0.018
A24: Outstanding shares | B24: ='Company Profile'!B7 -> 2082.61 | C24: ='Company Profile'!C7 -> 777.6612 | D24: ='Company Profile'!D7 -> 853.9133 | E24: ='Company Profile'!E7 -> 1101.105 | F24: ='Company Profile'!F7 -> 591.5398
A25: Cash and cash equivalents | B25: =Financials!F13 -> 1487 | C25: =Financials!M13 -> 314 | D25: =Financials!T13 -> 310 | E25: =Financials!AA13 -> 1070 | F25: =Financials!AH13 -> 179
A26: PV Discount rate | B26: =1/(1+B22)^6 -> 0.70225432 | C26: =1/(1+C22)^6 -> 0.7536471 | D26: =1/(1+D22)^6 -> 0.71700079 | E26: =1/(1+E22)^6 -> 0.73537279 | F26: =1/(1+F22)^6 -> 0.70252554

Sheet DCF
G1: NE | O1: DE | W1: DOE | AE1: SC | AM1: XCE
A2: Particulars | B2: 2025 | C2: 2026 | D2: 2027 | E2: 2028 | F2: 2029 | G2: 2030 | I2: Particulars | J2: 2025 | K2: 2026 | L2: 2027 | M2: 2028 | N2: 2029 | O2: 2030 | Q2: Particulars | R2: 2025 | S2: 2026 | T2: 2027 | U2: 2028 | V2: 2029 | W2: 2030 | Y2: Particulars | Z2: 2025 | AA2: 2026 | AB2: 2027 | AC2: 2028 | AD2: 2029 | AE2: 2030 | AG2: Particulars | AH2: 2025 | AI2: 2026 | AJ2: 2027 | AK2: 2028 | AL2: 2029 | AM2: 2030
A3: Revenue | B3: =Table1[[#This Row],[2024]]*(1+Assumptions!B4) -> 26382.344 | C3: =Table9[[#This Row],[2025]]*(1+Assumptions!$B$4) -> 28118.939 | D3: =Table9[[#This Row],[2026]]*(1+Assumptions!$B$4) -> 29969.844 | E3: =Table9[[#This Row],[2027]]*(1+Assumptions!$B$4) -> 31942.582 | F3: =Table9[[#This Row],[2028]]*(1+Assumptions!$B$4) -> 34045.175 | G3: =Table9[[#This Row],[2029]]*(1+Assumptions!$B$4) -> 36286.168 | I3: Revenue | J3: =Table18[[#This Row],[2024]]*(1+Assumptions!C4) -> 31852.785 | K3: =Table10[[#This Row],[2025]]*(1+Assumptions!$C$4) -> 33422.273 | L3: =Table10[[#This Row],[2026]]*(1+Assumptions!$C$4) -> 35069.094 | M3: =Table10[[#This Row],[2027]]*(1+Assumptions!$C$4) -> 36797.059 | N3: =Table10[[#This Row],[2028]]*(1+Assumptions!$C$4) -> 38610.166 | O3: =Table10[[#This Row],[2029]]*(1+Assumptions!$C$4) -> 40512.611 | Q3: Revenue | R3: =Table125[[#This Row],[2024]]*(1+Assumptions!D4) -> 14516.836 | S3: =Table96[[#This Row],[2025]]*(1+Assumptions!$D$4) -> 14574.903 | T3: =Table96[[#This Row],[2026]]*(1+Assumptions!$D$4) -> 14633.203 | U3: =Table96[[#This Row],[2027]]*(1+Assumptions!$D$4) -> 14691.736 | V3: =Table96[[#This Row],[2028]]*(1+Assumptions!$D$4) -> 14750.503 | W3: =Table96[[#This Row],[2029]]*(1+Assumptions!$D$4) -> 14809.505 | Y3: Revenue | Z3: =Table1828[[#This Row],[2024]]*(1+Assumptions!E4) -> 28213.842 | AA3: =Table107[[#This Row],[2025]]*(1+Assumptions!$E$4) -> 29786.742 | AB3: =Table107[[#This Row],[2026]]*(1+Assumptions!$E$4) -> 31447.329 | AC3: =Table107[[#This Row],[2027]]*(1+Assumptions!$E$4) -> 33200.494 | AD3: =Table107[[#This Row],[2028]]*(1+Assumptions!$E$4) -> 35051.395 | AE3: =Table107[[#This Row],[2029]]*(1+Assumptions!$E$4) -> 37005.483 | AG3: Revenue | AH3: =Table182837[[#This Row],[2024]]*(1+Assumptions!F4) -> 13860.605 | AI3: =Table9619[[#This Row],[2025]]*(1+Assumptions!$F$4) -> 14293.309 | AJ3: =Table9619[[#This Row],[2026]]*(1+Assumptions!$F$4) -> 14739.521 | AK3: =Table9619[[#This Row],[2027]]*(1+Assumptions!$F$4) -> 15199.663 | AL3: =Table9619[[#This Row],[2028]]*(1+Assumptions!$F$4) -> 15674.17 | AM3: =Table9619[[#This Row],[2029]]*(1+Assumptions!$F$4) -> 16163.49
A4: EBIT | B4: =B3*Assumptions!$B$5 -> 15038.002 | C4: =C3*Assumptions!$B$5 -> 16027.865 | D4: =D3*Assumptions!$B$5 -> 17082.885 | E4: =E3*Assumptions!$B$5 -> 18207.351 | F4: =F3*Assumptions!$B$5 -> 19405.834 | G4: =G3*Assumptions!$B$5 -> 20683.206 | I4: EBIT | J4: =J3*Assumptions!$C$5 -> 13154.051 | K4: =K3*Assumptions!$C$5 -> 13802.192 | L4: =L3*Assumptions!$C$5 -> 14482.27 | M4: =M3*Assumptions!$C$5 -> 15195.857 | N4: =N3*Assumptions!$C$5 -> 15944.605 | O4: =O3*Assumptions!$C$5 -> 16730.246 | Q4: EBIT | R4: =R3*Assumptions!$D$5 -> 5929.3099 | S4: =S3*Assumptions!$D$5 -> 5953.0271 | T4: =T3*Assumptions!$D$5 -> 5976.8392 | U4: =U3*Assumptions!$D$5 -> 6000.7466 | V4: =V3*Assumptions!$D$5 -> 6024.7496 | W4: =W3*Assumptions!$D$5 -> 6048.8486 | Y4: EBIT | Z4: =Z3*Assumptions!$E$5 -> 11481.494 | AA4: =AA3*Assumptions!$E$5 -> 12121.578 | AB4: =AB3*Assumptions!$E$5 -> 12797.347 | AC4: =AC3*Assumptions!$E$5 -> 13510.789 | AD4: =AD3*Assumptions!$E$5 -> 14264.005 | AE4: =AE3*Assumptions!$E$5 -> 15059.212 | AG4: EBIT | AH4: =AH3*Assumptions!$F$5 -> 4932.0519 | AI4: =AI3*Assumptions!$F$5 -> 5086.0219 | AJ4: =AJ3*Assumptions!$F$5 -> 5244.7987 | AK4: =AK3*Assumptions!$F$5 -> 5408.5321 | AL4: =AL3*Assumptions!$F$5 -> 5577.3771 | AM4: =AM3*Assumptions!$F$5 -> 5751.4931
A5: NOPAT | B5: =B4*(1-Assumptions!$B$15) -> 11579.261 | C5: =C4*(1-Assumptions!$B$15) -> 12341.456 | D5: =D4*(1-Assumptions!$B$15) -> 13153.822 | E5: =E4*(1-Assumptions!$B$15) -> 14019.66 | F5: =F4*(1-Assumptions!$B$15) -> 14942.492 | G5: =G4*(1-Assumptions!$B$15) -> 15926.069 | I5: NOPAT | J5: =J4*(1-Assumptions!$C$15) -> 10128.619 | K5: =K4*(1-Assumptions!$C$15) -> 10627.688 | L5: =L4*(1-Assumptions!$C$15) -> 11151.348 | M5: =M4*(1-Assumptions!$C$15) -> 11700.81 | N5: =N4*(1-Assumptions!$C$15) -> 12277.346 | O5: =O4*(1-Assumptions!$C$15) -> 12882.29 | Q5: NOPAT | R5: =R4*(1-Assumptions!$D$15) -> 5092.3587 | S5: =S4*(1-Assumptions!$D$15) -> 5112.7281 | T5: =T4*(1-Assumptions!$D$15) -> 5133.1791 | U5: =U4*(1-Assumptions!$D$15) -> 5153.7118 | V5: =V4*(1-Assumptions!$D$15) -> 5174.3266 | W5: =W4*(1-Assumptions!$D$15) -> 5195.0239 | Y5: NOPAT | Z5: =Z4*(1-Assumptions!$C$15) -> 8840.7504 | AA5: =AA4*(1-Assumptions!$C$15) -> 9333.6153 | AB5: =AB4*(1-Assumptions!$C$15) -> 9853.9571 | AC5: =AC4*(1-Assumptions!$C$15) -> 10403.307 | AD5: =AD4*(1-Assumptions!$C$15) -> 10983.284 | AE5: =AE4*(1-Assumptions!$C$15) -> 11595.593 | AG5: NOPAT | AH5: =AH4*(1-Assumptions!$F$15) -> 6360.4992 | AI5: =AI4*(1-Assumptions!$F$15) -> 6559.0629 | AJ5: =AJ4*(1-Assumptions!$F$15) -> 6763.8254 | AK5: =AK4*(1-Assumptions!$F$15) -> 6974.9802 | AL5: =AL4*(1-Assumptions!$F$15) -> 7192.7269 | AM5: =AM4*(1-Assumptions!$F$15) -> 7417.2713
A6: Depreciation | B6: =B3*Assumptions!$B$6 -> 5771.2666 | C6: =C3*Assumptions!$B$6 -> 6151.1551 | D6: =D3*Assumptions!$B$6 -> 6556.0495 | E6: =E3*Assumptions!$B$6 -> 6987.5957 | F6: =F3*Assumptions!$B$6 -> 7447.5481 | G6: =G3*Assumptions!$B$6 -> 7937.7764 | I6: Depreciation | J6: =J3*Assumptions!$C$6 -> 5998.2639 | K6: =K3*Assumptions!$C$6 -> 6293.8173 | L6: =L3*Assumptions!$C$6 -> 6603.9335 | M6: =M3*Assumptions!$C$6 -> 6929.3302 | N6: =N3*Assumptions!$C$6 -> 7270.7602 | O6: =O3*Assumptions!$C$6 -> 7629.0136 | Q6: Depreciation | R6: =R3*Assumptions!$D$6 -> 2459.5351 | S6: =S3*Assumptions!$D$6 -> 2469.3733 | T6: =T3*Assumptions!$D$6 -> 2479.2508 | U6: =U3*Assumptions!$D$6 -> 2489.1678 | V6: =V3*Assumptions!$D$6 -> 2499.1244 | W6: =W3*Assumptions!$D$6 -> 2509.1209 | Y6: Depreciation | Z6: =Z3*Assumptions!$E$6 -> 4529.3594 | AA6: =AA3*Assumptions!$E$6 -> 4781.8676 | AB6: =AB3*Assumptions!$E$6 -> 5048.453 | AC6: =AC3*Assumptions!$E$6 -> 5329.9003 | AD6: =AD3*Assumptions!$E$6 -> 5627.0381 | AE6: =AE3*Assumptions!$E$6 -> 5940.7411 | AG6: Depreciation | AH6: =AH3*Assumptions!$F$6 -> 2382.5529 | AI6: =AI3*Assumptions!$F$6 -> 2456.9321 | AJ6: =AJ3*Assumptions!$F$6 -> 2533.6332 | AK6: =AK3*Assumptions!$F$6 -> 2612.7288 | AL6: =AL3*Assumptions!$F$6 -> 2694.2936 | AM6: =AM3*Assumptions!$F$6 -> 2778.4048
A7: Capex | B7: =B3*Assumptions!$B$7 -> 9996.2601 | C7: =C3*Assumptions!$B$7 -> 10654.255 | D7: =D3*Assumptions!$B$7 -> 11355.562 | E7: =E3*Assumptions!$B$7 -> 12103.032 | F7: =F3*Assumptions!$B$7 -> 12899.704 | G7: =G3*Assumptions!$B$7 -> 13748.815 | I7: Capex | J7: =J3*Assumptions!$C$7 -> 12976.381 | K7: =K3*Assumptions!$C$7 -> 13615.768 | L7: =L3*Assumptions!$C$7 -> 14286.66 | M7: =M3*Assumptions!$C$7 -> 14990.609 | N7: =N3*Assumptions!$C$7 -> 15729.244 | O7: =O3*Assumptions!$C$7 -> 16504.274 | Q7: Capex | R7: =R3*Assumptions!$D$7 -> 5806.7344 | S7: =S3*Assumptions!$D$7 -> 5829.9613 | T7: =T3*Assumptions!$D$7 -> 5853.2812 | U7: =U3*Assumptions!$D$7 -> 5876.6943 | V7: =V3*Assumptions!$D$7 -> 5900.2011 | W7: =W3*Assumptions!$D$7 -> 5923.8019 | Y7: Capex | Z7: =Z3*Assumptions!$E$7 -> 9273.1316 | AA7: =AA3*Assumptions!$E$7 -> 9790.1014 | AB7: =AB3*Assumptions!$E$7 -> 10335.892 | AC7: =AC3*Assumptions!$E$7 -> 10912.11 | AD7: =AD3*Assumptions!$E$7 -> 11520.451 | AE7: =AE3*Assumptions!$E$7 -> 12162.708 | AG7: Capex | AH7: =AH3*Assumptions!$F$7 -> 5606.1629 | AI7: =AI3*Assumptions!$F$7 -> 5781.1775 | AJ7: =AJ3*Assumptions!$F$7 -> 5961.6558 | AK7: =AK3*Assumptions!$F$7 -> 6147.7683 | AL7: =AL3*Assumptions!$F$7 -> 6339.6909 | AM7: =AM3*Assumptions!$F$7 -> 6537.605
A8: Change in Working capital | B8: =Assumptions!I16-Assumptions!M8 -> -51.628058 | C8: =Assumptions!J16-Assumptions!I16 -> -885.7049 | D8: =Assumptions!K16-Assumptions!J16 -> -944.00565 | E8: =Assumptions!L16-Assumptions!K16 -> -1006.144 | F8: =Assumptions!M16-Assumptions!L16 -> -1072.3725 | G8: =Assumptions!N16-Assumptions!M16 -> -1142.9605 | I8: Change in Working capital | J8: =Assumptions!I17-Assumptions!M9 -> -603.632 | K8: =Assumptions!J17-Assumptions!I17 -> -345.436 | L8: =Assumptions!K17-Assumptions!J17 -> -362.45672 | M8: =Assumptions!L17-Assumptions!K17 -> -380.31611 | N8: =Assumptions!M17-Assumptions!L17 -> -399.05549 | O8: =Assumptions!N17-Assumptions!M17 -> -418.71821 | Q8: Change in Working capital | R8: =Assumptions!I18-Assumptions!M10 -> 585.83557 | S8: =Assumptions!J18-Assumptions!I18 -> -8.3606577 | T8: =Assumptions!K18-Assumptions!J18 -> -8.3941004 | U8: =Assumptions!L18-Assumptions!K18 -> -8.4276768 | V8: =Assumptions!M18-Assumptions!L18 -> -8.4613875 | W8: =Assumptions!N18-Assumptions!M18 -> -8.495233 | Y8: Change in Working capital | Z8: =Assumptions!I19-Assumptions!M11 -> 988.12468 | AA8: =Assumptions!J19-Assumptions!I19 -> -240.32794 | AB8: =Assumptions!K19-Assumptions!J19 -> -253.72603 | AC8: =Assumptions!L19-Assumptions!K19 -> -267.87106 | AD8: =Assumptions!M19-Assumptions!L19 -> -282.80466 | AE8: =Assumptions!N19-Assumptions!M19 -> -298.5708 | AG8: Change in Working capital | AH8: =Assumptions!I20-Assumptions!M12 -> 823.33058 | AI8: =Assumptions!J20-Assumptions!I20 -> -40.916814 | AJ8: =Assumptions!K20-Assumptions!J20 -> -42.194166 | AK8: =Assumptions!L20-Assumptions!K20 -> -43.511394 | AL8: =Assumptions!M20-Assumptions!L20 -> -44.869744 | AM8: =Assumptions!N20-Assumptions!M20 -> -46.270499
A9: FCFF | B9: =B5+B6-B7-B8 -> 7405.8959 | C9: =C5+C6-C7-C8 -> 8724.0609 | D9: =D5+D6-D7-D8 -> 9298.3146 | E9: =E5+E6-E7-E8 -> 9910.368 | F9: =F5+F6-F7-F8 -> 10562.709 | G9: =G5+G6-G7-G8 -> 11257.99 | I9: FCFF | J9: =J5+J6-J7-J8 -> 3754.1337 | K9: =K5+K6-K7-K8 -> 3651.1729 | L9: =L5+L6-L7-L8 -> 3831.0778 | M9: =M5+M6-M7-M8 -> 4019.8471 | N9: =N5+N6-N7-N8 -> 4217.9176 | O9: =O5+O6-O7-O8 -> 4425.7478 | Q9: FCFF | R9: =R5+R6-R7-R8 -> 1159.3239 | S9: =S5+S6-S7-S8 -> 1760.5007 | T9: =T5+T6-T7-T8 -> 1767.5427 | U9: =U5+U6-U7-U8 -> 1774.6129 | V9: =V5+V6-V7-V8 -> 1781.7114 | W9: =W5+W6-W7-W8 -> 1788.8382 | Y9: FCFF | Z9: =Z5+Z6-Z7-Z8 -> 3108.8534 | AA9: =AA5+AA6-AA7-AA8 -> 4565.7094 | AB9: =AB5+AB6-AB7-AB8 -> 4820.2441 | AC9: =AC5+AC6-AC7-AC8 -> 5088.969 | AD9: =AD5+AD6-AD7-AD8 -> 5372.675 | AE9: =AE5+AE6-AE7-AE8 -> 5672.1974 | AG9: FCFF | AH9: =AH5+AH6-AH7-AH8 -> 2313.5586 | AI9: =AI5+AI6-AI7-AI8 -> 3275.7342 | AJ9: =AJ5+AJ6-AJ7-AJ8 -> 3377.9969 | AK9: =AK5+AK6-AK7-AK8 -> 3483.4521 | AL9: =AL5+AL6-AL7-AL8 -> 3592.1994 | AM9: =AM5+AM6-AM7-AM8 -> 3704.3416
A12: Metrics | B12: Value | I12: Metrics | J12: Value | Q12: Metrics | R12: Value | Y12: Metrics | Z12: Value | AG12: Metrics | AH12: Value
A13: Terminal Value | B13: =G9*(1+Assumptions!B23)/(Assumptions!B22-Assumptions!B23) -> 282281.96 | I13: Terminal Value | J13: =O9*(1+Assumptions!C23)/(Assumptions!C22-Assumptions!C23) -> 159699.71 | Q13: Terminal Value | R13: =W9*(1+Assumptions!D23)/(Assumptions!D22-Assumptions!D23) -> 62280.075 | Y13: Terminal Value | Z13: =AE9*(1+Assumptions!E23)/(Assumptions!E22-Assumptions!E23) -> 167058.34 | AG13: Terminal Value | AH13: =AM9*(1+Assumptions!F23)/(Assumptions!F22-Assumptions!F23) -> 88497.792
A14: PV of Terminal value | B14: =B13/(1+Assumptions!B22)^6 -> 198233.73 | I14: PV of Terminal value | J14: =J13/(1+Assumptions!C22)^6 -> 120357.22 | Q14: PV of Terminal value | R14: =R13*Assumptions!D26 -> 44654.863 | Y14: PV of Terminal value | Z14: =Z13*Assumptions!E26 -> 122850.16 | AG14: PV of Terminal value | AH14: =AH13*Assumptions!F26 -> 62171.959
A15: PV of FCFF | B15: =NPV(Assumptions!B22,DCF!B9:G9) -> 46132.319 | I15: PV of FCFF | J15: =NPV(Assumptions!C22,DCF!J9:O9) -> 20226.588 | Q15: PV of FCFF | R15: =NPV(Assumptions!D22,DCF!R9:W9) -> 8223.7242 | Y15: PV of FCFF | Z15: =NPV(Assumptions!E22,DCF!Z9:AE9) -> 23684.052 | AG15: PV of FCFF | AH15: =NPV(Assumptions!F22,DCF!AH9:AM9) -> 15956.533
A16: Total enterprise value | B16: =B14+B15 -> 244366.05 | I16: Total enterprise value | J16: =J14+J15 -> 140583.81 | Q16: Total enterprise value | R16: =R14+R15 -> 52878.588 | Y16: Total enterprise value | Z16: =Z14+Z15 -> 146534.21 | AG16: Total enterprise value | AH16: =AH14+AH15 -> 78128.492
A17: Net debt | B17: =Financials!F20-Financials!F13 -> 80846 | I17: Net debt | J17: =Financials!M20-Financials!M13 -> 83959 | Q17: Net debt | R17: =Assumptions!D18-Assumptions!D25 -> 39715 | Y17: Net debt | Z17: =Assumptions!E18-Assumptions!E25 -> 57698 | AG17: Net debt | AH17: =Assumptions!F18-Assumptions!F25 -> 28935
A18: Total equity value | B18: =B16-B17 -> 163520.05 | I18: Total equity value | J18: =J16-J17 -> 56624.808 | Q18: Total equity value | R18: =R16-R17 -> 13163.588 | Y18: Total equity value | Z18: =Z16-Z17 -> 88836.208 | AG18: Total equity value | AH18: =AH16-AH17 -> 49193.492
A19: Outstanding shares | B19: =Assumptions!B24 -> 2082.61 | I19: Outstanding shares | J19: =Assumptions!C24 -> 777.6612 | Q19: Outstanding shares | R19: =Assumptions!D24 -> 853.9133 | Y19: Outstanding shares | Z19: =Assumptions!E24 -> 1101.105 | AG19: Outstanding shares | AH19: =Assumptions!F24 -> 591.5398
A20: Intrinsic value | B20: =B18/B19 -> 78.516883 | I20: Intrinsic value | J20: =J18/J19 -> 72.814239 | Q20: Intrinsic value | R20: =R18/R19 -> 15.415602 | Y20: Intrinsic value | Z20: =Z18/Z19 -> 80.679143 | AG20: Intrinsic value | AH20: =AH18/AH19 -> 83.161763
A21: Current market price | B21: ='Company Profile'!B3 -> 84.7 | I21: Current market price | J21: ='Company Profile'!C3 -> 24.89 | Q21: Current market price | R21: ='Company Profile'!D3 -> 61.45 | Y21: Current market price | Z21: ='Company Profile'!E3 -> 90.76 | AG21: Current market price | AH21: ='Company Profile'!F3 -> 81
A22: Upside/Downside | B22: =(B20-B21)/B21 -> -0.073000197 | I22: Upside/Downside | J22: =(J20-J21)/J21 -> 1.9254415 | Q22: Upside/Downside | R22: =(R20-R21)/R21 -> -0.74913585 | Y22: Upside/Downside | Z22: =(Z20-Z21)/Z21 -> -0.11107158 | AG22: Upside/Downside | AH22: =(AH20-AH21)/AH21 -> 0.026688427

Sheet Relative
A2: Company | B2: EV/EBITDA | C2: P/E | D2: P/S | E2: P/B | G2: Company | H2: EV/EBITDA | I2: P/E | J2: P/S | K2: P/B | L2: Shares
A3: #VALUE! | B3: 9.7 | C3: {=_FV(A3,"P/E",TRUE)} -> 13.3281 | D3: 1.78 | E3: 1.92 | G3: =A20 -> NextEra Energy | H3: =(B20*B17)/Relative!$L$3 -> 101.08962 | I3: =(C20*C17)/Relative!$L$3 -> 70.75755 | J3: =(D20*D17)/Relative!$L$3 -> 28.699072 | K3: =(E20*E17)/Relative!$L$3 -> 81.956406 | L3: =Assumptions!B24 -> 2082.61
A4: #VALUE! | B4: 13.51 | C4: {=_FV(A4,"P/E",TRUE)} -> 26.8814 | D4: 5.62 | E4: 2.95 | G4: =A21 -> Duke Energy | H4: =(B21*B17)/Relative!$L$4 -> 259.49606 | I4: =(C21*C17)/Relative!$L$4 -> 108.90713 | J4: =(D21*D17)/Relative!$L$4 -> 94.257601 | K4: =(E21*E17)/Relative!$L$4 -> 186.07027 | L4: =Assumptions!C24 -> 777.6612
A5: #VALUE! | B5: 11.56 | C5: {=_FV(A5,"P/E",TRUE)} -> 22.5179 | D5: 3.43 | E5: 2.72 | G5: =A22 -> Dominion Energy | H5: =(B22*B17)/Relative!$L$5 -> 106.22806 | I5: =(C22*C17)/Relative!$L$5 -> 47.342617 | J5: =(D22*D17)/Relative!$L$5 -> 40.885795 | K5: =(E22*E17)/Relative!$L$5 -> 99.81615 | L5: =Assumptions!D24 -> 853.9133
A6: #VALUE! | B6: 11.47 | C6: {=_FV(A6,"P/E",TRUE)} -> 19.4508 | D6: 2.75 | E6: 1.74 | G6: =A23 -> Southern Company | H6: =(B23*B17)/Relative!$L$6 -> 164.42236 | I6: =(C23*C17)/Relative!$L$6 -> 83.459795 | J6: =(D23*D17)/Relative!$L$6 -> 58.603114 | K6: =(E23*E17)/Relative!$L$6 -> 94.02693 | L6: =Assumptions!E24 -> 1101.105
A7: #VALUE! | B7: 7.75 | C7: {=_FV(A7,"P/E",TRUE)} -> 21.774 | D7: 1.87 | E7: 1.56 | G7: =A24 -> Xcel Energy | H7: =(B24*B17)/Relative!$L$7 -> 143.62835 | I7: =(C24*C17)/Relative!$L$7 -> 65.2778 | J7: =(D24*D17)/Relative!$L$7 -> 54.865024 | K7: =(E24*E17)/Relative!$L$7 -> 93.167201 | L7: =Assumptions!F24 -> 591.5398
A8: #VALUE! | B8: 6.14 | C8: {=_FV(A8,"P/E",TRUE)} -> 14.6202 | D8: 0.94 | E8: 2
A9: #VALUE! | B9: 10.54 | C9: {=_FV(A9,"P/E",TRUE)} -> 63.2525 | D9: 3.02 | E9: 15.8 | G9: Company | H9: Target price | I9: CMP | J9: U/D
A10: #VALUE! | B10: 12.27 | C10: {=_FV(A10,"P/E",TRUE)} -> 19.8263 | D10: 2.78 | E10: 1.42 | G10: =G3 -> NextEra Energy | H10: =AVERAGE(H3:K3) -> 70.625662 | I10: ='Company Profile'!B3 -> 84.7 | J10: =(Table39[[#This Row],[Target price]]-I10)/I10 -> -0.16616692
A11: #VALUE! | B11: 6 | C11: {=_FV(A11,"P/E",TRUE)} -> 3.74 | D11: 0.14 | E11: 0.34 | G11: =G4 -> Duke Energy | H11: =AVERAGE(H4:K4) -> 162.18276 | I11: ='Company Profile'!C3 -> 24.89 | J11: =(Table39[[#This Row],[Target price]]-I11)/I11 -> 5.5159809
A12: #VALUE! | B12: 10.82 | C12: {=_FV(A12,"P/E",TRUE)} -> 13.7742 | D12: 1.74 | E12: 1.65 | G12: =G5 -> Dominion Energy | H12: =AVERAGE(H5:K5) -> 73.568155 | I12: ='Company Profile'!D3 -> 61.45 | J12: =(Table39[[#This Row],[Target price]]-I12)/I12 -> 0.1972035
A13: #VALUE! | B13: 10.21 | C13: {=_FV(A13,"P/E",TRUE)} -> 16.6048 | D13: 1.65 | E13: 1.42 | G13: =G6 -> Southern Company | H13: =AVERAGE(H6:K6) -> 100.12805 | I13: ='Company Profile'!E3 -> 90.76 | J13: =(Table39[[#This Row],[Target price]]-I13)/I13 -> 0.10321782
A14: #VALUE! | B14: 13.16 | C14: {=_FV(A14,"P/E",TRUE)} -> 23.0669 | D14: 3.1 | E14: 1.75 | G14: =G7 -> Xcel Energy | H14: =AVERAGE(H7:K7) -> 89.234594 | I14: ='Company Profile'!F3 -> 81 | J14: =(Table39[[#This Row],[Target price]]-I14)/I14 -> 0.10166166
A15: #VALUE! | B15: 11.5 | C15: {=_FV(A15,"P/E",TRUE)} -> 21.6028 | D15: 2.57 | E15: 1.43
A17: Average | B17: =AVERAGE(B3:B15) -> 10.356154 | C17: =AVERAGE(C3:C15) -> 21.5723 | D17: =AVERAGE(D3:D15) -> 2.4146154 | E17: =AVERAGE(E3:E15) -> 2.8230769
A19: Company | B19: EBITDA | C19: Net Income | D19: Revenue | E19: Book Value
A20: NextEra Energy | B20: =Financials!F5+Financials!F6 -> 20329 | C20: =Financials!F9 -> 6831 | D20: =Financials!F3 -> 24753 | E20: =Financials!F21 -> 60460
A21: Duke Energy | B21: =Financials!M5+Financials!M6 -> 19486 | C21: =Financials!M9 -> 3926 | D21: =Financials!M3 -> 30357 | E21: =Table29[[#This Row],[2024]] -> 51256
A22: Dominion Energy | B22: =Financials!T5+Financials!T6 -> 8759 | C22: =Financials!T9 -> 1874 | D22: =Financials!T3 -> 14459 | E22: =Financials!T21 -> 30192
A23: Southern Company | B23: =Financials!AA5+Financials!AA6 -> 17482 | C23: =Financials!AA9 -> 4260 | D23: =Financials!AA3 -> 26724 | E23: =Financials!AA21 -> 36674
A24: Xcel Energy | B24: =Financials!AH5+Financials!AH6 -> 8204 | C24: =Financials!AH9 -> 1790 | D24: =Financials!AH3 -> 13441 | E24: =Financials!AH21 -> 19522

Sheet Calc
A1: Year | B1: Particulars | C1: Company | D1: Value | F1: Company | G1: Change in EBIT (historical) | H1: Change in CE | I1: Incremental ROCE (Historical) | J1: Change in EBIT (Forecast) | K1: Capex | L1: Depreciation | M1: Effective capital | N1: Raw ROCE | Q1: Particulars | R1: 2020 | S1: 2021 | T1: 2022 | U1: 2023 | V1: 2024 | Y1: Company | Z1: WACC | AA1: Terminal Growth | AB1: Cost of equity | AC1: Instrinsic Value | AD1: Share price | AE1: Upside/Downside
A2: 2020-24 | B2: Avg Capex | C2: =Relative!A20 -> NextEra Energy | D2: =AVERAGE(Financials!B26:F26) -> 8251.6 | F2: =C2 -> NextEra Energy | G2: =Financials!F5-Financials!B5 -> 4343 | H2: =(190144-25355)-(127684-15558) -> 52663 | I2: =G2/H2 -> 0.082467767 | J2: =DCF!G4-DCF!B4 -> 5645.2042 | K2: =D8 -> 11792.938 | L2: =AVERAGE(DCF!B6:G6) -> 6808.5652 | M2: =IF(K2-L2<=0,K2,MAX(K2-L2,0.1*K2)) -> 4984.3728 | N2: =J2/M2 -> 1.1325806 | Q2: Revenue | R2: {=Financials!B3:F3} -> 17997 | S2: 17069 | T2: 20956 | U2: 28114 | V2: 24753 | Y2: NextEra | Z2: =Assumptions!B22 -> 0.060679716 | AA2: =Assumptions!B23 -> 0.02 | AB2: =Assumptions!B13 -> 0.0785965 | AC2: =DCF!B20 -> 78.516883 | AD2: =DCF!B21 -> 84.7 | AE2: =(AC2-AD2)/AD2 -> -0.073000197
A3: 2020-24 | B3: Avg Capex | C3: =Relative!A21 -> Duke Energy | D3: =AVERAGE(Financials!I26:M26) -> 11174.6 | F3: =C3 -> Duke Energy | G3: =Financials!M5-Financials!I5 -> 4445 | H3: =(186343-17283)-(162388-16305) -> 22977 | I3: =G3/H3 -> 0.19345432 | J3: =DCF!O4-DCF!J4 -> 3576.1955 | K3: =D9 -> 14683.823 | L3: =AVERAGE(DCF!J6:O6) -> 6787.5198 | M3: =IF(K3-L3<=0,K3,MAX(K3-L3,0.1*K3)) -> 7896.3031 | N3: =J3/M3 -> 0.45289492 | Q3: Operating income | R3: {=Financials!B5:F5} -> 10524 | S3: 8561 | T3: 10139 | U3: 17976 | V3: 14867 | Y3: Duke | Z3: =Assumptions!C22 -> 0.048267195 | AA3: =Assumptions!C23 -> 0.02 | AB3: =Assumptions!C13 -> 0.0659587 | AC3: =DCF!J20 -> 72.814239 | AD3: =DCF!J21 -> 24.89 | AE3: =(AC3-AD3)/AD3 -> 1.9254415
A4: 2020-24 | B4: Avg Capex | C4: =Relative!A22 -> Dominion Energy | D4: =AVERAGE(Financials!P26:T26) -> 8396 | F4: =C4 -> Dominion Energy | G4: =Financials!T5-Financials!P5 -> 1294 | H4: =((Financials!T14-Financials!T18)-(Financials!P14-Financials!P18)) -> 8064 | I4: =G4/H4 -> 0.16046627 | J4: =Table96[[#This Row],[2030]]-Table96[[#This Row],[2025]] -> 119.53869 | K4: =D10 -> 5865.1124 | L4: =AVERAGE(DCF!R6:W6) -> 2484.2621 | M4: =IF(K4-L4<=0,K4,MAX(K4-L4,0.1*K4)) -> 3380.8503 | N4: =J4/M4 -> 0.035357581 | Q4: Net Income | R4: {=Financials!B9:F9} -> 4478 | S4: 3019 | T4: 4465 | U4: 7767 | V4: 6831
A5: 2020-24 | B5: Avg Capex | C5: =Relative!A23 -> Southern Company | D5: =AVERAGE(Financials!W26:AA26) -> 8200 | F5: =C5 -> Southern Company | G5: =Table1828[[#This Row],[2024]]-Table1828[[#This Row],[2020]] -> 3892 | H5: =((Financials!AA14-Financials!AA18)-(Financials!W14-Financials!W18)) -> 18331 | I5: =G5/H5 -> 0.21231793 | J5: =DCF!AE4-DCF!Z4 -> 3577.718 | K5: =D11 -> 10665.732 | L5: =AVERAGE(DCF!Z6:AE6) -> 5209.5599 | M5: =IF(K5-L5<=0,K5,MAX(K5-L5,0.1*K5)) -> 5456.1724 | N5: =J5/M5 -> 0.65571939
A6: 2020-24 | B6: Avg Capex | C6: =Relative!A24 -> Xcel Energy | D6: =AVERAGE(Financials!AD26:AH26) -> 5493.8 | F6: =C6 -> Xcel Energy | G6: =Financials!AH5-Financials!AD5 -> 1247 | H6: =((Financials!AH14-Financials!AH18)-(Financials!AD14-Financials!AD18)) -> 13858 | I6: =G6/H6 -> 0.089984125 | J6: =DCF!AM4-DCF!AH4 -> 819.4412 | K6: =D12 -> 6062.3434 | L6: =AVERAGE(Table9619[[#This Row],[2025]:[2030]]) -> 2576.4242 | M6: =IF(K6-L6<=0,K6,MAX(K6-L6,0.1*K6)) -> 3485.9192 | N6: =J6/M6 -> 0.23507177 | Q6: Particulars | R6: 2020 | S6: 2021 | T6: 2022 | U6: 2023 | V6: 2024
B7: Avg Capex | C7: Average | D7: =AVERAGE(D2:D6) -> 8303.2 | F7: =C7 -> Average | I7: =AVERAGE(I2:I6) -> 0.14773808 | N7: =AVERAGE(N2:N6) -> 0.50232486 | Q7: Revenue | R7: {=Financials!I3:M3} -> 23868 | S7: 25097 | T7: 28768 | U7: 29060 | V7: 30357
A8: 2025-30 | B8: Avg Capex | C8: =C2 -> NextEra Energy | D8: =AVERAGE(DCF!B7:G7) -> 11792.938 | Q8: Operating income | R8: {=Financials!I5:M5} -> 9248 | S8: 10350 | T8: 11076 | U8: 12271 | V8: 13693
A9: 2025-30 | B9: Avg Capex | C9: =C3 -> Duke Energy | D9: =AVERAGE(DCF!J7:O7) -> 14683.823 | Q9: Net Income | R9: {=Financials!I9:M9} -> 2145 | S9: 3272 | T9: 3251 | U9: 3566 | V9: 3926
A10: 2025-30 | B10: Avg Capex | C10: =C4 -> Dominion Energy | D10: =AVERAGE(DCF!R7:W7) -> 5865.1124
A11: 2025-30 | B11: Avg Capex | C11: =C5 -> Southern Company | D11: =AVERAGE(DCF!Z7:AE7) -> 10665.732 | G11: Metrics | H11: 2020-21 | I11: 2025-30 | Q11: Particulars | R11: 2025 | S11: 2026 | T11: 2027 | U11: 2028 | V11: 2029 | W11: 2030
A12: 2025-30 | B12: Avg Capex | C12: =C6 -> Xcel Energy | D12: =AVERAGE(DCF!AH7:AM7) -> 6062.3434 | G12: GDP | H12: =AVERAGE(-0.035,0.058) -> 0.0115 | I12: 0.02 | Q12: Revenue | R12: {=DCF!B3:G3} -> 26382.344 | S12: 28118.939 | T12: 29969.844 | U12: 31942.582 | V12: 34045.175 | W12: 36286.168
B13: Avg Capex | C13: =C7 -> Average | D13: =AVERAGE(D8:D12) -> 9813.9898 | G13: GDP | H13: 0.028 | I13: 0.023 | Q13: Operating income | R13: {=DCF!B4:G4} -> 15038.002 | S13: 16027.865 | T13: 17082.885 | U13: 18207.351 | V13: 19405.834 | W13: 20683.206
A14: 2025-30 | B14: Capex CAGR | C14: =C8 -> NextEra Energy | D14: =(DCF!G7/DCF!B7)^(1/6)-1 -> 0.054559984 | G14: Change | H14: =H13-H12 -> 0.0165 | I14: =I13-I12 -> 0.003 | Q14: Net Income | R14: {=DCF!B5:G5} -> 11579.261 | S14: 12341.456 | T14: 13153.822 | U14: 14019.66 | V14: 14942.492 | W14: 15926.069
A15: 2025-30 | B15: Capex CAGR | C15: =C9 -> Duke Energy | D15: =(DCF!O7/DCF!J7)^(1/6)-1 -> 0.040895514 | G15: Sensitivity | H15: =D61/H14 -> 29.435967 | I15: =D67/I14 -> 76.345353 | Q15: FCFE | R15: {=DCF!B9:G9} -> 7405.8959 | S15: 8724.0609 | T15: 9298.3146 | U15: 9910.368 | V15: 10562.709 | W15: 11257.99
A16: 2025-30 | B16: Capex CAGR | C16: =C10 -> Dominion Energy | D16: =(DCF!W7/DCF!R7)^(1/6)-1 -> 0.0033322239
A17: 2025-30 | B17: Capex CAGR | C17: =C11 -> Southern Company | D17: =(DCF!AE7/DCF!Z7)^(1/6)-1 -> 0.046246394 | Q17: Particulars | R17: 2025 | S17: 2026 | T17: 2027 | U17: 2028 | V17: 2029 | W17: 2030
A18: 2025-30 | B18: Capex CAGR | C18: =C12 -> Xcel Energy | D18: =(DCF!AM7/DCF!AH7)^(1/6)-1 -> 0.025948343 | Q18: Revenue | R18: {=DCF!J3:O3} -> 31852.785 | S18: 33422.273 | T18: 35069.094 | U18: 36797.059 | V18: 38610.166 | W18: 40512.611
A19: 2025-30 | B19: Capex CAGR | C19: =C13 -> Average | D19: =AVERAGE(D14:D18) -> 0.034196492 | Q19: Operating income | R19: {=DCF!J4:O4} -> 13154.051 | S19: 13802.192 | T19: 14482.27 | U19: 15195.857 | V19: 15944.605 | W19: 16730.246
A20: =A14 -> 2025-30 | B20: Earnings CAGR | C20: =C14 -> NextEra Energy | D20: =Calc!D14 -> 0.054559984 | Q20: Net Income | R20: {=DCF!J5:O5} -> 10128.619 | S20: 10627.688 | T20: 11151.348 | U20: 11700.81 | V20: 12277.346 | W20: 12882.29
A21: =A15 -> 2025-30 | B21: Earnings CAGR | C21: =C15 -> Duke Energy | D21: =Calc!D15 -> 0.040895514 | Q21: FCFE | R21: {=DCF!J9:O9} -> 3754.1337 | S21: 3651.1729 | T21: 3831.0778 | U21: 4019.8471 | V21: 4217.9176 | W21: 4425.7478
A22: =A16 -> 2025-30 | B22: Earnings CAGR | C22: =C16 -> Dominion Energy | D22: =Calc!D16 -> 0.0033322239
A23: =A17 -> 2025-30 | B23: Earnings CAGR | C23: =C17 -> Southern Company | D23: =Calc!D17 -> 0.046246394
A24: =A18 -> 2025-30 | B24: Earnings CAGR | C24: =C18 -> Xcel Energy | D24: =Calc!D18 -> 0.025948343
A25: =A19 -> 2025-30 | B25: Earnings CAGR | C25: =C19 -> Average | D25: =AVERAGE(D20:D24) -> 0.034196492
A26: =A20 -> 2025-30 | B26: Revenue CAGR | C26: =C20 -> NextEra Energy | D26: =D20 -> 0.054559984
A27: =A21 -> 2025-30 | B27: Revenue CAGR | C27: =C21 -> Duke Energy | D27: =D21 -> 0.040895514
A28: =A22 -> 2025-30 | B28: Revenue CAGR | C28: =C22 -> Dominion Energy | D28: =D22 -> 0.0033322239
A29: =A23 -> 2025-30 | B29: Revenue CAGR | C29: =C23 -> Southern Company | D29: =D23 -> 0.046246394
A30: =A24 -> 2025-30 | B30: Revenue CAGR | C30: =C24 -> Xcel Energy | D30: =D24 -> 0.025948343
A31: =A25 -> 2025-30 | B31: Revenue CAGR | C31: =C25 -> Average | D31: =AVERAGE(D26:D30) -> 0.034196492
A32: =A2 -> 2020-24 | B32: EBITDA Margin | C32: =C26 -> NextEra Energy | D32: =(AVERAGE(Financials!B5:F5)+AVERAGE(Financials!B6:F6))/AVERAGE(Financials!B3:F3) -> 0.78875736
A33: =A3 -> 2020-24 | B33: EBITDA Margin | C33: =C27 -> Duke Energy | D33: =(AVERAGE(Financials!I5:M5)+AVERAGE(Financials!I6:M6))/AVERAGE(Financials!I3:M3) -> 0.60127598
A34: =A4 -> 2020-24 | B34: EBITDA Margin | C34: =C28 -> Dominion Energy | D34: =(AVERAGE(Financials!P5:T5)+AVERAGE(Financials!P6:T6))/AVERAGE(Financials!P3:T3) -> 0.57787007
A35: =A5 -> 2020-24 | B35: EBITDA Margin | C35: =C29 -> Southern Company | D35: =(AVERAGE(Financials!W5:AA5)+AVERAGE(Financials!W6:AA6))/AVERAGE(Financials!W3:AA3) -> 0.5674822
A36: =A6 -> 2020-24 | B36: EBITDA Margin | C36: =C30 -> Xcel Energy | D36: =(AVERAGE(Financials!AD5:AH5)+AVERAGE(Financials!AD6:AH6))/AVERAGE(Financials!AD3:AH3) -> 0.52772624
A37: =$A$36 -> 2020-24 | B37: EBITDA Margin | C37: =C31 -> Average | D37: =AVERAGE(D32:D36) -> 0.61262237
A38: =$A$36 -> 2020-24 | B38: NPM | C38: =C32 -> NextEra Energy | D38: =AVERAGE(Financials!B9:F9)/AVERAGE(Financials!B3:F3) -> 0.24391812
A39: =$A$36 -> 2020-24 | B39: NPM | C39: =C33 -> Duke Energy | D39: =AVERAGE(Financials!I9:M9)/AVERAGE(Financials!I3:M3) -> 0.1178272
A40: =A32 -> 2020-24 | B40: NPM | C40: =C34 -> Dominion Energy | D40: =AVERAGE(Financials!P9:T9)/AVERAGE(Financials!P3:T3) -> 0.12157169
...
