Workbook

Sheet Company Profile
A1: Company | B1: #VALUE! | C1: #VALUE! | D1: #VALUE! | E1: #VALUE! | F1: #VALUE! | G1: #VALUE! | H1: #VALUE!
A2: Official Name | B2: {=_FV(B1,"Official name",TRUE)} -> JPMORGAN CHASE & CO. | C2: {=_FV(C1,"Official name",TRUE)} -> BANK OF AMERICA CORPORATION | D2: {=_FV(D1,"Official name",TRUE)} -> AMERICAN EXPRESS COMPANY | E2: {=_FV(E1,"Official name",TRUE)} -> BLACKROCK, INC. | F2: {=_FV(F1,"Official name",TRUE)} -> THE GOLDMAN SACHS GROUP, INC. | G2: {=_FV(G1,"Official name",TRUE)} -> MORGAN STANLEY | H2: {=_FV(H1,"Official name",TRUE)} -> WELLS FARGO & COMPANY
A3: Beta | B3: {=_FV(B1,"Beta")} -> 1.0811 | C3: {=_FV(C1,"Beta")} -> 1.3076 | D3: {=_FV(D1,"Beta")} -> 1.1574 | E3: {=_FV(E1,"Beta")} -> 1.4867 | F3: {=_FV(F1,"Beta")} -> 1.3514 | G3: {=_FV(G1,"Beta")} -> 1.2205 | H3: {=_FV(H1,"Beta")} -> 1.1136
A4: P/E | B4: {=_FV(B1,"P/E",TRUE)} -> 14.8154 | C4: {=_FV(C1,"P/E",TRUE)} -> 14.0965 | D4: {=_FV(D1,"P/E",TRUE)} -> 22.493 | E4: {=_FV(E1,"P/E",TRUE)} -> 26.4055 | F4: {=_FV(F1,"P/E",TRUE)} -> 15.7791 | G4: {=_FV(G1,"P/E",TRUE)} -> 16.3343 | H4: {=_FV(H1,"P/E",TRUE)} -> 13.8068
A5: Share Price | B5: {=_FV(B1,"Price")} -> 299.12 | C5: {=_FV(C1,"Price")} -> 51.5465 | D5: {=_FV(D1,"Price")} -> 335.078 | E5: {=_FV(E1,"Price")} -> 1016.08 | F5: {=_FV(F1,"Price")} -> 776.76 | G5: {=_FV(G1,"Price")} -> 159.17 | H5: {=_FV(H1,"Price")} -> 83.93
A6: Market Cap | B6: {=_FV(B1,"Market cap",TRUE)} -> 822506416480 | C6: {=_FV(C1,"Market cap",TRUE)} -> 376418110064 | D6: {=_FV(D1,"Market cap",TRUE)} -> 230819016424 | E6: {=_FV(E1,"Market cap",TRUE)} -> 157645726472 | F6: {=_FV(F1,"Market cap",TRUE)} -> 232972461660 | G6: {=_FV(G1,"Market cap",TRUE)} -> 253239469999 | H6: {=_FV(H1,"Market cap",TRUE)} -> 263463320120
A7: in millions | B7: =B6/1000000 -> 822506.42 | C7: =C6/1000000 -> 376418.11 | D7: =D6/1000000 -> 230819.02 | E7: =E6/1000000 -> 157645.73 | F7: =F6/1000000 -> 232972.46 | G7: =G6/1000000 -> 253239.47 | H7: =H6/1000000 -> 263463.32
A8: Shares Outstanding | B8: {=_FV(B1,"Shares outstanding",TRUE)} -> 2749754000 | C8: {=_FV(C1,"Shares outstanding",TRUE)} -> 7302496000 | D8: {=_FV(D1,"Shares outstanding",TRUE)} -> 688851600 | E8: {=_FV(E1,"Shares outstanding",TRUE)} -> 155150900 | F8: {=_FV(F1,"Shares outstanding",TRUE)} -> 299928500 | G8: {=_FV(G1,"Shares outstanding",TRUE)} -> 1591000000 | H8: {=_FV(H1,"Shares outstanding",TRUE)} -> 3139084000
A9: in millions | B9: =B8/1000000 -> 2749.754 | C9: =C8/1000000 -> 7302.496 | D9: =D8/1000000 -> 688.8516 | E9: =E8/1000000 -> 155.1509 | F9: =F8/1000000 -> 299.9285 | G9: =G8/1000000 -> 1591 | H9: =H8/1000000 -> 3139.084
A10: Change (%) | B10: {=_FV(B1,"Change (%)",TRUE)} -> -0.004162 | C10: {=_FV(C1,"Change (%)",TRUE)} -> 0.001292 | D10: {=_FV(D1,"Change (%)",TRUE)} -> -0.018086 | E10: {=_FV(E1,"Change (%)",TRUE)} -> -0.007541 | F10: {=_FV(F1,"Change (%)",TRUE)} -> 0.001547 | G10: {=_FV(G1,"Change (%)",TRUE)} -> -0.001756 | H10: {=_FV(H1,"Change (%)",TRUE)} -> 0.006114
A11: Year | B11: {=_FV(B1,"Year incorporated",TRUE)} -> 1968 | C11: {=_FV(C1,"Year incorporated",TRUE)} -> 1998 | D11: {=_FV(D1,"Year incorporated",TRUE)} -> 1965 | E11: {=_FV(E1,"Year incorporated",TRUE)} -> 2024 | F11: {=_FV(F1,"Year incorporated",TRUE)} -> 1998 | G11: {=_FV(G1,"Year incorporated",TRUE)} -> 1981 | H11: {=_FV(H1,"Year incorporated",TRUE)} -> 1929

Sheet Financials
A2: Income Statement | F2: JPMC | H2: Income Statement | M2: BOA | O2: Income Statement | T2: Amex | V2: Income Statement | AA2: Blackrock | AC2: Income Statement | AH2: Goldman Sachs | AJ2: Income Statement | AO2: Morgan Stanley | AQ2: Income Statement | AV2: Wells Fargo
A3: Particulars | B3: 2020 | C3: 2021 | D3: 2022 | E3: 2023 | F3: 2024 | H3: Particulars | I3: 2020 | J3: 2021 | K3: 2022 | L3: 2023 | M3: 2024 | O3: Particulars | P3: 2020 | Q3: 2021 | R3: 2022 | S3: 2023 | T3: 2024 | V3: Particulars | W3: 2020 | X3: 2021 | Y3: 2022 | Z3: 2023 | AA3: 2024 | AC3: Particulars | AD3: 2020 | AE3: 2021 | AF3: 2022 | AG3: 2023 | AH3: 2024 | AJ3: Particulars | AK3: 2020 | AL3: 2021 | AM3: 2022 | AN3: 2023 | AO3: 2024 | AQ3: Particulars | AR3: 2020 | AS3: 2021 | AT3: 2022 | AU3: 2023 | AV3: 2024
A4: Net Interest Income | B4: 54563 | C4: 52311 | D4: 66710 | E4: 89267 | F4: 92583 | H4: Net Interest Income | I4: 43360 | J4: 42934 | K4: 52462 | L4: 56931 | M4: 56060 | O4: Net Interest Income | P4: 7985 | Q4: 7750 | R4: 9895 | S4: 13134 | T4: 15543 | V4: Revenue | W4: 16205 | X4: 19374 | Y4: 17873 | Z4: 17859 | AA4: 20407 | AC4: Net Interest Income | AD4: 4751 | AE4: 6470 | AF4: 7678 | AG4: 6351 | AH4: 8056 | AJ4: Net Interest Income | AK4: 6313 | AL4: 8045 | AM4: 9327 | AN4: 8230 | AO4: 8611 | AQ4: Net Interest Income | AR4: 39956 | AS4: 35779 | AT4: 44950 | AU4: 52375 | AV4: 47676 | AX4: 2020 | AY4: 2021 | AZ4: 2022 | BA4: 2023 | BB4: 2024
A5: Non-interest income | B5: 65388 | C5: 69338 | D5: 61985 | E5: 68837 | F5: 84973 | H5: Non-interest income | I5: 42168 | J5: 46179 | K5: 42488 | L5: 41650 | M5: 45827 | O5: Non-interest income | P5: 28102 | Q5: 34630 | R5: 42967 | S5: 47381 | T5: 50406 | V5: Operating expenses | W5: =10510-106 -> 10404 | X5: =11924-147 -> 11777 | Y5: =11488-151 -> 11337 | Z5: =11584-151 -> 11433 | AA5: =12833-291 -> 12542 | AC5: Non-interest income | AD5: 39809 | AE5: 52869 | AF5: 39687 | AG5: 39903 | AH5: 45456 | AJ5: Non-interest income | AK5: 41885 | AL5: 51710 | AM5: 44341 | AN5: 45913 | AO5: 53150 | AQ5: Non-interest income | AR5: 34345 | AS5: 43387 | AT5: 29418 | AU5: 30222 | AV5: 34620 | AX5: {=B6:F6} -> 119951 | AY5: 121649 | AZ5: 128695 | BA5: 158104 | BB5: 177556
A6: Total net revenue | B6: =B4+B5 -> 119951 | C6: =C4+C5 -> 121649 | D6: =D4+D5 -> 128695 | E6: =E4+E5 -> 158104 | F6: =F4+F5 -> 177556 | H6: Total net revenue | I6: =I4+I5 -> 85528 | J6: =J4+J5 -> 89113 | K6: =K4+K5 -> 94950 | L6: =L4+L5 -> 98581 | M6: =M4+M5 -> 101887 | O6: Total net revenue | P6: =P4+P5 -> 36087 | Q6: =Q4+Q5 -> 42380 | R6: =R4+R5 -> 52862 | S6: =S4+S5 -> 60515 | T6: =T4+T5 -> 65949 | V6: Operating income (EBIT) | W6: =W4-W5 -> 5801 | X6: =X4-X5 -> 7597 | Y6: =Y4-Y5 -> 6536 | Z6: =Z4-Z5 -> 6426 | AA6: =AA4-AA5 -> 7865 | AC6: Total net revenue | AD6: =AD4+AD5 -> 44560 | AE6: =AE4+AE5 -> 59339 | AF6: =AF4+AF5 -> 47365 | AG6: =AG4+AG5 -> 46254 | AH6: =AH4+AH5 -> 53512 | AJ6: Total net revenue | AK6: =AK4+AK5 -> 48198 | AL6: =AL4+AL5 -> 59755 | AM6: =AM4+AM5 -> 53668 | AN6: =AN4+AN5 -> 54143 | AO6: =AO4+AO5 -> 61761 | AQ6: Total net revenue | AR6: =AR4+AR5 -> 74301 | AS6: =AS4+AS5 -> 79166 | AT6: =AT4+AT5 -> 74368 | AU6: =AU4+AU5 -> 82597 | AV6: =AV4+AV5 -> 82296 | AX6: {=B8:F8} -> 53295 | AY6: 50306 | AZ6: 52555 | BA6: 70932 | BB6: 85759
A7: Non-interest expense | B7: 66656 | C7: 71343 | D7: 76140 | E7: 87172 | F7: 91797 | H7: Non-interest expense | I7: 55213 | J7: 59731 | K7: 61438 | L7: 65845 | M7: 66812 | O7: Non-interest expense | P7: 27061 | Q7: 33110 | R7: 41095 | S7: 45079 | T7: 47869 | V7: Depreciation | W7: 106 | X7: 147 | Y7: 151 | Z7: 151 | AA7: 291 | AC7: Non-interest expense | AD7: 28983 | AE7: 31938 | AF7: 31164 | AG7: 34487 | AH7: 33767 | AJ7: Non-interest expense | AK7: 33780 | AL7: 40083 | AM7: 39299 | AN7: 41798 | AO7: 43901 | AQ7: Non-interest expense | AR7: 56131 | AS7: 53341 | AT7: 53897 | AU7: 53483 | AV7: 54065 | AX7: {=B11:F11} -> 28789.46 | AY7: 48364.344 | AZ7: 37486.792 | BA7: 50028.944 | BB7: 60965.772
A8: Operating Income | B8: =B6-B7 -> 53295 | C8: =C6-C7 -> 50306 | D8: =D6-D7 -> 52555 | E8: =E6-E7 -> 70932 | F8: =F6-F7 -> 85759 | H8: Operating Income | I8: =I6-I7 -> 30315 | J8: =J6-J7 -> 29382 | K8: =K6-K7 -> 33512 | L8: =L6-L7 -> 32736 | M8: =M6-M7 -> 35075 | O8: Operating Income | P8: =P6-P7 -> 9026 | Q8: =Q6-Q7 -> 9270 | R8: =R6-R7 -> 11767 | S8: =S6-S7 -> 15436 | T8: =T6-T7 -> 18080 | V8: Interest expense | W8: 205 | X8: 205 | Y8: 212 | Z8: 292 | AA8: 538 | AC8: Operating Income | AD8: =AD6-AD7 -> 15577 | AE8: =AE6-AE7 -> 27401 | AF8: =AF6-AF7 -> 16201 | AG8: =AG6-AG7 -> 11767 | AH8: =AH6-AH7 -> 19745 | AJ8: Operating Income | AK8: =AK6-AK7 -> 14418 | AL8: =AL6-AL7 -> 19672 | AM8: =AM6-AM7 -> 14369 | AN8: =AN6-AN7 -> 12345 | AO8: =AO6-AO7 -> 17860 | AQ8: Operating Income | AR8: =AR6-AR7 -> 18170 | AS8: =AS6-AS7 -> 25825 | AT8: =AT6-AT7 -> 20471 | AU8: =AU6-AU7 -> 29114 | AV8: =AV6-AV7 -> 28231 | AX8: {=B15:F15} -> 984525 | AY8: 1061328 | AZ8: 1115921 | BA8: 1301286 | BB8: 1323643
A9: Provision for credit losses | B9: 17840 | C9: -9256 | D9: 6389 | E9: 9320 | F9: 10678 | H9: Provision for credit losses | I9: 11320 | J9: -4594 | K9: 2543 | L9: 4394 | M9: 5821 | O9: Provision for credit losses | P9: 4730 | Q9: -1419 | R9: 2182 | S9: 4923 | T9: 5185 | V9: Interest income | W9: =972+62 -> 1034 | X9: =841+87 -> 928 | Y9: =-35+152 -> 117 | Z9: =699+473 -> 1172 | AA9: =492+767 -> 1259 | AC9: Provision for credit losses | AD9: 3098 | AE9: 357 | AF9: 2715 | AG9: 1028 | AH9: 1348 | AJ9: Provision for credit losses | AK9: 761 | AL9: 4 | AM9: 280 | AN9: 532 | AO9: 264 | AQ9: Provision for credit losses | AR9: 14129 | AS9: -4155 | AT9: 1534 | AU9: 5399 | AV9: 4334
A10: Pre-tax income | B10: =B8-B9 -> 35455 | C10: =C8-C9 -> 59562 | D10: =D8-D9 -> 46166 | E10: =E8-E9 -> 61612 | F10: =F8-F9 -> 75081 | H10: Pre-tax income | I10: =I8-I9 -> 18995 | J10: =J8-J9 -> 33976 | K10: =K8-K9 -> 30969 | L10: =L8-L9 -> 28342 | M10: =M8-M9 -> 29254 | O10: Pre-tax income | P10: =P8-P9 -> 4296 | Q10: =Q8-Q9 -> 10689 | R10: =R8-R9 -> 9585 | S10: =S8-S9 -> 10513 | T10: =T8-T9 -> 12895 | V10: Income tax | W10: 1238 | X10: 1968 | Y10: 1296 | Z10: 1479 | AA10: 1783 | AC10: Pre-tax income | AD10: =AD8-AD9 -> 12479 | AE10: =AE8-AE9 -> 27044 | AF10: =AF8-AF9 -> 13486 | AG10: =AG8-AG9 -> 10739 | AH10: =AH8-AH9 -> 18397 | AJ10: Pre-tax income | AK10: =AK8-AK9 -> 13657 | AL10: =AL8-AL9 -> 19668 | AM10: =AM8-AM9 -> 14089 | AN10: =AN8-AN9 -> 11813 | AO10: =AO8-AO9 -> 17596 | AQ10: Pre-tax income | AR10: =AR8-AR9 -> 4041 | AS10: =AS8-AS9 -> 29980 | AT10: =AT8-AT9 -> 18937 | AU10: =AU8-AU9 -> 23715 | AV10: =AV8-AV9 -> 23897 | AX10: 2020 | AY10: 2021 | AZ10: 2022 | BA10: 2023 | BB10: 2024
A11: Net Income | B11: =B10*(1-0.188) -> 28789.46 | C11: =C10*(1-0.188) -> 48364.344 | D11: =D10*(1-0.188) -> 37486.792 | E11: =E10*(1-0.188) -> 50028.944 | F11: =F10*(1-0.188) -> 60965.772 | H11: Net Income | I11: 17894 | J11: 31978 | K11: 27528 | L11: 26515 | M11: 27132 | O11: Net Income | P11: =P10*(1-0.2703) -> 3134.7912 | Q11: =Q10*(1-0.188) -> 8679.468 | R11: =R10*(1-0.188) -> 7783.02 | S11: =S10*(1-0.188) -> 8536.556 | T11: =T10*(1-0.188) -> 10470.74 | V11: Net income | W11: =W6-W7-W8-W10+W9 -> 5286 | X11: =X6-X7-X8-X10+X9 -> 6205 | Y11: =Y6-Y7-Y8-Y10+Y9 -> 4994 | Z11: =Z6-Z7-Z8-Z10+Z9 -> 5676 | AA11: =AA6-AA7-AA8-AA10+AA9 -> 6512 | AC11: Net Income | AD11: =AD10*(1-0.242) -> 9459.082 | AE11: =AE10*(1-0.188) -> 21959.728 | AF11: =AF10*(1-0.188) -> 10950.632 | AG11: =AG10*(1-0.188) -> 8720.068 | AH11: =AH10*(1-0.188) -> 14938.364 | AJ11: Net Income | AK11: =AK10*(1-0.2246) -> 10589.638 | AL11: =AL10*(1-0.2246) -> 15250.567 | AM11: =AM10*(1-0.2246) -> 10924.611 | AN11: =AN10*(1-0.2246) -> 9159.8002 | AO11: =AO10*(1-0.2246) -> 13643.938 | AQ11: Net Income | AR11: 3377 | AS11: 20818 | AT11: 13677 | AU11: 19142 | AV11: 19722 | AX11: {=I6:M6} -> 85528 | AY11: 89113 | AZ11: 94950 | BA11: 98581 | BB11: 101887
AX12: {=I8:M8} -> 30315 | AY12: 29382 | AZ12: 33512 | BA12: 32736 | BB12: 35075
A13: Balance Sheet | H13: Balance Sheet | O13: Balance Sheet | V13: Balance Sheet | AC13: Balance Sheet | AJ13: Balance Sheet | AQ13: Balance Sheet | AX13: {=I11:M11} -> 17894 | AY13: 31978 | AZ13: 27528 | BA13: 26515 | BB13: 27132
A14: Particulars | B14: 2020 | C14: 2021 | D14: 2022 | E14: 2023 | F14: 2024 | H14: Particulars | I14: 2020 | J14: 2021 | K14: 2022 | L14: 2023 | M14: 2024 | O14: Particulars | P14: 2020 | Q14: 2021 | R14: 2022 | S14: 2023 | T14: 2024 | V14: Particulars | W14: 2020 | X14: 2021 | Y14: 2022 | Z14: 2023 | AA14: 2024 | AC14: Particulars | AD14: 2020 | AE14: 2021 | AF14: 2022 | AG14: 2023 | AH14: 2024 | AJ14: Particulars | AK14: 2020 | AL14: 2021 | AM14: 2022 | AN14: 2023 | AO14: 2024 | AQ14: Particulars | AR14: 2020 | AS14: 2021 | AT14: 2022 | AU14: 2023 | AV14: 2024 | AX14: {=I15:M15} -> 982467 | AY14: 920401 | AZ14: 1016782 | BA14: 1046256 | BB14: 1060081
A15: Total Loans & Leases | B15: 984525 | C15: 1061328 | D15: 1115921 | E15: 1301286 | F15: 1323643 | H15: Total Loans & Leases | I15: 982467 | J15: 920401 | K15: 1016782 | L15: 1046256 | M15: 1060081 | O15: Total Loans & Leases | P15: =43434+68029+2614 -> 114077 | Q15: =53581+85257+2859 -> 141697 | R15: =57384+104217+5357 -> 166958 | S15: =60237+120877 -> 181114 | T15: =59240+133995+758 -> 193993 | V15: Total Assets | W15: 176982 | X15: 152648 | Y15: 117628 | Z15: 123211 | AA15: 138615 | AC15: Total Loans & Leases | AD15: 116115 | AE15: 158562 | AF15: 179286 | AG15: 183358 | AH15: 196200 | AJ15: Total Loans & Leases | AK15: =137784+12813 -> 150597 | AL15: =174302+13832 -> 188134 | AM15: =198997+14788 -> 213785 | AN15: =203385+15255 -> 218640 | AO15: =225834+12319 -> 238153 | AQ15: Total Loans & Leases | AR15: 949868 | AS15: 911162 | AT15: 964779 | AU15: 963272 | AV15: 965429
A16: Total deposits | B16: 2144257 | C16: 2462303 | D16: 2340179 | E16: 2400688 | F16: 2406032 | H16: Total deposits | I16: 1632998 | J16: 1914286 | K16: 1986158 | L16: 1887541 | M16: 1924106 | O16: Total deposits | P16: 86875 | Q16: 84382 | R16: 110239 | S16: 129144 | T16: 139413 | V16: Total current liabilities | W16: =2499+1028 -> 3527 | X16: =2951+1397 -> 4348 | Y16: =2272+1294 -> 3566 | Z16: =2393+1240 -> 3633 | AA16: =2964+1536 -> 4500 | AC16: Total deposits | AD16: 259962 | AE16: 364227 | AF16: 386665 | AG16: 428417 | AH16: 433013 | AJ16: Total deposits | AK16: 310782 | AL16: 347574 | AM16: 356646 | AN16: 351804 | AO16: 376007 | AQ16: Total deposits | AR16: 1397062 | AS16: 1463934 | AT16: 1442249 | AU16: 1426215 | AV16: 1418562 | AX16: 2025 | AY16: 2026 | AZ16: 2027 | BA16: 2028 | BB16: 2029 | BC16: 2030
A17: Total assets | B17: 3386071 | C17: 3743567 | D17: 3665743 | E17: 3875393 | F17: 4002814 | H17: Total assets | I17: 2683122 | J17: 3034623 | K17: 3135894 | L17: 3153513 | M17: 3284228 | O17: Total assets | P17: 191367 | Q17: 188548 | R17: 228354 | S17: 261108 | T17: 271461 | V17: Total current assets | W17: =8664+3535 -> 12199 | X17: =9323+3789 -> 13112 | Y17: =7416+3264 -> 10680 | Z17: =8736+3916 -> 12652 | AA17: =12762+4304 -> 17066 | AC17: Total assets | AD17: 1163028 | AE17: 1463988 | AF17: 1441799 | AG17: 1641594 | AH17: 1675972 | AJ17: Total assets | AK17: 1115862 | AL17: 1188140 | AM17: 1180231 | AN17: 1193693 | AO17: 1215071 | AQ17: Total assets | AR17: 1955163 | AS17: 1948674 | AT17: 1880591 | AU17: 1877490 | AV17: 1874567 | AX17: {=DCF!B6:G6} -> 182856.89 | AY17: 193364.59 | AZ17: 204478.48 | BA17: 216233.64 | BB17: 228667.23 | BC17: 241818.55
A18: Risk-weighted assets | B18: 1560609 | C18: 1638900 | D18: 1653538 | E18: 1671995 | F18: 1757460 | H18: Risk-weighted assets | I18: 1480000 | J18: 1618000 | K18: 1411000 | L18: 1459000 | M18: 1490000 | O18: Risk-weighted assets | P18: 138300 | Q18: 79195.66 | R18: 194400 | S18: 93782.977 | T18: 235800 | V18: Cash & cash equivalents | W18: 8664 | X18: 9323 | Y18: 7416 | Z18: 8736 | AA18: 12762 | AC18: Risk-weighted assets | AD18: 252355 | AE18: 269762 | AF18: 247653 | AG18: 16546 | AH18: 17767 | AJ18: Risk-weighted assets | AK18: 453106 | AL18: 471921 | AM18: 447849 | AN18: 456053 | AO18: 471834 | AQ18: Risk-weighted assets | AR18: 1088653 | AS18: 1081252 | AT18: 1063146 | AU18: 1072028 | AV18: 1074031 | AX18: {=DCF!B11:G11} -> 56586.482 | AY18: 59814.872 | AZ18: 63228.173 | BA18: 66837.019 | BB18: 70652.656 | BC18: 74686.979
A19: CET1 Capital | B19: 205078 | C19: 213942 | D19: 218934 | E19: 250585 | F19: 275513 | H19: CET1 Capital | I19: 176660 | J19: 171759 | K19: 180060 | L19: 194928 | M19: 201083 | O19: CET1 Capital | P19: 18700 | Q19: 11250 | R19: 20000 | S19: 10040 | T19: 24900 | V19: Accounts receivables | W19: 3535 | X19: 3789 | Y19: 3264 | Z19: 3916 | AA19: 4304 | AC19: CET1 Capital | AD19: 26394 | AE19: 28810 | AF19: 31780 | AG19: 3936 | AH19: 4336 | AJ19: CET1 Capital | AK19: 78650 | AL19: 75742 | AM19: 68670 | AN19: 69448 | AO19: 75095 | AQ19: CET1 Capital | AR19: 135112 | AS19: 139256 | AT19: 141452 | AU19: 142341 | AV19: 144055 | AX19: {=DCF!B13:G13} -> 45337.917 | AY19: 47924.55 | AZ19: 50659.337 | BA19: 53550.797 | BB19: 56607.941 | BC19: 59840.3
A20: Total Equity | B20: 279354 | C20: 294127 | D20: 292332 | E20: 327878 | F20: 344758 | H20: Total Equity | I20: 267309 | J20: 273757 | K20: 270299 | L20: 283353 | M20: 294014 | O20: Total Equity | P20: 22984 | Q20: 22177 | R20: 24711 | S20: 28057 | T20: 30264 | V20: Accounts payables | W20: 1028 | X20: 1397 | Y20: 1294 | Z20: 1240 | AA20: 1536 | AC20: Total Equity | AD20: 95932 | AE20: 109926 | AF20: 117189 | AG20: 116905 | AH20: 121996 | AJ20: Total Equity | AK20: 103149 | AL20: 106598 | AM20: 101231 | AN20: 99982 | AO20: 105428 | AQ20: Total Equity | AR20: 160724 | AS20: 163595 | AT20: 168241 | AU20: 169308 | AV20: 168900
A21: Shares Outstanding (in mn) | B21: 3082.4 | C21: 3021.5 | D21: 2965.8 | E21: 2938.6 | F21: 2873.9 | H21: Shares Outstanding (in mn) | I21: 8720 | J21: 8100 | K21: 8080 | L21: 8020 | M21: 7673 | O21: Shares Outstanding (in mn) | P21: 800 | Q21: 792 | R21: 763 | S21: 723 | T21: 702 | V21: PPE | W21: 681 | X21: 762 | Y21: 1031 | Z21: 1112 | AA21: 1103 | AC21: Shares Outstanding (in mn) | AD21: 344.09 | AE21: 333.57 | AF21: 323.38 | AG21: 310.65 | AH21: 308.8 | AJ21: Shares Outstanding (in mn) | AK21: 1770 | AL21: 1750 | AM21: 1690 | AN21: 1640 | AO21: 1610 | AQ21: Shares Outstanding (in mn) | AR21: 4062 | AS21: 3805 | AT21: 3688 | AU21: 3426 | AV21: 3302 | AX21: 2025 | AY21: 2026 | AZ21: 2027 | BA21: 2028 | BB21: 2029 | BC21: 2030
A22: Investments | B22: 2050638 | C22: 2293452 | D22: 2121132 | E22: 2189658 | F22: 2265700 | H22: Investments | I22: 1606972 | J22: 1870965 | K22: 1690101 | L22: 1788901 | M22: 1828150 | O22: Investments | P22: =157+21631 -> 21788 | Q22: =2591+188 -> 2779 | R22: =4578+307 -> 4885 | S22: =166+2186 -> 2352 | T22: =221+1240 -> 1461 | V22: Total debt | W22: 7264 | X22: 7446 | Y22: 6654 | Z22: 7918 | AA22: 12314 | AC22: Investments | AD22: 88445 | AE22: 88719 | AF22: 130629 | AG22: =49141+70310+27358 -> 146809 | AH22: =79458+78713+26343 -> 184514 | AJ22: Investments | AK22: 182154 | AL22: 182998 | AM22: 159931 | AN22: =88113+66694 -> 154807 | AO22: =98608+61071 -> 159679 | AQ22: Investments | AR22: 477200 | AS22: 501022 | AT22: 455357 | AU22: 422983 | AV22: 420251 | AX22: {=DCF!J6:O6} -> 100508.15 | AY22: 102116.2 | AZ22: 103750.03 | BA22: 105410.06 | BB22: 107096.7 | BC22: 108810.38
A23: Non-Performing Assets | B23: 6421 | C23: 4497 | D23: 5343 | E23: 8420 | F23: 9140 | H23: NPA | I23: 5116 | J23: 4697 | K23: 3978 | L23: 5630 | M23: 6120 | O23: GNPA | P23: 1560 | Q23: 2533 | R23: 2815 | S23: 3212 | T23: 2891 | V23: Shareholder's equity | W23: 35334 | X23: 37806 | Y23: 37876 | Z23: 39500 | AA23: 47664 | AJ23: NPA | AK23: 0 | AL23: 0 | AM23: 0 | AN23: 0 | AO23: 0 | AQ23: NPA | AR23: 9047 | AS23: 7550 | AT23: 7900 | AU23: 6612 | AV23: 6140 | AX23: {=DCF!J11:O11} -> 23600.309 | AY23: 23980.096 | AZ23: 24366.007 | BA23: 24758.142 | BB23: 25156.6 | BC23: 25561.484
O24: NNPA | P24: 492 | Q24: 638 | R24: 732 | S24: 1353 | T24: 432 | V24: Shares outstanding | W24: 152.8 | X24: 152 | Y24: 151.2 | Z24: 149.9 | AA24: 149.2 | AX24: {=DCF!J13:O13} -> 18641.609 | AY24: 18941.598 | AZ24: 19246.425 | BA24: 19556.168 | BB24: 19870.905 | BC24: 20190.719
A26: Cash Flow | H26: Cash Flow | O26: Cash Flow | V26: Cash Flow | AC26: Cash Flow | AJ26: Cash Flow | AQ26: Cash Flow | AX26: Cost of equity | AY26: Terminal Growth | AZ26: Intrinsic Value | BA26: Share price | BB26: Upside/Downside
A27: Particulars | B27: 2020 | C27: 2021 | D27: 2022 | E27: 2023 | F27: 2024 | H27: Particulars | I27: 2020 | J27: 2021 | K27: 2022 | L27: 2023 | M27: 2024 | O27: Particulars | P27: 2020 | Q27: 2021 | R27: 2022 | S27: 2023 | T27: 2024 | V27: Particulars | W27: 2020 | X27: 2021 | Y27: 2022 | Z27: 2023 | AA27: 2024 | AC27: Particulars | AD27: 2020 | AE27: 2021 | AF27: 2022 | AG27: 2023 | AH27: 2024 | AJ27: Particulars | AK27: 2020 | AL27: 2021 | AM27: 2022 | AN27: 2023 | AO27: 2024 | AQ27: Particulars | AR27: 2020 | AS27: 2021 | AT27: 2022 | AU27: 2023 | AV27: 2024 | AX27: ='Assumptions & WACC'!B5 -> 0.1034605 | AY27: ='Assumptions & WACC'!$B$6 -> 0.025 | AZ27: =DCF!B23 -> 227.93289 | BA27: ='Company Profile'!B5 -> 299.12 | BB27: =(AZ27-BA27)/BA27 -> -0.23798848
A28: Dividends Paid | B28: 12690 | C28: 12858 | D28: 13562 | E28: 13463 | F28: 14783 | H28: Dividends Paid | I28: 7727 | J28: 8055 | K28: 8576 | L28: 9087 | M28: 9503 | O28: Dividends Paid | P28: 1474 | Q28: 1448 | R28: 1565 | S28: 1780 | T28: 1999 | V28: Dividends Paid | W28: 2260 | X28: 2547 | Y28: 2990 | Z28: 3035 | AA28: 3101 | AC28: Dividends Paid | AD28: 2336 | AE28: 2725 | AF28: 3682 | AG28: 4189 | AH28: 4497 | AJ28: Dividends Paid | AK28: 2739 | AL28: 4171 | AM28: 5401 | AN28: 5763 | AO28: 6138 | AQ28: Dividends Paid | AR28: 2496 | AS28: 4178 | AT28: 4794 | AU28: 5146 | AV28: 5283 | AX28: ='Assumptions & WACC'!C5 -> 0.115918 | AY28: ='Assumptions & WACC'!$B$6 -> 0.025 | AZ28: =DCF!J23 -> 25.83004 | BA28: ='Company Profile'!C5 -> 51.5465 | BB28: =(AZ28-BA28)/BA28 -> -0.49889828
A29: Capex | B29: 4400 | C29: 4270 | D29: 4510 | E29: 4366 | F29: 4804 | H29: Capex | I29: 2285 | J29: 2375 | K29: 2487 | L29: 2462 | M29: 2512 | O29: Capex | P29: 1478 | Q29: 1550 | R29: 1855 | S29: 1563 | T29: 1911 | V29: Capex | W29: 194 | X29: 341 | Y29: 533 | Z29: 344 | AA29: 255 | AC29: Capex | AD29: 6309 | AE29: 4667 | AF29: 3748 | AG29: 2316 | AH29: 2091 | AJ29: Capex | AK29: 1444 | AL29: 2308 | AM29: 3078 | AN29: 3412 | AO29: 3462 | AQ29: Capex | AR29: 1008 | AS29: 1021 | AT29: 1042 | AU29: 1058 | AV29: 1073
O32: Particulars | P32: 2020 | Q32: 2021 | R32: 2022 | S32: 2023 | T32: 2024 | V32: Particulars | W32: 2020 | X32: 2021 | Y32: 2022 | Z32: 2023 | AA32: 2024 | AC32: Particulars | AD32: 2020 | AE32: 2021 | AF32: 2022 | AG32: 2023 | AH32: 2024 | AJ32: Particulars | AK32: 2020 | AL32: 2021 | AM32: 2022 | AN32: 2023 | AO32: 2024 | AQ32: Particulars | AR32: 2020 | AS32: 2021 | AT32: 2022 | AU32: 2023 | AV32: 2024
O33: Revenue | P33: =P6 -> 36087 | Q33: =Q6 -> 42380 | R33: =R6 -> 52862 | S33: =S6 -> 60515 | T33: =T6 -> 65949 | V33: Revenue | W33: =W4 -> 16205 | X33: =X4 -> 19374 | Y33: =Y4 -> 17873 | Z33: =Z4 -> 17859 | AA33: =AA4 -> 20407 | AC33: Revenue | AD33: =AD6 -> 44560 | AE33: =AE6 -> 59339 | AF33: =AF6 -> 47365 | AG33: =AG6 -> 46254 | AH33: =AH6 -> 53512 | AJ33: Revenue | AK33: =AK6 -> 48198 | AL33: =AL6 -> 59755 | AM33: =AM6 -> 53668 | AN33: =AN6 -> 54143 | AO33: =AO6 -> 61761 | AQ33: Revenue | AR33: =AR6 -> 74301 | AS33: =AS6 -> 79166 | AT33: =AT6 -> 74368 | AU33: =AU6 -> 82597 | AV33: =AV6 -> 82296
O34: Operating income | P34: =P8 -> 9026 | Q34: =Q8 -> 9270 | R34: =R8 -> 11767 | S34: =S8 -> 15436 | T34: =T8 -> 18080 | V34: Operating income | W34: =W6 -> 5801 | X34: =X6 -> 7597 | Y34: =Y6 -> 6536 | Z34: =Z6 -> 6426 | AA34: =AA6 -> 7865 | AC34: Operating income | AD34: =AD8 -> 15577 | AE34: =AE8 -> 27401 | AF34: =AF8 -> 16201 | AG34: =AG8 -> 11767 | AH34: =AH8 -> 19745 | AJ34: Operating income | AK34: =AK8 -> 14418 | AL34: =AL8 -> 19672 | AM34: =AM8 -> 14369 | AN34: =AN8 -> 12345 | AO34: =AO8 -> 17860 | AQ34: Operating income | AR34: =AR8 -> 18170 | AS34: =AS8 -> 25825 | AT34: =AT8 -> 20471 | AU34: =AU8 -> 29114 | AV34: =AV8 -> 28231
O35: Net Income | P35: =P11 -> 3134.7912 | Q35: =Q11 -> 8679.468 | R35: =R11 -> 7783.02 | S35: =S11 -> 8536.556 | T35: =T11 -> 10470.74 | V35: Net Income | W35: =W11 -> 5286 | X35: =X11 -> 6205 | Y35: =Y11 -> 4994 | Z35: =Z11 -> 5676 | AA35: =AA11 -> 6512 | AC35: Net Income | AD35: =AD11 -> 9459.082 | AE35: =AE11 -> 21959.728 | AF35: =AF11 -> 10950.632 | AG35: =AG11 -> 8720.068 | AH35: =AH11 -> 14938.364 | AJ35: Net Income | AK35: =AK11 -> 10589.638 | AL35: =AL11 -> 15250.567 | AM35: =AM11 -> 10924.611 | AN35: =AN11 -> 9159.8002 | AO35: =AO11 -> 13643.938 | AQ35: Net Income | AR35: =AR11 -> 3377 | AS35: =AS11 -> 20818 | AT35: =AT11 -> 13677 | AU35: =AU11 -> 19142 | AV35: =AV11 -> 19722
O36: Advances & Loans | P36: =P15 -> 114077 | Q36: =Q15 -> 141697 | R36: =R15 -> 166958 | S36: =S15 -> 181114 | T36: =T15 -> 193993 | AC36: Advances & Loans | AD36: =AD15 -> 116115 | AE36: =AE15 -> 158562 | AF36: =AF15 -> 179286 | AG36: =AG15 -> 183358 | AH36: =AH15 -> 196200 | AJ36: Advances & Loans | AK36: =AK15 -> 150597 | AL36: =AL15 -> 188134 | AM36: =AM15 -> 213785 | AN36: =AN15 -> 218640 | AO36: =AO15 -> 238153 | AQ36: Advances & Loans | AR36: =AR15 -> 949868 | AS36: =AS15 -> 911162 | AT36: =AT15 -> 964779 | AU36: =AU15 -> 963272 | AV36: =AV15 -> 965429
O38: Particulars | P38: 2025 | Q38: 2026 | R38: 2027 | S38: 2028 | T38: 2029 | U38: 2030 | AC38: Particulars | AD38: 2025 | AE38: 2026 | AF38: 2027 | AG38: 2028 | AH38: 2029 | AI38: 2030 | AQ38: Particulars | AR38: 2025 | AS38: 2026 | AT38: 2027 | AU38: 2028 | AV38: 2029 | AW38: 2030
O39: Revenue | P39: =DCF!R6 -> 71338.08 | Q39: =DCF!S6 -> 80005.737 | R39: =DCF!T6 -> 89728.183 | S39: =DCF!U6 -> 100633.96 | T39: =DCF!V6 -> 112867.32 | U39: =DCF!W6 -> 126590.09 | AC39: Revenue | AD39: =DCF!Z6 -> 55385.074 | AE39: =DCF!AA6 -> 57603.125 | AF39: =DCF!AB6 -> 59961.445 | AG39: =DCF!AC6 -> 62472.725 | AH39: =DCF!AD6 -> 65150.981 | AI39: =DCF!AE6 -> 68011.707 | AQ39: Revenue | AR39: =DCF!AX6 -> 79642.807 | AS39: =DCF!AY6 -> 79844.537 | AT39: =DCF!AZ6 -> 80046.832 | AU39: =DCF!BA6 -> 80249.693 | AV39: =DCF!BB6 -> 80453.122 | AW39: =DCF!BC6 -> 80657.122
O40: Net Income | P40: =DCF!R11 -> 10433.002 | Q40: =DCF!S11 -> 11731.777 | R40: =DCF!T11 -> 13192.164 | S40: =DCF!U11 -> 14834.265 | T40: =DCF!V11 -> 16680.682 | U40: =DCF!W11 -> 18756.827 | AC40: Net Income | AD40: =DCF!Z11 -> 13055.784 | AE40: =DCF!AA11 -> 13455.674 | AF40: =DCF!AB11 -> 13871.722 | AG40: =DCF!AC11 -> 14304.96 | AH40: =DCF!AD11 -> 14756.515 | AI40: =DCF!AE11 -> 15227.617 | AQ40: Net Income | AR40: =DCF!AX11 -> 15892.794 | AS40: =DCF!AY11 -> 15930.611 | AT40: =DCF!AZ11 -> 15968.53 | AU40: =DCF!BA11 -> 16006.55 | AV40: =DCF!BB11 -> 16044.671 | AW40: =DCF!BC11 -> 16082.894
O41: FCFE | P41: =DCF!R13 -> 8199.0904 | Q41: =DCF!S13 -> 9219.7723 | R41: =DCF!T13 -> 10367.462 | S41: =DCF!U13 -> 11657.956 | T41: =DCF!V13 -> 13109.019 | U41: =DCF!W13 -> 14740.62 | AC41: FCFE | AD41: =DCF!Z13 -> 10312.611 | AE41: =DCF!AA13 -> 10628.48 | AF41: =DCF!AB13 -> 10957.112 | AG41: =DCF!AC13 -> 11299.322 | AH41: =DCF!AD13 -> 11656 | AI41: =DCF!AE13 -> 12028.118 | AQ41: FCFE | AR41: =DCF!AX13 -> 11357.706 | AS41: =DCF!AY13 -> 11384.732 | AT41: =DCF!AZ13 -> 11411.83 | AU41: =DCF!BA13 -> 11439.001 | AV41: =DCF!BB13 -> 11466.244 | AW41: =DCF!BC13 -> 11493.56
O42: Advances & Loans | P42: =DCF!R3 -> 215726.58 | Q42: =DCF!S3 -> 239895.03 | R42: =DCF!T3 -> 266771.14 | S42: =DCF!U3 -> 296658.25 | T42: =DCF!V3 -> 329893.7 | U42: =DCF!W3 -> 366852.62 | AC42: Advances & Loans | AD42: =DCF!Z3 -> 217901.96 | AE42: =DCF!AA3 -> 242004.41 | AF42: =DCF!AB3 -> 268772.86 | AG42: =DCF!AC3 -> 298502.21 | AH42: =DCF!AD3 -> 331519.96 | AI42: =DCF!AE3 -> 368189.85 | AJ42: Particulars | AK42: 2025 | AL42: 2026 | AM42: 2027 | AN42: 2028 | AO42: 2029 | AP42: 2030 | AQ42: Advances & Loans | AR42: =DCF!AX3 -> 968571.66 | AS42: =DCF!AY3 -> 971724.55 | AT42: =DCF!AZ3 -> 974887.7 | AU42: =DCF!BA3 -> 978061.15 | AV42: =DCF!BB3 -> 981244.92 | AW42: =DCF!BC3 -> 984439.07
V43: Particulars | W43: 2025 | X43: 2026 | Y43: 2027 | Z43: 2028 | AA43: 2029 | AB43: 2030 | AJ43: Revenue | AK43: =DCF!AP6 -> 66223.539 | AL43: =DCF!AQ6 -> 69949.346 | AM43: =DCF!AR6 -> 73904.428 | AN43: =DCF!AS6 -> 78104.527 | AO43: =DCF!AT6 -> 82566.596 | AP43: =DCF!AU6 -> 87308.891
V44: Revenue | W44: =DCF!AH3 -> 21370.033 | X44: =DCF!AI3 -> 22378.513 | Y44: =DCF!AJ3 -> 23434.584 | Z44: =DCF!AK3 -> 24540.492 | AA44: =DCF!AL3 -> 25698.59 | AB44: =DCF!AM3 -> 26911.34 | AJ44: Net Income | AK44: =DCF!AP11 -> 14269.988 | AL44: =DCF!AQ11 -> 15058.079 | AM44: =DCF!AR11 -> 15893.437 | AN44: =DCF!AS11 -> 16779.216 | AO44: =DCF!AT11 -> 17718.803 | AP44: =DCF!AU11 -> 18715.84
V45: Net Income | W45: =DCF!AH6 -> 6219.9755 | X45: =DCF!AI6 -> 6513.5042 | Y45: =DCF!AJ6 -> 6820.885 | Z45: =DCF!AK6 -> 7142.7714 | AA45: =DCF!AL6 -> 7479.8481 | AB45: =DCF!AM6 -> 7832.8318 | AJ45: FCFE | AK45: =DCF!AP13 -> 8469.8651 | AL45: =DCF!AQ13 -> 8937.6313 | AM45: =DCF!AR13 -> 9433.4531 | AN45: =DCF!AS13 -> 9959.2017 | AO45: =DCF!AT13 -> 10516.888 | AP45: =DCF!AU13 -> 11108.673
...

Sheet Assumptions & WACC
A1: Input | B1: JPMC | C1: BOA | D1: Amex | E1: GS | F1: MS | G1: WF | I1: Input | J1: Blackrock
A2: Risk Free rate | B2: 0.044 | C2: 0.044 | D2: 0.044 | E2: 0.044 | F2: 0.044 | G2: 0.044 | I2: Revenue CAGR | J2: =(Financials!AA4/Financials!W4)^(1/5)-1 -> 0.047191301 | M2: Particulars | N2: 2020 | O2: 2021 | P2: 2022 | Q2: 2023 | R2: 2024
A3: Equity risk premium | B3: 0.055 | C3: 0.055 | D3: 0.055 | E3: 0.055 | F3: 0.055 | G3: 0.055 | I3: Operating margin (EBIT) | J3: =AVERAGE(Financials!W6:AA6)/AVERAGE(Financials!W4:AA4) -> 0.37315467 | M3: WC=Blackrock | N3: =Financials!W17-Financials!W16 -> 8672 | O3: =Financials!X17-Financials!X16 -> 8764 | P3: =Financials!Y17-Financials!Y16 -> 7114 | Q3: =Financials!Z17-Financials!Z16 -> 9019 | R3: =Financials!AA17-Financials!AA16 -> 12566
A4: Beta | B4: ='Company Profile'!B3 -> 1.0811 | C4: ='Company Profile'!C3 -> 1.3076 | D4: ='Company Profile'!D3 -> 1.1574 | E4: ='Company Profile'!F3 -> 1.3514 | F4: ='Company Profile'!G3 -> 1.2205 | G4: ='Company Profile'!H3 -> 1.1136 | I4: Depreciation rate | J4: =AVERAGE(Financials!W7:AA7)/AVERAGE(Table1823[[#This Row],[2020]:[2024]]) -> 0.0092239255 | M4: WC-F | N4: =DCF!AH3*'Assumptions & WACC'!$J$6 -> 10749.324 | O4: =DCF!AI3*'Assumptions & WACC'!$J$6 -> 11256.598 | P4: =DCF!AJ3*'Assumptions & WACC'!$J$6 -> 11787.812 | Q4: =DCF!AK3*'Assumptions & WACC'!$J$6 -> 12344.094 | R4: =DCF!AL3*'Assumptions & WACC'!$J$6 -> 12926.628 | S4: =DCF!AM3*'Assumptions & WACC'!$J$6 -> 13536.652
A5: Cost of Equity | B5: =B2+(B3*B4) -> 0.1034605 | C5: =C2+(C3*C4) -> 0.115918 | D5: =D2+(D3*D4) -> 0.107657 | E5: =E2+(E3*E4) -> 0.118327 | F5: =F2+(F3*F4) -> 0.1111275 | G5: =G2+(G3*G4) -> 0.105248 | I5: CapEx | J5: =AVERAGE(Financials!W29:AA29)/AVERAGE(Financials!W4:AA4) -> 0.018175276
A6: Terminal Growth | B6: 0.025 | C6: 0.025 | D6: 0.025 | E6: 0.02 | F6: 0.02 | G6: 0.02 | I6: Working capital | J6: =AVERAGE(N3:R3)/AVERAGE(Financials!W4:AA4) -> 0.50300922
A7: Dividend Payout | B7: =AVERAGE(Table3[[2020]:[2024]])/AVERAGE(Financials!B11:F11) -> 0.19878537 | C7: =AVERAGE(Table310[[2020]:[2024]])/AVERAGE(Financials!I11:M11) -> 0.21011164 | D7: =AVERAGE(Financials!P28:T28)/AVERAGE(Financials!P11:T11) -> 0.2141197 | E7: =AVERAGE(Financials!AD28:AH28)/AVERAGE(Financials!AD11:AH11) -> 0.26396428 | F7: =AVERAGE(Financials!AK28:AO28)/AVERAGE(Financials!AK11:AO11) -> 0.40645606 | G7: =AVERAGE(Financials!AR28:AV28)/AVERAGE(Financials!AR11:AV11) -> 0.28535498 | I7: Forecast horizon (yrs) | J7: 6
A8: Loan growth | B8: =(Financials!F15/Financials!B15)^(1/5)-1 -> 0.060983973 | C8: =(Financials!M15/Financials!I15)^(1/5)-1 -> 0.01532298 | D8: =(Financials!T15/Financials!P15)^(1/5)-1 -> 0.11203279 | E8: =(Financials!AH15/Financials!AD15)^(1/5)-1 -> 0.11061142 | F8: =(Financials!AO15/Financials!AK15)^(1/5)-1 -> 0.095993421 | G8: =(Financials!AV15/Financials!AR15)^(1/5)-1 -> 0.0032551936 | I8: Risk-free rate | J8: =G2 -> 0.044
A9: Net Interest margin | B9: =AVERAGE(Financials!D4:F4)/(AVERAGE(Financials!D15:F15)) -> 0.066444792 | C9: =AVERAGE(Financials!I4:M4)/(AVERAGE(Financials!I15:M15)) -> 0.050089067 | D9: =AVERAGE(Financials!P4:T4)/(AVERAGE(Financials!P15:T15)) -> 0.068067618 | E9: =AVERAGE(Financials!AD4:AH4)/(AVERAGE(Financials!AD15:AH15)) -> 0.039958201 | F9: =AVERAGE(Financials!AK4:AO4)/(AVERAGE(Financials!AK15:AO15)) -> 0.040152223 | G9: =AVERAGE(Financials!AR4:AV4)/(AVERAGE(Financials!AR15:AV15)) -> 0.046426656 | I9: Equity risk premium | J9: =G3 -> 0.055
A10: Non Interest income growth | B10: =(Financials!F5/Financials!B5)^(1/5)-1 -> 0.053796082 | C10: =(Financials!M5/Financials!I5)^(1/5)-1 -> 0.016781615 | D10: =(Financials!T5/Financials!P5)^(1/5)-1 -> 0.1239552 | E10: =(Financials!AH5/Financials!AD5)^(1/5)-1 -> 0.026885425 | F10: =(Financials!AO5/Financials!AK5)^(1/5)-1 -> 0.048790995 | G10: =(Financials!AV5/Financials!AR5)^(1/5)-1 -> 0.0015962931 | I10: Beta | J10: ='Company Profile'!E3 -> 1.4867
A11: Operating efficiency ratio | B11: =AVERAGE(Financials!B7:F7)/AVERAGE(Financials!B6:F6) -> 0.55684569 | C11: =AVERAGE(Financials!I7:M7)/AVERAGE(Financials!I6:M6) -> 0.65744726 | D11: =AVERAGE(Financials!P7:T7)/AVERAGE(Financials!P6:T6) -> 0.75337189 | E11: =AVERAGE(Financials!AD7:AH7)/AVERAGE(Financials!AD6:AH6) -> 0.63872446 | F11: =AVERAGE(Financials!AK7:AO7)/AVERAGE(Financials!AK6:AO6) -> 0.71655166 | G11: =AVERAGE(Financials!AR7:AV7)/AVERAGE(Financials!AR6:AV6) -> 0.68983368 | I11: Cost of equity | J11: =J8+(J9*J10) -> 0.1257685
A12: Tax rate | B12: 0.22 | C12: 0.22 | D12: 0.22 | E12: 0.22 | F12: 0.22 | G12: 0.22 | I12: Kd (pre-tax) | J12: =AVERAGE(Financials!W8:AA8)/AVERAGE(Financials!W22:AA22) -> 0.034907203
A13: PCR | B13: =AVERAGE(Financials!B9:F9)/AVERAGE(Financials!B15:F15) -> 0.0060433376 | C13: =AVERAGE(Financials!I9:M9)/AVERAGE(Financials!I15:M15) -> 0.0038766515 | D13: =AVERAGE(Financials!P9:T9)/AVERAGE(Financials!P15:T15) -> 0.01955407 | E13: =AVERAGE(Financials!AD9:AH9)/AVERAGE(Financials!AD15:AH15) -> 0.010252891 | F13: =AVERAGE(Financials!AK9:AO9)/AVERAGE(Financials!AK15:AO15) -> 0.0018240202 | G13: =AVERAGE(Financials!AR9:AV9)/AVERAGE(Financials!AR15:AV15) -> 0.0044675477 | I13: Tax rate | J13: 0.22
A14: NPA Ratio | B14: =AVERAGE(Financials!B23:F23)/AVERAGE(Financials!B15:F15) -> 0.0058446062 | C14: =AVERAGE(Financials!I23:M23)/AVERAGE(Financials!I15:M15) -> 0.0050817879 | D14: =AVERAGE(Financials!P23:T23)/AVERAGE(Financials!P15:T15) -> 0.016307801 | G14: =AVERAGE(Financials!AR23:AV23)/AVERAGE(Financials!AR15:AV15) -> 0.0078344561 | I14: Kd (after tax) | J14: =J12*(1-J13) -> 0.027227618
A15: Shares Outstanding | B15: =Financials!F21 -> 2873.9 | C15: =Financials!M21 -> 7673 | D15: =Financials!T21 -> 702 | E15: =Financials!AH21 -> 308.8 | F15: =Financials!AO21 -> 1610 | G15: =Financials!AV21 -> 3302 | I15: Total debt | J15: =Financials!AA22 -> 12314
A16: Present value discount rate | B16: =1/(1+B5)^6 -> 0.55393557 | C16: =1/(1+C5)^6 -> 0.51785277 | D16: =1/(1+D5)^6 -> 0.5414623 | E16: =1/(1+E5)^6 -> 0.51119564 | F16: =1/(1+F5)^6 -> 0.53139397 | G16: =1/(1+G5)^6 -> 0.54858203 | I16: Market cap | J16: ='Company Profile'!E7 -> 157645.73
A17: Debt | B17: =Financials!F16 -> 2406032 | C17: =Financials!M16 -> 1924106 | D17: =Financials!T16 -> 139413 | E17: =Financials!AA22 -> 12314 | F17: =Financials!AH16 -> 433013 | G17: =Financials!AO16 -> 376007 | I17: Total capital | J17: =J15+J16 -> 169959.73
A18: Equity | B18: =Financials!F20 -> 344758 | C18: =Financials!M20 -> 294014 | D18: =Financials!T20 -> 30264 | E18: =Financials!AA23 -> 47664 | F18: =Financials!AO20 -> 105428 | G18: =Financials!AV20 -> 168900 | I18: Debt weight | J18: =J15/$J$17 -> 0.072452458
A19: Total capital | B19: =B17+B18 -> 2750790 | C19: =C17+C18 -> 2218120 | D19: =D17+D18 -> 169677 | E19: =E17+E18 -> 59978 | F19: =F17+F18 -> 538441 | G19: =G17+G18 -> 544907 | I19: Equity weight | J19: =J16/$J$17 -> 0.92754754
A20: Debt weight | B20: =B17/B19 -> 0.87466946 | C20: =C17/C19 -> 0.86744901 | D20: =D17/D19 -> 0.82163758 | E20: =E17/E19 -> 0.20530861 | F20: =F17/F19 -> 0.80419767 | G20: =G17/G19 -> 0.69003885 | I20: WACC | J20: =(J11*J19)+(J14*J18) -> 0.11862897
A21: Equity weight | B21: =B18/B19 -> 0.12533054 | C21: =C18/C19 -> 0.13255099 | D21: =D18/D19 -> 0.17836242 | E21: =E18/E19 -> 0.79469139 | F21: =F18/F19 -> 0.19580233 | G21: =G18/G19 -> 0.30996115 | I21: Terminal year | J21: 2030
I22: PV discount rate (terminal year) | J22: =1/(1+J20)^6 -> 0.51036822
I23: Cash & cash equivalents | J23: =Financials!AA18 -> 12762
I24: Terminal growth rate | J24: 0.02
I25: Shares Outstanding | J25: =Financials!AA24 -> 149.2
I26: Dividend Payout | J26: =AVERAGE(Financials!W28:AA28)/AVERAGE(Financials!W11:AA11) -> 0.48592753

Sheet DCF
A1: DCF | G1: =Financials!F2 -> JPMC | O1: =Table10[[#Headers],[BOA]] -> BOA | Q1: DCF | W1: Amex | AE1: Goldman Sachs | AM1: Blackrock | AU1: Morgan Stanley | BC1: Wells Fargo
A2: Particulars | B2: 2025 | C2: 2026 | D2: 2027 | E2: 2028 | F2: 2029 | G2: 2030 | I2: Particulars | J2: 2025 | K2: 2026 | L2: 2027 | M2: 2028 | N2: 2029 | O2: 2030 | Q2: Particulars | R2: 2025 | S2: 2026 | T2: 2027 | U2: 2028 | V2: 2029 | W2: 2030 | Y2: Particulars | Z2: 2025 | AA2: 2026 | AB2: 2027 | AC2: 2028 | AD2: 2029 | AE2: 2030 | AG2: Particulars | AH2: 2025 | AI2: 2026 | AJ2: 2027 | AK2: 2028 | AL2: 2029 | AM2: 2030 | AO2: Particulars | AP2: 2025 | AQ2: 2026 | AR2: 2027 | AS2: 2028 | AT2: 2029 | AU2: 2030 | AW2: Particulars | AX2: 2025 | AY2: 2026 | AZ2: 2027 | BA2: 2028 | BB2: 2029 | BC2: 2030
A3: Loans | B3: =Financials!F15*(1+'Assumptions & WACC'!$B$8) -> 1404364 | C3: =B3*(1+'Assumptions & WACC'!$B$8) -> 1490007.7 | D3: =C3*(1+'Assumptions & WACC'!$B$8) -> 1580874.3 | E3: =D3*(1+'Assumptions & WACC'!$B$8) -> 1677282.3 | F3: =E3*(1+'Assumptions & WACC'!$B$8) -> 1779569.6 | G3: =F3*(1+'Assumptions & WACC'!$B$8) -> 1888094.9 | I3: Loans | J3: =Financials!M15*(1+'Assumptions & WACC'!$C$8) -> 1076324.6 | K3: =J3*(1+'Assumptions & WACC'!$C$8) -> 1092817.1 | L3: =K3*(1+'Assumptions & WACC'!$C$8) -> 1109562.3 | M3: =L3*(1+'Assumptions & WACC'!$C$8) -> 1126564.1 | N3: =M3*(1+'Assumptions & WACC'!$C$8) -> 1143826.4 | O3: =N3*(1+'Assumptions & WACC'!$C$8) -> 1161353.3 | Q3: Loans | R3: =Financials!T15*(1+'Assumptions & WACC'!D8) -> 215726.58 | S3: =Table1118[[#This Row],[2025]]*(1+'Assumptions & WACC'!$D$8) -> 239895.03 | T3: =Table1118[[#This Row],[2026]]*(1+'Assumptions & WACC'!$D$8) -> 266771.14 | U3: =Table1118[[#This Row],[2027]]*(1+'Assumptions & WACC'!$D$8) -> 296658.25 | V3: =Table1118[[#This Row],[2028]]*(1+'Assumptions & WACC'!$D$8) -> 329893.7 | W3: =Table1118[[#This Row],[2029]]*(1+'Assumptions & WACC'!$D$8) -> 366852.62 | Y3: Loans | Z3: =Financials!AH15*(1+'Assumptions & WACC'!E8) -> 217901.96 | AA3: =Table1335[[#This Row],[2025]]*(1+'Assumptions & WACC'!$E$8) -> 242004.41 | AB3: =Table1335[[#This Row],[2026]]*(1+'Assumptions & WACC'!$E$8) -> 268772.86 | AC3: =Table1335[[#This Row],[2027]]*(1+'Assumptions & WACC'!$E$8) -> 298502.21 | AD3: =Table1335[[#This Row],[2028]]*(1+'Assumptions & WACC'!$E$8) -> 331519.96 | AE3: =Table1335[[#This Row],[2029]]*(1+'Assumptions & WACC'!$E$8) -> 368189.85 | AG3: Revenue | AH3: =Financials!AA4*(1+'Assumptions & WACC'!J2) -> 21370.033 | AI3: =Table48[[#This Row],[2025]]*(1+'Assumptions & WACC'!$J$2) -> 22378.513 | AJ3: =Table48[[#This Row],[2026]]*(1+'Assumptions & WACC'!$J$2) -> 23434.584 | AK3: =Table48[[#This Row],[2027]]*(1+'Assumptions & WACC'!$J$2) -> 24540.492 | AL3: =Table48[[#This Row],[2028]]*(1+'Assumptions & WACC'!$J$2) -> 25698.59 | AM3: =Table48[[#This Row],[2029]]*(1+'Assumptions & WACC'!$J$2) -> 26911.34 | AO3: Loans | AP3: =Financials!AO15*(1+'Assumptions & WACC'!F8) -> 261014.12 | AQ3: =Table1343[[#This Row],[2025]]*(1+'Assumptions & WACC'!$F$8) -> 286069.76 | AR3: =Table1343[[#This Row],[2026]]*(1+'Assumptions & WACC'!$F$8) -> 313530.57 | AS3: =Table1343[[#This Row],[2027]]*(1+'Assumptions & WACC'!$F$8) -> 343627.45 | AT3: =Table1343[[#This Row],[2028]]*(1+'Assumptions & WACC'!$F$8) -> 376613.42 | AU3: =Table1343[[#This Row],[2029]]*(1+'Assumptions & WACC'!$F$8) -> 412765.83 | AW3: Loans | AX3: =Financials!AV15*(1+'Assumptions & WACC'!G8) -> 968571.66 | AY3: =Table134347[[#This Row],[2025]]*(1+'Assumptions & WACC'!$G$8) -> 971724.55 | AZ3: =Table134347[[#This Row],[2026]]*(1+'Assumptions & WACC'!$G$8) -> 974887.7 | BA3: =Table134347[[#This Row],[2027]]*(1+'Assumptions & WACC'!$G$8) -> 978061.15 | BB3: =Table134347[[#This Row],[2028]]*(1+'Assumptions & WACC'!$G$8) -> 981244.92 | BC3: =Table134347[[#This Row],[2029]]*(1+'Assumptions & WACC'!$G$8) -> 984439.07
A4: Net Interest Income | B4: =DCF!B3*'Assumptions & WACC'!$B$9 -> 93312.674 | C4: =DCF!C3*'Assumptions & WACC'!$B$9 -> 99003.252 | D4: =DCF!D3*'Assumptions & WACC'!$B$9 -> 105040.86 | E4: =DCF!E3*'Assumptions & WACC'!$B$9 -> 111446.67 | F4: =DCF!F3*'Assumptions & WACC'!$B$9 -> 118243.13 | G4: =DCF!G3*'Assumptions & WACC'!$B$9 -> 125454.07 | I4: Net Interest Income | J4: =J3*'Assumptions & WACC'!$C$9 -> 53912.095 | K4: =K3*'Assumptions & WACC'!$C$9 -> 54738.189 | L4: =L3*'Assumptions & WACC'!$C$9 -> 55576.941 | M4: =M3*'Assumptions & WACC'!$C$9 -> 56428.546 | N4: =N3*'Assumptions & WACC'!$C$9 -> 57293.199 | O4: =O3*'Assumptions & WACC'!$C$9 -> 58171.102 | Q4: Net Interest Income | R4: =R3*'Assumptions & WACC'!$D$9 -> 14683.994 | S4: =S3*'Assumptions & WACC'!$D$9 -> 16329.083 | T4: =T3*'Assumptions & WACC'!$D$9 -> 18158.476 | U4: =U3*'Assumptions & WACC'!$D$9 -> 20192.82 | V4: =V3*'Assumptions & WACC'!$D$9 -> 22455.078 | W4: =W3*'Assumptions & WACC'!$D$9 -> 24970.784 | Y4: Net Interest Income | Z4: =Z3*'Assumptions & WACC'!$E$9 -> 8706.9704 | AA4: =AA3*'Assumptions & WACC'!$E$9 -> 9670.0608 | AB4: =AB3*'Assumptions & WACC'!$E$9 -> 10739.68 | AC4: =AC3*'Assumptions & WACC'!$E$9 -> 11927.611 | AD4: =AD3*'Assumptions & WACC'!$E$9 -> 13246.941 | AE4: =AE3*'Assumptions & WACC'!$E$9 -> 14712.204 | AG4: EBIT | AH4: =AH3*'Assumptions & WACC'!$J$3 -> 7974.3276 | AI4: =AI3*'Assumptions & WACC'!$J$3 -> 8350.6465 | AJ4: =AJ3*'Assumptions & WACC'!$J$3 -> 8744.7243 | AK4: =AK3*'Assumptions & WACC'!$J$3 -> 9157.3992 | AL4: =AL3*'Assumptions & WACC'!$J$3 -> 9589.5488 | AM4: =AM3*'Assumptions & WACC'!$J$3 -> 10042.092 | AO4: Net Interest Income | AP4: =AP3*'Assumptions & WACC'!$F$9 -> 10480.297 | AQ4: =AQ3*'Assumptions & WACC'!$F$9 -> 11486.337 | AR4: =AR3*'Assumptions & WACC'!$F$9 -> 12588.95 | AS4: =AS3*'Assumptions & WACC'!$F$9 -> 13797.406 | AT4: =AT3*'Assumptions & WACC'!$F$9 -> 15121.866 | AU4: =AU3*'Assumptions & WACC'!$F$9 -> 16573.466 | AW4: Net Interest Income | AX4: =AX3*'Assumptions & WACC'!$G$9 -> 44967.543 | AY4: =AY3*'Assumptions & WACC'!$G$9 -> 45113.921 | AZ4: =AZ3*'Assumptions & WACC'!$G$9 -> 45260.776 | BA4: =BA3*'Assumptions & WACC'!$G$9 -> 45408.108 | BB4: =BB3*'Assumptions & WACC'!$G$9 -> 45555.921 | BC4: =BC3*'Assumptions & WACC'!$G$9 -> 45704.214
A5: Non-Interest income | B5: =Table1[[#This Row],[2024]]*(1+'Assumptions & WACC'!B10) -> 89544.214 | C5: =B5*(1+'Assumptions & WACC'!$B$10) -> 94361.342 | D5: =C5*(1+'Assumptions & WACC'!$B$10) -> 99437.613 | E5: =D5*(1+'Assumptions & WACC'!$B$10) -> 104786.97 | F5: =E5*(1+'Assumptions & WACC'!$B$10) -> 110424.1 | G5: =F5*(1+'Assumptions & WACC'!$B$10) -> 116364.48 | I5: Non-Interest income | J5: =Table18[[#This Row],[2024]]*(1+'Assumptions & WACC'!C10) -> 46596.051 | K5: =J5*(1+'Assumptions & WACC'!$C$10) -> 47378.008 | L5: =K5*(1+'Assumptions & WACC'!$C$10) -> 48173.088 | M5: =L5*(1+'Assumptions & WACC'!$C$10) -> 48981.51 | N5: =M5*(1+'Assumptions & WACC'!$C$10) -> 49803.499 | O5: =N5*(1+'Assumptions & WACC'!$C$10) -> 50639.282 | Q5: Non-Interest income | R5: =Table120[[#This Row],[2024]]*(1+'Assumptions & WACC'!D10) -> 56654.086 | S5: =Table1118[[#This Row],[2025]]*(1+'Assumptions & WACC'!$D$10) -> 63676.654 | T5: =Table1118[[#This Row],[2026]]*(1+'Assumptions & WACC'!$D$10) -> 71569.707 | U5: =Table1118[[#This Row],[2027]]*(1+'Assumptions & WACC'!$D$10) -> 80441.144 | V5: =Table1118[[#This Row],[2028]]*(1+'Assumptions & WACC'!$D$10) -> 90412.242 | W5: =Table1118[[#This Row],[2029]]*(1+'Assumptions & WACC'!$D$10) -> 101619.31 | Y5: Non-Interest income | Z5: =Table126[[#This Row],[2024]]*(1+'Assumptions & WACC'!E10) -> 46678.104 | AA5: =Table1335[[#This Row],[2025]]*(1+'Assumptions & WACC'!$E$10) -> 47933.065 | AB5: =Table1335[[#This Row],[2026]]*(1+'Assumptions & WACC'!$E$10) -> 49221.765 | AC5: =Table1335[[#This Row],[2027]]*(1+'Assumptions & WACC'!$E$10) -> 50545.113 | AD5: =Table1335[[#This Row],[2028]]*(1+'Assumptions & WACC'!$E$10) -> 51904.04 | AE5: =Table1335[[#This Row],[2029]]*(1+'Assumptions & WACC'!$E$10) -> 53299.502 | AG5: Tax | AH5: ='Assumptions & WACC'!$J$13 -> 0.22 | AI5: ='Assumptions & WACC'!$J$13 -> 0.22 | AJ5: ='Assumptions & WACC'!$J$13 -> 0.22 | AK5: ='Assumptions & WACC'!$J$13 -> 0.22 | AL5: ='Assumptions & WACC'!$J$13 -> 0.22 | AM5: ='Assumptions & WACC'!$J$13 -> 0.22 | AO5: Non-Interest income | AP5: =Table1829[[#This Row],[2024]]*(1+'Assumptions & WACC'!F10) -> 55743.241 | AQ5: =Table1343[[#This Row],[2025]]*(1+'Assumptions & WACC'!$F$10) -> 58463.01 | AR5: =Table1343[[#This Row],[2026]]*(1+'Assumptions & WACC'!$F$10) -> 61315.478 | AS5: =Table1343[[#This Row],[2027]]*(1+'Assumptions & WACC'!$F$10) -> 64307.121 | AT5: =Table1343[[#This Row],[2028]]*(1+'Assumptions & WACC'!$F$10) -> 67444.73 | AU5: =Table1343[[#This Row],[2029]]*(1+'Assumptions & WACC'!$F$10) -> 70735.425 | AW5: Non-Interest income | AX5: =Table182932[[#This Row],[2024]]*(1+'Assumptions & WACC'!G10) -> 34675.264 | AY5: =Table134347[[#This Row],[2025]]*(1+'Assumptions & WACC'!$G$10) -> 34730.616 | AZ5: =Table134347[[#This Row],[2026]]*(1+'Assumptions & WACC'!$G$10) -> 34786.056 | BA5: =Table134347[[#This Row],[2027]]*(1+'Assumptions & WACC'!$G$10) -> 34841.585 | BB5: =Table134347[[#This Row],[2028]]*(1+'Assumptions & WACC'!$G$10) -> 34897.202 | BC5: =Table134347[[#This Row],[2029]]*(1+'Assumptions & WACC'!$G$10) -> 34952.908
A6: Net Revenue | B6: =B4+B5 -> 182856.89 | C6: =C4+C5 -> 193364.59 | D6: =D4+D5 -> 204478.48 | E6: =E4+E5 -> 216233.64 | F6: =F4+F5 -> 228667.23 | G6: =G4+G5 -> 241818.55 | I6: Net Revenue | J6: =J4+J5 -> 100508.15 | K6: =K4+K5 -> 102116.2 | L6: =L4+L5 -> 103750.03 | M6: =M4+M5 -> 105410.06 | N6: =N4+N5 -> 107096.7 | O6: =O4+O5 -> 108810.38 | Q6: Net Revenue | R6: =R4+R5 -> 71338.08 | S6: =S4+S5 -> 80005.737 | T6: =T4+T5 -> 89728.183 | U6: =U4+U5 -> 100633.96 | V6: =V4+V5 -> 112867.32 | W6: =W4+W5 -> 126590.09 | Y6: Net Revenue | Z6: =Z4+Z5 -> 55385.074 | AA6: =AA4+AA5 -> 57603.125 | AB6: =AB4+AB5 -> 59961.445 | AC6: =AC4+AC5 -> 62472.725 | AD6: =AD4+AD5 -> 65150.981 | AE6: =AE4+AE5 -> 68011.707 | AG6: NOPAT | AH6: =AH4*(1-AH5) -> 6219.9755 | AI6: =AI4*(1-AI5) -> 6513.5042 | AJ6: =AJ4*(1-AJ5) -> 6820.885 | AK6: =AK4*(1-AK5) -> 7142.7714 | AL6: =AL4*(1-AL5) -> 7479.8481 | AM6: =AM4*(1-AM5) -> 7832.8318 | AO6: Net Revenue | AP6: =AP4+AP5 -> 66223.539 | AQ6: =AQ4+AQ5 -> 69949.346 | AR6: =AR4+AR5 -> 73904.428 | AS6: =AS4+AS5 -> 78104.527 | AT6: =AT4+AT5 -> 82566.596 | AU6: =AU4+AU5 -> 87308.891 | AW6: Net Revenue | AX6: =AX4+AX5 -> 79642.807 | AY6: =AY4+AY5 -> 79844.537 | AZ6: =AZ4+AZ5 -> 80046.832 | BA6: =BA4+BA5 -> 80249.693 | BB6: =BB4+BB5 -> 80453.122 | BC6: =BC4+BC5 -> 80657.122
A7: Operating Expense | B7: =B6*'Assumptions & WACC'!$B$11 -> 101823.07 | C7: =C6*'Assumptions & WACC'!$B$11 -> 107674.24 | D7: =D6*'Assumptions & WACC'!$B$11 -> 113862.96 | E7: =E6*'Assumptions & WACC'!$B$11 -> 120408.77 | F7: =F6*'Assumptions & WACC'!$B$11 -> 127332.36 | G7: =G6*'Assumptions & WACC'!$B$11 -> 134655.62 | I7: Operating Expense | J7: =J6*'Assumptions & WACC'!$C$11 -> 66078.805 | K7: =K6*'Assumptions & WACC'!$C$11 -> 67136.014 | L7: =L6*'Assumptions & WACC'!$C$11 -> 68210.172 | M7: =M6*'Assumptions & WACC'!$C$11 -> 69301.552 | N7: =N6*'Assumptions & WACC'!$C$11 -> 70410.43 | O7: =O6*'Assumptions & WACC'!$C$11 -> 71537.088 | Q7: Operating Expense | R7: =R6*'Assumptions & WACC'!$D$11 -> 53744.104 | S7: =S6*'Assumptions & WACC'!$D$11 -> 60274.074 | T7: =T6*'Assumptions & WACC'!$D$11 -> 67598.691 | U7: =U6*'Assumptions & WACC'!$D$11 -> 75814.8 | V7: =V6*'Assumptions & WACC'!$D$11 -> 85031.067 | W7: =W6*'Assumptions & WACC'!$D$11 -> 95369.418 | Y7: Operating Expense | Z7: =Z6*'Assumptions & WACC'!$C$11 -> 36412.765 | AA7: =AA6*'Assumptions & WACC'!$C$11 -> 37871.017 | AB7: =AB6*'Assumptions & WACC'!$C$11 -> 39421.488 | AC7: =AC6*'Assumptions & WACC'!$C$11 -> 41072.521 | AD7: =AD6*'Assumptions & WACC'!$C$11 -> 42833.334 | AE7: =AE6*'Assumptions & WACC'!$C$11 -> 44714.11 | AG7: Depreciation | AH7: =AH3*'Assumptions & WACC'!$J$4 -> 197.11559 | AI7: =AI3*'Assumptions & WACC'!$J$4 -> 206.41773 | AJ7: =AJ3*'Assumptions & WACC'!$J$4 -> 216.15885 | AK7: =AK3*'Assumptions & WACC'!$J$4 -> 226.35967 | AL7: =AL3*'Assumptions & WACC'!$J$4 -> 237.04188 | AM7: =AM3*'Assumptions & WACC'!$J$4 -> 248.22819 | AO7: Operating Expense | AP7: =AP6*'Assumptions & WACC'!$F$11 -> 47452.587 | AQ7: =AQ6*'Assumptions & WACC'!$F$11 -> 50122.32 | AR7: =AR6*'Assumptions & WACC'!$F$11 -> 52956.34 | AS7: =AS6*'Assumptions & WACC'!$F$11 -> 55965.929 | AT7: =AT6*'Assumptions & WACC'!$F$11 -> 59163.231 | AU7: =AU6*'Assumptions & WACC'!$F$11 -> 62561.331 | AW7: Operating Expense | AX7: =AX6*'Assumptions & WACC'!$G$11 -> 54940.29 | AY7: =AY6*'Assumptions & WACC'!$G$11 -> 55079.45 | AZ7: =AZ6*'Assumptions & WACC'!$G$11 -> 55219 | BA7: =BA6*'Assumptions & WACC'!$G$11 -> 55358.941 | BB7: =BB6*'Assumptions & WACC'!$G$11 -> 55499.273 | BC7: =BC6*'Assumptions & WACC'!$G$11 -> 55639.999
A8: Provisions | B8: =B3*'Assumptions & WACC'!$B$13 -> 8487.0459 | C8: =C3*'Assumptions & WACC'!$B$13 -> 9004.6196 | D8: =D3*'Assumptions & WACC'!$B$13 -> 9553.7571 | E8: =E3*'Assumptions & WACC'!$B$13 -> 10136.383 | F8: =F3*'Assumptions & WACC'!$B$13 -> 10754.54 | G8: =G3*'Assumptions & WACC'!$B$13 -> 11410.395 | I8: Provisions | J8: =J3*'Assumptions & WACC'!$C$13 -> 4172.5354 | K8: =K3*'Assumptions & WACC'!$C$13 -> 4236.471 | L8: =L3*'Assumptions & WACC'!$C$13 -> 4301.3864 | M8: =M3*'Assumptions & WACC'!$C$13 -> 4367.2965 | N8: =N3*'Assumptions & WACC'!$C$13 -> 4434.2165 | O8: =O3*'Assumptions & WACC'!$C$13 -> 4502.1619 | Q8: Provisions | R8: =R3*'Assumptions & WACC'!$D$13 -> 4218.3327 | S8: =S3*'Assumptions & WACC'!$D$13 -> 4690.9243 | T8: =T3*'Assumptions & WACC'!$D$13 -> 5216.4616 | U8: =U3*'Assumptions & WACC'!$D$13 -> 5800.8764 | V8: =V3*'Assumptions & WACC'!$D$13 -> 6450.7647 | W8: =W3*'Assumptions & WACC'!$D$13 -> 7173.4619 | Y8: Provisions | Z8: =Z3*'Assumptions & WACC'!$E$13 -> 2234.1251 | AA8: =AA3*'Assumptions & WACC'!$E$13 -> 2481.2448 | AB8: =AB3*'Assumptions & WACC'!$E$13 -> 2755.6988 | AC8: =AC3*'Assumptions & WACC'!$E$13 -> 3060.5106 | AD8: =AD3*'Assumptions & WACC'!$E$13 -> 3399.038 | AE8: =AE3*'Assumptions & WACC'!$E$13 -> 3775.0104 | AG8: Capex | AH8: =AH3*'Assumptions & WACC'!$J$5 -> 388.40625 | AI8: =AI3*'Assumptions & WACC'!$J$5 -> 406.73565 | AJ8: =AJ3*'Assumptions & WACC'!$J$5 -> 425.93003 | AK8: =AK3*'Assumptions & WACC'!$J$5 -> 446.03023 | AL8: =AL3*'Assumptions & WACC'!$J$5 -> 467.07897 | AM8: =AM3*'Assumptions & WACC'!$J$5 -> 489.12104 | AO8: Provisions | AP8: =AP3*'Assumptions & WACC'!$F$13 -> 476.09503 | AQ8: =AQ3*'Assumptions & WACC'!$F$13 -> 521.79702 | AR8: =AR3*'Assumptions & WACC'!$F$13 -> 571.8861 | AS8: =AS3*'Assumptions & WACC'!$F$13 -> 626.7834 | AT8: =AT3*'Assumptions & WACC'!$F$13 -> 686.95049 | AU8: =AU3*'Assumptions & WACC'!$F$13 -> 752.89321 | AW8: Provisions | AX8: =AX3*'Assumptions & WACC'!$G$13 -> 4327.14 | AY8: =AY3*'Assumptions & WACC'!$G$13 -> 4341.2257 | AZ8: =AZ3*'Assumptions & WACC'!$G$13 -> 4355.3572 | BA8: =BA3*'Assumptions & WACC'!$G$13 -> 4369.5348 | BB8: =BB3*'Assumptions & WACC'!$G$13 -> 4383.7585 | BC8: =BC3*'Assumptions & WACC'!$G$13 -> 4398.0284
A9: PBT | B9: =B6-B7-B8 -> 72546.772 | C9: =C6-C7-C8 -> 76685.734 | D9: =D6-D7-D8 -> 81061.761 | E9: =E6-E7-E8 -> 85688.486 | F9: =F6-F7-F8 -> 90580.328 | G9: =G6-G7-G8 -> 95752.537 | I9: PBT | J9: =J6-J7-J8 -> 30256.806 | K9: =K6-K7-K8 -> 30743.712 | L9: =L6-L7-L8 -> 31238.471 | M9: =M6-M7-M8 -> 31741.207 | N9: =N6-N7-N8 -> 32252.051 | O9: =O6-O7-O8 -> 32771.133 | Q9: PBT | R9: =R6-R7-R8 -> 13375.643 | S9: =S6-S7-S8 -> 15040.739 | T9: =T6-T7-T8 -> 16913.03 | U9: =U6-U7-U8 -> 19018.288 | V9: =V6-V7-V8 -> 21385.489 | W9: =W6-W7-W8 -> 24047.213 | Y9: PBT | Z9: =Z6-Z7-Z8 -> 16738.184 | AA9: =AA6-AA7-AA8 -> 17250.864 | AB9: =AB6-AB7-AB8 -> 17784.259 | AC9: =AC6-AC7-AC8 -> 18339.693 | AD9: =AD6-AD7-AD8 -> 18918.609 | AE9: =AE6-AE7-AE8 -> 19522.586 | AG9: Change in working capital | AH9: ='Assumptions & WACC'!N4-'Assumptions & WACC'!R3 -> -1816.6763 | AI9: ='Assumptions & WACC'!O4-'Assumptions & WACC'!N4 -> 507.27457 | AJ9: ='Assumptions & WACC'!P4-'Assumptions & WACC'!O4 -> 531.21351 | AK9: ='Assumptions & WACC'!Q4-'Assumptions & WACC'!P4 -> 556.28217 | AL9: ='Assumptions & WACC'!R4-'Assumptions & WACC'!Q4 -> 582.53385 | AM9: ='Assumptions & WACC'!S4-'Assumptions & WACC'!R4 -> 610.02438 | AO9: PBT | AP9: =AP6-AP7-AP8 -> 18294.857 | AQ9: =AQ6-AQ7-AQ8 -> 19305.229 | AR9: =AR6-AR7-AR8 -> 20376.201 | AS9: =AS6-AS7-AS8 -> 21511.815 | AT9: =AT6-AT7-AT8 -> 22716.414 | AU9: =AU6-AU7-AU8 -> 23994.667 | AW9: PBT | AX9: =AX6-AX7-AX8 -> 20375.377 | AY9: =AY6-AY7-AY8 -> 20423.861 | AZ9: =AZ6-AZ7-AZ8 -> 20472.474 | BA9: =BA6-BA7-BA8 -> 20521.217 | BB9: =BB6-BB7-BB8 -> 20570.091 | BC9: =BC6-BC7-BC8 -> 20619.095
A10: Tax | B10: 0.22 | C10: 0.22 | D10: 0.22 | E10: 0.22 | F10: 0.22 | G10: 0.22 | I10: Tax | J10: 0.22 | K10: 0.22 | L10: 0.22 | M10: 0.22 | N10: 0.22 | O10: 0.22 | Q10: Tax | R10: 0.22 | S10: 0.22 | T10: 0.22 | U10: 0.22 | V10: 0.22 | W10: 0.22 | Y10: Tax | Z10: 0.22 | AA10: 0.22 | AB10: 0.22 | AC10: 0.22 | AD10: 0.22 | AE10: 0.22 | AG10: FCFF | AH10: =AH6+AH7-AH8-AH9 -> 7845.3612 | AI10: =AI6+AI7-AI8-AI9 -> 5805.9117 | AJ10: =AJ6+AJ7-AJ8-AJ9 -> 6079.9003 | AK10: =AK6+AK7-AK8-AK9 -> 6366.8187 | AL10: =AL6+AL7-AL8-AL9 -> 6667.2771 | AM10: =AM6+AM7-AM8-AM9 -> 6981.9146 | AO10: Tax | AP10: 0.22 | AQ10: 0.22 | AR10: 0.22 | AS10: 0.22 | AT10: 0.22 | AU10: 0.22 | AW10: Tax | AX10: 0.22 | AY10: 0.22 | AZ10: 0.22 | BA10: 0.22 | BB10: 0.22 | BC10: 0.22
A11: Net Income | B11: =B9*(1-B10) -> 56586.482 | C11: =C9*(1-C10) -> 59814.872 | D11: =D9*(1-D10) -> 63228.173 | E11: =E9*(1-E10) -> 66837.019 | F11: =F9*(1-F10) -> 70652.656 | G11: =G9*(1-G10) -> 74686.979 | I11: Net Income | J11: =J9*(1-J10) -> 23600.309 | K11: =K9*(1-K10) -> 23980.096 | L11: =L9*(1-L10) -> 24366.007 | M11: =M9*(1-M10) -> 24758.142 | N11: =N9*(1-N10) -> 25156.6 | O11: =O9*(1-O10) -> 25561.484 | Q11: Net Income | R11: =R9*(1-R10) -> 10433.002 | S11: =S9*(1-S10) -> 11731.777 | T11: =T9*(1-T10) -> 13192.164 | U11: =U9*(1-U10) -> 14834.265 | V11: =V9*(1-V10) -> 16680.682 | W11: =W9*(1-W10) -> 18756.827 | Y11: Net Income | Z11: =Z9*(1-Z10) -> 13055.784 | AA11: =AA9*(1-AA10) -> 13455.674 | AB11: =AB9*(1-AB10) -> 13871.722 | AC11: =AC9*(1-AC10) -> 14304.96 | AD11: =AD9*(1-AD10) -> 14756.515 | AE11: =AE9*(1-AE10) -> 15227.617 | AO11: Net Income | AP11: =AP9*(1-AP10) -> 14269.988 | AQ11: =AQ9*(1-AQ10) -> 15058.079 | AR11: =AR9*(1-AR10) -> 15893.437 | AS11: =AS9*(1-AS10) -> 16779.216 | AT11: =AT9*(1-AT10) -> 17718.803 | AU11: =AU9*(1-AU10) -> 18715.84 | AW11: Net Income | AX11: =AX9*(1-AX10) -> 15892.794 | AY11: =AY9*(1-AY10) -> 15930.611 | AZ11: =AZ9*(1-AZ10) -> 15968.53 | BA11: =BA9*(1-BA10) -> 16006.55 | BB11: =BB9*(1-BB10) -> 16044.671 | BC11: =BC9*(1-BC10) -> 16082.894
A12: Dividend | B12: =B11*'Assumptions & WACC'!$B$7 -> 11248.565 | C12: =C11*'Assumptions & WACC'!$B$7 -> 11890.322 | D12: =D11*'Assumptions & WACC'!$B$7 -> 12568.836 | E12: =E11*'Assumptions & WACC'!$B$7 -> 13286.222 | F12: =F11*'Assumptions & WACC'!$B$7 -> 14044.715 | G12: =G11*'Assumptions & WACC'!$B$7 -> 14846.679 | I12: Dividend | J12: =J11*'Assumptions & WACC'!$C$7 -> 4958.6995 | K12: =K11*'Assumptions & WACC'!$C$7 -> 5038.4972 | L12: =L11*'Assumptions & WACC'!$C$7 -> 5119.5817 | M12: =M11*'Assumptions & WACC'!$C$7 -> 5201.9737 | N12: =N11*'Assumptions & WACC'!$C$7 -> 5285.6944 | O12: =O11*'Assumptions & WACC'!$C$7 -> 5370.7653 | Q12: Dividend | R12: =R11*'Assumptions & WACC'!$D$7 -> 2233.9112 | S12: =S11*'Assumptions & WACC'!$D$7 -> 2512.0045 | T12: =T11*'Assumptions & WACC'!$D$7 -> 2824.7021 | U12: =U11*'Assumptions & WACC'!$D$7 -> 3176.3083 | V12: =V11*'Assumptions & WACC'!$D$7 -> 3571.6625 | W12: =W11*'Assumptions & WACC'!$D$7 -> 4016.206 | Y12: Dividend | Z12: =Z11*'Assumptions & WACC'!$C$7 -> 2743.1721 | AA12: =AA11*'Assumptions & WACC'!$C$7 -> 2827.1937 | AB12: =AB11*'Assumptions & WACC'!$C$7 -> 2914.6102 | AC12: =AC11*'Assumptions & WACC'!$C$7 -> 3005.6386 | AD12: =AD11*'Assumptions & WACC'!$C$7 -> 3100.5156 | AE12: =AE11*'Assumptions & WACC'!$C$7 -> 3199.4996 | AG12: Dividend | AH12: =AH6*'Assumptions & WACC'!$J$26 -> 3022.4573 | AI12: =AI6*'Assumptions & WACC'!$J$26 -> 3165.091 | AJ12: =AJ6*'Assumptions & WACC'!$J$26 -> 3314.4558 | AK12: =AK6*'Assumptions & WACC'!$J$26 -> 3470.8692 | AL12: =AL6*'Assumptions & WACC'!$J$26 -> 3634.6641 | AM12: =AM6*'Assumptions & WACC'!$J$26 -> 3806.1886 | AO12: Dividend | AP12: =AP11*'Assumptions & WACC'!$F$7 -> 5800.1233 | AQ12: =AQ11*'Assumptions & WACC'!$F$7 -> 6120.4473 | AR12: =AR11*'Assumptions & WACC'!$F$7 -> 6459.9838 | AS12: =AS11*'Assumptions & WACC'!$F$7 -> 6820.0139 | AT12: =AT11*'Assumptions & WACC'!$F$7 -> 7201.9148 | AU12: =AU11*'Assumptions & WACC'!$F$7 -> 7607.1667 | AW12: Dividend | AX12: =AX11*'Assumptions & WACC'!$G$7 -> 4535.0879 | AY12: =AY11*'Assumptions & WACC'!$G$7 -> 4545.8793 | AZ12: =AZ11*'Assumptions & WACC'!$G$7 -> 4556.6996 | BA12: =BA11*'Assumptions & WACC'!$G$7 -> 4567.5487 | BB12: =BB11*'Assumptions & WACC'!$G$7 -> 4578.4268 | BC12: =BC11*'Assumptions & WACC'!$G$7 -> 4589.3339
A13: FCFE | B13: =B11-B12 -> 45337.917 | C13: =C11-C12 -> 47924.55 | D13: =D11-D12 -> 50659.337 | E13: =E11-E12 -> 53550.797 | F13: =F11-F12 -> 56607.941 | G13: =G11-G12 -> 59840.3 | I13: FCFE | J13: =J11-J12 -> 18641.609 | K13: =K11-K12 -> 18941.598 | L13: =L11-L12 -> 19246.425 | M13: =M11-M12 -> 19556.168 | N13: =N11-N12 -> 19870.905 | O13: =O11-O12 -> 20190.719 | Q13: FCFE | R13: =R11-R12 -> 8199.0904 | S13: =S11-S12 -> 9219.7723 | T13: =T11-T12 -> 10367.462 | U13: =U11-U12 -> 11657.956 | V13: =V11-V12 -> 13109.019 | W13: =W11-W12 -> 14740.62 | Y13: FCFE | Z13: =Z11-Z12 -> 10312.611 | AA13: =AA11-AA12 -> 10628.48 | AB13: =AB11-AB12 -> 10957.112 | AC13: =AC11-AC12 -> 11299.322 | AD13: =AD11-AD12 -> 11656 | AE13: =AE11-AE12 -> 12028.118 | AO13: FCFE | AP13: =AP11-AP12 -> 8469.8651 | AQ13: =AQ11-AQ12 -> 8937.6313 | AR13: =AR11-AR12 -> 9433.4531 | AS13: =AS11-AS12 -> 9959.2017 | AT13: =AT11-AT12 -> 10516.888 | AU13: =AU11-AU12 -> 11108.673 | AW13: FCFE | AX13: =AX11-AX12 -> 11357.706 | AY13: =AY11-AY12 -> 11384.732 | AZ13: =AZ11-AZ12 -> 11411.83 | BA13: =BA11-BA12 -> 11439.001 | BB13: =BB11-BB12 -> 11466.244 | BC13: =BC11-BC12 -> 11493.56
A17: Metric | B17: Value | I17: Metric | J17: Value | Q17: Metric | R17: Value | Y17: Metric | Z17: Value | AG17: Metric | AH17: Value | AO17: Metric | AP17: Value | AW17: Metric | AX17: Value
A18: Terminal Value | B18: =G13*(1+'Assumptions & WACC'!B6)/('Assumptions & WACC'!B5-'Assumptions & WACC'!B6) -> 781747.6 | I18: Terminal Value | J18: =O13*(1+'Assumptions & WACC'!C6)/('Assumptions & WACC'!C5-'Assumptions & WACC'!C6) -> 227628.05 | Q18: Terminal Value | R18: =W13/('Assumptions & WACC'!D5-'Assumptions & WACC'!D6) -> 178334.81 | Y18: Terminal Value | Z18: =AE13/('Assumptions & WACC'!E5-'Assumptions & WACC'!E6) -> 122327.72 | AG18: Terminal value | AH18: =AM10*(1+'Assumptions & WACC'!J24)/('Assumptions & WACC'!J20-'Assumptions & WACC'!J24) -> 72205.487 | AO18: Terminal Value | AP18: =AU13/('Assumptions & WACC'!F5-'Assumptions & WACC'!F6) -> 121902.54 | AW18: Terminal Value | AX18: =BC13/('Assumptions & WACC'!G5-'Assumptions & WACC'!G6) -> 134824.98
